{"time":1701245639,"time_ms":1701245639014,"channel":"futures.order_book_update","event":"update","result":{"U":53095233707,"a":[{"p":"38155.9","s":0},{"p":"38154.5","s":0},{"p":"38155.6","s":0},{"p":"38170.8","s":0}],"b":[{"p":"38139.8","s":0},{"p":"38139.2","s":0},{"p":"38135.2","s":0},{"p":"38140.7","s":2379},{"p":"38140.8","s":0},{"p":"38133.1","s":0}],"s":"BTC_USDT","t":1701245639006,"u":53095233724}}
{"time":1701245639,"time_ms":1701245639034,"channel":"futures.order_book_update","event":"update","result":{"U":53095233725,"a":[{"p":"38159.1","s":0},{"p":"38155.4","s":0},{"p":"38154.4","s":0},{"p":"38154.3","s":0},{"p":"38155.8","s":0}],"b":[{"p":"38140.5","s":6},{"p":"38140.4","s":0},{"p":"38139.8","s":0},{"p":"38140.9","s":2174},{"p":"38140.7","s":3112}],"s":"BTC_USDT","t":1701245639016,"u":53095233738}}
{"time":1701245639,"time_ms":1701245639054,"channel":"futures.order_book_update","event":"update","result":{"U":53095233739,"a":[{"p":"38158.9","s":0}],"b":[],"s":"BTC_USDT","t":1701245639040,"u":53095233740}}
{"time":1701245639,"time_ms":1701245639072,"channel":"futures.order_book_update","event":"update","result":{"U":53095233741,"a":[],"b":[{"p":"38139.6","s":0}],"s":"BTC_USDT","t":1701245639048,"u":53095233742}}
{"time":1701245639,"time_ms":1701245639113,"channel":"futures.order_book_update","event":"update","result":{"U":53095233743,"a":[],"b":[{"p":"38139.7","s":0},{"p":"38140.8","s":0},{"p":"38139.8","s":2306},{"p":"38141","s":2174},{"p":"38140.9","s":0},{"p":"38140.5","s":0}],"s":"BTC_USDT","t":1701245639100,"u":53095233750}}
{"time":1701245639,"time_ms":1701245639132,"channel":"futures.order_book_update","event":"update","result":{"U":53095233751,"a":[],"b":[{"p":"38140.5","s":6},{"p":"38139.8","s":0}],"s":"BTC_USDT","t":1701245639113,"u":53095233754}}
{"time":1701245639,"time_ms":1701245639152,"channel":"futures.order_book_update","event":"update","result":{"U":53095233755,"a":[{"p":"38153.2","s":0},{"p":"38155.7","s":0},{"p":"38155.5","s":0},{"p":"38156.2","s":0},{"p":"38145.6","s":19418},{"p":"38159.5","s":0},{"p":"38155.8","s":0}],"b":[{"p":"38139.8","s":0},{"p":"38140.8","s":2175},{"p":"38141","s":0}],"s":"BTC_USDT","t":1701245639144,"u":53095233768}}
{"time":1701245639,"time_ms":1701245639174,"channel":"futures.order_book_update","event":"update","result":{"U":53095233769,"a":[{"p":"38155.2","s":0},{"p":"38155.4","s":0}],"b":[{"p":"38139.8","s":2306},{"p":"38140.5","s":0}],"s":"BTC_USDT","t":1701245639162,"u":53095233777}}
{"time":1701245639,"time_ms":1701245639212,"channel":"futures.order_book_update","event":"update","result":{"U":53095233778,"a":[{"p":"38159.1","s":0},{"p":"38171","s":0},{"p":"38154.6","s":0},{"p":"38156.1","s":0}],"b":[{"p":"38140.4","s":733},{"p":"38139.8","s":0},{"p":"38133.5","s":0},{"p":"38140.7","s":2379}],"s":"BTC_USDT","t":1701245639197,"u":53095233791}}
{"time":1701245639,"time_ms":1701245639232,"channel":"futures.order_book_update","event":"update","result":{"U":53095233792,"a":[{"p":"38163.1","s":0}],"b":[],"s":"BTC_USDT","t":1701245639203,"u":53095233793}}
{"time":1701245639,"time_ms":1701245639293,"channel":"futures.order_book_update","event":"update","result":{"U":53095233794,"a":[{"p":"38154.5","s":0},{"p":"38153.2","s":0},{"p":"38158.5","s":0},{"p":"38163.1","s":0},{"p":"38170.8","s":0}],"b":[{"p":"38140.4","s":2908},{"p":"38139.8","s":131},{"p":"38140.8","s":0}],"s":"BTC_USDT","t":1701245639273,"u":53095233804}}
{"time":1701245639,"time_ms":1701245639314,"channel":"futures.order_book_update","event":"update","result":{"U":53095233805,"a":[{"p":"38170.8","s":0}],"b":[],"s":"BTC_USDT","t":1701245639302,"u":53095233807}}
{"time":1701245639,"time_ms":1701245639393,"channel":"futures.order_book_update","event":"update","result":{"U":53095233808,"a":[{"p":"38145.6","s":20418}],"b":[],"s":"BTC_USDT","t":1701245639381,"u":53095233809}}
{"time":1701245639,"time_ms":1701245639412,"channel":"futures.order_book_update","event":"update","result":{"U":53095233810,"a":[{"p":"38163.2","s":0}],"b":[],"s":"BTC_USDT","t":1701245639391,"u":53095233811}}
{"time":1701245639,"time_ms":1701245639454,"channel":"futures.order_book_update","event":"update","result":{"U":53095233812,"a":[{"p":"38145.6","s":19418}],"b":[],"s":"BTC_USDT","t":1701245639446,"u":53095233813}}
{"time":1701245639,"time_ms":1701245639513,"channel":"futures.order_book_update","event":"update","result":{"U":53095233814,"a":[{"p":"38158.6","s":0},{"p":"38154","s":0}],"b":[],"s":"BTC_USDT","t":1701245639496,"u":53095233817}}
{"time":1701245639,"time_ms":1701245639575,"channel":"futures.order_book_update","event":"update","result":{"U":53095233818,"a":[{"p":"38153.2","s":0}],"b":[],"s":"BTC_USDT","t":1701245639551,"u":53095233820}}
{"time":1701245639,"time_ms":1701245639995,"channel":"futures.order_book_update","event":"update","result":{"U":53095233821,"a":[{"p":"38158.9","s":0},{"p":"38154.3","s":0},{"p":"38155.5","s":0}],"b":[{"p":"38140.1","s":2175},{"p":"38139.8","s":0},{"p":"38139.2","s":0}],"s":"BTC_USDT","t":1701245639966,"u":53095233829}}
{"time":1701245640,"time_ms":1701245640012,"channel":"futures.order_book_update","event":"update","result":{"U":53095233830,"a":[{"p":"38159.5","s":0},{"p":"38167","s":0},{"p":"38155.5","s":0}],"b":[],"s":"BTC_USDT","t":1701245639993,"u":53095233832}}
{"time":1701245640,"time_ms":1701245640032,"channel":"futures.order_book_update","event":"update","result":{"U":53095233833,"a":[{"p":"38155.7","s":0},{"p":"38170.9","s":0},{"p":"38156","s":0}],"b":[{"p":"38140.4","s":733},{"p":"38140","s":2171},{"p":"38133.1","s":0},{"p":"38135.4","s":0},{"p":"38139.8","s":0},{"p":"38141.5","s":2299},{"p":"38140.8","s":2174},{"p":"38139.9","s":0},{"p":"38140.7","s":0},{"p":"38136","s":0},{"p":"38128.5","s":0}],"s":"BTC_USDT","t":1701245640020,"u":53095233849}}
{"time":1701245640,"time_ms":1701245640054,"channel":"futures.order_book_update","event":"update","result":{"U":53095233850,"a":[{"p":"38156.2","s":0}],"b":[{"p":"38140.8","s":2907},{"p":"38139.9","s":419},{"p":"38140.4","s":0}],"s":"BTC_USDT","t":1701245640027,"u":53095233853}}
{"time":1701245640,"time_ms":1701245640092,"channel":"futures.order_book_update","event":"update","result":{"U":53095233854,"a":[{"p":"38154.7","s":0},{"p":"38159.3","s":0},{"p":"38156.3","s":0},{"p":"38155.8","s":0}],"b":[{"p":"38139.8","s":131},{"p":"38140.8","s":5299},{"p":"38141.5","s":0},{"p":"38135.9","s":0}],"s":"BTC_USDT","t":1701245640086,"u":53095233868}}
{"time":1701245640,"time_ms":1701245640114,"channel":"futures.order_book_update","event":"update","result":{"U":53095233869,"a":[{"p":"38155.3","s":0},{"p":"38159.1","s":0},{"p":"38171.3","s":0},{"p":"38154.5","s":0},{"p":"38155.8","s":0},{"p":"38156.2","s":0}],"b":[{"p":"38140.1","s":0},{"p":"38133.5","s":0},{"p":"38139.7","s":0},{"p":"38140.4","s":733},{"p":"38139.8","s":2306},{"p":"38140.5","s":2175},{"p":"38140.8","s":0}],"s":"BTC_USDT","t":1701245640103,"u":53095233890}}
{"time":1701245640,"time_ms":1701245640134,"channel":"futures.order_book_update","event":"update","result":{"U":53095233891,"a":[{"p":"38154.3","s":0},{"p":"38158.7","s":0},{"p":"38155.2","s":0},{"p":"38153.5","s":0}],"b":[{"p":"38140.1","s":2175},{"p":"38140.4","s":2320},{"p":"38140.5","s":0},{"p":"38135.5","s":0},{"p":"38139.7","s":0},{"p":"38140","s":11083},{"p":"38139.8","s":131}],"s":"BTC_USDT","t":1701245640116,"u":53095233915}}
{"time":1701245640,"time_ms":1701245640152,"channel":"futures.order_book_update","event":"update","result":{"U":53095233916,"a":[{"p":"38154.9","s":0},{"p":"38154.7","s":0},{"p":"38158","s":0}],"b":[{"p":"38140.2","s":733},{"p":"38139.8","s":0}],"s":"BTC_USDT","t":1701245640144,"u":53095233923}}
{"time":1701245640,"time_ms":1701245640173,"channel":"futures.order_book_update","event":"update","result":{"U":53095233924,"a":[{"p":"38163.1","s":0},{"p":"38153.9","s":0}],"b":[{"p":"38138.6","s":0}],"s":"BTC_USDT","t":1701245640148,"u":53095233929}}
{"time":1701245640,"time_ms":1701245640212,"channel":"futures.order_book_update","event":"update","result":{"U":53095233930,"a":[{"p":"38170.8","s":0},{"p":"38154.8","s":0}],"b":[{"p":"38139.7","s":0}],"s":"BTC_USDT","t":1701245640196,"u":53095233935}}
{"time":1701245640,"time_ms":1701245640314,"channel":"futures.order_book_update","event":"update","result":{"U":53095233936,"a":[{"p":"38163.1","s":0}],"b":[],"s":"BTC_USDT","t":1701245640298,"u":53095233937}}
{"time":1701245640,"time_ms":1701245640432,"channel":"futures.order_book_update","event":"update","result":{"U":53095233938,"a":[{"p":"38170.7","s":0}],"b":[],"s":"BTC_USDT","t":1701245640423,"u":53095233941}}
{"time":1701245640,"time_ms":1701245640451,"channel":"futures.order_book_update","event":"update","result":{"U":53095233942,"a":[{"p":"38145.6","s":19918},{"p":"38163.1","s":0}],"b":[],"s":"BTC_USDT","t":1701245640433,"u":53095233944}}
{"time":1701245640,"time_ms":1701245640472,"channel":"futures.order_book_update","event":"update","result":{"U":53095233945,"a":[{"p":"38170.8","s":0}],"b":[],"s":"BTC_USDT","t":1701245640462,"u":53095233947}}
{"time":1701245640,"time_ms":1701245640496,"channel":"futures.order_book_update","event":"update","result":{"U":53095233948,"a":[{"p":"38159","s":0},{"p":"38155","s":0}],"b":[{"p":"38145.5","s":144132}],"s":"BTC_USDT","t":1701245640484,"u":53095233953}}
{"time":1701245640,"time_ms":1701245640512,"channel":"futures.order_book_update","event":"update","result":{"U":53095233954,"a":[{"p":"38145.6","s":38918},{"p":"38164","s":0},{"p":"38154.9","s":0}],"b":[{"p":"38139.9","s":419},{"p":"38143","s":200},{"p":"38144","s":0}],"s":"BTC_USDT","t":1701245640501,"u":53095233963}}
{"time":1701245640,"time_ms":1701245640533,"channel":"futures.order_book_update","event":"update","result":{"U":53095233964,"a":[{"p":"38145.6","s":19918},{"p":"38179.5","s":0},{"p":"38159","s":0},{"p":"38164","s":0}],"b":[{"p":"38144","s":200},{"p":"38143","s":0},{"p":"38118.6","s":0},{"p":"38139.9","s":419},{"p":"38109.7","s":0}],"s":"BTC_USDT","t":1701245640520,"u":53095233980}}
{"time":1701245640,"time_ms":1701245640572,"channel":"futures.order_book_update","event":"update","result":{"U":53095233981,"a":[{"p":"38148.9","s":0},{"p":"38190.3","s":0},{"p":"38164.1","s":0},{"p":"38174.3","s":0},{"p":"38152.2","s":4581}],"b":[{"p":"38120.8","s":0},{"p":"38004","s":0},{"p":"38117.9","s":0},{"p":"38095.1","s":0},{"p":"38072.2","s":0}],"s":"BTC_USDT","t":1701245640558,"u":53095233993}}
{"time":1701245640,"time_ms":1701245640591,"channel":"futures.order_book_update","event":"update","result":{"U":53095233994,"a":[{"p":"38170.8","s":0}],"b":[],"s":"BTC_USDT","t":1701245640579,"u":53095233996}}
{"time":1701245640,"time_ms":1701245640633,"channel":"futures.order_book_update","event":"update","result":{"U":53095233997,"a":[{"p":"38170.8","s":0}],"b":[{"p":"38121.8","s":0}],"s":"BTC_USDT","t":1701245640626,"u":53095234008}}
{"time":1701245640,"time_ms":1701245640682,"channel":"futures.order_book_update","event":"update","result":{"U":53095234009,"a":[{"p":"38145.6","s":19418},{"p":"38153.2","s":0}],"b":[{"p":"38140","s":11085},{"p":"38140.6","s":12171}],"s":"BTC_USDT","t":1701245640662,"u":53095234021}}
{"time":1701245640,"time_ms":1701245640693,"channel":"futures.order_book_update","event":"update","result":{"U":53095234022,"a":[{"p":"38155.8","s":0},{"p":"38154.2","s":0},{"p":"38145.6","s":20418},{"p":"38163.2","s":0},{"p":"38158.5","s":0},{"p":"38155.1","s":0},{"p":"38155.4","s":0}],"b":[{"p":"38141.8","s":0},{"p":"38140.7","s":4349},{"p":"38139.8","s":131},{"p":"38140.2","s":0},{"p":"38139.2","s":0},{"p":"38141.7","s":94},{"p":"38139.7","s":0},{"p":"38140.1","s":0},{"p":"38135.2","s":0}],"s":"BTC_USDT","t":1701245640685,"u":53095234049}}
{"time":1701245640,"time_ms":1701245640712,"channel":"futures.order_book_update","event":"update","result":{"U":53095234050,"a":[],"b":[{"p":"38140.7","s":5082}],"s":"BTC_USDT","t":1701245640685,"u":53095234050}}
{"time":1701245640,"time_ms":1701245640733,"channel":"futures.order_book_update","event":"update","result":{"U":53095234051,"a":[{"p":"38155.5","s":0},{"p":"38159.5","s":0}],"b":[{"p":"38140.7","s":2907},{"p":"38140.1","s":2175},{"p":"38139.8","s":0}],"s":"BTC_USDT","t":1701245640709,"u":53095234056}}
{"time":1701245640,"time_ms":1701245640792,"channel":"futures.order_book_update","event":"update","result":{"U":53095234057,"a":[{"p":"38156","s":0},{"p":"38160","s":0}],"b":[{"p":"38136.1","s":0},{"p":"38056.8","s":0},{"p":"38078.7","s":0}],"s":"BTC_USDT","t":1701245640784,"u":53095234064}}
{"time":1701245640,"time_ms":1701245640812,"channel":"futures.order_book_update","event":"update","result":{"U":53095234065,"a":[{"p":"38145.6","s":19418}],"b":[],"s":"BTC_USDT","t":1701245640795,"u":53095234066}}
{"time":1701245640,"time_ms":1701245640833,"channel":"futures.order_book_update","event":"update","result":{"U":53095234067,"a":[{"p":"38159.5","s":0},{"p":"38155.5","s":0}],"b":[],"s":"BTC_USDT","t":1701245640815,"u":53095234072}}
{"time":1701245641,"time_ms":1701245641033,"channel":"futures.order_book_update","event":"update","result":{"U":53095234073,"a":[{"p":"38156.8","s":0},{"p":"38156.1","s":0},{"p":"38171","s":0},{"p":"38160","s":0},{"p":"38155.6","s":0}],"b":[{"p":"38140.8","s":5318},{"p":"38140.7","s":0},{"p":"38135.4","s":0},{"p":"38139.9","s":419},{"p":"38140.6","s":12165},{"p":"38140","s":11083},{"p":"38139.8","s":131},{"p":"38140.4","s":0},{"p":"38133.2","s":0}],"s":"BTC_USDT","t":1701245641024,"u":53095234100}}
{"time":1701245641,"time_ms":1701245641052,"channel":"futures.order_book_update","event":"update","result":{"U":53095234101,"a":[],"b":[{"p":"38139.9","s":421},{"p":"38140.6","s":12171}],"s":"BTC_USDT","t":1701245641038,"u":53095234104}}
{"time":1701245641,"time_ms":1701245641117,"channel":"futures.order_book_update","event":"update","result":{"U":53095234105,"a":[{"p":"38156","s":0},{"p":"38160","s":0}],"b":[],"s":"BTC_USDT","t":1701245641093,"u":53095234110}}
{"time":1701245641,"time_ms":1701245641133,"channel":"futures.order_book_update","event":"update","result":{"U":53095234111,"a":[{"p":"38156.2","s":0},{"p":"38155.6","s":0},{"p":"38154.6","s":0}],"b":[{"p":"38141.5","s":2300},{"p":"38140.8","s":2907},{"p":"38139.8","s":0}],"s":"BTC_USDT","t":1701245641116,"u":53095234118}}
{"time":1701245641,"time_ms":1701245641176,"channel":"futures.order_book_update","event":"update","result":{"U":53095234119,"a":[],"b":[{"p":"38141.5","s":4474},{"p":"38140.8","s":733}],"s":"BTC_USDT","t":1701245641143,"u":53095234120}}
{"time":1701245641,"time_ms":1701245641191,"channel":"futures.order_book_update","event":"update","result":{"U":53095234121,"a":[{"p":"38154.8","s":0}],"b":[],"s":"BTC_USDT","t":1701245641179,"u":53095234122}}
{"time":1701245641,"time_ms":1701245641211,"channel":"futures.order_book_update","event":"update","result":{"U":53095234123,"a":[{"p":"38159.2","s":0}],"b":[{"p":"38140.9","s":0},{"p":"38141.5","s":4474},{"p":"38140.7","s":733},{"p":"38140.8","s":0},{"p":"38139.9","s":421}],"s":"BTC_USDT","t":1701245641191,"u":53095234130}}
{"time":1701245641,"time_ms":1701245641232,"channel":"futures.order_book_update","event":"update","result":{"U":53095234131,"a":[{"p":"38156.3","s":0}],"b":[],"s":"BTC_USDT","t":1701245641220,"u":53095234131}}
{"time":1701245641,"time_ms":1701245641272,"channel":"futures.order_book_update","event":"update","result":{"U":53095234132,"a":[{"p":"38159.4","s":0},{"p":"38156.2","s":0},{"p":"38154.7","s":0},{"p":"38155.8","s":0},{"p":"38171.3","s":0}],"b":[{"p":"38141.7","s":827},{"p":"38140.7","s":2175},{"p":"38139.8","s":131},{"p":"38140.1","s":0},{"p":"38136.1","s":0}],"s":"BTC_USDT","t":1701245641256,"u":53095234148}}
{"time":1701245641,"time_ms":1701245641311,"channel":"futures.order_book_update","event":"update","result":{"U":53095234149,"a":[],"b":[{"p":"38114.6","s":0}],"s":"BTC_USDT","t":1701245641302,"u":53095234149}}
{"time":1701245641,"time_ms":1701245641332,"channel":"futures.order_book_update","event":"update","result":{"U":53095234150,"a":[{"p":"38155.5","s":0}],"b":[{"p":"38140.7","s":0},{"p":"38136.5","s":0},{"p":"38141.7","s":94},{"p":"38140.8","s":2907},{"p":"38141.5","s":2300},{"p":"38140.1","s":2175},{"p":"38139.8","s":0}],"s":"BTC_USDT","t":1701245641307,"u":53095234159}}
{"time":1701245641,"time_ms":1701245641352,"channel":"futures.order_book_update","event":"update","result":{"U":53095234160,"a":[{"p":"38163.5","s":0}],"b":[],"s":"BTC_USDT","t":1701245641344,"u":53095234160}}
{"time":1701245641,"time_ms":1701245641495,"channel":"futures.order_book_update","event":"update","result":{"U":53095234161,"a":[{"p":"38153.3","s":0}],"b":[],"s":"BTC_USDT","t":1701245641478,"u":53095234161}}
{"time":1701245641,"time_ms":1701245641632,"channel":"futures.order_book_update","event":"update","result":{"U":53095234162,"a":[{"p":"38163.5","s":0}],"b":[],"s":"BTC_USDT","t":1701245641608,"u":53095234164}}
{"time":1701245641,"time_ms":1701245641671,"channel":"futures.order_book_update","event":"update","result":{"U":53095234165,"a":[{"p":"38163.5","s":0}],"b":[],"s":"BTC_USDT","t":1701245641662,"u":53095234165}}
{"time":1701245641,"time_ms":1701245641753,"channel":"futures.order_book_update","event":"update","result":{"U":53095234166,"a":[],"b":[{"p":"38139.9","s":419},{"p":"38140.6","s":12165}],"s":"BTC_USDT","t":1701245641734,"u":53095234169}}
{"time":1701245641,"time_ms":1701245641773,"channel":"futures.order_book_update","event":"update","result":{"U":53095234170,"a":[],"b":[{"p":"38139.9","s":421},{"p":"38140.6","s":12171}],"s":"BTC_USDT","t":1701245641764,"u":53095234173}}
{"time":1701245641,"time_ms":1701245641872,"channel":"futures.order_book_update","event":"update","result":{"U":53095234174,"a":[],"b":[{"p":"38143.9","s":406},{"p":"38139.9","s":0}],"s":"BTC_USDT","t":1701245641862,"u":53095234174}}
{"time":1701245641,"time_ms":1701245641900,"channel":"futures.order_book_update","event":"update","result":{"U":53095234175,"a":[{"p":"38145.6","s":18468}],"b":[],"s":"BTC_USDT","t":1701245641893,"u":53095234177}}
{"time":1701245641,"time_ms":1701245641973,"channel":"futures.order_book_update","event":"update","result":{"U":53095234178,"a":[{"p":"38154.7","s":0}],"b":[{"p":"38141.8","s":733},{"p":"38140.9","s":2175},{"p":"38140.8","s":0},{"p":"38140.1","s":0},{"p":"38139.9","s":0},{"p":"38136.1","s":0},{"p":"38141.7","s":2268}],"s":"BTC_USDT","t":1701245641957,"u":53095234187}}
{"time":1701245641,"time_ms":1701245641992,"channel":"futures.order_book_update","event":"update","result":{"U":53095234188,"a":[{"p":"38163.6","s":0}],"b":[],"s":"BTC_USDT","t":1701245641981,"u":53095234188}}
{"time":1701245642,"time_ms":1701245642033,"channel":"futures.order_book_update","event":"update","result":{"U":53095234189,"a":[{"p":"38156.8","s":0},{"p":"38150.4","s":7228},{"p":"38159.9","s":0},{"p":"38156.4","s":0}],"b":[{"p":"38141.8","s":3064},{"p":"38140.7","s":2175},{"p":"38141.7","s":94},{"p":"38141.5","s":0},{"p":"38133.5","s":0},{"p":"38141.9","s":2174},{"p":"38140.9","s":0},{"p":"38140","s":11083},{"p":"38139.9","s":0}],"s":"BTC_USDT","t":1701245642021,"u":53095234203}}
{"time":1701245642,"time_ms":1701245642072,"channel":"futures.order_book_update","event":"update","result":{"U":53095234204,"a":[{"p":"38155.6","s":0}],"b":[],"s":"BTC_USDT","t":1701245642062,"u":53095234207}}
{"time":1701245642,"time_ms":1701245642112,"channel":"futures.order_book_update","event":"update","result":{"U":53095234208,"a":[{"p":"38165.7","s":0},{"p":"38155.5","s":0},{"p":"38160","s":0},{"p":"38156.7","s":0},{"p":"38156.8","s":0}],"b":[{"p":"38141.8","s":0},{"p":"38136.9","s":0},{"p":"38134","s":0},{"p":"38141.7","s":94},{"p":"38140.8","s":5318},{"p":"38140.1","s":2175},{"p":"38141.9","s":0},{"p":"38139.8","s":0},{"p":"38139.9","s":421},{"p":"38140.7","s":0},{"p":"38140","s":11083}],"s":"BTC_USDT","t":1701245642097,"u":53095234232}}
{"time":1701245642,"time_ms":1701245642132,"channel":"futures.order_book_update","event":"update","result":{"U":53095234233,"a":[],"b":[{"p":"38140.6","s":12165},{"p":"38141.5","s":2300},{"p":"38139.9","s":0},{"p":"38140.8","s":2907}],"s":"BTC_USDT","t":1701245642106,"u":53095234238}}
{"time":1701245642,"time_ms":1701245642171,"channel":"futures.order_book_update","event":"update","result":{"U":53095234239,"a":[{"p":"38154.5","s":0},{"p":"38156.2","s":0}],"b":[{"p":"38141.5","s":2300},{"p":"38140.8","s":2907}],"s":"BTC_USDT","t":1701245642150,"u":53095234248}}
{"time":1701245642,"time_ms":1701245642190,"channel":"futures.order_book_update","event":"update","result":{"U":53095234249,"a":[],"b":[{"p":"38140.5","s":6},{"p":"38140","s":0}],"s":"BTC_USDT","t":1701245642180,"u":53095234251}}
{"time":1701245642,"time_ms":1701245642211,"channel":"futures.order_book_update","event":"update","result":{"U":53095234252,"a":[{"p":"38156.2","s":0}],"b":[{"p":"38141.5","s":4474},{"p":"38140.8","s":733}],"s":"BTC_USDT","t":1701245642203,"u":53095234256}}
{"time":1701245642,"time_ms":1701245642231,"channel":"futures.order_book_update","event":"update","result":{"U":53095234257,"a":[{"p":"38154.7","s":0},{"p":"38156","s":0},{"p":"38159.3","s":0}],"b":[{"p":"38140.8","s":0},{"p":"38140.1","s":0},{"p":"38140","s":0},{"p":"38139.9","s":0},{"p":"38136.1","s":0},{"p":"38140.9","s":2175},{"p":"38141.8","s":733}],"s":"BTC_USDT","t":1701245642208,"u":53095234268}}
{"time":1701245642,"time_ms":1701245642293,"channel":"futures.order_book_update","event":"update","result":{"U":53095234269,"a":[{"p":"38145.6","s":18918}],"b":[],"s":"BTC_USDT","t":1701245642274,"u":53095234270}}
{"time":1701245642,"time_ms":1701245642332,"channel":"futures.order_book_update","event":"update","result":{"U":53095234271,"a":[{"p":"38156.8","s":0}],"b":[{"p":"38140","s":11083},{"p":"38140.9","s":0},{"p":"38136.9","s":0}],"s":"BTC_USDT","t":1701245642325,"u":53095234275}}
{"time":1701245642,"time_ms":1701245642353,"channel":"futures.order_book_update","event":"update","result":{"U":53095234276,"a":[{"p":"38155.5","s":0},{"p":"38156.8","s":0},{"p":"38160","s":0}],"b":[{"p":"38141.5","s":0},{"p":"38140","s":11083},{"p":"38136.5","s":0},{"p":"38141","s":5258},{"p":"38140.4","s":2175},{"p":"38141.8","s":0}],"s":"BTC_USDT","t":1701245642337,"u":53095234290}}
{"time":1701245642,"time_ms":1701245642612,"channel":"futures.order_book_update","event":"update","result":{"U":53095234291,"a":[],"b":[{"p":"38139.9","s":419},{"p":"38140.5","s":0}],"s":"BTC_USDT","t":1701245642588,"u":53095234299}}
{"time":1701245642,"time_ms":1701245642653,"channel":"futures.order_book_update","event":"update","result":{"U":53095234300,"a":[{"p":"38153.2","s":0}],"b":[{"p":"38140.5","s":6},{"p":"38139.9","s":0}],"s":"BTC_USDT","t":1701245642628,"u":53095234304}}
{"time":1701245642,"time_ms":1701245642672,"channel":"futures.order_book_update","event":"update","result":{"U":53095234305,"a":[{"p":"38159.1","s":0}],"b":[],"s":"BTC_USDT","t":1701245642649,"u":53095234307}}
{"time":1701245642,"time_ms":1701245642793,"channel":"futures.order_book_update","event":"update","result":{"U":53095234308,"a":[],"b":[{"p":"38086.9","s":0}],"s":"BTC_USDT","t":1701245642773,"u":53095234308}}
{"time":1701245642,"time_ms":1701245642831,"channel":"futures.order_book_update","event":"update","result":{"U":53095234309,"a":[{"p":"38153.2","s":0}],"b":[{"p":"38131.2","s":0}],"s":"BTC_USDT","t":1701245642819,"u":53095234312}}
{"time":1701245642,"time_ms":1701245642914,"channel":"futures.order_book_update","event":"update","result":{"U":53095234313,"a":[],"b":[{"p":"38140.2","s":2620},{"p":"38140","s":0},{"p":"38139.5","s":0}],"s":"BTC_USDT","t":1701245642894,"u":53095234317}}
{"time":1701245642,"time_ms":1701245642994,"channel":"futures.order_book_update","event":"update","result":{"U":53095234318,"a":[],"b":[{"p":"38140","s":11083},{"p":"38140.5","s":0},{"p":"38139.9","s":0}],"s":"BTC_USDT","t":1701245642971,"u":53095234321}}
{"time":1701245643,"time_ms":1701245643011,"channel":"futures.order_book_update","event":"update","result":{"U":53095234322,"a":[],"b":[{"p":"38140","s":0},{"p":"38140.5","s":6}],"s":"BTC_USDT","t":1701245642994,"u":53095234325}}
{"time":1701245643,"time_ms":1701245643043,"channel":"futures.order_book_update","event":"update","result":{"U":53095234326,"a":[{"p":"38171.8","s":0},{"p":"38155.9","s":0},{"p":"38156.2","s":0}],"b":[{"p":"38141.5","s":733},{"p":"38141","s":2174},{"p":"38141.7","s":2387},{"p":"38140.2","s":0},{"p":"38133.5","s":0},{"p":"38136.1","s":0}],"s":"BTC_USDT","t":1701245643020,"u":53095234339}}
{"time":1701245643,"time_ms":1701245643052,"channel":"futures.order_book_update","event":"update","result":{"U":53095234340,"a":[{"p":"38156.8","s":0},{"p":"38156.6","s":0}],"b":[{"p":"38141","s":0},{"p":"38141.5","s":733},{"p":"38141.7","s":2268},{"p":"38140.2","s":2620}],"s":"BTC_USDT","t":1701245643038,"u":53095234349}}
{"time":1701245643,"time_ms":1701245643071,"channel":"futures.order_book_update","event":"update","result":{"U":53095234350,"a":[{"p":"38155","s":0},{"p":"38159","s":0}],"b":[{"p":"38141.7","s":4563}],"s":"BTC_USDT","t":1701245643058,"u":53095234355}}
{"time":1701245643,"time_ms":1701245643093,"channel":"futures.order_book_update","event":"update","result":{"U":53095234356,"a":[{"p":"38161.6","s":0}],"b":[],"s":"BTC_USDT","t":1701245643078,"u":53095234356}}
{"time":1701245643,"time_ms":1701245643115,"channel":"futures.order_book_update","event":"update","result":{"U":53095234357,"a":[{"p":"38156.5","s":0},{"p":"38159.6","s":0},{"p":"38154.9","s":0}],"b":[],"s":"BTC_USDT","t":1701245643097,"u":53095234362}}
{"time":1701245643,"time_ms":1701245643233,"channel":"futures.order_book_update","event":"update","result":{"U":53095234363,"a":[{"p":"38159.5","s":0},{"p":"38155.5","s":0}],"b":[],"s":"BTC_USDT","t":1701245643206,"u":53095234366}}
{"time":1701245643,"time_ms":1701245643253,"channel":"futures.order_book_update","event":"update","result":{"U":53095234367,"a":[{"p":"38156.3","s":0},{"p":"38156.4","s":0},{"p":"38156.7","s":0}],"b":[{"p":"38056.4","s":0},{"p":"38140.4","s":2175},{"p":"38140.2","s":2620},{"p":"38140","s":0},{"p":"38140.7","s":0}],"s":"BTC_USDT","t":1701245643238,"u":53095234377}}
{"time":1701245643,"time_ms":1701245643291,"channel":"futures.order_book_update","event":"update","result":{"U":53095234378,"a":[{"p":"38159.4","s":0},{"p":"38154.7","s":0},{"p":"38156.3","s":0}],"b":[{"p":"38141.5","s":0},{"p":"38140","s":0},{"p":"38141.8","s":733}],"s":"BTC_USDT","t":1701245643284,"u":53095234385}}
{"time":1701245643,"time_ms":1701245643312,"channel":"futures.order_book_update","event":"update","result":{"U":53095234386,"a":[{"p":"38154.8","s":0},{"p":"38155.5","s":0},{"p":"38155.3","s":0}],"b":[{"p":"38140","s":0},{"p":"38140.7","s":2175},{"p":"38140.4","s":0}],"s":"BTC_USDT","t":1701245643300,"u":53095234393}}
{"time":1701245643,"time_ms":1701245643353,"channel":"futures.order_book_update","event":"update","result":{"U":53095234394,"a":[],"b":[{"p":"38134.8","s":0}],"s":"BTC_USDT","t":1701245643344,"u":53095234395}}
{"time":1701245643,"time_ms":1701245643413,"channel":"futures.order_book_update","event":"update","result":{"U":53095234396,"a":[{"p":"38153.2","s":0}],"b":[],"s":"BTC_USDT","t":1701245643404,"u":53095234398}}
{"time":1701245643,"time_ms":1701245643453,"channel":"futures.order_book_update","event":"update","result":{"U":53095234399,"a":[],"b":[{"p":"38078.7","s":0},{"p":"38056.8","s":0}],"s":"BTC_USDT","t":1701245643436,"u":53095234400}}
{"time":1701245643,"time_ms":1701245643497,"channel":"futures.order_book_update","event":"update","result":{"U":53095234401,"a":[{"p":"38153.2","s":0},{"p":"38159.9","s":0},{"p":"38155.4","s":0}],"b":[{"p":"38140.8","s":733},{"p":"38140.4","s":2175},{"p":"38141.8","s":0},{"p":"38140.7","s":0},{"p":"38140","s":0},{"p":"38140.2","s":2620}],"s":"BTC_USDT","t":1701245643487,"u":53095234409}}
{"time":1701245643,"time_ms":1701245643513,"channel":"futures.order_book_update","event":"update","result":{"U":53095234410,"a":[{"p":"38156.7","s":0},{"p":"38156.8","s":0}],"b":[{"p":"38140.8","s":5291},{"p":"38141.7","s":94},{"p":"38134","s":0},{"p":"38136.8","s":0}],"s":"BTC_USDT","t":1701245643500,"u":53095234423}}
{"time":1701245643,"time_ms":1701245643552,"channel":"futures.order_book_update","event":"update","result":{"U":53095234424,"a":[],"b":[{"p":"38140.5","s":2},{"p":"38139.9","s":0}],"s":"BTC_USDT","t":1701245643542,"u":53095234427}}
{"time":1701245643,"time_ms":1701245643574,"channel":"futures.order_book_update","event":"update","result":{"U":53095234428,"a":[{"p":"38145.6","s":19918}],"b":[{"p":"38140.5","s":6},{"p":"38140","s":0}],"s":"BTC_USDT","t":1701245643564,"u":53095234435}}
{"time":1701245643,"time_ms":1701245643593,"channel":"futures.order_book_update","event":"update","result":{"U":53095234436,"a":[{"p":"38145.6","s":18918},{"p":"38159.4","s":0}],"b":[{"p":"38140.5","s":0},{"p":"38139.9","s":419},{"p":"38140","s":11083},{"p":"38140.4","s":0}],"s":"BTC_USDT","t":1701245643584,"u":53095234451}}
{"time":1701245643,"time_ms":1701245643672,"channel":"futures.order_book_update","event":"update","result":{"U":53095234452,"a":[{"p":"38145.6","s":19418}],"b":[],"s":"BTC_USDT","t":1701245643647,"u":53095234453}}
{"time":1701245643,"time_ms":1701245643712,"channel":"futures.order_book_update","event":"update","result":{"U":53095234454,"a":[{"p":"38158.6","s":0}],"b":[],"s":"BTC_USDT","t":1701245643698,"u":53095234455}}
{"time":1701245643,"time_ms":1701245643733,"channel":"futures.order_book_update","event":"update","result":{"U":53095234456,"a":[{"p":"38160.9","s":0}],"b":[],"s":"BTC_USDT","t":1701245643716,"u":53095234457}}
{"time":1701245643,"time_ms":1701245643874,"channel":"futures.order_book_update","event":"update","result":{"U":53095234458,"a":[{"p":"38150.4","s":10866},{"p":"38153.2","s":0}],"b":[],"s":"BTC_USDT","t":1701245643857,"u":53095234464}}
{"time":1701245643,"time_ms":1701245643933,"channel":"futures.order_book_update","event":"update","result":{"U":53095234465,"a":[{"p":"38163.8","s":0}],"b":[],"s":"BTC_USDT","t":1701245643901,"u":53095234466}}
{"time":1701245643,"time_ms":1701245643972,"channel":"futures.order_book_update","event":"update","result":{"U":53095234467,"a":[{"p":"38153.2","s":0}],"b":[{"p":"38139.9","s":0},{"p":"38140.5","s":6}],"s":"BTC_USDT","t":1701245643954,"u":53095234471}}
{"time":1701245643,"time_ms":1701245643994,"channel":"futures.order_book_update","event":"update","result":{"U":53095234472,"a":[{"p":"38159.1","s":0},{"p":"38155.9","s":0}],"b":[{"p":"38140.8","s":3117},{"p":"38141.7","s":2268}],"s":"BTC_USDT","t":1701245643981,"u":53095234480}}
{"time":1701245644,"time_ms":1701245644014,"channel":"futures.order_book_update","event":"update","result":{"U":53095234481,"a":[{"p":"38159.6","s":0},{"p":"38155.9","s":0},{"p":"38171.5","s":0}],"b":[{"p":"38140.8","s":2384},{"p":"38141.5","s":733},{"p":"38140","s":0},{"p":"38133.5","s":0}],"s":"BTC_USDT","t":1701245644004,"u":53095234489}}
{"time":1701245644,"time_ms":1701245644034,"channel":"futures.order_book_update","event":"update","result":{"U":53095234490,"a":[{"p":"38156.3","s":0}],"b":[{"p":"38140.4","s":2175},{"p":"38140.2","s":0},{"p":"38136.1","s":0},{"p":"38141.5","s":2318},{"p":"38140.9","s":733},{"p":"38140.8","s":0},{"p":"38134","s":0},{"p":"38139.8","s":0},{"p":"38140","s":0}],"s":"BTC_USDT","t":1701245644019,"u":53095234503}}
{"time":1701245644,"time_ms":1701245644051,"channel":"futures.order_book_update","event":"update","result":{"U":53095234504,"a":[],"b":[{"p":"38140.2","s":0},{"p":"38141.5","s":2318},{"p":"38140.9","s":733}],"s":"BTC_USDT","t":1701245644040,"u":53095234507}}
{"time":1701245644,"time_ms":1701245644071,"channel":"futures.order_book_update","event":"update","result":{"U":53095234508,"a":[],"b":[{"p":"38140.2","s":2620},{"p":"38141.5","s":3051},{"p":"38140.9","s":0}],"s":"BTC_USDT","t":1701245644055,"u":53095234509}}
{"time":1701245644,"time_ms":1701245644092,"channel":"futures.order_book_update","event":"update","result":{"U":53095234510,"a":[],"b":[{"p":"38141.5","s":2318},{"p":"38140.9","s":733},{"p":"38140.2","s":0}],"s":"BTC_USDT","t":1701245644071,"u":53095234511}}
{"time":1701245644,"time_ms":1701245644196,"channel":"futures.order_book_update","event":"update","result":{"U":53095234512,"a":[],"b":[{"p":"38136.5","s":0}],"s":"BTC_USDT","t":1701245644181,"u":53095234513}}
{"time":1701245644,"time_ms":1701245644252,"channel":"futures.order_book_update","event":"update","result":{"U":53095234514,"a":[{"p":"38154.6","s":0},{"p":"38156.2","s":0},{"p":"38156.8","s":0}],"b":[{"p":"38140.2","s":0},{"p":"38141.7","s":94},{"p":"38141","s":2174},{"p":"38140.7","s":2390},{"p":"38141.5","s":0},{"p":"38140.3","s":0}],"s":"BTC_USDT","t":1701245644244,"u":53095234523}}
{"time":1701245644,"time_ms":1701245644273,"channel":"futures.order_book_update","event":"update","result":{"U":53095234524,"a":[{"p":"38154.5","s":0},{"p":"38155.9","s":0},{"p":"38171.4","s":0},{"p":"38159.4","s":0},{"p":"38155.8","s":0}],"b":[{"p":"38140.5","s":0},{"p":"38140.4","s":0},{"p":"38140.1","s":0},{"p":"38136.1","s":0},{"p":"38139.8","s":0},{"p":"38140.3","s":1315},{"p":"38140.2","s":2620}],"s":"BTC_USDT","t":1701245644264,"u":53095234539}}
{"time":1701245644,"time_ms":1701245644294,"channel":"futures.order_book_update","event":"update","result":{"U":53095234540,"a":[{"p":"38158.5","s":0},{"p":"38159","s":0},{"p":"38171.1","s":0},{"p":"38163.2","s":0},{"p":"38155","s":0},{"p":"38145.6","s":20918},{"p":"38155.9","s":0},{"p":"38154.2","s":0}],"b":[{"p":"38140.5","s":4},{"p":"38140.4","s":733},{"p":"38140.9","s":0},{"p":"38141","s":0},{"p":"38135.4","s":0},{"p":"38140.2","s":2620},{"p":"38136.1","s":0},{"p":"38139.7","s":0},{"p":"38140.1","s":0},{"p":"38139.8","s":0}],"s":"BTC_USDT","t":1701245644285,"u":53095234575}}
{"time":1701245644,"time_ms":1701245644312,"channel":"futures.order_book_update","event":"update","result":{"U":53095234576,"a":[{"p":"38154.9","s":0},{"p":"38159.1","s":0},{"p":"38163.1","s":0},{"p":"38155.3","s":0}],"b":[{"p":"38140","s":11083},{"p":"38140.5","s":0},{"p":"38140.7","s":2390}],"s":"BTC_USDT","t":1701245644302,"u":53095234587}}
{"time":1701245644,"time_ms":1701245644332,"channel":"futures.order_book_update","event":"update","result":{"U":53095234588,"a":[{"p":"38153.9","s":0}],"b":[{"p":"38140.3","s":3490},{"p":"38140","s":11083},{"p":"38140.8","s":0},{"p":"38141.5","s":0},{"p":"38139.2","s":0}],"s":"BTC_USDT","t":1701245644322,"u":53095234597}}
{"time":1701245644,"time_ms":1701245644352,"channel":"futures.order_book_update","event":"update","result":{"U":53095234598,"a":[{"p":"38155.6","s":0}],"b":[{"p":"38140","s":0},{"p":"38141.5","s":2174}],"s":"BTC_USDT","t":1701245644341,"u":53095234600}}
{"time":1701245644,"time_ms":1701245644393,"channel":"futures.order_book_update","event":"update","result":{"U":53095234601,"a":[{"p":"38154.5","s":0}],"b":[{"p":"38140.3","s":1315},{"p":"38140.8","s":2174},{"p":"38141.5","s":0},{"p":"38140","s":0}],"s":"BTC_USDT","t":1701245644387,"u":53095234608}}
{"time":1701245644,"time_ms":1701245644412,"channel":"futures.order_book_update","event":"update","result":{"U":53095234609,"a":[{"p":"38171.3","s":0},{"p":"38156.9","s":0},{"p":"38163.2","s":0},{"p":"38158.5","s":0}],"b":[],"s":"BTC_USDT","t":1701245644398,"u":53095234614}}
{"time":1701245644,"time_ms":1701245644511,"channel":"futures.order_book_update","event":"update","result":{"U":53095234615,"a":[{"p":"38154.8","s":0}],"b":[],"s":"BTC_USDT","t":1701245644492,"u":53095234626}}
{"time":1701245644,"time_ms":1701245644572,"channel":"futures.order_book_update","event":"update","result":{"U":53095234627,"a":[{"p":"38145.6","s":19418}],"b":[],"s":"BTC_USDT","t":1701245644555,"u":53095234629}}
{"time":1701245644,"time_ms":1701245644673,"channel":"futures.order_book_update","event":"update","result":{"U":53095234630,"a":[],"b":[{"p":"38135.4","s":0}],"s":"BTC_USDT","t":1701245644661,"u":53095234631}}
{"time":1701245644,"time_ms":1701245644732,"channel":"futures.order_book_update","event":"update","result":{"U":53095234632,"a":[{"p":"38153.2","s":0}],"b":[],"s":"BTC_USDT","t":1701245644706,"u":53095234633}}
{"time":1701245644,"time_ms":1701245644931,"channel":"futures.order_book_update","event":"update","result":{"U":53095234634,"a":[],"b":[{"p":"38131.6","s":0}],"s":"BTC_USDT","t":1701245644920,"u":53095234635}}
{"time":1701245645,"time_ms":1701245645013,"channel":"futures.order_book_update","event":"update","result":{"U":53095234636,"a":[],"b":[{"p":"38125.6","s":0}],"s":"BTC_USDT","t":1701245644993,"u":53095234639}}
{"time":1701245645,"time_ms":1701245645032,"channel":"futures.order_book_update","event":"update","result":{"U":53095234640,"a":[{"p":"38170.9","s":0},{"p":"38156.1","s":0},{"p":"38154.4","s":0},{"p":"38156","s":0}],"b":[{"p":"38139.8","s":0},{"p":"38133.6","s":0},{"p":"38141.5","s":4473},{"p":"38140","s":11083},{"p":"38140.4","s":2908},{"p":"38140.8","s":0},{"p":"38140.7","s":0}],"s":"BTC_USDT","t":1701245645019,"u":53095234657}}
{"time":1701245645,"time_ms":1701245645052,"channel":"futures.order_book_update","event":"update","result":{"U":53095234658,"a":[{"p":"38159.2","s":0}],"b":[{"p":"38140.9","s":733},{"p":"38140","s":0},{"p":"38140.4","s":2175}],"s":"BTC_USDT","t":1701245645025,"u":53095234661}}
{"time":1701245645,"time_ms":1701245645114,"channel":"futures.order_book_update","event":"update","result":{"U":53095234662,"a":[{"p":"38145.6","s":19418},{"p":"38156.4","s":0}],"b":[{"p":"38140.7","s":733},{"p":"38140.9","s":0},{"p":"38140","s":0}],"s":"BTC_USDT","t":1701245645096,"u":53095234673}}
{"time":1701245645,"time_ms":1701245645132,"channel":"futures.order_book_update","event":"update","result":{"U":53095234674,"a":[],"b":[{"p":"38140.7","s":733},{"p":"38141.5","s":4468},{"p":"38145.5","s":134132}],"s":"BTC_USDT","t":1701245645121,"u":53095234681}}
{"time":1701245645,"time_ms":1701245645152,"channel":"futures.order_book_update","event":"update","result":{"U":53095234682,"a":[{"p":"38150.9","s":7549},{"p":"38145.6","s":46918},{"p":"38164","s":0},{"p":"38159","s":0},{"p":"38155","s":0}],"b":[{"p":"38136.5","s":0},{"p":"38140","s":0},{"p":"38141.7","s":2268},{"p":"38141.5","s":2294},{"p":"38143","s":200},{"p":"38144","s":0}],"s":"BTC_USDT","t":1701245645130,"u":53095234699}}
{"time":1701245645,"time_ms":1701245645172,"channel":"futures.order_book_update","event":"update","result":{"U":53095234700,"a":[{"p":"38156.2","s":0},{"p":"38154.5","s":0}],"b":[{"p":"38140.2","s":2620},{"p":"38144","s":200},{"p":"38143","s":0}],"s":"BTC_USDT","t":1701245645150,"u":53095234709}}
{"time":1701245645,"time_ms":1701245645213,"channel":"futures.order_book_update","event":"update","result":{"U":53095234710,"a":[{"p":"38154.9","s":0},{"p":"38159.3","s":0}],"b":[{"p":"38145.5","s":134062}],"s":"BTC_USDT","t":1701245645197,"u":53095234714}}
{"time":1701245645,"time_ms":1701245645232,"channel":"futures.order_book_update","event":"update","result":{"U":53095234715,"a":[{"p":"38145.6","s":47418}],"b":[],"s":"BTC_USDT","t":1701245645226,"u":53095234721}}
{"time":1701245645,"time_ms":1701245645252,"channel":"futures.order_book_update","event":"update","result":{"U":53095234722,"a":[{"p":"38154.5","s":0},{"p":"38158.5","s":0},{"p":"38145.6","s":47418}],"b":[],"s":"BTC_USDT","t":1701245645237,"u":53095234731}}
{"time":1701245645,"time_ms":1701245645273,"channel":"futures.order_book_update","event":"update","result":{"U":53095234732,"a":[{"p":"38156.4","s":0},{"p":"38145.6","s":19918},{"p":"38154.7","s":0}],"b":[{"p":"38140.7","s":733},{"p":"38141.5","s":2294},{"p":"38140","s":0},{"p":"38140.4","s":2175},{"p":"38139.9","s":0}],"s":"BTC_USDT","t":1701245645264,"u":53095234747}}
{"time":1701245645,"time_ms":1701245645294,"channel":"futures.order_book_update","event":"update","result":{"U":53095234748,"a":[{"p":"38156.7","s":0},{"p":"38156.8","s":0},{"p":"38155.2","s":0},{"p":"38159","s":0}],"b":[{"p":"38141.5","s":3027},{"p":"38140","s":11083},{"p":"38140.7","s":0}],"s":"BTC_USDT","t":1701245645283,"u":53095234756}}
{"time":1701245645,"time_ms":1701245645312,"channel":"futures.order_book_update","event":"update","result":{"U":53095234757,"a":[{"p":"38155.5","s":0},{"p":"38159.5","s":0},{"p":"38153.2","s":0}],"b":[{"p":"38145.5","s":134132},{"p":"38141.5","s":0},{"p":"38140","s":0},{"p":"38140.2","s":2620},{"p":"38136.9","s":0},{"p":"38140.5","s":6},{"p":"38140.7","s":3141}],"s":"BTC_USDT","t":1701245645298,"u":53095234773}}
{"time":1701245645,"time_ms":1701245645333,"channel":"futures.order_book_update","event":"update","result":{"U":53095234774,"a":[{"p":"38156.2","s":0}],"b":[{"p":"38141.8","s":733},{"p":"38141.7","s":4574},{"p":"38140.7","s":0},{"p":"38140.2","s":2620}],"s":"BTC_USDT","t":1701245645324,"u":53095234784}}
{"time":1701245645,"time_ms":1701245645354,"channel":"futures.order_book_update","event":"update","result":{"U":53095234785,"a":[{"p":"38156.6","s":0}],"b":[{"p":"38140.2","s":0},{"p":"38141.8","s":0},{"p":"38140","s":0},{"p":"38136.5","s":0},{"p":"38141.7","s":2268},{"p":"38140.8","s":733},{"p":"38140.7","s":2396}],"s":"BTC_USDT","t":1701245645340,"u":53095234794}}
{"time":1701245645,"time_ms":1701245645372,"channel":"futures.order_book_update","event":"update","result":{"U":53095234795,"a":[{"p":"38145.6","s":20418}],"b":[{"p":"38140.2","s":0},{"p":"38140.8","s":3353}],"s":"BTC_USDT","t":1701245645358,"u":53095234797}}
{"time":1701245645,"time_ms":1701245645395,"channel":"futures.order_book_update","event":"update","result":{"U":53095234798,"a":[{"p":"38154.4","s":0}],"b":[],"s":"BTC_USDT","t":1701245645386,"u":53095234799}}
{"time":1701245645,"time_ms":1701245645453,"channel":"futures.order_book_update","event":"update","result":{"U":53095234800,"a":[],"b":[{"p":"38140","s":11083},{"p":"38140.5","s":0},{"p":"38139.8","s":0}],"s":"BTC_USDT","t":1701245645439,"u":53095234805}}
{"time":1701245645,"time_ms":1701245645472,"channel":"futures.order_book_update","event":"update","result":{"U":53095234806,"a":[],"b":[{"p":"38141.7","s":94},{"p":"38140.9","s":2174},{"p":"38140","s":0}],"s":"BTC_USDT","t":1701245645461,"u":53095234807}}
{"time":1701245645,"time_ms":1701245645494,"channel":"futures.order_book_update","event":"update","result":{"U":53095234808,"a":[{"p":"38154.6","s":0}],"b":[{"p":"38140.5","s":6},{"p":"38140.4","s":0},{"p":"38140","s":0}],"s":"BTC_USDT","t":1701245645469,"u":53095234815}}
{"time":1701245645,"time_ms":1701245645513,"channel":"futures.order_book_update","event":"update","result":{"U":53095234816,"a":[{"p":"38155.9","s":0}],"b":[{"p":"38132","s":0}],"s":"BTC_USDT","t":1701245645504,"u":53095234818}}
{"time":1701245645,"time_ms":1701245645574,"channel":"futures.order_book_update","event":"update","result":{"U":53095234819,"a":[{"p":"38145.6","s":20918}],"b":[],"s":"BTC_USDT","t":1701245645550,"u":53095234819}}
{"time":1701245645,"time_ms":1701245645672,"channel":"futures.order_book_update","event":"update","result":{"U":53095234820,"a":[],"b":[{"p":"38140","s":11083},{"p":"38140.5","s":0},{"p":"38139.8","s":0}],"s":"BTC_USDT","t":1701245645653,"u":53095234826}}
{"time":1701245645,"time_ms":1701245645692,"channel":"futures.order_book_update","event":"update","result":{"U":53095234827,"a":[],"b":[{"p":"38140.5","s":6},{"p":"38140","s":0}],"s":"BTC_USDT","t":1701245645673,"u":53095234830}}
{"time":1701245645,"time_ms":1701245645752,"channel":"futures.order_book_update","event":"update","result":{"U":53095234831,"a":[],"b":[{"p":"38139.8","s":0},{"p":"38140","s":11083},{"p":"38140.5","s":0}],"s":"BTC_USDT","t":1701245645739,"u":53095234834}}
{"time":1701245645,"time_ms":1701245645777,"channel":"futures.order_book_update","event":"update","result":{"U":53095234835,"a":[{"p":"38156.1","s":0},{"p":"38159.6","s":0},{"p":"38155.9","s":0},{"p":"38156.6","s":0}],"b":[{"p":"38136.1","s":0},{"p":"38140.5","s":6},{"p":"38140","s":0},{"p":"38139.8","s":0}],"s":"BTC_USDT","t":1701245645759,"u":53095234852}}
{"time":1701245645,"time_ms":1701245645813,"channel":"futures.order_book_update","event":"update","result":{"U":53095234853,"a":[{"p":"38154.7","s":0}],"b":[],"s":"BTC_USDT","t":1701245645792,"u":53095234854}}
{"time":1701245645,"time_ms":1701245645852,"channel":"futures.order_book_update","event":"update","result":{"U":53095234855,"a":[{"p":"38145.6","s":20418}],"b":[],"s":"BTC_USDT","t":1701245645844,"u":53095234855}}
{"time":1701245645,"time_ms":1701245645871,"channel":"futures.order_book_update","event":"update","result":{"U":53095234856,"a":[{"p":"38155.3","s":0},{"p":"38154.5","s":0}],"b":[],"s":"BTC_USDT","t":1701245645856,"u":53095234859}}
{"time":1701245645,"time_ms":1701245645931,"channel":"futures.order_book_update","event":"update","result":{"U":53095234860,"a":[{"p":"38155.3","s":0},{"p":"38158.2","s":0},{"p":"38159","s":0},{"p":"38155","s":0}],"b":[],"s":"BTC_USDT","t":1701245645923,"u":53095234869}}
{"time":1701245645,"time_ms":1701245645992,"channel":"futures.order_book_update","event":"update","result":{"U":53095234870,"a":[{"p":"38154.8","s":0}],"b":[],"s":"BTC_USDT","t":1701245645980,"u":53095234871}}
{"time":1701245646,"time_ms":1701245646012,"channel":"futures.order_book_update","event":"update","result":{"U":53095234872,"a":[{"p":"38155.8","s":0}],"b":[{"p":"38140.5","s":0},{"p":"38139.8","s":0},{"p":"38140","s":11083}],"s":"BTC_USDT","t":1701245646003,"u":53095234876}}
{"time":1701245646,"time_ms":1701245646034,"channel":"futures.order_book_update","event":"update","result":{"U":53095234877,"a":[{"p":"38158.9","s":0},{"p":"38155.3","s":0},{"p":"38155.9","s":0},{"p":"38171.3","s":0}],"b":[{"p":"38135.4","s":0},{"p":"38133.5","s":0},{"p":"38141","s":3045},{"p":"38140.5","s":6},{"p":"38140.8","s":2620},{"p":"38140","s":0},{"p":"38140.7","s":0},{"p":"38139.2","s":0}],"s":"BTC_USDT","t":1701245646025,"u":53095234899}}
{"time":1701245646,"time_ms":1701245646094,"channel":"futures.order_book_update","event":"update","result":{"U":53095234900,"a":[{"p":"38155.2","s":0},{"p":"38155.6","s":0},{"p":"38153.9","s":0},{"p":"38154.2","s":0}],"b":[{"p":"38139.8","s":0},{"p":"38140.1","s":0}],"s":"BTC_USDT","t":1701245646076,"u":53095234911}}
{"time":1701245646,"time_ms":1701245646112,"channel":"futures.order_book_update","event":"update","result":{"U":53095234912,"a":[{"p":"38155.7","s":0}],"b":[{"p":"38141.1","s":2174},{"p":"38140.9","s":0},{"p":"38140","s":0}],"s":"BTC_USDT","t":1701245646103,"u":53095234918}}
{"time":1701245646,"time_ms":1701245646193,"channel":"futures.order_book_update","event":"update","result":{"U":53095234919,"a":[],"b":[{"p":"38141","s":2312},{"p":"38140.9","s":733},{"p":"38140.3","s":0}],"s":"BTC_USDT","t":1701245646182,"u":53095234920}}
{"time":1701245646,"time_ms":1701245646274,"channel":"futures.order_book_update","event":"update","result":{"U":53095234921,"a":[{"p":"38153.9","s":0},{"p":"38155.4","s":0}],"b":[],"s":"BTC_USDT","t":1701245646256,"u":53095234924}}
{"time":1701245646,"time_ms":1701245646332,"channel":"futures.order_book_update","event":"update","result":{"U":53095234925,"a":[{"p":"38160.2","s":0}],"b":[],"s":"BTC_USDT","t":1701245646320,"u":53095234926}}
{"time":1701245646,"time_ms":1701245646374,"channel":"futures.order_book_update","event":"update","result":{"U":53095234927,"a":[{"p":"38158.6","s":0},{"p":"38156","s":0},{"p":"38155.4","s":0},{"p":"38155.5","s":0},{"p":"38150.5","s":0},{"p":"38166","s":0},{"p":"38154","s":0},{"p":"38155.8","s":0},{"p":"38170.9","s":0},{"p":"38150.4","s":7228},{"p":"38155.9","s":0},{"p":"38157.8","s":0},{"p":"38154.2","s":0},{"p":"38161.5","s":0},{"p":"38152.4","s":7244},{"p":"38159.5","s":0},{"p":"38166.5","s":0},{"p":"38145.6","s":13198},{"p":"38153.2","s":0}],"b":[{"p":"38119.8","s":0},{"p":"38135.3","s":0},{"p":"38132.5","s":0},{"p":"38139.8","s":0},{"p":"38135.8","s":0},{"p":"38140.3","s":0},{"p":"38145.5","s":135632},{"p":"38140.7","s":2175},{"p":"38141.1","s":0},{"p":"38123.6","s":0}],"s":"BTC_USDT","t":1701245646363,"u":53095234966}}
{"time":1701245646,"time_ms":1701245646393,"channel":"futures.order_book_update","event":"update","result":{"U":53095234967,"a":[{"p":"38152.4","s":3606},{"p":"38145.6","s":7869},{"p":"38154.6","s":0},{"p":"38183.6","s":0},{"p":"38155","s":0},{"p":"38151.4","s":3622},{"p":"38159","s":0},{"p":"38160.4","s":0},{"p":"38164.7","s":0},{"p":"38154.7","s":0},{"p":"38159.1","s":0},{"p":"38156.8","s":0},{"p":"38150.4","s":3622},{"p":"38156.2","s":0},{"p":"38171.5","s":0},{"p":"38151","s":3},{"p":"38173.4","s":0},{"p":"38152.5","s":79},{"p":"38155.2","s":0},{"p":"38158.6","s":0},{"p":"38160.1","s":0},{"p":"38164.8","s":0},{"p":"38150.1","s":0}],"b":[{"p":"38140.9","s":0},{"p":"38101.5","s":0},{"p":"38136.7","s":0},{"p":"38140.3","s":1315},{"p":"38135.9","s":0},{"p":"38133.3","s":0},{"p":"38131","s":0},{"p":"38134.9","s":0},{"p":"38141.5","s":733},{"p":"38136.9","s":0},{"p":"38081.6","s":0},{"p":"38141.7","s":2268},{"p":"38136.4","s":0},{"p":"38140.8","s":0}],"s":"BTC_USDT","t":1701245646384,"u":53095235041}}
{"time":1701245646,"time_ms":1701245646412,"channel":"futures.order_book_update","event":"update","result":{"U":53095235042,"a":[{"p":"38159","s":0},{"p":"38154.8","s":0},{"p":"38159.8","s":0},{"p":"38153.1","s":0},{"p":"38156.8","s":0},{"p":"38152.8","s":0}],"b":[{"p":"38142.4","s":2620},{"p":"38141.8","s":2174},{"p":"38140.3","s":0},{"p":"38140.5","s":0}],"s":"BTC_USDT","t":1701245646396,"u":53095235058}}
{"time":1701245646,"time_ms":1701245646454,"channel":"futures.order_book_update","event":"update","result":{"U":53095235059,"a":[{"p":"38158","s":0},{"p":"38172.2","s":0},{"p":"38153.2","s":0},{"p":"38157.5","s":0},{"p":"38155.8","s":0},{"p":"38145.6","s":10203},{"p":"38150.3","s":0},{"p":"38152.7","s":15046},{"p":"38166.8","s":0}],"b":[{"p":"38124.4","s":0},{"p":"38141.9","s":3932},{"p":"38145.5","s":138777},{"p":"38143.5","s":2644},{"p":"38140.7","s":0},{"p":"38134.2","s":0},{"p":"38136.7","s":0},{"p":"38143","s":2174},{"p":"38141.5","s":0},{"p":"38142.4","s":0},{"p":"38138.1","s":0},{"p":"38141.1","s":2174},{"p":"38141","s":0},{"p":"38125.3","s":0},{"p":"38141.8","s":733},{"p":"38141.7","s":94},{"p":"38140.5","s":6},{"p":"38140.6","s":12165}],"s":"BTC_USDT","t":1701245646446,"u":53095235101}}
{"time":1701245646,"time_ms":1701245646472,"channel":"futures.order_book_update","event":"update","result":{"U":53095235102,"a":[{"p":"38158.5","s":0},{"p":"38156.7","s":0},{"p":"38160.9","s":0},{"p":"38158","s":0}],"b":[{"p":"38143.5","s":3601},{"p":"38140.3","s":1315},{"p":"38141.8","s":0},{"p":"38067.3","s":0}],"s":"BTC_USDT","t":1701245646456,"u":53095235126}}
{"time":1701245646,"time_ms":1701245646505,"channel":"futures.order_book_update","event":"update","result":{"U":53095235127,"a":[{"p":"38155.1","s":0},{"p":"38164.5","s":0},{"p":"38160.5","s":0},{"p":"38147.3","s":1825},{"p":"38152.5","s":733}],"b":[{"p":"38141.8","s":2174},{"p":"38140.3","s":0},{"p":"38141.1","s":0},{"p":"38122.5","s":0},{"p":"38143.6","s":733},{"p":"38143","s":4794}],"s":"BTC_USDT","t":1701245646497,"u":53095235148}}
{"time":1701245646,"time_ms":1701245646515,"channel":"futures.order_book_update","event":"update","result":{"U":53095235149,"a":[{"p":"38145.6","s":3369}],"b":[],"s":"BTC_USDT","t":1701245646503,"u":53095235160}}
{"time":1701245646,"time_ms":1701245646532,"channel":"futures.order_book_update","event":"update","result":{"U":53095235161,"a":[{"p":"38145.6","s":2869}],"b":[{"p":"38143.5","s":5054}],"s":"BTC_USDT","t":1701245646511,"u":53095235162}}
{"time":1701245646,"time_ms":1701245646553,"channel":"futures.order_book_update","event":"update","result":{"U":53095235163,"a":[{"p":"38161.1","s":0}],"b":[{"p":"38090.2","s":0}],"s":"BTC_USDT","t":1701245646545,"u":53095235165}}
{"time":1701245646,"time_ms":1701245646572,"channel":"futures.order_book_update","event":"update","result":{"U":53095235166,"a":[],"b":[{"p":"38128.8","s":0},{"p":"38136.7","s":0},{"p":"38145.5","s":142447},{"p":"38125.3","s":0}],"s":"BTC_USDT","t":1701245646555,"u":53095235183}}
{"time":1701245646,"time_ms":1701245646594,"channel":"futures.order_book_update","event":"update","result":{"U":53095235184,"a":[],"b":[{"p":"38132.6","s":0}],"s":"BTC_USDT","t":1701245646581,"u":53095235186}}
{"time":1701245646,"time_ms":1701245646614,"channel":"futures.order_book_update","event":"update","result":{"U":53095235187,"a":[],"b":[{"p":"38140.5","s":4}],"s":"BTC_USDT","t":1701245646606,"u":53095235191}}
{"time":1701245646,"time_ms":1701245646633,"channel":"futures.order_book_update","event":"update","result":{"U":53095235192,"a":[],"b":[{"p":"38140.3","s":1315},{"p":"38140.5","s":0},{"p":"38139.8","s":0}],"s":"BTC_USDT","t":1701245646607,"u":53095235194}}
{"time":1701245646,"time_ms":1701245646652,"channel":"futures.order_book_update","event":"update","result":{"U":53095235195,"a":[],"b":[{"p":"38141.4","s":6520},{"p":"38140.7","s":2},{"p":"38140.3","s":0},{"p":"38137.9","s":0}],"s":"BTC_USDT","t":1701245646644,"u":53095235200}}
{"time":1701245646,"time_ms":1701245646672,"channel":"futures.order_book_update","event":"update","result":{"U":53095235201,"a":[{"p":"38160","s":0},{"p":"38172","s":0},{"p":"38176.7","s":0},{"p":"38164","s":0}],"b":[],"s":"BTC_USDT","t":1701245646666,"u":53095235210}}
{"time":1701245646,"time_ms":1701245646731,"channel":"futures.order_book_update","event":"update","result":{"U":53095235211,"a":[{"p":"38145.6","s":5869},{"p":"38153.3","s":0}],"b":[],"s":"BTC_USDT","t":1701245646724,"u":53095235217}}
{"time":1701245646,"time_ms":1701245646751,"channel":"futures.order_book_update","event":"update","result":{"U":53095235218,"a":[{"p":"38145.6","s":2869},{"p":"38157.7","s":0}],"b":[],"s":"BTC_USDT","t":1701245646739,"u":53095235234}}
{"time":1701245646,"time_ms":1701245646772,"channel":"futures.order_book_update","event":"update","result":{"U":53095235235,"a":[{"p":"38159","s":0},{"p":"38163","s":0}],"b":[{"p":"38134.7","s":0}],"s":"BTC_USDT","t":1701245646755,"u":53095235240}}
{"time":1701245646,"time_ms":1701245646793,"channel":"futures.order_book_update","event":"update","result":{"U":53095235241,"a":[{"p":"38145.6","s":6327},{"p":"38158.1","s":0},{"p":"38152","s":1052},{"p":"38157.5","s":0},{"p":"38152.5","s":79}],"b":[{"p":"38143","s":5527},{"p":"38142","s":2469},{"p":"38143.6","s":0},{"p":"38139.2","s":0},{"p":"38140.6","s":12165},{"p":"38143.5","s":2726}],"s":"BTC_USDT","t":1701245646782,"u":53095235254}}
{"time":1701245646,"time_ms":1701245646811,"channel":"futures.order_book_update","event":"update","result":{"U":53095235255,"a":[{"p":"38155.9","s":0},{"p":"38156.8","s":0}],"b":[{"p":"38141.4","s":6514},{"p":"38140.3","s":1315},{"p":"38140.7","s":0},{"p":"38134.8","s":0},{"p":"38132","s":0}],"s":"BTC_USDT","t":1701245646803,"u":53095235267}}
{"time":1701245646,"time_ms":1701245646833,"channel":"futures.order_book_update","event":"update","result":{"U":53095235268,"a":[],"b":[{"p":"38141.4","s":6520},{"p":"38140.2","s":0}],"s":"BTC_USDT","t":1701245646826,"u":53095235272}}
{"time":1701245646,"time_ms":1701245646898,"channel":"futures.order_book_update","event":"update","result":{"U":53095235273,"a":[{"p":"38159.5","s":0},{"p":"38163.5","s":0}],"b":[],"s":"BTC_USDT","t":1701245646884,"u":53095235278}}
{"time":1701245646,"time_ms":1701245646912,"channel":"futures.order_book_update","event":"update","result":{"U":53095235279,"a":[{"p":"38145.6","s":2869}],"b":[],"s":"BTC_USDT","t":1701245646902,"u":53095235279}}
{"time":1701245646,"time_ms":1701245646991,"channel":"futures.order_book_update","event":"update","result":{"U":53095235280,"a":[],"b":[{"p":"38038.3","s":0}],"s":"BTC_USDT","t":1701245646983,"u":53095235281}}
{"time":1701245647,"time_ms":1701245647012,"channel":"futures.order_book_update","event":"update","result":{"U":53095235282,"a":[{"p":"38145.6","s":6288}],"b":[{"p":"38141.4","s":6514},{"p":"38140","s":11083},{"p":"38141.8","s":0},{"p":"38140.2","s":0}],"s":"BTC_USDT","t":1701245647003,"u":53095235287}}
{"time":1701245647,"time_ms":1701245647032,"channel":"futures.order_book_update","event":"update","result":{"U":53095235288,"a":[{"p":"38161.1","s":0},{"p":"38158.2","s":0},{"p":"38158","s":0},{"p":"38173.5","s":0},{"p":"38158.5","s":0},{"p":"38156.3","s":0},{"p":"38161.9","s":0},{"p":"38156.8","s":0},{"p":"38157.6","s":0}],"b":[{"p":"38142","s":0},{"p":"38134.8","s":0},{"p":"38137.9","s":0},{"p":"38138.2","s":0},{"p":"38131.2","s":0},{"p":"38140.5","s":0},{"p":"38143.6","s":2174},{"p":"38143.1","s":3046},{"p":"38143","s":2620},{"p":"38142.1","s":2174},{"p":"38140.3","s":0},{"p":"38140","s":0}],"s":"BTC_USDT","t":1701245647018,"u":53095235327}}
{"time":1701245647,"time_ms":1701245647053,"channel":"futures.order_book_update","event":"update","result":{"U":53095235328,"a":[{"p":"38158.2","s":0}],"b":[{"p":"38140.5","s":2},{"p":"38143.5","s":3447},{"p":"38143.6","s":0},{"p":"38139.8","s":0},{"p":"38139.1","s":0}],"s":"BTC_USDT","t":1701245647044,"u":53095235338}}
{"time":1701245647,"time_ms":1701245647073,"channel":"futures.order_book_update","event":"update","result":{"U":53095235339,"a":[{"p":"38145.6","s":13214},{"p":"38159","s":0},{"p":"38163","s":0}],"b":[{"p":"38140.3","s":1315},{"p":"38140.5","s":0}],"s":"BTC_USDT","t":1701245647069,"u":53095235356}}
{"time":1701245647,"time_ms":1701245647092,"channel":"futures.order_book_update","event":"update","result":{"U":53095235357,"a":[{"p":"38145.6","s":8214},{"p":"38156.7","s":0}],"b":[{"p":"38143.1","s":5220},{"p":"38143.5","s":1273},{"p":"38138.6","s":0}],"s":"BTC_USDT","t":1701245647080,"u":53095235373}}
{"time":1701245647,"time_ms":1701245647111,"channel":"futures.order_book_update","event":"update","result":{"U":53095235374,"a":[{"p":"38161.3","s":0},{"p":"38158.5","s":0},{"p":"38156.2","s":0},{"p":"38162.5","s":0}],"b":[{"p":"38141.7","s":2268},{"p":"38142.1","s":2907},{"p":"38143.1","s":0},{"p":"38138.2","s":0},{"p":"38135.4","s":0},{"p":"38140","s":0},{"p":"38143.5","s":2974},{"p":"38142.2","s":2399}],"s":"BTC_USDT","t":1701245647095,"u":53095235395}}
{"time":1701245647,"time_ms":1701245647132,"channel":"futures.order_book_update","event":"update","result":{"U":53095235396,"a":[],"b":[{"p":"38143.5","s":1273}],"s":"BTC_USDT","t":1701245647112,"u":53095235396}}
{"time":1701245647,"time_ms":1701245647151,"channel":"futures.order_book_update","event":"update","result":{"U":53095235397,"a":[],"b":[{"p":"38137.5","s":0}],"s":"BTC_USDT","t":1701245647123,"u":53095235397}}
{"time":1701245647,"time_ms":1701245647172,"channel":"futures.order_book_update","event":"update","result":{"U":53095235398,"a":[{"p":"38152.4","s":7239},{"p":"38155.8","s":0},{"p":"38160.5","s":0}],"b":[{"p":"38143.1","s":4467},{"p":"38142.1","s":733},{"p":"38142.2","s":0},{"p":"38140.3","s":1315}],"s":"BTC_USDT","t":1701245647166,"u":53095235406}}
{"time":1701245647,"time_ms":1701245647190,"channel":"futures.order_book_update","event":"update","result":{"U":53095235407,"a":[{"p":"38158","s":0},{"p":"38162","s":0}],"b":[{"p":"38143.1","s":2174},{"p":"38142.2","s":2437},{"p":"38140.3","s":0},{"p":"38145.5","s":138777},{"p":"38143.5","s":2523}],"s":"BTC_USDT","t":1701245647183,"u":53095235416}}
{"time":1701245647,"time_ms":1701245647212,"channel":"futures.order_book_update","event":"update","result":{"U":53095235417,"a":[{"p":"38152.8","s":0}],"b":[{"p":"38143.6","s":2620},{"p":"38143.5","s":1273},{"p":"38143","s":0},{"p":"38140.3","s":0}],"s":"BTC_USDT","t":1701245647206,"u":53095235421}}
{"time":1701245647,"time_ms":1701245647231,"channel":"futures.order_book_update","event":"update","result":{"U":53095235422,"a":[{"p":"38165.7","s":0}],"b":[],"s":"BTC_USDT","t":1701245647212,"u":53095235422}}
{"time":1701245647,"time_ms":1701245647332,"channel":"futures.order_book_update","event":"update","result":{"U":53095235423,"a":[{"p":"38145.6","s":6288}],"b":[],"s":"BTC_USDT","t":1701245647323,"u":53095235426}}
{"time":1701245647,"time_ms":1701245647372,"channel":"futures.order_book_update","event":"update","result":{"U":53095235427,"a":[{"p":"38145.6","s":2869},{"p":"38159","s":0},{"p":"38163","s":0}],"b":[{"p":"38140.6","s":12165},{"p":"38142.3","s":733},{"p":"38142.1","s":0},{"p":"38143","s":0},{"p":"38140.3","s":0}],"s":"BTC_USDT","t":1701245647352,"u":53095235435}}
{"time":1701245647,"time_ms":1701245647493,"channel":"futures.order_book_update","event":"update","result":{"U":53095235436,"a":[{"p":"38165.8","s":0}],"b":[{"p":"38142.2","s":0},{"p":"38136.1","s":0},{"p":"38140.3","s":0},{"p":"38143.2","s":2299}],"s":"BTC_USDT","t":1701245647484,"u":53095235445}}
{"time":1701245647,"time_ms":1701245647514,"channel":"futures.order_book_update","event":"update","result":{"U":53095235446,"a":[{"p":"38163.5","s":0},{"p":"38170.5","s":0},{"p":"38156.2","s":0},{"p":"38161.8","s":0},{"p":"38167","s":0},{"p":"38158","s":0},{"p":"38159.5","s":0}],"b":[{"p":"38142.3","s":0},{"p":"38138.2","s":0},{"p":"38143.2","s":3032},{"p":"38140.3","s":1315}],"s":"BTC_USDT","t":1701245647503,"u":53095235461}}
{"time":1701245647,"time_ms":1701245647534,"channel":"futures.order_book_update","event":"update","result":{"U":53095235462,"a":[{"p":"38156.2","s":0},{"p":"38155.7","s":0},{"p":"38155.9","s":0}],"b":[],"s":"BTC_USDT","t":1701245647522,"u":53095235465}}
{"time":1701245647,"time_ms":1701245647553,"channel":"futures.order_book_update","event":"update","result":{"U":53095235466,"a":[{"p":"38154.1","s":0},{"p":"38160.9","s":0},{"p":"38164","s":0},{"p":"38157.9","s":0},{"p":"38148","s":600}],"b":[{"p":"38140.8","s":6},{"p":"38143.1","s":0},{"p":"38140.3","s":1315},{"p":"38144","s":2374}],"s":"BTC_USDT","t":1701245647541,"u":53095235485}}
{"time":1701245647,"time_ms":1701245647576,"channel":"futures.order_book_update","event":"update","result":{"U":53095235486,"a":[{"p":"38157.9","s":0}],"b":[{"p":"38145.5","s":138777}],"s":"BTC_USDT","t":1701245647556,"u":53095235490}}
{"time":1701245647,"time_ms":1701245647593,"channel":"futures.order_book_update","event":"update","result":{"U":53095235491,"a":[{"p":"38157","s":0},{"p":"38156.8","s":0}],"b":[],"s":"BTC_USDT","t":1701245647578,"u":53095235494}}
{"time":1701245647,"time_ms":1701245647611,"channel":"futures.order_book_update","event":"update","result":{"U":53095235495,"a":[{"p":"38158.5","s":0}],"b":[{"p":"38133.7","s":0},{"p":"38145.5","s":138836}],"s":"BTC_USDT","t":1701245647599,"u":53095235501}}
{"time":1701245647,"time_ms":1701245647634,"channel":"futures.order_book_update","event":"update","result":{"U":53095235502,"a":[],"b":[{"p":"38137.5","s":0}],"s":"BTC_USDT","t":1701245647618,"u":53095235504}}
{"time":1701245647,"time_ms":1701245647692,"channel":"futures.order_book_update","event":"update","result":{"U":53095235505,"a":[{"p":"38154.1","s":0}],"b":[],"s":"BTC_USDT","t":1701245647679,"u":53095235506}}
{"time":1701245647,"time_ms":1701245647753,"channel":"futures.order_book_update","event":"update","result":{"U":53095235507,"a":[{"p":"38169","s":0}],"b":[],"s":"BTC_USDT","t":1701245647743,"u":53095235510}}
{"time":1701245647,"time_ms":1701245647773,"channel":"futures.order_book_update","event":"update","result":{"U":53095235511,"a":[{"p":"38170","s":0}],"b":[{"p":"38140","s":11083},{"p":"38140.8","s":0},{"p":"38140.2","s":0}],"s":"BTC_USDT","t":1701245647759,"u":53095235516}}
{"time":1701245647,"time_ms":1701245647791,"channel":"futures.order_book_update","event":"update","result":{"U":53095235517,"a":[],"b":[{"p":"38141.3","s":2},{"p":"38142","s":6},{"p":"38140","s":0},{"p":"38140.3","s":0}],"s":"BTC_USDT","t":1701245647780,"u":53095235521}}
{"time":1701245647,"time_ms":1701245647974,"channel":"futures.order_book_update","event":"update","result":{"U":53095235522,"a":[],"b":[{"p":"38141.3","s":0},{"p":"38142","s":0},{"p":"38121.4","s":0},{"p":"38140","s":11083},{"p":"38140.3","s":1315}],"s":"BTC_USDT","t":1701245647960,"u":53095235529}}
{"time":1701245647,"time_ms":1701245647997,"channel":"futures.order_book_update","event":"update","result":{"U":53095235530,"a":[{"p":"38162.9","s":0},{"p":"38159.1","s":0}],"b":[{"p":"38142","s":6},{"p":"38141.3","s":2},{"p":"38140","s":0},{"p":"38140.3","s":0}],"s":"BTC_USDT","t":1701245647983,"u":53095235538}}
{"time":1701245648,"time_ms":1701245648030,"channel":"futures.order_book_update","event":"update","result":{"U":53095235539,"a":[{"p":"38173","s":0},{"p":"38157.3","s":0},{"p":"38159","s":0},{"p":"38158.5","s":0},{"p":"38161.5","s":0}],"b":[{"p":"38141.7","s":94},{"p":"38143.6","s":4912},{"p":"38143.2","s":0},{"p":"38140.6","s":12165},{"p":"38144","s":200},{"p":"38142","s":2180},{"p":"38143.8","s":2174},{"p":"38143.5","s":2006},{"p":"38135.1","s":0}],"s":"BTC_USDT","t":1701245648020,"u":53095235560}}
{"time":1701245648,"time_ms":1701245648053,"channel":"futures.order_book_update","event":"update","result":{"U":53095235561,"a":[{"p":"38174.3","s":0},{"p":"38152.8","s":654},{"p":"38145.6","s":0},{"p":"38166.7","s":0},{"p":"38175.2","s":0},{"p":"38160","s":0},{"p":"38170.5","s":0}],"b":[{"p":"38143.5","s":1049},{"p":"38143.8","s":0},{"p":"38141.3","s":2},{"p":"38128.2","s":0},{"p":"38124.1","s":0},{"p":"38146.5","s":41927},{"p":"38145.6","s":988},{"p":"38143.7","s":2698},{"p":"38124.4","s":0},{"p":"38132","s":0},{"p":"38145.5","s":154462},{"p":"38140.6","s":0},{"p":"38139.9","s":0}],"s":"BTC_USDT","t":1701245648038,"u":53095235604}}
{"time":1701245648,"time_ms":1701245648072,"channel":"futures.order_book_update","event":"update","result":{"U":53095235605,"a":[{"p":"38152.9","s":3623},{"p":"38146.6","s":13196},{"p":"38150.4","s":0},{"p":"38164","s":0},{"p":"38160","s":0},{"p":"38153","s":0},{"p":"38150.9","s":3617},{"p":"38150.5","s":40},{"p":"38153.2","s":0},{"p":"38152.2","s":4541},{"p":"38149.5","s":0}],"b":[{"p":"38144.6","s":0},{"p":"38141.3","s":0},{"p":"38140","s":0},{"p":"38140.6","s":0},{"p":"38146.5","s":196244},{"p":"38143.3","s":2907},{"p":"38144.4","s":15000},{"p":"38125.3","s":0},{"p":"38143.5","s":316},{"p":"38141.6","s":6778},{"p":"38128.2","s":0},{"p":"38127.3","s":0},{"p":"38119.2","s":0},{"p":"38145.6","s":28488},{"p":"38145","s":200},{"p":"38109.3","s":0},{"p":"38136.7","s":0},{"p":"38141","s":0},{"p":"38144.5","s":18006},{"p":"38139.1","s":0},{"p":"38144","s":0},{"p":"38145.5","s":43036},{"p":"38138.6","s":0},{"p":"38136","s":0},{"p":"38143.7","s":524},{"p":"38142.6","s":26},{"p":"38141.4","s":0}],"s":"BTC_USDT","t":1701245648060,"u":53095235836}}
{"time":1701245648,"time_ms":1701245648093,"channel":"futures.order_book_update","event":"update","result":{"U":53095235837,"a":[{"p":"38176.2","s":0},{"p":"38165","s":0},{"p":"38186.6","s":0},{"p":"38161.5","s":0},{"p":"38161.9","s":0},{"p":"38184.7","s":0},{"p":"38163.8","s":0}],"b":[{"p":"38143.3","s":0},{"p":"38141.3","s":0},{"p":"38140.7","s":0},{"p":"38145.6","s":988},{"p":"38146.5","s":194288},{"p":"38110.1","s":0},{"p":"38131.1","s":0},{"p":"38129.1","s":0},{"p":"38141.4","s":6514},{"p":"38145.5","s":42381},{"p":"38109","s":0},{"p":"38143","s":0},{"p":"38141.6","s":6778},{"p":"38136.9","s":0},{"p":"38099.9","s":0},{"p":"38144.5","s":9007},{"p":"38142","s":6},{"p":"38141.7","s":2268},{"p":"38138.2","s":0}],"s":"BTC_USDT","t":1701245648084,"u":53095235876}}
{"time":1701245648,"time_ms":1701245648112,"channel":"futures.order_book_update","event":"update","result":{"U":53095235877,"a":[],"b":[{"p":"38146.5","s":185302},{"p":"38142","s":2913},{"p":"38111.3","s":0}],"s":"BTC_USDT","t":1701245648094,"u":53095235886}}
{"time":1701245648,"time_ms":1701245648131,"channel":"futures.order_book_update","event":"update","result":{"U":53095235887,"a":[],"b":[{"p":"38143","s":2174},{"p":"38142","s":739},{"p":"38141.4","s":0},{"p":"38132.9","s":0},{"p":"38141.6","s":13980}],"s":"BTC_USDT","t":1701245648116,"u":53095235893}}
{"time":1701245648,"time_ms":1701245648153,"channel":"futures.order_book_update","event":"update","result":{"U":53095235894,"a":[],"b":[{"p":"38142","s":2913},{"p":"38143.5","s":1273},{"p":"38141.4","s":6514},{"p":"38143","s":0}],"s":"BTC_USDT","t":1701245648133,"u":53095235897}}
{"time":1701245648,"time_ms":1701245648174,"channel":"futures.order_book_update","event":"update","result":{"U":53095235898,"a":[],"b":[{"p":"38143.5","s":316},{"p":"38101.1","s":0},{"p":"38102.5","s":0}],"s":"BTC_USDT","t":1701245648163,"u":53095235901}}
{"time":1701245648,"time_ms":1701245648191,"channel":"futures.order_book_update","event":"update","result":{"U":53095235902,"a":[],"b":[{"p":"38136.9","s":0}],"s":"BTC_USDT","t":1701245648173,"u":53095235902}}
{"time":1701245648,"time_ms":1701245648212,"channel":"futures.order_book_update","event":"update","result":{"U":53095235903,"a":[],"b":[{"p":"38138.5","s":0},{"p":"38142","s":739},{"p":"38143","s":2174},{"p":"38141.4","s":0}],"s":"BTC_USDT","t":1701245648192,"u":53095235905}}
{"time":1701245648,"time_ms":1701245648234,"channel":"futures.order_book_update","event":"update","result":{"U":53095235906,"a":[],"b":[{"p":"38143.5","s":1274},{"p":"38103.7","s":0}],"s":"BTC_USDT","t":1701245648213,"u":53095235908}}
{"time":1701245648,"time_ms":1701245648271,"channel":"futures.order_book_update","event":"update","result":{"U":53095235909,"a":[{"p":"38171","s":0}],"b":[],"s":"BTC_USDT","t":1701245648253,"u":53095235910}}
{"time":1701245648,"time_ms":1701245648293,"channel":"futures.order_book_update","event":"update","result":{"U":53095235911,"a":[{"p":"38154.7","s":0}],"b":[],"s":"BTC_USDT","t":1701245648265,"u":53095235911}}
{"time":1701245648,"time_ms":1701245648312,"channel":"futures.order_book_update","event":"update","result":{"U":53095235912,"a":[{"p":"38170","s":0}],"b":[],"s":"BTC_USDT","t":1701245648293,"u":53095235917}}
{"time":1701245648,"time_ms":1701245648392,"channel":"futures.order_book_update","event":"update","result":{"U":53095235918,"a":[{"p":"38162.5","s":0},{"p":"38156.8","s":0},{"p":"38157.9","s":0},{"p":"38161.9","s":0},{"p":"38153","s":34},{"p":"38146.6","s":16622},{"p":"38152","s":1706},{"p":"38152.8","s":0},{"p":"38156.4","s":0},{"p":"38156","s":0}],"b":[{"p":"38137.9","s":0},{"p":"38142.4","s":2620},{"p":"38142.1","s":2174},{"p":"38142","s":3205},{"p":"38135.9","s":0},{"p":"38138.9","s":0},{"p":"38093","s":0},{"p":"38141.7","s":94},{"p":"38143","s":0},{"p":"38143.6","s":0},{"p":"38141.4","s":0}],"s":"BTC_USDT","t":1701245648382,"u":53095235950}}
{"time":1701245648,"time_ms":1701245648412,"channel":"futures.order_book_update","event":"update","result":{"U":53095235951,"a":[{"p":"38146.6","s":17572},{"p":"38158.2","s":0}],"b":[{"p":"38143.5","s":316},{"p":"38138.8","s":0}],"s":"BTC_USDT","t":1701245648393,"u":53095235959}}
{"time":1701245648,"time_ms":1701245648451,"channel":"futures.order_book_update","event":"update","result":{"U":53095235960,"a":[{"p":"38155.8","s":0}],"b":[],"s":"BTC_USDT","t":1701245648436,"u":53095235961}}
{"time":1701245648,"time_ms":1701245648472,"channel":"futures.order_book_update","event":"update","result":{"U":53095235962,"a":[{"p":"38146.6","s":17072}],"b":[],"s":"BTC_USDT","t":1701245648451,"u":53095235963}}
{"time":1701245648,"time_ms":1701245648513,"channel":"futures.order_book_update","event":"update","result":{"U":53095235964,"a":[],"b":[{"p":"38141.5","s":0}],"s":"BTC_USDT","t":1701245648493,"u":53095235964}}
{"time":1701245648,"time_ms":1701245648533,"channel":"futures.order_book_update","event":"update","result":{"U":53095235965,"a":[],"b":[{"p":"38142","s":3199},{"p":"38141.3","s":0}],"s":"BTC_USDT","t":1701245648521,"u":53095235970}}
{"time":1701245648,"time_ms":1701245648611,"channel":"futures.order_book_update","event":"update","result":{"U":53095235971,"a":[],"b":[{"p":"38139.1","s":0},{"p":"38134","s":0}],"s":"BTC_USDT","t":1701245648602,"u":53095235977}}
{"time":1701245648,"time_ms":1701245648631,"channel":"futures.order_book_update","event":"update","result":{"U":53095235978,"a":[],"b":[{"p":"38141.4","s":0},{"p":"38140.7","s":0}],"s":"BTC_USDT","t":1701245648623,"u":53095235982}}
{"time":1701245648,"time_ms":1701245648680,"channel":"futures.order_book_update","event":"update","result":{"U":53095235983,"a":[{"p":"38146.6","s":17572},{"p":"38164.5","s":0},{"p":"38160.5","s":0}],"b":[],"s":"BTC_USDT","t":1701245648646,"u":53095235990}}
{"time":1701245648,"time_ms":1701245648752,"channel":"futures.order_book_update","event":"update","result":{"U":53095235991,"a":[],"b":[{"p":"38140.7","s":0},{"p":"38141.4","s":0}],"s":"BTC_USDT","t":1701245648734,"u":53095235995}}
{"time":1701245648,"time_ms":1701245648772,"channel":"futures.order_book_update","event":"update","result":{"U":53095235996,"a":[],"b":[{"p":"38137.5","s":0}],"s":"BTC_USDT","t":1701245648744,"u":53095235996}}
{"time":1701245648,"time_ms":1701245648792,"channel":"futures.order_book_update","event":"update","result":{"U":53095235997,"a":[{"p":"38146.6","s":17072}],"b":[],"s":"BTC_USDT","t":1701245648781,"u":53095236001}}
{"time":1701245648,"time_ms":1701245648851,"channel":"futures.order_book_update","event":"update","result":{"U":53095236002,"a":[{"p":"38157.5","s":0}],"b":[],"s":"BTC_USDT","t":1701245648833,"u":53095236003}}
{"time":1701245648,"time_ms":1701245648930,"channel":"futures.order_book_update","event":"update","result":{"U":53095236004,"a":[{"p":"38154.7","s":0}],"b":[],"s":"BTC_USDT","t":1701245648919,"u":53095236011}}
{"time":1701245649,"time_ms":1701245649013,"channel":"futures.order_book_update","event":"update","result":{"U":53095236012,"a":[{"p":"38158.4","s":0}],"b":[{"p":"38141.5","s":1315},{"p":"38142.1","s":0}],"s":"BTC_USDT","t":1701245649007,"u":53095236020}}
{"time":1701245649,"time_ms":1701245649032,"channel":"futures.order_book_update","event":"update","result":{"U":53095236021,"a":[{"p":"38156.2","s":0},{"p":"38173.4","s":0}],"b":[{"p":"38142.5","s":4595},{"p":"38141.7","s":2268},{"p":"38142","s":733},{"p":"38141.5","s":0},{"p":"38136.5","s":0},{"p":"38141.1","s":0}],"s":"BTC_USDT","t":1701245649018,"u":53095236031}}
{"time":1701245649,"time_ms":1701245649052,"channel":"futures.order_book_update","event":"update","result":{"U":53095236032,"a":[{"p":"38147.2","s":74},{"p":"38158","s":0},{"p":"38166.8","s":0},{"p":"38156.4","s":0},{"p":"38153","s":0},{"p":"38156.8","s":0},{"p":"38154.7","s":0},{"p":"38156.7","s":0},{"p":"38156.3","s":0}],"b":[{"p":"38142.2","s":2907},{"p":"38141.7","s":94},{"p":"38141.5","s":0},{"p":"38137.1","s":0},{"p":"38136.6","s":0},{"p":"38142.5","s":2421},{"p":"38143","s":2759},{"p":"38143.5","s":0},{"p":"38142","s":0}],"s":"BTC_USDT","t":1701245649037,"u":53095236057}}
{"time":1701245649,"time_ms":1701245649073,"channel":"futures.order_book_update","event":"update","result":{"U":53095236058,"a":[],"b":[{"p":"38140.7","s":0},{"p":"38141.4","s":0},{"p":"38141.3","s":0},{"p":"38146.5","s":157802},{"p":"38143","s":1455},{"p":"38141.5","s":0}],"s":"BTC_USDT","t":1701245649054,"u":53095236067}}
{"time":1701245649,"time_ms":1701245649092,"channel":"futures.order_book_update","event":"update","result":{"U":53095236068,"a":[{"p":"38160.9","s":0}],"b":[{"p":"38142","s":6},{"p":"38141.6","s":0}],"s":"BTC_USDT","t":1701245649083,"u":53095236073}}
{"time":1701245649,"time_ms":1701245649112,"channel":"futures.order_book_update","event":"update","result":{"U":53095236074,"a":[],"b":[{"p":"38142.5","s":733},{"p":"38143.1","s":2304},{"p":"38142.6","s":2200},{"p":"38142.2","s":0},{"p":"38141.7","s":94}],"s":"BTC_USDT","t":1701245649094,"u":53095236079}}
{"time":1701245649,"time_ms":1701245649131,"channel":"futures.order_book_update","event":"update","result":{"U":53095236080,"a":[],"b":[{"p":"38143.5","s":1386},{"p":"38143","s":0},{"p":"38141.6","s":0}],"s":"BTC_USDT","t":1701245649114,"u":53095236083}}
{"time":1701245649,"time_ms":1701245649212,"channel":"futures.order_book_update","event":"update","result":{"U":53095236084,"a":[],"b":[{"p":"38142.7","s":2376},{"p":"38143.1","s":0},{"p":"38141.6","s":0}],"s":"BTC_USDT","t":1701245649194,"u":53095236086}}
{"time":1701245649,"time_ms":1701245649333,"channel":"futures.order_book_update","event":"update","result":{"U":53095236087,"a":[{"p":"38157.7","s":0},{"p":"38154.7","s":0}],"b":[],"s":"BTC_USDT","t":1701245649310,"u":53095236090}}
{"time":1701245649,"time_ms":1701245649371,"channel":"futures.order_book_update","event":"update","result":{"U":53095236091,"a":[],"b":[{"p":"38141.3","s":0},{"p":"38141.6","s":0},{"p":"38142","s":4}],"s":"BTC_USDT","t":1701245649364,"u":53095236098}}
{"time":1701245649,"time_ms":1701245649413,"channel":"futures.order_book_update","event":"update","result":{"U":53095236099,"a":[],"b":[{"p":"38142","s":2},{"p":"38141.3","s":0}],"s":"BTC_USDT","t":1701245649394,"u":53095236102}}
{"time":1701245649,"time_ms":1701245649433,"channel":"futures.order_book_update","event":"update","result":{"U":53095236103,"a":[],"b":[{"p":"38142.5","s":0},{"p":"38141.6","s":13980},{"p":"38142","s":735}],"s":"BTC_USDT","t":1701245649426,"u":53095236106}}
{"time":1701245649,"time_ms":1701245649453,"channel":"futures.order_book_update","event":"update","result":{"U":53095236107,"a":[],"b":[{"p":"38142","s":739}],"s":"BTC_USDT","t":1701245649436,"u":53095236109}}
{"time":1701245649,"time_ms":1701245649632,"channel":"futures.order_book_update","event":"update","result":{"U":53095236110,"a":[],"b":[{"p":"38142.5","s":733},{"p":"38142","s":6},{"p":"38141.6","s":0}],"s":"BTC_USDT","t":1701245649608,"u":53095236111}}
{"time":1701245649,"time_ms":1701245649692,"channel":"futures.order_book_update","event":"update","result":{"U":53095236112,"a":[{"p":"38157.7","s":0},{"p":"38161.1","s":0},{"p":"38156.2","s":0},{"p":"38156.8","s":0},{"p":"38160.3","s":0}],"b":[{"p":"38137.1","s":0},{"p":"38141.6","s":0},{"p":"38142.1","s":2907},{"p":"38142.6","s":26},{"p":"38142.5","s":0}],"s":"BTC_USDT","t":1701245649680,"u":53095236131}}
{"time":1701245649,"time_ms":1701245649811,"channel":"futures.order_book_update","event":"update","result":{"U":53095236132,"a":[],"b":[{"p":"38141.3","s":0},{"p":"38141.6","s":13980},{"p":"38142","s":0}],"s":"BTC_USDT","t":1701245649801,"u":53095236135}}
{"time":1701245649,"time_ms":1701245649873,"channel":"futures.order_book_update","event":"update","result":{"U":53095236136,"a":[{"p":"38160","s":0},{"p":"38164","s":0}],"b":[],"s":"BTC_USDT","t":1701245649862,"u":53095236144}}
{"time":1701245649,"time_ms":1701245649932,"channel":"futures.order_book_update","event":"update","result":{"U":53095236145,"a":[],"b":[{"p":"38143","s":2174},{"p":"38142.1","s":733},{"p":"38141.6","s":0}],"s":"BTC_USDT","t":1701245649919,"u":53095236146}}
{"time":1701245649,"time_ms":1701245649973,"channel":"futures.order_book_update","event":"update","result":{"U":53095236147,"a":[{"p":"38154.7","s":0}],"b":[],"s":"BTC_USDT","t":1701245649964,"u":53095236147}}
{"time":1701245649,"time_ms":1701245649992,"channel":"futures.order_book_update","event":"update","result":{"U":53095236148,"a":[{"p":"38146.6","s":15122},{"p":"38157.5","s":0}],"b":[],"s":"BTC_USDT","t":1701245649973,"u":53095236153}}
{"time":1701245650,"time_ms":1701245650012,"channel":"futures.order_book_update","event":"update","result":{"U":53095236154,"a":[{"p":"38160.5","s":0},{"p":"38164.5","s":0}],"b":[],"s":"BTC_USDT","t":1701245649998,"u":53095236158}}
{"time":1701245650,"time_ms":1701245650031,"channel":"futures.order_book_update","event":"update","result":{"U":53095236159,"a":[{"p":"38173","s":0},{"p":"38158","s":0}],"b":[{"p":"38143.1","s":2295},{"p":"38142.7","s":0},{"p":"38141.5","s":0},{"p":"38141.6","s":0},{"p":"38141.7","s":2268}],"s":"BTC_USDT","t":1701245650010,"u":53095236166}}
{"time":1701245650,"time_ms":1701245650052,"channel":"futures.order_book_update","event":"update","result":{"U":53095236167,"a":[{"p":"38146.6","s":21622},{"p":"38161.1","s":0},{"p":"38157.9","s":0}],"b":[{"p":"38143","s":0},{"p":"38136.8","s":0},{"p":"38141.6","s":0},{"p":"38142.5","s":733},{"p":"38142.8","s":2174},{"p":"38142.1","s":0}],"s":"BTC_USDT","t":1701245650044,"u":53095236177}}
{"time":1701245650,"time_ms":1701245650091,"channel":"futures.order_book_update","event":"update","result":{"U":53095236178,"a":[{"p":"38157.7","s":0}],"b":[],"s":"BTC_USDT","t":1701245650071,"u":53095236179}}
{"time":1701245650,"time_ms":1701245650111,"channel":"futures.order_book_update","event":"update","result":{"U":53095236180,"a":[],"b":[{"p":"38142.6","s":2200},{"p":"38141.6","s":13980},{"p":"38142.8","s":0},{"p":"38143.1","s":0},{"p":"38142.9","s":2857},{"p":"38141.5","s":1315}],"s":"BTC_USDT","t":1701245650096,"u":53095236183}}
{"time":1701245650,"time_ms":1701245650218,"channel":"futures.order_book_update","event":"update","result":{"U":53095236184,"a":[],"b":[{"p":"38141.5","s":0},{"p":"38142.7","s":2368},{"p":"38142.9","s":525}],"s":"BTC_USDT","t":1701245650209,"u":53095236186}}
{"time":1701245650,"time_ms":1701245650272,"channel":"futures.order_book_update","event":"update","result":{"U":53095236187,"a":[],"b":[{"p":"38118.2","s":0}],"s":"BTC_USDT","t":1701245650257,"u":53095236189}}
{"time":1701245650,"time_ms":1701245650293,"channel":"futures.order_book_update","event":"update","result":{"U":53095236190,"a":[{"p":"38156.2","s":0},{"p":"38165","s":0},{"p":"38161","s":0}],"b":[{"p":"38141.7","s":94},{"p":"38051.9","s":0},{"p":"38053.4","s":0},{"p":"38048.6","s":0}],"s":"BTC_USDT","t":1701245650286,"u":53095236200}}
{"time":1701245650,"time_ms":1701245650311,"channel":"futures.order_book_update","event":"update","result":{"U":53095236201,"a":[{"p":"38160.9","s":0},{"p":"38160.5","s":0},{"p":"38155.9","s":0}],"b":[{"p":"38141.5","s":3489},{"p":"38142.5","s":0},{"p":"38142","s":0},{"p":"38137.1","s":0},{"p":"38137.4","s":0},{"p":"38054.9","s":0}],"s":"BTC_USDT","t":1701245650296,"u":53095236216}}
{"time":1701245650,"time_ms":1701245650334,"channel":"futures.order_book_update","event":"update","result":{"U":53095236217,"a":[],"b":[{"p":"38141.5","s":0},{"p":"38142.5","s":733}],"s":"BTC_USDT","t":1701245650302,"u":53095236219}}
{"time":1701245650,"time_ms":1701245650373,"channel":"futures.order_book_update","event":"update","result":{"U":53095236220,"a":[{"p":"38146.6","s":17072}],"b":[],"s":"BTC_USDT","t":1701245650353,"u":53095236224}}
{"time":1701245650,"time_ms":1701245650476,"channel":"futures.order_book_update","event":"update","result":{"U":53095236225,"a":[],"b":[{"p":"38140.7","s":0},{"p":"38140","s":0}],"s":"BTC_USDT","t":1701245650459,"u":53095236230}}
{"time":1701245650,"time_ms":1701245650492,"channel":"futures.order_book_update","event":"update","result":{"U":53095236231,"a":[{"p":"38157.7","s":0},{"p":"38156.1","s":0}],"b":[{"p":"38142.6","s":26},{"p":"38142","s":2174},{"p":"38141.6","s":0},{"p":"38141.5","s":0}],"s":"BTC_USDT","t":1701245650486,"u":53095236247}}
{"time":1701245650,"time_ms":1701245650512,"channel":"futures.order_book_update","event":"update","result":{"U":53095236248,"a":[{"p":"38156.8","s":0},{"p":"38152","s":1052},{"p":"38146.6","s":15122},{"p":"38152.9","s":0},{"p":"38160.9","s":0},{"p":"38158.2","s":0},{"p":"38172.9","s":0},{"p":"38158","s":0},{"p":"38152.6","s":654},{"p":"38157.9","s":0}],"b":[{"p":"38143.2","s":2620},{"p":"38143.5","s":3560},{"p":"38143.6","s":2309},{"p":"38142.7","s":0},{"p":"38142.4","s":0},{"p":"38141.5","s":0},{"p":"38137.4","s":0},{"p":"38141.6","s":0}],"s":"BTC_USDT","t":1701245650494,"u":53095236272}}
{"time":1701245650,"time_ms":1701245650532,"channel":"futures.order_book_update","event":"update","result":{"U":53095236273,"a":[{"p":"38157.5","s":0},{"p":"38161.3","s":0}],"b":[],"s":"BTC_USDT","t":1701245650505,"u":53095236276}}
{"time":1701245650,"time_ms":1701245650552,"channel":"futures.order_book_update","event":"update","result":{"U":53095236277,"a":[{"p":"38153.3","s":0},{"p":"38160.5","s":0},{"p":"38164.5","s":0}],"b":[],"s":"BTC_USDT","t":1701245650541,"u":53095236284}}
{"time":1701245650,"time_ms":1701245650573,"channel":"futures.order_book_update","event":"update","result":{"U":53095236285,"a":[{"p":"38156.7","s":0}],"b":[],"s":"BTC_USDT","t":1701245650560,"u":53095236287}}
{"time":1701245650,"time_ms":1701245650611,"channel":"futures.order_book_update","event":"update","result":{"U":53095236288,"a":[],"b":[{"p":"38134.3","s":0}],"s":"BTC_USDT","t":1701245650591,"u":53095236288}}
{"time":1701245650,"time_ms":1701245650672,"channel":"futures.order_book_update","event":"update","result":{"U":53095236289,"a":[{"p":"38152.9","s":3623},{"p":"38148","s":0}],"b":[],"s":"BTC_USDT","t":1701245650658,"u":53095236289}}
{"time":1701245650,"time_ms":1701245650712,"channel":"futures.order_book_update","event":"update","result":{"U":53095236290,"a":[],"b":[{"p":"38140.5","s":0},{"p":"38139.9","s":0}],"s":"BTC_USDT","t":1701245650697,"u":53095236294}}
{"time":1701245650,"time_ms":1701245650733,"channel":"futures.order_book_update","event":"update","result":{"U":53095236295,"a":[],"b":[{"p":"38142","s":2180},{"p":"38131.8","s":0}],"s":"BTC_USDT","t":1701245650709,"u":53095236299}}
{"time":1701245650,"time_ms":1701245650813,"channel":"futures.order_book_update","event":"update","result":{"U":53095236300,"a":[],"b":[{"p":"38127","s":0}],"s":"BTC_USDT","t":1701245650797,"u":53095236302}}
{"time":1701245650,"time_ms":1701245650871,"channel":"futures.order_book_update","event":"update","result":{"U":53095236303,"a":[{"p":"38146.6","s":15572}],"b":[],"s":"BTC_USDT","t":1701245650852,"u":53095236303}}
{"time":1701245650,"time_ms":1701245650972,"channel":"futures.order_book_update","event":"update","result":{"U":53095236304,"a":[],"b":[{"p":"38104.2","s":0}],"s":"BTC_USDT","t":1701245650958,"u":53095236306}}
{"time":1701245651,"time_ms":1701245651013,"channel":"futures.order_book_update","event":"update","result":{"U":53095236307,"a":[{"p":"38157","s":0}],"b":[{"p":"38143","s":733},{"p":"38142.5","s":0},{"p":"38141.6","s":0}],"s":"BTC_USDT","t":1701245651004,"u":53095236311}}
{"time":1701245651,"time_ms":1701245651034,"channel":"futures.order_book_update","event":"update","result":{"U":53095236312,"a":[{"p":"38158","s":0},{"p":"38161.9","s":0},{"p":"38158.5","s":0}],"b":[{"p":"38143.5","s":1386},{"p":"38143.6","s":4483}],"s":"BTC_USDT","t":1701245651023,"u":53095236318}}
{"time":1701245651,"time_ms":1701245651053,"channel":"futures.order_book_update","event":"update","result":{"U":53095236319,"a":[{"p":"38158.5","s":0},{"p":"38173.5","s":0}],"b":[{"p":"38135.4","s":0}],"s":"BTC_USDT","t":1701245651029,"u":53095236324}}
{"time":1701245651,"time_ms":1701245651112,"channel":"futures.order_book_update","event":"update","result":{"U":53095236325,"a":[{"p":"38157.6","s":0}],"b":[{"p":"38135.9","s":0},{"p":"38141.6","s":0},{"p":"38143.3","s":4498},{"p":"38142.1","s":733},{"p":"38143.6","s":0},{"p":"38143","s":0},{"p":"38142.6","s":26},{"p":"38141.7","s":94}],"s":"BTC_USDT","t":1701245651095,"u":53095236336}}
{"time":1701245651,"time_ms":1701245651133,"channel":"futures.order_book_update","event":"update","result":{"U":53095236337,"a":[{"p":"38158.4","s":0},{"p":"38156.8","s":0},{"p":"38153","s":0},{"p":"38151.9","s":654},{"p":"38152.6","s":0},{"p":"38146.6","s":15572}],"b":[{"p":"38142","s":6},{"p":"38142.1","s":2907},{"p":"38141.7","s":2268},{"p":"38141.6","s":13980},{"p":"38143.3","s":0}],"s":"BTC_USDT","t":1701245651124,"u":53095236355}}
{"time":1701245651,"time_ms":1701245651151,"channel":"futures.order_book_update","event":"update","result":{"U":53095236356,"a":[{"p":"38157.4","s":0},{"p":"38161.5","s":0}],"b":[{"p":"38142.1","s":5362},{"p":"38138.2","s":0}],"s":"BTC_USDT","t":1701245651130,"u":53095236363}}
{"time":1701245651,"time_ms":1701245651173,"channel":"futures.order_book_update","event":"update","result":{"U":53095236364,"a":[{"p":"38158.2","s":0}],"b":[{"p":"38137.5","s":0}],"s":"BTC_USDT","t":1701245651152,"u":53095236367}}
{"time":1701245651,"time_ms":1701245651193,"channel":"futures.order_book_update","event":"update","result":{"U":53095236368,"a":[],"b":[{"p":"38138.8","s":0}],"s":"BTC_USDT","t":1701245651178,"u":53095236369}}
{"time":1701245651,"time_ms":1701245651291,"channel":"futures.order_book_update","event":"update","result":{"U":53095236370,"a":[{"p":"38155.9","s":0}],"b":[{"p":"38142.1","s":3188},{"p":"38143","s":2174},{"p":"38141.6","s":0}],"s":"BTC_USDT","t":1701245651281,"u":53095236373}}
{"time":1701245651,"time_ms":1701245651352,"channel":"futures.order_book_update","event":"update","result":{"U":53095236374,"a":[{"p":"38168.4","s":0},{"p":"38157.5","s":0}],"b":[],"s":"BTC_USDT","t":1701245651338,"u":53095236379}}
{"time":1701245651,"time_ms":1701245651412,"channel":"futures.order_book_update","event":"update","result":{"U":53095236380,"a":[],"b":[{"p":"38143.1","s":2311},{"p":"38142.1","s":733},{"p":"38141.7","s":0}],"s":"BTC_USDT","t":1701245651388,"u":53095236383}}
{"time":1701245651,"time_ms":1701245651432,"channel":"futures.order_book_update","event":"update","result":{"U":53095236384,"a":[],"b":[{"p":"38146.5","s":157276},{"p":"38141.2","s":0}],"s":"BTC_USDT","t":1701245651423,"u":53095236386}}
{"time":1701245651,"time_ms":1701245651452,"channel":"futures.order_book_update","event":"update","result":{"U":53095236387,"a":[{"p":"38149.5","s":600},{"p":"38152.9","s":0},{"p":"38156.2","s":0},{"p":"38154.7","s":0},{"p":"38155.8","s":0}],"b":[{"p":"38142.2","s":2425},{"p":"38143.1","s":0},{"p":"38141.7","s":0},{"p":"38143","s":2174}],"s":"BTC_USDT","t":1701245651444,"u":53095236401}}
{"time":1701245651,"time_ms":1701245651475,"channel":"futures.order_book_update","event":"update","result":{"U":53095236402,"a":[],"b":[{"p":"38142.2","s":4599},{"p":"38141.7","s":94},{"p":"38143","s":0}],"s":"BTC_USDT","t":1701245651461,"u":53095236403}}
{"time":1701245651,"time_ms":1701245651498,"channel":"futures.order_book_update","event":"update","result":{"U":53095236404,"a":[],"b":[{"p":"38142","s":0},{"p":"38141.3","s":0},{"p":"38141.6","s":13980}],"s":"BTC_USDT","t":1701245651485,"u":53095236407}}
{"time":1701245651,"time_ms":1701245651533,"channel":"futures.order_book_update","event":"update","result":{"U":53095236408,"a":[],"b":[{"p":"38142.8","s":2},{"p":"38142.1","s":735},{"p":"38141.6","s":0}],"s":"BTC_USDT","t":1701245651519,"u":53095236411}}
{"time":1701245651,"time_ms":1701245651632,"channel":"futures.order_book_update","event":"update","result":{"U":53095236412,"a":[],"b":[{"p":"38140.2","s":0},{"p":"38141.6","s":13980},{"p":"38142.1","s":733},{"p":"38142.8","s":0},{"p":"38141.3","s":0}],"s":"BTC_USDT","t":1701245651607,"u":53095236415}}
{"time":1701245651,"time_ms":1701245651653,"channel":"futures.order_book_update","event":"update","result":{"U":53095236416,"a":[{"p":"38160.9","s":0}],"b":[{"p":"38142.1","s":735},{"p":"38142.9","s":527}],"s":"BTC_USDT","t":1701245651633,"u":53095236421}}
{"time":1701245651,"time_ms":1701245651672,"channel":"futures.order_book_update","event":"update","result":{"U":53095236422,"a":[{"p":"38148.3","s":208},{"p":"38152.7","s":0},{"p":"38154.7","s":0}],"b":[],"s":"BTC_USDT","t":1701245651654,"u":53095236425}}
{"time":1701245651,"time_ms":1701245651694,"channel":"futures.order_book_update","event":"update","result":{"U":53095236426,"a":[{"p":"38160","s":0},{"p":"38164","s":0}],"b":[],"s":"BTC_USDT","t":1701245651677,"u":53095236429}}
{"time":1701245651,"time_ms":1701245651714,"channel":"futures.order_book_update","event":"update","result":{"U":53095236430,"a":[{"p":"38160.3","s":0},{"p":"38161.4","s":0},{"p":"38156.1","s":0},{"p":"38160.9","s":0},{"p":"38152.7","s":15046},{"p":"38151.9","s":0},{"p":"38156.7","s":0}],"b":[{"p":"38142.3","s":2174},{"p":"38141.6","s":0},{"p":"38137.8","s":0},{"p":"38137.1","s":0},{"p":"38141.5","s":0},{"p":"38143.5","s":3689},{"p":"38142.2","s":2174},{"p":"38142.1","s":2}],"s":"BTC_USDT","t":1701245651704,"u":53095236447}}
{"time":1701245651,"time_ms":1701245651732,"channel":"futures.order_book_update","event":"update","result":{"U":53095236448,"a":[{"p":"38152.7","s":15700},{"p":"38157.7","s":0}],"b":[{"p":"38143.5","s":5863},{"p":"38143","s":733},{"p":"38142.2","s":0},{"p":"38141.7","s":94}],"s":"BTC_USDT","t":1701245651708,"u":53095236455}}
{"time":1701245651,"time_ms":1701245651811,"channel":"futures.order_book_update","event":"update","result":{"U":53095236456,"a":[{"p":"38146.6","s":13646}],"b":[],"s":"BTC_USDT","t":1701245651790,"u":53095236457}}
{"time":1701245651,"time_ms":1701245651833,"channel":"futures.order_book_update","event":"update","result":{"U":53095236458,"a":[],"b":[{"p":"38142.9","s":525},{"p":"38141.6","s":13980},{"p":"38142.1","s":0},{"p":"38141.3","s":0},{"p":"38140.2","s":0}],"s":"BTC_USDT","t":1701245651819,"u":53095236461}}
{"time":1701245651,"time_ms":1701245651874,"channel":"futures.order_book_update","event":"update","result":{"U":53095236462,"a":[{"p":"38161.4","s":0},{"p":"38157.5","s":0}],"b":[{"p":"38143","s":0},{"p":"38142.3","s":0},{"p":"38138.2","s":0},{"p":"38141.7","s":94},{"p":"38143.5","s":1386},{"p":"38143.1","s":2},{"p":"38142.4","s":5279},{"p":"38141.6","s":13982}],"s":"BTC_USDT","t":1701245651855,"u":53095236479}}
{"time":1701245651,"time_ms":1701245651993,"channel":"futures.order_book_update","event":"update","result":{"U":53095236480,"a":[{"p":"38163.8","s":0},{"p":"38160","s":0}],"b":[],"s":"BTC_USDT","t":1701245651971,"u":53095236483}}
{"time":1701245652,"time_ms":1701245652012,"channel":"futures.order_book_update","event":"update","result":{"U":53095236484,"a":[{"p":"38153.7","s":0},{"p":"38158","s":0}],"b":[{"p":"38137.5","s":0}],"s":"BTC_USDT","t":1701245652006,"u":53095236487}}
{"time":1701245652,"time_ms":1701245652035,"channel":"futures.order_book_update","event":"update","result":{"U":53095236488,"a":[{"p":"38158.2","s":0},{"p":"38173.4","s":0},{"p":"38156.5","s":0},{"p":"38156.6","s":0}],"b":[{"p":"38142.5","s":5271},{"p":"38142.4","s":2},{"p":"38141.6","s":0},{"p":"38135.5","s":0}],"s":"BTC_USDT","t":1701245652021,"u":53095236504}}
{"time":1701245652,"time_ms":1701245652051,"channel":"futures.order_book_update","event":"update","result":{"U":53095236505,"a":[],"b":[{"p":"38141.7","s":2268},{"p":"38143.5","s":0},{"p":"38141.5","s":0},{"p":"38143.3","s":3167}],"s":"BTC_USDT","t":1701245652040,"u":53095236508}}
{"time":1701245652,"time_ms":1701245652113,"channel":"futures.order_book_update","event":"update","result":{"U":53095236509,"a":[{"p":"38160.9","s":0},{"p":"38160.3","s":0}],"b":[],"s":"BTC_USDT","t":1701245652096,"u":53095236513}}
{"time":1701245652,"time_ms":1701245652131,"channel":"futures.order_book_update","event":"update","result":{"U":53095236514,"a":[{"p":"38160.3","s":0}],"b":[{"p":"38145.5","s":42306}],"s":"BTC_USDT","t":1701245652122,"u":53095236516}}
{"time":1701245652,"time_ms":1701245652154,"channel":"futures.order_book_update","event":"update","result":{"U":53095236517,"a":[{"p":"38160.3","s":0},{"p":"38160.9","s":0}],"b":[],"s":"BTC_USDT","t":1701245652137,"u":53095236519}}
{"time":1701245652,"time_ms":1701245652172,"channel":"futures.order_book_update","event":"update","result":{"U":53095236520,"a":[{"p":"38157.5","s":0}],"b":[],"s":"BTC_USDT","t":1701245652162,"u":53095236524}}
{"time":1701245652,"time_ms":1701245652194,"channel":"futures.order_book_update","event":"update","result":{"U":53095236525,"a":[{"p":"38164.5","s":0},{"p":"38171.4","s":0},{"p":"38155.8","s":0},{"p":"38167.6","s":0},{"p":"38175.2","s":0},{"p":"38160.5","s":0},{"p":"38175.3","s":0},{"p":"38160.1","s":0}],"b":[{"p":"38141.4","s":0},{"p":"38129.7","s":0},{"p":"38125.9","s":0},{"p":"38137.3","s":0},{"p":"38133.5","s":0}],"s":"BTC_USDT","t":1701245652170,"u":53095236540}}
{"time":1701245652,"time_ms":1701245652212,"channel":"futures.order_book_update","event":"update","result":{"U":53095236541,"a":[],"b":[{"p":"38141.7","s":0},{"p":"38142.5","s":3097},{"p":"38143","s":2174}],"s":"BTC_USDT","t":1701245652195,"u":53095236542}}
{"time":1701245652,"time_ms":1701245652231,"channel":"futures.order_book_update","event":"update","result":{"U":53095236543,"a":[],"b":[{"p":"38143.3","s":1864},{"p":"38141.7","s":0}],"s":"BTC_USDT","t":1701245652213,"u":53095236544}}
{"time":1701245652,"time_ms":1701245652293,"channel":"futures.order_book_update","event":"update","result":{"U":53095236545,"a":[{"p":"38152.7","s":15046},{"p":"38152","s":1706},{"p":"38157.7","s":0},{"p":"38162.2","s":0},{"p":"38156.8","s":0},{"p":"38155.3","s":0},{"p":"38155.9","s":0}],"b":[{"p":"38143","s":0},{"p":"38141.7","s":0},{"p":"38137.4","s":0},{"p":"38141.1","s":0},{"p":"38141.8","s":0},{"p":"38142","s":2174}],"s":"BTC_USDT","t":1701245652283,"u":53095236566}}
{"time":1701245652,"time_ms":1701245652313,"channel":"futures.order_book_update","event":"update","result":{"U":53095236567,"a":[{"p":"38156.8","s":0},{"p":"38156.2","s":0}],"b":[{"p":"38142.1","s":2460},{"p":"38142.5","s":733},{"p":"38143","s":2174},{"p":"38141.9","s":0},{"p":"38142","s":0},{"p":"38136.9","s":0},{"p":"38141.8","s":0}],"s":"BTC_USDT","t":1701245652295,"u":53095236576}}
{"time":1701245652,"time_ms":1701245652372,"channel":"futures.order_book_update","event":"update","result":{"U":53095236577,"a":[{"p":"38155.9","s":0}],"b":[],"s":"BTC_USDT","t":1701245652346,"u":53095236578}}
{"time":1701245652,"time_ms":1701245652412,"channel":"futures.order_book_update","event":"update","result":{"U":53095236579,"a":[],"b":[{"p":"38142.2","s":733},{"p":"38143.1","s":2297},{"p":"38141.9","s":3932},{"p":"38142.1","s":0},{"p":"38142.5","s":0}],"s":"BTC_USDT","t":1701245652394,"u":53095236582}}
{"time":1701245652,"time_ms":1701245652432,"channel":"futures.order_book_update","event":"update","result":{"U":53095236583,"a":[{"p":"38146.6","s":15572}],"b":[],"s":"BTC_USDT","t":1701245652420,"u":53095236585}}
{"time":1701245652,"time_ms":1701245652473,"channel":"futures.order_book_update","event":"update","result":{"U":53095236586,"a":[],"b":[{"p":"38142.4","s":0},{"p":"38141.6","s":0},{"p":"38140.5","s":0},{"p":"38143.1","s":2295},{"p":"38141.8","s":2174}],"s":"BTC_USDT","t":1701245652466,"u":53095236589}}
{"time":1701245652,"time_ms":1701245652506,"channel":"futures.order_book_update","event":"update","result":{"U":53095236590,"a":[],"b":[{"p":"38141.8","s":0},{"p":"38141.9","s":0},{"p":"38144","s":2},{"p":"38142.5","s":2},{"p":"38143.2","s":2622}],"s":"BTC_USDT","t":1701245652495,"u":53095236593}}
{"time":1701245652,"time_ms":1701245652532,"channel":"futures.order_book_update","event":"update","result":{"U":53095236594,"a":[{"p":"38153.1","s":0}],"b":[{"p":"38137.9","s":0}],"s":"BTC_USDT","t":1701245652509,"u":53095236595}}
{"time":1701245652,"time_ms":1701245652593,"channel":"futures.order_book_update","event":"update","result":{"U":53095236596,"a":[{"p":"38156.7","s":0},{"p":"38160.9","s":0},{"p":"38153.9","s":0},{"p":"38156.2","s":0}],"b":[{"p":"38143","s":0},{"p":"38141.3","s":0},{"p":"38141.7","s":0},{"p":"38141.9","s":0},{"p":"38144","s":2},{"p":"38137.5","s":0},{"p":"38142.3","s":2174},{"p":"38142","s":2477},{"p":"38143.1","s":0},{"p":"38143.2","s":2622},{"p":"38142.5","s":2},{"p":"38141.8","s":0}],"s":"BTC_USDT","t":1701245652585,"u":53095236620}}
{"time":1701245653,"time_ms":1701245653012,"channel":"futures.order_book_update","event":"update","result":{"U":53095236621,"a":[{"p":"38172.7","s":0},{"p":"38171.5","s":0},{"p":"38175.3","s":0},{"p":"38163.9","s":0},{"p":"38146.6","s":16072},{"p":"38159.9","s":0},{"p":"38157.7","s":0},{"p":"38156.1","s":0},{"p":"38160.1","s":0},{"p":"38167.7","s":0}],"b":[{"p":"38142.1","s":733},{"p":"38143.2","s":2620},{"p":"38141.7","s":94},{"p":"38144","s":0},{"p":"38142.5","s":0},{"p":"38137.7","s":0},{"p":"38126.3","s":0},{"p":"38141.5","s":0},{"p":"38141.3","s":0},{"p":"38141.9","s":3932},{"p":"38142","s":0},{"p":"38130.1","s":0},{"p":"38133.9","s":0},{"p":"38141.6","s":0},{"p":"38142.4","s":2330},{"p":"38142.2","s":0},{"p":"38135.2","s":0}],"s":"BTC_USDT","t":1701245653005,"u":53095236668}}
{"time":1701245653,"time_ms":1701245653032,"channel":"futures.order_book_update","event":"update","result":{"U":53095236669,"a":[],"b":[{"p":"38141.7","s":0},{"p":"38142.5","s":2},{"p":"38143.2","s":2622}],"s":"BTC_USDT","t":1701245653012,"u":53095236672}}
{"time":1701245653,"time_ms":1701245653053,"channel":"futures.order_book_update","event":"update","result":{"U":53095236673,"a":[{"p":"38146.6","s":15572},{"p":"38157.6","s":0}],"b":[],"s":"BTC_USDT","t":1701245653043,"u":53095236679}}
{"time":1701245653,"time_ms":1701245653072,"channel":"futures.order_book_update","event":"update","result":{"U":53095236680,"a":[{"p":"38146.6","s":16072}],"b":[{"p":"38144","s":2},{"p":"38141.9","s":0}],"s":"BTC_USDT","t":1701245653054,"u":53095236681}}
{"time":1701245653,"time_ms":1701245653091,"channel":"futures.order_book_update","event":"update","result":{"U":53095236682,"a":[{"p":"38156.8","s":0},{"p":"38159.8","s":0},{"p":"38156.2","s":0}],"b":[{"p":"38141.1","s":0}],"s":"BTC_USDT","t":1701245653081,"u":53095236689}}
{"time":1701245653,"time_ms":1701245653113,"channel":"futures.order_book_update","event":"update","result":{"U":53095236690,"a":[{"p":"38155.4","s":0},{"p":"38157","s":0},{"p":"38156.9","s":0}],"b":[{"p":"38142.3","s":0},{"p":"38141.9","s":3932},{"p":"38142.5","s":2176}],"s":"BTC_USDT","t":1701245653098,"u":53095236696}}
{"time":1701245653,"time_ms":1701245653133,"channel":"futures.order_book_update","event":"update","result":{"U":53095236697,"a":[],"b":[{"p":"38141.3","s":0}],"s":"BTC_USDT","t":1701245653121,"u":53095236699}}
{"time":1701245653,"time_ms":1701245653173,"channel":"futures.order_book_update","event":"update","result":{"U":53095236700,"a":[],"b":[{"p":"38143.2","s":2620},{"p":"38142.5","s":2174},{"p":"38141.7","s":94},{"p":"38144","s":0},{"p":"38141.3","s":0}],"s":"BTC_USDT","t":1701245653161,"u":53095236706}}
{"time":1701245653,"time_ms":1701245653213,"channel":"futures.order_book_update","event":"update","result":{"U":53095236707,"a":[],"b":[{"p":"38141.6","s":0},{"p":"38143.4","s":3111},{"p":"38142.6","s":28},{"p":"38142","s":2393},{"p":"38141.9","s":3934},{"p":"38142.4","s":0}],"s":"BTC_USDT","t":1701245653191,"u":53095236712}}
{"time":1701245653,"time_ms":1701245653231,"channel":"futures.order_book_update","event":"update","result":{"U":53095236713,"a":[],"b":[{"p":"38141.6","s":13980},{"p":"38142","s":0},{"p":"38142.6","s":2320}],"s":"BTC_USDT","t":1701245653205,"u":53095236714}}
{"time":1701245653,"time_ms":1701245653311,"channel":"futures.order_book_update","event":"update","result":{"U":53095236715,"a":[{"p":"38146.6","s":16572}],"b":[{"p":"38142.2","s":2174},{"p":"38142.5","s":0},{"p":"38141.5","s":0}],"s":"BTC_USDT","t":1701245653289,"u":53095236718}}
{"time":1701245653,"time_ms":1701245653409,"channel":"futures.order_book_update","event":"update","result":{"U":53095236719,"a":[],"b":[{"p":"38088.2","s":0}],"s":"BTC_USDT","t":1701245653379,"u":53095236719}}
{"time":1701245653,"time_ms":1701245653473,"channel":"futures.order_book_update","event":"update","result":{"U":53095236720,"a":[{"p":"38156.3","s":0}],"b":[{"p":"38143.4","s":3109},{"p":"38142.6","s":2318},{"p":"38137.1","s":0},{"p":"38140.7","s":0},{"p":"38141.9","s":3932}],"s":"BTC_USDT","t":1701245653462,"u":53095236729}}
{"time":1701245653,"time_ms":1701245653513,"channel":"futures.order_book_update","event":"update","result":{"U":53095236730,"a":[],"b":[{"p":"38141.9","s":3934},{"p":"38142.6","s":2320},{"p":"38143.4","s":3111}],"s":"BTC_USDT","t":1701245653496,"u":53095236735}}
{"time":1701245653,"time_ms":1701245653613,"channel":"futures.order_book_update","event":"update","result":{"U":53095236736,"a":[],"b":[{"p":"38135.2","s":0}],"s":"BTC_USDT","t":1701245653578,"u":53095236736}}
{"time":1701245653,"time_ms":1701245653633,"channel":"futures.order_book_update","event":"update","result":{"U":53095236737,"a":[],"b":[{"p":"38143.4","s":3109},{"p":"38141.9","s":3932},{"p":"38142.6","s":2318},{"p":"38140.7","s":0}],"s":"BTC_USDT","t":1701245653612,"u":53095236740}}
{"time":1701245653,"time_ms":1701245653674,"channel":"futures.order_book_update","event":"update","result":{"U":53095236741,"a":[{"p":"38156.4","s":0}],"b":[],"s":"BTC_USDT","t":1701245653665,"u":53095236744}}
{"time":1701245653,"time_ms":1701245653771,"channel":"futures.order_book_update","event":"update","result":{"U":53095236745,"a":[{"p":"38155.5","s":0},{"p":"38156.9","s":0}],"b":[{"p":"38141.1","s":0},{"p":"38141.7","s":2268}],"s":"BTC_USDT","t":1701245653761,"u":53095236749}}
{"time":1701245653,"time_ms":1701245653792,"channel":"futures.order_book_update","event":"update","result":{"U":53095236750,"a":[{"p":"38159.9","s":0}],"b":[],"s":"BTC_USDT","t":1701245653763,"u":53095236752}}
{"time":1701245653,"time_ms":1701245653812,"channel":"futures.order_book_update","event":"update","result":{"U":53095236753,"a":[{"p":"38171.5","s":0},{"p":"38154.7","s":0},{"p":"38160","s":0},{"p":"38164","s":0}],"b":[{"p":"38141.5","s":0},{"p":"38142.6","s":2320},{"p":"38143.4","s":3111},{"p":"38143","s":2174},{"p":"38141.9","s":3934},{"p":"38142.2","s":0}],"s":"BTC_USDT","t":1701245653800,"u":53095236762}}
{"time":1701245653,"time_ms":1701245653833,"channel":"futures.order_book_update","event":"update","result":{"U":53095236763,"a":[{"p":"38157.3","s":0}],"b":[{"p":"38137.4","s":0},{"p":"38142.7","s":733},{"p":"38142.1","s":0},{"p":"38141.5","s":0}],"s":"BTC_USDT","t":1701245653807,"u":53095236768}}
{"time":1701245653,"time_ms":1701245653911,"channel":"futures.order_book_update","event":"update","result":{"U":53095236769,"a":[],"b":[{"p":"38142.6","s":28},{"p":"38142","s":2475},{"p":"38141.6","s":0}],"s":"BTC_USDT","t":1701245653900,"u":53095236774}}
{"time":1701245653,"time_ms":1701245653931,"channel":"futures.order_book_update","event":"update","result":{"U":53095236775,"a":[{"p":"38154.1","s":0}],"b":[{"p":"38141.6","s":13980},{"p":"38143","s":0}],"s":"BTC_USDT","t":1701245653926,"u":53095236776}}
{"time":1701245653,"time_ms":1701245653952,"channel":"futures.order_book_update","event":"update","result":{"U":53095236777,"a":[{"p":"38160.9","s":0}],"b":[{"p":"38141.7","s":94},{"p":"38141.5","s":1315},{"p":"38142.7","s":0},{"p":"38138.2","s":0},{"p":"38142","s":5382}],"s":"BTC_USDT","t":1701245653930,"u":53095236785}}
{"time":1701245654,"time_ms":1701245654012,"channel":"futures.order_book_update","event":"update","result":{"U":53095236786,"a":[{"p":"38172.4","s":0},{"p":"38157.7","s":0}],"b":[{"p":"38142","s":2907},{"p":"38142.1","s":2398},{"p":"38141.5","s":0}],"s":"BTC_USDT","t":1701245654005,"u":53095236793}}
{"time":1701245654,"time_ms":1701245654033,"channel":"futures.order_book_update","event":"update","result":{"U":53095236794,"a":[{"p":"38155.8","s":0},{"p":"38159.8","s":0},{"p":"38156.8","s":0},{"p":"38157.5","s":0}],"b":[{"p":"38142.1","s":5305},{"p":"38141.5","s":1315},{"p":"38142","s":0}],"s":"BTC_USDT","t":1701245654023,"u":53095236807}}
{"time":1701245654,"time_ms":1701245654053,"channel":"futures.order_book_update","event":"update","result":{"U":53095236808,"a":[{"p":"38156.4","s":0}],"b":[{"p":"38146.5","s":157350}],"s":"BTC_USDT","t":1701245654041,"u":53095236817}}
{"time":1701245654,"time_ms":1701245654093,"channel":"futures.order_book_update","event":"update","result":{"U":53095236818,"a":[{"p":"38155.5","s":0}],"b":[{"p":"38143.4","s":3109},{"p":"38142.6","s":26},{"p":"38141.9","s":3932},{"p":"38140.7","s":0}],"s":"BTC_USDT","t":1701245654086,"u":53095236822}}
{"time":1701245654,"time_ms":1701245654133,"channel":"futures.order_book_update","event":"update","result":{"U":53095236823,"a":[],"b":[{"p":"38143.4","s":3111},{"p":"38142.6","s":28},{"p":"38141.9","s":3934}],"s":"BTC_USDT","t":1701245654116,"u":53095236827}}
{"time":1701245654,"time_ms":1701245654172,"channel":"futures.order_book_update","event":"update","result":{"U":53095236828,"a":[{"p":"38155.4","s":0}],"b":[],"s":"BTC_USDT","t":1701245654150,"u":53095236829}}
{"time":1701245654,"time_ms":1701245654191,"channel":"futures.order_book_update","event":"update","result":{"U":53095236830,"a":[{"p":"38156.8","s":0}],"b":[],"s":"BTC_USDT","t":1701245654171,"u":53095236831}}
{"time":1701245654,"time_ms":1701245654252,"channel":"futures.order_book_update","event":"update","result":{"U":53095236832,"a":[],"b":[{"p":"38133.7","s":0}],"s":"BTC_USDT","t":1701245654239,"u":53095236832}}
{"time":1701245654,"time_ms":1701245654312,"channel":"futures.order_book_update","event":"update","result":{"U":53095236833,"a":[],"b":[{"p":"38143.4","s":3109},{"p":"38142.6","s":26},{"p":"38140.7","s":0}],"s":"BTC_USDT","t":1701245654298,"u":53095236836}}
{"time":1701245654,"time_ms":1701245654332,"channel":"futures.order_book_update","event":"update","result":{"U":53095236837,"a":[],"b":[{"p":"38141.9","s":3932}],"s":"BTC_USDT","t":1701245654302,"u":53095236837}}
{"time":1701245654,"time_ms":1701245654353,"channel":"futures.order_book_update","event":"update","result":{"U":53095236838,"a":[],"b":[{"p":"38142.6","s":28},{"p":"38141.9","s":3934},{"p":"38143.4","s":3111}],"s":"BTC_USDT","t":1701245654339,"u":53095236841}}
{"time":1701245654,"time_ms":1701245654432,"channel":"futures.order_book_update","event":"update","result":{"U":53095236842,"a":[],"b":[{"p":"38141.3","s":0}],"s":"BTC_USDT","t":1701245654421,"u":53095236844}}
{"time":1701245654,"time_ms":1701245654452,"channel":"futures.order_book_update","event":"update","result":{"U":53095236845,"a":[{"p":"38156.7","s":0},{"p":"38156.3","s":0}],"b":[],"s":"BTC_USDT","t":1701245654443,"u":53095236849}}
{"time":1701245654,"time_ms":1701245654477,"channel":"futures.order_book_update","event":"update","result":{"U":53095236850,"a":[{"p":"38160","s":0},{"p":"38164","s":0}],"b":[{"p":"38146.5","s":160495},{"p":"38125.3","s":0},{"p":"38136.7","s":0}],"s":"BTC_USDT","t":1701245654447,"u":53095236856}}
{"time":1701245654,"time_ms":1701245654511,"channel":"futures.order_book_update","event":"update","result":{"U":53095236857,"a":[{"p":"38156.6","s":0}],"b":[],"s":"BTC_USDT","t":1701245654494,"u":53095236859}}
{"time":1701245654,"time_ms":1701245654552,"channel":"futures.order_book_update","event":"update","result":{"U":53095236860,"a":[{"p":"38157","s":0}],"b":[],"s":"BTC_USDT","t":1701245654546,"u":53095236860}}
{"time":1701245654,"time_ms":1701245654571,"channel":"futures.order_book_update","event":"update","result":{"U":53095236861,"a":[{"p":"38159.9","s":0},{"p":"38154.1","s":0}],"b":[],"s":"BTC_USDT","t":1701245654557,"u":53095236864}}
{"time":1701245654,"time_ms":1701245654591,"channel":"futures.order_book_update","event":"update","result":{"U":53095236865,"a":[{"p":"38157.3","s":0},{"p":"38164.5","s":0}],"b":[],"s":"BTC_USDT","t":1701245654581,"u":53095236871}}
{"time":1701245654,"time_ms":1701245654614,"channel":"futures.order_book_update","event":"update","result":{"U":53095236872,"a":[{"p":"38160.5","s":0}],"b":[],"s":"BTC_USDT","t":1701245654585,"u":53095236873}}
{"time":1701245654,"time_ms":1701245654697,"channel":"futures.order_book_update","event":"update","result":{"U":53095236874,"a":[{"p":"38160","s":0},{"p":"38155.5","s":0}],"b":[{"p":"38141.7","s":2268},{"p":"38141.1","s":0}],"s":"BTC_USDT","t":1701245654687,"u":53095236879}}
{"time":1701245654,"time_ms":1701245654732,"channel":"futures.order_book_update","event":"update","result":{"U":53095236880,"a":[],"b":[{"p":"38142.6","s":26},{"p":"38141.9","s":3932},{"p":"38143.4","s":3109},{"p":"38140.7","s":0}],"s":"BTC_USDT","t":1701245654714,"u":53095236883}}
{"time":1701245654,"time_ms":1701245654752,"channel":"futures.order_book_update","event":"update","result":{"U":53095236884,"a":[],"b":[{"p":"38144","s":2},{"p":"38141.6","s":0},{"p":"38141.5","s":0},{"p":"38142.5","s":2}],"s":"BTC_USDT","t":1701245654730,"u":53095236886}}
{"time":1701245654,"time_ms":1701245654772,"channel":"futures.order_book_update","event":"update","result":{"U":53095236887,"a":[],"b":[{"p":"38143.2","s":2622}],"s":"BTC_USDT","t":1701245654757,"u":53095236887}}
{"time":1701245654,"time_ms":1701245654854,"channel":"futures.order_book_update","event":"update","result":{"U":53095236888,"a":[{"p":"38157.2","s":0}],"b":[],"s":"BTC_USDT","t":1701245654828,"u":53095236889}}
{"time":1701245654,"time_ms":1701245654892,"channel":"futures.order_book_update","event":"update","result":{"U":53095236890,"a":[{"p":"38160.3","s":0}],"b":[],"s":"BTC_USDT","t":1701245654884,"u":53095236891}}
{"time":1701245654,"time_ms":1701245654912,"channel":"futures.order_book_update","event":"update","result":{"U":53095236892,"a":[{"p":"38160.9","s":0}],"b":[],"s":"BTC_USDT","t":1701245654895,"u":53095236893}}
{"time":1701245654,"time_ms":1701245654932,"channel":"futures.order_book_update","event":"update","result":{"U":53095236894,"a":[{"p":"38160.3","s":0}],"b":[],"s":"BTC_USDT","t":1701245654905,"u":53095236894}}
{"time":1701245654,"time_ms":1701245654951,"channel":"futures.order_book_update","event":"update","result":{"U":53095236895,"a":[{"p":"38164","s":0},{"p":"38171.5","s":0},{"p":"38160","s":0}],"b":[{"p":"38141.6","s":13980},{"p":"38142.5","s":0},{"p":"38144","s":0},{"p":"38141.3","s":0},{"p":"38143.2","s":2620},{"p":"38141.5","s":1315}],"s":"BTC_USDT","t":1701245654942,"u":53095236902}}
{"time":1701245654,"time_ms":1701245654973,"channel":"futures.order_book_update","event":"update","result":{"U":53095236903,"a":[{"p":"38157.5","s":0}],"b":[{"p":"38142.2","s":2174},{"p":"38142.1","s":3131},{"p":"38141.5","s":0},{"p":"38143","s":0},{"p":"38134.7","s":0}],"s":"BTC_USDT","t":1701245654955,"u":53095236912}}
{"time":1701245654,"time_ms":1701245654993,"channel":"futures.order_book_update","event":"update","result":{"U":53095236913,"a":[],"b":[{"p":"38143.2","s":2622},{"p":"38142.5","s":2},{"p":"38144","s":2},{"p":"38141.7","s":0},{"p":"38141.6","s":0}],"s":"BTC_USDT","t":1701245654967,"u":53095236916}}
{"time":1701245655,"time_ms":1701245655033,"channel":"futures.order_book_update","event":"update","result":{"U":53095236917,"a":[{"p":"38157.4","s":0},{"p":"38172.5","s":0}],"b":[{"p":"38142.1","s":0},{"p":"38142.2","s":0},{"p":"38141.7","s":0},{"p":"38137.4","s":0},{"p":"38141.9","s":3932},{"p":"38143","s":2174},{"p":"38142.3","s":3153}],"s":"BTC_USDT","t":1701245655022,"u":53095236929}}
{"time":1701245655,"time_ms":1701245655052,"channel":"futures.order_book_update","event":"update","result":{"U":53095236930,"a":[{"p":"38157.5","s":0},{"p":"38172.8","s":0},{"p":"38146.6","s":7696},{"p":"38160.9","s":0},{"p":"38153.4","s":0},{"p":"38152.8","s":0},{"p":"38156.8","s":0},{"p":"38152","s":1052},{"p":"38155.8","s":0},{"p":"38157.7","s":0}],"b":[{"p":"38143.2","s":2},{"p":"38143.9","s":3026},{"p":"38143.8","s":2174},{"p":"38141.7","s":0},{"p":"38135.4","s":0},{"p":"38143.5","s":3087},{"p":"38142.3","s":2174},{"p":"38143","s":0},{"p":"38141.9","s":0},{"p":"38137.9","s":0}],"s":"BTC_USDT","t":1701245655042,"u":53095236977}}
{"time":1701245655,"time_ms":1701245655073,"channel":"futures.order_book_update","event":"update","result":{"U":53095236978,"a":[],"b":[{"p":"38143.6","s":322},{"p":"38143.3","s":0},{"p":"38141.9","s":0}],"s":"BTC_USDT","t":1701245655053,"u":53095236979}}
{"time":1701245655,"time_ms":1701245655112,"channel":"futures.order_book_update","event":"update","result":{"U":53095236980,"a":[{"p":"38154.7","s":0},{"p":"38188.1","s":0}],"b":[],"s":"BTC_USDT","t":1701245655098,"u":53095236985}}
{"time":1701245655,"time_ms":1701245655134,"channel":"futures.order_book_update","event":"update","result":{"U":53095236986,"a":[],"b":[{"p":"38142.4","s":2174},{"p":"38142.3","s":0},{"p":"38142","s":0},{"p":"38141.9","s":0}],"s":"BTC_USDT","t":1701245655124,"u":53095236990}}
{"time":1701245655,"time_ms":1701245655213,"channel":"futures.order_book_update","event":"update","result":{"U":53095236991,"a":[{"p":"38161","s":0},{"p":"38165","s":0}],"b":[{"p":"38142","s":2174},{"p":"38142.4","s":0}],"s":"BTC_USDT","t":1701245655198,"u":53095236998}}
{"time":1701245655,"time_ms":1701245655272,"channel":"futures.order_book_update","event":"update","result":{"U":53095236999,"a":[{"p":"38161.9","s":0}],"b":[],"s":"BTC_USDT","t":1701245655256,"u":53095237000}}
{"time":1701245655,"time_ms":1701245655292,"channel":"futures.order_book_update","event":"update","result":{"U":53095237001,"a":[{"p":"38161.5","s":0}],"b":[],"s":"BTC_USDT","t":1701245655279,"u":53095237004}}
{"time":1701245655,"time_ms":1701245655333,"channel":"futures.order_book_update","event":"update","result":{"U":53095237005,"a":[{"p":"38160","s":0},{"p":"38164","s":0}],"b":[],"s":"BTC_USDT","t":1701245655323,"u":53095237008}}
{"time":1701245655,"time_ms":1701245655353,"channel":"futures.order_book_update","event":"update","result":{"U":53095237009,"a":[{"p":"38154.7","s":0}],"b":[],"s":"BTC_USDT","t":1701245655325,"u":53095237009}}
{"time":1701245655,"time_ms":1701245655374,"channel":"futures.order_book_update","event":"update","result":{"U":53095237010,"a":[{"p":"38152.2","s":5195},{"p":"38158.5","s":0},{"p":"38152.8","s":0}],"b":[{"p":"38139.6","s":0},{"p":"38139.2","s":0},{"p":"38142","s":2174},{"p":"38139.1","s":0},{"p":"38143","s":733},{"p":"38143.5","s":2354},{"p":"38143.6","s":2496},{"p":"38143.8","s":0}],"s":"BTC_USDT","t":1701245655366,"u":53095237023}}
{"time":1701245655,"time_ms":1701245655412,"channel":"futures.order_book_update","event":"update","result":{"U":53095237024,"a":[{"p":"38158.2","s":0},{"p":"38158","s":0},{"p":"38160.4","s":0},{"p":"38165","s":0},{"p":"38156.4","s":0},{"p":"38158.4","s":0},{"p":"38158.5","s":0},{"p":"38152.2","s":4541},{"p":"38146.6","s":45},{"p":"38156.8","s":0},{"p":"38161.8","s":0},{"p":"38157.1","s":0}],"b":[{"p":"38138.7","s":0},{"p":"38133.1","s":0},{"p":"38141.9","s":3932},{"p":"38143.9","s":3759},{"p":"38143","s":2174},{"p":"38142","s":0},{"p":"38138.2","s":0}],"s":"BTC_USDT","t":1701245655400,"u":53095237053}}
{"time":1701245655,"time_ms":1701245655431,"channel":"futures.order_book_update","event":"update","result":{"U":53095237054,"a":[{"p":"38165","s":0},{"p":"38158.9","s":0}],"b":[{"p":"38143.6","s":3446}],"s":"BTC_USDT","t":1701245655413,"u":53095237058}}
{"time":1701245655,"time_ms":1701245655467,"channel":"futures.order_book_update","event":"update","result":{"U":53095237059,"a":[{"p":"38146.6","s":233},{"p":"38186.4","s":0}],"b":[{"p":"38146.5","s":156571}],"s":"BTC_USDT","t":1701245655457,"u":53095237080}}
{"time":1701245655,"time_ms":1701245655473,"channel":"futures.order_book_update","event":"update","result":{"U":53095237081,"a":[{"p":"38146.6","s":559}],"b":[{"p":"38146.5","s":156353}],"s":"BTC_USDT","t":1701245655464,"u":53095237083}}
{"time":1701245655,"time_ms":1701245655503,"channel":"futures.order_book_update","event":"update","result":{"U":53095237084,"a":[{"p":"38172.5","s":0},{"p":"38174.3","s":0},{"p":"38146.6","s":17559},{"p":"38165","s":0},{"p":"38161","s":0}],"b":[{"p":"38102.8","s":0},{"p":"38134","s":0},{"p":"38145.7","s":0},{"p":"38132.1","s":0},{"p":"38113.2","s":0},{"p":"38141.7","s":94},{"p":"38146.5","s":125660},{"p":"38144.5","s":0}],"s":"BTC_USDT","t":1701245655493,"u":53095237165}}
{"time":1701245655,"time_ms":1701245655512,"channel":"futures.order_book_update","event":"update","result":{"U":53095237166,"a":[],"b":[{"p":"38145.6","s":3162},{"p":"38143.6","s":1272},{"p":"38146.5","s":133311},{"p":"38144.5","s":9006},{"p":"38143.7","s":2698},{"p":"38143","s":0},{"p":"38141.7","s":94}],"s":"BTC_USDT","t":1701245655502,"u":53095237171}}
{"time":1701245655,"time_ms":1701245655533,"channel":"futures.order_book_update","event":"update","result":{"U":53095237172,"a":[{"p":"38170","s":0}],"b":[{"p":"38143.6","s":322},{"p":"38141.7","s":0},{"p":"38141.9","s":0},{"p":"38143.7","s":524},{"p":"38144.6","s":2174},{"p":"38143.1","s":2174},{"p":"38145.6","s":988}],"s":"BTC_USDT","t":1701245655513,"u":53095237178}}
{"time":1701245655,"time_ms":1701245655552,"channel":"futures.order_book_update","event":"update","result":{"U":53095237179,"a":[{"p":"38146.6","s":25210}],"b":[{"p":"38143.6","s":1271}],"s":"BTC_USDT","t":1701245655537,"u":53095237180}}
{"time":1701245655,"time_ms":1701245655574,"channel":"futures.order_book_update","event":"update","result":{"U":53095237181,"a":[{"p":"38161","s":0},{"p":"38157.3","s":0},{"p":"38157","s":0},{"p":"38165","s":0}],"b":[],"s":"BTC_USDT","t":1701245655557,"u":53095237188}}
{"time":1701245655,"time_ms":1701245655612,"channel":"futures.order_book_update","event":"update","result":{"U":53095237189,"a":[{"p":"38152.1","s":654},{"p":"38146.6","s":24874},{"p":"38152.7","s":0},{"p":"38156.5","s":0},{"p":"38160.5","s":0}],"b":[{"p":"38142","s":2174},{"p":"38141.9","s":3932},{"p":"38143.8","s":2174},{"p":"38144.6","s":0},{"p":"38142.5","s":0},{"p":"38143.2","s":0},{"p":"38141.3","s":0},{"p":"38141.6","s":0},{"p":"38141.7","s":94},{"p":"38143.1","s":0},{"p":"38139.8","s":0},{"p":"38141.5","s":0}],"s":"BTC_USDT","t":1701245655595,"u":53095237205}}
{"time":1701245655,"time_ms":1701245655632,"channel":"futures.order_book_update","event":"update","result":{"U":53095237206,"a":[{"p":"38160.6","s":0},{"p":"38146.6","s":26800},{"p":"38169","s":0},{"p":"38158.9","s":0}],"b":[{"p":"38143.6","s":322},{"p":"38142.7","s":2},{"p":"38143.9","s":3026},{"p":"38143.2","s":733},{"p":"38141.7","s":0},{"p":"38144","s":0},{"p":"38139.1","s":0},{"p":"38135.9","s":0}],"s":"BTC_USDT","t":1701245655614,"u":53095237221}}
{"time":1701245655,"time_ms":1701245655653,"channel":"futures.order_book_update","event":"update","result":{"U":53095237222,"a":[],"b":[{"p":"38143.4","s":3111}],"s":"BTC_USDT","t":1701245655623,"u":53095237222}}
{"time":1701245655,"time_ms":1701245655674,"channel":"futures.order_book_update","event":"update","result":{"U":53095237223,"a":[],"b":[{"p":"38144.2","s":2},{"p":"38141.9","s":0},{"p":"38136.9","s":0}],"s":"BTC_USDT","t":1701245655646,"u":53095237224}}
{"time":1701245655,"time_ms":1701245655694,"channel":"futures.order_book_update","event":"update","result":{"U":53095237225,"a":[{"p":"38157.7","s":0}],"b":[{"p":"38142.7","s":0},{"p":"38140","s":0},{"p":"38139.6","s":0},{"p":"38143.4","s":3111},{"p":"38143.9","s":406},{"p":"38141.7","s":94},{"p":"38144.2","s":0},{"p":"38143.2","s":3353},{"p":"38141.9","s":3932},{"p":"38141.5","s":0}],"s":"BTC_USDT","t":1701245655684,"u":53095237237}}
{"time":1701245655,"time_ms":1701245655712,"channel":"futures.order_book_update","event":"update","result":{"U":53095237238,"a":[{"p":"38162.3","s":0},{"p":"38160","s":0}],"b":[{"p":"38144.2","s":2},{"p":"38143.6","s":1980},{"p":"38142.7","s":2},{"p":"38141.9","s":0},{"p":"38141.7","s":0}],"s":"BTC_USDT","t":1701245655696,"u":53095237247}}
{"time":1701245655,"time_ms":1701245655732,"channel":"futures.order_book_update","event":"update","result":{"U":53095237248,"a":[],"b":[{"p":"38143.5","s":0},{"p":"38141.9","s":0},{"p":"38142.1","s":2485}],"s":"BTC_USDT","t":1701245655699,"u":53095237249}}
{"time":1701245655,"time_ms":1701245655771,"channel":"futures.order_book_update","event":"update","result":{"U":53095237250,"a":[{"p":"38146.6","s":30300}],"b":[],"s":"BTC_USDT","t":1701245655759,"u":53095237256}}
{"time":1701245655,"time_ms":1701245655814,"channel":"futures.order_book_update","event":"update","result":{"U":53095237257,"a":[{"p":"38160","s":0},{"p":"38156","s":0}],"b":[{"p":"38141.9","s":3932},{"p":"38142.1","s":0},{"p":"38141.5","s":0},{"p":"38143.4","s":3109},{"p":"38143.3","s":2292},{"p":"38142.7","s":0},{"p":"38141.6","s":0},{"p":"38141.7","s":94},{"p":"38144.2","s":0}],"s":"BTC_USDT","t":1701245655800,"u":53095237267}}
{"time":1701245655,"time_ms":1701245655834,"channel":"futures.order_book_update","event":"update","result":{"U":53095237268,"a":[{"p":"38167.1","s":0},{"p":"38154.4","s":0}],"b":[{"p":"38141.9","s":0},{"p":"38141.7","s":0},{"p":"38121.1","s":0},{"p":"38144.2","s":2},{"p":"38142.7","s":2},{"p":"38143.4","s":3111}],"s":"BTC_USDT","t":1701245655820,"u":53095237274}}
{"time":1701245655,"time_ms":1701245655852,"channel":"futures.order_book_update","event":"update","result":{"U":53095237275,"a":[{"p":"38161.1","s":0},{"p":"38146.6","s":13300}],"b":[],"s":"BTC_USDT","t":1701245655844,"u":53095237278}}
{"time":1701245655,"time_ms":1701245655872,"channel":"futures.order_book_update","event":"update","result":{"U":53095237279,"a":[{"p":"38146.6","s":14300}],"b":[],"s":"BTC_USDT","t":1701245655862,"u":53095237280}}
{"time":1701245655,"time_ms":1701245655891,"channel":"futures.order_book_update","event":"update","result":{"U":53095237281,"a":[{"p":"38146.6","s":14300}],"b":[],"s":"BTC_USDT","t":1701245655867,"u":53095237282}}
{"time":1701245655,"time_ms":1701245655954,"channel":"futures.order_book_update","event":"update","result":{"U":53095237283,"a":[{"p":"38156.1","s":0},{"p":"38156.4","s":0},{"p":"38160.4","s":0}],"b":[],"s":"BTC_USDT","t":1701245655945,"u":53095237289}}
{"time":1701245655,"time_ms":1701245655972,"channel":"futures.order_book_update","event":"update","result":{"U":53095237290,"a":[{"p":"38158","s":0}],"b":[{"p":"38138.2","s":0}],"s":"BTC_USDT","t":1701245655949,"u":53095237294}}
{"time":1701245656,"time_ms":1701245656012,"channel":"futures.order_book_update","event":"update","result":{"U":53095237295,"a":[],"b":[{"p":"38143.2","s":2620},{"p":"38144","s":733},{"p":"38142","s":0}],"s":"BTC_USDT","t":1701245656002,"u":53095237296}}
{"time":1701245656,"time_ms":1701245656030,"channel":"futures.order_book_update","event":"update","result":{"U":53095237297,"a":[{"p":"38158.5","s":0},{"p":"38173.6","s":0},{"p":"38158.6","s":0}],"b":[{"p":"38143.9","s":2717},{"p":"38143","s":2174},{"p":"38144","s":2907},{"p":"38143.8","s":0},{"p":"38135.4","s":0},{"p":"38141.9","s":3932},{"p":"38143.3","s":0},{"p":"38141.7","s":0},{"p":"38139.9","s":0},{"p":"38142","s":0}],"s":"BTC_USDT","t":1701245656014,"u":53095237312}}
{"time":1701245656,"time_ms":1701245656052,"channel":"futures.order_book_update","event":"update","result":{"U":53095237313,"a":[{"p":"38158.6","s":0},{"p":"38156.5","s":0},{"p":"38160.5","s":0}],"b":[],"s":"BTC_USDT","t":1701245656038,"u":53095237320}}
{"time":1701245656,"time_ms":1701245656072,"channel":"futures.order_book_update","event":"update","result":{"U":53095237321,"a":[{"p":"38146.6","s":13800}],"b":[],"s":"BTC_USDT","t":1701245656054,"u":53095237321}}
{"time":1701245656,"time_ms":1701245656110,"channel":"futures.order_book_update","event":"update","result":{"U":53095237322,"a":[{"p":"38160","s":0},{"p":"38163.8","s":0}],"b":[{"p":"38144","s":2174},{"p":"38143.7","s":2864},{"p":"38143.9","s":406},{"p":"38143.8","s":733},{"p":"38141.9","s":0}],"s":"BTC_USDT","t":1701245656098,"u":53095237329}}
{"time":1701245656,"time_ms":1701245656172,"channel":"futures.order_book_update","event":"update","result":{"U":53095237330,"a":[],"b":[{"p":"38146.5","s":132958}],"s":"BTC_USDT","t":1701245656161,"u":53095237331}}
{"time":1701245656,"time_ms":1701245656192,"channel":"futures.order_book_update","event":"update","result":{"U":53095237332,"a":[{"p":"38157.3","s":0},{"p":"38175.9","s":0},{"p":"38171.4","s":0},{"p":"38165","s":0},{"p":"38160.7","s":0},{"p":"38167.6","s":0},{"p":"38158.5","s":0},{"p":"38146.6","s":41300},{"p":"38161.9","s":0},{"p":"38175.2","s":0}],"b":[{"p":"38129.7","s":0},{"p":"38125.9","s":0},{"p":"38137.3","s":0},{"p":"38141.2","s":0},{"p":"38144","s":2374},{"p":"38141.9","s":3932},{"p":"38145","s":0},{"p":"38133.5","s":0}],"s":"BTC_USDT","t":1701245656180,"u":53095237357}}
{"time":1701245656,"time_ms":1701245656214,"channel":"futures.order_book_update","event":"update","result":{"U":53095237358,"a":[{"p":"38158.5","s":0},{"p":"38160","s":0},{"p":"38157.3","s":0},{"p":"38158.6","s":0},{"p":"38157.5","s":0}],"b":[{"p":"38144","s":2174},{"p":"38146.5","s":133028},{"p":"38145","s":200},{"p":"38141.9","s":0}],"s":"BTC_USDT","t":1701245656200,"u":53095237374}}
{"time":1701245656,"time_ms":1701245656274,"channel":"futures.order_book_update","event":"update","result":{"U":53095237375,"a":[{"p":"38160.6","s":0},{"p":"38157.7","s":0}],"b":[{"p":"38141.7","s":94},{"p":"38142.7","s":0},{"p":"38144.2","s":0},{"p":"38141.5","s":0},{"p":"38143.4","s":3109},{"p":"38141.9","s":3932}],"s":"BTC_USDT","t":1701245656264,"u":53095237382}}
{"time":1701245656,"time_ms":1701245656293,"channel":"futures.order_book_update","event":"update","result":{"U":53095237383,"a":[{"p":"38157.5","s":0},{"p":"38158.9","s":0},{"p":"38159","s":0},{"p":"38162.3","s":0},{"p":"38165","s":0}],"b":[{"p":"38144","s":2},{"p":"38143.5","s":733},{"p":"38143.2","s":2622},{"p":"38140","s":0},{"p":"38139.8","s":0},{"p":"38143.8","s":2174},{"p":"38142","s":2174},{"p":"38141.7","s":0},{"p":"38143","s":0},{"p":"38141.6","s":0}],"s":"BTC_USDT","t":1701245656285,"u":53095237404}}
{"time":1701245656,"time_ms":1701245656312,"channel":"futures.order_book_update","event":"update","result":{"U":53095237405,"a":[{"p":"38146.6","s":20300},{"p":"38160","s":0},{"p":"38156","s":0}],"b":[{"p":"38142.5","s":2},{"p":"38141.9","s":0}],"s":"BTC_USDT","t":1701245656299,"u":53095237411}}
{"time":1701245656,"time_ms":1701245656332,"channel":"futures.order_book_update","event":"update","result":{"U":53095237412,"a":[{"p":"38146.6","s":13800}],"b":[],"s":"BTC_USDT","t":1701245656318,"u":53095237412}}
{"time":1701245656,"time_ms":1701245656413,"channel":"futures.order_book_update","event":"update","result":{"U":53095237413,"a":[{"p":"38160","s":0}],"b":[],"s":"BTC_USDT","t":1701245656389,"u":53095237414}}
{"time":1701245656,"time_ms":1701245656453,"channel":"futures.order_book_update","event":"update","result":{"U":53095237415,"a":[{"p":"38154.7","s":0},{"p":"38158.6","s":0}],"b":[{"p":"38143.3","s":2293},{"p":"38143.7","s":524},{"p":"38146.5","s":129883},{"p":"38142","s":0},{"p":"38135.9","s":0}],"s":"BTC_USDT","t":1701245656444,"u":53095237425}}
{"time":1701245656,"time_ms":1701245656477,"channel":"futures.order_book_update","event":"update","result":{"U":53095237426,"a":[{"p":"38146.6","s":15300}],"b":[{"p":"38139.1","s":0}],"s":"BTC_USDT","t":1701245656465,"u":53095237431}}
{"time":1701245656,"time_ms":1701245656551,"channel":"futures.order_book_update","event":"update","result":{"U":53095237432,"a":[],"b":[{"p":"38144","s":0},{"p":"38141.3","s":0},{"p":"38143.2","s":2620},{"p":"38142","s":2774},{"p":"38141.9","s":3932},{"p":"38142.5","s":0}],"s":"BTC_USDT","t":1701245656537,"u":53095237450}}
{"time":1701245656,"time_ms":1701245656592,"channel":"futures.order_book_update","event":"update","result":{"U":53095237451,"a":[{"p":"38192.1","s":0},{"p":"38158.1","s":0}],"b":[{"p":"38138.7","s":0}],"s":"BTC_USDT","t":1701245656580,"u":53095237456}}
{"time":1701245656,"time_ms":1701245656614,"channel":"futures.order_book_update","event":"update","result":{"U":53095237457,"a":[{"p":"38154.7","s":0},{"p":"38158.4","s":0}],"b":[{"p":"38143.9","s":408},{"p":"38142.4","s":2},{"p":"38143.1","s":2},{"p":"38142","s":0},{"p":"38141.9","s":0}],"s":"BTC_USDT","t":1701245656604,"u":53095237465}}
{"time":1701245656,"time_ms":1701245656633,"channel":"futures.order_book_update","event":"update","result":{"U":53095237466,"a":[{"p":"38157.7","s":0}],"b":[],"s":"BTC_USDT","t":1701245656619,"u":53095237469}}
{"time":1701245656,"time_ms":1701245656653,"channel":"futures.order_book_update","event":"update","result":{"U":53095237470,"a":[{"p":"38183.5","s":0}],"b":[],"s":"BTC_USDT","t":1701245656632,"u":53095237471}}
{"time":1701245656,"time_ms":1701245656694,"channel":"futures.order_book_update","event":"update","result":{"U":53095237472,"a":[{"p":"38181.8","s":0}],"b":[],"s":"BTC_USDT","t":1701245656683,"u":53095237476}}
{"time":1701245656,"time_ms":1701245656771,"channel":"futures.order_book_update","event":"update","result":{"U":53095237477,"a":[{"p":"38168.5","s":0},{"p":"38156.5","s":0},{"p":"38160.5","s":0}],"b":[],"s":"BTC_USDT","t":1701245656753,"u":53095237484}}
{"time":1701245656,"time_ms":1701245656893,"channel":"futures.order_book_update","event":"update","result":{"U":53095237485,"a":[],"b":[{"p":"38143.9","s":406},{"p":"38141.9","s":3932},{"p":"38142","s":2774},{"p":"38143.1","s":0},{"p":"38142.4","s":0},{"p":"38141.2","s":0}],"s":"BTC_USDT","t":1701245656883,"u":53095237490}}
{"time":1701245656,"time_ms":1701245656913,"channel":"futures.order_book_update","event":"update","result":{"U":53095237491,"a":[{"p":"38159.5","s":0},{"p":"38155.5","s":0}],"b":[],"s":"BTC_USDT","t":1701245656891,"u":53095237495}}
{"time":1701245656,"time_ms":1701245656932,"channel":"futures.order_book_update","event":"update","result":{"U":53095237496,"a":[],"b":[{"p":"38143.2","s":2622},{"p":"38142.5","s":2},{"p":"38141.9","s":0},{"p":"38142","s":0},{"p":"38144","s":2}],"s":"BTC_USDT","t":1701245656923,"u":53095237499}}
{"time":1701245656,"time_ms":1701245656986,"channel":"futures.order_book_update","event":"update","result":{"U":53095237500,"a":[{"p":"38163.3","s":0},{"p":"38186.8","s":0}],"b":[],"s":"BTC_USDT","t":1701245656972,"u":53095237503}}
{"time":1701245657,"time_ms":1701245657013,"channel":"futures.order_book_update","event":"update","result":{"U":53095237504,"a":[{"p":"38160.4","s":0},{"p":"38173.8","s":0},{"p":"38158.8","s":0},{"p":"38156.8","s":0},{"p":"38158.5","s":0}],"b":[{"p":"38143","s":2174},{"p":"38142.5","s":0},{"p":"38139.8","s":0},{"p":"38142","s":0}],"s":"BTC_USDT","t":1701245657006,"u":53095237517}}
{"time":1701245657,"time_ms":1701245657031,"channel":"futures.order_book_update","event":"update","result":{"U":53095237518,"a":[{"p":"38158","s":0},{"p":"38158.2","s":0},{"p":"38158.6","s":0},{"p":"38161.9","s":0}],"b":[{"p":"38142.5","s":2},{"p":"38142.6","s":26},{"p":"38139.9","s":0},{"p":"38143.3","s":0},{"p":"38135.4","s":0},{"p":"38144","s":735},{"p":"38144.6","s":2174},{"p":"38143.5","s":2325},{"p":"38143.8","s":0}],"s":"BTC_USDT","t":1701245657014,"u":53095237537}}
{"time":1701245657,"time_ms":1701245657092,"channel":"futures.order_book_update","event":"update","result":{"U":53095237538,"a":[],"b":[{"p":"38146.5","s":133028},{"p":"38140.4","s":0},{"p":"38136.7","s":0},{"p":"38125.3","s":0}],"s":"BTC_USDT","t":1701245657084,"u":53095237553}}
{"time":1701245657,"time_ms":1701245657112,"channel":"futures.order_book_update","event":"update","result":{"U":53095237554,"a":[{"p":"38157.5","s":0}],"b":[{"p":"38142","s":600},{"p":"38144","s":2909},{"p":"38144.6","s":0}],"s":"BTC_USDT","t":1701245657092,"u":53095237558}}
{"time":1701245657,"time_ms":1701245657131,"channel":"futures.order_book_update","event":"update","result":{"U":53095237559,"a":[],"b":[{"p":"38142","s":0},{"p":"38144","s":735},{"p":"38144.6","s":2174}],"s":"BTC_USDT","t":1701245657111,"u":53095237560}}
{"time":1701245657,"time_ms":1701245657153,"channel":"futures.order_book_update","event":"update","result":{"U":53095237561,"a":[],"b":[{"p":"38146.5","s":133059}],"s":"BTC_USDT","t":1701245657123,"u":53095237561}}
{"time":1701245657,"time_ms":1701245657192,"channel":"futures.order_book_update","event":"update","result":{"U":53095237562,"a":[{"p":"38157.3","s":0}],"b":[],"s":"BTC_USDT","t":1701245657182,"u":53095237563}}
{"time":1701245657,"time_ms":1701245657214,"channel":"futures.order_book_update","event":"update","result":{"U":53095237564,"a":[{"p":"38154.5","s":0},{"p":"38160.4","s":0},{"p":"38156.3","s":0},{"p":"38162.3","s":0},{"p":"38159.3","s":0},{"p":"38158.6","s":0},{"p":"38157.5","s":0},{"p":"38160.6","s":0}],"b":[{"p":"38143.1","s":2174},{"p":"38143","s":0},{"p":"38144.6","s":0},{"p":"38142","s":0},{"p":"38140.1","s":0},{"p":"38135.9","s":0},{"p":"38142.1","s":0},{"p":"38144","s":2},{"p":"38143.3","s":733},{"p":"38143.7","s":2698}],"s":"BTC_USDT","t":1701245657206,"u":53095237591}}
{"time":1701245657,"time_ms":1701245657233,"channel":"futures.order_book_update","event":"update","result":{"U":53095237592,"a":[{"p":"38161.3","s":0},{"p":"38158.2","s":0},{"p":"38157.9","s":0}],"b":[{"p":"38144.5","s":11180},{"p":"38143.7","s":524},{"p":"38144","s":735},{"p":"38142","s":600},{"p":"38143.3","s":0},{"p":"38139.1","s":0}],"s":"BTC_USDT","t":1701245657218,"u":53095237605}}
{"time":1701245657,"time_ms":1701245657312,"channel":"futures.order_book_update","event":"update","result":{"U":53095237606,"a":[],"b":[{"p":"38144.1","s":2174},{"p":"38144.5","s":9006},{"p":"38142","s":0}],"s":"BTC_USDT","t":1701245657304,"u":53095237607}}
{"time":1701245657,"time_ms":1701245657372,"channel":"futures.order_book_update","event":"update","result":{"U":53095237608,"a":[],"b":[{"p":"38143.2","s":2620},{"p":"38142","s":600},{"p":"38142.5","s":0},{"p":"38141.3","s":0}],"s":"BTC_USDT","t":1701245657358,"u":53095237610}}
{"time":1701245657,"time_ms":1701245657392,"channel":"futures.order_book_update","event":"update","result":{"U":53095237611,"a":[],"b":[{"p":"38144","s":733},{"p":"38142.5","s":2},{"p":"38143.2","s":2622},{"p":"38142","s":0}],"s":"BTC_USDT","t":1701245657374,"u":53095237614}}
{"time":1701245657,"time_ms":1701245657452,"channel":"futures.order_book_update","event":"update","result":{"U":53095237615,"a":[],"b":[{"p":"38144","s":735}],"s":"BTC_USDT","t":1701245657423,"u":53095237615}}
{"time":1701245657,"time_ms":1701245657502,"channel":"futures.order_book_update","event":"update","result":{"U":53095237616,"a":[{"p":"38160.6","s":0},{"p":"38157.5","s":0},{"p":"38162.3","s":0}],"b":[{"p":"38144","s":2},{"p":"38143.7","s":2698},{"p":"38142","s":600},{"p":"38144.1","s":0},{"p":"38143.1","s":0},{"p":"38140.2","s":0},{"p":"38143.6","s":2713},{"p":"38142.1","s":2174}],"s":"BTC_USDT","t":1701245657484,"u":53095237629}}
{"time":1701245657,"time_ms":1701245657574,"channel":"futures.order_book_update","event":"update","result":{"U":53095237630,"a":[{"p":"38148.2","s":368}],"b":[],"s":"BTC_USDT","t":1701245657546,"u":53095237630}}
{"time":1701245657,"time_ms":1701245657632,"channel":"futures.order_book_update","event":"update","result":{"U":53095237631,"a":[{"p":"38167","s":0},{"p":"38156.5","s":0}],"b":[{"p":"38137","s":0},{"p":"38141","s":0}],"s":"BTC_USDT","t":1701245657621,"u":53095237636}}
{"time":1701245657,"time_ms":1701245657651,"channel":"futures.order_book_update","event":"update","result":{"U":53095237637,"a":[{"p":"38146.6","s":15750},{"p":"38160.5","s":0}],"b":[{"p":"38128.5","s":0},{"p":"38141.3","s":0},{"p":"38141.7","s":120},{"p":"38141.9","s":3932},{"p":"38143.2","s":2620},{"p":"38142.5","s":0},{"p":"38144","s":0}],"s":"BTC_USDT","t":1701245657628,"u":53095237644}}
{"time":1701245657,"time_ms":1701245657671,"channel":"futures.order_book_update","event":"update","result":{"U":53095237645,"a":[{"p":"38152.5","s":8991},{"p":"38159.2","s":0},{"p":"38160","s":0},{"p":"38158.6","s":0},{"p":"38156","s":0}],"b":[{"p":"38143.6","s":1980},{"p":"38143","s":733},{"p":"38143.5","s":0},{"p":"38141.7","s":0},{"p":"38139.6","s":0},{"p":"38141.6","s":0},{"p":"38142.2","s":2479}],"s":"BTC_USDT","t":1701245657646,"u":53095237658}}
{"time":1701245657,"time_ms":1701245657694,"channel":"futures.order_book_update","event":"update","result":{"U":53095237659,"a":[],"b":[{"p":"38142","s":0},{"p":"38142.5","s":2},{"p":"38143.2","s":2622},{"p":"38144","s":2},{"p":"38141.9","s":0}],"s":"BTC_USDT","t":1701245657672,"u":53095237662}}
{"time":1701245657,"time_ms":1701245657715,"channel":"futures.order_book_update","event":"update","result":{"U":53095237663,"a":[],"b":[{"p":"38143.7","s":524},{"p":"38143.1","s":2174},{"p":"38143","s":0},{"p":"38142.1","s":2174}],"s":"BTC_USDT","t":1701245657700,"u":53095237667}}
{"time":1701245657,"time_ms":1701245657734,"channel":"futures.order_book_update","event":"update","result":{"U":53095237668,"a":[{"p":"38146.6","s":16250},{"p":"38158.5","s":0}],"b":[{"p":"38142.3","s":733},{"p":"38142.1","s":0}],"s":"BTC_USDT","t":1701245657717,"u":53095237671}}
{"time":1701245657,"time_ms":1701245657753,"channel":"futures.order_book_update","event":"update","result":{"U":53095237672,"a":[{"p":"38156.8","s":0}],"b":[{"p":"38142.3","s":2907},{"p":"38142.1","s":2174},{"p":"38143.1","s":0}],"s":"BTC_USDT","t":1701245657738,"u":53095237675}}
{"time":1701245657,"time_ms":1701245657775,"channel":"futures.order_book_update","event":"update","result":{"U":53095237676,"a":[{"p":"38161.4","s":0}],"b":[{"p":"38142","s":600},{"p":"38142.1","s":0},{"p":"38138.7","s":0},{"p":"38135.4","s":0}],"s":"BTC_USDT","t":1701245657767,"u":53095237684}}
{"time":1701245657,"time_ms":1701245657793,"channel":"futures.order_book_update","event":"update","result":{"U":53095237685,"a":[{"p":"38156.5","s":0},{"p":"38164","s":0}],"b":[{"p":"38126.7","s":0}],"s":"BTC_USDT","t":1701245657781,"u":53095237690}}
{"time":1701245657,"time_ms":1701245657813,"channel":"futures.order_book_update","event":"update","result":{"U":53095237691,"a":[{"p":"38152.5","s":79}],"b":[{"p":"38102.8","s":0}],"s":"BTC_USDT","t":1701245657797,"u":53095237693}}
{"time":1701245657,"time_ms":1701245657832,"channel":"futures.order_book_update","event":"update","result":{"U":53095237694,"a":[{"p":"38154.7","s":0}],"b":[],"s":"BTC_USDT","t":1701245657811,"u":53095237694}}
{"time":1701245657,"time_ms":1701245657912,"channel":"futures.order_book_update","event":"update","result":{"U":53095237695,"a":[{"p":"38154.8","s":0}],"b":[],"s":"BTC_USDT","t":1701245657890,"u":53095237702}}
{"time":1701245657,"time_ms":1701245657972,"channel":"futures.order_book_update","event":"update","result":{"U":53095237703,"a":[{"p":"38146.6","s":31250}],"b":[],"s":"BTC_USDT","t":1701245657955,"u":53095237704}}
{"time":1701245658,"time_ms":1701245658013,"channel":"futures.order_book_update","event":"update","result":{"U":53095237705,"a":[{"p":"38173.5","s":0},{"p":"38157.3","s":0},{"p":"38157.7","s":0},{"p":"38159.8","s":0}],"b":[{"p":"38142.3","s":0},{"p":"38142.2","s":0},{"p":"38141.5","s":0},{"p":"38142.4","s":5234},{"p":"38141.9","s":3932}],"s":"BTC_USDT","t":1701245658006,"u":53095237723}}
{"time":1701245658,"time_ms":1701245658032,"channel":"futures.order_book_update","event":"update","result":{"U":53095237724,"a":[{"p":"38157.9","s":0},{"p":"38156.8","s":0},{"p":"38155.5","s":0},{"p":"38160","s":0}],"b":[{"p":"38141.3","s":0}],"s":"BTC_USDT","t":1701245658017,"u":53095237734}}
{"time":1701245658,"time_ms":1701245658094,"channel":"futures.order_book_update","event":"update","result":{"U":53095237735,"a":[{"p":"38157.3","s":0}],"b":[],"s":"BTC_USDT","t":1701245658079,"u":53095237736}}
{"time":1701245658,"time_ms":1701245658115,"channel":"futures.order_book_update","event":"update","result":{"U":53095237737,"a":[{"p":"38160.3","s":0},{"p":"38156.9","s":0},{"p":"38152.7","s":0},{"p":"38155.6","s":0}],"b":[{"p":"38141.6","s":13980},{"p":"38144","s":0},{"p":"38142.5","s":0},{"p":"38141.3","s":0},{"p":"38143.2","s":2620},{"p":"38141.7","s":120}],"s":"BTC_USDT","t":1701245658101,"u":53095237750}}
{"time":1701245658,"time_ms":1701245658133,"channel":"futures.order_book_update","event":"update","result":{"U":53095237751,"a":[],"b":[{"p":"38142.5","s":2},{"p":"38144","s":2},{"p":"38143.2","s":2622},{"p":"38141.7","s":0},{"p":"38141.6","s":0}],"s":"BTC_USDT","t":1701245658109,"u":53095237753}}
{"time":1701245658,"time_ms":1701245658152,"channel":"futures.order_book_update","event":"update","result":{"U":53095237754,"a":[{"p":"38146.6","s":16750},{"p":"38159","s":0},{"p":"38157.3","s":0},{"p":"38157.4","s":0},{"p":"38155","s":0},{"p":"38166.5","s":0}],"b":[{"p":"38142.4","s":2907},{"p":"38143.2","s":2620},{"p":"38144","s":0},{"p":"38137.8","s":0},{"p":"38142","s":2978},{"p":"38141.6","s":13980},{"p":"38142.5","s":0},{"p":"38141.5","s":0},{"p":"38138.2","s":0},{"p":"38137.9","s":0},{"p":"38141.7","s":94}],"s":"BTC_USDT","t":1701245658146,"u":53095237782}}
{"time":1701245658,"time_ms":1701245658172,"channel":"futures.order_book_update","event":"update","result":{"U":53095237783,"a":[],"b":[{"p":"38142","s":600},{"p":"38144","s":2},{"p":"38142.5","s":2310},{"p":"38143.2","s":2622},{"p":"38141.7","s":0},{"p":"38141.6","s":0}],"s":"BTC_USDT","t":1701245658157,"u":53095237788}}
{"time":1701245658,"time_ms":1701245658194,"channel":"futures.order_book_update","event":"update","result":{"U":53095237789,"a":[{"p":"38154.7","s":0}],"b":[],"s":"BTC_USDT","t":1701245658181,"u":53095237789}}
{"time":1701245658,"time_ms":1701245658214,"channel":"futures.order_book_update","event":"update","result":{"U":53095237790,"a":[{"p":"38160.5","s":0}],"b":[{"p":"38142.4","s":2174},{"p":"38142.5","s":2},{"p":"38142.1","s":733},{"p":"38142","s":2978},{"p":"38141.9","s":0}],"s":"BTC_USDT","t":1701245658194,"u":53095237795}}
{"time":1701245658,"time_ms":1701245658296,"channel":"futures.order_book_update","event":"update","result":{"U":53095237796,"a":[{"p":"38154.7","s":0},{"p":"38157.5","s":0}],"b":[{"p":"38137.9","s":0}],"s":"BTC_USDT","t":1701245658273,"u":53095237800}}
{"time":1701245658,"time_ms":1701245658453,"channel":"futures.order_book_update","event":"update","result":{"U":53095237801,"a":[],"b":[{"p":"38142.5","s":0},{"p":"38144","s":0},{"p":"38141.3","s":0},{"p":"38143.2","s":2620},{"p":"38141.9","s":3932},{"p":"38141.7","s":94}],"s":"BTC_USDT","t":1701245658443,"u":53095237806}}
{"time":1701245658,"time_ms":1701245658475,"channel":"futures.order_book_update","event":"update","result":{"U":53095237807,"a":[],"b":[{"p":"38129.7","s":0}],"s":"BTC_USDT","t":1701245658460,"u":53095237811}}
{"time":1701245658,"time_ms":1701245658510,"channel":"futures.order_book_update","event":"update","result":{"U":53095237812,"a":[],"b":[{"p":"38141.9","s":0},{"p":"38142.5","s":2},{"p":"38143.2","s":2622},{"p":"38144","s":2},{"p":"38141.7","s":0}],"s":"BTC_USDT","t":1701245658486,"u":53095237816}}
{"time":1701245658,"time_ms":1701245658592,"channel":"futures.order_book_update","event":"update","result":{"U":53095237817,"a":[{"p":"38156.8","s":0}],"b":[],"s":"BTC_USDT","t":1701245658577,"u":53095237818}}
{"time":1701245658,"time_ms":1701245658692,"channel":"futures.order_book_update","event":"update","result":{"U":53095237819,"a":[{"p":"38146.6","s":17250},{"p":"38159.9","s":0}],"b":[{"p":"38141.9","s":3932},{"p":"38142.5","s":0},{"p":"38144","s":0},{"p":"38137.4","s":0},{"p":"38141.3","s":0},{"p":"38143.2","s":2620},{"p":"38141.7","s":94},{"p":"38142","s":2378}],"s":"BTC_USDT","t":1701245658682,"u":53095237830}}
{"time":1701245658,"time_ms":1701245658712,"channel":"futures.order_book_update","event":"update","result":{"U":53095237831,"a":[],"b":[{"p":"38143.2","s":2622},{"p":"38144","s":2},{"p":"38142.5","s":2},{"p":"38141.9","s":0},{"p":"38141.7","s":0}],"s":"BTC_USDT","t":1701245658694,"u":53095237834}}
{"time":1701245658,"time_ms":1701245658752,"channel":"futures.order_book_update","event":"update","result":{"U":53095237835,"a":[{"p":"38160.3","s":0}],"b":[{"p":"38141.7","s":94},{"p":"38141.9","s":3932},{"p":"38144","s":0},{"p":"38142.5","s":0},{"p":"38141.3","s":0},{"p":"38143.2","s":2620}],"s":"BTC_USDT","t":1701245658742,"u":53095237840}}
{"time":1701245658,"time_ms":1701245658793,"channel":"futures.order_book_update","event":"update","result":{"U":53095237841,"a":[],"b":[{"p":"38141.7","s":0},{"p":"38141.9","s":0},{"p":"38144","s":2},{"p":"38143.2","s":2622},{"p":"38142.5","s":2}],"s":"BTC_USDT","t":1701245658774,"u":53095237844}}
{"time":1701245658,"time_ms":1701245658952,"channel":"futures.order_book_update","event":"update","result":{"U":53095237845,"a":[{"p":"38146.6","s":28250}],"b":[],"s":"BTC_USDT","t":1701245658943,"u":53095237845}}
{"time":1701245658,"time_ms":1701245658996,"channel":"futures.order_book_update","event":"update","result":{"U":53095237846,"a":[{"p":"38157.3","s":0}],"b":[],"s":"BTC_USDT","t":1701245658969,"u":53095237847}}
{"time":1701245659,"time_ms":1701245659032,"channel":"futures.order_book_update","event":"update","result":{"U":53095237848,"a":[{"p":"38157.1","s":0},{"p":"38160.9","s":0},{"p":"38157.6","s":0}],"b":[{"p":"38138.2","s":0},{"p":"38142.5","s":3055},{"p":"38141.9","s":3932},{"p":"38141.7","s":94},{"p":"38143","s":2174},{"p":"38142","s":0},{"p":"38142.4","s":0},{"p":"38142.1","s":0}],"s":"BTC_USDT","t":1701245659024,"u":53095237861}}
{"time":1701245659,"time_ms":1701245659052,"channel":"futures.order_book_update","event":"update","result":{"U":53095237862,"a":[],"b":[{"p":"38141.7","s":2268},{"p":"38141.3","s":0}],"s":"BTC_USDT","t":1701245659029,"u":53095237863}}
{"time":1701245659,"time_ms":1701245659073,"channel":"futures.order_book_update","event":"update","result":{"U":53095237864,"a":[{"p":"38152.9","s":3623},{"p":"38147.2","s":0}],"b":[],"s":"BTC_USDT","t":1701245659058,"u":53095237864}}
{"time":1701245659,"time_ms":1701245659113,"channel":"futures.order_book_update","event":"update","result":{"U":53095237865,"a":[{"p":"38160.9","s":0},{"p":"38160.3","s":0}],"b":[{"p":"38142.6","s":2334},{"p":"38143.2","s":2620},{"p":"38144","s":0},{"p":"38141.7","s":2268},{"p":"38142","s":0},{"p":"38141.3","s":0},{"p":"38142.5","s":733},{"p":"38141.6","s":13980}],"s":"BTC_USDT","t":1701245659100,"u":53095237876}}
{"time":1701245659,"time_ms":1701245659133,"channel":"futures.order_book_update","event":"update","result":{"U":53095237877,"a":[{"p":"38157.5","s":0},{"p":"38157.7","s":0}],"b":[{"p":"38141.5","s":0},{"p":"38142.6","s":3060},{"p":"38143.5","s":2},{"p":"38142.7","s":2},{"p":"38142","s":2},{"p":"38141.6","s":0},{"p":"38142.5","s":0},{"p":"38141.7","s":0}],"s":"BTC_USDT","t":1701245659126,"u":53095237894}}
{"time":1701245659,"time_ms":1701245659152,"channel":"futures.order_book_update","event":"update","result":{"U":53095237895,"a":[{"p":"38157.6","s":0}],"b":[],"s":"BTC_USDT","t":1701245659133,"u":53095237895}}
{"time":1701245659,"time_ms":1701245659193,"channel":"futures.order_book_update","event":"update","result":{"U":53095237896,"a":[],"b":[{"p":"38142.6","s":26},{"p":"38142","s":3138}],"s":"BTC_USDT","t":1701245659186,"u":53095237900}}
{"time":1701245659,"time_ms":1701245659252,"channel":"futures.order_book_update","event":"update","result":{"U":53095237901,"a":[{"p":"38154.7","s":0}],"b":[{"p":"38141.5","s":0}],"s":"BTC_USDT","t":1701245659242,"u":53095237905}}
{"time":1701245659,"time_ms":1701245659271,"channel":"futures.order_book_update","event":"update","result":{"U":53095237906,"a":[],"b":[{"p":"38134","s":0}],"s":"BTC_USDT","t":1701245659245,"u":53095237907}}
{"time":1701245659,"time_ms":1701245659392,"channel":"futures.order_book_update","event":"update","result":{"U":53095237908,"a":[{"p":"38160.5","s":0},{"p":"38160.3","s":0},{"p":"38157.6","s":0},{"p":"38146.6","s":16750},{"p":"38156.5","s":0}],"b":[{"p":"38137.9","s":0}],"s":"BTC_USDT","t":1701245659373,"u":53095237920}}
{"time":1701245659,"time_ms":1701245659530,"channel":"futures.order_book_update","event":"update","result":{"U":53095237921,"a":[{"p":"38154.2","s":0}],"b":[{"p":"38134","s":0}],"s":"BTC_USDT","t":1701245659519,"u":53095237923}}
{"time":1701245659,"time_ms":1701245659592,"channel":"futures.order_book_update","event":"update","result":{"U":53095237924,"a":[{"p":"38157","s":0},{"p":"38161","s":0},{"p":"38161.5","s":0}],"b":[{"p":"38141","s":0},{"p":"38134.3","s":0},{"p":"38137","s":0},{"p":"38129.5","s":0}],"s":"BTC_USDT","t":1701245659579,"u":53095237941}}
{"time":1701245659,"time_ms":1701245659612,"channel":"futures.order_book_update","event":"update","result":{"U":53095237942,"a":[{"p":"38165.9","s":0}],"b":[{"p":"38143.2","s":0},{"p":"38138.6","s":0},{"p":"38141.7","s":2268}],"s":"BTC_USDT","t":1701245659594,"u":53095237949}}
{"time":1701245659,"time_ms":1701245659633,"channel":"futures.order_book_update","event":"update","result":{"U":53095237950,"a":[],"b":[{"p":"38143.6","s":1266}],"s":"BTC_USDT","t":1701245659613,"u":53095237951}}
{"time":1701245659,"time_ms":1701245659692,"channel":"futures.order_book_update","event":"update","result":{"U":53095237952,"a":[],"b":[{"p":"38141.7","s":0},{"p":"38141.4","s":0},{"p":"38142.1","s":9963}],"s":"BTC_USDT","t":1701245659677,"u":53095237956}}
{"time":1701245659,"time_ms":1701245659952,"channel":"futures.order_book_update","event":"update","result":{"U":53095237957,"a":[{"p":"38146.6","s":23250}],"b":[],"s":"BTC_USDT","t":1701245659932,"u":53095237963}}
{"time":1701245659,"time_ms":1701245659972,"channel":"futures.order_book_update","event":"update","result":{"U":53095237964,"a":[{"p":"38155.8","s":0},{"p":"38154.7","s":0},{"p":"38146.6","s":23750}],"b":[{"p":"38141.7","s":0},{"p":"38136.5","s":0},{"p":"38138.2","s":0}],"s":"BTC_USDT","t":1701245659964,"u":53095237973}}
{"time":1701245660,"time_ms":1701245660012,"channel":"futures.order_book_update","event":"update","result":{"U":53095237974,"a":[{"p":"38155.5","s":0}],"b":[{"p":"38140.8","s":0},{"p":"38142","s":3136},{"p":"38141.7","s":94},{"p":"38141.6","s":16600},{"p":"38142.7","s":0},{"p":"38143.5","s":0}],"s":"BTC_USDT","t":1701245660000,"u":53095237981}}
{"time":1701245660,"time_ms":1701245660031,"channel":"futures.order_book_update","event":"update","result":{"U":53095237982,"a":[{"p":"38160.9","s":0},{"p":"38157.9","s":0},{"p":"38157.5","s":0},{"p":"38172.4","s":0}],"b":[{"p":"38141.3","s":0},{"p":"38137.9","s":0},{"p":"38142.2","s":3111},{"p":"38141.7","s":2268},{"p":"38142","s":0},{"p":"38141.6","s":16600}],"s":"BTC_USDT","t":1701245660019,"u":53095237997}}
{"time":1701245660,"time_ms":1701245660051,"channel":"futures.order_book_update","event":"update","result":{"U":53095237998,"a":[],"b":[{"p":"38142.5","s":2},{"p":"38144","s":2},{"p":"38141.9","s":0},{"p":"38141.7","s":0},{"p":"38141.6","s":0},{"p":"38143.2","s":2}],"s":"BTC_USDT","t":1701245660033,"u":53095238001}}
{"time":1701245660,"time_ms":1701245660073,"channel":"futures.order_book_update","event":"update","result":{"U":53095238002,"a":[{"p":"38157.7","s":0}],"b":[{"p":"38135.1","s":0}],"s":"BTC_USDT","t":1701245660061,"u":53095238005}}
{"time":1701245660,"time_ms":1701245660092,"channel":"futures.order_book_update","event":"update","result":{"U":53095238006,"a":[],"b":[{"p":"38128.7","s":0}],"s":"BTC_USDT","t":1701245660081,"u":53095238006}}
{"time":1701245660,"time_ms":1701245660113,"channel":"futures.order_book_update","event":"update","result":{"U":53095238007,"a":[{"p":"38157.8","s":0}],"b":[],"s":"BTC_USDT","t":1701245660085,"u":53095238008}}
{"time":1701245660,"time_ms":1701245660153,"channel":"futures.order_book_update","event":"update","result":{"U":53095238009,"a":[{"p":"38160.5","s":0}],"b":[{"p":"38143.5","s":2174},{"p":"38143","s":0},{"p":"38141.9","s":0},{"p":"38141.4","s":0},{"p":"38134.7","s":0}],"s":"BTC_USDT","t":1701245660146,"u":53095238016}}
{"time":1701245660,"time_ms":1701245660173,"channel":"futures.order_book_update","event":"update","result":{"U":53095238017,"a":[{"p":"38146.6","s":17250},{"p":"38154.7","s":0}],"b":[{"p":"38143.6","s":322}],"s":"BTC_USDT","t":1701245660164,"u":53095238020}}
{"time":1701245660,"time_ms":1701245660192,"channel":"futures.order_book_update","event":"update","result":{"U":53095238021,"a":[{"p":"38160.9","s":0}],"b":[],"s":"BTC_USDT","t":1701245660183,"u":53095238023}}
{"time":1701245660,"time_ms":1701245660334,"channel":"futures.order_book_update","event":"update","result":{"U":53095238024,"a":[{"p":"38156","s":0},{"p":"38160","s":0}],"b":[{"p":"38146.5","s":132609}],"s":"BTC_USDT","t":1701245660317,"u":53095238028}}
{"time":1701245660,"time_ms":1701245660351,"channel":"futures.order_book_update","event":"update","result":{"U":53095238029,"a":[{"p":"38146.6","s":44750},{"p":"38165","s":0}],"b":[{"p":"38144","s":202},{"p":"38141.9","s":3932},{"p":"38145","s":0}],"s":"BTC_USDT","t":1701245660332,"u":53095238037}}
{"time":1701245660,"time_ms":1701245660372,"channel":"futures.order_book_update","event":"update","result":{"U":53095238038,"a":[{"p":"38155.9","s":0},{"p":"38157.4","s":0},{"p":"38160.5","s":0},{"p":"38176.8","s":0},{"p":"38155.8","s":0}],"b":[{"p":"38144","s":2},{"p":"38141.9","s":0},{"p":"38079.2","s":0},{"p":"38101.4","s":0},{"p":"38112.2","s":0},{"p":"38145","s":200}],"s":"BTC_USDT","t":1701245660365,"u":53095238058}}
{"time":1701245660,"time_ms":1701245660412,"channel":"futures.order_book_update","event":"update","result":{"U":53095238059,"a":[{"p":"38156.2","s":0},{"p":"38154.7","s":0},{"p":"38160","s":0}],"b":[{"p":"38146.5","s":132539},{"p":"38121.9","s":0}],"s":"BTC_USDT","t":1701245660396,"u":53095238067}}
{"time":1701245660,"time_ms":1701245660433,"channel":"futures.order_book_update","event":"update","result":{"U":53095238068,"a":[],"b":[{"p":"38135.1","s":0}],"s":"BTC_USDT","t":1701245660415,"u":53095238070}}
{"time":1701245660,"time_ms":1701245660614,"channel":"futures.order_book_update","event":"update","result":{"U":53095238071,"a":[{"p":"38157.9","s":0}],"b":[],"s":"BTC_USDT","t":1701245660598,"u":53095238074}}
{"time":1701245660,"time_ms":1701245660633,"channel":"futures.order_book_update","event":"update","result":{"U":53095238075,"a":[{"p":"38155.9","s":0},{"p":"38157.3","s":0},{"p":"38157.6","s":0}],"b":[{"p":"38142.2","s":2378}],"s":"BTC_USDT","t":1701245660623,"u":53095238084}}
{"time":1701245660,"time_ms":1701245660652,"channel":"futures.order_book_update","event":"update","result":{"U":53095238085,"a":[{"p":"38158.2","s":0}],"b":[{"p":"38143","s":733},{"p":"38142.1","s":0}],"s":"BTC_USDT","t":1701245660630,"u":53095238087}}
{"time":1701245660,"time_ms":1701245660712,"channel":"futures.order_book_update","event":"update","result":{"U":53095238088,"a":[{"p":"38146.6","s":45250}],"b":[],"s":"BTC_USDT","t":1701245660689,"u":53095238088}}
{"time":1701245660,"time_ms":1701245660752,"channel":"futures.order_book_update","event":"update","result":{"U":53095238089,"a":[{"p":"38154.6","s":0}],"b":[],"s":"BTC_USDT","t":1701245660732,"u":53095238089}}
{"time":1701245660,"time_ms":1701245660771,"channel":"futures.order_book_update","event":"update","result":{"U":53095238090,"a":[{"p":"38146.6","s":44250}],"b":[{"p":"38142.2","s":4552},{"p":"38141.7","s":0}],"s":"BTC_USDT","t":1701245660760,"u":53095238093}}
{"time":1701245660,"time_ms":1701245660792,"channel":"futures.order_book_update","event":"update","result":{"U":53095238094,"a":[{"p":"38146.6","s":16750}],"b":[],"s":"BTC_USDT","t":1701245660763,"u":53095238094}}
{"time":1701245660,"time_ms":1701245660812,"channel":"futures.order_book_update","event":"update","result":{"U":53095238095,"a":[{"p":"38146.6","s":15750},{"p":"38172.5","s":0},{"p":"38160.9","s":0},{"p":"38160","s":0},{"p":"38157.5","s":0}],"b":[{"p":"38146.5","s":132609}],"s":"BTC_USDT","t":1701245660801,"u":53095238105}}
{"time":1701245660,"time_ms":1701245660832,"channel":"futures.order_book_update","event":"update","result":{"U":53095238106,"a":[],"b":[{"p":"38138.2","s":0}],"s":"BTC_USDT","t":1701245660809,"u":53095238107}}
{"time":1701245660,"time_ms":1701245660851,"channel":"futures.order_book_update","event":"update","result":{"U":53095238108,"a":[{"p":"38152.1","s":0},{"p":"38153","s":0},{"p":"38156.2","s":0},{"p":"38157.9","s":0},{"p":"38152.8","s":654}],"b":[],"s":"BTC_USDT","t":1701245660836,"u":53095238113}}
{"time":1701245660,"time_ms":1701245660931,"channel":"futures.order_book_update","event":"update","result":{"U":53095238114,"a":[{"p":"38146.6","s":32250},{"p":"38156.5","s":0},{"p":"38160.5","s":0}],"b":[{"p":"38138.2","s":0},{"p":"38141.6","s":0},{"p":"38138.9","s":0}],"s":"BTC_USDT","t":1701245660921,"u":53095238123}}
{"time":1701245660,"time_ms":1701245660951,"channel":"futures.order_book_update","event":"update","result":{"U":53095238124,"a":[{"p":"38156","s":0},{"p":"38160","s":0}],"b":[],"s":"BTC_USDT","t":1701245660939,"u":53095238128}}
{"time":1701245660,"time_ms":1701245660978,"channel":"futures.order_book_update","event":"update","result":{"U":53095238129,"a":[{"p":"38161.3","s":0}],"b":[],"s":"BTC_USDT","t":1701245660948,"u":53095238130}}
{"time":1701245660,"time_ms":1701245660996,"channel":"futures.order_book_update","event":"update","result":{"U":53095238131,"a":[{"p":"38165","s":0},{"p":"38158.5","s":0}],"b":[{"p":"38142.2","s":2174},{"p":"38143.5","s":4477},{"p":"38134.7","s":0}],"s":"BTC_USDT","t":1701245660987,"u":53095238138}}
{"time":1701245661,"time_ms":1701245661014,"channel":"futures.order_book_update","event":"update","result":{"U":53095238139,"a":[{"p":"38173","s":0},{"p":"38158.2","s":0},{"p":"38157.8","s":0}],"b":[{"p":"38142.1","s":9963},{"p":"38144","s":2176},{"p":"38143.7","s":1257},{"p":"38143.5","s":2303},{"p":"38143","s":0}],"s":"BTC_USDT","t":1701245661006,"u":53095238148}}
{"time":1701245661,"time_ms":1701245661034,"channel":"futures.order_book_update","event":"update","result":{"U":53095238149,"a":[{"p":"38156.8","s":0}],"b":[],"s":"BTC_USDT","t":1701245661012,"u":53095238150}}
{"time":1701245661,"time_ms":1701245661052,"channel":"futures.order_book_update","event":"update","result":{"U":53095238151,"a":[{"p":"38158.9","s":0}],"b":[],"s":"BTC_USDT","t":1701245661028,"u":53095238152}}
{"time":1701245661,"time_ms":1701245661093,"channel":"futures.order_book_update","event":"update","result":{"U":53095238153,"a":[{"p":"38160","s":0},{"p":"38158.1","s":0}],"b":[{"p":"38142.5","s":0},{"p":"38143.2","s":0},{"p":"38141.3","s":0},{"p":"38144","s":2174},{"p":"38141.9","s":3932},{"p":"38141.7","s":94}],"s":"BTC_USDT","t":1701245661084,"u":53095238160}}
{"time":1701245661,"time_ms":1701245661113,"channel":"futures.order_book_update","event":"update","result":{"U":53095238161,"a":[{"p":"38156.9","s":0}],"b":[{"p":"38143.7","s":1259},{"p":"38142.9","s":527},{"p":"38142.1","s":9965}],"s":"BTC_USDT","t":1701245661101,"u":53095238167}}
{"time":1701245661,"time_ms":1701245661151,"channel":"futures.order_book_update","event":"update","result":{"U":53095238168,"a":[{"p":"38146.6","s":15300},{"p":"38158.7","s":0},{"p":"38154.4","s":0}],"b":[],"s":"BTC_USDT","t":1701245661144,"u":53095238172}}
{"time":1701245661,"time_ms":1701245661178,"channel":"futures.order_book_update","event":"update","result":{"U":53095238173,"a":[{"p":"38157.3","s":0},{"p":"38157","s":0}],"b":[],"s":"BTC_USDT","t":1701245661156,"u":53095238177}}
{"time":1701245661,"time_ms":1701245661198,"channel":"futures.order_book_update","event":"update","result":{"U":53095238178,"a":[],"b":[{"p":"38144.5","s":9006},{"p":"38139.1","s":0},{"p":"38141.6","s":0},{"p":"38144","s":2174}],"s":"BTC_USDT","t":1701245661180,"u":53095238183}}
{"time":1701245661,"time_ms":1701245661213,"channel":"futures.order_book_update","event":"update","result":{"U":53095238184,"a":[],"b":[{"p":"38144","s":0},{"p":"38141.6","s":0},{"p":"38144.1","s":2174}],"s":"BTC_USDT","t":1701245661196,"u":53095238185}}
{"time":1701245661,"time_ms":1701245661232,"channel":"futures.order_book_update","event":"update","result":{"U":53095238186,"a":[],"b":[{"p":"38143.6","s":1829}],"s":"BTC_USDT","t":1701245661216,"u":53095238186}}
{"time":1701245661,"time_ms":1701245661265,"channel":"futures.order_book_update","event":"update","result":{"U":53095238187,"a":[{"p":"38158.1","s":0},{"p":"38156.8","s":0},{"p":"38157.9","s":0},{"p":"38161.9","s":0},{"p":"38156.3","s":0},{"p":"38158.5","s":0},{"p":"38154.2","s":0},{"p":"38158.9","s":0}],"b":[{"p":"38139.6","s":0},{"p":"38135.9","s":0},{"p":"38141.5","s":0},{"p":"38143.8","s":2174},{"p":"38143.7","s":526},{"p":"38143.5","s":0},{"p":"38144.1","s":0},{"p":"38141.6","s":0},{"p":"38142.3","s":0},{"p":"38138.2","s":0},{"p":"38143","s":733}],"s":"BTC_USDT","t":1701245661245,"u":53095238215}}
{"time":1701245661,"time_ms":1701245661272,"channel":"futures.order_book_update","event":"update","result":{"U":53095238216,"a":[{"p":"38161.3","s":0}],"b":[{"p":"38143.5","s":2306},{"p":"38143.7","s":1259},{"p":"38143.6","s":322},{"p":"38143","s":0},{"p":"38141.7","s":94}],"s":"BTC_USDT","t":1701245661262,"u":53095238222}}
{"time":1701245661,"time_ms":1701245661374,"channel":"futures.order_book_update","event":"update","result":{"U":53095238223,"a":[{"p":"38146.6","s":17250},{"p":"38156.8","s":0}],"b":[{"p":"38139.1","s":0},{"p":"38137.5","s":0},{"p":"38143","s":733},{"p":"38143.7","s":526},{"p":"38142.3","s":2468},{"p":"38141.7","s":0},{"p":"38143.5","s":0},{"p":"38141.6","s":0}],"s":"BTC_USDT","t":1701245661363,"u":53095238236}}
{"time":1701245661,"time_ms":1701245661394,"channel":"futures.order_book_update","event":"update","result":{"U":53095238237,"a":[{"p":"38156.5","s":0},{"p":"38160.5","s":0}],"b":[{"p":"38141","s":0},{"p":"38129.5","s":0},{"p":"38137","s":0}],"s":"BTC_USDT","t":1701245661382,"u":53095238243}}
{"time":1701245661,"time_ms":1701245661414,"channel":"futures.order_book_update","event":"update","result":{"U":53095238244,"a":[{"p":"38162.7","s":0}],"b":[{"p":"38140.7","s":0}],"s":"BTC_USDT","t":1701245661402,"u":53095238245}}
{"time":1701245661,"time_ms":1701245661432,"channel":"futures.order_book_update","event":"update","result":{"U":53095238246,"a":[{"p":"38158.2","s":0},{"p":"38161.8","s":0}],"b":[],"s":"BTC_USDT","t":1701245661417,"u":53095238250}}
{"time":1701245661,"time_ms":1701245661453,"channel":"futures.order_book_update","event":"update","result":{"U":53095238251,"a":[{"p":"38163.9","s":0},{"p":"38168.6","s":0}],"b":[{"p":"38141","s":0},{"p":"38133.4","s":0},{"p":"38139.7","s":0},{"p":"38142.1","s":9963},{"p":"38143.7","s":524},{"p":"38142.9","s":525},{"p":"38135.8","s":0},{"p":"38130.7","s":0}],"s":"BTC_USDT","t":1701245661434,"u":53095238262}}
{"time":1701245661,"time_ms":1701245661478,"channel":"futures.order_book_update","event":"update","result":{"U":53095238263,"a":[{"p":"38159.5","s":0},{"p":"38155.5","s":0},{"p":"38156","s":0},{"p":"38160","s":0}],"b":[{"p":"38143.5","s":2},{"p":"38142.7","s":2},{"p":"38142.1","s":0},{"p":"38141.9","s":0},{"p":"38142","s":0}],"s":"BTC_USDT","t":1701245661464,"u":53095238276}}
{"time":1701245661,"time_ms":1701245661492,"channel":"futures.order_book_update","event":"update","result":{"U":53095238277,"a":[{"p":"38155","s":0},{"p":"38159","s":0}],"b":[{"p":"38142.1","s":9963},{"p":"38143.8","s":0}],"s":"BTC_USDT","t":1701245661481,"u":53095238282}}
{"time":1701245661,"time_ms":1701245661512,"channel":"futures.order_book_update","event":"update","result":{"U":53095238283,"a":[],"b":[{"p":"38143.1","s":2174},{"p":"38143","s":0},{"p":"38142.1","s":9963}],"s":"BTC_USDT","t":1701245661502,"u":53095238285}}
{"time":1701245661,"time_ms":1701245661534,"channel":"futures.order_book_update","event":"update","result":{"U":53095238286,"a":[],"b":[{"p":"38142.4","s":733},{"p":"38142.2","s":0},{"p":"38142","s":0}],"s":"BTC_USDT","t":1701245661508,"u":53095238288}}
{"time":1701245661,"time_ms":1701245661552,"channel":"futures.order_book_update","event":"update","result":{"U":53095238289,"a":[{"p":"38153","s":34},{"p":"38152.8","s":0}],"b":[{"p":"38143.5","s":0},{"p":"38142","s":0},{"p":"38140.8","s":0},{"p":"38143.6","s":1270},{"p":"38141.9","s":3932},{"p":"38141.7","s":2268},{"p":"38142.7","s":0}],"s":"BTC_USDT","t":1701245661540,"u":53095238297}}
{"time":1701245661,"time_ms":1701245661592,"channel":"futures.order_book_update","event":"update","result":{"U":53095238298,"a":[{"p":"38146.6","s":22544},{"p":"38155.5","s":0},{"p":"38159.5","s":0}],"b":[{"p":"38142.7","s":2},{"p":"38143.5","s":2},{"p":"38141.9","s":0},{"p":"38141.7","s":0},{"p":"38142","s":0}],"s":"BTC_USDT","t":1701245661578,"u":53095238306}}
{"time":1701245661,"time_ms":1701245661614,"channel":"futures.order_book_update","event":"update","result":{"U":53095238307,"a":[{"p":"38160","s":0},{"p":"38158.5","s":0},{"p":"38160.9","s":0},{"p":"38158.2","s":0},{"p":"38156.4","s":0},{"p":"38156","s":0}],"b":[{"p":"38142","s":0},{"p":"38138.2","s":0},{"p":"38135.4","s":0},{"p":"38142.5","s":2174},{"p":"38141.9","s":3932},{"p":"38141.7","s":94},{"p":"38143.1","s":0},{"p":"38143.5","s":0},{"p":"38142.7","s":0}],"s":"BTC_USDT","t":1701245661603,"u":53095238330}}
{"time":1701245661,"time_ms":1701245661634,"channel":"futures.order_book_update","event":"update","result":{"U":53095238331,"a":[],"b":[{"p":"38141.6","s":14006},{"p":"38143.6","s":0},{"p":"38140.4","s":0},{"p":"38146.5","s":129464}],"s":"BTC_USDT","t":1701245661616,"u":53095238334}}
{"time":1701245661,"time_ms":1701245661652,"channel":"futures.order_book_update","event":"update","result":{"U":53095238335,"a":[],"b":[{"p":"38141.6","s":0},{"p":"38143","s":1311}],"s":"BTC_USDT","t":1701245661632,"u":53095238336}}
{"time":1701245661,"time_ms":1701245661714,"channel":"futures.order_book_update","event":"update","result":{"U":53095238337,"a":[{"p":"38156.4","s":0}],"b":[],"s":"BTC_USDT","t":1701245661703,"u":53095238339}}
{"time":1701245661,"time_ms":1701245661776,"channel":"futures.order_book_update","event":"update","result":{"U":53095238340,"a":[{"p":"38159.5","s":0},{"p":"38155.5","s":0}],"b":[],"s":"BTC_USDT","t":1701245661749,"u":53095238348}}
{"time":1701245661,"time_ms":1701245661812,"channel":"futures.order_book_update","event":"update","result":{"U":53095238349,"a":[{"p":"38158.8","s":0}],"b":[],"s":"BTC_USDT","t":1701245661793,"u":53095238349}}
{"time":1701245661,"time_ms":1701245661872,"channel":"futures.order_book_update","event":"update","result":{"U":53095238350,"a":[{"p":"38165.4","s":0}],"b":[{"p":"38125.3","s":0},{"p":"38136.7","s":0},{"p":"38146.5","s":132609}],"s":"BTC_USDT","t":1701245661859,"u":53095238356}}
{"time":1701245661,"time_ms":1701245661932,"channel":"futures.order_book_update","event":"update","result":{"U":53095238357,"a":[{"p":"38146.6","s":33544},{"p":"38154.2","s":0}],"b":[],"s":"BTC_USDT","t":1701245661921,"u":53095238359}}
{"time":1701245662,"time_ms":1701245662012,"channel":"futures.order_book_update","event":"update","result":{"U":53095238360,"a":[{"p":"38155.2","s":0}],"b":[{"p":"38141.1","s":0}],"s":"BTC_USDT","t":1701245662003,"u":53095238364}}
{"time":1701245662,"time_ms":1701245662032,"channel":"futures.order_book_update","event":"update","result":{"U":53095238365,"a":[{"p":"38157.3","s":0},{"p":"38173.3","s":0}],"b":[{"p":"38142.3","s":0},{"p":"38141.6","s":0},{"p":"38142.2","s":2327}],"s":"BTC_USDT","t":1701245662024,"u":53095238374}}
{"time":1701245662,"time_ms":1701245662052,"channel":"futures.order_book_update","event":"update","result":{"U":53095238375,"a":[{"p":"38156.8","s":0}],"b":[],"s":"BTC_USDT","t":1701245662041,"u":53095238378}}
{"time":1701245662,"time_ms":1701245662073,"channel":"futures.order_book_update","event":"update","result":{"U":53095238379,"a":[{"p":"38157","s":0},{"p":"38172.2","s":0},{"p":"38155.4","s":0},{"p":"38159.9","s":0},{"p":"38156.9","s":0},{"p":"38159.8","s":0}],"b":[{"p":"38137.4","s":0},{"p":"38142.6","s":3068},{"p":"38141.7","s":2268},{"p":"38141.5","s":1315},{"p":"38143.1","s":2174},{"p":"38142.5","s":0},{"p":"38142.2","s":0},{"p":"38141.6","s":14006},{"p":"38142.4","s":0},{"p":"38141.3","s":0}],"s":"BTC_USDT","t":1701245662056,"u":53095238404}}
{"time":1701245662,"time_ms":1701245662113,"channel":"futures.order_book_update","event":"update","result":{"U":53095238405,"a":[],"b":[{"p":"38142.2","s":2377},{"p":"38142.6","s":759},{"p":"38141.5","s":0}],"s":"BTC_USDT","t":1701245662085,"u":53095238408}}
{"time":1701245662,"time_ms":1701245662134,"channel":"futures.order_book_update","event":"update","result":{"U":53095238409,"a":[],"b":[{"p":"38143.5","s":1312},{"p":"38143","s":0},{"p":"38141.5","s":0}],"s":"BTC_USDT","t":1701245662115,"u":53095238410}}
{"time":1701245662,"time_ms":1701245662192,"channel":"futures.order_book_update","event":"update","result":{"U":53095238411,"a":[{"p":"38148.1","s":75},{"p":"38153","s":0},{"p":"38160.9","s":0}],"b":[],"s":"BTC_USDT","t":1701245662184,"u":53095238413}}
{"time":1701245662,"time_ms":1701245662214,"channel":"futures.order_book_update","event":"update","result":{"U":53095238414,"a":[],"b":[{"p":"38142.3","s":733},{"p":"38142.6","s":26},{"p":"38141.6","s":0}],"s":"BTC_USDT","t":1701245662193,"u":53095238415}}
{"time":1701245662,"time_ms":1701245662272,"channel":"futures.order_book_update","event":"update","result":{"U":53095238416,"a":[],"b":[{"p":"38141.7","s":94},{"p":"38078.7","s":0},{"p":"38138.2","s":0},{"p":"38056.8","s":0}],"s":"BTC_USDT","t":1701245662261,"u":53095238421}}
{"time":1701245662,"time_ms":1701245662433,"channel":"futures.order_book_update","event":"update","result":{"U":53095238422,"a":[],"b":[{"p":"38141.6","s":0},{"p":"38130.2","s":0}],"s":"BTC_USDT","t":1701245662411,"u":53095238425}}
{"time":1701245662,"time_ms":1701245662499,"channel":"futures.order_book_update","event":"update","result":{"U":53095238426,"a":[{"p":"38157.5","s":0}],"b":[],"s":"BTC_USDT","t":1701245662474,"u":53095238429}}
{"time":1701245662,"time_ms":1701245662792,"channel":"futures.order_book_update","event":"update","result":{"U":53095238430,"a":[],"b":[{"p":"38145.6","s":2946}],"s":"BTC_USDT","t":1701245662785,"u":53095238446}}
{"time":1701245662,"time_ms":1701245662832,"channel":"futures.order_book_update","event":"update","result":{"U":53095238447,"a":[{"p":"38153.6","s":0}],"b":[],"s":"BTC_USDT","t":1701245662810,"u":53095238447}}
{"time":1701245662,"time_ms":1701245662932,"channel":"futures.order_book_update","event":"update","result":{"U":53095238448,"a":[{"p":"38157.7","s":0}],"b":[{"p":"38141.6","s":13980},{"p":"38143.1","s":0}],"s":"BTC_USDT","t":1701245662923,"u":53095238454}}
{"time":1701245662,"time_ms":1701245662952,"channel":"futures.order_book_update","event":"update","result":{"U":53095238455,"a":[{"p":"38157.4","s":0},{"p":"38160.5","s":0},{"p":"38155.8","s":0}],"b":[{"p":"38143.5","s":324},{"p":"38142.4","s":2174},{"p":"38141.6","s":0},{"p":"38137.9","s":0}],"s":"BTC_USDT","t":1701245662938,"u":53095238468}}
{"time":1701245663,"time_ms":1701245663014,"channel":"futures.order_book_update","event":"update","result":{"U":53095238469,"a":[{"p":"38146.6","s":22544}],"b":[],"s":"BTC_USDT","t":1701245663001,"u":53095238469}}
{"time":1701245663,"time_ms":1701245663032,"channel":"futures.order_book_update","event":"update","result":{"U":53095238470,"a":[{"p":"38159.8","s":0},{"p":"38157","s":0},{"p":"38155.3","s":0}],"b":[],"s":"BTC_USDT","t":1701245663021,"u":53095238475}}
{"time":1701245663,"time_ms":1701245663052,"channel":"futures.order_book_update","event":"update","result":{"U":53095238476,"a":[{"p":"38172.5","s":0},{"p":"38157.2","s":0}],"b":[],"s":"BTC_USDT","t":1701245663042,"u":53095238480}}
{"time":1701245663,"time_ms":1701245663071,"channel":"futures.order_book_update","event":"update","result":{"U":53095238481,"a":[{"p":"38159.6","s":0}],"b":[],"s":"BTC_USDT","t":1701245663053,"u":53095238483}}
{"time":1701245663,"time_ms":1701245663133,"channel":"futures.order_book_update","event":"update","result":{"U":53095238484,"a":[{"p":"38156.8","s":0}],"b":[{"p":"38081.9","s":0}],"s":"BTC_USDT","t":1701245663110,"u":53095238488}}
{"time":1701245663,"time_ms":1701245663153,"channel":"futures.order_book_update","event":"update","result":{"U":53095238489,"a":[{"p":"38153.6","s":0},{"p":"38156.7","s":0}],"b":[{"p":"38140.9","s":0}],"s":"BTC_USDT","t":1701245663138,"u":53095238494}}
{"time":1701245663,"time_ms":1701245663252,"channel":"futures.order_book_update","event":"update","result":{"U":53095238495,"a":[{"p":"38156.9","s":0}],"b":[],"s":"BTC_USDT","t":1701245663226,"u":53095238499}}
{"time":1701245663,"time_ms":1701245663293,"channel":"futures.order_book_update","event":"update","result":{"U":53095238500,"a":[{"p":"38146.6","s":23044},{"p":"38160","s":0},{"p":"38156.7","s":0},{"p":"38156","s":0}],"b":[{"p":"38134.7","s":0},{"p":"38141.3","s":0}],"s":"BTC_USDT","t":1701245663282,"u":53095238512}}
{"time":1701245663,"time_ms":1701245663313,"channel":"futures.order_book_update","event":"update","result":{"U":53095238513,"a":[{"p":"38159.7","s":0},{"p":"38159.4","s":0},{"p":"38155.5","s":0},{"p":"38156.6","s":0},{"p":"38168","s":0},{"p":"38156.4","s":0},{"p":"38155","s":0},{"p":"38159.5","s":0},{"p":"38155.2","s":0}],"b":[{"p":"38141.6","s":13980},{"p":"38142.3","s":0},{"p":"38142.2","s":0},{"p":"38142","s":3046}],"s":"BTC_USDT","t":1701245663305,"u":53095238535}}
{"time":1701245663,"time_ms":1701245663353,"channel":"futures.order_book_update","event":"update","result":{"U":53095238536,"a":[],"b":[{"p":"38142.9","s":527},{"p":"38142.1","s":9965}],"s":"BTC_USDT","t":1701245663333,"u":53095238541}}
{"time":1701245663,"time_ms":1701245663393,"channel":"futures.order_book_update","event":"update","result":{"U":53095238542,"a":[{"p":"38156.8","s":0},{"p":"38158.8","s":0}],"b":[{"p":"38142.2","s":2174},{"p":"38142.4","s":0},{"p":"38141.5","s":0}],"s":"BTC_USDT","t":1701245663381,"u":53095238545}}
{"time":1701245663,"time_ms":1701245663414,"channel":"futures.order_book_update","event":"update","result":{"U":53095238546,"a":[{"p":"38157","s":0},{"p":"38156.5","s":0},{"p":"38155.2","s":0},{"p":"38159.6","s":0},{"p":"38154.9","s":0}],"b":[{"p":"38141.3","s":0},{"p":"38141.5","s":0},{"p":"38143","s":2174},{"p":"38142.9","s":525},{"p":"38142.1","s":9963},{"p":"38142.2","s":0},{"p":"38137.4","s":0},{"p":"38140.2","s":0}],"s":"BTC_USDT","t":1701245663400,"u":53095238564}}
{"time":1701245663,"time_ms":1701245663433,"channel":"futures.order_book_update","event":"update","result":{"U":53095238565,"a":[{"p":"38157","s":0},{"p":"38155.6","s":0},{"p":"38161.5","s":0},{"p":"38157.5","s":0}],"b":[{"p":"38143","s":0},{"p":"38137.9","s":0},{"p":"38143.5","s":1265},{"p":"38141.5","s":1315}],"s":"BTC_USDT","t":1701245663418,"u":53095238575}}
{"time":1701245663,"time_ms":1701245663452,"channel":"futures.order_book_update","event":"update","result":{"U":53095238576,"a":[{"p":"38160.1","s":0}],"b":[{"p":"38142.5","s":2174},{"p":"38141.6","s":0},{"p":"38141.5","s":0},{"p":"38142","s":3048},{"p":"38143.5","s":324},{"p":"38142.8","s":2}],"s":"BTC_USDT","t":1701245663440,"u":53095238584}}
{"time":1701245663,"time_ms":1701245663473,"channel":"futures.order_book_update","event":"update","result":{"U":53095238585,"a":[{"p":"38153.6","s":0}],"b":[{"p":"38141.6","s":0},{"p":"38143","s":1306},{"p":"38143.5","s":0}],"s":"BTC_USDT","t":1701245663453,"u":53095238587}}
{"time":1701245663,"time_ms":1701245663654,"channel":"futures.order_book_update","event":"update","result":{"U":53095238588,"a":[],"b":[{"p":"38142","s":3046},{"p":"38141.6","s":13980},{"p":"38142.8","s":0},{"p":"38141.2","s":0},{"p":"38140.1","s":0}],"s":"BTC_USDT","t":1701245663624,"u":53095238592}}
{"time":1701245663,"time_ms":1701245663675,"channel":"futures.order_book_update","event":"update","result":{"U":53095238593,"a":[],"b":[{"p":"38142.8","s":2},{"p":"38142","s":3048},{"p":"38141.6","s":0}],"s":"BTC_USDT","t":1701245663663,"u":53095238596}}
{"time":1701245663,"time_ms":1701245663694,"channel":"futures.order_book_update","event":"update","result":{"U":53095238597,"a":[{"p":"38159.4","s":0},{"p":"38156.5","s":0}],"b":[],"s":"BTC_USDT","t":1701245663683,"u":53095238600}}
{"time":1701245663,"time_ms":1701245663712,"channel":"futures.order_book_update","event":"update","result":{"U":53095238601,"a":[{"p":"38155.2","s":0}],"b":[],"s":"BTC_USDT","t":1701245663685,"u":53095238602}}
{"time":1701245663,"time_ms":1701245663853,"channel":"futures.order_book_update","event":"update","result":{"U":53095238603,"a":[{"p":"38153.4","s":0}],"b":[],"s":"BTC_USDT","t":1701245663838,"u":53095238605}}
{"time":1701245663,"time_ms":1701245663873,"channel":"futures.order_book_update","event":"update","result":{"U":53095238606,"a":[{"p":"38169.5","s":0}],"b":[],"s":"BTC_USDT","t":1701245663853,"u":53095238607}}
{"time":1701245664,"time_ms":1701245664017,"channel":"futures.order_book_update","event":"update","result":{"U":53095238608,"a":[],"b":[{"p":"38146.5","s":129464}],"s":"BTC_USDT","t":1701245663983,"u":53095238609}}
{"time":1701245664,"time_ms":1701245664034,"channel":"futures.order_book_update","event":"update","result":{"U":53095238610,"a":[{"p":"38157.3","s":0},{"p":"38160.1","s":0},{"p":"38169.9","s":0},{"p":"38155.6","s":0},{"p":"38156.6","s":0},{"p":"38192.6","s":0}],"b":[{"p":"38091","s":0},{"p":"38141.1","s":0},{"p":"38141.7","s":94},{"p":"38142.2","s":3045},{"p":"38142.6","s":2200},{"p":"38142","s":2},{"p":"38142.5","s":0},{"p":"38137.5","s":0}],"s":"BTC_USDT","t":1701245664027,"u":53095238636}}
{"time":1701245664,"time_ms":1701245664072,"channel":"futures.order_book_update","event":"update","result":{"U":53095238637,"a":[],"b":[{"p":"38141.3","s":0}],"s":"BTC_USDT","t":1701245664057,"u":53095238640}}
{"time":1701245664,"time_ms":1701245664112,"channel":"futures.order_book_update","event":"update","result":{"U":53095238641,"a":[],"b":[{"p":"38142.6","s":26},{"p":"38142.7","s":2174},{"p":"38141.7","s":0},{"p":"38142.3","s":0}],"s":"BTC_USDT","t":1701245664096,"u":53095238644}}
{"time":1701245664,"time_ms":1701245664172,"channel":"futures.order_book_update","event":"update","result":{"U":53095238645,"a":[{"p":"38156.5","s":0},{"p":"38160.5","s":0}],"b":[],"s":"BTC_USDT","t":1701245664151,"u":53095238648}}
{"time":1701245664,"time_ms":1701245664191,"channel":"futures.order_book_update","event":"update","result":{"U":53095238649,"a":[],"b":[{"p":"38142.8","s":0},{"p":"38140.1","s":0},{"p":"38141.2","s":0},{"p":"38141.7","s":94},{"p":"38141.6","s":13980},{"p":"38142","s":0}],"s":"BTC_USDT","t":1701245664179,"u":53095238652}}
{"time":1701245664,"time_ms":1701245664212,"channel":"futures.order_book_update","event":"update","result":{"U":53095238653,"a":[],"b":[{"p":"38142.7","s":2},{"p":"38142","s":2},{"p":"38142.3","s":2174},{"p":"38141.6","s":0},{"p":"38141.7","s":0},{"p":"38141.5","s":0}],"s":"BTC_USDT","t":1701245664204,"u":53095238658}}
{"time":1701245664,"time_ms":1701245664232,"channel":"futures.order_book_update","event":"update","result":{"U":53095238659,"a":[],"b":[{"p":"38146.5","s":126827},{"p":"38143","s":0},{"p":"38129","s":0},{"p":"38141","s":0},{"p":"38141.7","s":0},{"p":"38137","s":0},{"p":"38143.5","s":318}],"s":"BTC_USDT","t":1701245664214,"u":53095238664}}
{"time":1701245664,"time_ms":1701245664253,"channel":"futures.order_book_update","event":"update","result":{"U":53095238665,"a":[{"p":"38155.2","s":0},{"p":"38156.9","s":0},{"p":"38159.6","s":0}],"b":[],"s":"BTC_USDT","t":1701245664246,"u":53095238669}}
{"time":1701245664,"time_ms":1701245664275,"channel":"futures.order_book_update","event":"update","result":{"U":53095238670,"a":[],"b":[{"p":"38142.2","s":733},{"p":"38142","s":2326}],"s":"BTC_USDT","t":1701245664252,"u":53095238672}}
{"time":1701245664,"time_ms":1701245664312,"channel":"futures.order_book_update","event":"update","result":{"U":53095238673,"a":[{"p":"38154.9","s":0}],"b":[],"s":"BTC_USDT","t":1701245664291,"u":53095238674}}
{"time":1701245664,"time_ms":1701245664413,"channel":"futures.order_book_update","event":"update","result":{"U":53095238675,"a":[],"b":[{"p":"38142","s":2324},{"p":"38141.2","s":0},{"p":"38140","s":0}],"s":"BTC_USDT","t":1701245664405,"u":53095238680}}
{"time":1701245664,"time_ms":1701245664432,"channel":"futures.order_book_update","event":"update","result":{"U":53095238681,"a":[],"b":[{"p":"38141.7","s":94},{"p":"38142.7","s":0}],"s":"BTC_USDT","t":1701245664413,"u":53095238681}}
{"time":1701245664,"time_ms":1701245664453,"channel":"futures.order_book_update","event":"update","result":{"U":53095238682,"a":[],"b":[{"p":"38143.5","s":320},{"p":"38142.7","s":2},{"p":"38142","s":2326},{"p":"38141.7","s":0}],"s":"BTC_USDT","t":1701245664443,"u":53095238685}}
{"time":1701245664,"time_ms":1701245664633,"channel":"futures.order_book_update","event":"update","result":{"U":53095238686,"a":[{"p":"38152.8","s":1315},{"p":"38152.9","s":0}],"b":[],"s":"BTC_USDT","t":1701245664606,"u":53095238688}}
{"time":1701245664,"time_ms":1701245664691,"channel":"futures.order_book_update","event":"update","result":{"U":53095238689,"a":[],"b":[{"p":"38142","s":2324},{"p":"38143.5","s":318},{"p":"38141.7","s":94},{"p":"38142.7","s":0},{"p":"38140.8","s":0}],"s":"BTC_USDT","t":1701245664672,"u":53095238694}}
{"time":1701245664,"time_ms":1701245664711,"channel":"futures.order_book_update","event":"update","result":{"U":53095238695,"a":[{"p":"38153.4","s":0}],"b":[{"p":"38142","s":2326},{"p":"38142.7","s":2},{"p":"38143.5","s":320},{"p":"38141.7","s":0}],"s":"BTC_USDT","t":1701245664702,"u":53095238699}}
{"time":1701245664,"time_ms":1701245664733,"channel":"futures.order_book_update","event":"update","result":{"U":53095238700,"a":[{"p":"38160","s":0},{"p":"38159.3","s":0},{"p":"38155.9","s":0},{"p":"38156.7","s":0},{"p":"38156","s":0}],"b":[{"p":"38134.4","s":0},{"p":"38146.5","s":124190}],"s":"BTC_USDT","t":1701245664720,"u":53095238711}}
{"time":1701245664,"time_ms":1701245664896,"channel":"futures.order_book_update","event":"update","result":{"U":53095238712,"a":[{"p":"38146.6","s":31544}],"b":[],"s":"BTC_USDT","t":1701245664876,"u":53095238713}}
{"time":1701245664,"time_ms":1701245664952,"channel":"futures.order_book_update","event":"update","result":{"U":53095238714,"a":[],"b":[{"p":"38143.5","s":318},{"p":"38142","s":2324},{"p":"38141.7","s":94},{"p":"38142.7","s":0},{"p":"38140.8","s":0}],"s":"BTC_USDT","t":1701245664941,"u":53095238717}}
{"time":1701245664,"time_ms":1701245664972,"channel":"futures.order_book_update","event":"update","result":{"U":53095238718,"a":[],"b":[{"p":"38142.6","s":28},{"p":"38141.9","s":3934}],"s":"BTC_USDT","t":1701245664960,"u":53095238721}}
{"time":1701245665,"time_ms":1701245665032,"channel":"futures.order_book_update","event":"update","result":{"U":53095238722,"a":[{"p":"38152.5","s":1394},{"p":"38156.8","s":0},{"p":"38156.4","s":0}],"b":[{"p":"38142.2","s":2311},{"p":"38142.4","s":733},{"p":"38142","s":0},{"p":"38141.6","s":0},{"p":"38141.2","s":0}],"s":"BTC_USDT","t":1701245665022,"u":53095238732}}
{"time":1701245665,"time_ms":1701245665052,"channel":"futures.order_book_update","event":"update","result":{"U":53095238733,"a":[{"p":"38156.7","s":0},{"p":"38172.1","s":0},{"p":"38156.9","s":0},{"p":"38159.6","s":0},{"p":"38155.2","s":0},{"p":"38146.6","s":23044},{"p":"38156.4","s":0},{"p":"38154.2","s":0},{"p":"38156.2","s":0}],"b":[{"p":"38141.3","s":0},{"p":"38134.4","s":0},{"p":"38142.4","s":3047},{"p":"38141.6","s":13980},{"p":"38142.2","s":0},{"p":"38141.7","s":94}],"s":"BTC_USDT","t":1701245665044,"u":53095238756}}
{"time":1701245665,"time_ms":1701245665072,"channel":"futures.order_book_update","event":"update","result":{"U":53095238757,"a":[{"p":"38159.8","s":0}],"b":[],"s":"BTC_USDT","t":1701245665060,"u":53095238759}}
{"time":1701245665,"time_ms":1701245665112,"channel":"futures.order_book_update","event":"update","result":{"U":53095238760,"a":[{"p":"38156.7","s":0}],"b":[],"s":"BTC_USDT","t":1701245665084,"u":53095238761}}
{"time":1701245665,"time_ms":1701245665133,"channel":"futures.order_book_update","event":"update","result":{"U":53095238762,"a":[{"p":"38155.4","s":0}],"b":[],"s":"BTC_USDT","t":1701245665106,"u":53095238762}}
{"time":1701245665,"time_ms":1701245665191,"channel":"futures.order_book_update","event":"update","result":{"U":53095238763,"a":[{"p":"38155.4","s":0}],"b":[],"s":"BTC_USDT","t":1701245665177,"u":53095238764}}
{"time":1701245665,"time_ms":1701245665253,"channel":"futures.order_book_update","event":"update","result":{"U":53095238765,"a":[{"p":"38156.4","s":0},{"p":"38155.9","s":0}],"b":[],"s":"BTC_USDT","t":1701245665246,"u":53095238768}}
{"time":1701245665,"time_ms":1701245665272,"channel":"futures.order_book_update","event":"update","result":{"U":53095238769,"a":[],"b":[{"p":"38142.6","s":26},{"p":"38141.9","s":3932},{"p":"38141.1","s":0}],"s":"BTC_USDT","t":1701245665263,"u":53095238771}}
{"time":1701245665,"time_ms":1701245665295,"channel":"futures.order_book_update","event":"update","result":{"U":53095238772,"a":[],"b":[{"p":"38139.9","s":0}],"s":"BTC_USDT","t":1701245665282,"u":53095238773}}
{"time":1701245665,"time_ms":1701245665312,"channel":"futures.order_book_update","event":"update","result":{"U":53095238774,"a":[],"b":[{"p":"38143.5","s":320},{"p":"38142.7","s":2},{"p":"38141.6","s":0},{"p":"38053.2","s":0}],"s":"BTC_USDT","t":1701245665300,"u":53095238778}}
{"time":1701245665,"time_ms":1701245665333,"channel":"futures.order_book_update","event":"update","result":{"U":53095238779,"a":[],"b":[{"p":"38054.8","s":0},{"p":"38051.6","s":0},{"p":"38048","s":0},{"p":"38142","s":2},{"p":"38141.7","s":0}],"s":"BTC_USDT","t":1701245665322,"u":53095238782}}
{"time":1701245665,"time_ms":1701245665354,"channel":"futures.order_book_update","event":"update","result":{"U":53095238783,"a":[{"p":"38166.4","s":0}],"b":[],"s":"BTC_USDT","t":1701245665334,"u":53095238788}}
{"time":1701245665,"time_ms":1701245665392,"channel":"futures.order_book_update","event":"update","result":{"U":53095238789,"a":[],"b":[{"p":"38146.5","s":113602}],"s":"BTC_USDT","t":1701245665385,"u":53095238790}}
{"time":1701245665,"time_ms":1701245665413,"channel":"futures.order_book_update","event":"update","result":{"U":53095238791,"a":[{"p":"38160.5","s":0},{"p":"38156.2","s":0},{"p":"38170.8","s":0},{"p":"38160.4","s":0},{"p":"38155.5","s":0},{"p":"38152.3","s":2174},{"p":"38185.1","s":0},{"p":"38157.1","s":0},{"p":"38156.3","s":0},{"p":"38146.6","s":81352},{"p":"38168","s":0},{"p":"38156.5","s":0},{"p":"38165.4","s":0},{"p":"38152.5","s":3405},{"p":"38152.8","s":0},{"p":"38153.7","s":0},{"p":"38156.4","s":0},{"p":"38154.9","s":0},{"p":"38155","s":0},{"p":"38154.5","s":0},{"p":"38159.4","s":0}],"b":[{"p":"38146.5","s":95802},{"p":"38145.5","s":24186},{"p":"38142","s":0},{"p":"38142.4","s":0},{"p":"38140.7","s":2296},{"p":"38145","s":0},{"p":"38140.8","s":0},{"p":"38129.5","s":0},{"p":"38140.6","s":0},{"p":"38132.8","s":0},{"p":"38141.2","s":0},{"p":"38141.7","s":2394},{"p":"38140.9","s":1315},{"p":"38141.3","s":26},{"p":"38142.7","s":0},{"p":"38142.3","s":0},{"p":"38141","s":0},{"p":"38141.6","s":13980},{"p":"38143.7","s":0},{"p":"38133.1","s":0},{"p":"38134.7","s":0},{"p":"38137.4","s":0},{"p":"38103.1","s":0},{"p":"38141.5","s":0},{"p":"38137","s":0},{"p":"38143.5","s":318},{"p":"38141.8","s":733}],"s":"BTC_USDT","t":1701245665403,"u":53095238875}}
{"time":1701245665,"time_ms":1701245665431,"channel":"futures.order_book_update","event":"update","result":{"U":53095238876,"a":[{"p":"38182.6","s":0},{"p":"38153.1","s":0},{"p":"38164.6","s":0},{"p":"38153.8","s":0},{"p":"38148.1","s":0},{"p":"38154.9","s":0},{"p":"38158.7","s":0},{"p":"38172.3","s":0},{"p":"38173.5","s":0},{"p":"38152.1","s":3340},{"p":"38152.5","s":0},{"p":"38152.4","s":7239},{"p":"38160","s":0},{"p":"38152.2","s":5856},{"p":"38150.8","s":4353},{"p":"38162","s":0},{"p":"38151.4","s":4276}],"b":[{"p":"38141.6","s":10379},{"p":"38146.5","s":94808},{"p":"38140.7","s":0},{"p":"38126.4","s":0},{"p":"38138.3","s":0},{"p":"38139.9","s":0},{"p":"38140.1","s":0},{"p":"38139.1","s":0},{"p":"38136.6","s":0},{"p":"38132.2","s":0},{"p":"38081.6","s":0},{"p":"38145.2","s":3857},{"p":"38140.6","s":12165},{"p":"38141.7","s":94},{"p":"38138.4","s":0},{"p":"38125.6","s":0},{"p":"38138.6","s":0},{"p":"38130.5","s":0},{"p":"38133","s":0},{"p":"38141.8","s":0},{"p":"38134.1","s":0},{"p":"38140.3","s":1315},{"p":"38135.9","s":0},{"p":"38103.1","s":0},{"p":"38059.6","s":0},{"p":"38139","s":0}],"s":"BTC_USDT","t":1701245665420,"u":53095238940}}
{"time":1701245665,"time_ms":1701245665452,"channel":"futures.order_book_update","event":"update","result":{"U":53095238941,"a":[{"p":"38166.5","s":0},{"p":"38151.4","s":3624},{"p":"38151.9","s":2174},{"p":"38156","s":0},{"p":"38162.5","s":0},{"p":"38169.3","s":0},{"p":"38154.2","s":0},{"p":"38146.6","s":82184},{"p":"38148.9","s":524},{"p":"38152.3","s":0},{"p":"38152.4","s":0}],"b":[{"p":"38145.5","s":9186},{"p":"38142.6","s":15026},{"p":"38137.3","s":0},{"p":"38141.6","s":6778},{"p":"38146.5","s":94084},{"p":"38137.4","s":0},{"p":"38139.9","s":0},{"p":"38141","s":7306},{"p":"38139.1","s":0},{"p":"38133.9","s":0},{"p":"38127.7","s":0},{"p":"38131.7","s":0},{"p":"38140","s":1415},{"p":"38144.4","s":0},{"p":"38133.5","s":0},{"p":"38098.6","s":0},{"p":"38142.1","s":0},{"p":"38137.1","s":0}],"s":"BTC_USDT","t":1701245665440,"u":53095238995}}
{"time":1701245665,"time_ms":1701245665474,"channel":"futures.order_book_update","event":"update","result":{"U":53095238996,"a":[{"p":"38181.6","s":0},{"p":"38151.3","s":2174},{"p":"38151.9","s":0},{"p":"38148.9","s":0},{"p":"38155.4","s":0},{"p":"38167.1","s":0},{"p":"38156.8","s":0},{"p":"38152.5","s":0},{"p":"38146.6","s":79547},{"p":"38152.4","s":7239}],"b":[{"p":"38146.5","s":109084},{"p":"38143.5","s":0},{"p":"38130.2","s":0},{"p":"38144.5","s":0},{"p":"38140","s":1415},{"p":"38137.5","s":0},{"p":"38136.8","s":0},{"p":"38139.9","s":393},{"p":"38140.6","s":8559},{"p":"38139.7","s":0},{"p":"38135.8","s":0},{"p":"38143","s":9023},{"p":"38138.9","s":0},{"p":"38132","s":0}],"s":"BTC_USDT","t":1701245665464,"u":53095239025}}
{"time":1701245665,"time_ms":1701245665496,"channel":"futures.order_book_update","event":"update","result":{"U":53095239026,"a":[{"p":"38151.1","s":524},{"p":"38149.8","s":3340},{"p":"38146.6","s":78939},{"p":"38152.4","s":0},{"p":"38152.1","s":0},{"p":"38160.2","s":0}],"b":[{"p":"38145.2","s":6538},{"p":"38139.8","s":131},{"p":"38141","s":0},{"p":"38132.8","s":0},{"p":"38138.4","s":0},{"p":"38146.5","s":109084}],"s":"BTC_USDT","t":1701245665480,"u":53095239045}}
{"time":1701245665,"time_ms":1701245665512,"channel":"futures.order_book_update","event":"update","result":{"U":53095239046,"a":[{"p":"38177.5","s":0},{"p":"38168.4","s":0},{"p":"38152.4","s":7239},{"p":"38151.3","s":5514},{"p":"38149.8","s":0}],"b":[{"p":"38140.9","s":0},{"p":"38138.2","s":0},{"p":"38136.7","s":0},{"p":"38146.5","s":109614},{"p":"38141","s":5144},{"p":"38140.6","s":4953},{"p":"38137.5","s":0},{"p":"38139.8","s":131},{"p":"38139.5","s":0}],"s":"BTC_USDT","t":1701245665501,"u":53095239061}}
{"time":1701245665,"time_ms":1701245665534,"channel":"futures.order_book_update","event":"update","result":{"U":53095239062,"a":[{"p":"38165","s":0},{"p":"38150.8","s":7430},{"p":"38151.9","s":2174},{"p":"38152.4","s":0},{"p":"38154.9","s":0},{"p":"38164","s":0},{"p":"38156.5","s":0},{"p":"38151.3","s":3340},{"p":"38155.6","s":0},{"p":"38158.5","s":0},{"p":"38152.5","s":0},{"p":"38154.5","s":0}],"b":[{"p":"38141","s":2972},{"p":"38146.5","s":95114},{"p":"38145.2","s":3857},{"p":"38139.7","s":0},{"p":"38130","s":0},{"p":"38133.4","s":0}],"s":"BTC_USDT","t":1701245665524,"u":53095239094}}
{"time":1701245665,"time_ms":1701245665553,"channel":"futures.order_book_update","event":"update","result":{"U":53095239095,"a":[{"p":"38165","s":0}],"b":[{"p":"38146.5","s":94614},{"p":"38137.5","s":0}],"s":"BTC_USDT","t":1701245665546,"u":53095239106}}
{"time":1701245665,"time_ms":1701245665572,"channel":"futures.order_book_update","event":"update","result":{"U":53095239107,"a":[{"p":"38162.4","s":0}],"b":[{"p":"38040","s":0}],"s":"BTC_USDT","t":1701245665560,"u":53095239112}}
{"time":1701245665,"time_ms":1701245665594,"channel":"futures.order_book_update","event":"update","result":{"U":53095239113,"a":[{"p":"38152.4","s":7239},{"p":"38149.5","s":0},{"p":"38154.6","s":0}],"b":[{"p":"38146.5","s":92614}],"s":"BTC_USDT","t":1701245665576,"u":53095239121}}
{"time":1701245665,"time_ms":1701245665612,"channel":"futures.order_book_update","event":"update","result":{"U":53095239122,"a":[{"p":"38149.7","s":5514},{"p":"38149.3","s":27117},{"p":"38152.5","s":3405},{"p":"38151.3","s":0},{"p":"38151.9","s":0},{"p":"38150.8","s":0},{"p":"38152.4","s":7239}],"b":[{"p":"38146.5","s":92014},{"p":"38139.1","s":0}],"s":"BTC_USDT","t":1701245665598,"u":53095239138}}
{"time":1701245665,"time_ms":1701245665634,"channel":"futures.order_book_update","event":"update","result":{"U":53095239139,"a":[{"p":"38151.9","s":1315},{"p":"38152.5","s":0}],"b":[{"p":"38140","s":1315},{"p":"38145.5","s":206}],"s":"BTC_USDT","t":1701245665613,"u":53095239142}}
{"time":1701245665,"time_ms":1701245665652,"channel":"futures.order_book_update","event":"update","result":{"U":53095239143,"a":[{"p":"38151.3","s":2174},{"p":"38152.4","s":0},{"p":"38152.7","s":0}],"b":[{"p":"38146.5","s":86363}],"s":"BTC_USDT","t":1701245665642,"u":53095239154}}
{"time":1701245665,"time_ms":1701245665672,"channel":"futures.order_book_update","event":"update","result":{"U":53095239155,"a":[{"p":"38163.1","s":0},{"p":"38156.2","s":0}],"b":[{"p":"38138.4","s":0},{"p":"38052.2","s":0},{"p":"38146.5","s":94014},{"p":"38139.7","s":1315},{"p":"38141","s":11884},{"p":"38142.9","s":0}],"s":"BTC_USDT","t":1701245665660,"u":53095239167}}
{"time":1701245665,"time_ms":1701245665694,"channel":"futures.order_book_update","event":"update","result":{"U":53095239168,"a":[],"b":[{"p":"38138.3","s":0},{"p":"38137.1","s":0},{"p":"38138.5","s":0}],"s":"BTC_USDT","t":1701245665677,"u":53095239173}}
{"time":1701245665,"time_ms":1701245665712,"channel":"futures.order_book_update","event":"update","result":{"U":53095239174,"a":[{"p":"38151.2","s":799},{"p":"38146.6","s":86804},{"p":"38166.5","s":0},{"p":"38155","s":0},{"p":"38159","s":0}],"b":[{"p":"38139.7","s":0},{"p":"38137","s":0},{"p":"38136.7","s":0},{"p":"38136.8","s":0},{"p":"38139.4","s":0},{"p":"38139","s":2115},{"p":"38140.6","s":3638},{"p":"38140.5","s":8912},{"p":"38143.9","s":0},{"p":"38137.4","s":0},{"p":"38131.3","s":0},{"p":"38138.8","s":0},{"p":"38131.9","s":0},{"p":"38130.6","s":0},{"p":"38139.6","s":550},{"p":"38139.5","s":4432},{"p":"38138.9","s":1},{"p":"38141","s":2972},{"p":"38140.3","s":0},{"p":"38140","s":0},{"p":"38125.5","s":0},{"p":"38146.5","s":49262},{"p":"38141.9","s":0},{"p":"38135.1","s":0},{"p":"38130","s":0}],"s":"BTC_USDT","t":1701245665702,"u":53095239218}}
{"time":1701245665,"time_ms":1701245665735,"channel":"futures.order_book_update","event":"update","result":{"U":53095239219,"a":[{"p":"38161.2","s":0},{"p":"38145.7","s":36202},{"p":"38147.2","s":2174},{"p":"38150.9","s":7549},{"p":"38149.2","s":2174},{"p":"38150.4","s":654},{"p":"38152.2","s":0},{"p":"38151.4","s":0},{"p":"38153.8","s":0},{"p":"38160.5","s":0},{"p":"38154.4","s":0},{"p":"38154.7","s":0},{"p":"38149.9","s":2416},{"p":"38146.6","s":108306},{"p":"38151.9","s":0},{"p":"38153.1","s":0},{"p":"38147","s":600},{"p":"38146.4","s":10},{"p":"38154.1","s":0},{"p":"38165","s":0},{"p":"38171.6","s":0},{"p":"38161.1","s":0},{"p":"38161.5","s":0},{"p":"38151.3","s":0},{"p":"38151.2","s":0},{"p":"38152","s":0},{"p":"38146.5","s":51079},{"p":"38171.3","s":0},{"p":"38154.5","s":0},{"p":"38149.7","s":0},{"p":"38167.6","s":0},{"p":"38159.5","s":0},{"p":"38160.4","s":0},{"p":"38154","s":0},{"p":"38155.5","s":0}],"b":[{"p":"38132.9","s":0},{"p":"38094.7","s":0},{"p":"38140.5","s":0},{"p":"38146.5","s":0},{"p":"38141.6","s":0},{"p":"38134.6","s":0},{"p":"38135.9","s":0},{"p":"38129.2","s":0},{"p":"38125.8","s":0},{"p":"38141","s":2188},{"p":"38135.4","s":0},{"p":"38139","s":200},{"p":"38119.9","s":0},{"p":"38140.6","s":0},{"p":"38137.8","s":3841},{"p":"38138","s":216},{"p":"38136.5","s":0},{"p":"38131","s":0},{"p":"38138.8","s":143},{"p":"38135.1","s":0},{"p":"38134","s":0},{"p":"38138.1","s":13896},{"p":"38125.9","s":0},{"p":"38129","s":0},{"p":"38137.4","s":0},{"p":"38133","s":0},{"p":"38142.6","s":26},{"p":"38143.4","s":0},{"p":"38096.2","s":0},{"p":"38136.8","s":0},{"p":"38137.9","s":28297}],"s":"BTC_USDT","t":1701245665725,"u":53095239390}}
{"time":1701245665,"time_ms":1701245665754,"channel":"futures.order_book_update","event":"update","result":{"U":53095239391,"a":[{"p":"38191.2","s":0},{"p":"38145.7","s":152855},{"p":"38151.1","s":524},{"p":"38159.5","s":0},{"p":"38189.9","s":0},{"p":"38148.7","s":3932},{"p":"38151.2","s":0},{"p":"38153.7","s":0},{"p":"38170.7","s":0},{"p":"38146.6","s":58696},{"p":"38148.1","s":7864},{"p":"38150.5","s":0},{"p":"38189.5","s":0},{"p":"38149.6","s":40},{"p":"38171.4","s":0},{"p":"38153.8","s":0},{"p":"38146.5","s":51079},{"p":"38160","s":0},{"p":"38159","s":0},{"p":"38169.1","s":0},{"p":"38150.9","s":11150},{"p":"38147.2","s":0},{"p":"38161.2","s":0},{"p":"38167.5","s":0},{"p":"38165","s":0},{"p":"38149.2","s":0},{"p":"38162.4","s":0},{"p":"38151","s":3},{"p":"38180.1","s":0}],"b":[{"p":"38137.8","s":15208},{"p":"38142.6","s":0},{"p":"38134.3","s":0},{"p":"38129.2","s":0},{"p":"38125.3","s":0},{"p":"38145.6","s":2946},{"p":"38136.4","s":2621},{"p":"38139.5","s":0},{"p":"38134.1","s":0},{"p":"38131.1","s":0},{"p":"38134.6","s":0},{"p":"38139","s":0},{"p":"38137.3","s":0},{"p":"38133.4","s":0},{"p":"38141","s":0},{"p":"38145.3","s":0},{"p":"38128.2","s":0},{"p":"38135.8","s":2681},{"p":"38122.2","s":0},{"p":"38109.3","s":0},{"p":"38132.3","s":0},{"p":"38136.6","s":183},{"p":"38141.7","s":120},{"p":"38136.3","s":15},{"p":"38112.5","s":0},{"p":"38135","s":0},{"p":"38134.2","s":0},{"p":"38140","s":653},{"p":"38136.7","s":6820},{"p":"38133.6","s":0},{"p":"38131.9","s":0},{"p":"38098.3","s":0},{"p":"38130.2","s":0},{"p":"38136.8","s":0},{"p":"38134.4","s":0},{"p":"38138","s":816},{"p":"38143","s":0},{"p":"38116.6","s":0},{"p":"38106.2","s":0},{"p":"38118.4","s":0}],"s":"BTC_USDT","t":1701245665743,"u":53095239568}}
