{"time":1701245729,"time_ms":1701245729752,"channel":"futures.order_book_update","event":"update","result":{"U":53095258585,"a":[],"b":[{"p":"38128","s":0},{"p":"38125.4","s":9594},{"p":"38126.9","s":15000},{"p":"38125.5","s":182},{"p":"38125.6","s":3633},{"p":"38129.6","s":0},{"p":"38128.8","s":0}],"s":"BTC_USDT","t":1701245729742,"u":53095258590}}
{"time":1701245729,"time_ms":1701245729771,"channel":"futures.order_book_update","event":"update","result":{"U":53095258591,"a":[],"b":[{"p":"38125.3","s":0},{"p":"38120.3","s":0},{"p":"38119.4","s":0}],"s":"BTC_USDT","t":1701245729759,"u":53095258595}}
{"time":1701245729,"time_ms":1701245729852,"channel":"futures.order_book_update","event":"update","result":{"U":53095258596,"a":[],"b":[{"p":"38127","s":9109},{"p":"38122","s":0}],"s":"BTC_USDT","t":1701245729845,"u":53095258600}}
{"time":1701245729,"time_ms":1701245729871,"channel":"futures.order_book_update","event":"update","result":{"U":53095258601,"a":[],"b":[{"p":"38126","s":100},{"p":"38125.4","s":0},{"p":"38121","s":0}],"s":"BTC_USDT","t":1701245729852,"u":53095258604}}
{"time":1701245729,"time_ms":1701245729914,"channel":"futures.order_book_update","event":"update","result":{"U":53095258605,"a":[{"p":"38145.6","s":0}],"b":[{"p":"38119.6","s":0}],"s":"BTC_USDT","t":1701245729900,"u":53095258609}}
{"time":1701245729,"time_ms":1701245729933,"channel":"futures.order_book_update","event":"update","result":{"U":53095258610,"a":[],"b":[{"p":"38125.5","s":0},{"p":"38119.4","s":0},{"p":"38127.3","s":655},{"p":"38126.6","s":131}],"s":"BTC_USDT","t":1701245729922,"u":53095258616}}
{"time":1701245729,"time_ms":1701245729955,"channel":"futures.order_book_update","event":"update","result":{"U":53095258617,"a":[],"b":[{"p":"38112","s":0},{"p":"38119.5","s":0},{"p":"38124","s":0},{"p":"38120","s":0}],"s":"BTC_USDT","t":1701245729933,"u":53095258621}}
{"time":1701245729,"time_ms":1701245729992,"channel":"futures.order_book_update","event":"update","result":{"U":53095258622,"a":[],"b":[{"p":"38120.7","s":0}],"s":"BTC_USDT","t":1701245729982,"u":53095258622}}
{"time":1701245730,"time_ms":1701245730013,"channel":"futures.order_book_update","event":"update","result":{"U":53095258623,"a":[{"p":"38147.4","s":0}],"b":[{"p":"38134.1","s":7014},{"p":"38114.5","s":0}],"s":"BTC_USDT","t":1701245729992,"u":53095258627}}
{"time":1701245730,"time_ms":1701245730033,"channel":"futures.order_book_update","event":"update","result":{"U":53095258628,"a":[{"p":"38136.9","s":2323},{"p":"38138.4","s":2175},{"p":"38134.2","s":174977},{"p":"38137.6","s":3341},{"p":"38139.2","s":0},{"p":"38137.4","s":0},{"p":"38139.1","s":0},{"p":"38144.9","s":0},{"p":"38138.1","s":40},{"p":"38137.1","s":583},{"p":"38140.8","s":0}],"b":[{"p":"38118.7","s":0},{"p":"38114.1","s":0},{"p":"38120.5","s":0},{"p":"38066","s":0},{"p":"38120.6","s":0}],"s":"BTC_USDT","t":1701245730018,"u":53095258648}}
{"time":1701245730,"time_ms":1701245730052,"channel":"futures.order_book_update","event":"update","result":{"U":53095258649,"a":[{"p":"38137.8","s":3341},{"p":"38137.6","s":0},{"p":"38139.1","s":0},{"p":"38138","s":0},{"p":"38138.4","s":2175},{"p":"38140.9","s":0}],"b":[{"p":"38120.9","s":0},{"p":"38115.8","s":0},{"p":"38106.1","s":0},{"p":"38122","s":0}],"s":"BTC_USDT","t":1701245730041,"u":53095258668}}
{"time":1701245730,"time_ms":1701245730073,"channel":"futures.order_book_update","event":"update","result":{"U":53095258669,"a":[{"p":"38141.2","s":0}],"b":[{"p":"38120.8","s":0},{"p":"38116","s":0},{"p":"38122.3","s":0}],"s":"BTC_USDT","t":1701245730057,"u":53095258675}}
{"time":1701245730,"time_ms":1701245730093,"channel":"futures.order_book_update","event":"update","result":{"U":53095258676,"a":[],"b":[{"p":"38127","s":9209},{"p":"38125.5","s":182},{"p":"38126","s":0},{"p":"38114.6","s":0}],"s":"BTC_USDT","t":1701245730086,"u":53095258682}}
{"time":1701245730,"time_ms":1701245730152,"channel":"futures.order_book_update","event":"update","result":{"U":53095258683,"a":[{"p":"38137","s":0},{"p":"38137.1","s":2758},{"p":"38139.1","s":10858}],"b":[],"s":"BTC_USDT","t":1701245730136,"u":53095258684}}
{"time":1701245730,"time_ms":1701245730173,"channel":"futures.order_book_update","event":"update","result":{"U":53095258685,"a":[{"p":"38137.1","s":583},{"p":"38137.4","s":2175},{"p":"38139.1","s":0},{"p":"38140.9","s":0}],"b":[],"s":"BTC_USDT","t":1701245730148,"u":53095258688}}
{"time":1701245730,"time_ms":1701245730193,"channel":"futures.order_book_update","event":"update","result":{"U":53095258689,"a":[{"p":"38135.2","s":394},{"p":"38138.5","s":0},{"p":"38140.2","s":0}],"b":[],"s":"BTC_USDT","t":1701245730181,"u":53095258693}}
{"time":1701245730,"time_ms":1701245730214,"channel":"futures.order_book_update","event":"update","result":{"U":53095258694,"a":[{"p":"38134.2","s":175764}],"b":[],"s":"BTC_USDT","t":1701245730193,"u":53095258694}}
{"time":1701245730,"time_ms":1701245730232,"channel":"futures.order_book_update","event":"update","result":{"U":53095258695,"a":[{"p":"38138.2","s":3341},{"p":"38137.8","s":0},{"p":"38138.5","s":0}],"b":[],"s":"BTC_USDT","t":1701245730207,"u":53095258696}}
{"time":1701245730,"time_ms":1701245730254,"channel":"futures.order_book_update","event":"update","result":{"U":53095258697,"a":[{"p":"38138.5","s":0},{"p":"38137.3","s":2324},{"p":"38136.9","s":0},{"p":"38144.4","s":0}],"b":[{"p":"38098","s":0}],"s":"BTC_USDT","t":1701245730242,"u":53095258702}}
{"time":1701245730,"time_ms":1701245730276,"channel":"futures.order_book_update","event":"update","result":{"U":53095258703,"a":[{"p":"38189.1","s":0},{"p":"38134.2","s":175155}],"b":[],"s":"BTC_USDT","t":1701245730264,"u":53095258706}}
{"time":1701245730,"time_ms":1701245730353,"channel":"futures.order_book_update","event":"update","result":{"U":53095258707,"a":[],"b":[{"p":"38134.1","s":13281},{"p":"38115.3","s":0}],"s":"BTC_USDT","t":1701245730337,"u":53095258711}}
{"time":1701245730,"time_ms":1701245730412,"channel":"futures.order_book_update","event":"update","result":{"U":53095258712,"a":[],"b":[{"p":"38134.1","s":11781}],"s":"BTC_USDT","t":1701245730402,"u":53095258713}}
{"time":1701245730,"time_ms":1701245730432,"channel":"futures.order_book_update","event":"update","result":{"U":53095258714,"a":[],"b":[{"p":"38134.1","s":5514}],"s":"BTC_USDT","t":1701245730411,"u":53095258714}}
{"time":1701245730,"time_ms":1701245730511,"channel":"futures.order_book_update","event":"update","result":{"U":53095258715,"a":[],"b":[{"p":"38134.1","s":5719}],"s":"BTC_USDT","t":1701245730487,"u":53095258720}}
{"time":1701245730,"time_ms":1701245730614,"channel":"futures.order_book_update","event":"update","result":{"U":53095258721,"a":[{"p":"38139.8","s":0}],"b":[{"p":"38100.2","s":0}],"s":"BTC_USDT","t":1701245730596,"u":53095258726}}
{"time":1701245730,"time_ms":1701245730639,"channel":"futures.order_book_update","event":"update","result":{"U":53095258727,"a":[{"p":"38149.9","s":0}],"b":[],"s":"BTC_USDT","t":1701245730615,"u":53095258728}}
{"time":1701245730,"time_ms":1701245730658,"channel":"futures.order_book_update","event":"update","result":{"U":53095258729,"a":[{"p":"38155","s":0},{"p":"38147.4","s":0},{"p":"38143.6","s":0},{"p":"38151.2","s":0},{"p":"38139.1","s":0}],"b":[{"p":"38134.1","s":7219},{"p":"38110.3","s":0},{"p":"38106.4","s":0},{"p":"38102.5","s":0}],"s":"BTC_USDT","t":1701245730632,"u":53095258738}}
{"time":1701245730,"time_ms":1701245730732,"channel":"futures.order_book_update","event":"update","result":{"U":53095258739,"a":[],"b":[{"p":"38124","s":0},{"p":"38120","s":0},{"p":"38112","s":0}],"s":"BTC_USDT","t":1701245730720,"u":53095258744}}
{"time":1701245730,"time_ms":1701245730751,"channel":"futures.order_book_update","event":"update","result":{"U":53095258745,"a":[],"b":[{"p":"38128","s":655},{"p":"38127.3","s":0},{"p":"38125.4","s":0}],"s":"BTC_USDT","t":1701245730726,"u":53095258746}}
{"time":1701245730,"time_ms":1701245730812,"channel":"futures.order_book_update","event":"update","result":{"U":53095258747,"a":[],"b":[{"p":"38119.4","s":0}],"s":"BTC_USDT","t":1701245730795,"u":53095258748}}
{"time":1701245730,"time_ms":1701245730912,"channel":"futures.order_book_update","event":"update","result":{"U":53095258749,"a":[],"b":[{"p":"38120","s":0}],"s":"BTC_USDT","t":1701245730899,"u":53095258754}}
{"time":1701245730,"time_ms":1701245730993,"channel":"futures.order_book_update","event":"update","result":{"U":53095258755,"a":[{"p":"38152.5","s":0},{"p":"38141.1","s":0}],"b":[{"p":"38130","s":2},{"p":"38130.8","s":2},{"p":"38129.2","s":2},{"p":"38128.1","s":2},{"p":"38125.5","s":0},{"p":"38126.6","s":0},{"p":"38125.6","s":0},{"p":"38126.2","s":0}],"s":"BTC_USDT","t":1701245730982,"u":53095258762}}
{"time":1701245731,"time_ms":1701245731031,"channel":"futures.order_book_update","event":"update","result":{"U":53095258763,"a":[{"p":"38139.5","s":0},{"p":"38138.5","s":550},{"p":"38137.1","s":2878},{"p":"38137.3","s":0},{"p":"38139","s":0},{"p":"38138.4","s":2175},{"p":"38143.5","s":0},{"p":"38141.2","s":0},{"p":"38151","s":0}],"b":[{"p":"38114.2","s":0},{"p":"38119.5","s":0},{"p":"38116.4","s":0},{"p":"38112","s":0},{"p":"38115.1","s":0},{"p":"38122.1","s":0},{"p":"38120.6","s":0},{"p":"38124","s":0},{"p":"38120","s":0},{"p":"38115.8","s":0},{"p":"38120.2","s":0},{"p":"38121.2","s":0},{"p":"38121.5","s":0},{"p":"38119.4","s":0},{"p":"38122.7","s":0},{"p":"38120.8","s":0}],"s":"BTC_USDT","t":1701245731019,"u":53095258812}}
{"time":1701245731,"time_ms":1701245731054,"channel":"futures.order_book_update","event":"update","result":{"U":53095258813,"a":[{"p":"38138.4","s":2175},{"p":"38139.1","s":0}],"b":[{"p":"38122.5","s":0},{"p":"38120.2","s":0},{"p":"38114.8","s":0}],"s":"BTC_USDT","t":1701245731029,"u":53095258818}}
{"time":1701245731,"time_ms":1701245731071,"channel":"futures.order_book_update","event":"update","result":{"U":53095258819,"a":[{"p":"38137.2","s":6107},{"p":"38139.1","s":11467},{"p":"38137.4","s":0}],"b":[],"s":"BTC_USDT","t":1701245731049,"u":53095258823}}
{"time":1701245731,"time_ms":1701245731111,"channel":"futures.order_book_update","event":"update","result":{"U":53095258824,"a":[],"b":[{"p":"38121","s":0}],"s":"BTC_USDT","t":1701245731088,"u":53095258825}}
{"time":1701245731,"time_ms":1701245731153,"channel":"futures.order_book_update","event":"update","result":{"U":53095258826,"a":[],"b":[{"p":"38120.9","s":0}],"s":"BTC_USDT","t":1701245731130,"u":53095258827}}
{"time":1701245731,"time_ms":1701245731172,"channel":"futures.order_book_update","event":"update","result":{"U":53095258828,"a":[{"p":"38141.4","s":0}],"b":[],"s":"BTC_USDT","t":1701245731159,"u":53095258829}}
{"time":1701245731,"time_ms":1701245731191,"channel":"futures.order_book_update","event":"update","result":{"U":53095258830,"a":[],"b":[{"p":"38134","s":17000},{"p":"38126.7","s":0}],"s":"BTC_USDT","t":1701245731176,"u":53095258832}}
{"time":1701245731,"time_ms":1701245731213,"channel":"futures.order_book_update","event":"update","result":{"U":53095258833,"a":[],"b":[{"p":"38121.3","s":0}],"s":"BTC_USDT","t":1701245731185,"u":53095258834}}
{"time":1701245731,"time_ms":1701245731232,"channel":"futures.order_book_update","event":"update","result":{"U":53095258835,"a":[{"p":"38137.6","s":2175},{"p":"38137.2","s":3932},{"p":"38139","s":2175},{"p":"38138.4","s":0},{"p":"38139.1","s":0},{"p":"38139.2","s":0}],"b":[{"p":"38126.7","s":1},{"p":"38126.6","s":131},{"p":"38125.6","s":3633},{"p":"38130.8","s":0},{"p":"38120.9","s":0},{"p":"38126.2","s":2000},{"p":"38130","s":0},{"p":"38129.2","s":0},{"p":"38128.1","s":0},{"p":"38119.5","s":0}],"s":"BTC_USDT","t":1701245731221,"u":53095258846}}
{"time":1701245731,"time_ms":1701245731253,"channel":"futures.order_book_update","event":"update","result":{"U":53095258847,"a":[],"b":[{"p":"38130.2","s":28},{"p":"38129.5","s":2},{"p":"38131","s":2},{"p":"38128.3","s":133},{"p":"38126.2","s":0},{"p":"38125.6","s":0}],"s":"BTC_USDT","t":1701245731242,"u":53095258850}}
{"time":1701245731,"time_ms":1701245731270,"channel":"futures.order_book_update","event":"update","result":{"U":53095258851,"a":[{"p":"38139.1","s":11467},{"p":"38138.2","s":0},{"p":"38141.4","s":0},{"p":"38139","s":5516}],"b":[{"p":"38134.1","s":14870},{"p":"38116.2","s":0}],"s":"BTC_USDT","t":1701245731259,"u":53095258857}}
{"time":1701245731,"time_ms":1701245731293,"channel":"futures.order_book_update","event":"update","result":{"U":53095258858,"a":[{"p":"38138.4","s":3341},{"p":"38137.1","s":583},{"p":"38139.1","s":0},{"p":"38139","s":2175},{"p":"38138.1","s":2452}],"b":[{"p":"38116.7","s":0},{"p":"38120.7","s":0}],"s":"BTC_USDT","t":1701245731279,"u":53095258866}}
{"time":1701245731,"time_ms":1701245731311,"channel":"futures.order_book_update","event":"update","result":{"U":53095258867,"a":[],"b":[{"p":"38121.7","s":0},{"p":"38121.2","s":0}],"s":"BTC_USDT","t":1701245731287,"u":53095258870}}
{"time":1701245731,"time_ms":1701245731331,"channel":"futures.order_book_update","event":"update","result":{"U":53095258871,"a":[],"b":[{"p":"38126.2","s":0},{"p":"38120.2","s":0},{"p":"38127.4","s":3611},{"p":"38134","s":0}],"s":"BTC_USDT","t":1701245731306,"u":53095258874}}
{"time":1701245731,"time_ms":1701245731353,"channel":"futures.order_book_update","event":"update","result":{"U":53095258875,"a":[{"p":"38141.6","s":0},{"p":"38139","s":2175},{"p":"38139.1","s":0},{"p":"38138","s":2175},{"p":"38138.1","s":40},{"p":"38138.9","s":5861},{"p":"38138.4","s":0},{"p":"38137.6","s":0}],"b":[{"p":"38110.8","s":0},{"p":"38116.1","s":0}],"s":"BTC_USDT","t":1701245731344,"u":53095258886}}
{"time":1701245731,"time_ms":1701245731377,"channel":"futures.order_book_update","event":"update","result":{"U":53095258887,"a":[],"b":[{"p":"38070.6","s":0}],"s":"BTC_USDT","t":1701245731354,"u":53095258888}}
{"time":1701245731,"time_ms":1701245731393,"channel":"futures.order_book_update","event":"update","result":{"U":53095258889,"a":[{"p":"38144.9","s":0},{"p":"38139.1","s":11467},{"p":"38139","s":0}],"b":[{"p":"38119.4","s":0},{"p":"38074.8","s":0}],"s":"BTC_USDT","t":1701245731380,"u":53095258895}}
{"time":1701245731,"time_ms":1701245731413,"channel":"futures.order_book_update","event":"update","result":{"U":53095258896,"a":[],"b":[{"p":"38112.1","s":0}],"s":"BTC_USDT","t":1701245731397,"u":53095258896}}
{"time":1701245731,"time_ms":1701245731451,"channel":"futures.order_book_update","event":"update","result":{"U":53095258897,"a":[{"p":"38138.8","s":2175},{"p":"38138.9","s":2520},{"p":"38138","s":0},{"p":"38139.7","s":0},{"p":"38139.2","s":0}],"b":[{"p":"38120.9","s":0},{"p":"38122.3","s":0},{"p":"38121.2","s":0},{"p":"38116.4","s":0},{"p":"38122.5","s":0}],"s":"BTC_USDT","t":1701245731441,"u":53095258912}}
{"time":1701245731,"time_ms":1701245731492,"channel":"futures.order_book_update","event":"update","result":{"U":53095258913,"a":[],"b":[{"p":"38130.2","s":26},{"p":"38128.4","s":732},{"p":"38128.3","s":131},{"p":"38126.2","s":2000},{"p":"38131","s":0},{"p":"38105.9","s":0},{"p":"38134.1","s":29870}],"s":"BTC_USDT","t":1701245731484,"u":53095258920}}
{"time":1701245731,"time_ms":1701245731510,"channel":"futures.order_book_update","event":"update","result":{"U":53095258921,"a":[],"b":[{"p":"38131.1","s":2},{"p":"38130.4","s":133},{"p":"38129.5","s":0},{"p":"38126.2","s":2000},{"p":"38123.3","s":0}],"s":"BTC_USDT","t":1701245731495,"u":53095258926}}
{"time":1701245731,"time_ms":1701245731531,"channel":"futures.order_book_update","event":"update","result":{"U":53095258927,"a":[{"p":"38145.5","s":0},{"p":"38141.5","s":0},{"p":"38153","s":0},{"p":"38134.2","s":174631},{"p":"38136.3","s":524},{"p":"38139.1","s":0}],"b":[{"p":"38129.6","s":2},{"p":"38134.1","s":27870},{"p":"38126.2","s":0},{"p":"38125.5","s":0},{"p":"38114","s":0}],"s":"BTC_USDT","t":1701245731520,"u":53095258944}}
{"time":1701245731,"time_ms":1701245731553,"channel":"futures.order_book_update","event":"update","result":{"U":53095258945,"a":[{"p":"38138.9","s":2919},{"p":"38134.2","s":175120},{"p":"38151","s":0},{"p":"38136.7","s":21290}],"b":[{"p":"38121.5","s":0},{"p":"38127","s":9109},{"p":"38134.1","s":42870}],"s":"BTC_USDT","t":1701245731543,"u":53095258953}}
{"time":1701245731,"time_ms":1701245731572,"channel":"futures.order_book_update","event":"update","result":{"U":53095258954,"a":[{"p":"38139.2","s":10932},{"p":"38145.6","s":0},{"p":"38139.8","s":0},{"p":"38148","s":0},{"p":"38139.1","s":11467},{"p":"38135.9","s":525},{"p":"38151","s":0},{"p":"38145.5","s":0},{"p":"38138.9","s":399},{"p":"38138.8","s":0},{"p":"38135.8","s":0},{"p":"38139.5","s":0},{"p":"38153","s":0},{"p":"38142.6","s":0},{"p":"38143.5","s":0},{"p":"38134.2","s":162889},{"p":"38141.5","s":0},{"p":"38169.6","s":0},{"p":"38146.8","s":0},{"p":"38140.3","s":0},{"p":"38141.8","s":0},{"p":"38141.4","s":0}],"b":[{"p":"38123.7","s":0},{"p":"38114.8","s":0},{"p":"38112.5","s":0},{"p":"38117.7","s":0},{"p":"38099.1","s":0},{"p":"38111.9","s":0},{"p":"38120.5","s":0},{"p":"38128","s":0},{"p":"38116.9","s":0},{"p":"38125.3","s":0},{"p":"38122.1","s":0},{"p":"38120","s":0},{"p":"38129.6","s":657},{"p":"38129.3","s":10864},{"p":"38126.2","s":2000},{"p":"38124","s":0},{"p":"38123.5","s":0},{"p":"38110.5","s":0}],"s":"BTC_USDT","t":1701245731562,"u":53095259024}}
{"time":1701245731,"time_ms":1701245731594,"channel":"futures.order_book_update","event":"update","result":{"U":53095259025,"a":[{"p":"38144.3","s":0},{"p":"38134.2","s":147889},{"p":"38139.1","s":10858}],"b":[{"p":"38126","s":0},{"p":"38126.1","s":0},{"p":"38114","s":0},{"p":"38121.5","s":0},{"p":"38127","s":9209},{"p":"38126.3","s":600},{"p":"38129.3","s":11217},{"p":"38126.2","s":0}],"s":"BTC_USDT","t":1701245731580,"u":53095259049}}
{"time":1701245731,"time_ms":1701245731612,"channel":"futures.order_book_update","event":"update","result":{"U":53095259050,"a":[{"p":"38152.5","s":0},{"p":"38139.7","s":0},{"p":"38134.2","s":129389},{"p":"38139.3","s":16024},{"p":"38139","s":524},{"p":"38140.6","s":0},{"p":"38154.1","s":0},{"p":"38148.1","s":0},{"p":"38142.7","s":0},{"p":"38134.6","s":0},{"p":"38136.3","s":0},{"p":"38144.4","s":0}],"b":[{"p":"38118.4","s":0},{"p":"38109.5","s":0},{"p":"38129.6","s":2},{"p":"38129.4","s":6245},{"p":"38134.1","s":43545},{"p":"38126.3","s":0},{"p":"38113.4","s":0},{"p":"38128","s":8915},{"p":"38119.4","s":0},{"p":"38125.5","s":0}],"s":"BTC_USDT","t":1701245731602,"u":53095259084}}
{"time":1701245731,"time_ms":1701245731633,"channel":"futures.order_book_update","event":"update","result":{"U":53095259085,"a":[{"p":"38135.8","s":2681},{"p":"38139.5","s":8357},{"p":"38134.2","s":140720},{"p":"38137.2","s":0},{"p":"38134.9","s":0},{"p":"38139.8","s":0},{"p":"38141.7","s":0},{"p":"38145.1","s":0},{"p":"38142.2","s":0},{"p":"38142.8","s":0},{"p":"38147.2","s":0},{"p":"38141.8","s":0},{"p":"38141.4","s":0}],"b":[{"p":"38134.1","s":46335},{"p":"38091.7","s":0},{"p":"38115","s":0}],"s":"BTC_USDT","t":1701245731625,"u":53095259115}}
{"time":1701245731,"time_ms":1701245731651,"channel":"futures.order_book_update","event":"update","result":{"U":53095259116,"a":[{"p":"38134.2","s":125720},{"p":"38142.5","s":0},{"p":"38149.1","s":0},{"p":"38142.2","s":0},{"p":"38137.5","s":525}],"b":[{"p":"38126.3","s":0},{"p":"38123.8","s":0},{"p":"38134.1","s":48591},{"p":"38124.4","s":0}],"s":"BTC_USDT","t":1701245731640,"u":53095259132}}
{"time":1701245731,"time_ms":1701245731670,"channel":"futures.order_book_update","event":"update","result":{"U":53095259133,"a":[{"p":"38139.8","s":1315},{"p":"38135.8","s":0}],"b":[{"p":"38126.2","s":2000},{"p":"38134.1","s":49091},{"p":"38128.4","s":730},{"p":"38126.3","s":734},{"p":"38131.1","s":0},{"p":"38129.6","s":0},{"p":"38125.7","s":0}],"s":"BTC_USDT","t":1701245731664,"u":53095259141}}
{"time":1701245731,"time_ms":1701245731694,"channel":"futures.order_book_update","event":"update","result":{"U":53095259142,"a":[],"b":[{"p":"38126.2","s":0},{"p":"38121.6","s":0},{"p":"38117.8","s":0},{"p":"38134.1","s":52326},{"p":"38129.7","s":2},{"p":"38130.4","s":131}],"s":"BTC_USDT","t":1701245731680,"u":53095259146}}
{"time":1701245731,"time_ms":1701245731715,"channel":"futures.order_book_update","event":"update","result":{"U":53095259147,"a":[{"p":"38136.7","s":18145},{"p":"38164.2","s":0},{"p":"38146","s":0},{"p":"38143.1","s":0},{"p":"38148.4","s":0},{"p":"38140.6","s":0},{"p":"38142","s":0},{"p":"38134.2","s":116738}],"b":[{"p":"38126.9","s":0},{"p":"38126.6","s":0},{"p":"38126.3","s":0},{"p":"38127","s":9109},{"p":"38131.6","s":2},{"p":"38127.1","s":2328},{"p":"38132.4","s":2},{"p":"38134.1","s":56861},{"p":"38125","s":0},{"p":"38127.6","s":2175},{"p":"38126.7","s":0},{"p":"38125.6","s":0}],"s":"BTC_USDT","t":1701245731705,"u":53095259176}}
{"time":1701245731,"time_ms":1701245731734,"channel":"futures.order_book_update","event":"update","result":{"U":53095259177,"a":[{"p":"38143.3","s":0},{"p":"38139.9","s":15000},{"p":"38136.5","s":0}],"b":[{"p":"38131.2","s":2},{"p":"38127","s":0}],"s":"BTC_USDT","t":1701245731725,"u":53095259184}}
{"time":1701245731,"time_ms":1701245731754,"channel":"futures.order_book_update","event":"update","result":{"U":53095259185,"a":[{"p":"38142.3","s":0},{"p":"38143","s":0},{"p":"38154","s":0},{"p":"38147","s":0}],"b":[{"p":"38134.1","s":63336}],"s":"BTC_USDT","t":1701245731736,"u":53095259193}}
{"time":1701245731,"time_ms":1701245731774,"channel":"futures.order_book_update","event":"update","result":{"U":53095259194,"a":[{"p":"38142.4","s":0}],"b":[{"p":"38126.6","s":131},{"p":"38126.4","s":2175},{"p":"38134.1","s":59301},{"p":"38118.5","s":0},{"p":"38077.7","s":0},{"p":"38127","s":9109},{"p":"38126.7","s":1},{"p":"38131.2","s":0},{"p":"38132.4","s":0},{"p":"38129.7","s":0},{"p":"38127.6","s":0},{"p":"38126.9","s":15000},{"p":"38131.6","s":0}],"s":"BTC_USDT","t":1701245731759,"u":53095259208}}
{"time":1701245731,"time_ms":1701245731794,"channel":"futures.order_book_update","event":"update","result":{"U":53095259209,"a":[],"b":[{"p":"38130.1","s":2},{"p":"38131.3","s":2},{"p":"38126.6","s":0},{"p":"38126.4","s":0},{"p":"38019.5","s":0},{"p":"38113.9","s":0}],"s":"BTC_USDT","t":1701245731783,"u":53095259214}}
{"time":1701245731,"time_ms":1701245731813,"channel":"futures.order_book_update","event":"update","result":{"U":53095259215,"a":[],"b":[{"p":"38127","s":0},{"p":"38126","s":0},{"p":"38132.1","s":2},{"p":"38134.1","s":68601},{"p":"38132.9","s":2},{"p":"38132","s":100},{"p":"38126.7","s":0},{"p":"38126.9","s":0}],"s":"BTC_USDT","t":1701245731798,"u":53095259220}}
{"time":1701245731,"time_ms":1701245731832,"channel":"futures.order_book_update","event":"update","result":{"U":53095259221,"a":[{"p":"38134.2","s":116214},{"p":"38154.7","s":0},{"p":"38147.5","s":0},{"p":"38143.5","s":0}],"b":[{"p":"38109.4","s":0}],"s":"BTC_USDT","t":1701245731820,"u":53095259231}}
{"time":1701245731,"time_ms":1701245731854,"channel":"futures.order_book_update","event":"update","result":{"U":53095259232,"a":[{"p":"38134.2","s":112912},{"p":"38140.1","s":1315},{"p":"38138.9","s":0},{"p":"38139.3","s":0},{"p":"38147","s":0},{"p":"38143","s":0},{"p":"38142.3","s":0},{"p":"38140","s":2026}],"b":[{"p":"38129.7","s":655},{"p":"38127.1","s":0}],"s":"BTC_USDT","t":1701245731844,"u":53095259248}}
{"time":1701245731,"time_ms":1701245731874,"channel":"futures.order_book_update","event":"update","result":{"U":53095259249,"a":[{"p":"38146.5","s":0},{"p":"38178","s":0},{"p":"38143.9","s":0},{"p":"38140.4","s":1315},{"p":"38142.5","s":0},{"p":"38173.7","s":0},{"p":"38147","s":0},{"p":"38155.5","s":0},{"p":"38144","s":0},{"p":"38134.2","s":112837},{"p":"38135.9","s":0}],"b":[{"p":"38120.9","s":0},{"p":"38126.4","s":0},{"p":"38122.5","s":0}],"s":"BTC_USDT","t":1701245731858,"u":53095259276}}
{"time":1701245731,"time_ms":1701245731893,"channel":"futures.order_book_update","event":"update","result":{"U":53095259277,"a":[],"b":[{"p":"38118.5","s":0}],"s":"BTC_USDT","t":1701245731881,"u":53095259286}}
{"time":1701245731,"time_ms":1701245731912,"channel":"futures.order_book_update","event":"update","result":{"U":53095259287,"a":[{"p":"38144.1","s":0},{"p":"38142.8","s":0},{"p":"38151.5","s":0},{"p":"38148.1","s":0}],"b":[{"p":"38127","s":9109},{"p":"38132.9","s":0},{"p":"38129.7","s":0},{"p":"38127.4","s":3611},{"p":"38124.5","s":0},{"p":"38127.1","s":2328},{"p":"38132.1","s":0},{"p":"38134.1","s":67092},{"p":"38134","s":564},{"p":"38126.7","s":1},{"p":"38128.4","s":131},{"p":"38130.1","s":0},{"p":"38131.3","s":0},{"p":"38123.3","s":0},{"p":"38126.9","s":15000}],"s":"BTC_USDT","t":1701245731904,"u":53095259316}}
{"time":1701245731,"time_ms":1701245731932,"channel":"futures.order_book_update","event":"update","result":{"U":53095259317,"a":[{"p":"38134.2","s":136335},{"p":"38143.7","s":0},{"p":"38144.1","s":0},{"p":"38145.1","s":0},{"p":"38141.7","s":0}],"b":[{"p":"38113.4","s":0},{"p":"38126.5","s":0},{"p":"38122.3","s":0},{"p":"38126.6","s":131},{"p":"38127.7","s":0},{"p":"38118.3","s":0}],"s":"BTC_USDT","t":1701245731926,"u":53095259331}}
{"time":1701245731,"time_ms":1701245731950,"channel":"futures.order_book_update","event":"update","result":{"U":53095259332,"a":[{"p":"38134.2","s":121335},{"p":"38165.9","s":0}],"b":[{"p":"38133.7","s":2},{"p":"38133","s":2},{"p":"38126.9","s":0},{"p":"38126.6","s":0},{"p":"38126.7","s":0},{"p":"38119.9","s":0},{"p":"38134.1","s":77156},{"p":"38131.8","s":2}],"s":"BTC_USDT","t":1701245731941,"u":53095259343}}
{"time":1701245731,"time_ms":1701245731971,"channel":"futures.order_book_update","event":"update","result":{"U":53095259344,"a":[{"p":"38134.2","s":106335}],"b":[],"s":"BTC_USDT","t":1701245731958,"u":53095259347}}
{"time":1701245731,"time_ms":1701245731994,"channel":"futures.order_book_update","event":"update","result":{"U":53095259348,"a":[{"p":"38137.8","s":330},{"p":"38136.5","s":10896},{"p":"38140.4","s":0},{"p":"38140.1","s":0},{"p":"38134.2","s":64394}],"b":[{"p":"38132","s":200},{"p":"38127","s":9009}],"s":"BTC_USDT","t":1701245731984,"u":53095259355}}
{"time":1701245732,"time_ms":1701245732014,"channel":"futures.order_book_update","event":"update","result":{"U":53095259356,"a":[{"p":"38142.4","s":0},{"p":"38149.8","s":0},{"p":"38144.2","s":0},{"p":"38134.2","s":65181},{"p":"38149.3","s":0}],"b":[{"p":"38134.1","s":77154},{"p":"38133","s":0},{"p":"38133.7","s":0},{"p":"38131.8","s":0},{"p":"38117.2","s":0},{"p":"38126.9","s":15000},{"p":"38126.5","s":2314},{"p":"38127.1","s":0},{"p":"38114.4","s":0},{"p":"38126.7","s":1},{"p":"38126.6","s":131}],"s":"BTC_USDT","t":1701245732006,"u":53095259374}}
{"time":1701245732,"time_ms":1701245732032,"channel":"futures.order_book_update","event":"update","result":{"U":53095259375,"a":[{"p":"38138.2","s":16644},{"p":"38140","s":0},{"p":"38141.7","s":0},{"p":"38142.4","s":0},{"p":"38147.1","s":0}],"b":[{"p":"38126.3","s":0},{"p":"38126.4","s":0}],"s":"BTC_USDT","t":1701245732024,"u":53095259387}}
{"time":1701245732,"time_ms":1701245732054,"channel":"futures.order_book_update","event":"update","result":{"U":53095259388,"a":[{"p":"38137.8","s":9946},{"p":"38141.2","s":0},{"p":"38145.2","s":0}],"b":[{"p":"38126.5","s":0},{"p":"38120.7","s":0},{"p":"38021.3","s":0},{"p":"38132.8","s":119},{"p":"38134.1","s":77156},{"p":"38126.6","s":0},{"p":"38120.6","s":0},{"p":"38133.6","s":2},{"p":"38131.7","s":2}],"s":"BTC_USDT","t":1701245732043,"u":53095259403}}
{"time":1701245732,"time_ms":1701245732074,"channel":"futures.order_book_update","event":"update","result":{"U":53095259404,"a":[{"p":"38146.5","s":0},{"p":"38142","s":0},{"p":"38142.5","s":0},{"p":"38145.4","s":0}],"b":[{"p":"38128.9","s":655},{"p":"38126.7","s":0}],"s":"BTC_USDT","t":1701245732064,"u":53095259414}}
{"time":1701245732,"time_ms":1701245732093,"channel":"futures.order_book_update","event":"update","result":{"U":53095259415,"a":[],"b":[{"p":"38119.2","s":0},{"p":"38128.1","s":5351},{"p":"38126.9","s":0}],"s":"BTC_USDT","t":1701245732075,"u":53095259416}}
{"time":1701245732,"time_ms":1701245732113,"channel":"futures.order_book_update","event":"update","result":{"U":53095259417,"a":[{"p":"38145.6","s":0},{"p":"38140.6","s":0},{"p":"38142.2","s":0},{"p":"38142.3","s":0}],"b":[],"s":"BTC_USDT","t":1701245732100,"u":53095259425}}
{"time":1701245732,"time_ms":1701245732132,"channel":"futures.order_book_update","event":"update","result":{"U":53095259426,"a":[{"p":"38142.7","s":0}],"b":[],"s":"BTC_USDT","t":1701245732118,"u":53095259428}}
{"time":1701245732,"time_ms":1701245732274,"channel":"futures.order_book_update","event":"update","result":{"U":53095259429,"a":[],"b":[{"p":"38112.7","s":0}],"s":"BTC_USDT","t":1701245732249,"u":53095259436}}
{"time":1701245732,"time_ms":1701245732292,"channel":"futures.order_book_update","event":"update","result":{"U":53095259437,"a":[],"b":[{"p":"38119.9","s":0}],"s":"BTC_USDT","t":1701245732268,"u":53095259437}}
{"time":1701245732,"time_ms":1701245732314,"channel":"futures.order_book_update","event":"update","result":{"U":53095259438,"a":[{"p":"38153","s":0}],"b":[],"s":"BTC_USDT","t":1701245732303,"u":53095259441}}
{"time":1701245732,"time_ms":1701245732334,"channel":"futures.order_book_update","event":"update","result":{"U":53095259442,"a":[{"p":"38135.2","s":0},{"p":"38140","s":2026}],"b":[{"p":"38133.6","s":0},{"p":"38126.7","s":1},{"p":"38126.9","s":15000},{"p":"38134.1","s":77154},{"p":"38132.8","s":117},{"p":"38131.7","s":0}],"s":"BTC_USDT","t":1701245732325,"u":53095259449}}
{"time":1701245732,"time_ms":1701245732351,"channel":"futures.order_book_update","event":"update","result":{"U":53095259450,"a":[{"p":"38143","s":0}],"b":[{"p":"38121","s":0},{"p":"38133.6","s":2},{"p":"38131.7","s":2},{"p":"38134.1","s":77156},{"p":"38132.8","s":119},{"p":"38126.9","s":0},{"p":"38126.7","s":0}],"s":"BTC_USDT","t":1701245732339,"u":53095259457}}
{"time":1701245732,"time_ms":1701245732452,"channel":"futures.order_book_update","event":"update","result":{"U":53095259458,"a":[],"b":[{"p":"38125.7","s":0}],"s":"BTC_USDT","t":1701245732442,"u":53095259465}}
{"time":1701245732,"time_ms":1701245732472,"channel":"futures.order_book_update","event":"update","result":{"U":53095259466,"a":[{"p":"38141.2","s":0}],"b":[{"p":"38134.1","s":77099},{"p":"38124.4","s":0},{"p":"38124.3","s":0},{"p":"38125.5","s":0}],"s":"BTC_USDT","t":1701245732457,"u":53095259475}}
{"time":1701245732,"time_ms":1701245732493,"channel":"futures.order_book_update","event":"update","result":{"U":53095259476,"a":[{"p":"38140.1","s":1315},{"p":"38134.2","s":122681},{"p":"38136.5","s":0}],"b":[{"p":"38127","s":9209},{"p":"38126.9","s":15000},{"p":"38132","s":0},{"p":"38120.7","s":0}],"s":"BTC_USDT","t":1701245732485,"u":53095259487}}
{"time":1701245732,"time_ms":1701245732514,"channel":"futures.order_book_update","event":"update","result":{"U":53095259488,"a":[{"p":"38134.2","s":103681},{"p":"38140.8","s":0},{"p":"38141.1","s":0}],"b":[{"p":"38126","s":0},{"p":"38067.2","s":0},{"p":"38127","s":9109},{"p":"38132","s":100},{"p":"38126.9","s":0}],"s":"BTC_USDT","t":1701245732501,"u":53095259497}}
{"time":1701245732,"time_ms":1701245732531,"channel":"futures.order_book_update","event":"update","result":{"U":53095259498,"a":[{"p":"38134.2","s":95181},{"p":"38141.5","s":0}],"b":[],"s":"BTC_USDT","t":1701245732514,"u":53095259500}}
{"time":1701245732,"time_ms":1701245732651,"channel":"futures.order_book_update","event":"update","result":{"U":53095259501,"a":[{"p":"38134.2","s":80181}],"b":[],"s":"BTC_USDT","t":1701245732624,"u":53095259501}}
{"time":1701245732,"time_ms":1701245732672,"channel":"futures.order_book_update","event":"update","result":{"U":53095259502,"a":[{"p":"38140","s":2000},{"p":"38143.8","s":0}],"b":[],"s":"BTC_USDT","t":1701245732662,"u":53095259506}}
{"time":1701245732,"time_ms":1701245732692,"channel":"futures.order_book_update","event":"update","result":{"U":53095259507,"a":[{"p":"38134.2","s":65181},{"p":"38141.2","s":0}],"b":[],"s":"BTC_USDT","t":1701245732681,"u":53095259509}}
{"time":1701245732,"time_ms":1701245732713,"channel":"futures.order_book_update","event":"update","result":{"U":53095259510,"a":[{"p":"38140.1","s":0},{"p":"38155.2","s":0},{"p":"38151.4","s":0},{"p":"38158.2","s":0},{"p":"38143","s":0},{"p":"38147.6","s":0},{"p":"38136.5","s":10891}],"b":[{"p":"38132","s":200},{"p":"38110.1","s":0},{"p":"38106.2","s":0},{"p":"38127","s":9009}],"s":"BTC_USDT","t":1701245732685,"u":53095259519}}
{"time":1701245732,"time_ms":1701245732752,"channel":"futures.order_book_update","event":"update","result":{"U":53095259520,"a":[],"b":[{"p":"38035.2","s":0}],"s":"BTC_USDT","t":1701245732731,"u":53095259521}}
{"time":1701245732,"time_ms":1701245732833,"channel":"futures.order_book_update","event":"update","result":{"U":53095259522,"a":[{"p":"38140.9","s":0}],"b":[],"s":"BTC_USDT","t":1701245732824,"u":53095259523}}
{"time":1701245732,"time_ms":1701245732853,"channel":"futures.order_book_update","event":"update","result":{"U":53095259524,"a":[{"p":"38139.1","s":11252}],"b":[{"p":"38117.2","s":0},{"p":"38122.5","s":0},{"p":"38109.4","s":0}],"s":"BTC_USDT","t":1701245732836,"u":53095259530}}
{"time":1701245732,"time_ms":1701245732934,"channel":"futures.order_book_update","event":"update","result":{"U":53095259531,"a":[],"b":[{"p":"38134.1","s":77108}],"s":"BTC_USDT","t":1701245732923,"u":53095259533}}
{"time":1701245732,"time_ms":1701245732953,"channel":"futures.order_book_update","event":"update","result":{"U":53095259534,"a":[],"b":[{"p":"38134.1","s":52642}],"s":"BTC_USDT","t":1701245732942,"u":53095259541}}
{"time":1701245732,"time_ms":1701245732971,"channel":"futures.order_book_update","event":"update","result":{"U":53095259542,"a":[],"b":[{"p":"38120.3","s":0},{"p":"38126.9","s":15000},{"p":"38132.8","s":117},{"p":"38131.9","s":2},{"p":"38133.6","s":0},{"p":"38131.7","s":0},{"p":"38134.1","s":52642},{"p":"38126.7","s":0}],"s":"BTC_USDT","t":1701245732963,"u":53095259549}}
{"time":1701245732,"time_ms":1701245732993,"channel":"futures.order_book_update","event":"update","result":{"U":53095259550,"a":[{"p":"38140.1","s":1315},{"p":"38136.5","s":0}],"b":[{"p":"38133.9","s":395},{"p":"38133.1","s":2},{"p":"38134.1","s":72493},{"p":"38132","s":100},{"p":"38127","s":9109},{"p":"38126.9","s":0},{"p":"38125.2","s":0}],"s":"BTC_USDT","t":1701245732982,"u":53095259559}}
{"time":1701245733,"time_ms":1701245733012,"channel":"futures.order_book_update","event":"update","result":{"U":53095259560,"a":[{"p":"38141.4","s":0}],"b":[{"p":"38134.1","s":72993},{"p":"38126.5","s":0},{"p":"38126","s":0},{"p":"38118.7","s":0},{"p":"38124.1","s":0}],"s":"BTC_USDT","t":1701245733006,"u":53095259571}}
{"time":1701245733,"time_ms":1701245733032,"channel":"futures.order_book_update","event":"update","result":{"U":53095259572,"a":[{"p":"38142.9","s":0},{"p":"38145.2","s":0}],"b":[{"p":"38131.7","s":2},{"p":"38134.1","s":72991},{"p":"38133.9","s":393},{"p":"38126.3","s":0},{"p":"38130.1","s":2},{"p":"38129","s":2},{"p":"38130.9","s":2},{"p":"38131.9","s":0},{"p":"38127.4","s":0},{"p":"38133.1","s":0},{"p":"38127","s":0},{"p":"38121.3","s":0}],"s":"BTC_USDT","t":1701245733023,"u":53095259587}}
{"time":1701245733,"time_ms":1701245733053,"channel":"futures.order_book_update","event":"update","result":{"U":53095259588,"a":[{"p":"38146.2","s":0},{"p":"38143.2","s":0}],"b":[{"p":"38126","s":0}],"s":"BTC_USDT","t":1701245733044,"u":53095259595}}
{"time":1701245733,"time_ms":1701245733091,"channel":"futures.order_book_update","event":"update","result":{"U":53095259596,"a":[{"p":"38134.2","s":64581},{"p":"38142.4","s":0}],"b":[{"p":"38128.9","s":0},{"p":"38134.1","s":72982},{"p":"38127.4","s":3611}],"s":"BTC_USDT","t":1701245733084,"u":53095259602}}
{"time":1701245733,"time_ms":1701245733114,"channel":"futures.order_book_update","event":"update","result":{"U":53095259603,"a":[{"p":"38143","s":0},{"p":"38148.8","s":0},{"p":"38146.3","s":0},{"p":"38141.1","s":0},{"p":"38143.4","s":0},{"p":"38141.2","s":0}],"b":[{"p":"38130","s":655},{"p":"38127.4","s":3611},{"p":"38124.4","s":0},{"p":"38121.2","s":0},{"p":"38127","s":0},{"p":"38125","s":0},{"p":"38132","s":200},{"p":"38128.1","s":0},{"p":"38125.7","s":0},{"p":"38127.1","s":0},{"p":"38126.6","s":0}],"s":"BTC_USDT","t":1701245733095,"u":53095259633}}
{"time":1701245733,"time_ms":1701245733131,"channel":"futures.order_book_update","event":"update","result":{"U":53095259634,"a":[{"p":"38146","s":0},{"p":"38142","s":0}],"b":[{"p":"38126.7","s":2342},{"p":"38131.7","s":0},{"p":"38130.1","s":0},{"p":"38126.6","s":0},{"p":"38127","s":9009},{"p":"38131.6","s":2},{"p":"38134.1","s":72907},{"p":"38126.9","s":15000},{"p":"38130.9","s":0},{"p":"38129","s":0}],"s":"BTC_USDT","t":1701245733124,"u":53095259643}}
{"time":1701245733,"time_ms":1701245733152,"channel":"futures.order_book_update","event":"update","result":{"U":53095259644,"a":[],"b":[{"p":"38128.9","s":2},{"p":"38130.1","s":2},{"p":"38132","s":0},{"p":"38126.7","s":0},{"p":"38126.9","s":0},{"p":"38126.6","s":0},{"p":"38127","s":9209},{"p":"38130.8","s":2}],"s":"BTC_USDT","t":1701245733132,"u":53095259651}}
{"time":1701245733,"time_ms":1701245733171,"channel":"futures.order_book_update","event":"update","result":{"U":53095259652,"a":[{"p":"38142.5","s":0},{"p":"38146.5","s":0},{"p":"38154.5","s":0}],"b":[{"p":"38122.5","s":0}],"s":"BTC_USDT","t":1701245733155,"u":53095259656}}
{"time":1701245733,"time_ms":1701245733212,"channel":"futures.order_book_update","event":"update","result":{"U":53095259657,"a":[],"b":[{"p":"38132","s":200},{"p":"38127","s":0}],"s":"BTC_USDT","t":1701245733195,"u":53095259662}}
{"time":1701245733,"time_ms":1701245733233,"channel":"futures.order_book_update","event":"update","result":{"U":53095259663,"a":[],"b":[{"p":"38124.5","s":0}],"s":"BTC_USDT","t":1701245733217,"u":53095259664}}
{"time":1701245733,"time_ms":1701245733252,"channel":"futures.order_book_update","event":"update","result":{"U":53095259665,"a":[{"p":"38142.6","s":0}],"b":[],"s":"BTC_USDT","t":1701245733232,"u":53095259666}}
{"time":1701245733,"time_ms":1701245733272,"channel":"futures.order_book_update","event":"update","result":{"U":53095259667,"a":[],"b":[{"p":"38134.1","s":73407}],"s":"BTC_USDT","t":1701245733255,"u":53095259670}}
{"time":1701245733,"time_ms":1701245733314,"channel":"futures.order_book_update","event":"update","result":{"U":53095259671,"a":[{"p":"38146.8","s":0}],"b":[],"s":"BTC_USDT","t":1701245733292,"u":53095259673}}
{"time":1701245733,"time_ms":1701245733352,"channel":"futures.order_book_update","event":"update","result":{"U":53095259674,"a":[{"p":"38138","s":600},{"p":"38140.1","s":0},{"p":"38142.3","s":0}],"b":[],"s":"BTC_USDT","t":1701245733336,"u":53095259676}}
{"time":1701245733,"time_ms":1701245733391,"channel":"futures.order_book_update","event":"update","result":{"U":53095259677,"a":[],"b":[{"p":"38120.6","s":0}],"s":"BTC_USDT","t":1701245733369,"u":53095259678}}
{"time":1701245733,"time_ms":1701245733413,"channel":"futures.order_book_update","event":"update","result":{"U":53095259679,"a":[{"p":"38147.2","s":0},{"p":"38144.2","s":0},{"p":"38141.9","s":0}],"b":[],"s":"BTC_USDT","t":1701245733401,"u":53095259684}}
{"time":1701245733,"time_ms":1701245733433,"channel":"futures.order_book_update","event":"update","result":{"U":53095259685,"a":[],"b":[{"p":"38134.1","s":73907}],"s":"BTC_USDT","t":1701245733424,"u":53095259693}}
{"time":1701245733,"time_ms":1701245733451,"channel":"futures.order_book_update","event":"update","result":{"U":53095259694,"a":[],"b":[{"p":"38134.1","s":73407}],"s":"BTC_USDT","t":1701245733433,"u":53095259695}}
{"time":1701245733,"time_ms":1701245733473,"channel":"futures.order_book_update","event":"update","result":{"U":53095259696,"a":[{"p":"38146.2","s":0},{"p":"38134.2","s":64581},{"p":"38142.4","s":0},{"p":"38147.5","s":0},{"p":"38141.2","s":0},{"p":"38143.7","s":0},{"p":"38143.1","s":0},{"p":"38144.9","s":0}],"b":[{"p":"38127","s":9009},{"p":"38036.9","s":0},{"p":"38125.1","s":0},{"p":"38126","s":0},{"p":"38130","s":0},{"p":"38059.8","s":0},{"p":"38121.7","s":0},{"p":"38126.7","s":0},{"p":"38129.1","s":0}],"s":"BTC_USDT","t":1701245733463,"u":53095259732}}
{"time":1701245733,"time_ms":1701245733492,"channel":"futures.order_book_update","event":"update","result":{"U":53095259733,"a":[{"p":"38142.6","s":0},{"p":"38134.2","s":64581},{"p":"38142","s":0},{"p":"38142.9","s":0},{"p":"38141.8","s":0}],"b":[{"p":"38134.1","s":72907},{"p":"38124.4","s":0}],"s":"BTC_USDT","t":1701245733483,"u":53095259746}}
{"time":1701245733,"time_ms":1701245733511,"channel":"futures.order_book_update","event":"update","result":{"U":53095259747,"a":[{"p":"38146.8","s":0},{"p":"38143.9","s":0}],"b":[],"s":"BTC_USDT","t":1701245733488,"u":53095259751}}
{"time":1701245733,"time_ms":1701245733533,"channel":"futures.order_book_update","event":"update","result":{"U":53095259752,"a":[{"p":"38135.4","s":524},{"p":"38140","s":0}],"b":[],"s":"BTC_USDT","t":1701245733513,"u":53095259752}}
{"time":1701245733,"time_ms":1701245733553,"channel":"futures.order_book_update","event":"update","result":{"U":53095259753,"a":[{"p":"38136.5","s":10895},{"p":"38139.9","s":0}],"b":[],"s":"BTC_USDT","t":1701245733534,"u":53095259753}}
{"time":1701245733,"time_ms":1701245733613,"channel":"futures.order_book_update","event":"update","result":{"U":53095259754,"a":[],"b":[{"p":"38126.7","s":1},{"p":"38131.6","s":0},{"p":"38130.8","s":0},{"p":"38130.1","s":0},{"p":"38128.9","s":0},{"p":"38126.6","s":131},{"p":"38126.3","s":2396},{"p":"38126.9","s":15000}],"s":"BTC_USDT","t":1701245733603,"u":53095259757}}
{"time":1701245733,"time_ms":1701245733673,"channel":"futures.order_book_update","event":"update","result":{"U":53095259758,"a":[{"p":"38147","s":0},{"p":"38144.9","s":0},{"p":"38143","s":0}],"b":[{"p":"38131.3","s":2},{"p":"38126.7","s":0},{"p":"38126.3","s":0},{"p":"38126.9","s":0},{"p":"38125.5","s":0},{"p":"38128.6","s":2},{"p":"38129.8","s":2},{"p":"38130.5","s":2},{"p":"38126.6","s":0}],"s":"BTC_USDT","t":1701245733662,"u":53095259769}}
{"time":1701245733,"time_ms":1701245733711,"channel":"futures.order_book_update","event":"update","result":{"U":53095259770,"a":[{"p":"38143","s":0},{"p":"38146.8","s":0}],"b":[{"p":"38122.5","s":0},{"p":"38134.1","s":72407}],"s":"BTC_USDT","t":1701245733699,"u":53095259783}}
{"time":1701245733,"time_ms":1701245733731,"channel":"futures.order_book_update","event":"update","result":{"U":53095259784,"a":[{"p":"38134.2","s":64581}],"b":[],"s":"BTC_USDT","t":1701245733707,"u":53095259785}}
{"time":1701245733,"time_ms":1701245733811,"channel":"futures.order_book_update","event":"update","result":{"U":53095259786,"a":[{"p":"38134.2","s":67726}],"b":[],"s":"BTC_USDT","t":1701245733790,"u":53095259787}}
{"time":1701245733,"time_ms":1701245733832,"channel":"futures.order_book_update","event":"update","result":{"U":53095259788,"a":[],"b":[{"p":"38115","s":0}],"s":"BTC_USDT","t":1701245733811,"u":53095259789}}
{"time":1701245733,"time_ms":1701245733875,"channel":"futures.order_book_update","event":"update","result":{"U":53095259790,"a":[],"b":[{"p":"38131.3","s":0},{"p":"38130.5","s":0},{"p":"38128.6","s":0},{"p":"38129.8","s":0},{"p":"38126.6","s":131},{"p":"38126.3","s":2396},{"p":"38126.9","s":15000},{"p":"38126.7","s":1}],"s":"BTC_USDT","t":1701245733853,"u":53095259793}}
{"time":1701245733,"time_ms":1701245733914,"channel":"futures.order_book_update","event":"update","result":{"U":53095259794,"a":[],"b":[{"p":"38128.6","s":2},{"p":"38130.5","s":2},{"p":"38131.2","s":2},{"p":"38129.7","s":2},{"p":"38126.3","s":0},{"p":"38126.9","s":0},{"p":"38126.7","s":0},{"p":"38126.6","s":0}],"s":"BTC_USDT","t":1701245733901,"u":53095259797}}
{"time":1701245733,"time_ms":1701245733954,"channel":"futures.order_book_update","event":"update","result":{"U":53095259798,"a":[],"b":[{"p":"38107.3","s":0}],"s":"BTC_USDT","t":1701245733944,"u":53095259804}}
{"time":1701245733,"time_ms":1701245733971,"channel":"futures.order_book_update","event":"update","result":{"U":53095259805,"a":[{"p":"38134.2","s":68326},{"p":"38143.2","s":0},{"p":"38143.7","s":0},{"p":"38147.5","s":0}],"b":[{"p":"38129.3","s":11872},{"p":"38126","s":0},{"p":"38125.7","s":0}],"s":"BTC_USDT","t":1701245733958,"u":53095259815}}
{"time":1701245734,"time_ms":1701245734010,"channel":"futures.order_book_update","event":"update","result":{"U":53095259816,"a":[{"p":"38142","s":0},{"p":"38146","s":0}],"b":[{"p":"38125.5","s":0}],"s":"BTC_USDT","t":1701245733994,"u":53095259823}}
{"time":1701245734,"time_ms":1701245734031,"channel":"futures.order_book_update","event":"update","result":{"U":53095259824,"a":[{"p":"38149.4","s":0},{"p":"38142.4","s":0},{"p":"38141.7","s":0},{"p":"38143.6","s":0}],"b":[{"p":"38016.1","s":0},{"p":"38119","s":0},{"p":"38121.2","s":0},{"p":"38125.1","s":0}],"s":"BTC_USDT","t":1701245734022,"u":53095259837}}
{"time":1701245734,"time_ms":1701245734052,"channel":"futures.order_book_update","event":"update","result":{"U":53095259838,"a":[],"b":[{"p":"38124.1","s":0},{"p":"38124.4","s":0}],"s":"BTC_USDT","t":1701245734036,"u":53095259843}}
{"time":1701245734,"time_ms":1701245734073,"channel":"futures.order_book_update","event":"update","result":{"U":53095259844,"a":[{"p":"38142.3","s":0}],"b":[{"p":"38125","s":0}],"s":"BTC_USDT","t":1701245734060,"u":53095259847}}
{"time":1701245734,"time_ms":1701245734092,"channel":"futures.order_book_update","event":"update","result":{"U":53095259848,"a":[],"b":[{"p":"38102.3","s":0}],"s":"BTC_USDT","t":1701245734085,"u":53095259849}}
{"time":1701245734,"time_ms":1701245734132,"channel":"futures.order_book_update","event":"update","result":{"U":53095259850,"a":[],"b":[{"p":"38126.7","s":1},{"p":"38126.6","s":131},{"p":"38126.3","s":2396},{"p":"38128.6","s":0},{"p":"38125","s":0},{"p":"38126.9","s":15000},{"p":"38130.5","s":0},{"p":"38129.7","s":0},{"p":"38131.2","s":0}],"s":"BTC_USDT","t":1701245734123,"u":53095259856}}
{"time":1701245734,"time_ms":1701245734171,"channel":"futures.order_book_update","event":"update","result":{"U":53095259857,"a":[],"b":[{"p":"38131.2","s":2},{"p":"38130.4","s":133},{"p":"38128.5","s":2},{"p":"38126.6","s":0},{"p":"38126.3","s":0}],"s":"BTC_USDT","t":1701245734155,"u":53095259859}}
{"time":1701245734,"time_ms":1701245734192,"channel":"futures.order_book_update","event":"update","result":{"U":53095259860,"a":[],"b":[{"p":"38129.7","s":2},{"p":"38126.7","s":0}],"s":"BTC_USDT","t":1701245734166,"u":53095259860}}
{"time":1701245734,"time_ms":1701245734253,"channel":"futures.order_book_update","event":"update","result":{"U":53095259861,"a":[{"p":"38142.4","s":0},{"p":"38142","s":0}],"b":[],"s":"BTC_USDT","t":1701245734238,"u":53095259866}}
{"time":1701245734,"time_ms":1701245734294,"channel":"futures.order_book_update","event":"update","result":{"U":53095259867,"a":[{"p":"38142.1","s":0}],"b":[{"p":"38118.9","s":0}],"s":"BTC_USDT","t":1701245734273,"u":53095259868}}
{"time":1701245734,"time_ms":1701245734332,"channel":"futures.order_book_update","event":"update","result":{"U":53095259869,"a":[{"p":"38184.3","s":0}],"b":[],"s":"BTC_USDT","t":1701245734316,"u":53095259870}}
{"time":1701245734,"time_ms":1701245734354,"channel":"futures.order_book_update","event":"update","result":{"U":53095259871,"a":[{"p":"38140.8","s":0},{"p":"38148.5","s":0},{"p":"38134.2","s":64581},{"p":"38145.6","s":0},{"p":"38140.9","s":0},{"p":"38142.4","s":0},{"p":"38143","s":0},{"p":"38143.2","s":0}],"b":[{"p":"38130.3","s":655},{"p":"38126.9","s":0},{"p":"38124.9","s":0},{"p":"38129.3","s":11217},{"p":"38121","s":0},{"p":"38125.5","s":0},{"p":"38113.4","s":0},{"p":"38118.3","s":0},{"p":"38123.8","s":0},{"p":"38120.7","s":0}],"s":"BTC_USDT","t":1701245734341,"u":53095259903}}
{"time":1701245734,"time_ms":1701245734372,"channel":"futures.order_book_update","event":"update","result":{"U":53095259904,"a":[],"b":[{"p":"38126.9","s":15000},{"p":"38134.1","s":72416},{"p":"38128","s":0},{"p":"38116.5","s":0},{"p":"38124","s":0},{"p":"38122.5","s":0}],"s":"BTC_USDT","t":1701245734362,"u":53095259909}}
{"time":1701245734,"time_ms":1701245734432,"channel":"futures.order_book_update","event":"update","result":{"U":53095259910,"a":[],"b":[{"p":"38125.5","s":0}],"s":"BTC_USDT","t":1701245734419,"u":53095259912}}
{"time":1701245734,"time_ms":1701245734476,"channel":"futures.order_book_update","event":"update","result":{"U":53095259913,"a":[],"b":[{"p":"38134.1","s":72916},{"p":"38128","s":8915},{"p":"38126.9","s":0}],"s":"BTC_USDT","t":1701245734467,"u":53095259923}}
{"time":1701245734,"time_ms":1701245734491,"channel":"futures.order_book_update","event":"update","result":{"U":53095259924,"a":[],"b":[{"p":"38134.1","s":72416}],"s":"BTC_USDT","t":1701245734484,"u":53095259926}}
{"time":1701245734,"time_ms":1701245734512,"channel":"futures.order_book_update","event":"update","result":{"U":53095259927,"a":[],"b":[{"p":"38134.1","s":72416}],"s":"BTC_USDT","t":1701245734495,"u":53095259934}}
{"time":1701245734,"time_ms":1701245734552,"channel":"futures.order_book_update","event":"update","result":{"U":53095259935,"a":[],"b":[{"p":"38134.1","s":72416}],"s":"BTC_USDT","t":1701245734538,"u":53095259936}}
{"time":1701245734,"time_ms":1701245734572,"channel":"futures.order_book_update","event":"update","result":{"U":53095259937,"a":[],"b":[{"p":"38134.1","s":72416}],"s":"BTC_USDT","t":1701245734554,"u":53095259942}}
{"time":1701245734,"time_ms":1701245734612,"channel":"futures.order_book_update","event":"update","result":{"U":53095259943,"a":[],"b":[{"p":"38134.1","s":72416}],"s":"BTC_USDT","t":1701245734596,"u":53095259944}}
{"time":1701245734,"time_ms":1701245734653,"channel":"futures.order_book_update","event":"update","result":{"U":53095259945,"a":[{"p":"38134.2","s":65181},{"p":"38141.5","s":0},{"p":"38146.6","s":0},{"p":"38143.7","s":0}],"b":[{"p":"38121.6","s":0},{"p":"38126","s":0},{"p":"38126.3","s":0}],"s":"BTC_USDT","t":1701245734642,"u":53095259959}}
{"time":1701245734,"time_ms":1701245734711,"channel":"futures.order_book_update","event":"update","result":{"U":53095259960,"a":[],"b":[{"p":"38134.1","s":72916},{"p":"38124.4","s":0}],"s":"BTC_USDT","t":1701245734698,"u":53095259963}}
{"time":1701245734,"time_ms":1701245734731,"channel":"futures.order_book_update","event":"update","result":{"U":53095259964,"a":[],"b":[{"p":"38134.1","s":72416}],"s":"BTC_USDT","t":1701245734720,"u":53095259970}}
{"time":1701245734,"time_ms":1701245734853,"channel":"futures.order_book_update","event":"update","result":{"U":53095259971,"a":[],"b":[{"p":"38126.9","s":15000},{"p":"38130.4","s":131},{"p":"38126.6","s":131},{"p":"38131.2","s":0},{"p":"38129.7","s":0},{"p":"38128.5","s":0},{"p":"38126.7","s":1}],"s":"BTC_USDT","t":1701245734829,"u":53095259975}}
{"time":1701245734,"time_ms":1701245734872,"channel":"futures.order_book_update","event":"update","result":{"U":53095259976,"a":[],"b":[{"p":"38129.6","s":2},{"p":"38126.6","s":0},{"p":"38126.7","s":0},{"p":"38128.4","s":133},{"p":"38130.4","s":133},{"p":"38131.1","s":2}],"s":"BTC_USDT","t":1701245734861,"u":53095259979}}
{"time":1701245734,"time_ms":1701245734953,"channel":"futures.order_book_update","event":"update","result":{"U":53095259980,"a":[],"b":[{"p":"38129.6","s":0},{"p":"38131.1","s":0},{"p":"38130.4","s":131},{"p":"38128.4","s":131},{"p":"38126.7","s":1},{"p":"38126.6","s":131}],"s":"BTC_USDT","t":1701245734946,"u":53095259986}}
{"time":1701245734,"time_ms":1701245734974,"channel":"futures.order_book_update","event":"update","result":{"U":53095259987,"a":[{"p":"38155","s":0},{"p":"38142.5","s":0},{"p":"38146.5","s":0},{"p":"38145.6","s":0}],"b":[{"p":"38126.6","s":0},{"p":"38130.3","s":657},{"p":"38131.1","s":2},{"p":"38129.6","s":2},{"p":"38126.7","s":0}],"s":"BTC_USDT","t":1701245734962,"u":53095259994}}
{"time":1701245735,"time_ms":1701245735018,"channel":"futures.order_book_update","event":"update","result":{"U":53095259995,"a":[{"p":"38149","s":0},{"p":"38141.5","s":0},{"p":"38144","s":0}],"b":[{"p":"38128.4","s":133}],"s":"BTC_USDT","t":1701245735006,"u":53095260002}}
{"time":1701245735,"time_ms":1701245735034,"channel":"futures.order_book_update","event":"update","result":{"U":53095260003,"a":[{"p":"38146.2","s":0},{"p":"38142.7","s":0}],"b":[{"p":"38124.1","s":0},{"p":"38125.5","s":0}],"s":"BTC_USDT","t":1701245735016,"u":53095260010}}
{"time":1701245735,"time_ms":1701245735092,"channel":"futures.order_book_update","event":"update","result":{"U":53095260011,"a":[{"p":"38143.1","s":0},{"p":"38134.2","s":64581},{"p":"38142.1","s":0},{"p":"38141.2","s":0},{"p":"38140.9","s":0}],"b":[{"p":"38130.3","s":2},{"p":"38121","s":0},{"p":"38119.3","s":0}],"s":"BTC_USDT","t":1701245735083,"u":53095260025}}
{"time":1701245735,"time_ms":1701245735112,"channel":"futures.order_book_update","event":"update","result":{"U":53095260026,"a":[{"p":"38143.2","s":0},{"p":"38141.2","s":0},{"p":"38145.6","s":0},{"p":"38140","s":2000},{"p":"38136.5","s":0},{"p":"38143.8","s":0},{"p":"38142","s":0},{"p":"38145.1","s":0},{"p":"38143.4","s":0},{"p":"38142.4","s":0},{"p":"38139.9","s":15000},{"p":"38135.4","s":0},{"p":"38143.6","s":0},{"p":"38148.8","s":0},{"p":"38149.6","s":0},{"p":"38142.3","s":0},{"p":"38139.6","s":0},{"p":"38148","s":0},{"p":"38147.5","s":0},{"p":"38134.2","s":63794},{"p":"38143.7","s":0},{"p":"38147.1","s":0},{"p":"38139.8","s":1315},{"p":"38142.1","s":0}],"b":[{"p":"38127","s":9009},{"p":"38130.9","s":0},{"p":"38131.1","s":0},{"p":"38114.4","s":0},{"p":"38127.1","s":2325},{"p":"38129.6","s":0},{"p":"38130.3","s":0},{"p":"38125.6","s":0},{"p":"38124.4","s":0},{"p":"38126.3","s":0},{"p":"38133.5","s":2},{"p":"38132.3","s":2},{"p":"38125.7","s":0},{"p":"38126.6","s":0},{"p":"38118.7","s":0},{"p":"38121.2","s":0},{"p":"38126.7","s":0},{"p":"38126.9","s":15000},{"p":"38134.1","s":86447},{"p":"38128.4","s":131},{"p":"38122.3","s":0}],"s":"BTC_USDT","t":1701245735104,"u":53095260112}}
{"time":1701245735,"time_ms":1701245735132,"channel":"futures.order_book_update","event":"update","result":{"U":53095260113,"a":[{"p":"38142.6","s":0},{"p":"38142.7","s":0},{"p":"38146.2","s":0},{"p":"38141.9","s":0},{"p":"38145.4","s":0},{"p":"38142.4","s":0},{"p":"38144","s":0},{"p":"38149.5","s":0},{"p":"38142.3","s":0},{"p":"38144.7","s":0}],"b":[{"p":"38126.9","s":15000},{"p":"38126.7","s":1},{"p":"38127.1","s":0},{"p":"38128.1","s":0},{"p":"38123.3","s":0},{"p":"38127.6","s":0},{"p":"38126.1","s":0}],"s":"BTC_USDT","t":1701245735124,"u":53095260146}}
{"time":1701245735,"time_ms":1701245735153,"channel":"futures.order_book_update","event":"update","result":{"U":53095260147,"a":[{"p":"38144.7","s":0}],"b":[{"p":"38127.1","s":2322},{"p":"38126.6","s":131},{"p":"38134.1","s":86443},{"p":"38133.5","s":0},{"p":"38132.3","s":0},{"p":"38126.7","s":1},{"p":"38125.5","s":0}],"s":"BTC_USDT","t":1701245735135,"u":53095260158}}
{"time":1701245735,"time_ms":1701245735212,"channel":"futures.order_book_update","event":"update","result":{"U":53095260159,"a":[],"b":[{"p":"38134.1","s":86447},{"p":"38126.9","s":0},{"p":"38126.7","s":0},{"p":"38126.6","s":0},{"p":"38115.6","s":0},{"p":"38130.5","s":655},{"p":"38133.5","s":2},{"p":"38132.4","s":2}],"s":"BTC_USDT","t":1701245735195,"u":53095260170}}
{"time":1701245735,"time_ms":1701245735251,"channel":"futures.order_book_update","event":"update","result":{"U":53095260171,"a":[{"p":"38134.2","s":64394},{"p":"38142.4","s":0},{"p":"38142","s":0}],"b":[{"p":"38125","s":0}],"s":"BTC_USDT","t":1701245735236,"u":53095260176}}
{"time":1701245735,"time_ms":1701245735271,"channel":"futures.order_book_update","event":"update","result":{"U":53095260177,"a":[{"p":"38140","s":0},{"p":"38136.4","s":524}],"b":[],"s":"BTC_USDT","t":1701245735242,"u":53095260177}}
{"time":1701245735,"time_ms":1701245735294,"channel":"futures.order_book_update","event":"update","result":{"U":53095260178,"a":[{"p":"38145.7","s":0}],"b":[{"p":"38105.9","s":0}],"s":"BTC_USDT","t":1701245735271,"u":53095260180}}
{"time":1701245735,"time_ms":1701245735313,"channel":"futures.order_book_update","event":"update","result":{"U":53095260181,"a":[],"b":[{"p":"38126.4","s":0},{"p":"38122.1","s":0}],"s":"BTC_USDT","t":1701245735302,"u":53095260186}}
{"time":1701245735,"time_ms":1701245735331,"channel":"futures.order_book_update","event":"update","result":{"U":53095260187,"a":[{"p":"38147.9","s":0}],"b":[],"s":"BTC_USDT","t":1701245735316,"u":53095260188}}
{"time":1701245735,"time_ms":1701245735353,"channel":"futures.order_book_update","event":"update","result":{"U":53095260189,"a":[{"p":"38153","s":0},{"p":"38144.9","s":0},{"p":"38151.6","s":0}],"b":[{"p":"38120","s":0},{"p":"38122.5","s":0}],"s":"BTC_USDT","t":1701245735344,"u":53095260196}}
{"time":1701245735,"time_ms":1701245735374,"channel":"futures.order_book_update","event":"update","result":{"U":53095260197,"a":[{"p":"38153","s":0}],"b":[{"p":"38134.1","s":78947}],"s":"BTC_USDT","t":1701245735360,"u":53095260200}}
{"time":1701245735,"time_ms":1701245735414,"channel":"futures.order_book_update","event":"update","result":{"U":53095260201,"a":[],"b":[{"p":"38134.1","s":78943},{"p":"38126.9","s":15000},{"p":"38133.5","s":0}],"s":"BTC_USDT","t":1701245735399,"u":53095260203}}
{"time":1701245735,"time_ms":1701245735430,"channel":"futures.order_book_update","event":"update","result":{"U":53095260204,"a":[],"b":[{"p":"38127.1","s":0},{"p":"38132.4","s":0},{"p":"38126.6","s":0},{"p":"38126.3","s":0},{"p":"38134.1","s":78947},{"p":"38133.6","s":2},{"p":"38126.7","s":1}],"s":"BTC_USDT","t":1701245735418,"u":53095260210}}
{"time":1701245735,"time_ms":1701245735452,"channel":"futures.order_book_update","event":"update","result":{"U":53095260211,"a":[],"b":[{"p":"38132.4","s":2},{"p":"38126.7","s":0}],"s":"BTC_USDT","t":1701245735434,"u":53095260211}}
{"time":1701245735,"time_ms":1701245735512,"channel":"futures.order_book_update","event":"update","result":{"U":53095260212,"a":[{"p":"38142.9","s":0}],"b":[],"s":"BTC_USDT","t":1701245735496,"u":53095260212}}
{"time":1701245735,"time_ms":1701245735533,"channel":"futures.order_book_update","event":"update","result":{"U":53095260213,"a":[],"b":[{"p":"38126","s":0}],"s":"BTC_USDT","t":1701245735520,"u":53095260215}}
{"time":1701245735,"time_ms":1701245735551,"channel":"futures.order_book_update","event":"update","result":{"U":53095260216,"a":[{"p":"38148.8","s":0}],"b":[],"s":"BTC_USDT","t":1701245735541,"u":53095260216}}
{"time":1701245735,"time_ms":1701245735573,"channel":"futures.order_book_update","event":"update","result":{"U":53095260217,"a":[{"p":"38143.2","s":0}],"b":[],"s":"BTC_USDT","t":1701245735552,"u":53095260218}}
{"time":1701245735,"time_ms":1701245735590,"channel":"futures.order_book_update","event":"update","result":{"U":53095260219,"a":[{"p":"38145.8","s":0}],"b":[],"s":"BTC_USDT","t":1701245735573,"u":53095260219}}
{"time":1701245735,"time_ms":1701245735613,"channel":"futures.order_book_update","event":"update","result":{"U":53095260220,"a":[],"b":[{"p":"38134.1","s":78938}],"s":"BTC_USDT","t":1701245735595,"u":53095260221}}
{"time":1701245735,"time_ms":1701245735754,"channel":"futures.order_book_update","event":"update","result":{"U":53095260222,"a":[],"b":[{"p":"38133.6","s":0},{"p":"38134.1","s":78934},{"p":"38126.7","s":1},{"p":"38126.6","s":131},{"p":"38132.4","s":0}],"s":"BTC_USDT","t":1701245735726,"u":53095260226}}
{"time":1701245735,"time_ms":1701245735771,"channel":"futures.order_book_update","event":"update","result":{"U":53095260227,"a":[{"p":"38143","s":0},{"p":"38150.6","s":0}],"b":[{"p":"38133.6","s":2},{"p":"38126.7","s":0},{"p":"38126.6","s":0},{"p":"38132.5","s":2},{"p":"38134.1","s":78938}],"s":"BTC_USDT","t":1701245735758,"u":53095260234}}
{"time":1701245735,"time_ms":1701245735813,"channel":"futures.order_book_update","event":"update","result":{"U":53095260235,"a":[{"p":"38178.1","s":0}],"b":[],"s":"BTC_USDT","t":1701245735784,"u":53095260236}}
{"time":1701245735,"time_ms":1701245735852,"channel":"futures.order_book_update","event":"update","result":{"U":53095260237,"a":[{"p":"38159.2","s":0},{"p":"38154.4","s":0},{"p":"38144","s":0},{"p":"38158.2","s":0}],"b":[{"p":"38111.3","s":0},{"p":"38107.4","s":0},{"p":"38103.5","s":0}],"s":"BTC_USDT","t":1701245735840,"u":53095260244}}
{"time":1701245735,"time_ms":1701245735972,"channel":"futures.order_book_update","event":"update","result":{"U":53095260245,"a":[{"p":"38142.5","s":0}],"b":[],"s":"BTC_USDT","t":1701245735964,"u":53095260246}}
{"time":1701245735,"time_ms":1701245735991,"channel":"futures.order_book_update","event":"update","result":{"U":53095260247,"a":[{"p":"38146.5","s":0}],"b":[],"s":"BTC_USDT","t":1701245735973,"u":53095260248}}
{"time":1701245736,"time_ms":1701245736013,"channel":"futures.order_book_update","event":"update","result":{"U":53095260249,"a":[{"p":"38150.3","s":0},{"p":"38142","s":0}],"b":[{"p":"38119.4","s":0}],"s":"BTC_USDT","t":1701245736004,"u":53095260253}}
{"time":1701245736,"time_ms":1701245736032,"channel":"futures.order_book_update","event":"update","result":{"U":53095260254,"a":[{"p":"38143.4","s":0},{"p":"38141.5","s":0},{"p":"38146.4","s":0}],"b":[{"p":"38121.5","s":0},{"p":"38125.7","s":0},{"p":"38124.4","s":0}],"s":"BTC_USDT","t":1701245736021,"u":53095260266}}
{"time":1701245736,"time_ms":1701245736091,"channel":"futures.order_book_update","event":"update","result":{"U":53095260267,"a":[],"b":[{"p":"38125.5","s":0}],"s":"BTC_USDT","t":1701245736067,"u":53095260268}}
{"time":1701245736,"time_ms":1701245736172,"channel":"futures.order_book_update","event":"update","result":{"U":53095260269,"a":[{"p":"38141.9","s":0}],"b":[{"p":"38126.7","s":1},{"p":"38133.6","s":0},{"p":"38126.3","s":0},{"p":"38126.6","s":0},{"p":"38125.5","s":0},{"p":"38118.7","s":0},{"p":"38132.5","s":2},{"p":"38134.1","s":78934}],"s":"BTC_USDT","t":1701245736164,"u":53095260284}}
{"time":1701245736,"time_ms":1701245736192,"channel":"futures.order_book_update","event":"update","result":{"U":53095260285,"a":[{"p":"38145.8","s":0}],"b":[{"p":"38133.6","s":2},{"p":"38127","s":0},{"p":"38126.7","s":0},{"p":"38121.2","s":0},{"p":"38124.1","s":0},{"p":"38131.7","s":2},{"p":"38129","s":2},{"p":"38130.9","s":2},{"p":"38132.5","s":0},{"p":"38126.9","s":0},{"p":"38125.1","s":0}],"s":"BTC_USDT","t":1701245736179,"u":53095260300}}
{"time":1701245736,"time_ms":1701245736233,"channel":"futures.order_book_update","event":"update","result":{"U":53095260301,"a":[],"b":[{"p":"38055.4","s":0}],"s":"BTC_USDT","t":1701245736204,"u":53095260301}}
{"time":1701245736,"time_ms":1701245736271,"channel":"futures.order_book_update","event":"update","result":{"U":53095260302,"a":[],"b":[{"p":"38130.1","s":2},{"p":"38133.6","s":0},{"p":"38127","s":0}],"s":"BTC_USDT","t":1701245736254,"u":53095260303}}
{"time":1701245736,"time_ms":1701245736293,"channel":"futures.order_book_update","event":"update","result":{"U":53095260304,"a":[{"p":"38142","s":0},{"p":"38146","s":0}],"b":[{"p":"38131.7","s":2},{"p":"38130.9","s":2},{"p":"38126.9","s":0},{"p":"38130.1","s":2},{"p":"38127","s":9009},{"p":"38129","s":0},{"p":"38126.6","s":0},{"p":"38125.5","s":0},{"p":"38126.7","s":0},{"p":"38124.9","s":0}],"s":"BTC_USDT","t":1701245736279,"u":53095260318}}
{"time":1701245736,"time_ms":1701245736313,"channel":"futures.order_book_update","event":"update","result":{"U":53095260319,"a":[],"b":[{"p":"38127","s":0},{"p":"38129","s":2}],"s":"BTC_USDT","t":1701245736305,"u":53095260320}}
{"time":1701245736,"time_ms":1701245736352,"channel":"futures.order_book_update","event":"update","result":{"U":53095260321,"a":[],"b":[{"p":"38122.5","s":0}],"s":"BTC_USDT","t":1701245736340,"u":53095260321}}
{"time":1701245736,"time_ms":1701245736411,"channel":"futures.order_book_update","event":"update","result":{"U":53095260322,"a":[],"b":[{"p":"38125","s":0}],"s":"BTC_USDT","t":1701245736402,"u":53095260325}}
{"time":1701245736,"time_ms":1701245736433,"channel":"futures.order_book_update","event":"update","result":{"U":53095260326,"a":[{"p":"38143.1","s":0},{"p":"38145.4","s":0}],"b":[{"p":"38123.8","s":0}],"s":"BTC_USDT","t":1701245736416,"u":53095260331}}
{"time":1701245736,"time_ms":1701245736452,"channel":"futures.order_book_update","event":"update","result":{"U":53095260332,"a":[],"b":[{"p":"38121","s":0}],"s":"BTC_USDT","t":1701245736444,"u":53095260332}}
{"time":1701245736,"time_ms":1701245736475,"channel":"futures.order_book_update","event":"update","result":{"U":53095260333,"a":[{"p":"38139.8","s":3490},{"p":"38140.6","s":0},{"p":"38145.5","s":0},{"p":"38141.5","s":0}],"b":[{"p":"38126","s":0}],"s":"BTC_USDT","t":1701245736464,"u":53095260341}}
{"time":1701245736,"time_ms":1701245736515,"channel":"futures.order_book_update","event":"update","result":{"U":53095260342,"a":[{"p":"38134.2","s":67539},{"p":"38141.7","s":0}],"b":[],"s":"BTC_USDT","t":1701245736489,"u":53095260344}}
{"time":1701245736,"time_ms":1701245736520,"channel":"futures.order_book_update","event":"update","result":{"U":53095260345,"a":[{"p":"38141","s":0}],"b":[],"s":"BTC_USDT","t":1701245736508,"u":53095260345}}
{"time":1701245736,"time_ms":1701245736532,"channel":"futures.order_book_update","event":"update","result":{"U":53095260346,"a":[],"b":[{"p":"38123.5","s":0}],"s":"BTC_USDT","t":1701245736523,"u":53095260348}}
{"time":1701245736,"time_ms":1701245736554,"channel":"futures.order_book_update","event":"update","result":{"U":53095260349,"a":[],"b":[{"p":"38120.7","s":0}],"s":"BTC_USDT","t":1701245736525,"u":53095260350}}
{"time":1701245736,"time_ms":1701245736572,"channel":"futures.order_book_update","event":"update","result":{"U":53095260351,"a":[{"p":"38134.2","s":82539}],"b":[{"p":"38124.5","s":0},{"p":"38122.8","s":0},{"p":"38115.4","s":0}],"s":"BTC_USDT","t":1701245736555,"u":53095260357}}
{"time":1701245736,"time_ms":1701245736591,"channel":"futures.order_book_update","event":"update","result":{"U":53095260358,"a":[{"p":"38134.2","s":97539}],"b":[],"s":"BTC_USDT","t":1701245736581,"u":53095260359}}
{"time":1701245736,"time_ms":1701245736612,"channel":"futures.order_book_update","event":"update","result":{"U":53095260360,"a":[{"p":"38139.8","s":1315}],"b":[],"s":"BTC_USDT","t":1701245736585,"u":53095260361}}
{"time":1701245736,"time_ms":1701245736632,"channel":"futures.order_book_update","event":"update","result":{"U":53095260362,"a":[{"p":"38140","s":2000},{"p":"38138","s":0}],"b":[],"s":"BTC_USDT","t":1701245736614,"u":53095260362}}
{"time":1701245736,"time_ms":1701245736732,"channel":"futures.order_book_update","event":"update","result":{"U":53095260363,"a":[{"p":"38140","s":0},{"p":"38142.7","s":0},{"p":"38140.3","s":0},{"p":"38139.4","s":2175}],"b":[{"p":"38122.5","s":0},{"p":"38124.4","s":0},{"p":"38118.2","s":0},{"p":"38130.5","s":0},{"p":"38125.7","s":0},{"p":"38124.1","s":0},{"p":"38120.3","s":0},{"p":"38127","s":0},{"p":"38129.6","s":655},{"p":"38134.1","s":78334}],"s":"BTC_USDT","t":1701245736719,"u":53095260387}}
{"time":1701245736,"time_ms":1701245736752,"channel":"futures.order_book_update","event":"update","result":{"U":53095260388,"a":[{"p":"38147.8","s":0},{"p":"38134.2","s":99161},{"p":"38148","s":0},{"p":"38144","s":0},{"p":"38155.4","s":0},{"p":"38151.6","s":0},{"p":"38159.2","s":0},{"p":"38136","s":600},{"p":"38139.9","s":0}],"b":[{"p":"38134.1","s":105834},{"p":"38115","s":0},{"p":"38111.4","s":0}],"s":"BTC_USDT","t":1701245736741,"u":53095260415}}
{"time":1701245736,"time_ms":1701245736775,"channel":"futures.order_book_update","event":"update","result":{"U":53095260416,"a":[{"p":"38139.8","s":0},{"p":"38135.9","s":10887}],"b":[{"p":"38123.5","s":0},{"p":"38123.4","s":0}],"s":"BTC_USDT","t":1701245736762,"u":53095260422}}
{"time":1701245736,"time_ms":1701245736792,"channel":"futures.order_book_update","event":"update","result":{"U":53095260423,"a":[{"p":"38144.3","s":0},{"p":"38153","s":0},{"p":"38148.6","s":0}],"b":[{"p":"38125.1","s":0},{"p":"38134.1","s":78334},{"p":"38121.7","s":0},{"p":"38122.8","s":0},{"p":"38122.6","s":0},{"p":"38119.4","s":0}],"s":"BTC_USDT","t":1701245736781,"u":53095260440}}
{"time":1701245736,"time_ms":1701245736833,"channel":"futures.order_book_update","event":"update","result":{"U":53095260441,"a":[],"b":[{"p":"38043","s":0},{"p":"38065.4","s":0}],"s":"BTC_USDT","t":1701245736816,"u":53095260442}}
{"time":1701245736,"time_ms":1701245736872,"channel":"futures.order_book_update","event":"update","result":{"U":53095260443,"a":[{"p":"38139","s":2835},{"p":"38140.3","s":0}],"b":[],"s":"BTC_USDT","t":1701245736863,"u":53095260444}}
{"time":1701245736,"time_ms":1701245736891,"channel":"futures.order_book_update","event":"update","result":{"U":53095260445,"a":[{"p":"38139.5","s":0},{"p":"38140.9","s":0},{"p":"38141.8","s":0},{"p":"38138.9","s":2175}],"b":[{"p":"38126.6","s":131},{"p":"38126.7","s":1},{"p":"38126.9","s":15000},{"p":"38131.7","s":0},{"p":"38127","s":9009},{"p":"38130.9","s":0},{"p":"38130.1","s":0},{"p":"38129","s":0},{"p":"38118.7","s":0},{"p":"38122","s":0}],"s":"BTC_USDT","t":1701245736884,"u":53095260456}}
{"time":1701245736,"time_ms":1701245736913,"channel":"futures.order_book_update","event":"update","result":{"U":53095260457,"a":[{"p":"38137.6","s":2175},{"p":"38139.4","s":0},{"p":"38139.5","s":0}],"b":[{"p":"38124.4","s":0},{"p":"38122.1","s":0},{"p":"38117.2","s":0},{"p":"38121","s":0},{"p":"38132","s":100},{"p":"38127","s":9109}],"s":"BTC_USDT","t":1701245736893,"u":53095260468}}
{"time":1701245736,"time_ms":1701245736934,"channel":"futures.order_book_update","event":"update","result":{"U":53095260469,"a":[],"b":[{"p":"38129.7","s":2},{"p":"38131.2","s":2},{"p":"38126.7","s":0},{"p":"38126.9","s":0},{"p":"38126.6","s":0},{"p":"38130.4","s":133},{"p":"38128.5","s":2}],"s":"BTC_USDT","t":1701245736911,"u":53095260474}}
{"time":1701245736,"time_ms":1701245736991,"channel":"futures.order_book_update","event":"update","result":{"U":53095260475,"a":[],"b":[{"p":"38134.1","s":63334},{"p":"38127","s":9009},{"p":"38132","s":200}],"s":"BTC_USDT","t":1701245736982,"u":53095260479}}
{"time":1701245737,"time_ms":1701245737013,"channel":"futures.order_book_update","event":"update","result":{"U":53095260480,"a":[{"p":"38139.5","s":8357},{"p":"38139","s":2699},{"p":"38138.9","s":0},{"p":"38146.9","s":0}],"b":[{"p":"38116","s":0},{"p":"38121.3","s":0},{"p":"38123.7","s":0}],"s":"BTC_USDT","t":1701245737006,"u":53095260487}}
{"time":1701245737,"time_ms":1701245737035,"channel":"futures.order_book_update","event":"update","result":{"U":53095260488,"a":[{"p":"38135.8","s":2681},{"p":"38147.1","s":0},{"p":"38140.2","s":0},{"p":"38139.5","s":0},{"p":"38138.1","s":40},{"p":"38138.8","s":0},{"p":"38143","s":0},{"p":"38137.7","s":3236},{"p":"38140.6","s":0},{"p":"38153.3","s":0},{"p":"38142.1","s":0},{"p":"38139.4","s":0},{"p":"38143.8","s":0},{"p":"38137.4","s":2175},{"p":"38137.6","s":0},{"p":"38134.2","s":99161},{"p":"38139","s":2699},{"p":"38146.2","s":0}],"b":[{"p":"38126.6","s":131},{"p":"38127","s":9109},{"p":"38126.9","s":15000},{"p":"38124","s":0},{"p":"38114.5","s":0},{"p":"38116.4","s":0},{"p":"38126.2","s":2000},{"p":"38128.5","s":0},{"p":"38129.7","s":0},{"p":"38129.6","s":0},{"p":"38130.4","s":131},{"p":"38119.1","s":0},{"p":"38117.9","s":0},{"p":"38124.4","s":0},{"p":"38126","s":525},{"p":"38117.7","s":0},{"p":"38116.5","s":0},{"p":"38116.1","s":0},{"p":"38118.1","s":0},{"p":"38120.3","s":0},{"p":"38132","s":100},{"p":"38131.2","s":0},{"p":"38128","s":0},{"p":"38121.3","s":0},{"p":"38126.7","s":1},{"p":"38134.1","s":48334},{"p":"38120.7","s":0}],"s":"BTC_USDT","t":1701245737026,"u":53095260550}}
{"time":1701245737,"time_ms":1701245737054,"channel":"futures.order_book_update","event":"update","result":{"U":53095260551,"a":[{"p":"38138","s":3341},{"p":"38134.2","s":118736},{"p":"38146.5","s":0},{"p":"38140.9","s":0},{"p":"38136.3","s":2175},{"p":"38139.2","s":0},{"p":"38139.1","s":0},{"p":"38139.7","s":0},{"p":"38137.5","s":2536},{"p":"38139","s":524},{"p":"38142.5","s":0},{"p":"38142.4","s":0},{"p":"38139.5","s":0},{"p":"38137.4","s":2175}],"b":[{"p":"38127","s":9209},{"p":"38134.1","s":12462},{"p":"38132","s":0},{"p":"38123.5","s":0},{"p":"38122.8","s":0},{"p":"38119.4","s":0},{"p":"38125.9","s":0},{"p":"38117.4","s":0},{"p":"38120.2","s":0},{"p":"38119","s":0},{"p":"38128.9","s":655},{"p":"38115.4","s":0},{"p":"38121.7","s":0}],"s":"BTC_USDT","t":1701245737041,"u":53095260597}}
{"time":1701245737,"time_ms":1701245737072,"channel":"futures.order_book_update","event":"update","result":{"U":53095260598,"a":[{"p":"38139.1","s":11252},{"p":"38136.3","s":0},{"p":"38141.4","s":0},{"p":"38135.8","s":4856},{"p":"38134.2","s":124236}],"b":[{"p":"38127.6","s":2181},{"p":"38126","s":0},{"p":"38114.8","s":0},{"p":"38118.2","s":0},{"p":"38119.4","s":0},{"p":"38023.6","s":0},{"p":"38122.5","s":0},{"p":"38134.1","s":3662}],"s":"BTC_USDT","t":1701245737064,"u":53095260617}}
{"time":1701245737,"time_ms":1701245737094,"channel":"futures.order_book_update","event":"update","result":{"U":53095260618,"a":[{"p":"38136.3","s":2175},{"p":"38134.2","s":119608},{"p":"38135.8","s":2681},{"p":"38139.1","s":0},{"p":"38142.5","s":0}],"b":[{"p":"38115","s":0},{"p":"38108.4","s":0},{"p":"38120.5","s":0}],"s":"BTC_USDT","t":1701245737083,"u":53095260629}}
{"time":1701245737,"time_ms":1701245737113,"channel":"futures.order_book_update","event":"update","result":{"U":53095260630,"a":[{"p":"38142.3","s":0}],"b":[{"p":"38122.5","s":0},{"p":"38120.3","s":0},{"p":"38106.5","s":0},{"p":"38127","s":9009}],"s":"BTC_USDT","t":1701245737104,"u":53095260641}}
{"time":1701245737,"time_ms":1701245737154,"channel":"futures.order_book_update","event":"update","result":{"U":53095260642,"a":[{"p":"38134.2","s":120132},{"p":"38139.1","s":11252},{"p":"38139","s":0}],"b":[],"s":"BTC_USDT","t":1701245737134,"u":53095260648}}
{"time":1701245737,"time_ms":1701245737173,"channel":"futures.order_book_update","event":"update","result":{"U":53095260649,"a":[],"b":[{"p":"38128.6","s":2},{"p":"38130.1","s":2},{"p":"38129.3","s":11219},{"p":"38127.4","s":3613},{"p":"38126.2","s":0},{"p":"38126.6","s":0},{"p":"38022.6","s":0}],"s":"BTC_USDT","t":1701245737154,"u":53095260653}}
{"time":1701245737,"time_ms":1701245737192,"channel":"futures.order_book_update","event":"update","result":{"U":53095260654,"a":[],"b":[{"p":"38134.1","s":10653}],"s":"BTC_USDT","t":1701245737182,"u":53095260657}}
{"time":1701245737,"time_ms":1701245737213,"channel":"futures.order_book_update","event":"update","result":{"U":53095260658,"a":[],"b":[{"p":"38128.6","s":0},{"p":"38120.9","s":0},{"p":"38134.1","s":19653},{"p":"38127.4","s":3611},{"p":"38126.2","s":2000},{"p":"38129.3","s":11217},{"p":"38126.6","s":131},{"p":"38130.1","s":0}],"s":"BTC_USDT","t":1701245737204,"u":53095260666}}
{"time":1701245737,"time_ms":1701245737231,"channel":"futures.order_book_update","event":"update","result":{"U":53095260667,"a":[],"b":[{"p":"38128.6","s":2},{"p":"38129.3","s":11219},{"p":"38127.4","s":3613},{"p":"38130.1","s":2},{"p":"38126.2","s":0},{"p":"38126.6","s":0},{"p":"38106.5","s":0}],"s":"BTC_USDT","t":1701245737223,"u":53095260671}}
{"time":1701245737,"time_ms":1701245737253,"channel":"futures.order_book_update","event":"update","result":{"U":53095260672,"a":[],"b":[{"p":"38122","s":0},{"p":"38127","s":9109}],"s":"BTC_USDT","t":1701245737244,"u":53095260673}}
{"time":1701245737,"time_ms":1701245737275,"channel":"futures.order_book_update","event":"update","result":{"U":53095260674,"a":[],"b":[{"p":"38127","s":9209},{"p":"38121","s":0}],"s":"BTC_USDT","t":1701245737252,"u":53095260675}}
{"time":1701245737,"time_ms":1701245737292,"channel":"futures.order_book_update","event":"update","result":{"U":53095260676,"a":[],"b":[{"p":"38129.3","s":11217},{"p":"38126.2","s":2000},{"p":"38126.6","s":131},{"p":"38134.1","s":10653},{"p":"38127.4","s":3611},{"p":"38130.1","s":0},{"p":"38128.6","s":0}],"s":"BTC_USDT","t":1701245737282,"u":53095260680}}
{"time":1701245737,"time_ms":1701245737312,"channel":"futures.order_book_update","event":"update","result":{"U":53095260681,"a":[{"p":"38137.4","s":0},{"p":"38145.8","s":0},{"p":"38138.4","s":2},{"p":"38139.1","s":0},{"p":"38137.2","s":3932},{"p":"38138.5","s":0},{"p":"38134.2","s":136214},{"p":"38136.2","s":2175},{"p":"38138","s":0},{"p":"38142","s":0},{"p":"38146","s":0},{"p":"38140.6","s":0},{"p":"38140.8","s":0},{"p":"38136.5","s":3341},{"p":"38141.3","s":0}],"b":[{"p":"38126","s":0},{"p":"38118.2","s":0},{"p":"38119.4","s":0},{"p":"38114","s":0},{"p":"38107.3","s":0},{"p":"38111.5","s":0},{"p":"38134.1","s":5162},{"p":"38129.3","s":3642},{"p":"38128.9","s":0},{"p":"38122","s":0},{"p":"38119.5","s":0},{"p":"38119","s":0},{"p":"38115.4","s":0},{"p":"38126.2","s":2000},{"p":"38096.5","s":0},{"p":"38123.4","s":0},{"p":"38127","s":9009},{"p":"38128.1","s":655},{"p":"38114.8","s":0},{"p":"38126.8","s":0}],"s":"BTC_USDT","t":1701245737304,"u":53095260731}}
{"time":1701245737,"time_ms":1701245737331,"channel":"futures.order_book_update","event":"update","result":{"U":53095260732,"a":[{"p":"38134.2","s":136288},{"p":"38137.7","s":919},{"p":"38135.7","s":2293},{"p":"38138.4","s":0}],"b":[{"p":"38120.9","s":0},{"p":"38121","s":0},{"p":"38123","s":0},{"p":"38129.4","s":2190},{"p":"38126","s":525},{"p":"38134.1","s":3662},{"p":"38134","s":0},{"p":"38114.3","s":0},{"p":"38113.4","s":0},{"p":"38118.3","s":0}],"s":"BTC_USDT","t":1701245737320,"u":53095260753}}
{"time":1701245737,"time_ms":1701245737354,"channel":"futures.order_book_update","event":"update","result":{"U":53095260754,"a":[{"p":"38154","s":0},{"p":"38145.5","s":0},{"p":"38140.5","s":0},{"p":"38141.3","s":0},{"p":"38141.1","s":0},{"p":"38141.8","s":0},{"p":"38141.5","s":0}],"b":[{"p":"38108.3","s":0},{"p":"38102.7","s":0},{"p":"38125.5","s":0},{"p":"38120.5","s":0},{"p":"38124.8","s":0},{"p":"38128.1","s":0},{"p":"38125.1","s":0},{"p":"38118.7","s":0},{"p":"38101.5","s":0},{"p":"38114.1","s":0},{"p":"38125.9","s":3933},{"p":"38113.4","s":0},{"p":"38121.7","s":0},{"p":"38122.2","s":0},{"p":"38120.4","s":0},{"p":"38124.2","s":0},{"p":"38125.4","s":0},{"p":"38079.7","s":0},{"p":"38119","s":0}],"s":"BTC_USDT","t":1701245737343,"u":53095260805}}
{"time":1701245737,"time_ms":1701245737372,"channel":"futures.order_book_update","event":"update","result":{"U":53095260806,"a":[],"b":[{"p":"38134.1","s":3587},{"p":"38125.4","s":13563},{"p":"38129.3","s":0},{"p":"38127.4","s":0},{"p":"38117.1","s":0},{"p":"38112.5","s":0},{"p":"38117.7","s":0},{"p":"38125.6","s":3633},{"p":"38125.5","s":182},{"p":"38127.6","s":0}],"s":"BTC_USDT","t":1701245737359,"u":53095260814}}
{"time":1701245737,"time_ms":1701245737396,"channel":"futures.order_book_update","event":"update","result":{"U":53095260815,"a":[{"p":"38134.2","s":138463},{"p":"38138.4","s":2},{"p":"38136.3","s":0},{"p":"38162","s":0}],"b":[{"p":"38127.6","s":2183},{"p":"38129.4","s":0},{"p":"38119.6","s":0},{"p":"38125.4","s":13563},{"p":"38117.3","s":0},{"p":"38119.7","s":0},{"p":"38021.4","s":0},{"p":"38091.9","s":0},{"p":"38118.3","s":0},{"p":"38120.7","s":0},{"p":"38118","s":0}],"s":"BTC_USDT","t":1701245737385,"u":53095260850}}
{"time":1701245737,"time_ms":1701245737414,"channel":"futures.order_book_update","event":"update","result":{"U":53095260851,"a":[{"p":"38138.4","s":0},{"p":"38141.1","s":0},{"p":"38154.9","s":0},{"p":"38188","s":0},{"p":"38142.5","s":0},{"p":"38134.9","s":3932}],"b":[{"p":"38125.3","s":17824},{"p":"38126","s":0},{"p":"38119.6","s":0},{"p":"38112.6","s":0}],"s":"BTC_USDT","t":1701245737402,"u":53095260866}}
{"time":1701245737,"time_ms":1701245737432,"channel":"futures.order_book_update","event":"update","result":{"U":53095260867,"a":[{"p":"38171","s":0}],"b":[{"p":"38105.7","s":0},{"p":"38110.4","s":0}],"s":"BTC_USDT","t":1701245737421,"u":53095260873}}
{"time":1701245737,"time_ms":1701245737453,"channel":"futures.order_book_update","event":"update","result":{"U":53095260874,"a":[{"p":"38155.3","s":0}],"b":[{"p":"38125.4","s":9953},{"p":"38123.6","s":0},{"p":"38123","s":0}],"s":"BTC_USDT","t":1701245737432,"u":53095260877}}
{"time":1701245737,"time_ms":1701245737475,"channel":"futures.order_book_update","event":"update","result":{"U":53095260878,"a":[],"b":[{"p":"38020.4","s":0},{"p":"38108.9","s":0},{"p":"38114","s":0}],"s":"BTC_USDT","t":1701245737461,"u":53095260882}}
{"time":1701245737,"time_ms":1701245737492,"channel":"futures.order_book_update","event":"update","result":{"U":53095260883,"a":[{"p":"38144.7","s":0}],"b":[],"s":"BTC_USDT","t":1701245737482,"u":53095260887}}
{"time":1701245737,"time_ms":1701245737512,"channel":"futures.order_book_update","event":"update","result":{"U":53095260888,"a":[{"p":"38134.8","s":5516},{"p":"38138.4","s":2},{"p":"38136.2","s":0},{"p":"38136.5","s":0},{"p":"38138.3","s":95}],"b":[{"p":"38127.7","s":1221},{"p":"38125.3","s":0}],"s":"BTC_USDT","t":1701245737497,"u":53095260894}}
{"time":1701245737,"time_ms":1701245737533,"channel":"futures.order_book_update","event":"update","result":{"U":53095260895,"a":[{"p":"38140.1","s":0},{"p":"38135.6","s":5516},{"p":"38134.8","s":0},{"p":"38138.5","s":0}],"b":[{"p":"38127.7","s":566},{"p":"38117","s":0}],"s":"BTC_USDT","t":1701245737506,"u":53095260902}}
{"time":1701245737,"time_ms":1701245737572,"channel":"futures.order_book_update","event":"update","result":{"U":53095260903,"a":[],"b":[{"p":"38125.4","s":10553},{"p":"38026.5","s":0}],"s":"BTC_USDT","t":1701245737566,"u":53095260908}}
{"time":1701245737,"time_ms":1701245737592,"channel":"futures.order_book_update","event":"update","result":{"U":53095260909,"a":[],"b":[{"p":"38119.6","s":0}],"s":"BTC_USDT","t":1701245737582,"u":53095260911}}
{"time":1701245737,"time_ms":1701245737617,"channel":"futures.order_book_update","event":"update","result":{"U":53095260912,"a":[],"b":[{"p":"38125.9","s":1},{"p":"38123.6","s":0},{"p":"38112.5","s":0},{"p":"38027.2","s":0}],"s":"BTC_USDT","t":1701245737606,"u":53095260915}}
{"time":1701245737,"time_ms":1701245737673,"channel":"futures.order_book_update","event":"update","result":{"U":53095260916,"a":[{"p":"38138.4","s":0},{"p":"38138.3","s":0},{"p":"38135.6","s":3341},{"p":"38134.2","s":138255},{"p":"38135.5","s":2175},{"p":"38136.3","s":2175}],"b":[{"p":"38129","s":655},{"p":"38125.4","s":0}],"s":"BTC_USDT","t":1701245737666,"u":53095260928}}
{"time":1701245737,"time_ms":1701245737694,"channel":"futures.order_book_update","event":"update","result":{"U":53095260929,"a":[{"p":"38136.5","s":3341},{"p":"38135.6","s":0},{"p":"38141","s":0},{"p":"38138.3","s":0}],"b":[],"s":"BTC_USDT","t":1701245737683,"u":53095260932}}
{"time":1701245737,"time_ms":1701245737711,"channel":"futures.order_book_update","event":"update","result":{"U":53095260933,"a":[{"p":"38134.2","s":138779},{"p":"38138.3","s":95},{"p":"38136.4","s":0}],"b":[],"s":"BTC_USDT","t":1701245737697,"u":53095260934}}
{"time":1701245737,"time_ms":1701245737732,"channel":"futures.order_book_update","event":"update","result":{"U":53095260935,"a":[{"p":"38139","s":0}],"b":[],"s":"BTC_USDT","t":1701245737703,"u":53095260936}}
{"time":1701245737,"time_ms":1701245737753,"channel":"futures.order_book_update","event":"update","result":{"U":53095260937,"a":[{"p":"38145.8","s":0},{"p":"38179.6","s":0}],"b":[{"p":"38125.4","s":10553},{"p":"38129","s":0},{"p":"38117.9","s":0}],"s":"BTC_USDT","t":1701245737744,"u":53095260945}}
{"time":1701245737,"time_ms":1701245737773,"channel":"futures.order_book_update","event":"update","result":{"U":53095260946,"a":[],"b":[{"p":"38125.4","s":0},{"p":"38129.6","s":655}],"s":"BTC_USDT","t":1701245737749,"u":53095260951}}
{"time":1701245737,"time_ms":1701245737792,"channel":"futures.order_book_update","event":"update","result":{"U":53095260952,"a":[],"b":[{"p":"38129.7","s":398},{"p":"38125.5","s":0}],"s":"BTC_USDT","t":1701245737774,"u":53095260954}}
{"time":1701245737,"time_ms":1701245737853,"channel":"futures.order_book_update","event":"update","result":{"U":53095260955,"a":[{"p":"38135.2","s":788},{"p":"38135.3","s":525},{"p":"38135.4","s":1050},{"p":"38138.1","s":0},{"p":"38138.3","s":0},{"p":"38138.2","s":0}],"b":[],"s":"BTC_USDT","t":1701245737844,"u":53095260960}}
{"time":1701245737,"time_ms":1701245737871,"channel":"futures.order_book_update","event":"update","result":{"U":53095260961,"a":[],"b":[{"p":"38115","s":0}],"s":"BTC_USDT","t":1701245737845,"u":53095260962}}
{"time":1701245737,"time_ms":1701245737890,"channel":"futures.order_book_update","event":"update","result":{"U":53095260963,"a":[],"b":[{"p":"38071.6","s":0}],"s":"BTC_USDT","t":1701245737873,"u":53095260964}}
{"time":1701245737,"time_ms":1701245737914,"channel":"futures.order_book_update","event":"update","result":{"U":53095260965,"a":[{"p":"38135.2","s":1182}],"b":[{"p":"38122","s":0},{"p":"38127","s":9209},{"p":"38121","s":0}],"s":"BTC_USDT","t":1701245737902,"u":53095260969}}
{"time":1701245737,"time_ms":1701245737933,"channel":"futures.order_book_update","event":"update","result":{"U":53095260970,"a":[{"p":"38135.7","s":2818}],"b":[],"s":"BTC_USDT","t":1701245737924,"u":53095260970}}
{"time":1701245737,"time_ms":1701245737973,"channel":"futures.order_book_update","event":"update","result":{"U":53095260971,"a":[{"p":"38135.2","s":1576},{"p":"38135.5","s":2700}],"b":[],"s":"BTC_USDT","t":1701245737946,"u":53095260973}}
{"time":1701245738,"time_ms":1701245738014,"channel":"futures.order_book_update","event":"update","result":{"U":53095260974,"a":[{"p":"38145.2","s":0}],"b":[{"p":"38119.5","s":0},{"p":"38112.4","s":0}],"s":"BTC_USDT","t":1701245738005,"u":53095260979}}
{"time":1701245738,"time_ms":1701245738031,"channel":"futures.order_book_update","event":"update","result":{"U":53095260980,"a":[{"p":"38137","s":3341},{"p":"38136.5","s":0},{"p":"38138.1","s":0},{"p":"38139.7","s":0}],"b":[{"p":"38113","s":0},{"p":"38117.5","s":0}],"s":"BTC_USDT","t":1701245738022,"u":53095260985}}
{"time":1701245738,"time_ms":1701245738052,"channel":"futures.order_book_update","event":"update","result":{"U":53095260986,"a":[{"p":"38135.1","s":2175},{"p":"38135.5","s":525},{"p":"38135.8","s":4856},{"p":"38136.3","s":0},{"p":"38138.1","s":0}],"b":[{"p":"38116.7","s":0},{"p":"38113.5","s":0},{"p":"38117.4","s":0}],"s":"BTC_USDT","t":1701245738038,"u":53095260997}}
{"time":1701245738,"time_ms":1701245738113,"channel":"futures.order_book_update","event":"update","result":{"U":53095260998,"a":[{"p":"38165.6","s":0}],"b":[{"p":"38105.3","s":0},{"p":"38113.1","s":0}],"s":"BTC_USDT","t":1701245738096,"u":53095261005}}
{"time":1701245738,"time_ms":1701245738131,"channel":"futures.order_book_update","event":"update","result":{"U":53095261006,"a":[],"b":[{"p":"38117.7","s":0},{"p":"38118.7","s":0}],"s":"BTC_USDT","t":1701245738112,"u":53095261009}}
{"time":1701245738,"time_ms":1701245738171,"channel":"futures.order_book_update","event":"update","result":{"U":53095261010,"a":[{"p":"38147.3","s":0}],"b":[],"s":"BTC_USDT","t":1701245738158,"u":53095261012}}
{"time":1701245738,"time_ms":1701245738193,"channel":"futures.order_book_update","event":"update","result":{"U":53095261013,"a":[],"b":[{"p":"38113.2","s":0}],"s":"BTC_USDT","t":1701245738182,"u":53095261016}}
{"time":1701245738,"time_ms":1701245738211,"channel":"futures.order_book_update","event":"update","result":{"U":53095261017,"a":[{"p":"38171.5","s":0}],"b":[{"p":"38125.9","s":0},{"p":"38105.3","s":0},{"p":"38134.1","s":11238},{"p":"38127.6","s":2185},{"p":"38126.4","s":2},{"p":"38129.1","s":2},{"p":"38128.3","s":133},{"p":"38125.6","s":0}],"s":"BTC_USDT","t":1701245738201,"u":53095261032}}
{"time":1701245738,"time_ms":1701245738232,"channel":"futures.order_book_update","event":"update","result":{"U":53095261033,"a":[],"b":[{"p":"38127.6","s":2},{"p":"38117.5","s":0}],"s":"BTC_USDT","t":1701245738218,"u":53095261035}}
{"time":1701245738,"time_ms":1701245738252,"channel":"futures.order_book_update","event":"update","result":{"U":53095261036,"a":[],"b":[{"p":"38120.9","s":0}],"s":"BTC_USDT","t":1701245738225,"u":53095261038}}
{"time":1701245738,"time_ms":1701245738312,"channel":"futures.order_book_update","event":"update","result":{"U":53095261039,"a":[],"b":[{"p":"38113.3","s":0},{"p":"38109.5","s":0}],"s":"BTC_USDT","t":1701245738293,"u":53095261042}}
{"time":1701245738,"time_ms":1701245738431,"channel":"futures.order_book_update","event":"update","result":{"U":53095261043,"a":[{"p":"38138.1","s":40},{"p":"38135.3","s":2700},{"p":"38136.9","s":3341},{"p":"38139.4","s":0},{"p":"38137.6","s":0},{"p":"38136.5","s":0},{"p":"38135.8","s":2681},{"p":"38135.7","s":4993},{"p":"38135.1","s":0},{"p":"38137","s":0},{"p":"38138.2","s":0},{"p":"38154.8","s":0}],"b":[{"p":"38118.8","s":0},{"p":"38117.2","s":0},{"p":"38118.2","s":0},{"p":"38114.3","s":0},{"p":"38115.1","s":0},{"p":"38117.9","s":0}],"s":"BTC_USDT","t":1701245738424,"u":53095261072}}
{"time":1701245738,"time_ms":1701245738453,"channel":"futures.order_book_update","event":"update","result":{"U":53095261073,"a":[{"p":"38136.5","s":2175},{"p":"38135.7","s":2818},{"p":"38138.1","s":0}],"b":[{"p":"38129.3","s":3642},{"p":"38126.2","s":0}],"s":"BTC_USDT","t":1701245738442,"u":53095261077}}
{"time":1701245738,"time_ms":1701245738474,"channel":"futures.order_book_update","event":"update","result":{"U":53095261078,"a":[{"p":"38135","s":2175},{"p":"38135.8","s":4856},{"p":"38135.3","s":525},{"p":"38136.5","s":0},{"p":"38138.1","s":0}],"b":[{"p":"38129.7","s":2535},{"p":"38107.3","s":0}],"s":"BTC_USDT","t":1701245738462,"u":53095261083}}
{"time":1701245738,"time_ms":1701245738512,"channel":"futures.order_book_update","event":"update","result":{"U":53095261084,"a":[],"b":[{"p":"38115.9","s":0}],"s":"BTC_USDT","t":1701245738492,"u":53095261084}}
{"time":1701245738,"time_ms":1701245738553,"channel":"futures.order_book_update","event":"update","result":{"U":53095261085,"a":[{"p":"38136.5","s":2175},{"p":"38135.8","s":2681},{"p":"38137.9","s":0}],"b":[],"s":"BTC_USDT","t":1701245738522,"u":53095261087}}
{"time":1701245738,"time_ms":1701245738592,"channel":"futures.order_book_update","event":"update","result":{"U":53095261088,"a":[{"p":"38137.9","s":525},{"p":"38136.5","s":0},{"p":"38167.5","s":0},{"p":"38135.7","s":4993}],"b":[],"s":"BTC_USDT","t":1701245738580,"u":53095261092}}
{"time":1701245738,"time_ms":1701245738612,"channel":"futures.order_book_update","event":"update","result":{"U":53095261093,"a":[{"p":"38167.5","s":0}],"b":[],"s":"BTC_USDT","t":1701245738592,"u":53095261094}}
{"time":1701245738,"time_ms":1701245738631,"channel":"futures.order_book_update","event":"update","result":{"U":53095261095,"a":[{"p":"38167.5","s":0}],"b":[],"s":"BTC_USDT","t":1701245738626,"u":53095261098}}
{"time":1701245738,"time_ms":1701245738692,"channel":"futures.order_book_update","event":"update","result":{"U":53095261099,"a":[{"p":"38167.5","s":0}],"b":[],"s":"BTC_USDT","t":1701245738680,"u":53095261101}}
{"time":1701245738,"time_ms":1701245738732,"channel":"futures.order_book_update","event":"update","result":{"U":53095261102,"a":[{"p":"38167.5","s":0}],"b":[],"s":"BTC_USDT","t":1701245738722,"u":53095261103}}
{"time":1701245738,"time_ms":1701245738774,"channel":"futures.order_book_update","event":"update","result":{"U":53095261104,"a":[{"p":"38167.5","s":0},{"p":"38143.1","s":0}],"b":[{"p":"38134.1","s":3087},{"p":"38120.9","s":0},{"p":"38117.3","s":0},{"p":"38118.2","s":0},{"p":"38114.3","s":0},{"p":"38118.1","s":0}],"s":"BTC_USDT","t":1701245738766,"u":53095261123}}
{"time":1701245738,"time_ms":1701245738794,"channel":"futures.order_book_update","event":"update","result":{"U":53095261124,"a":[{"p":"38134.2","s":157279},{"p":"38167.4","s":0}],"b":[],"s":"BTC_USDT","t":1701245738778,"u":53095261129}}
{"time":1701245738,"time_ms":1701245738813,"channel":"futures.order_book_update","event":"update","result":{"U":53095261130,"a":[{"p":"38134.2","s":138779},{"p":"38167.4","s":0}],"b":[],"s":"BTC_USDT","t":1701245738792,"u":53095261132}}
{"time":1701245738,"time_ms":1701245738853,"channel":"futures.order_book_update","event":"update","result":{"U":53095261133,"a":[{"p":"38167.6","s":0}],"b":[{"p":"38134","s":11500},{"p":"38126.4","s":0}],"s":"BTC_USDT","t":1701245738828,"u":53095261136}}
{"time":1701245738,"time_ms":1701245738872,"channel":"futures.order_book_update","event":"update","result":{"U":53095261137,"a":[{"p":"38154.5","s":0},{"p":"38139.2","s":0},{"p":"38158.3","s":0},{"p":"38167.6","s":0},{"p":"38150.7","s":0},{"p":"38146.9","s":0}],"b":[{"p":"38109.7","s":0},{"p":"38114","s":0},{"p":"38125.4","s":0},{"p":"38126.4","s":2},{"p":"38134","s":0},{"p":"38105.8","s":0}],"s":"BTC_USDT","t":1701245738862,"u":53095261151}}
{"time":1701245738,"time_ms":1701245738893,"channel":"futures.order_book_update","event":"update","result":{"U":53095261152,"a":[{"p":"38167.5","s":0}],"b":[{"p":"38106.1","s":0}],"s":"BTC_USDT","t":1701245738885,"u":53095261156}}
{"time":1701245738,"time_ms":1701245738911,"channel":"futures.order_book_update","event":"update","result":{"U":53095261157,"a":[{"p":"38167.5","s":0}],"b":[{"p":"38106.1","s":0}],"s":"BTC_USDT","t":1701245738895,"u":53095261161}}
{"time":1701245738,"time_ms":1701245738933,"channel":"futures.order_book_update","event":"update","result":{"U":53095261162,"a":[{"p":"38167.5","s":0}],"b":[],"s":"BTC_USDT","t":1701245738918,"u":53095261164}}
{"time":1701245738,"time_ms":1701245738953,"channel":"futures.order_book_update","event":"update","result":{"U":53095261165,"a":[{"p":"38167.5","s":0}],"b":[{"p":"38119.7","s":0},{"p":"38125.4","s":0}],"s":"BTC_USDT","t":1701245738941,"u":53095261173}}
{"time":1701245738,"time_ms":1701245738992,"channel":"futures.order_book_update","event":"update","result":{"U":53095261174,"a":[{"p":"38167.5","s":0}],"b":[],"s":"BTC_USDT","t":1701245738968,"u":53095261179}}
{"time":1701245739,"time_ms":1701245739012,"channel":"futures.order_book_update","event":"update","result":{"U":53095261180,"a":[{"p":"38137.9","s":0},{"p":"38167.5","s":0},{"p":"38138.4","s":0},{"p":"38136.1","s":2}],"b":[{"p":"38114.1","s":0},{"p":"38125.3","s":0},{"p":"38114","s":0},{"p":"38128.3","s":131},{"p":"38126.2","s":2000},{"p":"38125","s":0},{"p":"38126.4","s":0},{"p":"38114.2","s":0},{"p":"38115.6","s":0},{"p":"38123","s":0},{"p":"38125.9","s":1},{"p":"38129.1","s":0},{"p":"38113.9","s":0},{"p":"38134.1","s":967},{"p":"38115.9","s":0}],"s":"BTC_USDT","t":1701245738997,"u":53095261206}}
{"time":1701245739,"time_ms":1701245739032,"channel":"futures.order_book_update","event":"update","result":{"U":53095261207,"a":[{"p":"38136.5","s":3341},{"p":"38137.8","s":0},{"p":"38167.5","s":0},{"p":"38150.6","s":0},{"p":"38139.7","s":0},{"p":"38188","s":0},{"p":"38141","s":0},{"p":"38134.8","s":2175},{"p":"38135.1","s":2175},{"p":"38137.9","s":0},{"p":"38135.7","s":525},{"p":"38137.5","s":2011},{"p":"38136.9","s":0},{"p":"38152.5","s":0},{"p":"38134.2","s":166279},{"p":"38134.9","s":6242},{"p":"38135","s":0},{"p":"38143.2","s":0},{"p":"38140.8","s":0},{"p":"38140.9","s":0},{"p":"38150.5","s":0}],"b":[{"p":"38127.6","s":0},{"p":"38116.4","s":0},{"p":"38125.5","s":0},{"p":"38115","s":0},{"p":"38117.4","s":0},{"p":"38105.7","s":0},{"p":"38125.6","s":3633},{"p":"38125.4","s":13564},{"p":"38129.3","s":0},{"p":"38116.7","s":0},{"p":"38120.4","s":0},{"p":"38114.3","s":0}],"s":"BTC_USDT","t":1701245739022,"u":53095261254}}
{"time":1701245739,"time_ms":1701245739052,"channel":"futures.order_book_update","event":"update","result":{"U":53095261255,"a":[{"p":"38137.8","s":9946},{"p":"38135.1","s":0},{"p":"38135.4","s":3225}],"b":[{"p":"38129.7","s":398},{"p":"38127.8","s":2187},{"p":"38125.4","s":0}],"s":"BTC_USDT","t":1701245739035,"u":53095261258}}
{"time":1701245739,"time_ms":1701245739072,"channel":"futures.order_book_update","event":"update","result":{"U":53095261259,"a":[{"p":"38167.5","s":0},{"p":"38144","s":0}],"b":[{"p":"38105.8","s":0},{"p":"38090","s":0}],"s":"BTC_USDT","t":1701245739060,"u":53095261269}}
{"time":1701245739,"time_ms":1701245739092,"channel":"futures.order_book_update","event":"update","result":{"U":53095261270,"a":[{"p":"38134.9","s":3932},{"p":"38135.1","s":2342},{"p":"38137.8","s":0},{"p":"38135.4","s":1050}],"b":[{"p":"38116.1","s":0},{"p":"38125.4","s":0},{"p":"38123.2","s":0},{"p":"38117.2","s":0},{"p":"38117.7","s":0}],"s":"BTC_USDT","t":1701245739082,"u":53095261283}}
{"time":1701245739,"time_ms":1701245739113,"channel":"futures.order_book_update","event":"update","result":{"U":53095261284,"a":[{"p":"38137.7","s":0},{"p":"38167.5","s":0},{"p":"38152.4","s":0},{"p":"38135.6","s":2175}],"b":[{"p":"38114.7","s":0}],"s":"BTC_USDT","t":1701245739094,"u":53095261288}}
{"time":1701245739,"time_ms":1701245739136,"channel":"futures.order_book_update","event":"update","result":{"U":53095261289,"a":[{"p":"38137.7","s":919},{"p":"38136.1","s":0},{"p":"38134.2","s":138779}],"b":[],"s":"BTC_USDT","t":1701245739119,"u":53095261292}}
{"time":1701245739,"time_ms":1701245739153,"channel":"futures.order_book_update","event":"update","result":{"U":53095261293,"a":[{"p":"38136.1","s":2},{"p":"38137.7","s":0},{"p":"38167.5","s":0}],"b":[],"s":"BTC_USDT","t":1701245739142,"u":53095261298}}
{"time":1701245739,"time_ms":1701245739213,"channel":"futures.order_book_update","event":"update","result":{"U":53095261299,"a":[{"p":"38167.5","s":0},{"p":"38149.9","s":0}],"b":[],"s":"BTC_USDT","t":1701245739195,"u":53095261302}}
{"time":1701245739,"time_ms":1701245739232,"channel":"futures.order_book_update","event":"update","result":{"U":53095261303,"a":[{"p":"38167.5","s":0}],"b":[],"s":"BTC_USDT","t":1701245739222,"u":53095261305}}
{"time":1701245739,"time_ms":1701245739253,"channel":"futures.order_book_update","event":"update","result":{"U":53095261306,"a":[{"p":"38167.5","s":0}],"b":[{"p":"38113.8","s":0}],"s":"BTC_USDT","t":1701245739238,"u":53095261311}}
{"time":1701245739,"time_ms":1701245739273,"channel":"futures.order_book_update","event":"update","result":{"U":53095261312,"a":[{"p":"38167.5","s":0}],"b":[],"s":"BTC_USDT","t":1701245739258,"u":53095261314}}
{"time":1701245739,"time_ms":1701245739315,"channel":"futures.order_book_update","event":"update","result":{"U":53095261315,"a":[{"p":"38167.5","s":0}],"b":[],"s":"BTC_USDT","t":1701245739291,"u":53095261315}}
{"time":1701245739,"time_ms":1701245739413,"channel":"futures.order_book_update","event":"update","result":{"U":53095261316,"a":[{"p":"38167.5","s":0}],"b":[],"s":"BTC_USDT","t":1701245739406,"u":53095261320}}
{"time":1701245739,"time_ms":1701245739453,"channel":"futures.order_book_update","event":"update","result":{"U":53095261321,"a":[{"p":"38167.5","s":0}],"b":[{"p":"38117","s":0},{"p":"38116.9","s":0},{"p":"38115","s":0},{"p":"38125.4","s":9595},{"p":"38129.7","s":0}],"s":"BTC_USDT","t":1701245739443,"u":53095261327}}
{"time":1701245739,"time_ms":1701245739474,"channel":"futures.order_book_update","event":"update","result":{"U":53095261328,"a":[{"p":"38166.2","s":0},{"p":"38142","s":0},{"p":"38134.2","s":179683},{"p":"38145.3","s":0},{"p":"38147","s":0}],"b":[{"p":"38122.3","s":0},{"p":"38134.1","s":500},{"p":"38125.4","s":5984},{"p":"38118.7","s":0},{"p":"38119.8","s":0},{"p":"38120.8","s":0},{"p":"38113.6","s":0},{"p":"38125","s":1695},{"p":"38120","s":0},{"p":"38117.5","s":0},{"p":"38120.3","s":0},{"p":"38124.3","s":0},{"p":"38125.3","s":9960},{"p":"38129.6","s":0},{"p":"38123.4","s":0},{"p":"38124","s":0},{"p":"38112","s":0},{"p":"38127","s":200},{"p":"38127.8","s":0},{"p":"38127.6","s":0},{"p":"38121.5","s":0}],"s":"BTC_USDT","t":1701245739462,"u":53095261358}}
{"time":1701245739,"time_ms":1701245739497,"channel":"futures.order_book_update","event":"update","result":{"U":53095261359,"a":[{"p":"38136.5","s":0},{"p":"38148.2","s":0},{"p":"38137.8","s":0},{"p":"38137.7","s":919},{"p":"38137","s":3341},{"p":"38134.2","s":143895},{"p":"38135.9","s":0}],"b":[{"p":"38125","s":0},{"p":"38117.2","s":0},{"p":"38096.8","s":0},{"p":"38122.9","s":0},{"p":"38113.9","s":0},{"p":"38120.7","s":0},{"p":"38125.3","s":6815},{"p":"38128.7","s":655},{"p":"38105.1","s":0},{"p":"38111.4","s":0}],"s":"BTC_USDT","t":1701245739490,"u":53095261385}}
{"time":1701245739,"time_ms":1701245739513,"channel":"futures.order_book_update","event":"update","result":{"U":53095261386,"a":[{"p":"38166.6","s":0},{"p":"38139.5","s":0},{"p":"38143.5","s":0}],"b":[{"p":"38117.9","s":0},{"p":"38098.7","s":0},{"p":"38118.1","s":0}],"s":"BTC_USDT","t":1701245739497,"u":53095261397}}
{"time":1701245739,"time_ms":1701245739531,"channel":"futures.order_book_update","event":"update","result":{"U":53095261398,"a":[{"p":"38166.6","s":0}],"b":[{"p":"38134.1","s":9300}],"s":"BTC_USDT","t":1701245739521,"u":53095261406}}
{"time":1701245739,"time_ms":1701245739552,"channel":"futures.order_book_update","event":"update","result":{"U":53095261407,"a":[{"p":"38135.9","s":15969},{"p":"38137.7","s":0},{"p":"38151.5","s":0}],"b":[{"p":"38117.6","s":0},{"p":"38115","s":0},{"p":"38116.6","s":0},{"p":"38127.8","s":2527},{"p":"38125.4","s":4089},{"p":"38127","s":9209},{"p":"38125.3","s":0},{"p":"38119","s":0}],"s":"BTC_USDT","t":1701245739546,"u":53095261421}}
{"time":1701245739,"time_ms":1701245739572,"channel":"futures.order_book_update","event":"update","result":{"U":53095261422,"a":[{"p":"38144","s":0},{"p":"38166.8","s":0},{"p":"38140","s":0}],"b":[{"p":"38117","s":0},{"p":"38121","s":0},{"p":"38109","s":0}],"s":"BTC_USDT","t":1701245739561,"u":53095261432}}
{"time":1701245739,"time_ms":1701245739591,"channel":"futures.order_book_update","event":"update","result":{"U":53095261433,"a":[{"p":"38166.9","s":0}],"b":[],"s":"BTC_USDT","t":1701245739576,"u":53095261435}}
{"time":1701245739,"time_ms":1701245739613,"channel":"futures.order_book_update","event":"update","result":{"U":53095261436,"a":[{"p":"38166.8","s":0},{"p":"38166.9","s":0}],"b":[{"p":"38118.1","s":0},{"p":"38118.7","s":0},{"p":"38119.1","s":0}],"s":"BTC_USDT","t":1701245739603,"u":53095261445}}
{"time":1701245739,"time_ms":1701245739672,"channel":"futures.order_book_update","event":"update","result":{"U":53095261446,"a":[{"p":"38142.7","s":0},{"p":"38166.7","s":0}],"b":[{"p":"38125.3","s":6815},{"p":"38128.7","s":0}],"s":"BTC_USDT","t":1701245739659,"u":53095261454}}
{"time":1701245739,"time_ms":1701245739732,"channel":"futures.order_book_update","event":"update","result":{"U":53095261455,"a":[{"p":"38137.7","s":919},{"p":"38135.5","s":2886},{"p":"38135.1","s":0},{"p":"38166.7","s":0}],"b":[{"p":"38090.5","s":0}],"s":"BTC_USDT","t":1701245739707,"u":53095261462}}
{"time":1701245739,"time_ms":1701245739752,"channel":"futures.order_book_update","event":"update","result":{"U":53095261463,"a":[{"p":"38166.7","s":0}],"b":[{"p":"38115","s":0}],"s":"BTC_USDT","t":1701245739746,"u":53095261466}}
{"time":1701245739,"time_ms":1701245739773,"channel":"futures.order_book_update","event":"update","result":{"U":53095261467,"a":[{"p":"38166.7","s":0}],"b":[],"s":"BTC_USDT","t":1701245739765,"u":53095261474}}
{"time":1701245739,"time_ms":1701245739812,"channel":"futures.order_book_update","event":"update","result":{"U":53095261475,"a":[{"p":"38166.7","s":0}],"b":[{"p":"38101.8","s":0}],"s":"BTC_USDT","t":1701245739793,"u":53095261481}}
{"time":1701245739,"time_ms":1701245739834,"channel":"futures.order_book_update","event":"update","result":{"U":53095261482,"a":[{"p":"38167.1","s":0}],"b":[],"s":"BTC_USDT","t":1701245739810,"u":53095261483}}
{"time":1701245739,"time_ms":1701245739852,"channel":"futures.order_book_update","event":"update","result":{"U":53095261484,"a":[{"p":"38134.2","s":116395},{"p":"38167.1","s":0}],"b":[],"s":"BTC_USDT","t":1701245739834,"u":53095261488}}
{"time":1701245739,"time_ms":1701245739871,"channel":"futures.order_book_update","event":"update","result":{"U":53095261489,"a":[{"p":"38167.1","s":0}],"b":[{"p":"38129.3","s":3638},{"p":"38125.3","s":0}],"s":"BTC_USDT","t":1701245739861,"u":53095261493}}
{"time":1701245739,"time_ms":1701245739897,"channel":"futures.order_book_update","event":"update","result":{"U":53095261494,"a":[],"b":[{"p":"38127.8","s":0},{"p":"38125.4","s":4089},{"p":"38129.4","s":2186}],"s":"BTC_USDT","t":1701245739883,"u":53095261497}}
{"time":1701245739,"time_ms":1701245739912,"channel":"futures.order_book_update","event":"update","result":{"U":53095261498,"a":[{"p":"38167.1","s":0}],"b":[{"p":"38134","s":11500},{"p":"38125.4","s":0},{"p":"38118.7","s":0},{"p":"38119.7","s":0},{"p":"38117.8","s":0}],"s":"BTC_USDT","t":1701245739903,"u":53095261506}}
{"time":1701245739,"time_ms":1701245739932,"channel":"futures.order_book_update","event":"update","result":{"U":53095261507,"a":[{"p":"38167.1","s":0}],"b":[{"p":"38125.4","s":4689},{"p":"38134","s":0}],"s":"BTC_USDT","t":1701245739925,"u":53095261511}}
{"time":1701245739,"time_ms":1701245739973,"channel":"futures.order_book_update","event":"update","result":{"U":53095261512,"a":[{"p":"38166.9","s":0},{"p":"38139","s":0},{"p":"38137.9","s":0},{"p":"38137.4","s":3341},{"p":"38137","s":0},{"p":"38135.6","s":0},{"p":"38137.8","s":0},{"p":"38136.5","s":4567},{"p":"38135.5","s":525}],"b":[{"p":"38127.8","s":655},{"p":"38125.4","s":0},{"p":"38114.3","s":0},{"p":"38120.3","s":0},{"p":"38118.2","s":0},{"p":"38119.4","s":0},{"p":"38117.6","s":0}],"s":"BTC_USDT","t":1701245739967,"u":53095261531}}
{"time":1701245739,"time_ms":1701245739991,"channel":"futures.order_book_update","event":"update","result":{"U":53095261532,"a":[{"p":"38137.8","s":9946},{"p":"38135.2","s":3751},{"p":"38134.8","s":0}],"b":[],"s":"BTC_USDT","t":1701245739977,"u":53095261535}}
{"time":1701245740,"time_ms":1701245740012,"channel":"futures.order_book_update","event":"update","result":{"U":53095261536,"a":[{"p":"38166.9","s":0}],"b":[{"p":"38125.4","s":0}],"s":"BTC_USDT","t":1701245739998,"u":53095261540}}
{"time":1701245740,"time_ms":1701245740032,"channel":"futures.order_book_update","event":"update","result":{"U":53095261541,"a":[{"p":"38136.5","s":0},{"p":"38137.8","s":9946},{"p":"38143.2","s":0},{"p":"38135.1","s":0},{"p":"38139.7","s":0},{"p":"38135.6","s":2175},{"p":"38137","s":3341},{"p":"38137.9","s":0},{"p":"38136.4","s":0},{"p":"38135.2","s":3751},{"p":"38135.7","s":2831},{"p":"38137.4","s":0}],"b":[{"p":"38113.7","s":0},{"p":"38120","s":0},{"p":"38115.3","s":0},{"p":"38118.8","s":0},{"p":"38112.8","s":0},{"p":"38119.6","s":0},{"p":"38118.7","s":0},{"p":"38118.1","s":0},{"p":"38119.7","s":0},{"p":"38119.8","s":0},{"p":"38121.3","s":0}],"s":"BTC_USDT","t":1701245740017,"u":53095261577}}
{"time":1701245740,"time_ms":1701245740054,"channel":"futures.order_book_update","event":"update","result":{"U":53095261578,"a":[{"p":"38135.2","s":1576},{"p":"38134.2","s":143895},{"p":"38166.9","s":0},{"p":"38166.4","s":0}],"b":[{"p":"38134.1","s":8975},{"p":"38114.1","s":0},{"p":"38113.4","s":0}],"s":"BTC_USDT","t":1701245740042,"u":53095261592}}
{"time":1701245740,"time_ms":1701245740073,"channel":"futures.order_book_update","event":"update","result":{"U":53095261593,"a":[{"p":"38135.2","s":3751},{"p":"38137","s":0},{"p":"38137.8","s":9946},{"p":"38134.8","s":0},{"p":"38139.4","s":0},{"p":"38136.4","s":2175},{"p":"38137.3","s":3341},{"p":"38135.6","s":0},{"p":"38137.9","s":0},{"p":"38155.1","s":0}],"b":[{"p":"38089.2","s":0},{"p":"38074.2","s":0}],"s":"BTC_USDT","t":1701245740062,"u":53095261610}}
{"time":1701245740,"time_ms":1701245740091,"channel":"futures.order_book_update","event":"update","result":{"U":53095261611,"a":[{"p":"38166.7","s":0},{"p":"38166.6","s":0}],"b":[],"s":"BTC_USDT","t":1701245740076,"u":53095261614}}
{"time":1701245740,"time_ms":1701245740114,"channel":"futures.order_book_update","event":"update","result":{"U":53095261615,"a":[{"p":"38137.9","s":525},{"p":"38135.7","s":5006},{"p":"38136.4","s":0}],"b":[{"p":"38115.1","s":0},{"p":"38119.2","s":0},{"p":"38125.4","s":0},{"p":"38119.6","s":0},{"p":"38113.4","s":0}],"s":"BTC_USDT","t":1701245740103,"u":53095261626}}
{"time":1701245740,"time_ms":1701245740132,"channel":"futures.order_book_update","event":"update","result":{"U":53095261627,"a":[{"p":"38138.1","s":40},{"p":"38136.6","s":11205},{"p":"38137.3","s":0},{"p":"38164.6","s":0},{"p":"38139.7","s":0}],"b":[{"p":"38118.7","s":0}],"s":"BTC_USDT","t":1701245740121,"u":53095261639}}
{"time":1701245740,"time_ms":1701245740152,"channel":"futures.order_book_update","event":"update","result":{"U":53095261640,"a":[{"p":"38142.1","s":0}],"b":[{"p":"38125.4","s":4089},{"p":"38125.9","s":0}],"s":"BTC_USDT","t":1701245740135,"u":53095261645}}
{"time":1701245740,"time_ms":1701245740172,"channel":"futures.order_book_update","event":"update","result":{"U":53095261646,"a":[],"b":[{"p":"38111.5","s":0},{"p":"38120.9","s":0},{"p":"38123.5","s":0},{"p":"38118.1","s":0},{"p":"38119.2","s":0},{"p":"38119.5","s":0}],"s":"BTC_USDT","t":1701245740158,"u":53095261656}}
{"time":1701245740,"time_ms":1701245740212,"channel":"futures.order_book_update","event":"update","result":{"U":53095261657,"a":[],"b":[{"p":"38118.2","s":0}],"s":"BTC_USDT","t":1701245740201,"u":53095261658}}
{"time":1701245740,"time_ms":1701245740231,"channel":"futures.order_book_update","event":"update","result":{"U":53095261659,"a":[],"b":[{"p":"38125.3","s":6815},{"p":"38129.3","s":0}],"s":"BTC_USDT","t":1701245740223,"u":53095261659}}
{"time":1701245740,"time_ms":1701245740254,"channel":"futures.order_book_update","event":"update","result":{"U":53095261660,"a":[],"b":[{"p":"38115","s":0},{"p":"38125","s":0},{"p":"38127.9","s":2917},{"p":"38129.4","s":0}],"s":"BTC_USDT","t":1701245740246,"u":53095261665}}
{"time":1701245740,"time_ms":1701245740312,"channel":"futures.order_book_update","event":"update","result":{"U":53095261666,"a":[],"b":[{"p":"38115.9","s":0}],"s":"BTC_USDT","t":1701245740298,"u":53095261669}}
{"time":1701245740,"time_ms":1701245740333,"channel":"futures.order_book_update","event":"update","result":{"U":53095261670,"a":[{"p":"38135.6","s":525},{"p":"38135.7","s":5531},{"p":"38138.1","s":0}],"b":[],"s":"BTC_USDT","t":1701245740324,"u":53095261671}}
{"time":1701245740,"time_ms":1701245740592,"channel":"futures.order_book_update","event":"update","result":{"U":53095261672,"a":[{"p":"38134.2","s":116395}],"b":[{"p":"38125.2","s":0}],"s":"BTC_USDT","t":1701245740583,"u":53095261678}}
{"time":1701245740,"time_ms":1701245740613,"channel":"futures.order_book_update","event":"update","result":{"U":53095261679,"a":[{"p":"38136.6","s":7864},{"p":"38137","s":3341},{"p":"38137.9","s":0}],"b":[{"p":"38037.8","s":0},{"p":"38023.7","s":0}],"s":"BTC_USDT","t":1701245740603,"u":53095261683}}
{"time":1701245740,"time_ms":1701245740635,"channel":"futures.order_book_update","event":"update","result":{"U":53095261684,"a":[],"b":[{"p":"38050.2","s":0},{"p":"38044","s":0}],"s":"BTC_USDT","t":1701245740626,"u":53095261693}}
{"time":1701245740,"time_ms":1701245740653,"channel":"futures.order_book_update","event":"update","result":{"U":53095261694,"a":[],"b":[{"p":"38020.6","s":0}],"s":"BTC_USDT","t":1701245740641,"u":53095261694}}
{"time":1701245740,"time_ms":1701245740675,"channel":"futures.order_book_update","event":"update","result":{"U":53095261695,"a":[],"b":[{"p":"38036","s":0},{"p":"38042.8","s":0},{"p":"38049.6","s":0}],"s":"BTC_USDT","t":1701245740655,"u":53095261697}}
{"time":1701245740,"time_ms":1701245740692,"channel":"futures.order_book_update","event":"update","result":{"U":53095261698,"a":[{"p":"38136.5","s":2175},{"p":"38137.4","s":3341},{"p":"38135.7","s":3356},{"p":"38137.8","s":0},{"p":"38137","s":0},{"p":"38137.9","s":0}],"b":[{"p":"38119.7","s":0},{"p":"38118.2","s":0},{"p":"38125.4","s":4689},{"p":"38125.2","s":0},{"p":"38112.4","s":0},{"p":"38117.6","s":0},{"p":"38122.5","s":0},{"p":"38124.4","s":0},{"p":"38114.3","s":0}],"s":"BTC_USDT","t":1701245740684,"u":53095261715}}
{"time":1701245740,"time_ms":1701245740713,"channel":"futures.order_book_update","event":"update","result":{"U":53095261716,"a":[{"p":"38137.8","s":9946},{"p":"38135.3","s":2700},{"p":"38136.5","s":0}],"b":[{"p":"38119.6","s":0},{"p":"38125.4","s":4089},{"p":"38115.4","s":0}],"s":"BTC_USDT","t":1701245740694,"u":53095261722}}
{"time":1701245740,"time_ms":1701245740732,"channel":"futures.order_book_update","event":"update","result":{"U":53095261723,"a":[],"b":[{"p":"38118.7","s":0}],"s":"BTC_USDT","t":1701245740707,"u":53095261724}}
{"time":1701245740,"time_ms":1701245740752,"channel":"futures.order_book_update","event":"update","result":{"U":53095261725,"a":[],"b":[{"p":"38125.4","s":4091}],"s":"BTC_USDT","t":1701245740725,"u":53095261729}}
{"time":1701245740,"time_ms":1701245740771,"channel":"futures.order_book_update","event":"update","result":{"U":53095261730,"a":[{"p":"38139","s":0}],"b":[],"s":"BTC_USDT","t":1701245740759,"u":53095261731}}
{"time":1701245740,"time_ms":1701245740793,"channel":"futures.order_book_update","event":"update","result":{"U":53095261732,"a":[{"p":"38136.5","s":2175},{"p":"38135.3","s":525},{"p":"38137.8","s":0}],"b":[{"p":"38134.1","s":15020}],"s":"BTC_USDT","t":1701245740784,"u":53095261737}}
{"time":1701245740,"time_ms":1701245740812,"channel":"futures.order_book_update","event":"update","result":{"U":53095261738,"a":[{"p":"38135.7","s":1050},{"p":"38136.5","s":4563}],"b":[{"p":"38125.3","s":0},{"p":"38119.1","s":0},{"p":"38120.3","s":0},{"p":"38129.3","s":3638}],"s":"BTC_USDT","t":1701245740797,"u":53095261743}}
{"time":1701245740,"time_ms":1701245740832,"channel":"futures.order_book_update","event":"update","result":{"U":53095261744,"a":[],"b":[{"p":"38127.9","s":0},{"p":"38125.4","s":4091},{"p":"38129.4","s":2188}],"s":"BTC_USDT","t":1701245740813,"u":53095261745}}
{"time":1701245740,"time_ms":1701245740852,"channel":"futures.order_book_update","event":"update","result":{"U":53095261746,"a":[{"p":"38144","s":0},{"p":"38137.8","s":9946},{"p":"38136.1","s":0},{"p":"38140","s":0}],"b":[{"p":"38119.5","s":0},{"p":"38123.5","s":0}],"s":"BTC_USDT","t":1701245740844,"u":53095261755}}
{"time":1701245740,"time_ms":1701245740871,"channel":"futures.order_book_update","event":"update","result":{"U":53095261756,"a":[],"b":[{"p":"38117.8","s":0}],"s":"BTC_USDT","t":1701245740847,"u":53095261756}}
{"time":1701245740,"time_ms":1701245740892,"channel":"futures.order_book_update","event":"update","result":{"U":53095261757,"a":[{"p":"38136","s":602}],"b":[],"s":"BTC_USDT","t":1701245740873,"u":53095261757}}
{"time":1701245740,"time_ms":1701245740972,"channel":"futures.order_book_update","event":"update","result":{"U":53095261758,"a":[],"b":[{"p":"38120.2","s":0}],"s":"BTC_USDT","t":1701245740963,"u":53095261759}}
{"time":1701245741,"time_ms":1701245741013,"channel":"futures.order_book_update","event":"update","result":{"U":53095261760,"a":[{"p":"38137.9","s":0},{"p":"38135.1","s":2175},{"p":"38135.8","s":4978},{"p":"38136.4","s":2175},{"p":"38137.8","s":0},{"p":"38136.5","s":0}],"b":[{"p":"38118","s":0},{"p":"38122.7","s":0},{"p":"38125.4","s":4089},{"p":"38118.7","s":0},{"p":"38112.9","s":0},{"p":"38121.3","s":0},{"p":"38123.7","s":0}],"s":"BTC_USDT","t":1701245741006,"u":53095261776}}
{"time":1701245741,"time_ms":1701245741034,"channel":"futures.order_book_update","event":"update","result":{"U":53095261777,"a":[{"p":"38137.8","s":9946},{"p":"38135.2","s":1576},{"p":"38135.8","s":7153},{"p":"38136.4","s":0}],"b":[{"p":"38114.3","s":0},{"p":"38124.6","s":0}],"s":"BTC_USDT","t":1701245741024,"u":53095261786}}
{"time":1701245741,"time_ms":1701245741052,"channel":"futures.order_book_update","event":"update","result":{"U":53095261787,"a":[{"p":"38134.8","s":2175},{"p":"38135.1","s":0},{"p":"38137.4","s":0},{"p":"38143.7","s":0},{"p":"38134.2","s":116602},{"p":"38137.1","s":3924},{"p":"38137.9","s":525},{"p":"38136","s":600}],"b":[{"p":"38119.5","s":0},{"p":"38115.1","s":0},{"p":"38113.4","s":0},{"p":"38121.2","s":0}],"s":"BTC_USDT","t":1701245741046,"u":53095261803}}
{"time":1701245741,"time_ms":1701245741072,"channel":"futures.order_book_update","event":"update","result":{"U":53095261804,"a":[{"p":"38136","s":602},{"p":"38139.7","s":0}],"b":[],"s":"BTC_USDT","t":1701245741059,"u":53095261806}}
{"time":1701245741,"time_ms":1701245741111,"channel":"futures.order_book_update","event":"update","result":{"U":53095261807,"a":[{"p":"38137.9","s":0},{"p":"38135.8","s":4978},{"p":"38136.5","s":3341},{"p":"38135.3","s":2700},{"p":"38137.1","s":583}],"b":[{"p":"38118.1","s":0},{"p":"38119.4","s":0},{"p":"38119.1","s":0},{"p":"38114.8","s":0}],"s":"BTC_USDT","t":1701245741096,"u":53095261818}}
{"time":1701245741,"time_ms":1701245741132,"channel":"futures.order_book_update","event":"update","result":{"U":53095261819,"a":[{"p":"38135.8","s":2681},{"p":"38137.8","s":0},{"p":"38135.1","s":2300}],"b":[{"p":"38120.9","s":0},{"p":"38117.9","s":0},{"p":"38118.7","s":0},{"p":"38119","s":0}],"s":"BTC_USDT","t":1701245741108,"u":53095261828}}
{"time":1701245741,"time_ms":1701245741152,"channel":"futures.order_book_update","event":"update","result":{"U":53095261829,"a":[],"b":[{"p":"38129.3","s":0},{"p":"38125.3","s":6817},{"p":"38134.1","s":8975}],"s":"BTC_USDT","t":1701245741144,"u":53095261831}}
{"time":1701245741,"time_ms":1701245741172,"channel":"futures.order_book_update","event":"update","result":{"U":53095261832,"a":[{"p":"38168.5","s":0},{"p":"38152","s":0},{"p":"38132.9","s":0},{"p":"38136.1","s":2116},{"p":"38134.2","s":101871},{"p":"38149.3","s":0},{"p":"38137.5","s":0},{"p":"38137.8","s":0},{"p":"38139","s":0},{"p":"38135.9","s":10889},{"p":"38134.1","s":13404},{"p":"38134.8","s":0},{"p":"38135.7","s":4391},{"p":"38137.2","s":0},{"p":"38141.7","s":0},{"p":"38136.5","s":0},{"p":"38137.7","s":0},{"p":"38143.5","s":0},{"p":"38139.5","s":0},{"p":"38130.5","s":57776},{"p":"38134","s":6765},{"p":"38132.8","s":13263}],"b":[{"p":"38127.9","s":2179},{"p":"38134.1","s":0},{"p":"38124.5","s":0},{"p":"38124","s":0},{"p":"38133.9","s":0},{"p":"38116.8","s":0},{"p":"38120","s":0},{"p":"38124.9","s":2621},{"p":"38132.8","s":0},{"p":"38117","s":0},{"p":"38118.7","s":0},{"p":"38115.9","s":0},{"p":"38130.4","s":10329},{"p":"38125.5","s":8916},{"p":"38125","s":1695},{"p":"38129.4","s":0},{"p":"38113","s":0},{"p":"38125.3","s":6817},{"p":"38111.5","s":0}],"s":"BTC_USDT","t":1701245741162,"u":53095261907}}
{"time":1701245741,"time_ms":1701245741193,"channel":"futures.order_book_update","event":"update","result":{"U":53095261908,"a":[{"p":"38130.5","s":147025},{"p":"38147.6","s":0},{"p":"38134.2","s":68918},{"p":"38137.1","s":0},{"p":"38140","s":0},{"p":"38132.2","s":0},{"p":"38130.7","s":0},{"p":"38162.7","s":0},{"p":"38145.7","s":0},{"p":"38130.6","s":559},{"p":"38153.3","s":0},{"p":"38148","s":0},{"p":"38132.9","s":320},{"p":"38145.5","s":0},{"p":"38136.6","s":0},{"p":"38173.8","s":0},{"p":"38155","s":0},{"p":"38135.7","s":1050},{"p":"38134","s":11590},{"p":"38134.1","s":40904},{"p":"38132.8","s":0},{"p":"38138.1","s":0},{"p":"38143.8","s":0},{"p":"38150.5","s":0},{"p":"38164.3","s":0},{"p":"38134.7","s":2175},{"p":"38136.1","s":0},{"p":"38153.5","s":0},{"p":"38154.2","s":0},{"p":"38141.5","s":0},{"p":"38138.4","s":0},{"p":"38134.4","s":40},{"p":"38136","s":2},{"p":"38136.7","s":0},{"p":"38141.9","s":0},{"p":"38159.7","s":0},{"p":"38133.9","s":45761}],"b":[{"p":"38125.6","s":11198},{"p":"38130.2","s":0},{"p":"38122.6","s":0},{"p":"38126.5","s":26},{"p":"38126","s":100},{"p":"38116.6","s":0},{"p":"38123.6","s":0},{"p":"37981.5","s":0},{"p":"38124","s":8916},{"p":"38127.5","s":0},{"p":"38128.3","s":0},{"p":"38000.6","s":0},{"p":"38109.2","s":0},{"p":"38113.5","s":0},{"p":"38127","s":9009},{"p":"38124.5","s":2},{"p":"38125.5","s":0},{"p":"38125.4","s":0},{"p":"38121.5","s":0},{"p":"38124.1","s":5352},{"p":"38130.4","s":48874}],"s":"BTC_USDT","t":1701245741184,"u":53095262243}}
{"time":1701245741,"time_ms":1701245741211,"channel":"futures.order_book_update","event":"update","result":{"U":53095262244,"a":[{"p":"38135.3","s":525},{"p":"38172.5","s":0},{"p":"38147","s":0},{"p":"38134.1","s":13404},{"p":"38134.2","s":40844},{"p":"38138.9","s":0},{"p":"38136.6","s":0},{"p":"38153.4","s":0},{"p":"38143.5","s":0},{"p":"38130.5","s":148025},{"p":"38134.7","s":0},{"p":"38138","s":0},{"p":"38146","s":0},{"p":"38147.2","s":0},{"p":"38131.9","s":655},{"p":"38134","s":8635},{"p":"38137.1","s":0},{"p":"38139.5","s":0},{"p":"38136.5","s":0},{"p":"38149.1","s":0},{"p":"38171.1","s":0},{"p":"38136","s":2},{"p":"38151.5","s":0}],"b":[{"p":"38114.3","s":0},{"p":"38119","s":0},{"p":"38123.7","s":524},{"p":"38127.9","s":0},{"p":"38117","s":0},{"p":"38123.9","s":3633},{"p":"38121","s":0},{"p":"38126","s":0},{"p":"38128.4","s":0},{"p":"38120","s":0},{"p":"38123.6","s":182},{"p":"38124.5","s":8918},{"p":"38124","s":0},{"p":"38123.8","s":2},{"p":"38117.6","s":0}],"s":"BTC_USDT","t":1701245741203,"u":53095262317}}
{"time":1701245741,"time_ms":1701245741232,"channel":"futures.order_book_update","event":"update","result":{"U":53095262318,"a":[{"p":"38135.7","s":4656},{"p":"38133.9","s":24512},{"p":"38134","s":450},{"p":"38169.6","s":0},{"p":"38136.1","s":0},{"p":"38168.3","s":0}],"b":[{"p":"38125.1","s":5355},{"p":"38124.1","s":0},{"p":"38123.6","s":182}],"s":"BTC_USDT","t":1701245741223,"u":53095262342}}
{"time":1701245741,"time_ms":1701245741253,"channel":"futures.order_book_update","event":"update","result":{"U":53095262343,"a":[{"p":"38167.3","s":0},{"p":"38135.6","s":4131},{"p":"38136.3","s":3638},{"p":"38136.1","s":2116},{"p":"38132.9","s":0},{"p":"38134","s":0}],"b":[{"p":"38123.6","s":0},{"p":"38120.5","s":0},{"p":"38119.7","s":0},{"p":"38124.5","s":2},{"p":"38130.4","s":49474},{"p":"38124","s":8916}],"s":"BTC_USDT","t":1701245741247,"u":53095262365}}
{"time":1701245741,"time_ms":1701245741271,"channel":"futures.order_book_update","event":"update","result":{"U":53095262366,"a":[{"p":"38136.6","s":7864},{"p":"38137.6","s":0},{"p":"38138","s":0},{"p":"38157.1","s":0},{"p":"38152.9","s":0},{"p":"38142","s":0},{"p":"38135.7","s":6966},{"p":"38135.1","s":0},{"p":"38140.3","s":0},{"p":"38137","s":0}],"b":[{"p":"38130.4","s":48874},{"p":"38125.1","s":0},{"p":"38114.1","s":0},{"p":"38123.6","s":0},{"p":"38124.1","s":5356}],"s":"BTC_USDT","t":1701245741261,"u":53095262388}}
{"time":1701245741,"time_ms":1701245741293,"channel":"futures.order_book_update","event":"update","result":{"U":53095262389,"a":[{"p":"38141.3","s":0},{"p":"38170.7","s":0},{"p":"38139","s":0},{"p":"38170.6","s":0}],"b":[],"s":"BTC_USDT","t":1701245741276,"u":53095262394}}
{"time":1701245741,"time_ms":1701245741313,"channel":"futures.order_book_update","event":"update","result":{"U":53095262395,"a":[{"p":"38138.5","s":0},{"p":"38150","s":0},{"p":"38135.3","s":2700},{"p":"38142.5","s":0},{"p":"38136.7","s":0},{"p":"38143.3","s":0},{"p":"38141.5","s":0},{"p":"38130.5","s":147762},{"p":"38135.9","s":4727},{"p":"38139","s":0},{"p":"38137.6","s":0},{"p":"38144.8","s":0}],"b":[{"p":"38118","s":0}],"s":"BTC_USDT","t":1701245741299,"u":53095262415}}
{"time":1701245741,"time_ms":1701245741371,"channel":"futures.order_book_update","event":"update","result":{"U":53095262416,"a":[{"p":"38130.5","s":145125},{"p":"38173.8","s":0}],"b":[],"s":"BTC_USDT","t":1701245741355,"u":53095262418}}
{"time":1701245741,"time_ms":1701245741393,"channel":"futures.order_book_update","event":"update","result":{"U":53095262419,"a":[{"p":"38130.5","s":156379}],"b":[],"s":"BTC_USDT","t":1701245741377,"u":53095262422}}
{"time":1701245741,"time_ms":1701245741411,"channel":"futures.order_book_update","event":"update","result":{"U":53095262423,"a":[],"b":[{"p":"38113.7","s":0}],"s":"BTC_USDT","t":1701245741396,"u":53095262424}}
{"time":1701245741,"time_ms":1701245741465,"channel":"futures.order_book_update","event":"update","result":{"U":53095262425,"a":[{"p":"38136.7","s":3606},{"p":"38136","s":0}],"b":[],"s":"BTC_USDT","t":1701245741431,"u":53095262425}}
{"time":1701245741,"time_ms":1701245741494,"channel":"futures.order_book_update","event":"update","result":{"U":53095262426,"a":[{"p":"38135.9","s":4729},{"p":"38141","s":0}],"b":[{"p":"38114.6","s":0}],"s":"BTC_USDT","t":1701245741486,"u":53095262428}}
{"time":1701245741,"time_ms":1701245741574,"channel":"futures.order_book_update","event":"update","result":{"U":53095262429,"a":[],"b":[{"p":"38123.6","s":182},{"p":"38125.3","s":6815},{"p":"38123.3","s":550},{"p":"38123.8","s":0},{"p":"38124.5","s":0},{"p":"38122.6","s":0}],"s":"BTC_USDT","t":1701245741547,"u":53095262432}}
{"time":1701245741,"time_ms":1701245741592,"channel":"futures.order_book_update","event":"update","result":{"U":53095262433,"a":[{"p":"38135.9","s":4727}],"b":[{"p":"38125.2","s":2},{"p":"38124.4","s":2},{"p":"38123.7","s":526},{"p":"38123.6","s":0},{"p":"38123.3","s":0}],"s":"BTC_USDT","t":1701245741576,"u":53095262439}}
{"time":1701245741,"time_ms":1701245741612,"channel":"futures.order_book_update","event":"update","result":{"U":53095262440,"a":[],"b":[{"p":"38126.9","s":15002},{"p":"38123.7","s":524},{"p":"38124.4","s":0},{"p":"38125.2","s":0},{"p":"38122.5","s":0},{"p":"38125.8","s":2},{"p":"38127.7","s":568},{"p":"38128.4","s":2}],"s":"BTC_USDT","t":1701245741603,"u":53095262447}}
{"time":1701245741,"time_ms":1701245741692,"channel":"futures.order_book_update","event":"update","result":{"U":53095262448,"a":[{"p":"38140.7","s":0}],"b":[],"s":"BTC_USDT","t":1701245741677,"u":53095262448}}
{"time":1701245741,"time_ms":1701245741711,"channel":"futures.order_book_update","event":"update","result":{"U":53095262449,"a":[{"p":"38130.5","s":153742}],"b":[],"s":"BTC_USDT","t":1701245741693,"u":53095262449}}
{"time":1701245741,"time_ms":1701245741753,"channel":"futures.order_book_update","event":"update","result":{"U":53095262450,"a":[{"p":"38130.5","s":126242}],"b":[{"p":"38118","s":0}],"s":"BTC_USDT","t":1701245741743,"u":53095262452}}
{"time":1701245741,"time_ms":1701245741772,"channel":"futures.order_book_update","event":"update","result":{"U":53095262453,"a":[{"p":"38137.6","s":0},{"p":"38136","s":2175},{"p":"38136.7","s":0}],"b":[{"p":"38117","s":0}],"s":"BTC_USDT","t":1701245741758,"u":53095262456}}
{"time":1701245741,"time_ms":1701245741893,"channel":"futures.order_book_update","event":"update","result":{"U":53095262457,"a":[{"p":"38140.4","s":0}],"b":[],"s":"BTC_USDT","t":1701245741880,"u":53095262459}}
{"time":1701245741,"time_ms":1701245741992,"channel":"futures.order_book_update","event":"update","result":{"U":53095262460,"a":[{"p":"38136.6","s":0},{"p":"38136.3","s":0},{"p":"38136.1","s":0},{"p":"38131.1","s":525},{"p":"38131","s":525},{"p":"38130.9","s":1050}],"b":[],"s":"BTC_USDT","t":1701245741977,"u":53095262464}}
{"time":1701245742,"time_ms":1701245742032,"channel":"futures.order_book_update","event":"update","result":{"U":53095262465,"a":[{"p":"38135.2","s":3751},{"p":"38135.7","s":7997},{"p":"38135.3","s":525},{"p":"38136","s":0},{"p":"38143.2","s":0},{"p":"38137.1","s":0},{"p":"38135.1","s":2309}],"b":[{"p":"38112.4","s":0},{"p":"38113","s":0}],"s":"BTC_USDT","t":1701245742012,"u":53095262476}}
{"time":1701245742,"time_ms":1701245742053,"channel":"futures.order_book_update","event":"update","result":{"U":53095262477,"a":[{"p":"38136","s":0}],"b":[{"p":"38118.2","s":0},{"p":"38122.7","s":0}],"s":"BTC_USDT","t":1701245742029,"u":53095262484}}
{"time":1701245742,"time_ms":1701245742072,"channel":"futures.order_book_update","event":"update","result":{"U":53095262485,"a":[{"p":"38139.1","s":0}],"b":[{"p":"38125.8","s":0},{"p":"38123.3","s":0},{"p":"38118.3","s":0},{"p":"38124.4","s":2},{"p":"38125.2","s":2},{"p":"38128.4","s":0},{"p":"38123.6","s":0},{"p":"38120.5","s":0},{"p":"38127.7","s":566},{"p":"38126.9","s":15000}],"s":"BTC_USDT","t":1701245742058,"u":53095262497}}
{"time":1701245742,"time_ms":1701245742093,"channel":"futures.order_book_update","event":"update","result":{"U":53095262498,"a":[{"p":"38140.1","s":0}],"b":[{"p":"38118","s":0}],"s":"BTC_USDT","t":1701245742078,"u":53095262500}}
{"time":1701245742,"time_ms":1701245742133,"channel":"futures.order_book_update","event":"update","result":{"U":53095262501,"a":[{"p":"38136.2","s":0},{"p":"38142.7","s":0},{"p":"38135.7","s":6831},{"p":"38135.8","s":2683},{"p":"38136.1","s":2116},{"p":"38135.1","s":0},{"p":"38135.2","s":1576},{"p":"38135.5","s":2837},{"p":"38130.5","s":127434},{"p":"38139.7","s":0}],"b":[{"p":"38118.1","s":0},{"p":"38116.9","s":0},{"p":"38112.5","s":0},{"p":"38120.3","s":0}],"s":"BTC_USDT","t":1701245742116,"u":53095262523}}
{"time":1701245742,"time_ms":1701245742152,"channel":"futures.order_book_update","event":"update","result":{"U":53095262524,"a":[],"b":[{"p":"38118.7","s":0},{"p":"38113","s":0}],"s":"BTC_USDT","t":1701245742140,"u":53095262527}}
{"time":1701245742,"time_ms":1701245742172,"channel":"futures.order_book_update","event":"update","result":{"U":53095262528,"a":[{"p":"38135.3","s":2700},{"p":"38135.7","s":4656}],"b":[{"p":"38117.6","s":0},{"p":"38120.9","s":0}],"s":"BTC_USDT","t":1701245742148,"u":53095262533}}
{"time":1701245742,"time_ms":1701245742191,"channel":"futures.order_book_update","event":"update","result":{"U":53095262534,"a":[{"p":"38130.9","s":1650}],"b":[],"s":"BTC_USDT","t":1701245742181,"u":53095262539}}
{"time":1701245742,"time_ms":1701245742214,"channel":"futures.order_book_update","event":"update","result":{"U":53095262540,"a":[],"b":[{"p":"38130.4","s":49374}],"s":"BTC_USDT","t":1701245742196,"u":53095262542}}
{"time":1701245742,"time_ms":1701245742230,"channel":"futures.order_book_update","event":"update","result":{"U":53095262543,"a":[{"p":"38136","s":2175},{"p":"38136.1","s":0},{"p":"38136.5","s":0},{"p":"38140.2","s":0},{"p":"38136.2","s":0},{"p":"38135.3","s":525}],"b":[{"p":"38130.4","s":49474},{"p":"38119.7","s":0},{"p":"38118.2","s":0},{"p":"38117.2","s":0}],"s":"BTC_USDT","t":1701245742217,"u":53095262559}}
{"time":1701245742,"time_ms":1701245742251,"channel":"futures.order_book_update","event":"update","result":{"U":53095262560,"a":[],"b":[{"p":"38130.4","s":48874}],"s":"BTC_USDT","t":1701245742242,"u":53095262561}}
{"time":1701245742,"time_ms":1701245742276,"channel":"futures.order_book_update","event":"update","result":{"U":53095262562,"a":[{"p":"38143.5","s":0},{"p":"38139.5","s":0}],"b":[],"s":"BTC_USDT","t":1701245742259,"u":53095262565}}
{"time":1701245742,"time_ms":1701245742294,"channel":"futures.order_book_update","event":"update","result":{"U":53095262566,"a":[{"p":"38143","s":0},{"p":"38139.8","s":0},{"p":"38139","s":0}],"b":[{"p":"38124.5","s":8916},{"p":"38130.4","s":63874},{"p":"38124","s":0},{"p":"38120","s":0},{"p":"38123.6","s":0}],"s":"BTC_USDT","t":1701245742278,"u":53095262576}}
{"time":1701245742,"time_ms":1701245742312,"channel":"futures.order_book_update","event":"update","result":{"U":53095262577,"a":[],"b":[{"p":"38119.7","s":0},{"p":"38119.2","s":0},{"p":"38123.6","s":0},{"p":"38130.4","s":64474},{"p":"38125.1","s":5350},{"p":"38124.1","s":0}],"s":"BTC_USDT","t":1701245742301,"u":53095262582}}
{"time":1701245742,"time_ms":1701245742331,"channel":"futures.order_book_update","event":"update","result":{"U":53095262583,"a":[],"b":[{"p":"38128","s":100},{"p":"38123.7","s":0},{"p":"38117.9","s":0},{"p":"38123","s":0}],"s":"BTC_USDT","t":1701245742314,"u":53095262587}}
{"time":1701245742,"time_ms":1701245742374,"channel":"futures.order_book_update","event":"update","result":{"U":53095262588,"a":[],"b":[{"p":"38118.7","s":0}],"s":"BTC_USDT","t":1701245742355,"u":53095262589}}
{"time":1701245742,"time_ms":1701245742393,"channel":"futures.order_book_update","event":"update","result":{"U":53095262590,"a":[],"b":[{"p":"38115.4","s":0}],"s":"BTC_USDT","t":1701245742378,"u":53095262591}}
{"time":1701245742,"time_ms":1701245742435,"channel":"futures.order_book_update","event":"update","result":{"U":53095262592,"a":[{"p":"38135.8","s":2681}],"b":[],"s":"BTC_USDT","t":1701245742422,"u":53095262592}}
{"time":1701245742,"time_ms":1701245742474,"channel":"futures.order_book_update","event":"update","result":{"U":53095262593,"a":[],"b":[{"p":"38130.3","s":2},{"p":"38130.4","s":64476},{"p":"38128.4","s":2},{"p":"38124.4","s":0},{"p":"38123.7","s":0},{"p":"38122.5","s":0},{"p":"38123.6","s":0},{"p":"38129.6","s":2},{"p":"38125.2","s":0},{"p":"38123.9","s":0}],"s":"BTC_USDT","t":1701245742449,"u":53095262603}}
{"time":1701245742,"time_ms":1701245742497,"channel":"futures.order_book_update","event":"update","result":{"U":53095262604,"a":[{"p":"38139.5","s":0}],"b":[],"s":"BTC_USDT","t":1701245742477,"u":53095262604}}
{"time":1701245742,"time_ms":1701245742511,"channel":"futures.order_book_update","event":"update","result":{"U":53095262605,"a":[],"b":[{"p":"38124","s":0}],"s":"BTC_USDT","t":1701245742504,"u":53095262605}}
{"time":1701245742,"time_ms":1701245742532,"channel":"futures.order_book_update","event":"update","result":{"U":53095262606,"a":[],"b":[{"p":"38130.4","s":65066},{"p":"38124","s":100},{"p":"38127.7","s":0},{"p":"38123","s":0}],"s":"BTC_USDT","t":1701245742505,"u":53095262608}}
{"time":1701245742,"time_ms":1701245742693,"channel":"futures.order_book_update","event":"update","result":{"U":53095262609,"a":[{"p":"38139.2","s":0}],"b":[],"s":"BTC_USDT","t":1701245742680,"u":53095262610}}
{"time":1701245742,"time_ms":1701245742773,"channel":"futures.order_book_update","event":"update","result":{"U":53095262611,"a":[{"p":"38135.8","s":2683},{"p":"38141.8","s":0}],"b":[{"p":"38129.6","s":0},{"p":"38128.4","s":0},{"p":"38123.7","s":524},{"p":"38125.1","s":5352},{"p":"38130.4","s":65064},{"p":"38124.3","s":2},{"p":"38123.9","s":3633},{"p":"38130.3","s":0}],"s":"BTC_USDT","t":1701245742753,"u":53095262620}}
{"time":1701245742,"time_ms":1701245742813,"channel":"futures.order_book_update","event":"update","result":{"U":53095262621,"a":[],"b":[{"p":"38123.6","s":184},{"p":"38124","s":0}],"s":"BTC_USDT","t":1701245742791,"u":53095262624}}
{"time":1701245742,"time_ms":1701245742832,"channel":"futures.order_book_update","event":"update","result":{"U":53095262625,"a":[{"p":"38146.6","s":0}],"b":[],"s":"BTC_USDT","t":1701245742817,"u":53095262627}}
{"time":1701245742,"time_ms":1701245742875,"channel":"futures.order_book_update","event":"update","result":{"U":53095262628,"a":[{"p":"38151.5","s":0},{"p":"38138.5","s":0},{"p":"38142.5","s":0}],"b":[{"p":"38130.4","s":64464},{"p":"38118.7","s":0},{"p":"38116.5","s":0}],"s":"BTC_USDT","t":1701245742865,"u":53095262638}}
{"time":1701245742,"time_ms":1701245742893,"channel":"futures.order_book_update","event":"update","result":{"U":53095262639,"a":[{"p":"38138.9","s":0}],"b":[{"p":"38117.9","s":0},{"p":"38116.2","s":0}],"s":"BTC_USDT","t":1701245742878,"u":53095262642}}
{"time":1701245742,"time_ms":1701245742913,"channel":"futures.order_book_update","event":"update","result":{"U":53095262643,"a":[{"p":"38137.1","s":0}],"b":[],"s":"BTC_USDT","t":1701245742887,"u":53095262644}}
{"time":1701245742,"time_ms":1701245742932,"channel":"futures.order_book_update","event":"update","result":{"U":53095262645,"a":[{"p":"38135.8","s":6024},{"p":"38140.7","s":0},{"p":"38137.1","s":0}],"b":[{"p":"38118.1","s":0},{"p":"38117.2","s":0}],"s":"BTC_USDT","t":1701245742916,"u":53095262653}}
{"time":1701245742,"time_ms":1701245742974,"channel":"futures.order_book_update","event":"update","result":{"U":53095262654,"a":[{"p":"38130.5","s":127434},{"p":"38134.8","s":2175},{"p":"38136","s":0},{"p":"38139.9","s":0},{"p":"38136.1","s":0}],"b":[{"p":"38115","s":0},{"p":"38112.6","s":0},{"p":"38124.5","s":0},{"p":"38119.7","s":0},{"p":"38130.4","s":64464},{"p":"38117.6","s":0},{"p":"38112.8","s":0},{"p":"38112","s":0},{"p":"38123.3","s":550},{"p":"38120.5","s":0},{"p":"38118.2","s":0}],"s":"BTC_USDT","t":1701245742965,"u":53095262679}}
{"time":1701245742,"time_ms":1701245742992,"channel":"futures.order_book_update","event":"update","result":{"U":53095262680,"a":[],"b":[{"p":"38123.3","s":550},{"p":"38125.4","s":4092},{"p":"38125.1","s":2},{"p":"38128","s":0},{"p":"38038.7","s":0},{"p":"38036.8","s":0},{"p":"38120.7","s":0},{"p":"38059.7","s":0}],"s":"BTC_USDT","t":1701245742986,"u":53095262693}}
{"time":1701245743,"time_ms":1701245743011,"channel":"futures.order_book_update","event":"update","result":{"U":53095262694,"a":[],"b":[{"p":"38123.1","s":3637},{"p":"38123","s":200},{"p":"38130.4","s":36964},{"p":"38125.1","s":0},{"p":"38124.3","s":0},{"p":"38122.4","s":0},{"p":"38123.6","s":182}],"s":"BTC_USDT","t":1701245742998,"u":53095262698}}
{"time":1701245743,"time_ms":1701245743031,"channel":"futures.order_book_update","event":"update","result":{"U":53095262699,"a":[{"p":"38134.7","s":2360},{"p":"38133.8","s":2175},{"p":"38135.8","s":0},{"p":"38135.9","s":0},{"p":"38139.4","s":0},{"p":"38135.1","s":5516},{"p":"38135.5","s":525},{"p":"38134.8","s":0},{"p":"38143.2","s":0},{"p":"38136.2","s":0}],"b":[{"p":"38125.1","s":2},{"p":"38123.6","s":184},{"p":"38116.9","s":0},{"p":"38117.6","s":0},{"p":"38124.3","s":2},{"p":"38130.4","s":21964},{"p":"38123","s":0},{"p":"38123.1","s":0},{"p":"38112.1","s":0},{"p":"38116.1","s":0},{"p":"38111.7","s":0},{"p":"38116.4","s":0}],"s":"BTC_USDT","t":1701245743021,"u":53095262727}}
{"time":1701245743,"time_ms":1701245743051,"channel":"futures.order_book_update","event":"update","result":{"U":53095262728,"a":[],"b":[{"p":"38123.6","s":182},{"p":"38125.1","s":0},{"p":"38124.3","s":0},{"p":"38122.4","s":0},{"p":"38112","s":0},{"p":"38123","s":200},{"p":"38123.1","s":3637}],"s":"BTC_USDT","t":1701245743036,"u":53095262733}}
{"time":1701245743,"time_ms":1701245743073,"channel":"futures.order_book_update","event":"update","result":{"U":53095262734,"a":[{"p":"38135.2","s":3751},{"p":"38135.1","s":3341},{"p":"38138","s":0},{"p":"38142","s":0}],"b":[{"p":"38123","s":0},{"p":"38124.5","s":8916}],"s":"BTC_USDT","t":1701245743064,"u":53095262745}}
{"time":1701245743,"time_ms":1701245743093,"channel":"futures.order_book_update","event":"update","result":{"U":53095262746,"a":[{"p":"38130.5","s":127697},{"p":"38138.6","s":0},{"p":"38141","s":0}],"b":[],"s":"BTC_USDT","t":1701245743080,"u":53095262750}}
{"time":1701245743,"time_ms":1701245743113,"channel":"futures.order_book_update","event":"update","result":{"U":53095262751,"a":[],"b":[{"p":"38130","s":12500},{"p":"38123.1","s":0},{"p":"38117.9","s":0},{"p":"38112.3","s":0}],"s":"BTC_USDT","t":1701245743102,"u":53095262756}}
{"time":1701245743,"time_ms":1701245743172,"channel":"futures.order_book_update","event":"update","result":{"U":53095262757,"a":[],"b":[{"p":"38115","s":0}],"s":"BTC_USDT","t":1701245743143,"u":53095262757}}
{"time":1701245743,"time_ms":1701245743193,"channel":"futures.order_book_update","event":"update","result":{"U":53095262758,"a":[{"p":"38130.5","s":127434},{"p":"38134","s":2175},{"p":"38133.8","s":0},{"p":"38135.8","s":0}],"b":[{"p":"38117.6","s":0}],"s":"BTC_USDT","t":1701245743180,"u":53095262763}}
{"time":1701245743,"time_ms":1701245743253,"channel":"futures.order_book_update","event":"update","result":{"U":53095262764,"a":[],"b":[{"p":"38123.1","s":3637},{"p":"38130","s":0}],"s":"BTC_USDT","t":1701245743246,"u":53095262766}}
{"time":1701245743,"time_ms":1701245743272,"channel":"futures.order_book_update","event":"update","result":{"U":53095262767,"a":[],"b":[{"p":"38067.7","s":0}],"s":"BTC_USDT","t":1701245743248,"u":53095262768}}
{"time":1701245743,"time_ms":1701245743294,"channel":"futures.order_book_update","event":"update","result":{"U":53095262769,"a":[{"p":"38138.3","s":0}],"b":[],"s":"BTC_USDT","t":1701245743278,"u":53095262769}}
{"time":1701245743,"time_ms":1701245743313,"channel":"futures.order_book_update","event":"update","result":{"U":53095262770,"a":[{"p":"38134.6","s":2175},{"p":"38135.4","s":3225},{"p":"38134","s":0},{"p":"38135.7","s":4656},{"p":"38135.2","s":1576},{"p":"38130.5","s":127697},{"p":"38139","s":0},{"p":"38139.8","s":0},{"p":"38136","s":0}],"b":[{"p":"38119.6","s":0},{"p":"38117.5","s":0},{"p":"38118.7","s":0},{"p":"38130.4","s":21964},{"p":"38118.1","s":0},{"p":"38118","s":0}],"s":"BTC_USDT","t":1701245743299,"u":53095262792}}
{"time":1701245743,"time_ms":1701245743391,"channel":"futures.order_book_update","event":"update","result":{"U":53095262793,"a":[{"p":"38135.6","s":5446}],"b":[],"s":"BTC_USDT","t":1701245743378,"u":53095262797}}
{"time":1701245743,"time_ms":1701245743452,"channel":"futures.order_book_update","event":"update","result":{"U":53095262798,"a":[{"p":"38135.8","s":0}],"b":[],"s":"BTC_USDT","t":1701245743442,"u":53095262798}}
{"time":1701245743,"time_ms":1701245743502,"channel":"futures.order_book_update","event":"update","result":{"U":53095262799,"a":[{"p":"38135.7","s":4658},{"p":"38138","s":0}],"b":[],"s":"BTC_USDT","t":1701245743478,"u":53095262800}}
{"time":1701245743,"time_ms":1701245743532,"channel":"futures.order_book_update","event":"update","result":{"U":53095262801,"a":[{"p":"38130.5","s":127772}],"b":[],"s":"BTC_USDT","t":1701245743508,"u":53095262801}}
{"time":1701245743,"time_ms":1701245743612,"channel":"futures.order_book_update","event":"update","result":{"U":53095262802,"a":[{"p":"38134.6","s":0},{"p":"38151.6","s":0},{"p":"38135.7","s":4658},{"p":"38134","s":2175}],"b":[],"s":"BTC_USDT","t":1701245743589,"u":53095262805}}
{"time":1701245743,"time_ms":1701245743651,"channel":"futures.order_book_update","event":"update","result":{"U":53095262806,"a":[{"p":"38135.7","s":4656}],"b":[],"s":"BTC_USDT","t":1701245743630,"u":53095262806}}
{"time":1701245743,"time_ms":1701245743671,"channel":"futures.order_book_update","event":"update","result":{"U":53095262807,"a":[{"p":"38135.8","s":0},{"p":"38135.7","s":4658},{"p":"38134.8","s":2175},{"p":"38134","s":0}],"b":[],"s":"BTC_USDT","t":1701245743662,"u":53095262809}}
{"time":1701245743,"time_ms":1701245743713,"channel":"futures.order_book_update","event":"update","result":{"U":53095262810,"a":[{"p":"38134","s":2175},{"p":"38134.8","s":0},{"p":"38131.9","s":0},{"p":"38145.6","s":0},{"p":"38135.8","s":2681},{"p":"38131","s":1180}],"b":[{"p":"38127.8","s":0},{"p":"38123","s":0},{"p":"38130","s":9000},{"p":"38126.9","s":15655}],"s":"BTC_USDT","t":1701245743692,"u":53095262818}}
{"time":1701245743,"time_ms":1701245743753,"channel":"futures.order_book_update","event":"update","result":{"U":53095262819,"a":[{"p":"38134.6","s":3341},{"p":"38135.1","s":0},{"p":"38135.9","s":0}],"b":[],"s":"BTC_USDT","t":1701245743732,"u":53095262820}}
{"time":1701245743,"time_ms":1701245743793,"channel":"futures.order_book_update","event":"update","result":{"U":53095262821,"a":[{"p":"38162.8","s":0}],"b":[{"p":"38130","s":0},{"p":"38118.6","s":0},{"p":"38113.9","s":0},{"p":"38120.5","s":0},{"p":"38123","s":200},{"p":"38122.9","s":9001},{"p":"38124.5","s":0}],"s":"BTC_USDT","t":1701245743784,"u":53095262827}}
{"time":1701245743,"time_ms":1701245743813,"channel":"futures.order_book_update","event":"update","result":{"U":53095262828,"a":[{"p":"38144.5","s":0},{"p":"38170.4","s":0},{"p":"38138.5","s":0},{"p":"38133.8","s":5516},{"p":"38134.1","s":15702},{"p":"38135.4","s":1050},{"p":"38142.5","s":0},{"p":"38154.8","s":0},{"p":"38158.5","s":0},{"p":"38151.9","s":0},{"p":"38136.1","s":0},{"p":"38135.9","s":6042},{"p":"38134.7","s":0},{"p":"38134.6","s":0},{"p":"38139","s":0},{"p":"38139.5","s":0}],"b":[{"p":"38122.8","s":884},{"p":"38074.9","s":0},{"p":"38119.6","s":0},{"p":"38091","s":0},{"p":"38109.6","s":0},{"p":"38111.3","s":0},{"p":"38117","s":0},{"p":"38122.6","s":3572},{"p":"38110.9","s":0},{"p":"38112.5","s":0},{"p":"38111.4","s":0},{"p":"38116.6","s":0},{"p":"38117.2","s":0},{"p":"38125.1","s":0},{"p":"38124","s":2186},{"p":"38126.2","s":0},{"p":"38122.4","s":0},{"p":"38117.6","s":0},{"p":"38111.8","s":0},{"p":"38091.1","s":0},{"p":"38112.8","s":0},{"p":"38116","s":0},{"p":"38123","s":0},{"p":"38113.2","s":0},{"p":"38130.4","s":4190},{"p":"38121.9","s":0},{"p":"38112","s":0},{"p":"38122.7","s":15026},{"p":"38125.4","s":0},{"p":"38123.7","s":0},{"p":"38093.4","s":0},{"p":"38119.4","s":0},{"p":"38108.1","s":0},{"p":"38116.5","s":0},{"p":"38118.1","s":0},{"p":"38117.5","s":0}],"s":"BTC_USDT","t":1701245743803,"u":53095262915}}
{"time":1701245743,"time_ms":1701245743832,"channel":"futures.order_book_update","event":"update","result":{"U":53095262916,"a":[{"p":"38130.5","s":130917},{"p":"38131","s":4291}],"b":[{"p":"38122.5","s":0}],"s":"BTC_USDT","t":1701245743826,"u":53095262933}}
{"time":1701245743,"time_ms":1701245743853,"channel":"futures.order_book_update","event":"update","result":{"U":53095262934,"a":[{"p":"38144.3","s":0},{"p":"38142.7","s":0},{"p":"38142.8","s":0},{"p":"38143.7","s":0},{"p":"38142.9","s":0},{"p":"38144.5","s":0},{"p":"38145.6","s":0},{"p":"38185.6","s":0},{"p":"38144.6","s":0}],"b":[{"p":"38126.9","s":15000},{"p":"38125.9","s":655},{"p":"38122.6","s":0}],"s":"BTC_USDT","t":1701245743840,"u":53095262957}}
{"time":1701245743,"time_ms":1701245743872,"channel":"futures.order_book_update","event":"update","result":{"U":53095262958,"a":[{"p":"38139.2","s":0}],"b":[],"s":"BTC_USDT","t":1701245743863,"u":53095262961}}
{"time":1701245743,"time_ms":1701245743894,"channel":"futures.order_book_update","event":"update","result":{"U":53095262962,"a":[{"p":"38186.4","s":0}],"b":[{"p":"38110.2","s":0},{"p":"38119","s":0},{"p":"38109.7","s":0},{"p":"38116.1","s":0}],"s":"BTC_USDT","t":1701245743885,"u":53095262968}}
{"time":1701245743,"time_ms":1701245743914,"channel":"futures.order_book_update","event":"update","result":{"U":53095262969,"a":[{"p":"38144.4","s":0},{"p":"38135.9","s":24050},{"p":"38152.8","s":0},{"p":"38138.3","s":0}],"b":[{"p":"38130.4","s":3600},{"p":"38120.9","s":0},{"p":"38102","s":0},{"p":"38115.4","s":0},{"p":"38116.6","s":0}],"s":"BTC_USDT","t":1701245743904,"u":53095262986}}
{"time":1701245743,"time_ms":1701245743931,"channel":"futures.order_book_update","event":"update","result":{"U":53095262987,"a":[],"b":[{"p":"38082.8","s":0}],"s":"BTC_USDT","t":1701245743921,"u":53095262993}}
{"time":1701245743,"time_ms":1701245743952,"channel":"futures.order_book_update","event":"update","result":{"U":53095262994,"a":[],"b":[{"p":"38019.5","s":0}],"s":"BTC_USDT","t":1701245743929,"u":53095262994}}
{"time":1701245743,"time_ms":1701245743971,"channel":"futures.order_book_update","event":"update","result":{"U":53095262995,"a":[{"p":"38138.2","s":0}],"b":[{"p":"38111.6","s":0}],"s":"BTC_USDT","t":1701245743962,"u":53095262999}}
{"time":1701245743,"time_ms":1701245743992,"channel":"futures.order_book_update","event":"update","result":{"U":53095263000,"a":[{"p":"38131","s":19058},{"p":"38137.8","s":0}],"b":[{"p":"38130","s":9000},{"p":"38122.7","s":0}],"s":"BTC_USDT","t":1701245743985,"u":53095263003}}
{"time":1701245744,"time_ms":1701245744032,"channel":"futures.order_book_update","event":"update","result":{"U":53095263004,"a":[{"p":"38136.1","s":2116},{"p":"38134.1","s":13404},{"p":"38134","s":0},{"p":"38133.8","s":0},{"p":"38141.7","s":0},{"p":"38137.7","s":0},{"p":"38135.9","s":24050},{"p":"38133.7","s":10105}],"b":[{"p":"38117.9","s":0},{"p":"38110.3","s":0},{"p":"38115.4","s":0},{"p":"38114.8","s":0},{"p":"38122.7","s":15026},{"p":"38130","s":0},{"p":"38115.8","s":0}],"s":"BTC_USDT","t":1701245744024,"u":53095263029}}
{"time":1701245744,"time_ms":1701245744054,"channel":"futures.order_book_update","event":"update","result":{"U":53095263030,"a":[{"p":"38134.2","s":40320},{"p":"38130.5","s":131441},{"p":"38137.4","s":0}],"b":[],"s":"BTC_USDT","t":1701245744035,"u":53095263033}}
{"time":1701245744,"time_ms":1701245744075,"channel":"futures.order_book_update","event":"update","result":{"U":53095263034,"a":[{"p":"38134.2","s":31340},{"p":"38142","s":0},{"p":"38138","s":0},{"p":"38140.9","s":0},{"p":"38130.5","s":140421},{"p":"38135.7","s":4656}],"b":[{"p":"38098.8","s":0},{"p":"38115.6","s":0},{"p":"38124.3","s":2},{"p":"38123.5","s":2},{"p":"38122.7","s":0},{"p":"38118","s":0},{"p":"38118.1","s":0},{"p":"38130.4","s":75},{"p":"38125","s":1697},{"p":"38122.8","s":0},{"p":"38122","s":0}],"s":"BTC_USDT","t":1701245744065,"u":53095263060}}
{"time":1701245744,"time_ms":1701245744091,"channel":"futures.order_book_update","event":"update","result":{"U":53095263061,"a":[{"p":"38187.8","s":0},{"p":"38137.6","s":0},{"p":"38135.7","s":4658}],"b":[{"p":"38125.6","s":3986},{"p":"38127.1","s":590},{"p":"38112.9","s":0},{"p":"38115.4","s":0},{"p":"38123.9","s":7239},{"p":"38122.9","s":0},{"p":"38113.3","s":0},{"p":"38115","s":0},{"p":"38121","s":0}],"s":"BTC_USDT","t":1701245744082,"u":53095263077}}
{"time":1701245744,"time_ms":1701245744113,"channel":"futures.order_book_update","event":"update","result":{"U":53095263078,"a":[{"p":"38137.9","s":0}],"b":[{"p":"38130.4","s":1575},{"p":"38125.6","s":353},{"p":"38124","s":4071},{"p":"38110.4","s":0},{"p":"38115.1","s":0}],"s":"BTC_USDT","t":1701245744104,"u":53095263089}}
{"time":1701245744,"time_ms":1701245744132,"channel":"futures.order_book_update","event":"update","result":{"U":53095263090,"a":[{"p":"38130.5","s":145921}],"b":[{"p":"38124.1","s":353},{"p":"38125.6","s":0},{"p":"38122.9","s":0},{"p":"38112.4","s":0},{"p":"38130.4","s":1490}],"s":"BTC_USDT","t":1701245744126,"u":53095263098}}
{"time":1701245744,"time_ms":1701245744151,"channel":"futures.order_book_update","event":"update","result":{"U":53095263099,"a":[{"p":"38130.5","s":140749}],"b":[{"p":"38130.4","s":2798},{"p":"38124.3","s":3608},{"p":"38087.7","s":0},{"p":"38111.6","s":0}],"s":"BTC_USDT","t":1701245744142,"u":53095263110}}
{"time":1701245744,"time_ms":1701245744171,"channel":"futures.order_book_update","event":"update","result":{"U":53095263111,"a":[{"p":"38133.7","s":7930},{"p":"38134.8","s":2175},{"p":"38136.1","s":0}],"b":[],"s":"BTC_USDT","t":1701245744149,"u":53095263113}}
{"time":1701245744,"time_ms":1701245744213,"channel":"futures.order_book_update","event":"update","result":{"U":53095263114,"a":[{"p":"38130.5","s":140824}],"b":[{"p":"38123","s":0},{"p":"38130.4","s":2873},{"p":"38118","s":0}],"s":"BTC_USDT","t":1701245744196,"u":53095263118}}
{"time":1701245744,"time_ms":1701245744231,"channel":"futures.order_book_update","event":"update","result":{"U":53095263119,"a":[],"b":[{"p":"38117","s":0}],"s":"BTC_USDT","t":1701245744202,"u":53095263121}}
{"time":1701245744,"time_ms":1701245744253,"channel":"futures.order_book_update","event":"update","result":{"U":53095263122,"a":[],"b":[{"p":"38115.9","s":0}],"s":"BTC_USDT","t":1701245744236,"u":53095263123}}
{"time":1701245744,"time_ms":1701245744311,"channel":"futures.order_book_update","event":"update","result":{"U":53095263124,"a":[],"b":[{"p":"38126.9","s":15655},{"p":"38123","s":200},{"p":"38125.9","s":0}],"s":"BTC_USDT","t":1701245744296,"u":53095263127}}
{"time":1701245744,"time_ms":1701245744334,"channel":"futures.order_book_update","event":"update","result":{"U":53095263128,"a":[],"b":[{"p":"38123","s":0},{"p":"38116.1","s":0},{"p":"38090.3","s":0},{"p":"38125.6","s":3638}],"s":"BTC_USDT","t":1701245744313,"u":53095263133}}
{"time":1701245744,"time_ms":1701245744351,"channel":"futures.order_book_update","event":"update","result":{"U":53095263134,"a":[{"p":"38150.3","s":0}],"b":[{"p":"38095.5","s":0}],"s":"BTC_USDT","t":1701245744333,"u":53095263135}}
{"time":1701245744,"time_ms":1701245744372,"channel":"futures.order_book_update","event":"update","result":{"U":53095263136,"a":[{"p":"38135.8","s":0},{"p":"38135.9","s":0},{"p":"38133.2","s":2101},{"p":"38133.3","s":525},{"p":"38133.4","s":1969},{"p":"38135.7","s":0}],"b":[{"p":"38114.3","s":0},{"p":"38116.9","s":0},{"p":"38112.7","s":0}],"s":"BTC_USDT","t":1701245744365,"u":53095263153}}
{"time":1701245744,"time_ms":1701245744391,"channel":"futures.order_book_update","event":"update","result":{"U":53095263154,"a":[],"b":[{"p":"38130","s":14500},{"p":"38123.1","s":0}],"s":"BTC_USDT","t":1701245744371,"u":53095263154}}
{"time":1701245744,"time_ms":1701245744414,"channel":"futures.order_book_update","event":"update","result":{"U":53095263155,"a":[{"p":"38133.7","s":2414},{"p":"38130.5","s":137679},{"p":"38135.6","s":0},{"p":"38133.1","s":2175},{"p":"38133.3","s":3866}],"b":[{"p":"38130.4","s":1565},{"p":"38116.4","s":0}],"s":"BTC_USDT","t":1701245744395,"u":53095263164}}
{"time":1701245744,"time_ms":1701245744452,"channel":"futures.order_book_update","event":"update","result":{"U":53095263165,"a":[{"p":"38133.3","s":525},{"p":"38133.6","s":3341},{"p":"38135.5","s":0}],"b":[{"p":"38130.4","s":7169},{"p":"38124.3","s":3608},{"p":"38123.1","s":0},{"p":"38122.4","s":0},{"p":"38125","s":1697},{"p":"38123.5","s":2}],"s":"BTC_USDT","t":1701245744442,"u":53095263179}}
{"time":1701245744,"time_ms":1701245744574,"channel":"futures.order_book_update","event":"update","result":{"U":53095263180,"a":[],"b":[{"p":"38123.3","s":0},{"p":"38122.3","s":0},{"p":"38124.7","s":2},{"p":"38126.3","s":2},{"p":"38123.6","s":0},{"p":"38123.5","s":0},{"p":"38123.1","s":0},{"p":"38125","s":1695},{"p":"38125.5","s":2},{"p":"38124.3","s":3606}],"s":"BTC_USDT","t":1701245744562,"u":53095263188}}
{"time":1701245744,"time_ms":1701245744610,"channel":"futures.order_book_update","event":"update","result":{"U":53095263189,"a":[],"b":[{"p":"38124","s":4171},{"p":"38123","s":0}],"s":"BTC_USDT","t":1701245744587,"u":53095263190}}
{"time":1701245744,"time_ms":1701245744652,"channel":"futures.order_book_update","event":"update","result":{"U":53095263191,"a":[],"b":[{"p":"38123","s":100},{"p":"38130.4","s":1565},{"p":"38123.1","s":3637},{"p":"38130","s":0},{"p":"38126.3","s":0},{"p":"38123.3","s":550},{"p":"38123.6","s":182},{"p":"38124.7","s":0},{"p":"38125.5","s":0}],"s":"BTC_USDT","t":1701245744637,"u":53095263196}}
{"time":1701245744,"time_ms":1701245744672,"channel":"futures.order_book_update","event":"update","result":{"U":53095263197,"a":[],"b":[{"p":"38122.9","s":9001},{"p":"38125.6","s":0}],"s":"BTC_USDT","t":1701245744655,"u":53095263199}}
{"time":1701245744,"time_ms":1701245744692,"channel":"futures.order_book_update","event":"update","result":{"U":53095263200,"a":[{"p":"38130.5","s":140824}],"b":[{"p":"38124","s":4071},{"p":"38123","s":200},{"p":"38120.9","s":0}],"s":"BTC_USDT","t":1701245744682,"u":53095263204}}
{"time":1701245744,"time_ms":1701245744711,"channel":"futures.order_book_update","event":"update","result":{"U":53095263205,"a":[],"b":[{"p":"38129.9","s":251}],"s":"BTC_USDT","t":1701245744687,"u":53095263205}}
{"time":1701245744,"time_ms":1701245744732,"channel":"futures.order_book_update","event":"update","result":{"U":53095263206,"a":[],"b":[{"p":"38112.7","s":0}],"s":"BTC_USDT","t":1701245744707,"u":53095263207}}
{"time":1701245744,"time_ms":1701245744753,"channel":"futures.order_book_update","event":"update","result":{"U":53095263208,"a":[{"p":"38134","s":2175},{"p":"38134.8","s":0},{"p":"38135.4","s":1050}],"b":[{"p":"38110","s":0},{"p":"38018.6","s":0},{"p":"38122.5","s":0},{"p":"38117.7","s":0},{"p":"38118.5","s":0}],"s":"BTC_USDT","t":1701245744745,"u":53095263218}}
{"time":1701245744,"time_ms":1701245744791,"channel":"futures.order_book_update","event":"update","result":{"U":53095263219,"a":[{"p":"38135.7","s":0}],"b":[{"p":"38123.3","s":552},{"p":"38124.1","s":355}],"s":"BTC_USDT","t":1701245744774,"u":53095263229}}
{"time":1701245744,"time_ms":1701245744812,"channel":"futures.order_book_update","event":"update","result":{"U":53095263230,"a":[{"p":"38134.8","s":2},{"p":"38134","s":0},{"p":"38135.4","s":0},{"p":"38135.5","s":0},{"p":"38134.7","s":2175}],"b":[{"p":"38122.6","s":0},{"p":"38123.3","s":550},{"p":"38124.1","s":353},{"p":"38121.4","s":0},{"p":"38116.1","s":0}],"s":"BTC_USDT","t":1701245744802,"u":53095263239}}
{"time":1701245744,"time_ms":1701245744832,"channel":"futures.order_book_update","event":"update","result":{"U":53095263240,"a":[],"b":[{"p":"38124.1","s":355},{"p":"38123.3","s":552},{"p":"38117.2","s":0},{"p":"38116.6","s":0},{"p":"38116.5","s":0}],"s":"BTC_USDT","t":1701245744822,"u":53095263248}}
{"time":1701245744,"time_ms":1701245744853,"channel":"futures.order_book_update","event":"update","result":{"U":53095263249,"a":[{"p":"38139.1","s":0}],"b":[],"s":"BTC_USDT","t":1701245744835,"u":53095263253}}
{"time":1701245744,"time_ms":1701245744912,"channel":"futures.order_book_update","event":"update","result":{"U":53095263254,"a":[{"p":"38130.5","s":147926}],"b":[{"p":"38117.2","s":0},{"p":"38124.1","s":353},{"p":"38123.3","s":550},{"p":"38121.4","s":0},{"p":"38122.5","s":0}],"s":"BTC_USDT","t":1701245744901,"u":53095263261}}
{"time":1701245744,"time_ms":1701245744932,"channel":"futures.order_book_update","event":"update","result":{"U":53095263262,"a":[{"p":"38130.5","s":149146}],"b":[{"p":"38123.3","s":552},{"p":"38117.6","s":0},{"p":"38117.4","s":0},{"p":"38118.7","s":0},{"p":"38124.1","s":355}],"s":"BTC_USDT","t":1701245744921,"u":53095263272}}
{"time":1701245744,"time_ms":1701245744972,"channel":"futures.order_book_update","event":"update","result":{"U":53095263273,"a":[],"b":[{"p":"38115.4","s":0},{"p":"38116.4","s":0}],"s":"BTC_USDT","t":1701245744954,"u":53095263278}}
{"time":1701245745,"time_ms":1701245745033,"channel":"futures.order_book_update","event":"update","result":{"U":53095263279,"a":[{"p":"38138.2","s":0},{"p":"38141.4","s":0},{"p":"38135.5","s":0},{"p":"38133.2","s":5442},{"p":"38135.4","s":1050},{"p":"38134.7","s":0},{"p":"38133.7","s":0},{"p":"38133.5","s":0},{"p":"38133.6","s":2175},{"p":"38133","s":2307}],"b":[{"p":"38115.8","s":0},{"p":"38110.4","s":0},{"p":"38110.8","s":0},{"p":"38115.6","s":0}],"s":"BTC_USDT","t":1701245745011,"u":53095263300}}
{"time":1701245745,"time_ms":1701245745052,"channel":"futures.order_book_update","event":"update","result":{"U":53095263301,"a":[{"p":"38156.5","s":0},{"p":"38187.1","s":0},{"p":"38132.9","s":1388},{"p":"38135.4","s":0}],"b":[],"s":"BTC_USDT","t":1701245745035,"u":53095263304}}
{"time":1701245745,"time_ms":1701245745073,"channel":"futures.order_book_update","event":"update","result":{"U":53095263305,"a":[],"b":[{"p":"38124.1","s":353},{"p":"38123.3","s":550},{"p":"38122.5","s":0},{"p":"38121.4","s":0},{"p":"38075.7","s":0}],"s":"BTC_USDT","t":1701245745064,"u":53095263309}}
{"time":1701245745,"time_ms":1701245745093,"channel":"futures.order_book_update","event":"update","result":{"U":53095263310,"a":[],"b":[{"p":"38124.1","s":355},{"p":"38123.3","s":552}],"s":"BTC_USDT","t":1701245745083,"u":53095263313}}
{"time":1701245745,"time_ms":1701245745111,"channel":"futures.order_book_update","event":"update","result":{"U":53095263314,"a":[{"p":"38133.8","s":2175},{"p":"38133.2","s":2101},{"p":"38133.5","s":3341},{"p":"38135.3","s":0},{"p":"38133.1","s":0},{"p":"38133.6","s":0},{"p":"38135.4","s":0},{"p":"38132.8","s":2175}],"b":[{"p":"38115","s":0},{"p":"38116","s":0}],"s":"BTC_USDT","t":1701245745099,"u":53095263324}}
{"time":1701245745,"time_ms":1701245745132,"channel":"futures.order_book_update","event":"update","result":{"U":53095263325,"a":[{"p":"38130.5","s":142524}],"b":[],"s":"BTC_USDT","t":1701245745122,"u":53095263327}}
{"time":1701245745,"time_ms":1701245745153,"channel":"futures.order_book_update","event":"update","result":{"U":53095263328,"a":[{"p":"38166.8","s":0},{"p":"38135.2","s":1576},{"p":"38130.5","s":143203},{"p":"38134.2","s":30816},{"p":"38133.1","s":3341},{"p":"38133.5","s":0},{"p":"38143.6","s":0}],"b":[{"p":"38130.4","s":27065}],"s":"BTC_USDT","t":1701245745141,"u":53095263337}}
{"time":1701245745,"time_ms":1701245745173,"channel":"futures.order_book_update","event":"update","result":{"U":53095263338,"a":[{"p":"38130.5","s":143727}],"b":[{"p":"38110.5","s":0},{"p":"38130","s":0},{"p":"38122.9","s":0},{"p":"38115.8","s":0},{"p":"38021.6","s":0},{"p":"38125.6","s":3638},{"p":"38122.5","s":0},{"p":"38118.5","s":0},{"p":"38110.9","s":0},{"p":"38114.9","s":0},{"p":"38123","s":0},{"p":"38115.9","s":0},{"p":"38057.8","s":0},{"p":"38124.5","s":8916}],"s":"BTC_USDT","t":1701245745163,"u":53095263359}}
{"time":1701245745,"time_ms":1701245745191,"channel":"futures.order_book_update","event":"update","result":{"U":53095263360,"a":[],"b":[{"p":"38123","s":0},{"p":"38124.6","s":5355},{"p":"38124","s":0}],"s":"BTC_USDT","t":1701245745183,"u":53095263363}}
{"time":1701245745,"time_ms":1701245745212,"channel":"futures.order_book_update","event":"update","result":{"U":53095263364,"a":[{"p":"38177.8","s":0},{"p":"38150.6","s":0},{"p":"38137.8","s":0}],"b":[{"p":"38080","s":0}],"s":"BTC_USDT","t":1701245745202,"u":53095263370}}
{"time":1701245745,"time_ms":1701245745232,"channel":"futures.order_book_update","event":"update","result":{"U":53095263371,"a":[],"b":[{"p":"38114.6","s":0}],"s":"BTC_USDT","t":1701245745206,"u":53095263371}}
{"time":1701245745,"time_ms":1701245745272,"channel":"futures.order_book_update","event":"update","result":{"U":53095263372,"a":[],"b":[{"p":"38119","s":0}],"s":"BTC_USDT","t":1701245745261,"u":53095263377}}
{"time":1701245745,"time_ms":1701245745312,"channel":"futures.order_book_update","event":"update","result":{"U":53095263378,"a":[{"p":"38138.5","s":0},{"p":"38142.5","s":0}],"b":[{"p":"38107.6","s":0}],"s":"BTC_USDT","t":1701245745297,"u":53095263383}}
{"time":1701245745,"time_ms":1701245745351,"channel":"futures.order_book_update","event":"update","result":{"U":53095263384,"a":[{"p":"38135.3","s":0},{"p":"38133.7","s":3341},{"p":"38133.1","s":0},{"p":"38169.6","s":0},{"p":"38142.6","s":0}],"b":[{"p":"38104","s":0}],"s":"BTC_USDT","t":1701245745341,"u":53095263391}}
{"time":1701245745,"time_ms":1701245745375,"channel":"futures.order_book_update","event":"update","result":{"U":53095263392,"a":[],"b":[{"p":"38130.4","s":34716}],"s":"BTC_USDT","t":1701245745357,"u":53095263393}}
{"time":1701245745,"time_ms":1701245745392,"channel":"futures.order_book_update","event":"update","result":{"U":53095263394,"a":[{"p":"38146.3","s":0}],"b":[],"s":"BTC_USDT","t":1701245745380,"u":53095263394}}
{"time":1701245745,"time_ms":1701245745452,"channel":"futures.order_book_update","event":"update","result":{"U":53095263395,"a":[],"b":[{"p":"38124.1","s":353},{"p":"38123.3","s":550},{"p":"38122.5","s":0},{"p":"38121.4","s":0}],"s":"BTC_USDT","t":1701245745443,"u":53095263398}}
{"time":1701245745,"time_ms":1701245745473,"channel":"futures.order_book_update","event":"update","result":{"U":53095263399,"a":[{"p":"38150","s":0},{"p":"38142","s":0}],"b":[{"p":"38124.5","s":0},{"p":"38120.5","s":0},{"p":"38121.6","s":0},{"p":"38112.5","s":0},{"p":"38123","s":0},{"p":"38124","s":2},{"p":"38123.3","s":552},{"p":"38130.4","s":25575}],"s":"BTC_USDT","t":1701245745463,"u":53095263413}}
{"time":1701245745,"time_ms":1701245745495,"channel":"futures.order_book_update","event":"update","result":{"U":53095263414,"a":[{"p":"38138","s":0},{"p":"38137.8","s":0},{"p":"38141.7","s":0}],"b":[{"p":"38121.1","s":0},{"p":"38120.1","s":0},{"p":"38120.6","s":0},{"p":"38120.9","s":0},{"p":"38114.3","s":0}],"s":"BTC_USDT","t":1701245745484,"u":53095263427}}
{"time":1701245745,"time_ms":1701245745532,"channel":"futures.order_book_update","event":"update","result":{"U":53095263428,"a":[],"b":[{"p":"38130.4","s":75}],"s":"BTC_USDT","t":1701245745523,"u":53095263429}}
{"time":1701245745,"time_ms":1701245745552,"channel":"futures.order_book_update","event":"update","result":{"U":53095263430,"a":[{"p":"38130","s":57717},{"p":"38130.5","s":132005},{"p":"38135.2","s":0}],"b":[{"p":"38130.4","s":0},{"p":"38110.6","s":0},{"p":"38096.9","s":0},{"p":"38114.8","s":0},{"p":"38123","s":200},{"p":"38122.9","s":4353},{"p":"38126.9","s":655},{"p":"38127","s":0}],"s":"BTC_USDT","t":1701245745542,"u":53095263462}}
{"time":1701245745,"time_ms":1701245745572,"channel":"futures.order_book_update","event":"update","result":{"U":53095263463,"a":[{"p":"38148.1","s":0},{"p":"38154.8","s":0},{"p":"38132.9","s":1388},{"p":"38138.5","s":0},{"p":"38144","s":0},{"p":"38135.3","s":0},{"p":"38146.4","s":0},{"p":"38133.2","s":2101},{"p":"38140","s":0},{"p":"38135.2","s":0},{"p":"38133.7","s":2175},{"p":"38134.9","s":7570},{"p":"38130.3","s":0},{"p":"38155.6","s":0},{"p":"38176.1","s":0},{"p":"38143.8","s":0},{"p":"38153.3","s":0},{"p":"38130.5","s":62003},{"p":"38134.2","s":15816},{"p":"38130","s":201782},{"p":"38133.6","s":3341},{"p":"38133.8","s":0},{"p":"38148.7","s":0},{"p":"38144.4","s":0}],"b":[{"p":"38121.8","s":0},{"p":"38122.8","s":884},{"p":"38123.3","s":0},{"p":"38124.1","s":0},{"p":"38119.4","s":0},{"p":"38117.5","s":0},{"p":"38122.9","s":8475},{"p":"38122.7","s":15026},{"p":"38122.5","s":2000},{"p":"38124.3","s":0},{"p":"38123","s":0},{"p":"38121.4","s":0},{"p":"38122.4","s":7255},{"p":"38125.7","s":2184},{"p":"38125.6","s":0},{"p":"38122.6","s":3572},{"p":"38124","s":0}],"s":"BTC_USDT","t":1701245745562,"u":53095263625}}
{"time":1701245745,"time_ms":1701245745592,"channel":"futures.order_book_update","event":"update","result":{"U":53095263626,"a":[{"p":"38133.8","s":2175},{"p":"38167.1","s":0},{"p":"38146.2","s":0},{"p":"38135.5","s":0},{"p":"38135.2","s":1576},{"p":"38130.5","s":26688},{"p":"38130","s":204217},{"p":"38133.6","s":0},{"p":"38139.5","s":0},{"p":"38133.5","s":9495},{"p":"38133.9","s":0},{"p":"38135.3","s":0},{"p":"38141.1","s":0},{"p":"38136","s":0},{"p":"38168.8","s":0},{"p":"38133.7","s":0},{"p":"38140.9","s":0},{"p":"38167.3","s":0},{"p":"38143","s":0}],"b":[{"p":"38122.3","s":0},{"p":"38117.9","s":0},{"p":"38126.9","s":0},{"p":"38125.7","s":0},{"p":"38122.2","s":0},{"p":"38114.2","s":0},{"p":"38127","s":494},{"p":"38122.5","s":2002},{"p":"38123.3","s":2}],"s":"BTC_USDT","t":1701245745584,"u":53095263671}}
{"time":1701245745,"time_ms":1701245745613,"channel":"futures.order_book_update","event":"update","result":{"U":53095263672,"a":[{"p":"38130.5","s":26164},{"p":"38172.8","s":0},{"p":"38170.9","s":0},{"p":"38143.9","s":0},{"p":"38135.3","s":1840},{"p":"38130","s":193457},{"p":"38131","s":18403},{"p":"38133.8","s":0},{"p":"38137.6","s":0},{"p":"38135.1","s":3341},{"p":"38154.7","s":0},{"p":"38135.2","s":3751},{"p":"38132.9","s":3563},{"p":"38132.8","s":0},{"p":"38137.3","s":0}],"b":[{"p":"38127","s":0},{"p":"38079.6","s":0},{"p":"38115","s":0},{"p":"38122.5","s":2002},{"p":"38127.2","s":448},{"p":"38122.4","s":0},{"p":"38115.6","s":0},{"p":"38087.8","s":0},{"p":"38117.3","s":0},{"p":"38120.9","s":0},{"p":"38124.1","s":2}],"s":"BTC_USDT","t":1701245745604,"u":53095263714}}
{"time":1701245745,"time_ms":1701245745634,"channel":"futures.order_book_update","event":"update","result":{"U":53095263715,"a":[{"p":"38176.9","s":0},{"p":"38173.9","s":0},{"p":"38135.4","s":0},{"p":"38186.6","s":0},{"p":"38130","s":194048},{"p":"38133.6","s":3341},{"p":"38135.1","s":0}],"b":[{"p":"38079.6","s":0},{"p":"38122.4","s":7255},{"p":"38112","s":0},{"p":"38123.3","s":0},{"p":"38124.1","s":0},{"p":"38121.4","s":0},{"p":"38110.3","s":0},{"p":"38122.5","s":2000},{"p":"38122.3","s":525}],"s":"BTC_USDT","t":1701245745623,"u":53095263735}}
{"time":1701245745,"time_ms":1701245745652,"channel":"futures.order_book_update","event":"update","result":{"U":53095263736,"a":[{"p":"38144.7","s":0},{"p":"38143.5","s":0},{"p":"38138.2","s":0},{"p":"38134","s":2175},{"p":"38135.2","s":1576},{"p":"38135.3","s":0}],"b":[{"p":"38122.2","s":4178},{"p":"38123.9","s":3633},{"p":"38122.3","s":0},{"p":"38115.6","s":0},{"p":"38117.6","s":0}],"s":"BTC_USDT","t":1701245745638,"u":53095263747}}
{"time":1701245745,"time_ms":1701245745676,"channel":"futures.order_book_update","event":"update","result":{"U":53095263748,"a":[],"b":[{"p":"38122.2","s":4178},{"p":"38118","s":0},{"p":"38117","s":0},{"p":"38124.6","s":0},{"p":"38123.9","s":0},{"p":"38110.6","s":0},{"p":"38125.4","s":4090},{"p":"38123","s":100},{"p":"38114.4","s":0}],"s":"BTC_USDT","t":1701245745658,"u":53095263760}}
{"time":1701245745,"time_ms":1701245745696,"channel":"futures.order_book_update","event":"update","result":{"U":53095263761,"a":[{"p":"38162.8","s":0},{"p":"38137.7","s":0}],"b":[{"p":"38122.2","s":0},{"p":"38004.1","s":0},{"p":"38117","s":0},{"p":"38125.8","s":655}],"s":"BTC_USDT","t":1701245745681,"u":53095263768}}
{"time":1701245745,"time_ms":1701245745731,"channel":"futures.order_book_update","event":"update","result":{"U":53095263769,"a":[],"b":[{"p":"38109.6","s":0}],"s":"BTC_USDT","t":1701245745718,"u":53095263775}}
{"time":1701245745,"time_ms":1701245745753,"channel":"futures.order_book_update","event":"update","result":{"U":53095263776,"a":[{"p":"38140","s":0},{"p":"38148","s":0},{"p":"38136","s":0}],"b":[{"p":"38107.5","s":0},{"p":"38016.5","s":0},{"p":"38119.5","s":0},{"p":"38115.5","s":0}],"s":"BTC_USDT","t":1701245745740,"u":53095263789}}
{"time":1701245745,"time_ms":1701245745773,"channel":"futures.order_book_update","event":"update","result":{"U":53095263790,"a":[{"p":"38130","s":204142}],"b":[{"p":"38122.2","s":4178},{"p":"38127.2","s":0}],"s":"BTC_USDT","t":1701245745762,"u":53095263793}}
{"time":1701245745,"time_ms":1701245745793,"channel":"futures.order_book_update","event":"update","result":{"U":53095263794,"a":[{"p":"38148.4","s":0},{"p":"38135.3","s":0},{"p":"38145.1","s":0},{"p":"38130","s":187980},{"p":"38127.2","s":31878},{"p":"38130.5","s":24579},{"p":"38135.2","s":0},{"p":"38132.8","s":2175},{"p":"38134","s":0},{"p":"38138","s":0},{"p":"38137.1","s":0},{"p":"38142","s":0},{"p":"38150","s":0},{"p":"38140","s":0}],"b":[{"p":"38115.1","s":0},{"p":"38109","s":0},{"p":"38107.5","s":0},{"p":"38107","s":0},{"p":"38117.1","s":0},{"p":"38120.9","s":0},{"p":"38121.1","s":0},{"p":"38119.5","s":0},{"p":"38122.6","s":0},{"p":"38129.9","s":0},{"p":"38114","s":0},{"p":"38115.5","s":0},{"p":"38121.3","s":0},{"p":"38118.6","s":0},{"p":"38109.4","s":0},{"p":"38121.9","s":92},{"p":"38119.2","s":0},{"p":"38121.6","s":3592},{"p":"38125.8","s":0},{"p":"38107.3","s":0},{"p":"38121","s":0},{"p":"38117.2","s":0},{"p":"38122.2","s":4178},{"p":"38122","s":141},{"p":"38121.4","s":3633},{"p":"38113.4","s":0},{"p":"38120.1","s":0},{"p":"38125.4","s":0},{"p":"38114.7","s":0},{"p":"38113.9","s":0},{"p":"38122.3","s":0},{"p":"38121.2","s":4178},{"p":"38123.1","s":26},{"p":"38117.8","s":0},{"p":"38109.7","s":0},{"p":"38122.7","s":26},{"p":"38125.3","s":0},{"p":"38123","s":0},{"p":"38117","s":0},{"p":"38125.9","s":395},{"p":"38122.4","s":3642}],"s":"BTC_USDT","t":1701245745786,"u":53095263891}}
{"time":1701245745,"time_ms":1701245745812,"channel":"futures.order_book_update","event":"update","result":{"U":53095263892,"a":[{"p":"38130","s":126816},{"p":"38133","s":0},{"p":"38135","s":0},{"p":"38151.8","s":0},{"p":"38154","s":0},{"p":"38127.2","s":140148},{"p":"38146.4","s":0},{"p":"38134.9","s":7570},{"p":"38132.6","s":3932},{"p":"38159.2","s":0},{"p":"38148.1","s":0},{"p":"38129.9","s":11000},{"p":"38134.1","s":0},{"p":"38152.9","s":0},{"p":"38152.6","s":0}],"b":[{"p":"38122.2","s":0},{"p":"38121.2","s":0},{"p":"38058.8","s":0},{"p":"38076","s":0},{"p":"38120.4","s":3642},{"p":"38123.6","s":0},{"p":"38121.6","s":0},{"p":"38107.5","s":0},{"p":"38114.1","s":0},{"p":"38036.1","s":0},{"p":"38112.7","s":0},{"p":"38120.6","s":1779},{"p":"38120.8","s":2621},{"p":"38125.9","s":0},{"p":"38124.9","s":0},{"p":"38116.1","s":0},{"p":"38120.9","s":262},{"p":"38121.3","s":5354},{"p":"38120.2","s":551},{"p":"38122.4","s":0},{"p":"38047.3","s":0},{"p":"38116.4","s":0},{"p":"38109.7","s":0},{"p":"38117","s":0},{"p":"38120.5","s":3932}],"s":"BTC_USDT","t":1701245745799,"u":53095264007}}
{"time":1701245745,"time_ms":1701245745834,"channel":"futures.order_book_update","event":"update","result":{"U":53095264008,"a":[{"p":"38144.8","s":0},{"p":"38141","s":0},{"p":"38188","s":0},{"p":"38147.2","s":0},{"p":"38134.4","s":0},{"p":"38137.2","s":0},{"p":"38148","s":0},{"p":"38187.5","s":0},{"p":"38183","s":0},{"p":"38132.8","s":4350},{"p":"38132.9","s":0},{"p":"38136","s":0},{"p":"38150.6","s":0},{"p":"38177.7","s":0},{"p":"38165.1","s":0},{"p":"38140","s":0},{"p":"38130","s":106856},{"p":"38133","s":8918},{"p":"38166.2","s":0},{"p":"38142","s":0},{"p":"38178.9","s":0},{"p":"38138.2","s":0},{"p":"38153","s":0},{"p":"38130.5","s":524},{"p":"38164.8","s":0},{"p":"38150.7","s":0},{"p":"38142.8","s":0},{"p":"38137.7","s":0},{"p":"38183.7","s":0},{"p":"38141.4","s":0},{"p":"38143.5","s":0},{"p":"38143.3","s":0},{"p":"38127.6","s":0},{"p":"38128","s":0},{"p":"38134.5","s":0},{"p":"38143","s":0},{"p":"38132.1","s":3637},{"p":"38187.9","s":0},{"p":"38191.6","s":0},{"p":"38165.3","s":0},{"p":"38157.1","s":0},{"p":"38129.9","s":75},{"p":"38127.2","s":206570},{"p":"38131.1","s":565},{"p":"38134.9","s":7610},{"p":"38130.9","s":3349},{"p":"38134.8","s":2}],"b":[{"p":"38120.1","s":0},{"p":"38118.9","s":10749},{"p":"38122.7","s":0},{"p":"38106.8","s":0},{"p":"38098.4","s":0},{"p":"38126.5","s":0},{"p":"38111.2","s":0},{"p":"38119.1","s":3821},{"p":"38116.3","s":0},{"p":"38118","s":0},{"p":"37996.4","s":0},{"p":"38099.9","s":0},{"p":"38120.8","s":0},{"p":"38099.7","s":0},{"p":"38119.9","s":884},{"p":"38123.2","s":26},{"p":"38127.1","s":3642},{"p":"38126.6","s":0},{"p":"38108.1","s":0},{"p":"38108.9","s":0},{"p":"38121.4","s":3634},{"p":"38118.6","s":0},{"p":"38112.4","s":0},{"p":"38117","s":0},{"p":"38108","s":0},{"p":"38101.4","s":0},{"p":"38119.4","s":26},{"p":"38126.9","s":75},{"p":"38119.3","s":10539},{"p":"38101","s":0},{"p":"38088.3","s":0},{"p":"38117.3","s":0},{"p":"38107.4","s":0},{"p":"38076.2","s":0},{"p":"38113.4","s":0},{"p":"38116","s":0},{"p":"38113.3","s":0},{"p":"38116.5","s":0},{"p":"38114.3","s":0},{"p":"38108.7","s":0},{"p":"38122.9","s":1752},{"p":"38126.7","s":0},{"p":"38114.8","s":0},{"p":"38109.1","s":0},{"p":"38117.9","s":0},{"p":"38121.3","s":0},{"p":"38115.9","s":0},{"p":"38122.5","s":0},{"p":"38119.2","s":0},{"p":"38112.9","s":0},{"p":"38098.6","s":0},{"p":"38120.9","s":2497},{"p":"38107.5","s":0},{"p":"38117.4","s":0},{"p":"38092.8","s":0}],"s":"BTC_USDT","t":1701245745824,"u":53095264325}}
{"time":1701245745,"time_ms":1701245745852,"channel":"futures.order_book_update","event":"update","result":{"U":53095264326,"a":[{"p":"38140","s":0},{"p":"38163.3","s":0},{"p":"38150.9","s":0},{"p":"38165.2","s":0},{"p":"38152","s":0},{"p":"38132.1","s":7242},{"p":"38133.9","s":3605},{"p":"38134.2","s":0},{"p":"38188.6","s":0},{"p":"38147.9","s":0},{"p":"38166.1","s":0},{"p":"38138.8","s":0},{"p":"38132.3","s":2},{"p":"38134.9","s":0},{"p":"38135","s":0},{"p":"38127.2","s":197201},{"p":"38132.8","s":2175},{"p":"38130.3","s":3932},{"p":"38134.8","s":0},{"p":"38191.6","s":0},{"p":"38134","s":0}],"b":[{"p":"38117","s":0},{"p":"38127.1","s":590},{"p":"38122.9","s":538},{"p":"38118.9","s":3573},{"p":"38114.2","s":0},{"p":"38116","s":0},{"p":"38118.6","s":0},{"p":"38114.3","s":0}],"s":"BTC_USDT","t":1701245745844,"u":53095264384}}
{"time":1701245745,"time_ms":1701245745872,"channel":"futures.order_book_update","event":"update","result":{"U":53095264385,"a":[{"p":"38127","s":170681},{"p":"38132.8","s":0},{"p":"38145.8","s":0},{"p":"38191.3","s":0},{"p":"38145.4","s":0},{"p":"38130.8","s":2175},{"p":"38127.6","s":600},{"p":"38130","s":91856},{"p":"38132.1","s":10848},{"p":"38133.9","s":0},{"p":"38133.6","s":0},{"p":"38189.4","s":0},{"p":"38127.2","s":64502}],"b":[{"p":"38120.5","s":0},{"p":"38127.1","s":0},{"p":"38108","s":0},{"p":"38115.2","s":0},{"p":"38118.6","s":0},{"p":"38125.1","s":965},{"p":"38119","s":600},{"p":"38121.4","s":1},{"p":"38108.8","s":0},{"p":"38118.9","s":1},{"p":"38113.7","s":0},{"p":"38111.6","s":0},{"p":"38112.4","s":0},{"p":"38114.1","s":0},{"p":"38118.7","s":2000},{"p":"38126.9","s":3845},{"p":"38119.1","s":3638},{"p":"38117.1","s":0},{"p":"38122.9","s":0},{"p":"38118","s":0},{"p":"38055.9","s":0},{"p":"38082.4","s":0},{"p":"38113.9","s":0}],"s":"BTC_USDT","t":1701245745864,"u":53095264541}}
{"time":1701245745,"time_ms":1701245745895,"channel":"futures.order_book_update","event":"update","result":{"U":53095264542,"a":[{"p":"38130","s":64965},{"p":"38130.8","s":0},{"p":"38181.6","s":0},{"p":"38134","s":0},{"p":"38127.2","s":49603},{"p":"38129.9","s":2250},{"p":"38135.7","s":0},{"p":"38141","s":0},{"p":"38134.2","s":0},{"p":"38137.4","s":0},{"p":"38133.1","s":733},{"p":"38127","s":173778},{"p":"38133.5","s":0},{"p":"38145.5","s":0},{"p":"38137","s":0},{"p":"38132.5","s":28311},{"p":"38188.7","s":0},{"p":"38133.6","s":0}],"b":[{"p":"38123","s":15000},{"p":"38121.9","s":0},{"p":"38102.4","s":0},{"p":"38091.7","s":0},{"p":"38113.9","s":0},{"p":"38126.9","s":4717},{"p":"38112.2","s":0},{"p":"38118.6","s":0},{"p":"38107.6","s":0},{"p":"38114.1","s":0}],"s":"BTC_USDT","t":1701245745887,"u":53095264611}}
{"time":1701245745,"time_ms":1701245745912,"channel":"futures.order_book_update","event":"update","result":{"U":53095264612,"a":[{"p":"38135.4","s":0},{"p":"38141","s":0},{"p":"38142.5","s":0},{"p":"38132.8","s":2175},{"p":"38130","s":63786},{"p":"38133.1","s":0},{"p":"38129.9","s":0},{"p":"38133.4","s":1969},{"p":"38130.8","s":5516},{"p":"38127","s":172308},{"p":"38137.1","s":0},{"p":"38133.5","s":0}],"b":[{"p":"38099.4","s":0},{"p":"38118.7","s":0},{"p":"38119","s":0},{"p":"38123.1","s":9032},{"p":"38114","s":0},{"p":"38107.5","s":0},{"p":"38115","s":0},{"p":"38121","s":567},{"p":"38119.6","s":179},{"p":"38120.2","s":0},{"p":"38118.9","s":1},{"p":"38117.1","s":0},{"p":"38126.9","s":4142},{"p":"38119.5","s":600}],"s":"BTC_USDT","t":1701245745902,"u":53095264661}}
{"time":1701245745,"time_ms":1701245745932,"channel":"futures.order_book_update","event":"update","result":{"U":53095264662,"a":[{"p":"38127","s":172045},{"p":"38130.8","s":2175},{"p":"38132","s":3341},{"p":"38133.4","s":0},{"p":"38143.5","s":0},{"p":"38138.3","s":0}],"b":[{"p":"38126.9","s":13283},{"p":"38118.7","s":2000},{"p":"38119.5","s":0},{"p":"38062.6","s":0},{"p":"38111.3","s":0},{"p":"38097.7","s":0}],"s":"BTC_USDT","t":1701245745918,"u":53095264686}}
{"time":1701245745,"time_ms":1701245745951,"channel":"futures.order_book_update","event":"update","result":{"U":53095264687,"a":[{"p":"38127","s":172445},{"p":"38137.4","s":0},{"p":"38178.5","s":0}],"b":[{"p":"38119.5","s":600},{"p":"38126.9","s":5632},{"p":"38118.7","s":0},{"p":"38118.1","s":0},{"p":"38114.2","s":0},{"p":"38110.5","s":0}],"s":"BTC_USDT","t":1701245745939,"u":53095264706}}
{"time":1701245745,"time_ms":1701245745974,"channel":"futures.order_book_update","event":"update","result":{"U":53095264707,"a":[{"p":"38185.5","s":0},{"p":"38131.9","s":93},{"p":"38127.2","s":22103},{"p":"38133.3","s":0},{"p":"38159.8","s":0},{"p":"38191.2","s":0}],"b":[{"p":"38021.6","s":0},{"p":"38053.8","s":0},{"p":"38126.9","s":13283},{"p":"38120.9","s":131},{"p":"38061.6","s":0},{"p":"38118.7","s":0},{"p":"38010.1","s":0},{"p":"38014.7","s":0},{"p":"38017.8","s":0},{"p":"38076.8","s":0},{"p":"38120.7","s":538},{"p":"38125.1","s":0},{"p":"38073.2","s":0}],"s":"BTC_USDT","t":1701245745962,"u":53095264848}}
{"time":1701245746,"time_ms":1701245746029,"channel":"futures.order_book_update","event":"update","result":{"U":53095264849,"a":[{"p":"38127","s":175590},{"p":"38142.1","s":0}],"b":[{"p":"38120.7","s":2118},{"p":"38125.1","s":863},{"p":"38118.9","s":0},{"p":"38118.7","s":0},{"p":"38017.8","s":0}],"s":"BTC_USDT","t":1701245745982,"u":53095264864}}
{"time":1701245746,"time_ms":1701245746030,"channel":"futures.order_book_update","event":"update","result":{"U":53095264865,"a":[{"p":"38138.2","s":0}],"b":[{"p":"38123.4","s":655},{"p":"38126.9","s":5632},{"p":"38119.1","s":0},{"p":"38112.4","s":0}],"s":"BTC_USDT","t":1701245746002,"u":53095264870}}
{"time":1701245746,"time_ms":1701245746032,"channel":"futures.order_book_update","event":"update","result":{"U":53095264871,"a":[{"p":"38133.4","s":1969},{"p":"38130.9","s":1050},{"p":"38137.4","s":0},{"p":"38133","s":0},{"p":"38132.8","s":0},{"p":"38133.2","s":2101},{"p":"38134.8","s":0},{"p":"38137.5","s":0},{"p":"38133.3","s":525},{"p":"38132","s":2175},{"p":"38145","s":0},{"p":"38130.5","s":3865},{"p":"38129.9","s":4544},{"p":"38130.8","s":0}],"b":[{"p":"38118.7","s":2000},{"p":"38123.4","s":0},{"p":"38118","s":0},{"p":"38103.5","s":0},{"p":"38119.1","s":3638},{"p":"38113.5","s":0},{"p":"38112.9","s":0},{"p":"38114.1","s":0},{"p":"38119.6","s":0},{"p":"38076","s":0},{"p":"38106.9","s":0},{"p":"38116.5","s":0},{"p":"38107.9","s":0},{"p":"38112","s":0},{"p":"38105","s":0},{"p":"38113.3","s":0}],"s":"BTC_USDT","t":1701245746022,"u":53095264912}}
{"time":1701245746,"time_ms":1701245746053,"channel":"futures.order_book_update","event":"update","result":{"U":53095264913,"a":[{"p":"38130.5","s":524},{"p":"38132","s":0},{"p":"38129.9","s":4544},{"p":"38133.5","s":0},{"p":"38130.2","s":3341}],"b":[{"p":"38103","s":0},{"p":"38108","s":0},{"p":"38110.3","s":0},{"p":"38089.9","s":0},{"p":"38125.1","s":0},{"p":"38120.7","s":538},{"p":"38119.5","s":0},{"p":"38110.2","s":0},{"p":"38083.6","s":0},{"p":"38126.9","s":2422},{"p":"38118.6","s":15051},{"p":"38107.8","s":0},{"p":"38107.5","s":0},{"p":"38112.4","s":0},{"p":"38118","s":525}],"s":"BTC_USDT","t":1701245746044,"u":53095264955}}
{"time":1701245746,"time_ms":1701245746071,"channel":"futures.order_book_update","event":"update","result":{"U":53095264956,"a":[{"p":"38129.8","s":38272},{"p":"38133.2","s":2834},{"p":"38130","s":41118},{"p":"38133.4","s":0},{"p":"38141.6","s":0},{"p":"38130.7","s":0},{"p":"38129.9","s":6719},{"p":"38146.4","s":0},{"p":"38142.9","s":0},{"p":"38134.1","s":0},{"p":"38170.2","s":0}],"b":[{"p":"38114.8","s":0},{"p":"38112.1","s":0},{"p":"38112.7","s":0},{"p":"38107.4","s":0},{"p":"38107.3","s":0},{"p":"38112.9","s":0},{"p":"38113.1","s":0}],"s":"BTC_USDT","t":1701245746058,"u":53095265077}}
{"time":1701245746,"time_ms":1701245746098,"channel":"futures.order_book_update","event":"update","result":{"U":53095265078,"a":[{"p":"38130.7","s":2175},{"p":"38133.2","s":2101},{"p":"38133.3","s":0},{"p":"38130.2","s":0},{"p":"38129.8","s":24672},{"p":"38127.2","s":15000},{"p":"38129.9","s":4544},{"p":"38133","s":8918},{"p":"38139.5","s":0},{"p":"38137.1","s":0},{"p":"38135","s":0},{"p":"38148","s":0},{"p":"38127","s":182693}],"b":[{"p":"38111.6","s":0},{"p":"38111.3","s":0},{"p":"38112.4","s":0}],"s":"BTC_USDT","t":1701245746084,"u":53095265121}}
{"time":1701245746,"time_ms":1701245746111,"channel":"futures.order_book_update","event":"update","result":{"U":53095265122,"a":[{"p":"38166.1","s":0},{"p":"38164.3","s":0},{"p":"38130.2","s":3341},{"p":"38133.2","s":0}],"b":[],"s":"BTC_USDT","t":1701245746101,"u":53095265128}}
{"time":1701245746,"time_ms":1701245746131,"channel":"futures.order_book_update","event":"update","result":{"U":53095265129,"a":[{"p":"38132.3","s":0},{"p":"38130.5","s":0},{"p":"38133.3","s":525},{"p":"38133.2","s":2101},{"p":"38127","s":183217}],"b":[{"p":"38118.6","s":0},{"p":"38118","s":0},{"p":"38120.4","s":3644},{"p":"38119.6","s":2},{"p":"38118.8","s":2}],"s":"BTC_USDT","t":1701245746113,"u":53095265137}}
{"time":1701245746,"time_ms":1701245746153,"channel":"futures.order_book_update","event":"update","result":{"U":53095265138,"a":[{"p":"38131.1","s":567},{"p":"38133.2","s":2626},{"p":"38132.7","s":525},{"p":"38133.3","s":0},{"p":"38143.4","s":0}],"b":[{"p":"38126.9","s":2362}],"s":"BTC_USDT","t":1701245746143,"u":53095265147}}
{"time":1701245746,"time_ms":1701245746175,"channel":"futures.order_book_update","event":"update","result":{"U":53095265148,"a":[],"b":[{"p":"38126.9","s":1490}],"s":"BTC_USDT","t":1701245746158,"u":53095265149}}
{"time":1701245746,"time_ms":1701245746193,"channel":"futures.order_book_update","event":"update","result":{"U":53095265150,"a":[{"p":"38127","s":185184}],"b":[{"p":"38118.6","s":15051},{"p":"38123","s":0}],"s":"BTC_USDT","t":1701245746182,"u":53095265156}}
{"time":1701245746,"time_ms":1701245746212,"channel":"futures.order_book_update","event":"update","result":{"U":53095265157,"a":[{"p":"38154.7","s":0},{"p":"38145.8","s":0}],"b":[{"p":"38123","s":15000},{"p":"38120.7","s":2123},{"p":"38126.9","s":5371},{"p":"38123.1","s":559},{"p":"38118.6","s":0}],"s":"BTC_USDT","t":1701245746202,"u":53095265172}}
{"time":1701245746,"time_ms":1701245746234,"channel":"futures.order_book_update","event":"update","result":{"U":53095265173,"a":[],"b":[{"p":"38112.1","s":0},{"p":"38109.9","s":0},{"p":"38123.1","s":9495},{"p":"38120.7","s":538},{"p":"38117.4","s":0}],"s":"BTC_USDT","t":1701245746220,"u":53095265182}}
{"time":1701245746,"time_ms":1701245746252,"channel":"futures.order_book_update","event":"update","result":{"U":53095265183,"a":[{"p":"38127","s":185839}],"b":[{"p":"38122.6","s":655},{"p":"38118.7","s":0}],"s":"BTC_USDT","t":1701245746238,"u":53095265187}}
{"time":1701245746,"time_ms":1701245746273,"channel":"futures.order_book_update","event":"update","result":{"U":53095265188,"a":[{"p":"38127","s":185989}],"b":[],"s":"BTC_USDT","t":1701245746255,"u":53095265192}}
{"time":1701245746,"time_ms":1701245746291,"channel":"futures.order_book_update","event":"update","result":{"U":53095265193,"a":[{"p":"38133.3","s":525},{"p":"38132","s":0},{"p":"38133.4","s":0},{"p":"38130.9","s":1050},{"p":"38130.5","s":2175},{"p":"38131.1","s":565},{"p":"38130.7","s":0},{"p":"38130.2","s":0},{"p":"38136.8","s":0},{"p":"38134.1","s":0}],"b":[{"p":"38115","s":0},{"p":"38114.1","s":0},{"p":"38111.6","s":0},{"p":"38106.3","s":0},{"p":"38107.4","s":0}],"s":"BTC_USDT","t":1701245746281,"u":53095265214}}
{"time":1701245746,"time_ms":1701245746314,"channel":"futures.order_book_update","event":"update","result":{"U":53095265215,"a":[{"p":"38129.7","s":3342},{"p":"38131.2","s":2},{"p":"38133.2","s":0},{"p":"38133.3","s":0}],"b":[{"p":"38120.4","s":3642},{"p":"38118.7","s":2000},{"p":"38118.6","s":15051},{"p":"38119.6","s":0},{"p":"38118.8","s":0},{"p":"38112.4","s":0},{"p":"38117.7","s":0},{"p":"38112.7","s":0},{"p":"38113","s":0}],"s":"BTC_USDT","t":1701245746299,"u":53095265226}}
{"time":1701245746,"time_ms":1701245746331,"channel":"futures.order_book_update","event":"update","result":{"U":53095265227,"a":[{"p":"38125.1","s":16106},{"p":"38133","s":0},{"p":"38134.6","s":0},{"p":"38145.8","s":0},{"p":"38127","s":165682}],"b":[{"p":"38118","s":525},{"p":"38126.9","s":0},{"p":"38107.4","s":0},{"p":"38111.6","s":0},{"p":"38112.4","s":0}],"s":"BTC_USDT","t":1701245746322,"u":53095265246}}
{"time":1701245746,"time_ms":1701245746352,"channel":"futures.order_book_update","event":"update","result":{"U":53095265247,"a":[{"p":"38149.1","s":0},{"p":"38149.6","s":0},{"p":"38133","s":0},{"p":"38145.5","s":0},{"p":"38132","s":16993},{"p":"38132.6","s":0},{"p":"38163.2","s":0},{"p":"38141.5","s":0},{"p":"38132.7","s":0},{"p":"38134.9","s":0},{"p":"38126.6","s":0},{"p":"38125.1","s":185874},{"p":"38129.2","s":394},{"p":"38129","s":40},{"p":"38127","s":21603},{"p":"38151.8","s":0},{"p":"38132.5","s":28311},{"p":"38131.1","s":525},{"p":"38127.6","s":0},{"p":"38127.2","s":0},{"p":"38150.6","s":0},{"p":"38137.5","s":0},{"p":"38129.4","s":525},{"p":"38140","s":0},{"p":"38126.8","s":0},{"p":"38144.1","s":0}],"b":[{"p":"38117.6","s":0},{"p":"38121.1","s":26},{"p":"38120.6","s":1781},{"p":"38119","s":2},{"p":"38119.8","s":2},{"p":"38117.9","s":2623},{"p":"38119.4","s":0},{"p":"38118","s":0},{"p":"38111.6","s":0},{"p":"38112","s":0},{"p":"38114.2","s":0},{"p":"38114","s":0},{"p":"38110.8","s":0},{"p":"38125","s":11806},{"p":"38120.4","s":0},{"p":"38123.2","s":0},{"p":"37993.4","s":0},{"p":"38113","s":0},{"p":"38116.5","s":0},{"p":"38117.5","s":0},{"p":"38117.8","s":0},{"p":"38106.8","s":0},{"p":"38092.1","s":0}],"s":"BTC_USDT","t":1701245746342,"u":53095265412}}
{"time":1701245746,"time_ms":1701245746371,"channel":"futures.order_book_update","event":"update","result":{"U":53095265413,"a":[{"p":"38129.7","s":0},{"p":"38132.6","s":6107},{"p":"38125.1","s":183229},{"p":"38130.9","s":1050},{"p":"38133.1","s":0},{"p":"38132.8","s":40},{"p":"38130.5","s":0},{"p":"38131.9","s":93},{"p":"38134.8","s":0},{"p":"38134.4","s":0},{"p":"38131.8","s":0},{"p":"38129.9","s":9612},{"p":"38131.2","s":0},{"p":"38132.7","s":525}],"b":[{"p":"38110.9","s":0},{"p":"38105.6","s":0},{"p":"38125","s":14773},{"p":"38123.8","s":2},{"p":"38120.6","s":1779},{"p":"38120.1","s":3637},{"p":"38117.9","s":0},{"p":"38122.2","s":2},{"p":"38119.8","s":0},{"p":"38106.3","s":0},{"p":"38108.7","s":0},{"p":"38111.6","s":0},{"p":"38123","s":2},{"p":"38115.2","s":0},{"p":"38113.7","s":0},{"p":"38112.5","s":0},{"p":"38121.1","s":28},{"p":"38119","s":0},{"p":"38117.8","s":0},{"p":"38077.5","s":0}],"s":"BTC_USDT","t":1701245746361,"u":53095265475}}
{"time":1701245746,"time_ms":1701245746392,"channel":"futures.order_book_update","event":"update","result":{"U":53095265476,"a":[{"p":"38132.9","s":0},{"p":"38125.1","s":180333},{"p":"38131.9","s":2268},{"p":"38141.4","s":0},{"p":"38162.4","s":0},{"p":"38161.4","s":0},{"p":"38144.6","s":0},{"p":"38129.9","s":13218},{"p":"38132.5","s":28862},{"p":"38127","s":17803},{"p":"38132.6","s":3932}],"b":[{"p":"38120.7","s":2124},{"p":"38123.1","s":892},{"p":"38012.3","s":0},{"p":"38118.3","s":0},{"p":"38112.5","s":0},{"p":"38112.9","s":0}],"s":"BTC_USDT","t":1701245746386,"u":53095265506}}
{"time":1701245746,"time_ms":1701245746411,"channel":"futures.order_book_update","event":"update","result":{"U":53095265507,"a":[{"p":"38131.9","s":93},{"p":"38125.1","s":180407},{"p":"38132.7","s":0},{"p":"38132.8","s":0},{"p":"38130.8","s":3341},{"p":"38129.7","s":2175}],"b":[{"p":"38124.8","s":75},{"p":"38118.6","s":0}],"s":"BTC_USDT","t":1701245746400,"u":53095265514}}
{"time":1701245746,"time_ms":1701245746434,"channel":"futures.order_book_update","event":"update","result":{"U":53095265515,"a":[{"p":"38134.4","s":0}],"b":[{"p":"38121.1","s":26},{"p":"38123.8","s":0},{"p":"38123","s":0},{"p":"38122.2","s":0},{"p":"38125","s":13255},{"p":"38118.3","s":3606},{"p":"38117.9","s":2621},{"p":"38118.6","s":15051}],"s":"BTC_USDT","t":1701245746422,"u":53095265523}}
{"time":1701245746,"time_ms":1701245746453,"channel":"futures.order_book_update","event":"update","result":{"U":53095265524,"a":[],"b":[{"p":"38123.7","s":2},{"p":"38122.2","s":2},{"p":"38118.3","s":0},{"p":"38118.6","s":0},{"p":"38113","s":0},{"p":"38123","s":2},{"p":"38121.1","s":28},{"p":"38117.9","s":0},{"p":"38096.2","s":0}],"s":"BTC_USDT","t":1701245746443,"u":53095265532}}
{"time":1701245746,"time_ms":1701245746473,"channel":"futures.order_book_update","event":"update","result":{"U":53095265533,"a":[{"p":"38169.9","s":0},{"p":"38134.5","s":0},{"p":"38139","s":0}],"b":[{"p":"38117.5","s":0}],"s":"BTC_USDT","t":1701245746462,"u":53095265541}}
{"time":1701245746,"time_ms":1701245746492,"channel":"futures.order_book_update","event":"update","result":{"U":53095265542,"a":[{"p":"38125.1","s":181062},{"p":"38141.3","s":0},{"p":"38158.5","s":0}],"b":[],"s":"BTC_USDT","t":1701245746481,"u":53095265546}}
{"time":1701245746,"time_ms":1701245746514,"channel":"futures.order_book_update","event":"update","result":{"U":53095265547,"a":[{"p":"38136.5","s":0}],"b":[{"p":"38112","s":0},{"p":"38113.1","s":0}],"s":"BTC_USDT","t":1701245746497,"u":53095265552}}
{"time":1701245746,"time_ms":1701245746591,"channel":"futures.order_book_update","event":"update","result":{"U":53095265553,"a":[{"p":"38129.8","s":0},{"p":"38147.5","s":0},{"p":"38132.5","s":28862},{"p":"38125.6","s":525},{"p":"38130.2","s":11043},{"p":"38132.6","s":0}],"b":[{"p":"38117.9","s":2621},{"p":"38118.3","s":3606},{"p":"38123","s":0},{"p":"38123.7","s":0},{"p":"38122.2","s":0},{"p":"38121.1","s":26},{"p":"38118.6","s":15051}],"s":"BTC_USDT","t":1701245746578,"u":53095265566}}
{"time":1701245746,"time_ms":1701245746611,"channel":"futures.order_book_update","event":"update","result":{"U":53095265567,"a":[],"b":[{"p":"38121.1","s":28},{"p":"38123.7","s":2},{"p":"38123","s":2},{"p":"38122.2","s":2},{"p":"38118.6","s":0},{"p":"38117.9","s":0},{"p":"38118.3","s":0}],"s":"BTC_USDT","t":1701245746600,"u":53095265571}}
{"time":1701245746,"time_ms":1701245746633,"channel":"futures.order_book_update","event":"update","result":{"U":53095265572,"a":[{"p":"38125.1","s":175788},{"p":"38138","s":0}],"b":[{"p":"38112","s":0}],"s":"BTC_USDT","t":1701245746614,"u":53095265577}}
{"time":1701245746,"time_ms":1701245746653,"channel":"futures.order_book_update","event":"update","result":{"U":53095265578,"a":[],"b":[{"p":"38121.1","s":26},{"p":"38117.9","s":2621},{"p":"38118.3","s":3606},{"p":"38118.6","s":15051},{"p":"38123","s":0},{"p":"38123.7","s":0},{"p":"38122.2","s":0}],"s":"BTC_USDT","t":1701245746628,"u":53095265581}}
{"time":1701245746,"time_ms":1701245746672,"channel":"futures.order_book_update","event":"update","result":{"U":53095265582,"a":[],"b":[{"p":"38122.2","s":2},{"p":"38123","s":2},{"p":"38121.1","s":28},{"p":"38123.7","s":2},{"p":"38118.3","s":0},{"p":"38117.9","s":0},{"p":"38118.6","s":0}],"s":"BTC_USDT","t":1701245746655,"u":53095265585}}
{"time":1701245746,"time_ms":1701245746694,"channel":"futures.order_book_update","event":"update","result":{"U":53095265586,"a":[{"p":"38136.2","s":0}],"b":[],"s":"BTC_USDT","t":1701245746681,"u":53095265586}}
{"time":1701245746,"time_ms":1701245746712,"channel":"futures.order_book_update","event":"update","result":{"U":53095265587,"a":[{"p":"38125.5","s":549},{"p":"38130.6","s":0},{"p":"38132.6","s":0}],"b":[],"s":"BTC_USDT","t":1701245746690,"u":53095265588}}
{"time":1701245746,"time_ms":1701245746732,"channel":"futures.order_book_update","event":"update","result":{"U":53095265589,"a":[{"p":"38130.8","s":0},{"p":"38132.5","s":28862},{"p":"38131.8","s":3341}],"b":[],"s":"BTC_USDT","t":1701245746709,"u":53095265590}}
{"time":1701245746,"time_ms":1701245746775,"channel":"futures.order_book_update","event":"update","result":{"U":53095265591,"a":[],"b":[{"p":"38118.7","s":0},{"p":"38124.9","s":27500}],"s":"BTC_USDT","t":1701245746761,"u":53095265596}}
{"time":1701245746,"time_ms":1701245746795,"channel":"futures.order_book_update","event":"update","result":{"U":53095265597,"a":[],"b":[{"p":"38125","s":13855},{"p":"38117.2","s":0}],"s":"BTC_USDT","t":1701245746782,"u":53095265599}}
{"time":1701245746,"time_ms":1701245746812,"channel":"futures.order_book_update","event":"update","result":{"U":53095265600,"a":[{"p":"38152","s":0}],"b":[{"p":"38120.1","s":7243},{"p":"38103.2","s":0},{"p":"38111","s":0},{"p":"38113","s":0}],"s":"BTC_USDT","t":1701245746803,"u":53095265609}}
{"time":1701245746,"time_ms":1701245746833,"channel":"futures.order_book_update","event":"update","result":{"U":53095265610,"a":[{"p":"38125.1","s":171986}],"b":[{"p":"38125","s":28855},{"p":"38120.7","s":4083},{"p":"38112","s":0}],"s":"BTC_USDT","t":1701245746821,"u":53095265615}}
{"time":1701245746,"time_ms":1701245746852,"channel":"futures.order_book_update","event":"update","result":{"U":53095265616,"a":[{"p":"38125.1","s":163184}],"b":[],"s":"BTC_USDT","t":1701245746841,"u":53095265616}}
{"time":1701245746,"time_ms":1701245746873,"channel":"futures.order_book_update","event":"update","result":{"U":53095265617,"a":[],"b":[{"p":"38104","s":0},{"p":"38112.5","s":0},{"p":"38116.5","s":0}],"s":"BTC_USDT","t":1701245746851,"u":53095265622}}
{"time":1701245746,"time_ms":1701245746891,"channel":"futures.order_book_update","event":"update","result":{"U":53095265623,"a":[{"p":"38130.8","s":2175},{"p":"38129.7","s":0},{"p":"38136.9","s":0},{"p":"38132.6","s":0}],"b":[{"p":"38125","s":43855}],"s":"BTC_USDT","t":1701245746879,"u":53095265628}}
{"time":1701245746,"time_ms":1701245746913,"channel":"futures.order_book_update","event":"update","result":{"U":53095265629,"a":[{"p":"38154.4","s":0},{"p":"38146.8","s":0},{"p":"38150.6","s":0},{"p":"38143","s":0},{"p":"38135.9","s":0},{"p":"38133.2","s":0}],"b":[{"p":"38123.1","s":866},{"p":"38104.7","s":0},{"p":"38108.6","s":0},{"p":"38100.8","s":0}],"s":"BTC_USDT","t":1701245746900,"u":53095265638}}
{"time":1701245746,"time_ms":1701245746953,"channel":"futures.order_book_update","event":"update","result":{"U":53095265639,"a":[],"b":[{"p":"38120.1","s":11202}],"s":"BTC_USDT","t":1701245746933,"u":53095265640}}
{"time":1701245746,"time_ms":1701245746971,"channel":"futures.order_book_update","event":"update","result":{"U":53095265641,"a":[{"p":"38125.1","s":163334}],"b":[{"p":"38120.7","s":6215},{"p":"38125","s":57855}],"s":"BTC_USDT","t":1701245746956,"u":53095265644}}
{"time":1701245746,"time_ms":1701245746992,"channel":"futures.order_book_update","event":"update","result":{"U":53095265645,"a":[{"p":"38155.1","s":0},{"p":"38144.4","s":0}],"b":[{"p":"38118.7","s":2000},{"p":"38125","s":58422},{"p":"38121","s":0}],"s":"BTC_USDT","t":1701245746982,"u":53095265651}}
{"time":1701245747,"time_ms":1701245747011,"channel":"futures.order_book_update","event":"update","result":{"U":53095265652,"a":[],"b":[{"p":"38125","s":58830},{"p":"38118.6","s":15051},{"p":"38123.1","s":0},{"p":"38102.2","s":0}],"s":"BTC_USDT","t":1701245746995,"u":53095265656}}
{"time":1701245747,"time_ms":1701245747032,"channel":"futures.order_book_update","event":"update","result":{"U":53095265657,"a":[{"p":"38137.1","s":0},{"p":"38129.9","s":10849},{"p":"38131.7","s":2175},{"p":"38132.5","s":0},{"p":"38131.8","s":0},{"p":"38136.4","s":0},{"p":"38131.9","s":3434},{"p":"38130.1","s":2304},{"p":"38132.1","s":10848},{"p":"38132.9","s":0}],"b":[{"p":"38118.5","s":8917},{"p":"38124.9","s":0},{"p":"38113.2","s":0},{"p":"38108","s":0},{"p":"38113","s":0},{"p":"38115.1","s":0},{"p":"38108.1","s":0}],"s":"BTC_USDT","t":1701245747023,"u":53095265682}}
{"time":1701245747,"time_ms":1701245747053,"channel":"futures.order_book_update","event":"update","result":{"U":53095265683,"a":[{"p":"38137.5","s":0},{"p":"38133.5","s":0},{"p":"38131.9","s":93},{"p":"38132.4","s":0}],"b":[{"p":"38125","s":59867}],"s":"BTC_USDT","t":1701245747033,"u":53095265689}}
{"time":1701245747,"time_ms":1701245747073,"channel":"futures.order_book_update","event":"update","result":{"U":53095265690,"a":[{"p":"38131.9","s":2268},{"p":"38129.8","s":24677},{"p":"38131.7","s":0},{"p":"38130.2","s":0},{"p":"38132.5","s":0},{"p":"38132.1","s":10848},{"p":"38132.4","s":3341},{"p":"38130.7","s":2378},{"p":"38130.1","s":0}],"b":[],"s":"BTC_USDT","t":1701245747058,"u":53095265695}}
{"time":1701245747,"time_ms":1701245747092,"channel":"futures.order_book_update","event":"update","result":{"U":53095265696,"a":[{"p":"38130.9","s":3225},{"p":"38132.5","s":28862},{"p":"38130.8","s":0},{"p":"38135.6","s":0}],"b":[{"p":"38112.1","s":0},{"p":"38117.2","s":0},{"p":"38125","s":59867}],"s":"BTC_USDT","t":1701245747082,"u":53095265704}}
{"time":1701245747,"time_ms":1701245747112,"channel":"futures.order_book_update","event":"update","result":{"U":53095265705,"a":[{"p":"38130.1","s":2296},{"p":"38130.7","s":0},{"p":"38133.7","s":0},{"p":"38132.6","s":0}],"b":[{"p":"38112.4","s":0}],"s":"BTC_USDT","t":1701245747098,"u":53095265710}}
{"time":1701245747,"time_ms":1701245747172,"channel":"futures.order_book_update","event":"update","result":{"U":53095265711,"a":[{"p":"38137","s":0},{"p":"38133","s":0}],"b":[],"s":"BTC_USDT","t":1701245747151,"u":53095265716}}
{"time":1701245747,"time_ms":1701245747193,"channel":"futures.order_book_update","event":"update","result":{"U":53095265717,"a":[{"p":"38156.6","s":0},{"p":"38133.9","s":0}],"b":[{"p":"38123","s":0},{"p":"38118.3","s":3606},{"p":"38118","s":100},{"p":"38118.6","s":15000},{"p":"38117.9","s":2621},{"p":"38123.7","s":0},{"p":"38122.2","s":0}],"s":"BTC_USDT","t":1701245747175,"u":53095265722}}
{"time":1701245747,"time_ms":1701245747212,"channel":"futures.order_book_update","event":"update","result":{"U":53095265723,"a":[],"b":[{"p":"38121.1","s":26}],"s":"BTC_USDT","t":1701245747183,"u":53095265724}}
{"time":1701245747,"time_ms":1701245747253,"channel":"futures.order_book_update","event":"update","result":{"U":53095265725,"a":[{"p":"38131.9","s":4268}],"b":[],"s":"BTC_USDT","t":1701245747242,"u":53095265725}}
{"time":1701245747,"time_ms":1701245747294,"channel":"futures.order_book_update","event":"update","result":{"U":53095265726,"a":[{"p":"38135.3","s":0}],"b":[],"s":"BTC_USDT","t":1701245747284,"u":53095265730}}
{"time":1701245747,"time_ms":1701245747313,"channel":"futures.order_book_update","event":"update","result":{"U":53095265731,"a":[],"b":[{"p":"38125","s":45867}],"s":"BTC_USDT","t":1701245747295,"u":53095265731}}
{"time":1701245747,"time_ms":1701245747332,"channel":"futures.order_book_update","event":"update","result":{"U":53095265732,"a":[],"b":[{"p":"38099.8","s":0}],"s":"BTC_USDT","t":1701245747319,"u":53095265733}}
{"time":1701245747,"time_ms":1701245747352,"channel":"futures.order_book_update","event":"update","result":{"U":53095265734,"a":[{"p":"38125.5","s":1149},{"p":"38135.2","s":0}],"b":[{"p":"38125","s":15867}],"s":"BTC_USDT","t":1701245747342,"u":53095265738}}
{"time":1701245747,"time_ms":1701245747372,"channel":"futures.order_book_update","event":"update","result":{"U":53095265739,"a":[{"p":"38132.1","s":10850},{"p":"38134.4","s":0}],"b":[{"p":"38112.2","s":0}],"s":"BTC_USDT","t":1701245747362,"u":53095265743}}
{"time":1701245747,"time_ms":1701245747392,"channel":"futures.order_book_update","event":"update","result":{"U":53095265744,"a":[{"p":"38139.1","s":0},{"p":"38134.9","s":0}],"b":[{"p":"38118.6","s":15051}],"s":"BTC_USDT","t":1701245747382,"u":53095265749}}
