{"time":1701245715,"time_ms":1701245715035,"channel":"futures.order_book_update","event":"update","result":{"U":53095250148,"a":[{"p":"38162.4","s":0},{"p":"38157.6","s":0},{"p":"38150.7","s":1971},{"p":"38154.3","s":0},{"p":"38154.7","s":0},{"p":"38154","s":0}],"b":[{"p":"38138.5","s":0},{"p":"38139.3","s":0},{"p":"38139.2","s":0},{"p":"38140","s":1315},{"p":"38137.3","s":0},{"p":"38139.1","s":0}],"s":"BTC_USDT","t":1701245715028,"u":53095250168}}
{"time":1701245715,"time_ms":1701245715074,"channel":"futures.order_book_update","event":"update","result":{"U":53095250169,"a":[],"b":[{"p":"38140","s":1317}],"s":"BTC_USDT","t":1701245715060,"u":53095250172}}
{"time":1701245715,"time_ms":1701245715094,"channel":"futures.order_book_update","event":"update","result":{"U":53095250173,"a":[],"b":[{"p":"38139.3","s":2908},{"p":"38139.6","s":12912},{"p":"38139.7","s":0}],"s":"BTC_USDT","t":1701245715069,"u":53095250174}}
{"time":1701245715,"time_ms":1701245715152,"channel":"futures.order_book_update","event":"update","result":{"U":53095250175,"a":[{"p":"38154.1","s":0},{"p":"38150.7","s":1969},{"p":"38157.7","s":0}],"b":[{"p":"38138.5","s":0},{"p":"38132","s":0},{"p":"38140","s":1315},{"p":"38139.9","s":2},{"p":"38141.8","s":9024},{"p":"38141.1","s":2},{"p":"38139.5","s":0},{"p":"38139.4","s":0},{"p":"38142.6","s":2},{"p":"38139.3","s":0},{"p":"38137.3","s":0},{"p":"38138.2","s":0},{"p":"38139.2","s":0}],"s":"BTC_USDT","t":1701245715145,"u":53095250195}}
{"time":1701245715,"time_ms":1701245715172,"channel":"futures.order_book_update","event":"update","result":{"U":53095250196,"a":[{"p":"38152.7","s":0},{"p":"38152.2","s":0},{"p":"38154.5","s":0},{"p":"38156.8","s":0},{"p":"38154","s":0},{"p":"38153.6","s":0},{"p":"38154.3","s":0}],"b":[{"p":"38139.6","s":10602},{"p":"38135.2","s":0},{"p":"38134.3","s":0},{"p":"38137.9","s":0}],"s":"BTC_USDT","t":1701245715153,"u":53095250218}}
{"time":1701245715,"time_ms":1701245715213,"channel":"futures.order_book_update","event":"update","result":{"U":53095250219,"a":[{"p":"38154","s":0}],"b":[{"p":"38138.3","s":0}],"s":"BTC_USDT","t":1701245715192,"u":53095250222}}
{"time":1701245715,"time_ms":1701245715313,"channel":"futures.order_book_update","event":"update","result":{"U":53095250223,"a":[],"b":[{"p":"38139.5","s":8912},{"p":"38139.4","s":3641},{"p":"38139.2","s":1315},{"p":"38141.1","s":0},{"p":"38142.6","s":0},{"p":"38139.9","s":0},{"p":"38141.8","s":9022}],"s":"BTC_USDT","t":1701245715296,"u":53095250226}}
{"time":1701245715,"time_ms":1701245715332,"channel":"futures.order_book_update","event":"update","result":{"U":53095250227,"a":[{"p":"38145.7","s":23176}],"b":[{"p":"38139.4","s":0},{"p":"38139.2","s":0},{"p":"38142.6","s":2},{"p":"38139.9","s":2},{"p":"38141.8","s":9024},{"p":"38141.1","s":2},{"p":"38139.5","s":0}],"s":"BTC_USDT","t":1701245715321,"u":53095250231}}
{"time":1701245715,"time_ms":1701245715353,"channel":"futures.order_book_update","event":"update","result":{"U":53095250232,"a":[],"b":[{"p":"38137.5","s":0}],"s":"BTC_USDT","t":1701245715336,"u":53095250233}}
{"time":1701245715,"time_ms":1701245715415,"channel":"futures.order_book_update","event":"update","result":{"U":53095250234,"a":[],"b":[{"p":"38114.6","s":0}],"s":"BTC_USDT","t":1701245715404,"u":53095250234}}
{"time":1701245715,"time_ms":1701245715452,"channel":"futures.order_book_update","event":"update","result":{"U":53095250235,"a":[],"b":[{"p":"38136","s":0},{"p":"38141.8","s":9022},{"p":"38139.4","s":3641},{"p":"38139.5","s":8912},{"p":"38142.6","s":0},{"p":"38141.1","s":0}],"s":"BTC_USDT","t":1701245715438,"u":53095250238}}
{"time":1701245715,"time_ms":1701245715473,"channel":"futures.order_book_update","event":"update","result":{"U":53095250239,"a":[],"b":[{"p":"38142.6","s":2},{"p":"38141.8","s":9024},{"p":"38139.9","s":0},{"p":"38139.2","s":0}],"s":"BTC_USDT","t":1701245715453,"u":53095250241}}
{"time":1701245715,"time_ms":1701245715496,"channel":"futures.order_book_update","event":"update","result":{"U":53095250242,"a":[],"b":[{"p":"38139.5","s":0},{"p":"38139.4","s":0},{"p":"38141.1","s":2},{"p":"38139.9","s":2}],"s":"BTC_USDT","t":1701245715481,"u":53095250243}}
{"time":1701245715,"time_ms":1701245715513,"channel":"futures.order_book_update","event":"update","result":{"U":53095250244,"a":[],"b":[{"p":"38135.2","s":0}],"s":"BTC_USDT","t":1701245715497,"u":53095250245}}
{"time":1701245715,"time_ms":1701245715572,"channel":"futures.order_book_update","event":"update","result":{"U":53095250246,"a":[],"b":[{"p":"38138.2","s":0}],"s":"BTC_USDT","t":1701245715558,"u":53095250249}}
{"time":1701245715,"time_ms":1701245715652,"channel":"futures.order_book_update","event":"update","result":{"U":53095250250,"a":[],"b":[{"p":"38139.9","s":0},{"p":"38139.2","s":1315},{"p":"38141.8","s":9022},{"p":"38139.5","s":8912},{"p":"38139.4","s":3641},{"p":"38142.6","s":0},{"p":"38141.1","s":0}],"s":"BTC_USDT","t":1701245715642,"u":53095250253}}
{"time":1701245715,"time_ms":1701245715673,"channel":"futures.order_book_update","event":"update","result":{"U":53095250254,"a":[{"p":"38170.5","s":0}],"b":[],"s":"BTC_USDT","t":1701245715652,"u":53095250255}}
{"time":1701245715,"time_ms":1701245715693,"channel":"futures.order_book_update","event":"update","result":{"U":53095250256,"a":[],"b":[{"p":"38142.6","s":2},{"p":"38139.9","s":2},{"p":"38141.1","s":2},{"p":"38139.2","s":0},{"p":"38139.5","s":0},{"p":"38139.4","s":0},{"p":"38141.8","s":9024}],"s":"BTC_USDT","t":1701245715670,"u":53095250259}}
{"time":1701245715,"time_ms":1701245715832,"channel":"futures.order_book_update","event":"update","result":{"U":53095250260,"a":[{"p":"38157.5","s":0}],"b":[],"s":"BTC_USDT","t":1701245715802,"u":53095250261}}
{"time":1701245715,"time_ms":1701245715890,"channel":"futures.order_book_update","event":"update","result":{"U":53095250262,"a":[],"b":[{"p":"38100.3","s":0},{"p":"38134.9","s":0},{"p":"38145.6","s":96241}],"s":"BTC_USDT","t":1701245715884,"u":53095250266}}
{"time":1701245716,"time_ms":1701245716032,"channel":"futures.order_book_update","event":"update","result":{"U":53095250267,"a":[{"p":"38154","s":0},{"p":"38152.7","s":0},{"p":"38161.9","s":0},{"p":"38154.3","s":0},{"p":"38154.5","s":0}],"b":[{"p":"38131.8","s":0},{"p":"38139","s":0},{"p":"38139.5","s":8912},{"p":"38141.8","s":9022},{"p":"38139.4","s":1341},{"p":"38139.9","s":0},{"p":"38141.1","s":0},{"p":"38134.3","s":0}],"s":"BTC_USDT","t":1701245716026,"u":53095250293}}
{"time":1701245716,"time_ms":1701245716053,"channel":"futures.order_book_update","event":"update","result":{"U":53095250294,"a":[{"p":"38150.6","s":10842},{"p":"38153.3","s":0}],"b":[{"p":"38139.3","s":2305},{"p":"38142.6","s":0}],"s":"BTC_USDT","t":1701245716041,"u":53095250297}}
{"time":1701245716,"time_ms":1701245716074,"channel":"futures.order_book_update","event":"update","result":{"U":53095250298,"a":[],"b":[{"p":"38139.1","s":0},{"p":"38134.9","s":0},{"p":"38134.4","s":0},{"p":"38140","s":1317}],"s":"BTC_USDT","t":1701245716061,"u":53095250306}}
{"time":1701245716,"time_ms":1701245716092,"channel":"futures.order_book_update","event":"update","result":{"U":53095250307,"a":[],"b":[{"p":"38134.9","s":0},{"p":"38077.1","s":0}],"s":"BTC_USDT","t":1701245716078,"u":53095250309}}
{"time":1701245716,"time_ms":1701245716132,"channel":"futures.order_book_update","event":"update","result":{"U":53095250310,"a":[{"p":"38152.2","s":0}],"b":[{"p":"38139.2","s":1317},{"p":"38139.3","s":0},{"p":"38139","s":0},{"p":"38137.9","s":0},{"p":"38139.1","s":0}],"s":"BTC_USDT","t":1701245716123,"u":53095250319}}
{"time":1701245716,"time_ms":1701245716151,"channel":"futures.order_book_update","event":"update","result":{"U":53095250320,"a":[{"p":"38156.8","s":0}],"b":[],"s":"BTC_USDT","t":1701245716142,"u":53095250321}}
{"time":1701245716,"time_ms":1701245716171,"channel":"futures.order_book_update","event":"update","result":{"U":53095250322,"a":[{"p":"38156.4","s":0}],"b":[],"s":"BTC_USDT","t":1701245716150,"u":53095250323}}
{"time":1701245716,"time_ms":1701245716213,"channel":"futures.order_book_update","event":"update","result":{"U":53095250324,"a":[{"p":"38151.4","s":1859},{"p":"38153.6","s":0}],"b":[],"s":"BTC_USDT","t":1701245716188,"u":53095250326}}
{"time":1701245716,"time_ms":1701245716253,"channel":"futures.order_book_update","event":"update","result":{"U":53095250327,"a":[{"p":"38145.7","s":14676}],"b":[{"p":"38138.4","s":0},{"p":"38137.3","s":0},{"p":"38139.2","s":1315},{"p":"38140","s":1315}],"s":"BTC_USDT","t":1701245716236,"u":53095250333}}
{"time":1701245716,"time_ms":1701245716273,"channel":"futures.order_book_update","event":"update","result":{"U":53095250334,"a":[],"b":[{"p":"38140","s":1317},{"p":"38139.2","s":1317},{"p":"38112.6","s":0}],"s":"BTC_USDT","t":1701245716264,"u":53095250338}}
{"time":1701245716,"time_ms":1701245716293,"channel":"futures.order_book_update","event":"update","result":{"U":53095250339,"a":[{"p":"38153.3","s":0}],"b":[{"p":"38129.2","s":0}],"s":"BTC_USDT","t":1701245716280,"u":53095250342}}
{"time":1701245716,"time_ms":1701245716313,"channel":"futures.order_book_update","event":"update","result":{"U":53095250343,"a":[{"p":"38145.7","s":21676}],"b":[],"s":"BTC_USDT","t":1701245716296,"u":53095250343}}
{"time":1701245716,"time_ms":1701245716333,"channel":"futures.order_book_update","event":"update","result":{"U":53095250344,"a":[{"p":"38152.9","s":0}],"b":[],"s":"BTC_USDT","t":1701245716321,"u":53095250345}}
{"time":1701245716,"time_ms":1701245716351,"channel":"futures.order_book_update","event":"update","result":{"U":53095250346,"a":[{"p":"38161.7","s":0}],"b":[{"p":"38111","s":0},{"p":"38138.2","s":0},{"p":"38130","s":0}],"s":"BTC_USDT","t":1701245716341,"u":53095250355}}
{"time":1701245716,"time_ms":1701245716413,"channel":"futures.order_book_update","event":"update","result":{"U":53095250356,"a":[],"b":[{"p":"38086.9","s":0}],"s":"BTC_USDT","t":1701245716404,"u":53095250359}}
{"time":1701245716,"time_ms":1701245716451,"channel":"futures.order_book_update","event":"update","result":{"U":53095250360,"a":[],"b":[{"p":"38139.2","s":1315},{"p":"38140","s":1315},{"p":"38138.4","s":0}],"s":"BTC_USDT","t":1701245716446,"u":53095250362}}
{"time":1701245716,"time_ms":1701245716471,"channel":"futures.order_book_update","event":"update","result":{"U":53095250363,"a":[],"b":[{"p":"38137.3","s":0}],"s":"BTC_USDT","t":1701245716447,"u":53095250363}}
{"time":1701245716,"time_ms":1701245716493,"channel":"futures.order_book_update","event":"update","result":{"U":53095250364,"a":[],"b":[{"p":"38139.2","s":1317},{"p":"38140","s":1317}],"s":"BTC_USDT","t":1701245716470,"u":53095250367}}
{"time":1701245716,"time_ms":1701245716532,"channel":"futures.order_book_update","event":"update","result":{"U":53095250368,"a":[],"b":[{"p":"38140","s":1315},{"p":"38139.2","s":1315},{"p":"38137.3","s":0},{"p":"38138.4","s":0}],"s":"BTC_USDT","t":1701245716526,"u":53095250371}}
{"time":1701245716,"time_ms":1701245716575,"channel":"futures.order_book_update","event":"update","result":{"U":53095250372,"a":[],"b":[{"p":"38133.1","s":0}],"s":"BTC_USDT","t":1701245716551,"u":53095250375}}
{"time":1701245716,"time_ms":1701245716675,"channel":"futures.order_book_update","event":"update","result":{"U":53095250376,"a":[{"p":"38150.6","s":10840}],"b":[{"p":"38140","s":1317},{"p":"38139.2","s":1317}],"s":"BTC_USDT","t":1701245716658,"u":53095250380}}
{"time":1701245716,"time_ms":1701245716690,"channel":"futures.order_book_update","event":"update","result":{"U":53095250381,"a":[{"p":"38150.6","s":10842}],"b":[{"p":"38132","s":0}],"s":"BTC_USDT","t":1701245716675,"u":53095250382}}
{"time":1701245716,"time_ms":1701245716713,"channel":"futures.order_book_update","event":"update","result":{"U":53095250383,"a":[{"p":"38150.7","s":1315},{"p":"38149.9","s":30336}],"b":[{"p":"38132.1","s":0}],"s":"BTC_USDT","t":1701245716703,"u":53095250387}}
{"time":1701245716,"time_ms":1701245716733,"channel":"futures.order_book_update","event":"update","result":{"U":53095250388,"a":[{"p":"38145.7","s":14676},{"p":"38165.9","s":0}],"b":[{"p":"38119.9","s":0}],"s":"BTC_USDT","t":1701245716723,"u":53095250390}}
{"time":1701245716,"time_ms":1701245716751,"channel":"futures.order_book_update","event":"update","result":{"U":53095250391,"a":[{"p":"38154.1","s":0}],"b":[],"s":"BTC_USDT","t":1701245716729,"u":53095250392}}
{"time":1701245716,"time_ms":1701245716813,"channel":"futures.order_book_update","event":"update","result":{"U":53095250393,"a":[{"p":"38159","s":0}],"b":[{"p":"38144","s":100}],"s":"BTC_USDT","t":1701245716801,"u":53095250399}}
{"time":1701245716,"time_ms":1701245716832,"channel":"futures.order_book_update","event":"update","result":{"U":53095250400,"a":[],"b":[{"p":"38144","s":200}],"s":"BTC_USDT","t":1701245716823,"u":53095250403}}
{"time":1701245716,"time_ms":1701245716852,"channel":"futures.order_book_update","event":"update","result":{"U":53095250404,"a":[],"b":[{"p":"38134.4","s":0}],"s":"BTC_USDT","t":1701245716835,"u":53095250407}}
{"time":1701245716,"time_ms":1701245716872,"channel":"futures.order_book_update","event":"update","result":{"U":53095250408,"a":[],"b":[{"p":"38140","s":1315},{"p":"38139.2","s":1315},{"p":"38137.3","s":0}],"s":"BTC_USDT","t":1701245716859,"u":53095250410}}
{"time":1701245716,"time_ms":1701245716892,"channel":"futures.order_book_update","event":"update","result":{"U":53095250411,"a":[{"p":"38150.6","s":10840}],"b":[{"p":"38137.4","s":0},{"p":"38141.8","s":9024},{"p":"38142.6","s":2},{"p":"38139.2","s":0},{"p":"38139.4","s":0},{"p":"38138.4","s":0},{"p":"38137.9","s":0},{"p":"38141.1","s":2},{"p":"38139.9","s":2},{"p":"38139.5","s":0}],"s":"BTC_USDT","t":1701245716883,"u":53095250421}}
{"time":1701245716,"time_ms":1701245716976,"channel":"futures.order_book_update","event":"update","result":{"U":53095250422,"a":[],"b":[{"p":"38141.1","s":0},{"p":"38139.9","s":0},{"p":"38139.4","s":1341},{"p":"38139.2","s":1315},{"p":"38141.8","s":9022},{"p":"38139.5","s":8912},{"p":"38142.6","s":0}],"s":"BTC_USDT","t":1701245716951,"u":53095250427}}
{"time":1701245716,"time_ms":1701245716994,"channel":"futures.order_book_update","event":"update","result":{"U":53095250428,"a":[],"b":[{"p":"38139.9","s":2},{"p":"38142.6","s":2},{"p":"38139.4","s":0},{"p":"38139.2","s":0},{"p":"38139.5","s":0},{"p":"38141.1","s":2},{"p":"38141.8","s":9024}],"s":"BTC_USDT","t":1701245716972,"u":53095250431}}
{"time":1701245717,"time_ms":1701245717014,"channel":"futures.order_book_update","event":"update","result":{"U":53095250432,"a":[{"p":"38153.3","s":0},{"p":"38161.5","s":0}],"b":[],"s":"BTC_USDT","t":1701245717006,"u":53095250435}}
{"time":1701245717,"time_ms":1701245717031,"channel":"futures.order_book_update","event":"update","result":{"U":53095250436,"a":[{"p":"38152","s":0},{"p":"38153.3","s":0},{"p":"38151.8","s":0}],"b":[{"p":"38137.5","s":0},{"p":"38138.3","s":0}],"s":"BTC_USDT","t":1701245717021,"u":53095250445}}
{"time":1701245717,"time_ms":1701245717051,"channel":"futures.order_book_update","event":"update","result":{"U":53095250446,"a":[{"p":"38156.8","s":0}],"b":[],"s":"BTC_USDT","t":1701245717041,"u":53095250452}}
{"time":1701245717,"time_ms":1701245717071,"channel":"futures.order_book_update","event":"update","result":{"U":53095250453,"a":[],"b":[{"p":"38139.2","s":1315},{"p":"38141.1","s":0},{"p":"38142.6","s":0},{"p":"38139.9","s":0},{"p":"38139.5","s":8912},{"p":"38141.8","s":9022},{"p":"38139.4","s":1341}],"s":"BTC_USDT","t":1701245717048,"u":53095250457}}
{"time":1701245717,"time_ms":1701245717092,"channel":"futures.order_book_update","event":"update","result":{"U":53095250458,"a":[{"p":"38151.4","s":1230}],"b":[{"p":"38141.1","s":2},{"p":"38142.6","s":2},{"p":"38139.4","s":0},{"p":"38139.2","s":0},{"p":"38139.5","s":0},{"p":"38141.8","s":9024},{"p":"38139.9","s":2}],"s":"BTC_USDT","t":1701245717072,"u":53095250463}}
{"time":1701245717,"time_ms":1701245717112,"channel":"futures.order_book_update","event":"update","result":{"U":53095250464,"a":[{"p":"38153.9","s":0}],"b":[{"p":"38134","s":0},{"p":"38138.5","s":0},{"p":"38138.6","s":0},{"p":"38139.1","s":0}],"s":"BTC_USDT","t":1701245717104,"u":53095250472}}
{"time":1701245717,"time_ms":1701245717132,"channel":"futures.order_book_update","event":"update","result":{"U":53095250473,"a":[{"p":"38153.3","s":0}],"b":[{"p":"38138.7","s":0}],"s":"BTC_USDT","t":1701245717119,"u":53095250476}}
{"time":1701245717,"time_ms":1701245717312,"channel":"futures.order_book_update","event":"update","result":{"U":53095250477,"a":[{"p":"38145.7","s":21176}],"b":[],"s":"BTC_USDT","t":1701245717286,"u":53095250484}}
{"time":1701245717,"time_ms":1701245717352,"channel":"futures.order_book_update","event":"update","result":{"U":53095250485,"a":[{"p":"38165.9","s":0},{"p":"38160.6","s":0}],"b":[],"s":"BTC_USDT","t":1701245717341,"u":53095250488}}
{"time":1701245717,"time_ms":1701245717371,"channel":"futures.order_book_update","event":"update","result":{"U":53095250489,"a":[{"p":"38153.6","s":0},{"p":"38151.8","s":0},{"p":"38153","s":0},{"p":"38145.7","s":14676}],"b":[{"p":"38139.5","s":8912},{"p":"38139.2","s":1315},{"p":"38141.8","s":9022},{"p":"38139.9","s":0},{"p":"38142.6","s":0},{"p":"38141.1","s":0},{"p":"38133.7","s":0},{"p":"38139.4","s":1341}],"s":"BTC_USDT","t":1701245717349,"u":53095250501}}
{"time":1701245717,"time_ms":1701245717393,"channel":"futures.order_book_update","event":"update","result":{"U":53095250502,"a":[],"b":[{"p":"38139.5","s":0},{"p":"38141.1","s":2},{"p":"38142.6","s":2},{"p":"38139.9","s":2},{"p":"38141.8","s":9024},{"p":"38139.2","s":0},{"p":"38139.4","s":0}],"s":"BTC_USDT","t":1701245717368,"u":53095250505}}
{"time":1701245717,"time_ms":1701245717413,"channel":"futures.order_book_update","event":"update","result":{"U":53095250506,"a":[{"p":"38151.4","s":1946}],"b":[],"s":"BTC_USDT","t":1701245717390,"u":53095250506}}
{"time":1701245717,"time_ms":1701245717454,"channel":"futures.order_book_update","event":"update","result":{"U":53095250507,"a":[],"b":[{"p":"38134","s":0}],"s":"BTC_USDT","t":1701245717434,"u":53095250508}}
{"time":1701245717,"time_ms":1701245717472,"channel":"futures.order_book_update","event":"update","result":{"U":53095250509,"a":[{"p":"38159","s":0},{"p":"38155","s":0}],"b":[],"s":"BTC_USDT","t":1701245717458,"u":53095250512}}
{"time":1701245717,"time_ms":1701245717490,"channel":"futures.order_book_update","event":"update","result":{"U":53095250513,"a":[{"p":"38151.7","s":0},{"p":"38153.3","s":0},{"p":"38151.9","s":0},{"p":"38151.6","s":2174}],"b":[],"s":"BTC_USDT","t":1701245717479,"u":53095250515}}
{"time":1701245717,"time_ms":1701245717513,"channel":"futures.order_book_update","event":"update","result":{"U":53095250516,"a":[{"p":"38151.6","s":0},{"p":"38154.2","s":0},{"p":"38151.8","s":0},{"p":"38151.4","s":1230},{"p":"38151.7","s":1315}],"b":[],"s":"BTC_USDT","t":1701245717493,"u":53095250521}}
{"time":1701245717,"time_ms":1701245717533,"channel":"futures.order_book_update","event":"update","result":{"U":53095250522,"a":[{"p":"38151.4","s":635}],"b":[],"s":"BTC_USDT","t":1701245717515,"u":53095250522}}
{"time":1701245717,"time_ms":1701245717552,"channel":"futures.order_book_update","event":"update","result":{"U":53095250523,"a":[{"p":"38154.5","s":0},{"p":"38158.5","s":0}],"b":[],"s":"BTC_USDT","t":1701245717523,"u":53095250526}}
{"time":1701245717,"time_ms":1701245717571,"channel":"futures.order_book_update","event":"update","result":{"U":53095250527,"a":[],"b":[{"p":"38141.1","s":0},{"p":"38139.9","s":0},{"p":"38142.6","s":0},{"p":"38139.4","s":1341},{"p":"38141.8","s":9022},{"p":"38139.2","s":1315},{"p":"38139.5","s":8912}],"s":"BTC_USDT","t":1701245717545,"u":53095250530}}
{"time":1701245717,"time_ms":1701245717613,"channel":"futures.order_book_update","event":"update","result":{"U":53095250531,"a":[{"p":"38151.4","s":1233},{"p":"38154.3","s":0}],"b":[{"p":"38141.8","s":9024},{"p":"38139.9","s":2},{"p":"38141.1","s":2},{"p":"38142.6","s":2},{"p":"38139.5","s":0},{"p":"38139.4","s":0},{"p":"38139.2","s":0}],"s":"BTC_USDT","t":1701245717600,"u":53095250537}}
{"time":1701245717,"time_ms":1701245717633,"channel":"futures.order_book_update","event":"update","result":{"U":53095250538,"a":[],"b":[{"p":"38128","s":0},{"p":"38139.5","s":0},{"p":"38135.5","s":0}],"s":"BTC_USDT","t":1701245717610,"u":53095250540}}
{"time":1701245717,"time_ms":1701245717658,"channel":"futures.order_book_update","event":"update","result":{"U":53095250541,"a":[{"p":"38154","s":0},{"p":"38153.3","s":0},{"p":"38158","s":0}],"b":[],"s":"BTC_USDT","t":1701245717641,"u":53095250549}}
{"time":1701245717,"time_ms":1701245717693,"channel":"futures.order_book_update","event":"update","result":{"U":53095250550,"a":[{"p":"38154.5","s":0}],"b":[],"s":"BTC_USDT","t":1701245717683,"u":53095250551}}
{"time":1701245717,"time_ms":1701245717712,"channel":"futures.order_book_update","event":"update","result":{"U":53095250552,"a":[{"p":"38149.8","s":2174},{"p":"38151.7","s":0},{"p":"38158.5","s":0},{"p":"38152.8","s":0},{"p":"38151.8","s":0},{"p":"38156.4","s":0}],"b":[{"p":"38133.7","s":0},{"p":"38138.6","s":0},{"p":"38139","s":0},{"p":"38131.4","s":0}],"s":"BTC_USDT","t":1701245717698,"u":53095250568}}
{"time":1701245717,"time_ms":1701245717733,"channel":"futures.order_book_update","event":"update","result":{"U":53095250569,"a":[{"p":"38152.4","s":0}],"b":[{"p":"38139.5","s":0}],"s":"BTC_USDT","t":1701245717710,"u":53095250573}}
{"time":1701245717,"time_ms":1701245717753,"channel":"futures.order_book_update","event":"update","result":{"U":53095250574,"a":[{"p":"38145.7","s":44676}],"b":[{"p":"38145.6","s":106786}],"s":"BTC_USDT","t":1701245717746,"u":53095250576}}
{"time":1701245717,"time_ms":1701245717774,"channel":"futures.order_book_update","event":"update","result":{"U":53095250577,"a":[{"p":"38152.7","s":0},{"p":"38151.8","s":0},{"p":"38156","s":0},{"p":"38151.7","s":1315},{"p":"38149.8","s":0},{"p":"38152.6","s":0}],"b":[{"p":"38139.9","s":0},{"p":"38139.5","s":8912},{"p":"38139.2","s":1315},{"p":"38141.8","s":9022},{"p":"38139.4","s":1341},{"p":"38142.6","s":0},{"p":"38141.1","s":0}],"s":"BTC_USDT","t":1701245717766,"u":53095250588}}
{"time":1701245717,"time_ms":1701245717794,"channel":"futures.order_book_update","event":"update","result":{"U":53095250589,"a":[],"b":[{"p":"38139.9","s":2},{"p":"38141.1","s":2},{"p":"38139.5","s":0},{"p":"38139.2","s":0},{"p":"38139.4","s":0},{"p":"38141.8","s":9024},{"p":"38142.6","s":2}],"s":"BTC_USDT","t":1701245717782,"u":53095250592}}
{"time":1701245717,"time_ms":1701245717812,"channel":"futures.order_book_update","event":"update","result":{"U":53095250593,"a":[],"b":[{"p":"38145.6","s":106716},{"p":"38137.4","s":0}],"s":"BTC_USDT","t":1701245717796,"u":53095250595}}
{"time":1701245717,"time_ms":1701245717833,"channel":"futures.order_book_update","event":"update","result":{"U":53095250596,"a":[{"p":"38154","s":0},{"p":"38158","s":0}],"b":[],"s":"BTC_USDT","t":1701245717812,"u":53095250599}}
{"time":1701245717,"time_ms":1701245717933,"channel":"futures.order_book_update","event":"update","result":{"U":53095250600,"a":[],"b":[{"p":"38110.7","s":0}],"s":"BTC_USDT","t":1701245717916,"u":53095250602}}
{"time":1701245717,"time_ms":1701245717952,"channel":"futures.order_book_update","event":"update","result":{"U":53095250603,"a":[],"b":[{"p":"38138.2","s":0},{"p":"38145.6","s":97736}],"s":"BTC_USDT","t":1701245717942,"u":53095250606}}
{"time":1701245718,"time_ms":1701245718010,"channel":"futures.order_book_update","event":"update","result":{"U":53095250607,"a":[{"p":"38150.6","s":10842},{"p":"38153.3","s":0}],"b":[{"p":"38142.6","s":0},{"p":"38141.1","s":0},{"p":"38139.9","s":0},{"p":"38139.5","s":8912},{"p":"38139.2","s":1315},{"p":"38141.8","s":9022},{"p":"38139.4","s":1341}],"s":"BTC_USDT","t":1701245717999,"u":53095250613}}
{"time":1701245718,"time_ms":1701245718033,"channel":"futures.order_book_update","event":"update","result":{"U":53095250614,"a":[{"p":"38153.1","s":0},{"p":"38153.9","s":0},{"p":"38156.3","s":0},{"p":"38161.3","s":0}],"b":[{"p":"38138.3","s":0}],"s":"BTC_USDT","t":1701245718024,"u":53095250627}}
{"time":1701245718,"time_ms":1701245718052,"channel":"futures.order_book_update","event":"update","result":{"U":53095250628,"a":[{"p":"38152.9","s":0}],"b":[{"p":"38137.9","s":0}],"s":"BTC_USDT","t":1701245718032,"u":53095250631}}
{"time":1701245718,"time_ms":1701245718074,"channel":"futures.order_book_update","event":"update","result":{"U":53095250632,"a":[],"b":[{"p":"38139.9","s":2},{"p":"38139.2","s":0}],"s":"BTC_USDT","t":1701245718067,"u":53095250635}}
{"time":1701245718,"time_ms":1701245718093,"channel":"futures.order_book_update","event":"update","result":{"U":53095250636,"a":[{"p":"38151.6","s":2174},{"p":"38151.7","s":0},{"p":"38153.9","s":0},{"p":"38151.8","s":0}],"b":[{"p":"38145.6","s":97236},{"p":"38138.4","s":0},{"p":"38138.2","s":0},{"p":"38135.9","s":0}],"s":"BTC_USDT","t":1701245718086,"u":53095250647}}
{"time":1701245718,"time_ms":1701245718113,"channel":"futures.order_book_update","event":"update","result":{"U":53095250648,"a":[{"p":"38152.8","s":0}],"b":[],"s":"BTC_USDT","t":1701245718094,"u":53095250649}}
{"time":1701245718,"time_ms":1701245718131,"channel":"futures.order_book_update","event":"update","result":{"U":53095250650,"a":[{"p":"38153.6","s":0},{"p":"38152.6","s":0},{"p":"38152.7","s":0}],"b":[{"p":"38138.2","s":0}],"s":"BTC_USDT","t":1701245718117,"u":53095250657}}
{"time":1701245718,"time_ms":1701245718152,"channel":"futures.order_book_update","event":"update","result":{"U":53095250658,"a":[{"p":"38152.7","s":0}],"b":[],"s":"BTC_USDT","t":1701245718133,"u":53095250660}}
{"time":1701245718,"time_ms":1701245718174,"channel":"futures.order_book_update","event":"update","result":{"U":53095250661,"a":[],"b":[{"p":"38145.6","s":97236}],"s":"BTC_USDT","t":1701245718163,"u":53095250662}}
{"time":1701245718,"time_ms":1701245718191,"channel":"futures.order_book_update","event":"update","result":{"U":53095250663,"a":[{"p":"38152.4","s":0}],"b":[],"s":"BTC_USDT","t":1701245718168,"u":53095250664}}
{"time":1701245718,"time_ms":1701245718213,"channel":"futures.order_book_update","event":"update","result":{"U":53095250665,"a":[{"p":"38153.1","s":0}],"b":[{"p":"38145.6","s":96736}],"s":"BTC_USDT","t":1701245718196,"u":53095250667}}
{"time":1701245718,"time_ms":1701245718232,"channel":"futures.order_book_update","event":"update","result":{"U":53095250668,"a":[],"b":[{"p":"38128","s":0}],"s":"BTC_USDT","t":1701245718225,"u":53095250671}}
{"time":1701245718,"time_ms":1701245718253,"channel":"futures.order_book_update","event":"update","result":{"U":53095250672,"a":[],"b":[{"p":"38139.2","s":1315},{"p":"38139.9","s":0},{"p":"38138.4","s":0},{"p":"38137.3","s":0}],"s":"BTC_USDT","t":1701245718238,"u":53095250675}}
{"time":1701245718,"time_ms":1701245718273,"channel":"futures.order_book_update","event":"update","result":{"U":53095250676,"a":[],"b":[{"p":"38139.9","s":2},{"p":"38139.2","s":0}],"s":"BTC_USDT","t":1701245718263,"u":53095250679}}
{"time":1701245718,"time_ms":1701245718313,"channel":"futures.order_book_update","event":"update","result":{"U":53095250680,"a":[],"b":[{"p":"38145.6","s":96736}],"s":"BTC_USDT","t":1701245718289,"u":53095250683}}
{"time":1701245718,"time_ms":1701245718416,"channel":"futures.order_book_update","event":"update","result":{"U":53095250684,"a":[],"b":[{"p":"38145.6","s":96736},{"p":"38138.4","s":0},{"p":"38137.3","s":0},{"p":"38139.2","s":0}],"s":"BTC_USDT","t":1701245718398,"u":53095250690}}
{"time":1701245718,"time_ms":1701245718432,"channel":"futures.order_book_update","event":"update","result":{"U":53095250691,"a":[],"b":[{"p":"38139.2","s":1315},{"p":"38139.9","s":0}],"s":"BTC_USDT","t":1701245718401,"u":53095250691}}
{"time":1701245718,"time_ms":1701245718452,"channel":"futures.order_book_update","event":"update","result":{"U":53095250692,"a":[{"p":"38154.5","s":0},{"p":"38152.6","s":0},{"p":"38158.5","s":0}],"b":[],"s":"BTC_USDT","t":1701245718435,"u":53095250697}}
{"time":1701245718,"time_ms":1701245718501,"channel":"futures.order_book_update","event":"update","result":{"U":53095250698,"a":[{"p":"38156.2","s":0},{"p":"38151.8","s":0},{"p":"38151.7","s":1315},{"p":"38151.6","s":0},{"p":"38153.6","s":0}],"b":[{"p":"38139.2","s":0},{"p":"38137","s":0},{"p":"38138","s":0},{"p":"38139.9","s":2}],"s":"BTC_USDT","t":1701245718484,"u":53095250719}}
{"time":1701245718,"time_ms":1701245718512,"channel":"futures.order_book_update","event":"update","result":{"U":53095250720,"a":[{"p":"38155","s":0},{"p":"38151.8","s":0},{"p":"38151.4","s":1228},{"p":"38151.2","s":2179}],"b":[{"p":"38137.9","s":0},{"p":"38137.4","s":0}],"s":"BTC_USDT","t":1701245718498,"u":53095250729}}
{"time":1701245718,"time_ms":1701245718532,"channel":"futures.order_book_update","event":"update","result":{"U":53095250730,"a":[{"p":"38149.8","s":2174},{"p":"38151.2","s":5},{"p":"38151.7","s":0},{"p":"38152.6","s":0},{"p":"38152.8","s":0}],"b":[{"p":"38133.3","s":0},{"p":"38137.4","s":0},{"p":"38138.2","s":0}],"s":"BTC_USDT","t":1701245718517,"u":53095250741}}
{"time":1701245718,"time_ms":1701245718552,"channel":"futures.order_book_update","event":"update","result":{"U":53095250742,"a":[],"b":[{"p":"38130.6","s":0},{"p":"38137.9","s":0},{"p":"38132.8","s":0},{"p":"38135.9","s":0}],"s":"BTC_USDT","t":1701245718546,"u":53095250746}}
{"time":1701245718,"time_ms":1701245718573,"channel":"futures.order_book_update","event":"update","result":{"U":53095250747,"a":[{"p":"38155.7","s":0}],"b":[{"p":"38137.4","s":0}],"s":"BTC_USDT","t":1701245718550,"u":53095250753}}
{"time":1701245718,"time_ms":1701245718611,"channel":"futures.order_book_update","event":"update","result":{"U":53095250754,"a":[{"p":"38151.4","s":1945}],"b":[{"p":"38145.6","s":96736}],"s":"BTC_USDT","t":1701245718593,"u":53095250758}}
{"time":1701245718,"time_ms":1701245718652,"channel":"futures.order_book_update","event":"update","result":{"U":53095250759,"a":[{"p":"38150.6","s":10840}],"b":[{"p":"38139.2","s":1315},{"p":"38139.9","s":0},{"p":"38138.4","s":0},{"p":"38137.3","s":0}],"s":"BTC_USDT","t":1701245718637,"u":53095250763}}
{"time":1701245718,"time_ms":1701245718672,"channel":"futures.order_book_update","event":"update","result":{"U":53095250764,"a":[{"p":"38150.6","s":10842}],"b":[],"s":"BTC_USDT","t":1701245718653,"u":53095250764}}
{"time":1701245718,"time_ms":1701245718713,"channel":"futures.order_book_update","event":"update","result":{"U":53095250765,"a":[],"b":[{"p":"38145.6","s":96736}],"s":"BTC_USDT","t":1701245718692,"u":53095250768}}
{"time":1701245718,"time_ms":1701245718773,"channel":"futures.order_book_update","event":"update","result":{"U":53095250769,"a":[{"p":"38145.7","s":55886},{"p":"38170.8","s":0}],"b":[],"s":"BTC_USDT","t":1701245718758,"u":53095250771}}
{"time":1701245718,"time_ms":1701245718796,"channel":"futures.order_book_update","event":"update","result":{"U":53095250772,"a":[{"p":"38155","s":0},{"p":"38159","s":0}],"b":[{"p":"38145.6","s":80736},{"p":"38128.5","s":0}],"s":"BTC_USDT","t":1701245718788,"u":53095250779}}
{"time":1701245718,"time_ms":1701245718813,"channel":"futures.order_book_update","event":"update","result":{"U":53095250780,"a":[{"p":"38154.9","s":0}],"b":[{"p":"38145.6","s":80736},{"p":"38129.4","s":0}],"s":"BTC_USDT","t":1701245718803,"u":53095250785}}
{"time":1701245718,"time_ms":1701245718853,"channel":"futures.order_book_update","event":"update","result":{"U":53095250786,"a":[{"p":"38145.7","s":56036}],"b":[],"s":"BTC_USDT","t":1701245718834,"u":53095250788}}
{"time":1701245718,"time_ms":1701245718894,"channel":"futures.order_book_update","event":"update","result":{"U":53095250789,"a":[{"p":"38154.3","s":0}],"b":[{"p":"38145.6","s":80236}],"s":"BTC_USDT","t":1701245718885,"u":53095250791}}
{"time":1701245718,"time_ms":1701245718911,"channel":"futures.order_book_update","event":"update","result":{"U":53095250792,"a":[{"p":"38152.4","s":0},{"p":"38165.5","s":0},{"p":"38153","s":0},{"p":"38151.3","s":3617},{"p":"38146.9","s":0},{"p":"38151.4","s":1945},{"p":"38164.5","s":0},{"p":"38148.1","s":567},{"p":"38154.5","s":0},{"p":"38161.2","s":0},{"p":"38166.9","s":0},{"p":"38149.9","s":29682},{"p":"38145.7","s":90934},{"p":"38158.5","s":0},{"p":"38159.9","s":0},{"p":"38152.1","s":0},{"p":"38154.9","s":0}],"b":[{"p":"38138.4","s":78},{"p":"38138.8","s":143},{"p":"38140.5","s":0},{"p":"38135.5","s":0},{"p":"38145.6","s":6028},{"p":"38140","s":0},{"p":"38130.1","s":0},{"p":"38139.6","s":9287},{"p":"38141.4","s":0},{"p":"38137","s":0},{"p":"38135.6","s":0},{"p":"38141.5","s":0},{"p":"38145.3","s":3299},{"p":"38140.8","s":7555},{"p":"38137.9","s":1},{"p":"38139.5","s":0},{"p":"38144.2","s":0},{"p":"38139","s":0},{"p":"38137.8","s":0},{"p":"38130","s":0},{"p":"38139.2","s":0},{"p":"38139.4","s":26},{"p":"38141.7","s":26},{"p":"38138.1","s":9126},{"p":"38142.3","s":9017},{"p":"38132.3","s":0},{"p":"38139.8","s":2524},{"p":"38145.2","s":4512},{"p":"38141.8","s":0},{"p":"38128","s":0},{"p":"38137.5","s":0},{"p":"38141.9","s":221},{"p":"38138.9","s":7784},{"p":"38138","s":100},{"p":"38144","s":0},{"p":"38125.7","s":0},{"p":"38134.2","s":0}],"s":"BTC_USDT","t":1701245718898,"u":53095250882}}
{"time":1701245718,"time_ms":1701245718934,"channel":"futures.order_book_update","event":"update","result":{"U":53095250883,"a":[{"p":"38161.5","s":0},{"p":"38154.2","s":0},{"p":"38151.3","s":0},{"p":"38181.1","s":0},{"p":"38151.9","s":0},{"p":"38154.4","s":0},{"p":"38153.7","s":0},{"p":"38151.7","s":0},{"p":"38148.7","s":0},{"p":"38147.7","s":0},{"p":"38158","s":0},{"p":"38154.9","s":0},{"p":"38173.6","s":0},{"p":"38154.8","s":0},{"p":"38192.1","s":0},{"p":"38154.3","s":0},{"p":"38150.9","s":5258},{"p":"38151.4","s":0},{"p":"38161.3","s":0},{"p":"38150.5","s":2174},{"p":"38147.9","s":1},{"p":"38155.1","s":0},{"p":"38154.1","s":0},{"p":"38168.1","s":0},{"p":"38155.3","s":0},{"p":"38147.2","s":3340},{"p":"38149.8","s":0},{"p":"38153.4","s":0},{"p":"38153.8","s":0},{"p":"38148.1","s":4915},{"p":"38155.2","s":0},{"p":"38154.5","s":0},{"p":"38153.6","s":0},{"p":"38151","s":8916},{"p":"38155.8","s":0},{"p":"38154","s":0}],"b":[{"p":"38145.3","s":0},{"p":"38136.8","s":20384},{"p":"38130.4","s":0},{"p":"38137.4","s":0},{"p":"38137.3","s":4168},{"p":"38145.6","s":3928},{"p":"38099.6","s":0},{"p":"38123.6","s":0},{"p":"38077","s":0},{"p":"38133.1","s":0},{"p":"38138.9","s":4183},{"p":"38139","s":100},{"p":"38138.4","s":0},{"p":"38136.9","s":3633},{"p":"38129.9","s":0},{"p":"38136.4","s":0},{"p":"38140.8","s":0},{"p":"38134.4","s":0},{"p":"38144.3","s":0},{"p":"38142.3","s":0},{"p":"38055.1","s":0},{"p":"38137.9","s":1},{"p":"38133.3","s":0},{"p":"38142.2","s":0},{"p":"38137.8","s":15208},{"p":"38129","s":0},{"p":"38135.2","s":0},{"p":"38111.4","s":0},{"p":"38135.9","s":0},{"p":"38136.5","s":0},{"p":"38124.5","s":0},{"p":"38140.9","s":4536},{"p":"38134.1","s":0}],"s":"BTC_USDT","t":1701245718919,"u":53095251020}}
{"time":1701245718,"time_ms":1701245718954,"channel":"futures.order_book_update","event":"update","result":{"U":53095251021,"a":[{"p":"38154.9","s":0},{"p":"38151.3","s":0},{"p":"38171.8","s":0},{"p":"38145.7","s":107833},{"p":"38147.2","s":6449},{"p":"38147.9","s":0},{"p":"38169.4","s":0},{"p":"38151.4","s":0},{"p":"38174.4","s":0},{"p":"38146","s":524},{"p":"38148","s":2614},{"p":"38160.9","s":0},{"p":"38153.3","s":0},{"p":"38156.2","s":0},{"p":"38146.8","s":2174},{"p":"38151.1","s":0},{"p":"38151.2","s":0},{"p":"38152.3","s":0},{"p":"38169.3","s":0},{"p":"38156.3","s":0},{"p":"38148.1","s":2174},{"p":"38157","s":0},{"p":"38161.3","s":0},{"p":"38169.2","s":0},{"p":"38161.6","s":0}],"b":[{"p":"38139.6","s":3932},{"p":"38136.4","s":0},{"p":"38107.1","s":0},{"p":"38104.6","s":0},{"p":"38136.8","s":17764},{"p":"38132.7","s":0},{"p":"38118.1","s":0},{"p":"38135.2","s":0},{"p":"38123.9","s":0},{"p":"38131.9","s":0},{"p":"38136.6","s":418},{"p":"38138","s":0},{"p":"38135.1","s":0},{"p":"38136.7","s":17824},{"p":"38139","s":0},{"p":"38138.5","s":0},{"p":"38127.9","s":0},{"p":"38131.2","s":0},{"p":"38129.5","s":0},{"p":"38131.7","s":0},{"p":"38126.5","s":0},{"p":"38133","s":0},{"p":"38119.5","s":0},{"p":"38112.6","s":0},{"p":"38129","s":0},{"p":"38132.2","s":0},{"p":"38145.6","s":2926},{"p":"38139.8","s":524},{"p":"38140.9","s":0},{"p":"38138.4","s":600}],"s":"BTC_USDT","t":1701245718942,"u":53095251112}}
{"time":1701245718,"time_ms":1701245718973,"channel":"futures.order_book_update","event":"update","result":{"U":53095251113,"a":[{"p":"38150.6","s":10840},{"p":"38163.9","s":0},{"p":"38152.9","s":0},{"p":"38148.3","s":2},{"p":"38150.5","s":0},{"p":"38154.6","s":0},{"p":"38170.4","s":0},{"p":"38165.7","s":0},{"p":"38147.2","s":3109},{"p":"38149.7","s":733},{"p":"38148.1","s":7864},{"p":"38150.9","s":5258},{"p":"38157.8","s":0},{"p":"38159.2","s":0},{"p":"38145.7","s":120677},{"p":"38146.9","s":2248},{"p":"38151","s":0},{"p":"38150.7","s":1315},{"p":"38146.7","s":0},{"p":"38168.3","s":0},{"p":"38146","s":0},{"p":"38153","s":0},{"p":"38169.4","s":0}],"b":[{"p":"38137.3","s":236},{"p":"38138.4","s":0},{"p":"38141.9","s":0},{"p":"38129.4","s":0},{"p":"38135.8","s":0},{"p":"38137.2","s":524},{"p":"38112.6","s":0},{"p":"38132.8","s":0},{"p":"38138.3","s":600},{"p":"38139.6","s":0},{"p":"38123.7","s":0},{"p":"38127","s":0},{"p":"38133.7","s":0},{"p":"38136.2","s":0},{"p":"38136.4","s":0},{"p":"38127.6","s":0},{"p":"38145.2","s":3857},{"p":"38139.7","s":4949},{"p":"38133.3","s":0},{"p":"38134.3","s":0},{"p":"38132.9","s":0}],"s":"BTC_USDT","t":1701245718962,"u":53095251176}}
{"time":1701245718,"time_ms":1701245718993,"channel":"futures.order_book_update","event":"update","result":{"U":53095251177,"a":[{"p":"38145.7","s":124888},{"p":"38146.9","s":74},{"p":"38150.9","s":5258},{"p":"38169.3","s":0},{"p":"38162.2","s":0},{"p":"38164.4","s":0},{"p":"38148","s":6871},{"p":"38168.8","s":0},{"p":"38159.3","s":0},{"p":"38155.5","s":0},{"p":"38146.4","s":3340},{"p":"38148.3","s":0},{"p":"38163.1","s":0},{"p":"38163","s":0}],"b":[{"p":"38137.5","s":2000},{"p":"38139.7","s":0},{"p":"38134.5","s":0},{"p":"38036.4","s":0},{"p":"38134.3","s":0},{"p":"38125.3","s":0},{"p":"38136.7","s":9960},{"p":"38132.4","s":0},{"p":"38134.1","s":0},{"p":"38131.4","s":0},{"p":"38139.8","s":131},{"p":"38138.3","s":0},{"p":"38136.6","s":418},{"p":"38126.9","s":0},{"p":"38126.6","s":0},{"p":"38139","s":2595},{"p":"38133.1","s":0}],"s":"BTC_USDT","t":1701245718982,"u":53095251229}}
{"time":1701245719,"time_ms":1701245719012,"channel":"futures.order_book_update","event":"update","result":{"U":53095251230,"a":[{"p":"38146.4","s":0},{"p":"38153.4","s":0},{"p":"38151","s":8916},{"p":"38151.1","s":1315},{"p":"38146.8","s":0},{"p":"38190.3","s":0},{"p":"38177.3","s":0},{"p":"38145.7","s":140363},{"p":"38155","s":0},{"p":"38158.7","s":0}],"b":[{"p":"38092.4","s":0},{"p":"38128.4","s":0},{"p":"38133","s":0},{"p":"38104.6","s":0},{"p":"38107.4","s":0},{"p":"38145.6","s":2426},{"p":"38137.3","s":237},{"p":"38136.8","s":14791},{"p":"38134","s":0},{"p":"38127.3","s":0},{"p":"38126.6","s":0},{"p":"38126.7","s":0},{"p":"38128.3","s":0}],"s":"BTC_USDT","t":1701245719000,"u":53095251274}}
{"time":1701245719,"time_ms":1701245719034,"channel":"futures.order_book_update","event":"update","result":{"U":53095251275,"a":[{"p":"38151.1","s":0},{"p":"38152.8","s":0},{"p":"38151.2","s":0},{"p":"38155","s":0},{"p":"38148","s":4257},{"p":"38145.7","s":138689},{"p":"38149.7","s":0},{"p":"38178.8","s":0},{"p":"38149.8","s":0},{"p":"38148.7","s":733},{"p":"38151","s":3},{"p":"38146.3","s":2174}],"b":[{"p":"38134.1","s":0},{"p":"38132.2","s":0},{"p":"38135.6","s":0},{"p":"38134.8","s":0},{"p":"38133.1","s":0},{"p":"38132.9","s":0},{"p":"38131.4","s":0},{"p":"38130.6","s":0}],"s":"BTC_USDT","t":1701245719026,"u":53095251310}}
{"time":1701245719,"time_ms":1701245719053,"channel":"futures.order_book_update","event":"update","result":{"U":53095251311,"a":[{"p":"38147.9","s":2312},{"p":"38149.4","s":2116},{"p":"38151","s":0},{"p":"38155.9","s":0},{"p":"38146.3","s":2174},{"p":"38145.7","s":136515},{"p":"38150.9","s":0},{"p":"38155.8","s":0},{"p":"38151.3","s":0}],"b":[{"p":"38141.7","s":15026},{"p":"38140.4","s":0},{"p":"38133.3","s":0},{"p":"38145.6","s":1956},{"p":"38136.8","s":5978},{"p":"38136.4","s":2621},{"p":"38117.7","s":0},{"p":"38132.8","s":0},{"p":"38131.4","s":0},{"p":"38132.9","s":0}],"s":"BTC_USDT","t":1701245719046,"u":53095251345}}
{"time":1701245719,"time_ms":1701245719074,"channel":"futures.order_book_update","event":"update","result":{"U":53095251346,"a":[{"p":"38150.9","s":5258},{"p":"38149.6","s":773},{"p":"38148.7","s":0},{"p":"38146.9","s":2248}],"b":[{"p":"38125.5","s":0},{"p":"38141.8","s":9020},{"p":"38139","s":0},{"p":"38034.5","s":0},{"p":"38132.9","s":0},{"p":"38136.2","s":0}],"s":"BTC_USDT","t":1701245719060,"u":53095251364}}
{"time":1701245719,"time_ms":1701245719093,"channel":"futures.order_book_update","event":"update","result":{"U":53095251365,"a":[],"b":[{"p":"38133.6","s":0},{"p":"38131.7","s":0},{"p":"38134.4","s":0},{"p":"38132.9","s":0}],"s":"BTC_USDT","t":1701245719083,"u":53095251377}}
{"time":1701245719,"time_ms":1701245719111,"channel":"futures.order_book_update","event":"update","result":{"U":53095251378,"a":[{"p":"38148.7","s":3932},{"p":"38150.9","s":0},{"p":"38154","s":0},{"p":"38146.3","s":2174},{"p":"38151","s":0},{"p":"38146.9","s":74},{"p":"38145.7","s":143334},{"p":"38153.7","s":0},{"p":"38154.3","s":0}],"b":[{"p":"38136.2","s":15},{"p":"38136.8","s":0},{"p":"38132.8","s":0},{"p":"38138.9","s":550},{"p":"38125.6","s":0},{"p":"38133.4","s":0},{"p":"38127.4","s":0},{"p":"38126","s":0},{"p":"38127.5","s":0}],"s":"BTC_USDT","t":1701245719102,"u":53095251405}}
{"time":1701245719,"time_ms":1701245719133,"channel":"futures.order_book_update","event":"update","result":{"U":53095251406,"a":[{"p":"38150.9","s":0},{"p":"38190.1","s":0},{"p":"38169.8","s":0},{"p":"38155.5","s":0},{"p":"38162.5","s":0},{"p":"38146.8","s":2174},{"p":"38146.3","s":0},{"p":"38151.5","s":0}],"b":[{"p":"38133","s":0},{"p":"38136.5","s":8913},{"p":"38138.9","s":0},{"p":"38133.4","s":0},{"p":"38127.2","s":0},{"p":"38132.2","s":0},{"p":"38135.4","s":0}],"s":"BTC_USDT","t":1701245719124,"u":53095251444}}
{"time":1701245719,"time_ms":1701245719155,"channel":"futures.order_book_update","event":"update","result":{"U":53095251445,"a":[{"p":"38149","s":15966},{"p":"38150.7","s":0}],"b":[{"p":"38130.6","s":0},{"p":"38079.5","s":0},{"p":"38134.8","s":0},{"p":"38132.2","s":0},{"p":"38131.8","s":0},{"p":"38118.9","s":0}],"s":"BTC_USDT","t":1701245719139,"u":53095251456}}
{"time":1701245719,"time_ms":1701245719175,"channel":"futures.order_book_update","event":"update","result":{"U":53095251457,"a":[{"p":"38148.7","s":4665},{"p":"38149.6","s":40}],"b":[{"p":"38131.4","s":0},{"p":"38130.3","s":0},{"p":"38133","s":0},{"p":"38128.5","s":0},{"p":"38121.7","s":0},{"p":"38132.2","s":0},{"p":"38102.1","s":0},{"p":"38125.1","s":0}],"s":"BTC_USDT","t":1701245719166,"u":53095251478}}
{"time":1701245719,"time_ms":1701245719191,"channel":"futures.order_book_update","event":"update","result":{"U":53095251479,"a":[{"p":"38145.7","s":153331}],"b":[{"p":"38071.8","s":0}],"s":"BTC_USDT","t":1701245719181,"u":53095251482}}
{"time":1701245719,"time_ms":1701245719215,"channel":"futures.order_book_update","event":"update","result":{"U":53095251483,"a":[{"p":"38149.3","s":733},{"p":"38150.6","s":0},{"p":"38168.5","s":0},{"p":"38151.2","s":0},{"p":"38150.5","s":0},{"p":"38148.7","s":3932},{"p":"38145.7","s":147817}],"b":[{"p":"38071.9","s":0},{"p":"38133.8","s":0},{"p":"38130.6","s":0},{"p":"38131.4","s":0},{"p":"38137.3","s":1},{"p":"38145.6","s":1372}],"s":"BTC_USDT","t":1701245719198,"u":53095251501}}
{"time":1701245719,"time_ms":1701245719232,"channel":"futures.order_book_update","event":"update","result":{"U":53095251502,"a":[{"p":"38155","s":0},{"p":"38150","s":61061},{"p":"38163.9","s":0},{"p":"38146.2","s":0},{"p":"38146.7","s":2174},{"p":"38146.4","s":3340},{"p":"38149.3","s":0},{"p":"38150.2","s":0}],"b":[{"p":"38132.1","s":0},{"p":"38141.9","s":592},{"p":"38136.2","s":0},{"p":"38106.5","s":0},{"p":"38132.9","s":0}],"s":"BTC_USDT","t":1701245719218,"u":53095251517}}
{"time":1701245719,"time_ms":1701245719251,"channel":"futures.order_book_update","event":"update","result":{"U":53095251518,"a":[{"p":"38150.2","s":0},{"p":"38146.7","s":2174}],"b":[{"p":"38141.7","s":26}],"s":"BTC_USDT","t":1701245719243,"u":53095251523}}
{"time":1701245719,"time_ms":1701245719273,"channel":"futures.order_book_update","event":"update","result":{"U":53095251524,"a":[{"p":"38145.7","s":153332},{"p":"38150.5","s":798},{"p":"38150.2","s":2},{"p":"38146.7","s":0},{"p":"38146.4","s":0}],"b":[{"p":"38136.2","s":0},{"p":"38142","s":5738},{"p":"38141.8","s":0},{"p":"38131.5","s":0}],"s":"BTC_USDT","t":1701245719259,"u":53095251536}}
{"time":1701245719,"time_ms":1701245719292,"channel":"futures.order_book_update","event":"update","result":{"U":53095251537,"a":[{"p":"38145.7","s":149989},{"p":"38146.4","s":7272},{"p":"38150.5","s":0},{"p":"38165.8","s":0}],"b":[{"p":"38136.2","s":15},{"p":"38142","s":371},{"p":"38136.5","s":0},{"p":"38124.5","s":0},{"p":"38132.5","s":0}],"s":"BTC_USDT","t":1701245719282,"u":53095251548}}
{"time":1701245719,"time_ms":1701245719313,"channel":"futures.order_book_update","event":"update","result":{"U":53095251549,"a":[{"p":"38145.7","s":147817},{"p":"38146.7","s":2174},{"p":"38150.2","s":0}],"b":[{"p":"38136.2","s":15},{"p":"38123.6","s":0},{"p":"38144.1","s":0}],"s":"BTC_USDT","t":1701245719303,"u":53095251556}}
{"time":1701245719,"time_ms":1701245719354,"channel":"futures.order_book_update","event":"update","result":{"U":53095251557,"a":[],"b":[{"p":"38141.7","s":15026}],"s":"BTC_USDT","t":1701245719340,"u":53095251558}}
{"time":1701245719,"time_ms":1701245719371,"channel":"futures.order_book_update","event":"update","result":{"U":53095251559,"a":[{"p":"38150.2","s":0},{"p":"38145.7","s":147847},{"p":"38148.6","s":2375},{"p":"38147.8","s":2174},{"p":"38147.9","s":0},{"p":"38146.8","s":0},{"p":"38150.5","s":0},{"p":"38150.6","s":0}],"b":[{"p":"38142","s":9327},{"p":"38134.1","s":0},{"p":"38132.2","s":0},{"p":"38126.7","s":0},{"p":"38145.6","s":7110}],"s":"BTC_USDT","t":1701245719366,"u":53095251603}}
{"time":1701245719,"time_ms":1701245719395,"channel":"futures.order_book_update","event":"update","result":{"U":53095251604,"a":[{"p":"38160.9","s":0}],"b":[{"p":"38136.5","s":8913},{"p":"38136.2","s":0},{"p":"38130.7","s":0},{"p":"38035.1","s":0}],"s":"BTC_USDT","t":1701245719385,"u":53095251613}}
{"time":1701245719,"time_ms":1701245719412,"channel":"futures.order_book_update","event":"update","result":{"U":53095251614,"a":[{"p":"38146.9","s":3414},{"p":"38146.4","s":3932}],"b":[],"s":"BTC_USDT","t":1701245719389,"u":53095251615}}
{"time":1701245719,"time_ms":1701245719452,"channel":"futures.order_book_update","event":"update","result":{"U":53095251616,"a":[],"b":[{"p":"38131.7","s":0},{"p":"38134.4","s":0},{"p":"38132.9","s":0},{"p":"38145.6","s":7035},{"p":"38133.6","s":0}],"s":"BTC_USDT","t":1701245719436,"u":53095251620}}
{"time":1701245719,"time_ms":1701245719473,"channel":"futures.order_book_update","event":"update","result":{"U":53095251621,"a":[{"p":"38148.6","s":4476},{"p":"38148.8","s":1256},{"p":"38148.7","s":4326},{"p":"38157.5","s":0},{"p":"38153.5","s":0}],"b":[{"p":"38136.2","s":15},{"p":"38136.5","s":0},{"p":"38132.5","s":0},{"p":"38124.5","s":0}],"s":"BTC_USDT","t":1701245719460,"u":53095251641}}
{"time":1701245719,"time_ms":1701245719494,"channel":"futures.order_book_update","event":"update","result":{"U":53095251642,"a":[{"p":"38158","s":0},{"p":"38154","s":0}],"b":[],"s":"BTC_USDT","t":1701245719474,"u":53095251646}}
{"time":1701245719,"time_ms":1701245719511,"channel":"futures.order_book_update","event":"update","result":{"U":53095251647,"a":[{"p":"38156.8","s":0},{"p":"38165.8","s":0},{"p":"38148.7","s":4851},{"p":"38145.7","s":147845},{"p":"38148.8","s":1781},{"p":"38149.1","s":527},{"p":"38150","s":0}],"b":[{"p":"38131.7","s":0},{"p":"38132.9","s":0},{"p":"38138","s":200},{"p":"38136.4","s":0},{"p":"38133","s":0},{"p":"38135.7","s":0},{"p":"38137.6","s":2},{"p":"38136.6","s":0},{"p":"38136.9","s":3635},{"p":"38136.2","s":0},{"p":"38133.6","s":0},{"p":"38134.4","s":0},{"p":"38138.4","s":2},{"p":"38145.6","s":2605}],"s":"BTC_USDT","t":1701245719502,"u":53095251682}}
{"time":1701245719,"time_ms":1701245719534,"channel":"futures.order_book_update","event":"update","result":{"U":53095251683,"a":[],"b":[{"p":"38132","s":0}],"s":"BTC_USDT","t":1701245719504,"u":53095251684}}
{"time":1701245719,"time_ms":1701245719551,"channel":"futures.order_book_update","event":"update","result":{"U":53095251685,"a":[{"p":"38148.6","s":4870}],"b":[],"s":"BTC_USDT","t":1701245719542,"u":53095251685}}
{"time":1701245719,"time_ms":1701245719610,"channel":"futures.order_book_update","event":"update","result":{"U":53095251686,"a":[{"p":"38157.5","s":0},{"p":"38165.5","s":0},{"p":"38153.5","s":0}],"b":[],"s":"BTC_USDT","t":1701245719597,"u":53095251696}}
{"time":1701245719,"time_ms":1701245719632,"channel":"futures.order_book_update","event":"update","result":{"U":53095251697,"a":[{"p":"38156.8","s":0}],"b":[{"p":"38140.9","s":0},{"p":"38136.7","s":9960}],"s":"BTC_USDT","t":1701245719620,"u":53095251700}}
{"time":1701245719,"time_ms":1701245719653,"channel":"futures.order_book_update","event":"update","result":{"U":53095251701,"a":[{"p":"38145.9","s":655},{"p":"38149.9","s":0}],"b":[{"p":"38124.4","s":0}],"s":"BTC_USDT","t":1701245719629,"u":53095251702}}
{"time":1701245719,"time_ms":1701245719672,"channel":"futures.order_book_update","event":"update","result":{"U":53095251703,"a":[{"p":"38158.4","s":0}],"b":[],"s":"BTC_USDT","t":1701245719657,"u":53095251704}}
{"time":1701245719,"time_ms":1701245719713,"channel":"futures.order_book_update","event":"update","result":{"U":53095251705,"a":[],"b":[{"p":"38137.6","s":0},{"p":"38135.7","s":0},{"p":"38136.6","s":418},{"p":"38136.5","s":8913},{"p":"38136.9","s":3633},{"p":"38138.4","s":0}],"s":"BTC_USDT","t":1701245719694,"u":53095251711}}
{"time":1701245719,"time_ms":1701245719731,"channel":"futures.order_book_update","event":"update","result":{"U":53095251712,"a":[],"b":[{"p":"38136.5","s":0},{"p":"38137.6","s":2},{"p":"38136.9","s":3635},{"p":"38138.4","s":2},{"p":"38136.6","s":0}],"s":"BTC_USDT","t":1701245719721,"u":53095251715}}
{"time":1701245719,"time_ms":1701245719811,"channel":"futures.order_book_update","event":"update","result":{"U":53095251716,"a":[{"p":"38153.5","s":0},{"p":"38157.5","s":0}],"b":[{"p":"38137.5","s":10913},{"p":"38132.5","s":0},{"p":"38136.5","s":0},{"p":"38127.7","s":0}],"s":"BTC_USDT","t":1701245719794,"u":53095251726}}
{"time":1701245719,"time_ms":1701245719871,"channel":"futures.order_book_update","event":"update","result":{"U":53095251727,"a":[],"b":[{"p":"38132.6","s":0},{"p":"38127.2","s":0},{"p":"38124","s":0},{"p":"38133.4","s":0}],"s":"BTC_USDT","t":1701245719860,"u":53095251736}}
{"time":1701245719,"time_ms":1701245719932,"channel":"futures.order_book_update","event":"update","result":{"U":53095251737,"a":[{"p":"38154.5","s":0},{"p":"38158.5","s":0}],"b":[{"p":"38133.5","s":0},{"p":"38137.5","s":2000}],"s":"BTC_USDT","t":1701245719922,"u":53095251750}}
{"time":1701245719,"time_ms":1701245719953,"channel":"futures.order_book_update","event":"update","result":{"U":53095251751,"a":[{"p":"38145.7","s":148369},{"p":"38154","s":0}],"b":[{"p":"38140.1","s":655},{"p":"38136.7","s":0}],"s":"BTC_USDT","t":1701245719947,"u":53095251758}}
{"time":1701245719,"time_ms":1701245719977,"channel":"futures.order_book_update","event":"update","result":{"U":53095251759,"a":[],"b":[{"p":"38138.9","s":3633},{"p":"38136.9","s":0}],"s":"BTC_USDT","t":1701245719954,"u":53095251760}}
{"time":1701245719,"time_ms":1701245719993,"channel":"futures.order_book_update","event":"update","result":{"U":53095251761,"a":[{"p":"38175.3","s":0}],"b":[{"p":"38139","s":2183},{"p":"38137.2","s":0},{"p":"38122.5","s":0}],"s":"BTC_USDT","t":1701245719976,"u":53095251763}}
{"time":1701245720,"time_ms":1701245720033,"channel":"futures.order_book_update","event":"update","result":{"U":53095251764,"a":[{"p":"38155.5","s":0},{"p":"38148.5","s":2366},{"p":"38146.8","s":2174},{"p":"38147.9","s":2174},{"p":"38146.6","s":3340},{"p":"38148.6","s":2495},{"p":"38149.6","s":0},{"p":"38149.4","s":0},{"p":"38146.9","s":74},{"p":"38146.7","s":0},{"p":"38147.8","s":0},{"p":"38149.1","s":527}],"b":[{"p":"38124.3","s":0},{"p":"38132.3","s":0},{"p":"38131.3","s":0},{"p":"38127.2","s":0},{"p":"38132.6","s":0},{"p":"38125.5","s":0},{"p":"38126.6","s":0}],"s":"BTC_USDT","t":1701245720020,"u":53095251791}}
{"time":1701245720,"time_ms":1701245720055,"channel":"futures.order_book_update","event":"update","result":{"U":53095251792,"a":[{"p":"38147.7","s":2174},{"p":"38147.9","s":0},{"p":"38186.8","s":0},{"p":"38149.4","s":0}],"b":[{"p":"38108.4","s":0},{"p":"38127","s":0}],"s":"BTC_USDT","t":1701245720038,"u":53095251799}}
{"time":1701245720,"time_ms":1701245720076,"channel":"futures.order_book_update","event":"update","result":{"U":53095251800,"a":[],"b":[{"p":"38121.2","s":0}],"s":"BTC_USDT","t":1701245720057,"u":53095251800}}
{"time":1701245720,"time_ms":1701245720092,"channel":"futures.order_book_update","event":"update","result":{"U":53095251801,"a":[{"p":"38187.8","s":0},{"p":"38160.2","s":0},{"p":"38149.4","s":2116},{"p":"38146.8","s":0}],"b":[{"p":"38139","s":2283}],"s":"BTC_USDT","t":1701245720085,"u":53095251805}}
{"time":1701245720,"time_ms":1701245720112,"channel":"futures.order_book_update","event":"update","result":{"U":53095251806,"a":[{"p":"38149.6","s":0},{"p":"38147.9","s":2174},{"p":"38146.9","s":2248},{"p":"38147.7","s":0}],"b":[{"p":"38127","s":0},{"p":"38138","s":100}],"s":"BTC_USDT","t":1701245720093,"u":53095251811}}
{"time":1701245720,"time_ms":1701245720154,"channel":"futures.order_book_update","event":"update","result":{"U":53095251812,"a":[{"p":"38175.6","s":0}],"b":[],"s":"BTC_USDT","t":1701245720144,"u":53095251815}}
{"time":1701245720,"time_ms":1701245720172,"channel":"futures.order_book_update","event":"update","result":{"U":53095251816,"a":[{"p":"38147.1","s":2174},{"p":"38146.9","s":74},{"p":"38149.4","s":0},{"p":"38155.7","s":0},{"p":"38151.6","s":0}],"b":[{"p":"38126.1","s":0},{"p":"38125.6","s":0},{"p":"38133","s":0},{"p":"38131.8","s":0}],"s":"BTC_USDT","t":1701245720161,"u":53095251829}}
{"time":1701245720,"time_ms":1701245720191,"channel":"futures.order_book_update","event":"update","result":{"U":53095251830,"a":[],"b":[{"p":"38125.7","s":0}],"s":"BTC_USDT","t":1701245720176,"u":53095251831}}
{"time":1701245720,"time_ms":1701245720212,"channel":"futures.order_book_update","event":"update","result":{"U":53095251832,"a":[],"b":[{"p":"38106.6","s":0}],"s":"BTC_USDT","t":1701245720193,"u":53095251834}}
{"time":1701245720,"time_ms":1701245720271,"channel":"futures.order_book_update","event":"update","result":{"U":53095251835,"a":[{"p":"38145.7","s":120869}],"b":[{"p":"38132.2","s":0},{"p":"38133.3","s":0}],"s":"BTC_USDT","t":1701245720257,"u":53095251841}}
{"time":1701245720,"time_ms":1701245720292,"channel":"futures.order_book_update","event":"update","result":{"U":53095251842,"a":[{"p":"38149.4","s":2116},{"p":"38146.5","s":2374},{"p":"38147.1","s":0}],"b":[],"s":"BTC_USDT","t":1701245720266,"u":53095251843}}
{"time":1701245720,"time_ms":1701245720314,"channel":"futures.order_book_update","event":"update","result":{"U":53095251844,"a":[{"p":"38147.2","s":5283},{"p":"38149.6","s":40},{"p":"38147.9","s":0},{"p":"38151.8","s":0}],"b":[{"p":"38138","s":200},{"p":"38139","s":2183},{"p":"38131.8","s":0}],"s":"BTC_USDT","t":1701245720308,"u":53095251851}}
{"time":1701245720,"time_ms":1701245720353,"channel":"futures.order_book_update","event":"update","result":{"U":53095251852,"a":[{"p":"38147.1","s":2174},{"p":"38148.9","s":2324},{"p":"38149.6","s":0},{"p":"38146.6","s":0},{"p":"38156","s":0},{"p":"38147.2","s":3109},{"p":"38146.3","s":3340},{"p":"38147.9","s":2174},{"p":"38148.5","s":0},{"p":"38149.4","s":0},{"p":"38151.2","s":0},{"p":"38146.5","s":200}],"b":[{"p":"38133.4","s":0},{"p":"38132.8","s":0},{"p":"38127.9","s":0},{"p":"38133.8","s":0},{"p":"38145.6","s":5105},{"p":"38126.7","s":0},{"p":"38131.4","s":0},{"p":"38132.9","s":0},{"p":"38133","s":0}],"s":"BTC_USDT","t":1701245720343,"u":53095251893}}
{"time":1701245720,"time_ms":1701245720373,"channel":"futures.order_book_update","event":"update","result":{"U":53095251894,"a":[{"p":"38149.4","s":2116},{"p":"38146.3","s":5514},{"p":"38147.1","s":0}],"b":[],"s":"BTC_USDT","t":1701245720355,"u":53095251896}}
{"time":1701245720,"time_ms":1701245720412,"channel":"futures.order_book_update","event":"update","result":{"U":53095251897,"a":[{"p":"38146.9","s":2248},{"p":"38146.3","s":3340}],"b":[],"s":"BTC_USDT","t":1701245720397,"u":53095251898}}
{"time":1701245720,"time_ms":1701245720432,"channel":"futures.order_book_update","event":"update","result":{"U":53095251899,"a":[],"b":[{"p":"38145.6","s":2605}],"s":"BTC_USDT","t":1701245720408,"u":53095251903}}
{"time":1701245720,"time_ms":1701245720472,"channel":"futures.order_book_update","event":"update","result":{"U":53095251904,"a":[{"p":"38153.5","s":0},{"p":"38157.5","s":0}],"b":[{"p":"38132.5","s":0},{"p":"38136.5","s":0}],"s":"BTC_USDT","t":1701245720456,"u":53095251912}}
{"time":1701245720,"time_ms":1701245720513,"channel":"futures.order_book_update","event":"update","result":{"U":53095251913,"a":[{"p":"38154.6","s":0}],"b":[],"s":"BTC_USDT","t":1701245720483,"u":53095251914}}
{"time":1701245720,"time_ms":1701245720572,"channel":"futures.order_book_update","event":"update","result":{"U":53095251915,"a":[],"b":[{"p":"38128.2","s":0}],"s":"BTC_USDT","t":1701245720555,"u":53095251916}}
{"time":1701245720,"time_ms":1701245720631,"channel":"futures.order_book_update","event":"update","result":{"U":53095251917,"a":[],"b":[{"p":"38132.9","s":0}],"s":"BTC_USDT","t":1701245720607,"u":53095251920}}
{"time":1701245720,"time_ms":1701245720692,"channel":"futures.order_book_update","event":"update","result":{"U":53095251921,"a":[{"p":"38149.1","s":527}],"b":[],"s":"BTC_USDT","t":1701245720684,"u":53095251924}}
{"time":1701245720,"time_ms":1701245720833,"channel":"futures.order_book_update","event":"update","result":{"U":53095251925,"a":[{"p":"38164.4","s":0},{"p":"38146.8","s":3340},{"p":"38146.3","s":0},{"p":"38160.6","s":0},{"p":"38172","s":0},{"p":"38168.2","s":0},{"p":"38152.6","s":0},{"p":"38149.6","s":0}],"b":[{"p":"38115","s":0},{"p":"38137.2","s":524},{"p":"38139.4","s":0}],"s":"BTC_USDT","t":1701245720815,"u":53095251934}}
{"time":1701245720,"time_ms":1701245720894,"channel":"futures.order_book_update","event":"update","result":{"U":53095251935,"a":[{"p":"38145.7","s":148369}],"b":[{"p":"38145.6","s":2084},{"p":"38128.8","s":0}],"s":"BTC_USDT","t":1701245720879,"u":53095251941}}
{"time":1701245720,"time_ms":1701245720911,"channel":"futures.order_book_update","event":"update","result":{"U":53095251942,"a":[{"p":"38172.1","s":0}],"b":[{"p":"38103.8","s":0},{"p":"38114.1","s":0}],"s":"BTC_USDT","t":1701245720894,"u":53095251949}}
{"time":1701245720,"time_ms":1701245720998,"channel":"futures.order_book_update","event":"update","result":{"U":53095251950,"a":[],"b":[{"p":"38128.2","s":0}],"s":"BTC_USDT","t":1701245720984,"u":53095251953}}
{"time":1701245721,"time_ms":1701245721032,"channel":"futures.order_book_update","event":"update","result":{"U":53095251954,"a":[{"p":"38148.5","s":2355},{"p":"38148.9","s":0},{"p":"38156.8","s":0},{"p":"38149.6","s":0}],"b":[{"p":"38125.7","s":0},{"p":"38132.6","s":0}],"s":"BTC_USDT","t":1701245721011,"u":53095251961}}
{"time":1701245721,"time_ms":1701245721053,"channel":"futures.order_book_update","event":"update","result":{"U":53095251962,"a":[{"p":"38152","s":0}],"b":[{"p":"38132.2","s":0}],"s":"BTC_USDT","t":1701245721028,"u":53095251965}}
{"time":1701245721,"time_ms":1701245721074,"channel":"futures.order_book_update","event":"update","result":{"U":53095251966,"a":[{"p":"38155.9","s":0},{"p":"38180.9","s":0}],"b":[],"s":"BTC_USDT","t":1701245721060,"u":53095251969}}
{"time":1701245721,"time_ms":1701245721093,"channel":"futures.order_book_update","event":"update","result":{"U":53095251970,"a":[{"p":"38148","s":6559},{"p":"38146.7","s":2174},{"p":"38146.9","s":74},{"p":"38149.4","s":0}],"b":[{"p":"38131.8","s":0},{"p":"38126.5","s":0},{"p":"38132.3","s":0},{"p":"38126.6","s":0},{"p":"38132.8","s":0}],"s":"BTC_USDT","t":1701245721086,"u":53095251984}}
{"time":1701245721,"time_ms":1701245721115,"channel":"futures.order_book_update","event":"update","result":{"U":53095251985,"a":[{"p":"38149.4","s":2116},{"p":"38148.5","s":0},{"p":"38159.2","s":0},{"p":"38185","s":0},{"p":"38166","s":0}],"b":[{"p":"38123.7","s":0},{"p":"38125.5","s":0}],"s":"BTC_USDT","t":1701245721106,"u":53095251996}}
{"time":1701245721,"time_ms":1701245721134,"channel":"futures.order_book_update","event":"update","result":{"U":53095251997,"a":[{"p":"38154","s":0},{"p":"38179.1","s":0},{"p":"38151.6","s":0},{"p":"38159.5","s":0},{"p":"38146.7","s":0},{"p":"38146.3","s":5514},{"p":"38149.6","s":40},{"p":"38147.9","s":0},{"p":"38146.8","s":0},{"p":"38154.4","s":0},{"p":"38146.9","s":2248},{"p":"38149.9","s":29682},{"p":"38158","s":0},{"p":"38161.2","s":0}],"b":[{"p":"38136.9","s":3635},{"p":"38140.1","s":0},{"p":"38137","s":0},{"p":"38121.9","s":0},{"p":"38049.8","s":0},{"p":"38135","s":0},{"p":"38125.6","s":0},{"p":"38131.2","s":0},{"p":"38145.6","s":776},{"p":"38133.3","s":0},{"p":"38128.9","s":0},{"p":"38132.4","s":0},{"p":"38123.2","s":0},{"p":"38123","s":0},{"p":"38141.7","s":26},{"p":"38131.4","s":0},{"p":"38133","s":0},{"p":"38132.2","s":0}],"s":"BTC_USDT","t":1701245721124,"u":53095252038}}
{"time":1701245721,"time_ms":1701245721152,"channel":"futures.order_book_update","event":"update","result":{"U":53095252039,"a":[{"p":"38145.8","s":3340},{"p":"38146.3","s":2174},{"p":"38149.9","s":0}],"b":[{"p":"38142","s":371},{"p":"38139","s":0},{"p":"38126.1","s":0},{"p":"38136.9","s":3635},{"p":"38139.2","s":655}],"s":"BTC_USDT","t":1701245721140,"u":53095252052}}
{"time":1701245721,"time_ms":1701245721172,"channel":"futures.order_book_update","event":"update","result":{"U":53095252053,"a":[{"p":"38145.7","s":149694},{"p":"38179.3","s":0}],"b":[],"s":"BTC_USDT","t":1701245721161,"u":53095252057}}
{"time":1701245721,"time_ms":1701245721191,"channel":"futures.order_book_update","event":"update","result":{"U":53095252058,"a":[{"p":"38146.7","s":2296},{"p":"38151","s":0},{"p":"38149.9","s":0},{"p":"38148.2","s":368},{"p":"38145.8","s":0},{"p":"38149.6","s":0},{"p":"38150.5","s":0},{"p":"38145.7","s":153618},{"p":"38148","s":4257},{"p":"38146.3","s":4348},{"p":"38153.9","s":0},{"p":"38155.8","s":0},{"p":"38146.9","s":74},{"p":"38149.3","s":733}],"b":[{"p":"38131.4","s":0},{"p":"38133.7","s":0},{"p":"38136.7","s":0},{"p":"38139.2","s":0},{"p":"38125","s":0},{"p":"38138","s":100},{"p":"38131.9","s":0},{"p":"38124.3","s":0},{"p":"38130.7","s":0},{"p":"38125.1","s":0},{"p":"38132.8","s":0},{"p":"38145.6","s":638},{"p":"38139","s":100}],"s":"BTC_USDT","t":1701245721182,"u":53095252094}}
{"time":1701245721,"time_ms":1701245721211,"channel":"futures.order_book_update","event":"update","result":{"U":53095252095,"a":[{"p":"38145.7","s":153618},{"p":"38163.9","s":0}],"b":[{"p":"38089.2","s":0},{"p":"38135.1","s":0},{"p":"38133.2","s":0}],"s":"BTC_USDT","t":1701245721195,"u":53095252101}}
{"time":1701245721,"time_ms":1701245721232,"channel":"futures.order_book_update","event":"update","result":{"U":53095252102,"a":[{"p":"38145.7","s":155792},{"p":"38146.3","s":2174},{"p":"38178.8","s":0}],"b":[{"p":"38118.6","s":0},{"p":"38130.6","s":0}],"s":"BTC_USDT","t":1701245721212,"u":53095252108}}
{"time":1701245721,"time_ms":1701245721253,"channel":"futures.order_book_update","event":"update","result":{"U":53095252109,"a":[{"p":"38149.6","s":40},{"p":"38146.8","s":2174},{"p":"38146.3","s":0},{"p":"38149.3","s":0},{"p":"38178.8","s":0},{"p":"38149.8","s":0},{"p":"38165.8","s":0}],"b":[{"p":"38130.7","s":0},{"p":"38123.7","s":0},{"p":"38130.5","s":0},{"p":"38103.4","s":0},{"p":"38121.3","s":0}],"s":"BTC_USDT","t":1701245721242,"u":53095252127}}
{"time":1701245721,"time_ms":1701245721272,"channel":"futures.order_book_update","event":"update","result":{"U":53095252128,"a":[{"p":"38178.8","s":0}],"b":[],"s":"BTC_USDT","t":1701245721256,"u":53095252130}}
{"time":1701245721,"time_ms":1701245721293,"channel":"futures.order_book_update","event":"update","result":{"U":53095252131,"a":[{"p":"38147.9","s":2368},{"p":"38146.3","s":2174},{"p":"38147.2","s":5283},{"p":"38146.2","s":3340},{"p":"38149.6","s":0},{"p":"38154.5","s":0},{"p":"38145.7","s":152451},{"p":"38146.7","s":0},{"p":"38146.8","s":0},{"p":"38149.9","s":0},{"p":"38149.8","s":0},{"p":"38178.9","s":0},{"p":"38163.2","s":0}],"b":[{"p":"38130.5","s":0},{"p":"38131.2","s":0}],"s":"BTC_USDT","t":1701245721285,"u":53095252152}}
{"time":1701245721,"time_ms":1701245721312,"channel":"futures.order_book_update","event":"update","result":{"U":53095252153,"a":[{"p":"38147.2","s":3109},{"p":"38147.9","s":4542},{"p":"38145.7","s":150277}],"b":[{"p":"38130.1","s":0}],"s":"BTC_USDT","t":1701245721296,"u":53095252157}}
{"time":1701245721,"time_ms":1701245721332,"channel":"futures.order_book_update","event":"update","result":{"U":53095252158,"a":[{"p":"38147.9","s":2368},{"p":"38145.7","s":148952},{"p":"38161.7","s":0},{"p":"38178.9","s":0}],"b":[{"p":"38131.8","s":0}],"s":"BTC_USDT","t":1701245721314,"u":53095252164}}
{"time":1701245721,"time_ms":1701245721352,"channel":"futures.order_book_update","event":"update","result":{"U":53095252165,"a":[{"p":"38147.9","s":4542},{"p":"38151.5","s":0},{"p":"38179.2","s":0},{"p":"38155.5","s":0},{"p":"38163.5","s":0}],"b":[{"p":"38135","s":0},{"p":"38122.5","s":0},{"p":"38131","s":0}],"s":"BTC_USDT","t":1701245721345,"u":53095252181}}
{"time":1701245721,"time_ms":1701245721377,"channel":"futures.order_book_update","event":"update","result":{"U":53095252182,"a":[{"p":"38157.5","s":0}],"b":[{"p":"38132.5","s":0}],"s":"BTC_USDT","t":1701245721352,"u":53095252185}}
{"time":1701245721,"time_ms":1701245721393,"channel":"futures.order_book_update","event":"update","result":{"U":53095252186,"a":[{"p":"38151.1","s":0},{"p":"38179","s":0},{"p":"38149.7","s":0},{"p":"38149.6","s":0},{"p":"38147.9","s":2368},{"p":"38145.7","s":152293},{"p":"38146.6","s":2174},{"p":"38146.2","s":0}],"b":[{"p":"38136.9","s":3633},{"p":"38136.7","s":9960},{"p":"38137.6","s":0},{"p":"38135.7","s":0},{"p":"38133","s":0},{"p":"38132.2","s":0}],"s":"BTC_USDT","t":1701245721384,"u":53095252202}}
{"time":1701245721,"time_ms":1701245721412,"channel":"futures.order_book_update","event":"update","result":{"U":53095252203,"a":[{"p":"38179.1","s":0},{"p":"38150.8","s":0},{"p":"38149.6","s":40},{"p":"38145.7","s":154467},{"p":"38146.3","s":0},{"p":"38155","s":0}],"b":[{"p":"38139.1","s":2},{"p":"38137.2","s":526},{"p":"38138.3","s":2},{"p":"38136.7","s":0},{"p":"38138.4","s":0},{"p":"38136.6","s":0},{"p":"38131.4","s":0}],"s":"BTC_USDT","t":1701245721403,"u":53095252218}}
{"time":1701245721,"time_ms":1701245721431,"channel":"futures.order_book_update","event":"update","result":{"U":53095252219,"a":[{"p":"38149.7","s":0}],"b":[{"p":"38139.9","s":2},{"p":"38136.9","s":0},{"p":"38113.1","s":0}],"s":"BTC_USDT","t":1701245721412,"u":53095252223}}
{"time":1701245721,"time_ms":1701245721452,"channel":"futures.order_book_update","event":"update","result":{"U":53095252224,"a":[{"p":"38179.1","s":0}],"b":[],"s":"BTC_USDT","t":1701245721438,"u":53095252227}}
{"time":1701245721,"time_ms":1701245721494,"channel":"futures.order_book_update","event":"update","result":{"U":53095252228,"a":[{"p":"38179.1","s":0}],"b":[],"s":"BTC_USDT","t":1701245721480,"u":53095252236}}
{"time":1701245721,"time_ms":1701245721511,"channel":"futures.order_book_update","event":"update","result":{"U":53095252237,"a":[{"p":"38156.4","s":0},{"p":"38152.6","s":0},{"p":"38150.5","s":0}],"b":[{"p":"38136.9","s":3633},{"p":"38138","s":200},{"p":"38139","s":0}],"s":"BTC_USDT","t":1701245721495,"u":53095252245}}
{"time":1701245721,"time_ms":1701245721532,"channel":"futures.order_book_update","event":"update","result":{"U":53095252246,"a":[{"p":"38179","s":0},{"p":"38150.5","s":0},{"p":"38145.7","s":148952},{"p":"38147.8","s":2174},{"p":"38146.3","s":5514},{"p":"38146.6","s":0},{"p":"38149.6","s":0}],"b":[{"p":"38123.8","s":0}],"s":"BTC_USDT","t":1701245721524,"u":53095252255}}
{"time":1701245721,"time_ms":1701245721553,"channel":"futures.order_book_update","event":"update","result":{"U":53095252256,"a":[{"p":"38146.9","s":2248},{"p":"38179.4","s":0},{"p":"38146.3","s":3340}],"b":[],"s":"BTC_USDT","t":1701245721541,"u":53095252260}}
{"time":1701245721,"time_ms":1701245721572,"channel":"futures.order_book_update","event":"update","result":{"U":53095252261,"a":[{"p":"38152.6","s":0},{"p":"38167.8","s":0},{"p":"38164","s":0},{"p":"38160.2","s":0}],"b":[{"p":"38115","s":0}],"s":"BTC_USDT","t":1701245721556,"u":53095252266}}
{"time":1701245721,"time_ms":1701245721594,"channel":"futures.order_book_update","event":"update","result":{"U":53095252267,"a":[{"p":"38158","s":0},{"p":"38179.4","s":0}],"b":[{"p":"38132","s":0}],"s":"BTC_USDT","t":1701245721576,"u":53095252272}}
{"time":1701245721,"time_ms":1701245721611,"channel":"futures.order_book_update","event":"update","result":{"U":53095252273,"a":[{"p":"38179.4","s":0}],"b":[],"s":"BTC_USDT","t":1701245721600,"u":53095252275}}
{"time":1701245721,"time_ms":1701245721633,"channel":"futures.order_book_update","event":"update","result":{"U":53095252276,"a":[{"p":"38179.4","s":0}],"b":[],"s":"BTC_USDT","t":1701245721606,"u":53095252276}}
{"time":1701245721,"time_ms":1701245721651,"channel":"futures.order_book_update","event":"update","result":{"U":53095252277,"a":[{"p":"38179.4","s":0}],"b":[{"p":"38136.7","s":9960},{"p":"38137.2","s":524},{"p":"38136.6","s":418},{"p":"38138.3","s":0},{"p":"38139.1","s":0},{"p":"38139.9","s":0},{"p":"38136.5","s":8913}],"s":"BTC_USDT","t":1701245721640,"u":53095252284}}
{"time":1701245721,"time_ms":1701245721671,"channel":"futures.order_book_update","event":"update","result":{"U":53095252285,"a":[{"p":"38179.4","s":0}],"b":[{"p":"38140.6","s":3633},{"p":"38139.9","s":2},{"p":"38137.3","s":3},{"p":"38136.5","s":0},{"p":"38136.7","s":0},{"p":"38128.2","s":0},{"p":"38125","s":0},{"p":"38138.4","s":2},{"p":"38139.2","s":2},{"p":"38136.6","s":0},{"p":"38136.9","s":0},{"p":"38128.4","s":0}],"s":"BTC_USDT","t":1701245721664,"u":53095252293}}
{"time":1701245721,"time_ms":1701245721691,"channel":"futures.order_book_update","event":"update","result":{"U":53095252294,"a":[{"p":"38179.3","s":0}],"b":[{"p":"38136.9","s":0},{"p":"38140.7","s":2182},{"p":"38142","s":0}],"s":"BTC_USDT","t":1701245721673,"u":53095252297}}
{"time":1701245721,"time_ms":1701245721713,"channel":"futures.order_book_update","event":"update","result":{"U":53095252298,"a":[{"p":"38179.4","s":0},{"p":"38153.5","s":0},{"p":"38157.5","s":0},{"p":"38179.3","s":0}],"b":[{"p":"38138","s":100},{"p":"38139","s":100},{"p":"38137.2","s":0},{"p":"38113","s":0},{"p":"38136.5","s":0},{"p":"38132.5","s":0},{"p":"38126.5","s":0},{"p":"38137","s":0}],"s":"BTC_USDT","t":1701245721700,"u":53095252314}}
{"time":1701245721,"time_ms":1701245721733,"channel":"futures.order_book_update","event":"update","result":{"U":53095252315,"a":[],"b":[{"p":"38127.4","s":0}],"s":"BTC_USDT","t":1701245721713,"u":53095252316}}
{"time":1701245721,"time_ms":1701245721755,"channel":"futures.order_book_update","event":"update","result":{"U":53095252317,"a":[{"p":"38179.4","s":0}],"b":[],"s":"BTC_USDT","t":1701245721743,"u":53095252320}}
{"time":1701245721,"time_ms":1701245721772,"channel":"futures.order_book_update","event":"update","result":{"U":53095252321,"a":[],"b":[{"p":"38071.5","s":0}],"s":"BTC_USDT","t":1701245721750,"u":53095252322}}
{"time":1701245721,"time_ms":1701245721792,"channel":"futures.order_book_update","event":"update","result":{"U":53095252323,"a":[{"p":"38158","s":0},{"p":"38157.5","s":0},{"p":"38179.4","s":0},{"p":"38153.5","s":0},{"p":"38154","s":0},{"p":"38166","s":0}],"b":[{"p":"38133","s":0},{"p":"38137","s":0},{"p":"38124","s":0},{"p":"38132.5","s":0}],"s":"BTC_USDT","t":1701245721780,"u":53095252342}}
{"time":1701245721,"time_ms":1701245721813,"channel":"futures.order_book_update","event":"update","result":{"U":53095252343,"a":[{"p":"38179.4","s":0}],"b":[],"s":"BTC_USDT","t":1701245721785,"u":53095252344}}
{"time":1701245721,"time_ms":1701245721832,"channel":"futures.order_book_update","event":"update","result":{"U":53095252345,"a":[{"p":"38179.3","s":0}],"b":[{"p":"38132.6","s":0}],"s":"BTC_USDT","t":1701245721814,"u":53095252347}}
{"time":1701245721,"time_ms":1701245721854,"channel":"futures.order_book_update","event":"update","result":{"U":53095252348,"a":[{"p":"38179.3","s":0}],"b":[{"p":"38136.7","s":9960},{"p":"38139.2","s":0},{"p":"38138.4","s":0},{"p":"38139.9","s":0},{"p":"38137.2","s":524},{"p":"38137.3","s":1},{"p":"38136.9","s":3633}],"s":"BTC_USDT","t":1701245721844,"u":53095252354}}
{"time":1701245721,"time_ms":1701245721873,"channel":"futures.order_book_update","event":"update","result":{"U":53095252355,"a":[{"p":"38179.3","s":0}],"b":[],"s":"BTC_USDT","t":1701245721857,"u":53095252356}}
{"time":1701245721,"time_ms":1701245721891,"channel":"futures.order_book_update","event":"update","result":{"U":53095252357,"a":[{"p":"38179.3","s":0}],"b":[{"p":"38121.3","s":0}],"s":"BTC_USDT","t":1701245721881,"u":53095252361}}
{"time":1701245721,"time_ms":1701245721914,"channel":"futures.order_book_update","event":"update","result":{"U":53095252362,"a":[{"p":"38179.3","s":0},{"p":"38154","s":0}],"b":[{"p":"38138.1","s":9781}],"s":"BTC_USDT","t":1701245721898,"u":53095252366}}
{"time":1701245721,"time_ms":1701245721933,"channel":"futures.order_book_update","event":"update","result":{"U":53095252367,"a":[{"p":"38179.3","s":0}],"b":[{"p":"38139.4","s":2},{"p":"38137.5","s":2002},{"p":"38136.6","s":0},{"p":"38138.6","s":2},{"p":"38138","s":200},{"p":"38140.2","s":2},{"p":"38136.7","s":0},{"p":"38139","s":0},{"p":"38136.9","s":0}],"s":"BTC_USDT","t":1701245721923,"u":53095252376}}
{"time":1701245721,"time_ms":1701245721954,"channel":"futures.order_book_update","event":"update","result":{"U":53095252377,"a":[{"p":"38149.6","s":40},{"p":"38149.1","s":525},{"p":"38145.7","s":152295},{"p":"38146.9","s":74},{"p":"38146.3","s":0},{"p":"38179.3","s":0}],"b":[{"p":"38137.5","s":2000},{"p":"38138.6","s":0},{"p":"38136.9","s":3633}],"s":"BTC_USDT","t":1701245721946,"u":53095252385}}
{"time":1701245721,"time_ms":1701245721974,"channel":"futures.order_book_update","event":"update","result":{"U":53095252386,"a":[{"p":"38149.6","s":0},{"p":"38179.3","s":0},{"p":"38151.6","s":0},{"p":"38145.7","s":154469},{"p":"38149.3","s":733}],"b":[{"p":"38136.6","s":418},{"p":"38140.2","s":0},{"p":"38127.8","s":0},{"p":"38134","s":0},{"p":"38133.3","s":0},{"p":"38136.7","s":9960},{"p":"38139.4","s":0},{"p":"38132.1","s":0},{"p":"38132.2","s":0},{"p":"38134.8","s":0}],"s":"BTC_USDT","t":1701245721964,"u":53095252406}}
{"time":1701245721,"time_ms":1701245721994,"channel":"futures.order_book_update","event":"update","result":{"U":53095252407,"a":[{"p":"38179.3","s":0}],"b":[{"p":"38131.4","s":0},{"p":"38130.7","s":0},{"p":"38125.4","s":0}],"s":"BTC_USDT","t":1701245721986,"u":53095252415}}
{"time":1701245722,"time_ms":1701245722013,"channel":"futures.order_book_update","event":"update","result":{"U":53095252416,"a":[{"p":"38147.9","s":0},{"p":"38149.9","s":0},{"p":"38158.8","s":0},{"p":"38145.7","s":145732},{"p":"38147.8","s":0},{"p":"38149.6","s":0},{"p":"38146.3","s":2301},{"p":"38145.8","s":2174},{"p":"38149.3","s":0},{"p":"38154.6","s":0},{"p":"38145.6","s":11793},{"p":"38145.3","s":31883},{"p":"38149.4","s":0},{"p":"38179.3","s":0}],"b":[{"p":"38138.1","s":9126},{"p":"38136.2","s":15},{"p":"38135.4","s":16984},{"p":"38145.6","s":0},{"p":"38145.5","s":0},{"p":"38137.2","s":0},{"p":"38145.2","s":3757},{"p":"38136.4","s":2621},{"p":"38129.1","s":0}],"s":"BTC_USDT","t":1701245722003,"u":53095252468}}
{"time":1701245722,"time_ms":1701245722031,"channel":"futures.order_book_update","event":"update","result":{"U":53095252469,"a":[{"p":"38149.1","s":0},{"p":"38148","s":0},{"p":"38149.4","s":0},{"p":"38163.9","s":0},{"p":"38184","s":0},{"p":"38178.5","s":0},{"p":"38148.6","s":2495},{"p":"38145.7","s":63566},{"p":"38145.8","s":0},{"p":"38167.9","s":0},{"p":"38149.3","s":0},{"p":"38148.1","s":8597},{"p":"38145","s":2011},{"p":"38145.3","s":251072},{"p":"38145.6","s":60716},{"p":"38155.4","s":0},{"p":"38157.7","s":0},{"p":"38149.6","s":0},{"p":"38145.5","s":43245},{"p":"38145.2","s":2681},{"p":"38142","s":40670},{"p":"38146.9","s":0},{"p":"38175.1","s":0},{"p":"38159.5","s":0},{"p":"38165.1","s":0}],"b":[{"p":"38012.9","s":0},{"p":"38117.1","s":0},{"p":"38124.6","s":0},{"p":"38093.7","s":0},{"p":"38039","s":0},{"p":"38122.5","s":0},{"p":"38140.6","s":0},{"p":"38135","s":0},{"p":"38130","s":0},{"p":"38122.7","s":0},{"p":"38129.4","s":0},{"p":"38135.2","s":550},{"p":"38135.3","s":28297},{"p":"38130.5","s":0},{"p":"38137.1","s":0},{"p":"38135.1","s":3362},{"p":"38124.3","s":0},{"p":"38131.4","s":0},{"p":"38134.8","s":0},{"p":"38122.4","s":0},{"p":"38103.9","s":0},{"p":"38130.8","s":0},{"p":"38132","s":0},{"p":"38135.4","s":16984},{"p":"38132.9","s":0},{"p":"38145.2","s":0},{"p":"38115.2","s":0},{"p":"38132.8","s":0},{"p":"38138","s":0},{"p":"38132.1","s":0},{"p":"38131.7","s":0}],"s":"BTC_USDT","t":1701245722021,"u":53095252756}}
{"time":1701245722,"time_ms":1701245722052,"channel":"futures.order_book_update","event":"update","result":{"U":53095252757,"a":[{"p":"38146.9","s":0},{"p":"38177.7","s":0},{"p":"38164","s":0},{"p":"38149.6","s":0},{"p":"38148.7","s":4851},{"p":"38148.8","s":1781},{"p":"38148.1","s":7864},{"p":"38145.6","s":25121},{"p":"38148","s":14074},{"p":"38148.5","s":0},{"p":"38154.3","s":0},{"p":"38151.5","s":0},{"p":"38153.1","s":0},{"p":"38149","s":15966},{"p":"38159","s":0},{"p":"38148.2","s":368},{"p":"38144.3","s":0},{"p":"38149.4","s":0},{"p":"38145.7","s":16718},{"p":"38142.7","s":0},{"p":"38144.4","s":0},{"p":"38181.9","s":0},{"p":"38149.1","s":0},{"p":"38144.8","s":0},{"p":"38142","s":177054},{"p":"38181.8","s":0},{"p":"38154","s":0},{"p":"38144.5","s":0},{"p":"38142.4","s":0},{"p":"38144.1","s":3932},{"p":"38145.3","s":90801},{"p":"38146.3","s":0},{"p":"38145.5","s":0},{"p":"38148.6","s":2495},{"p":"38155.5","s":0},{"p":"38160.1","s":0}],"b":[{"p":"38131.2","s":0},{"p":"38051.7","s":0},{"p":"38133.3","s":0},{"p":"38124.2","s":0},{"p":"38138.9","s":0},{"p":"38135","s":0},{"p":"38141.9","s":13901},{"p":"38137.4","s":15000},{"p":"38136.7","s":6815},{"p":"38131.4","s":0},{"p":"38129.4","s":0},{"p":"38132.9","s":0},{"p":"38129.9","s":0},{"p":"38134.8","s":0},{"p":"38138","s":26},{"p":"38137.8","s":208},{"p":"38128.7","s":0},{"p":"38130.9","s":0},{"p":"38133.7","s":0},{"p":"38140.7","s":0},{"p":"38132","s":0},{"p":"38074.3","s":0},{"p":"38139","s":2266},{"p":"38137.5","s":0},{"p":"38133","s":0},{"p":"38123.7","s":0},{"p":"38125.3","s":0}],"s":"BTC_USDT","t":1701245722038,"u":53095252958}}
{"time":1701245722,"time_ms":1701245722081,"channel":"futures.order_book_update","event":"update","result":{"U":53095252959,"a":[{"p":"38147.9","s":8447},{"p":"38150.6","s":0},{"p":"38154","s":0},{"p":"38162","s":0},{"p":"38182.9","s":0},{"p":"38142","s":174526},{"p":"38145.3","s":86460},{"p":"38145.7","s":16109},{"p":"38147","s":0},{"p":"38156","s":0},{"p":"38148.9","s":0},{"p":"38145.9","s":695},{"p":"38147.2","s":6742},{"p":"38148","s":8914},{"p":"38152.3","s":0},{"p":"38148.8","s":1781},{"p":"38165.6","s":0},{"p":"38147.1","s":0},{"p":"38156.1","s":0},{"p":"38146.9","s":3601},{"p":"38181","s":0},{"p":"38161.6","s":0},{"p":"38145.6","s":12105},{"p":"38149","s":0},{"p":"38175.4","s":0},{"p":"38180.2","s":0},{"p":"38186.7","s":0},{"p":"38177.3","s":0},{"p":"38179.4","s":0},{"p":"38160.1","s":0},{"p":"38159.9","s":0}],"b":[{"p":"38141.9","s":6904},{"p":"38134.8","s":3601},{"p":"38139","s":0},{"p":"38138.8","s":117},{"p":"38135","s":3932},{"p":"38128.7","s":0},{"p":"38123.7","s":0},{"p":"38141.7","s":0},{"p":"38130.1","s":0},{"p":"38089.3","s":0},{"p":"38123.2","s":0},{"p":"38135.4","s":18984},{"p":"38123.5","s":0},{"p":"37991.7","s":0},{"p":"38121.3","s":0}],"s":"BTC_USDT","t":1701245722063,"u":53095253067}}
{"time":1701245722,"time_ms":1701245722094,"channel":"futures.order_book_update","event":"update","result":{"U":53095253068,"a":[{"p":"38147.1","s":3606},{"p":"38147.9","s":5352},{"p":"38145.6","s":8962},{"p":"38148.8","s":0},{"p":"38185.9","s":0},{"p":"38142","s":169166},{"p":"38145.3","s":84729},{"p":"38146.3","s":2174},{"p":"38148.7","s":0},{"p":"38177.5","s":0},{"p":"38155","s":0}],"b":[{"p":"38141.9","s":6312},{"p":"38129.2","s":0},{"p":"38119.9","s":0}],"s":"BTC_USDT","t":1701245722087,"u":53095253107}}
{"time":1701245722,"time_ms":1701245722112,"channel":"futures.order_book_update","event":"update","result":{"U":53095253108,"a":[{"p":"38145.6","s":6264},{"p":"38142","s":167821},{"p":"38144.9","s":2174},{"p":"38145.9","s":40},{"p":"38146.3","s":0},{"p":"38156.3","s":0},{"p":"38184.8","s":0},{"p":"38148.7","s":0},{"p":"38152","s":0}],"b":[{"p":"38134.7","s":0},{"p":"38127.9","s":0},{"p":"38129","s":0},{"p":"38141.9","s":3998},{"p":"38092.8","s":0}],"s":"BTC_USDT","t":1701245722097,"u":53095253135}}
{"time":1701245722,"time_ms":1701245722133,"channel":"futures.order_book_update","event":"update","result":{"U":53095253136,"a":[{"p":"38160.5","s":0},{"p":"38152.5","s":0},{"p":"38142","s":164849},{"p":"38146.3","s":2174},{"p":"38148","s":0},{"p":"38148.7","s":0},{"p":"38177.6","s":0}],"b":[{"p":"38123.2","s":0},{"p":"38101.9","s":0}],"s":"BTC_USDT","t":1701245722120,"u":53095253161}}
{"time":1701245722,"time_ms":1701245722153,"channel":"futures.order_book_update","event":"update","result":{"U":53095253162,"a":[{"p":"38148.7","s":4851},{"p":"38145.2","s":4855},{"p":"38146.3","s":0}],"b":[{"p":"38136.6","s":235}],"s":"BTC_USDT","t":1701245722141,"u":53095253165}}
{"time":1701245722,"time_ms":1701245722172,"channel":"futures.order_book_update","event":"update","result":{"U":53095253166,"a":[{"p":"38152.3","s":0},{"p":"38177.6","s":0}],"b":[],"s":"BTC_USDT","t":1701245722157,"u":53095253170}}
{"time":1701245722,"time_ms":1701245722192,"channel":"futures.order_book_update","event":"update","result":{"U":53095253171,"a":[{"p":"38149","s":0},{"p":"38177.8","s":0},{"p":"38154.5","s":0},{"p":"38150","s":0},{"p":"38145.7","s":16107}],"b":[],"s":"BTC_USDT","t":1701245722171,"u":53095253179}}
{"time":1701245722,"time_ms":1701245722212,"channel":"futures.order_book_update","event":"update","result":{"U":53095253180,"a":[{"p":"38151.2","s":0},{"p":"38142.4","s":600},{"p":"38145.3","s":48249},{"p":"38145.6","s":6266},{"p":"38142","s":173829},{"p":"38148.7","s":0},{"p":"38177.7","s":0},{"p":"38189.7","s":0}],"b":[],"s":"BTC_USDT","t":1701245722197,"u":53095253193}}
{"time":1701245722,"time_ms":1701245722233,"channel":"futures.order_book_update","event":"update","result":{"U":53095253194,"a":[{"p":"38142","s":185744},{"p":"38146.3","s":2174},{"p":"38145.2","s":2681},{"p":"38148.6","s":0}],"b":[{"p":"38134.8","s":0},{"p":"38138.2","s":599}],"s":"BTC_USDT","t":1701245722219,"u":53095253206}}
{"time":1701245722,"time_ms":1701245722253,"channel":"futures.order_book_update","event":"update","result":{"U":53095253207,"a":[{"p":"38146.8","s":2174},{"p":"38146.3","s":0},{"p":"38177.7","s":0},{"p":"38148.6","s":0}],"b":[{"p":"38141.9","s":8498}],"s":"BTC_USDT","t":1701245722241,"u":53095253214}}
{"time":1701245722,"time_ms":1701245722274,"channel":"futures.order_book_update","event":"update","result":{"U":53095253215,"a":[{"p":"38142","s":186399},{"p":"38188.1","s":0}],"b":[],"s":"BTC_USDT","t":1701245722262,"u":53095253220}}
{"time":1701245722,"time_ms":1701245722293,"channel":"futures.order_book_update","event":"update","result":{"U":53095253221,"a":[{"p":"38177.6","s":0}],"b":[],"s":"BTC_USDT","t":1701245722283,"u":53095253223}}
{"time":1701245722,"time_ms":1701245722313,"channel":"futures.order_book_update","event":"update","result":{"U":53095253224,"a":[],"b":[{"p":"38129","s":0},{"p":"38128","s":0}],"s":"BTC_USDT","t":1701245722301,"u":53095253228}}
{"time":1701245722,"time_ms":1701245722333,"channel":"futures.order_book_update","event":"update","result":{"U":53095253229,"a":[{"p":"38177.6","s":0}],"b":[],"s":"BTC_USDT","t":1701245722315,"u":53095253231}}
{"time":1701245722,"time_ms":1701245722374,"channel":"futures.order_book_update","event":"update","result":{"U":53095253232,"a":[{"p":"38177.6","s":0},{"p":"38148.6","s":0},{"p":"38152.1","s":0},{"p":"38145.8","s":16163},{"p":"38145","s":0}],"b":[],"s":"BTC_USDT","t":1701245722358,"u":53095253241}}
{"time":1701245722,"time_ms":1701245722391,"channel":"futures.order_book_update","event":"update","result":{"U":53095253242,"a":[],"b":[{"p":"38136.6","s":890}],"s":"BTC_USDT","t":1701245722379,"u":53095253243}}
{"time":1701245722,"time_ms":1701245722414,"channel":"futures.order_book_update","event":"update","result":{"U":53095253244,"a":[{"p":"38155","s":0},{"p":"38177.6","s":0}],"b":[{"p":"38129","s":0}],"s":"BTC_USDT","t":1701245722397,"u":53095253251}}
{"time":1701245722,"time_ms":1701245722455,"channel":"futures.order_book_update","event":"update","result":{"U":53095253252,"a":[{"p":"38177.6","s":0}],"b":[],"s":"BTC_USDT","t":1701245722443,"u":53095253256}}
{"time":1701245722,"time_ms":1701245722483,"channel":"futures.order_book_update","event":"update","result":{"U":53095253257,"a":[{"p":"38145.1","s":28956},{"p":"38144","s":3340},{"p":"38144.8","s":2174},{"p":"38152.3","s":0},{"p":"38150","s":0},{"p":"38154.5","s":0},{"p":"38162.5","s":0},{"p":"38145","s":2011},{"p":"38149.8","s":0},{"p":"38145.7","s":15583},{"p":"38147.9","s":0},{"p":"38148.2","s":0},{"p":"38150.5","s":0},{"p":"38142","s":190068},{"p":"38176.8","s":0},{"p":"38148.1","s":0},{"p":"38146.8","s":0},{"p":"38154","s":0},{"p":"38176.4","s":0},{"p":"38145.6","s":2926}],"b":[{"p":"38129.4","s":0},{"p":"38130.8","s":0},{"p":"38121","s":0},{"p":"38135.4","s":19639},{"p":"38136.6","s":235},{"p":"38129","s":0},{"p":"38134.8","s":0},{"p":"38134.7","s":0},{"p":"38130.2","s":0},{"p":"38086.7","s":0},{"p":"38118.7","s":0},{"p":"38115.6","s":0},{"p":"38133.5","s":0},{"p":"38132","s":0},{"p":"38123.7","s":0},{"p":"38134.4","s":600},{"p":"38128.8","s":0},{"p":"38129.5","s":0},{"p":"38128.7","s":0},{"p":"38128.3","s":0},{"p":"38141.9","s":2090},{"p":"38136.9","s":0},{"p":"38133","s":0},{"p":"38123.3","s":0},{"p":"38069.9","s":0},{"p":"38047.3","s":0},{"p":"38134.2","s":0}],"s":"BTC_USDT","t":1701245722475,"u":53095253336}}
{"time":1701245722,"time_ms":1701245722497,"channel":"futures.order_book_update","event":"update","result":{"U":53095253337,"a":[{"p":"38142","s":191668},{"p":"38149.4","s":0},{"p":"38149.2","s":0},{"p":"38149.3","s":0},{"p":"38156.5","s":0}],"b":[{"p":"38141.9","s":620},{"p":"38128.7","s":0},{"p":"38132.3","s":0},{"p":"38126","s":0},{"p":"38123.2","s":0},{"p":"38134.2","s":6111},{"p":"38134","s":4233},{"p":"38134.4","s":0},{"p":"38137.4","s":0}],"s":"BTC_USDT","t":1701245722488,"u":53095253361}}
{"time":1701245722,"time_ms":1701245722513,"channel":"futures.order_book_update","event":"update","result":{"U":53095253362,"a":[{"p":"38145.3","s":41434},{"p":"38175.5","s":0},{"p":"38166.2","s":0},{"p":"38175.7","s":0},{"p":"38154.9","s":0},{"p":"38142","s":200087},{"p":"38162.3","s":0},{"p":"38154.3","s":0},{"p":"38159.5","s":0},{"p":"38148.2","s":0}],"b":[{"p":"38138.3","s":508},{"p":"38136.7","s":0},{"p":"38119.6","s":0},{"p":"38133.2","s":0},{"p":"38125.3","s":0},{"p":"38121.5","s":0},{"p":"38127","s":0},{"p":"38133.1","s":0},{"p":"38131.9","s":0},{"p":"38133.9","s":5667},{"p":"38134","s":3633},{"p":"38138.1","s":0},{"p":"38127.7","s":0},{"p":"38101.1","s":0},{"p":"38131.6","s":0},{"p":"38134.4","s":0},{"p":"38141.9","s":74},{"p":"38016","s":0},{"p":"38128.9","s":0},{"p":"38122.6","s":0},{"p":"38133.8","s":0}],"s":"BTC_USDT","t":1701245722506,"u":53095253417}}
{"time":1701245722,"time_ms":1701245722535,"channel":"futures.order_book_update","event":"update","result":{"U":53095253418,"a":[{"p":"38166.8","s":0},{"p":"38151.1","s":0},{"p":"38174.8","s":0},{"p":"38142","s":200088}],"b":[{"p":"38106.8","s":0},{"p":"38130.4","s":0},{"p":"38127.8","s":0},{"p":"38122","s":0},{"p":"38134.2","s":120},{"p":"38131.6","s":0}],"s":"BTC_USDT","t":1701245722525,"u":53095253448}}
{"time":1701245722,"time_ms":1701245722552,"channel":"futures.order_book_update","event":"update","result":{"U":53095253449,"a":[{"p":"38160","s":0},{"p":"38151.2","s":0},{"p":"38157","s":0},{"p":"38154.9","s":0},{"p":"38145.6","s":2924},{"p":"38164.8","s":0}],"b":[{"p":"38129.5","s":0},{"p":"38128.1","s":0}],"s":"BTC_USDT","t":1701245722539,"u":53095253468}}
{"time":1701245722,"time_ms":1701245722575,"channel":"futures.order_book_update","event":"update","result":{"U":53095253469,"a":[{"p":"38151.9","s":0},{"p":"38148.6","s":0},{"p":"38174.8","s":0},{"p":"38152.2","s":0},{"p":"38144.5","s":525},{"p":"38145","s":2013},{"p":"38147.1","s":0},{"p":"38150.4","s":0},{"p":"38162","s":0},{"p":"38144.3","s":525},{"p":"38165.8","s":0},{"p":"38152","s":0},{"p":"38166.8","s":0},{"p":"38147","s":733},{"p":"38147.3","s":0},{"p":"38147.2","s":0}],"b":[{"p":"38076.8","s":0},{"p":"38089.6","s":0},{"p":"38122.9","s":0},{"p":"38131.2","s":0},{"p":"38108.4","s":0},{"p":"38127.9","s":0},{"p":"38133.8","s":0},{"p":"38109.9","s":0},{"p":"38127.5","s":0},{"p":"38133.7","s":4333},{"p":"38135.2","s":0},{"p":"38126.5","s":0},{"p":"38122.3","s":0}],"s":"BTC_USDT","t":1701245722567,"u":53095253505}}
{"time":1701245722,"time_ms":1701245722593,"channel":"futures.order_book_update","event":"update","result":{"U":53095253506,"a":[{"p":"38147","s":0},{"p":"38174.8","s":0},{"p":"38143.9","s":2360}],"b":[],"s":"BTC_USDT","t":1701245722582,"u":53095253511}}
{"time":1701245722,"time_ms":1701245722612,"channel":"futures.order_book_update","event":"update","result":{"U":53095253512,"a":[{"p":"38174.8","s":0},{"p":"38151.6","s":0},{"p":"38142","s":205604},{"p":"38147","s":733},{"p":"38147.1","s":3606},{"p":"38144","s":0},{"p":"38144.9","s":0}],"b":[{"p":"38121.8","s":0},{"p":"38077","s":0},{"p":"38121.7","s":0},{"p":"38120.2","s":0},{"p":"38133.6","s":525},{"p":"38035","s":0},{"p":"38127.2","s":0},{"p":"38131.8","s":0},{"p":"38135.4","s":16984},{"p":"38122","s":0},{"p":"38092.4","s":0},{"p":"38126.5","s":0},{"p":"38067.7","s":0},{"p":"38132.7","s":0},{"p":"38113.1","s":0},{"p":"38013.3","s":0},{"p":"38133.7","s":0},{"p":"38127.8","s":0},{"p":"38131.2","s":0},{"p":"38132.8","s":117},{"p":"38135","s":0},{"p":"38131.6","s":0},{"p":"38128.7","s":0},{"p":"38132.9","s":0},{"p":"38134.1","s":3402},{"p":"38031.1","s":0},{"p":"38130.9","s":0},{"p":"38131.3","s":0},{"p":"38020.9","s":0},{"p":"38135.1","s":0},{"p":"38085.8","s":0}],"s":"BTC_USDT","t":1701245722599,"u":53095253613}}
{"time":1701245722,"time_ms":1701245722634,"channel":"futures.order_book_update","event":"update","result":{"U":53095253614,"a":[{"p":"38162","s":0},{"p":"38161.6","s":0},{"p":"38177.5","s":0},{"p":"38142","s":179809},{"p":"38144.4","s":394},{"p":"38147.1","s":0},{"p":"38152.8","s":0},{"p":"38139.9","s":53289},{"p":"38178.4","s":0},{"p":"38148.6","s":0},{"p":"38145.6","s":2315},{"p":"38147","s":0},{"p":"38148.8","s":0},{"p":"38174.7","s":0}],"b":[{"p":"38128.7","s":0},{"p":"38115.4","s":0},{"p":"38030.8","s":0},{"p":"38113.1","s":0},{"p":"38113.7","s":0},{"p":"38132","s":12660},{"p":"38132.1","s":3633},{"p":"38134.1","s":0},{"p":"38131.8","s":0},{"p":"38104.3","s":0},{"p":"38126.4","s":0},{"p":"38128.5","s":0},{"p":"38137.3","s":0},{"p":"38141.9","s":0},{"p":"38107.4","s":0},{"p":"38132.3","s":2000},{"p":"38131.7","s":0}],"s":"BTC_USDT","t":1701245722626,"u":53095253695}}
{"time":1701245722,"time_ms":1701245722653,"channel":"futures.order_book_update","event":"update","result":{"U":53095253696,"a":[{"p":"38146.4","s":3932},{"p":"38145.9","s":0},{"p":"38157.1","s":0},{"p":"38145.8","s":16163},{"p":"38177.2","s":0},{"p":"38140.3","s":0},{"p":"38160.5","s":0},{"p":"38172.4","s":0},{"p":"38157.8","s":0},{"p":"38155","s":0},{"p":"38179.8","s":0},{"p":"38148","s":0},{"p":"38140.2","s":0},{"p":"38147","s":733},{"p":"38146.9","s":3601},{"p":"38160.1","s":0},{"p":"38146.5","s":200},{"p":"38168.6","s":0},{"p":"38162.8","s":0},{"p":"38139.9","s":207947},{"p":"38142","s":48257},{"p":"38181","s":0},{"p":"38140.1","s":0},{"p":"38145.3","s":13414},{"p":"38153.2","s":0},{"p":"38152.5","s":0},{"p":"38140.6","s":0},{"p":"38141.8","s":3932},{"p":"38142.4","s":0},{"p":"38149.4","s":0},{"p":"38159.5","s":0}],"b":[{"p":"38139.8","s":3616},{"p":"38126.4","s":0},{"p":"38119.5","s":0},{"p":"38115.9","s":0},{"p":"38122.5","s":0},{"p":"38131.8","s":1},{"p":"38138","s":0},{"p":"38130.6","s":0},{"p":"38135.9","s":15000},{"p":"38130","s":0},{"p":"38129","s":0},{"p":"38126.2","s":0},{"p":"38134.2","s":94},{"p":"38136.4","s":0},{"p":"38127.2","s":0},{"p":"38121.2","s":0},{"p":"38127.3","s":0}],"s":"BTC_USDT","t":1701245722643,"u":53095253865}}
{"time":1701245722,"time_ms":1701245722672,"channel":"futures.order_book_update","event":"update","result":{"U":53095253866,"a":[{"p":"38145.1","s":9702},{"p":"38142","s":45022},{"p":"38144.8","s":9426},{"p":"38143.8","s":5554},{"p":"38174","s":0},{"p":"38163.6","s":0},{"p":"38179.1","s":0},{"p":"38139.9","s":199378},{"p":"38147","s":0},{"p":"38185","s":0},{"p":"38149.7","s":0},{"p":"38167.4","s":0}],"b":[{"p":"38098.8","s":0},{"p":"38125.3","s":0},{"p":"38134.2","s":0},{"p":"38120.2","s":0},{"p":"38134.1","s":131},{"p":"38111.9","s":0},{"p":"38118.7","s":0},{"p":"37989.3","s":0},{"p":"38110.4","s":0},{"p":"38135.9","s":15026},{"p":"38132.1","s":3659},{"p":"38086.1","s":0},{"p":"38131.8","s":1},{"p":"38008.4","s":0}],"s":"BTC_USDT","t":1701245722663,"u":53095253931}}
{"time":1701245722,"time_ms":1701245722693,"channel":"futures.order_book_update","event":"update","result":{"U":53095253932,"a":[{"p":"38139.9","s":191063},{"p":"38143.9","s":0},{"p":"38154","s":0},{"p":"38179.1","s":0},{"p":"38149.5","s":0},{"p":"38160","s":0},{"p":"38144.8","s":13032},{"p":"38143.7","s":3338},{"p":"38174","s":0},{"p":"38162.5","s":0},{"p":"38147","s":0}],"b":[{"p":"38139.8","s":2308},{"p":"38111.9","s":0},{"p":"38124.5","s":0}],"s":"BTC_USDT","t":1701245722682,"u":53095253965}}
{"time":1701245722,"time_ms":1701245722714,"channel":"futures.order_book_update","event":"update","result":{"U":53095253966,"a":[{"p":"38177","s":0},{"p":"38142","s":31193},{"p":"38146","s":8915},{"p":"38147","s":0},{"p":"38139.9","s":195331},{"p":"38161","s":0},{"p":"38159.2","s":0},{"p":"38179","s":0},{"p":"38145.7","s":17583},{"p":"38141.9","s":2315},{"p":"38152.5","s":0},{"p":"38183.1","s":0},{"p":"38145.6","s":0},{"p":"38146.9","s":0},{"p":"38148","s":0}],"b":[{"p":"38120.7","s":0},{"p":"38131","s":0},{"p":"38119.8","s":0},{"p":"38133.6","s":0},{"p":"38131.1","s":3633},{"p":"38138.3","s":0},{"p":"38023.5","s":0},{"p":"38118","s":0},{"p":"38125.7","s":0},{"p":"38130.9","s":0},{"p":"38136","s":26000},{"p":"38135.4","s":0},{"p":"38134.3","s":0},{"p":"38131.8","s":1},{"p":"38139.8","s":1308},{"p":"38129.4","s":0},{"p":"38093.2","s":0},{"p":"38126.5","s":0},{"p":"38122.5","s":0},{"p":"38120.2","s":0},{"p":"38131.7","s":19190}],"s":"BTC_USDT","t":1701245722705,"u":53095254123}}
{"time":1701245722,"time_ms":1701245722734,"channel":"futures.order_book_update","event":"update","result":{"U":53095254124,"a":[{"p":"38138.9","s":48497},{"p":"38141.9","s":2317},{"p":"38139.9","s":172484},{"p":"38147","s":0},{"p":"38145.7","s":17000},{"p":"38145","s":2011},{"p":"38146.4","s":0},{"p":"38155.3","s":0},{"p":"38144.9","s":733},{"p":"38140.3","s":600},{"p":"38146.5","s":0},{"p":"38145.8","s":0},{"p":"38144.8","s":10858},{"p":"38141.7","s":4932},{"p":"38143.8","s":3380},{"p":"38146","s":0}],"b":[{"p":"38130.6","s":2621},{"p":"38126.5","s":0},{"p":"38135.9","s":26},{"p":"38135.3","s":0},{"p":"38134","s":0},{"p":"38129.3","s":0},{"p":"38127","s":0},{"p":"38128","s":0},{"p":"38130.9","s":550},{"p":"38123.5","s":0},{"p":"38128.2","s":0},{"p":"38105.7","s":0},{"p":"38028.3","s":0},{"p":"38126.8","s":0},{"p":"38131.7","s":15000},{"p":"38130.5","s":183},{"p":"38139.8","s":0},{"p":"38130","s":0},{"p":"38111.9","s":0},{"p":"38088.7","s":0}],"s":"BTC_USDT","t":1701245722724,"u":53095254185}}
{"time":1701245722,"time_ms":1701245722753,"channel":"futures.order_book_update","event":"update","result":{"U":53095254186,"a":[{"p":"38141.7","s":583},{"p":"38139.9","s":52025},{"p":"38143.8","s":3610},{"p":"38153","s":0},{"p":"38178","s":0},{"p":"38159.5","s":0},{"p":"38138.9","s":207019},{"p":"38162.8","s":0},{"p":"38150.5","s":0},{"p":"38153.5","s":0},{"p":"38145.8","s":0},{"p":"38177.2","s":0},{"p":"38158.1","s":0},{"p":"38147.2","s":0},{"p":"38179.9","s":0},{"p":"38146","s":0},{"p":"38142","s":16193},{"p":"38145.3","s":13404},{"p":"38141.9","s":2315},{"p":"38142.8","s":40},{"p":"38143.7","s":0},{"p":"38174.6","s":0},{"p":"38172","s":0}],"b":[{"p":"38111.4","s":0},{"p":"38135.9","s":0},{"p":"38111.8","s":0},{"p":"38125.7","s":0},{"p":"38113.2","s":0},{"p":"38126.7","s":0},{"p":"38127.9","s":0},{"p":"38122.3","s":0},{"p":"38128.6","s":0},{"p":"38130.4","s":4063},{"p":"38126","s":0},{"p":"38129.7","s":0},{"p":"38098.8","s":0},{"p":"38132.4","s":9001},{"p":"38134.9","s":26},{"p":"38134","s":3400},{"p":"38138.2","s":0},{"p":"38121.5","s":0},{"p":"38122.5","s":0},{"p":"38117.3","s":0},{"p":"38136","s":0},{"p":"38132","s":0},{"p":"38128","s":0},{"p":"38127","s":0}],"s":"BTC_USDT","t":1701245722746,"u":53095254340}}
{"time":1701245722,"time_ms":1701245722775,"channel":"futures.order_book_update","event":"update","result":{"U":53095254341,"a":[{"p":"38139.9","s":42380},{"p":"38143.6","s":7689},{"p":"38145","s":10926},{"p":"38151.7","s":0},{"p":"38141.7","s":583},{"p":"38147","s":0},{"p":"38180.9","s":0},{"p":"38143.8","s":7252},{"p":"38179.1","s":0},{"p":"38145.2","s":2681},{"p":"38159.5","s":0},{"p":"38138.9","s":193401},{"p":"38144.9","s":0},{"p":"38151.5","s":0},{"p":"38139.5","s":3110},{"p":"38145.3","s":0},{"p":"38145.7","s":0},{"p":"38177.2","s":0},{"p":"38141.6","s":9718}],"b":[{"p":"38133.9","s":3030}],"s":"BTC_USDT","t":1701245722767,"u":53095254383}}
{"time":1701245722,"time_ms":1701245722794,"channel":"futures.order_book_update","event":"update","result":{"U":53095254384,"a":[{"p":"38166","s":0},{"p":"38158","s":0},{"p":"38138.9","s":184429},{"p":"38145","s":2011},{"p":"38143.5","s":321},{"p":"38159","s":0},{"p":"38156.5","s":0},{"p":"38153.1","s":0},{"p":"38139.9","s":42465},{"p":"38143.8","s":10858},{"p":"38180","s":0},{"p":"38142","s":15586},{"p":"38145.2","s":0},{"p":"38178.3","s":0},{"p":"38177.4","s":0},{"p":"38167","s":0}],"b":[{"p":"38122.4","s":0},{"p":"38134.2","s":599},{"p":"38130.7","s":2518},{"p":"38130.1","s":0},{"p":"38119.5","s":0},{"p":"38106.9","s":0},{"p":"38125.7","s":0},{"p":"38134","s":1823},{"p":"38130.4","s":0},{"p":"38130.5","s":0},{"p":"38122.6","s":0},{"p":"38133.9","s":393},{"p":"38130.3","s":0},{"p":"38100.2","s":0},{"p":"38122.5","s":0},{"p":"38127.4","s":0},{"p":"38090.8","s":0},{"p":"38124.6","s":0}],"s":"BTC_USDT","t":1701245722784,"u":53095254435}}
{"time":1701245722,"time_ms":1701245722813,"channel":"futures.order_book_update","event":"update","result":{"U":53095254436,"a":[{"p":"38143.6","s":2174},{"p":"38143.7","s":733},{"p":"38145","s":0},{"p":"38145.1","s":0},{"p":"38146.3","s":0},{"p":"38149.2","s":0},{"p":"38140.2","s":5516},{"p":"38138.9","s":184953},{"p":"38139.9","s":34353},{"p":"38178.3","s":0},{"p":"38156.1","s":0}],"b":[{"p":"38126.9","s":0},{"p":"38122.5","s":0},{"p":"38128.2","s":0},{"p":"38130.4","s":0},{"p":"38130","s":0},{"p":"38130.5","s":183},{"p":"38132.1","s":26},{"p":"38134","s":0},{"p":"38126","s":0},{"p":"38121","s":0},{"p":"38129.1","s":0},{"p":"38103.3","s":0}],"s":"BTC_USDT","t":1701245722802,"u":53095254506}}
{"time":1701245722,"time_ms":1701245722831,"channel":"futures.order_book_update","event":"update","result":{"U":53095254507,"a":[{"p":"38140.2","s":0},{"p":"38139.9","s":33744},{"p":"38138.9","s":185562},{"p":"38145","s":2011},{"p":"38141.6","s":15234}],"b":[{"p":"38134.3","s":680},{"p":"38130.5","s":0},{"p":"38121.7","s":0},{"p":"38025.1","s":0},{"p":"38105.2","s":0},{"p":"38122.4","s":0}],"s":"BTC_USDT","t":1701245722820,"u":53095254528}}
{"time":1701245722,"time_ms":1701245722854,"channel":"futures.order_book_update","event":"update","result":{"U":53095254529,"a":[{"p":"38142","s":15062},{"p":"38138.9","s":186086},{"p":"38143.8","s":10949},{"p":"38162.7","s":0},{"p":"38162.5","s":0}],"b":[{"p":"38115.3","s":0}],"s":"BTC_USDT","t":1701245722842,"u":53095254539}}
{"time":1701245722,"time_ms":1701245722874,"channel":"futures.order_book_update","event":"update","result":{"U":53095254540,"a":[{"p":"38138.9","s":190761},{"p":"38139.9","s":30074},{"p":"38155.5","s":0}],"b":[{"p":"38130.5","s":183},{"p":"38138.8","s":97},{"p":"38130.9","s":0},{"p":"38131.1","s":0},{"p":"38126.1","s":0},{"p":"38130.4","s":131},{"p":"38121.4","s":0},{"p":"38129.1","s":0},{"p":"38097","s":0}],"s":"BTC_USDT","t":1701245722866,"u":53095254560}}
{"time":1701245722,"time_ms":1701245722892,"channel":"futures.order_book_update","event":"update","result":{"U":53095254561,"a":[{"p":"38139.5","s":7042},{"p":"38150.7","s":0},{"p":"38159.5","s":0},{"p":"38156.3","s":0}],"b":[{"p":"38130.7","s":0},{"p":"38128","s":0},{"p":"38118.5","s":0},{"p":"38130.1","s":2187}],"s":"BTC_USDT","t":1701245722880,"u":53095254573}}
{"time":1701245722,"time_ms":1701245722914,"channel":"futures.order_book_update","event":"update","result":{"U":53095254574,"a":[{"p":"38157.9","s":0}],"b":[{"p":"38125","s":0},{"p":"38129.2","s":0},{"p":"38124","s":0},{"p":"38029.2","s":0}],"s":"BTC_USDT","t":1701245722905,"u":53095254597}}
{"time":1701245722,"time_ms":1701245722931,"channel":"futures.order_book_update","event":"update","result":{"U":53095254598,"a":[{"p":"38138.9","s":194431}],"b":[{"p":"38133.1","s":655},{"p":"38130.1","s":0},{"p":"38117.7","s":0}],"s":"BTC_USDT","t":1701245722919,"u":53095254606}}
{"time":1701245722,"time_ms":1701245722954,"channel":"futures.order_book_update","event":"update","result":{"U":53095254607,"a":[{"p":"38139.9","s":30729},{"p":"38159","s":0}],"b":[{"p":"38109.2","s":0},{"p":"38130.1","s":2187},{"p":"38133.1","s":0}],"s":"BTC_USDT","t":1701245722934,"u":53095254611}}
{"time":1701245722,"time_ms":1701245722974,"channel":"futures.order_book_update","event":"update","result":{"U":53095254612,"a":[{"p":"38151.3","s":0}],"b":[{"p":"38138.8","s":597}],"s":"BTC_USDT","t":1701245722958,"u":53095254614}}
{"time":1701245722,"time_ms":1701245722994,"channel":"futures.order_book_update","event":"update","result":{"U":53095254615,"a":[{"p":"38141.2","s":525},{"p":"38145","s":0}],"b":[{"p":"38115.9","s":0}],"s":"BTC_USDT","t":1701245722975,"u":53095254616}}
{"time":1701245723,"time_ms":1701245723011,"channel":"futures.order_book_update","event":"update","result":{"U":53095254617,"a":[{"p":"38142","s":11917},{"p":"38138.9","s":194694},{"p":"38159.5","s":0}],"b":[{"p":"38126","s":0}],"s":"BTC_USDT","t":1701245722998,"u":53095254628}}
{"time":1701245723,"time_ms":1701245723034,"channel":"futures.order_book_update","event":"update","result":{"U":53095254629,"a":[{"p":"38145","s":2011},{"p":"38141.1","s":5910},{"p":"38144.3","s":1258},{"p":"38138.9","s":197839},{"p":"38143.6","s":0},{"p":"38144.8","s":10858},{"p":"38145.1","s":9702},{"p":"38141.5","s":11746},{"p":"38143.7","s":0},{"p":"38141.9","s":0},{"p":"38141.6","s":0},{"p":"38182","s":0}],"b":[{"p":"38123.6","s":0},{"p":"38126.5","s":0},{"p":"38119.8","s":0},{"p":"38126.6","s":0},{"p":"38129.3","s":0},{"p":"38126.1","s":0},{"p":"38138.8","s":97},{"p":"38126.4","s":0},{"p":"38127.8","s":0},{"p":"38128.5","s":0},{"p":"38124.7","s":0},{"p":"38119","s":0}],"s":"BTC_USDT","t":1701245723026,"u":53095254670}}
{"time":1701245723,"time_ms":1701245723052,"channel":"futures.order_book_update","event":"update","result":{"U":53095254671,"a":[{"p":"38144.1","s":4457},{"p":"38145.1","s":0},{"p":"38143.5","s":7057},{"p":"38141","s":7049},{"p":"38141.5","s":4595}],"b":[],"s":"BTC_USDT","t":1701245723042,"u":53095254675}}
{"time":1701245723,"time_ms":1701245723071,"channel":"futures.order_book_update","event":"update","result":{"U":53095254676,"a":[{"p":"38141","s":3550},{"p":"38145.1","s":0}],"b":[{"p":"38119.7","s":0}],"s":"BTC_USDT","t":1701245723060,"u":53095254681}}
{"time":1701245723,"time_ms":1701245723093,"channel":"futures.order_book_update","event":"update","result":{"U":53095254682,"a":[{"p":"38172.4","s":0},{"p":"38177.6","s":0},{"p":"38154.1","s":0},{"p":"38144.8","s":10858},{"p":"38147.6","s":0},{"p":"38138","s":92733},{"p":"38137.9","s":169187},{"p":"38145","s":0},{"p":"38159.5","s":0},{"p":"38145.5","s":0},{"p":"38157.1","s":0},{"p":"38138.9","s":41791},{"p":"38141.5","s":0},{"p":"38149.5","s":0},{"p":"38138.8","s":5000},{"p":"38142.8","s":0},{"p":"38159","s":0},{"p":"38144.5","s":525},{"p":"38141.1","s":8084}],"b":[{"p":"38124","s":0},{"p":"38125.7","s":0},{"p":"38128","s":0},{"p":"38126","s":0},{"p":"38129.9","s":40},{"p":"38129.3","s":3633},{"p":"38137.8","s":24500},{"p":"38124.7","s":0},{"p":"38138.8","s":0},{"p":"38137.9","s":0}],"s":"BTC_USDT","t":1701245723083,"u":53095254870}}
{"time":1701245723,"time_ms":1701245723114,"channel":"futures.order_book_update","event":"update","result":{"U":53095254871,"a":[{"p":"38138","s":21799},{"p":"38139.9","s":15655},{"p":"38141","s":4075},{"p":"38140.9","s":2880},{"p":"38164.8","s":0},{"p":"38146.5","s":0},{"p":"38150.5","s":0},{"p":"38137.9","s":202996},{"p":"38138.8","s":27500},{"p":"38138.9","s":23472},{"p":"38141.6","s":2174},{"p":"38144.5","s":0},{"p":"38175.3","s":0},{"p":"38145","s":0},{"p":"38176.2","s":0},{"p":"38142.8","s":3610},{"p":"38140.3","s":0},{"p":"38144.8","s":0},{"p":"38152","s":0},{"p":"38177","s":0},{"p":"38178","s":0},{"p":"38140.8","s":1050},{"p":"38141.8","s":3972},{"p":"38141.1","s":394},{"p":"38144.4","s":0}],"b":[{"p":"38128.9","s":4191},{"p":"38134.9","s":0},{"p":"38119.5","s":0},{"p":"37987.2","s":0},{"p":"38133.9","s":419},{"p":"38128.8","s":207},{"p":"38128.5","s":2000},{"p":"38132.1","s":0},{"p":"38125","s":0},{"p":"38127","s":0},{"p":"38130.1","s":2213},{"p":"38137.8","s":25100},{"p":"38132.4","s":0}],"s":"BTC_USDT","t":1701245723106,"u":53095254986}}
{"time":1701245723,"time_ms":1701245723147,"channel":"futures.order_book_update","event":"update","result":{"U":53095254987,"a":[{"p":"38140.2","s":3341},{"p":"38172.2","s":0},{"p":"38138.9","s":16657},{"p":"38139.4","s":2346},{"p":"38140","s":2},{"p":"38158.4","s":0},{"p":"38156.1","s":0},{"p":"38141.1","s":1970},{"p":"38142.8","s":0},{"p":"38176.3","s":0},{"p":"38138","s":6584},{"p":"38137.9","s":121910},{"p":"38141.3","s":1050},{"p":"38143.8","s":0},{"p":"38143.4","s":0},{"p":"38142.7","s":0},{"p":"38141.4","s":2174},{"p":"38157.5","s":0},{"p":"38137.5","s":2011},{"p":"38141","s":2917},{"p":"38138.8","s":27574},{"p":"38141.6","s":0},{"p":"38146.3","s":0},{"p":"38136.7","s":93014},{"p":"38142","s":0},{"p":"38144.1","s":0},{"p":"38144.8","s":0},{"p":"38189","s":0},{"p":"38181.8","s":0},{"p":"38163.7","s":0},{"p":"38159.5","s":0},{"p":"38143.5","s":0},{"p":"38144.3","s":0},{"p":"38148.5","s":0},{"p":"38141.9","s":0},{"p":"38144.5","s":0},{"p":"38140.9","s":2700}],"b":[{"p":"38127.4","s":0},{"p":"38125.2","s":0},{"p":"38110.6","s":0},{"p":"38126.3","s":0},{"p":"38124.5","s":0},{"p":"38128.5","s":0},{"p":"38095.3","s":0},{"p":"38108.9","s":0},{"p":"38123","s":0},{"p":"38124.3","s":0},{"p":"38127","s":0},{"p":"38128.3","s":131},{"p":"38118.7","s":0},{"p":"38132.6","s":2},{"p":"38115.7","s":0},{"p":"38124.8","s":0},{"p":"38125.1","s":0},{"p":"38124.2","s":0},{"p":"38117.9","s":0},{"p":"38132.4","s":9001},{"p":"38131.5","s":2},{"p":"38132.3","s":0},{"p":"38125.4","s":0},{"p":"38127.8","s":0},{"p":"38128.2","s":0},{"p":"38123.7","s":0},{"p":"38125.6","s":0},{"p":"38026.8","s":0},{"p":"38119.1","s":0},{"p":"38087","s":0},{"p":"38126.2","s":0},{"p":"38128.1","s":0},{"p":"38102","s":0},{"p":"38133.4","s":2},{"p":"38122.5","s":0},{"p":"38093.7","s":0},{"p":"38095","s":0},{"p":"38121.4","s":0},{"p":"38124.6","s":0},{"p":"38118.9","s":0},{"p":"38115","s":0},{"p":"38134.1","s":133},{"p":"38128.8","s":0},{"p":"38129.3","s":0},{"p":"38137.8","s":0},{"p":"38125.7","s":0},{"p":"38126","s":0}],"s":"BTC_USDT","t":1701245723138,"u":53095255178}}
{"time":1701245723,"time_ms":1701245723151,"channel":"futures.order_book_update","event":"update","result":{"U":53095255179,"a":[{"p":"38137.9","s":125580},{"p":"38141.8","s":0},{"p":"38160.5","s":0},{"p":"38136.7","s":94433},{"p":"38138.3","s":600}],"b":[{"p":"38125.3","s":0},{"p":"38126.9","s":0},{"p":"38127.6","s":0},{"p":"38116.7","s":0},{"p":"38124","s":0},{"p":"38102.5","s":0},{"p":"38127.1","s":0},{"p":"38115.3","s":0},{"p":"38123.2","s":0},{"p":"38083.6","s":0},{"p":"38126.3","s":0}],"s":"BTC_USDT","t":1701245723145,"u":53095255206}}
{"time":1701245723,"time_ms":1701245723172,"channel":"futures.order_book_update","event":"update","result":{"U":53095255207,"a":[{"p":"38141.6","s":3642},{"p":"38145.7","s":0},{"p":"38141.8","s":3932},{"p":"38161","s":0},{"p":"38142.3","s":0},{"p":"38174.3","s":0},{"p":"38141.4","s":0},{"p":"38137.5","s":0},{"p":"38140.2","s":0},{"p":"38151","s":0},{"p":"38142","s":0},{"p":"38170.5","s":0},{"p":"38139.8","s":2175},{"p":"38138.8","s":2249},{"p":"38150.5","s":0},{"p":"38140.6","s":40},{"p":"38138","s":0},{"p":"38137.9","s":54619},{"p":"38151.1","s":0},{"p":"38154.4","s":0},{"p":"38138.9","s":1657},{"p":"38149.5","s":0},{"p":"38159.5","s":0},{"p":"38140.9","s":525},{"p":"38140","s":2},{"p":"38159","s":0},{"p":"38153.3","s":0},{"p":"38146.5","s":0},{"p":"38137","s":0},{"p":"38157.5","s":0},{"p":"38136.7","s":191679}],"b":[{"p":"38133.4","s":0},{"p":"38130.5","s":0},{"p":"38126","s":0},{"p":"38127.5","s":3725},{"p":"38128.2","s":4389},{"p":"38121.7","s":0},{"p":"38127.1","s":0},{"p":"38128.3","s":2131},{"p":"38123.2","s":0},{"p":"38125.3","s":0},{"p":"38132.6","s":0},{"p":"38123.3","s":0},{"p":"38127.2","s":550},{"p":"38134.1","s":131},{"p":"38132.7","s":26},{"p":"38134.3","s":0},{"p":"38121.2","s":0},{"p":"38106.2","s":0},{"p":"38127.3","s":26},{"p":"38116.9","s":0},{"p":"38124","s":0},{"p":"38131.5","s":0},{"p":"38120.9","s":0},{"p":"38133.9","s":393},{"p":"38127.6","s":4189},{"p":"38128.9","s":0},{"p":"38096.8","s":0},{"p":"38130.1","s":26}],"s":"BTC_USDT","t":1701245723164,"u":53095255389}}
{"time":1701245723,"time_ms":1701245723194,"channel":"futures.order_book_update","event":"update","result":{"U":53095255390,"a":[{"p":"38139.8","s":0},{"p":"38173.8","s":0},{"p":"38141.8","s":3932},{"p":"38149.4","s":0},{"p":"38144.5","s":0},{"p":"38141.7","s":2699},{"p":"38137.5","s":2011},{"p":"38137.9","s":49621},{"p":"38148.5","s":0},{"p":"38140.9","s":2700},{"p":"38141.6","s":7248},{"p":"38159.5","s":0},{"p":"38139.4","s":2346},{"p":"38136.7","s":191408}],"b":[{"p":"38123","s":0},{"p":"38116.1","s":0},{"p":"38123.2","s":0},{"p":"38116","s":0},{"p":"38127.7","s":2516},{"p":"38127.3","s":26},{"p":"38124.3","s":0},{"p":"38134.3","s":675},{"p":"38123.7","s":0},{"p":"38128.2","s":0},{"p":"38121.7","s":0},{"p":"38121.6","s":0},{"p":"38124.1","s":0},{"p":"38127.2","s":0},{"p":"38122.3","s":0}],"s":"BTC_USDT","t":1701245723185,"u":53095255450}}
{"time":1701245723,"time_ms":1701245723211,"channel":"futures.order_book_update","event":"update","result":{"U":53095255451,"a":[{"p":"38147.4","s":0},{"p":"38156.9","s":0},{"p":"38139.9","s":15000},{"p":"38175","s":0},{"p":"38145.1","s":0},{"p":"38136.7","s":189574},{"p":"38139.4","s":4521},{"p":"38141.6","s":10858},{"p":"38163.7","s":0},{"p":"38159.2","s":0},{"p":"38154.2","s":0},{"p":"38175.1","s":0},{"p":"38138.9","s":1133},{"p":"38140.9","s":525}],"b":[{"p":"38127.6","s":0},{"p":"38086.4","s":0},{"p":"38071.1","s":0},{"p":"38121.5","s":0},{"p":"38118.3","s":0},{"p":"38127.1","s":0},{"p":"38131.8","s":0},{"p":"38127.2","s":550},{"p":"38005.3","s":0},{"p":"38081.6","s":0},{"p":"37985.2","s":0},{"p":"38124.9","s":0},{"p":"38126.9","s":15000}],"s":"BTC_USDT","t":1701245723199,"u":53095255526}}
{"time":1701245723,"time_ms":1701245723232,"channel":"futures.order_book_update","event":"update","result":{"U":53095255527,"a":[{"p":"38168.2","s":0},{"p":"38151.7","s":0},{"p":"38141.8","s":3932},{"p":"38144.2","s":0},{"p":"38137.4","s":4501},{"p":"38141","s":4870},{"p":"38174.3","s":0},{"p":"38140.7","s":733},{"p":"38139.4","s":0},{"p":"38177","s":0},{"p":"38138.8","s":0},{"p":"38136.7","s":197266},{"p":"38159.4","s":0},{"p":"38147","s":0},{"p":"38137.9","s":22121}],"b":[{"p":"38134.3","s":0},{"p":"38123.4","s":0},{"p":"38097.2","s":0},{"p":"38110.6","s":0},{"p":"38123.2","s":0},{"p":"38109","s":0},{"p":"38127.1","s":9004},{"p":"38086.4","s":0},{"p":"38114.7","s":0},{"p":"38126.9","s":15000},{"p":"38120.5","s":0},{"p":"38065.4","s":0},{"p":"38126.7","s":1},{"p":"38120.4","s":0},{"p":"38067.3","s":0},{"p":"38131.7","s":0},{"p":"38122.9","s":0},{"p":"38071.1","s":0}],"s":"BTC_USDT","t":1701245723226,"u":53095255578}}
{"time":1701245723,"time_ms":1701245723251,"channel":"futures.order_book_update","event":"update","result":{"U":53095255579,"a":[{"p":"38138.7","s":2175},{"p":"38141.5","s":733},{"p":"38141","s":6533},{"p":"38139.4","s":9002},{"p":"38141.8","s":0},{"p":"38141.7","s":0},{"p":"38137.4","s":4501},{"p":"38178.7","s":0},{"p":"38136.7","s":177316},{"p":"38140.7","s":0},{"p":"38178.4","s":0}],"b":[{"p":"38130.7","s":1676},{"p":"38132.4","s":0},{"p":"38122.1","s":0},{"p":"38126.6","s":0},{"p":"38071.1","s":0}],"s":"BTC_USDT","t":1701245723243,"u":53095255599}}
{"time":1701245723,"time_ms":1701245723275,"channel":"futures.order_book_update","event":"update","result":{"U":53095255600,"a":[{"p":"38136.7","s":173975},{"p":"38138.2","s":2175},{"p":"38138.7","s":7854},{"p":"38141.7","s":2699},{"p":"38141.5","s":0},{"p":"38137.4","s":0},{"p":"38141.6","s":10858},{"p":"38145.8","s":0}],"b":[{"p":"38123","s":0},{"p":"38081.8","s":0},{"p":"38107.9","s":0},{"p":"38023.1","s":0},{"p":"38120.9","s":0},{"p":"38119.6","s":0}],"s":"BTC_USDT","t":1701245723264,"u":53095255625}}
{"time":1701245723,"time_ms":1701245723294,"channel":"futures.order_book_update","event":"update","result":{"U":53095255626,"a":[{"p":"38139.3","s":16024},{"p":"38141.6","s":0},{"p":"38141.7","s":0},{"p":"38142.7","s":0},{"p":"38136.7","s":173525},{"p":"38137.2","s":3932},{"p":"38138.7","s":4513},{"p":"38153.2","s":0},{"p":"38153.1","s":0}],"b":[{"p":"38127.6","s":2},{"p":"38126.7","s":0},{"p":"38123.3","s":0},{"p":"38126.8","s":0}],"s":"BTC_USDT","t":1701245723282,"u":53095255648}}
{"time":1701245723,"time_ms":1701245723312,"channel":"futures.order_book_update","event":"update","result":{"U":53095255649,"a":[{"p":"38141.6","s":0},{"p":"38136.7","s":179115},{"p":"38137.9","s":22646},{"p":"38141.2","s":0},{"p":"38137.7","s":525},{"p":"38139.4","s":0},{"p":"38160.8","s":0},{"p":"38142.3","s":0},{"p":"38147.9","s":0},{"p":"38139.2","s":9617},{"p":"38140.7","s":733},{"p":"38137.1","s":583},{"p":"38138.2","s":0},{"p":"38145.1","s":0},{"p":"38141.3","s":0},{"p":"38149.1","s":0},{"p":"38141.7","s":0}],"b":[{"p":"38029.1","s":0},{"p":"38126.8","s":2},{"p":"38127.2","s":0},{"p":"38120.1","s":0},{"p":"38113.9","s":0},{"p":"38121.6","s":0},{"p":"38123.6","s":0},{"p":"38125","s":0},{"p":"38125.3","s":0},{"p":"38125.9","s":0},{"p":"38122.5","s":0},{"p":"38114.5","s":0},{"p":"38062.6","s":0}],"s":"BTC_USDT","t":1701245723302,"u":53095255727}}
{"time":1701245723,"time_ms":1701245723333,"channel":"futures.order_book_update","event":"update","result":{"U":53095255728,"a":[{"p":"38136.7","s":181810}],"b":[{"p":"38084.3","s":0},{"p":"38069.4","s":0},{"p":"38123.5","s":0},{"p":"38124.9","s":0},{"p":"38098.8","s":0},{"p":"38126.7","s":1},{"p":"38134.2","s":0},{"p":"38100.4","s":0}],"s":"BTC_USDT","t":1701245723324,"u":53095255747}}
{"time":1701245723,"time_ms":1701245723352,"channel":"futures.order_book_update","event":"update","result":{"U":53095255748,"a":[],"b":[{"p":"38102.5","s":0}],"s":"BTC_USDT","t":1701245723344,"u":53095255757}}
{"time":1701245723,"time_ms":1701245723373,"channel":"futures.order_book_update","event":"update","result":{"U":53095255758,"a":[{"p":"38136.7","s":185480},{"p":"38150.9","s":0},{"p":"38157.3","s":0}],"b":[{"p":"38126.1","s":0},{"p":"38126.6","s":131},{"p":"38126.3","s":4189},{"p":"38127.6","s":0},{"p":"38126.8","s":0},{"p":"38124.9","s":0}],"s":"BTC_USDT","t":1701245723361,"u":53095255767}}
{"time":1701245723,"time_ms":1701245723391,"channel":"futures.order_book_update","event":"update","result":{"U":53095255768,"a":[],"b":[{"p":"38125.7","s":0},{"p":"38118.5","s":0},{"p":"38125.4","s":0},{"p":"38127.6","s":2},{"p":"38128.4","s":2},{"p":"38126.9","s":15002},{"p":"38126.6","s":0},{"p":"38126.3","s":0}],"s":"BTC_USDT","t":1701245723380,"u":53095255780}}
{"time":1701245723,"time_ms":1701245723413,"channel":"futures.order_book_update","event":"update","result":{"U":53095255781,"a":[{"p":"38136.7","s":186004},{"p":"38138.9","s":609},{"p":"38153.4","s":0},{"p":"38154.1","s":0}],"b":[{"p":"38005.4","s":0},{"p":"38016.9","s":0},{"p":"38131","s":655},{"p":"38025.3","s":0},{"p":"38006.2","s":0},{"p":"38013","s":0},{"p":"38114.5","s":0},{"p":"38059.9","s":0},{"p":"38126.7","s":0},{"p":"38024.5","s":0},{"p":"38016.7","s":0},{"p":"38028.3","s":0}],"s":"BTC_USDT","t":1701245723398,"u":53095255888}}
{"time":1701245723,"time_ms":1701245723431,"channel":"futures.order_book_update","event":"update","result":{"U":53095255889,"a":[{"p":"38136.7","s":186154},{"p":"38177.6","s":0}],"b":[{"p":"38131","s":0},{"p":"38106.8","s":0},{"p":"38113.5","s":0},{"p":"38126.7","s":1}],"s":"BTC_USDT","t":1701245723422,"u":53095255899}}
{"time":1701245723,"time_ms":1701245723452,"channel":"futures.order_book_update","event":"update","result":{"U":53095255900,"a":[{"p":"38134.2","s":5101},{"p":"38137.9","s":15525},{"p":"38136.7","s":193255},{"p":"38136.3","s":18802},{"p":"38141.1","s":0},{"p":"38141","s":0},{"p":"38161","s":0}],"b":[{"p":"38126.6","s":131},{"p":"38126.3","s":4189},{"p":"38136.2","s":0},{"p":"38136.6","s":0}],"s":"BTC_USDT","t":1701245723439,"u":53095255917}}
{"time":1701245723,"time_ms":1701245723474,"channel":"futures.order_book_update","event":"update","result":{"U":53095255918,"a":[{"p":"38136.6","s":7864},{"p":"38145.6","s":0},{"p":"38172.3","s":0},{"p":"38136.3","s":18706},{"p":"38167.6","s":0},{"p":"38135.8","s":2681},{"p":"38155.8","s":0},{"p":"38147.5","s":0},{"p":"38157.2","s":0},{"p":"38138.1","s":40},{"p":"38138.3","s":0},{"p":"38159","s":0},{"p":"38137.9","s":525},{"p":"38140.6","s":0},{"p":"38140.9","s":0},{"p":"38137.1","s":2758},{"p":"38140.8","s":0},{"p":"38164.7","s":0},{"p":"38143","s":0},{"p":"38142.5","s":0},{"p":"38150.1","s":0},{"p":"38138.7","s":2338},{"p":"38139.1","s":3642},{"p":"38137","s":3341},{"p":"38150.4","s":0},{"p":"38162.8","s":0},{"p":"38152.4","s":0},{"p":"38150","s":0},{"p":"38136.7","s":60609},{"p":"38140.7","s":0},{"p":"38186.5","s":0},{"p":"38156","s":0},{"p":"38146.3","s":0},{"p":"38134.2","s":155881}],"b":[{"p":"38130.6","s":0},{"p":"38120.5","s":0},{"p":"38125.3","s":0},{"p":"38113.1","s":0},{"p":"38125.7","s":2},{"p":"38125.5","s":182},{"p":"38125.6","s":3633},{"p":"38115.9","s":0},{"p":"37984","s":0},{"p":"38128.4","s":133},{"p":"38134.1","s":12767},{"p":"38107.2","s":0},{"p":"38121","s":0},{"p":"38095.9","s":0},{"p":"38092","s":0},{"p":"38102.4","s":0},{"p":"38089.2","s":0},{"p":"38130.2","s":26},{"p":"38127.3","s":0},{"p":"38130.1","s":0},{"p":"38124","s":0},{"p":"38123","s":0},{"p":"38132.7","s":0},{"p":"38120.7","s":0},{"p":"38098.6","s":0}],"s":"BTC_USDT","t":1701245723468,"u":53095256137}}
{"time":1701245723,"time_ms":1701245723506,"channel":"futures.order_book_update","event":"update","result":{"U":53095256138,"a":[{"p":"38139.1","s":7248},{"p":"38134.2","s":154230},{"p":"38138.2","s":4350},{"p":"38139.9","s":0},{"p":"38140.7","s":0},{"p":"38140","s":0},{"p":"38148.5","s":0},{"p":"38137.1","s":583},{"p":"38157.5","s":0},{"p":"38136.7","s":60085},{"p":"38136.3","s":6779},{"p":"38138.6","s":1409},{"p":"38144","s":0},{"p":"38172.9","s":0}],"b":[{"p":"38122","s":0},{"p":"38128.4","s":732},{"p":"38125.4","s":5984},{"p":"38130.7","s":0},{"p":"38120.9","s":0},{"p":"38124","s":0},{"p":"38125.3","s":0}],"s":"BTC_USDT","t":1701245723484,"u":53095256177}}
{"time":1701245723,"time_ms":1701245723513,"channel":"futures.order_book_update","event":"update","result":{"U":53095256178,"a":[{"p":"38134.2","s":154305},{"p":"38136.5","s":2175},{"p":"38138.2","s":2175},{"p":"38139.1","s":10858},{"p":"38138.7","s":0},{"p":"38173.6","s":0},{"p":"38139.5","s":7042},{"p":"38136.9","s":2293},{"p":"38139.9","s":0},{"p":"38136.3","s":0}],"b":[{"p":"38110.7","s":0},{"p":"38115.4","s":0}],"s":"BTC_USDT","t":1701245723505,"u":53095256290}}
{"time":1701245723,"time_ms":1701245723532,"channel":"futures.order_book_update","event":"update","result":{"U":53095256291,"a":[{"p":"38139.9","s":15000},{"p":"38134.2","s":157187},{"p":"38138.6","s":0}],"b":[],"s":"BTC_USDT","t":1701245723516,"u":53095256298}}
{"time":1701245723,"time_ms":1701245723550,"channel":"futures.order_book_update","event":"update","result":{"U":53095256299,"a":[],"b":[{"p":"38125.4","s":9594},{"p":"38047.4","s":0}],"s":"BTC_USDT","t":1701245723542,"u":53095256310}}
{"time":1701245723,"time_ms":1701245723573,"channel":"futures.order_book_update","event":"update","result":{"U":53095256311,"a":[{"p":"38150.9","s":0},{"p":"38134.9","s":3932},{"p":"38139.9","s":0},{"p":"38150.7","s":0}],"b":[{"p":"38134.1","s":11459},{"p":"38127.5","s":3633},{"p":"38126.3","s":4713},{"p":"38120","s":0},{"p":"38122.7","s":0}],"s":"BTC_USDT","t":1701245723562,"u":53095256322}}
{"time":1701245723,"time_ms":1701245723615,"channel":"futures.order_book_update","event":"update","result":{"U":53095256323,"a":[{"p":"38153.1","s":0},{"p":"38147.2","s":0},{"p":"38134.2","s":157450}],"b":[],"s":"BTC_USDT","t":1701245723593,"u":53095256328}}
{"time":1701245723,"time_ms":1701245723634,"channel":"futures.order_book_update","event":"update","result":{"U":53095256329,"a":[],"b":[{"p":"38128.4","s":730},{"p":"38126.9","s":15000},{"p":"38125.3","s":9960},{"p":"38125","s":5873},{"p":"38127.6","s":0},{"p":"38125.7","s":0}],"s":"BTC_USDT","t":1701245723618,"u":53095256332}}
{"time":1701245723,"time_ms":1701245723653,"channel":"futures.order_book_update","event":"update","result":{"U":53095256333,"a":[{"p":"38139.5","s":0},{"p":"38177.7","s":0},{"p":"38137.4","s":1305}],"b":[{"p":"38129","s":2},{"p":"38127.8","s":2},{"p":"38125.4","s":0},{"p":"38125.5","s":0},{"p":"38129.7","s":2},{"p":"38130.5","s":2},{"p":"38125.3","s":0},{"p":"38125","s":0},{"p":"38115","s":0}],"s":"BTC_USDT","t":1701245723643,"u":53095256340}}
{"time":1701245723,"time_ms":1701245723673,"channel":"futures.order_book_update","event":"update","result":{"U":53095256341,"a":[{"p":"38136.7","s":59561},{"p":"38134.2","s":157974}],"b":[{"p":"38094.9","s":0}],"s":"BTC_USDT","t":1701245723664,"u":53095256347}}
{"time":1701245723,"time_ms":1701245723692,"channel":"futures.order_book_update","event":"update","result":{"U":53095256348,"a":[{"p":"38134.2","s":165076},{"p":"38136.7","s":52460}],"b":[],"s":"BTC_USDT","t":1701245723676,"u":53095256350}}
{"time":1701245723,"time_ms":1701245723712,"channel":"futures.order_book_update","event":"update","result":{"U":53095256351,"a":[{"p":"38138.5","s":550},{"p":"38139.3","s":0}],"b":[{"p":"38134.1","s":3808},{"p":"38120","s":0},{"p":"38121","s":0}],"s":"BTC_USDT","t":1701245723689,"u":53095256356}}
{"time":1701245723,"time_ms":1701245723734,"channel":"futures.order_book_update","event":"update","result":{"U":53095256357,"a":[{"p":"38147","s":0},{"p":"38142.5","s":0},{"p":"38139.5","s":7042},{"p":"38138.1","s":4570},{"p":"38139.3","s":16024},{"p":"38136.5","s":0},{"p":"38136.9","s":0}],"b":[{"p":"38108.9","s":0},{"p":"38124.5","s":0},{"p":"38120","s":0},{"p":"38134.1","s":3808},{"p":"38122.1","s":0}],"s":"BTC_USDT","t":1701245723728,"u":53095256378}}
{"time":1701245723,"time_ms":1701245723754,"channel":"futures.order_book_update","event":"update","result":{"U":53095256379,"a":[{"p":"38137.8","s":2743},{"p":"38137.4","s":0},{"p":"38139.5","s":7042}],"b":[],"s":"BTC_USDT","t":1701245723736,"u":53095256380}}
{"time":1701245723,"time_ms":1701245723772,"channel":"futures.order_book_update","event":"update","result":{"U":53095256381,"a":[{"p":"38137.7","s":919},{"p":"38136.7","s":53115},{"p":"38141","s":0},{"p":"38150.5","s":0}],"b":[],"s":"BTC_USDT","t":1701245723762,"u":53095256389}}
{"time":1701245723,"time_ms":1701245723792,"channel":"futures.order_book_update","event":"update","result":{"U":53095256390,"a":[{"p":"38136.7","s":52460}],"b":[],"s":"BTC_USDT","t":1701245723779,"u":53095256392}}
{"time":1701245723,"time_ms":1701245723813,"channel":"futures.order_book_update","event":"update","result":{"U":53095256393,"a":[{"p":"38134.2","s":162176}],"b":[{"p":"38134.1","s":12059},{"p":"38127.2","s":655},{"p":"38125.6","s":0},{"p":"38104.3","s":0},{"p":"38122.1","s":0}],"s":"BTC_USDT","t":1701245723801,"u":53095256403}}
{"time":1701245723,"time_ms":1701245723832,"channel":"futures.order_book_update","event":"update","result":{"U":53095256404,"a":[{"p":"38149.7","s":0},{"p":"38140","s":0}],"b":[{"p":"38134.1","s":11459},{"p":"38125.6","s":3633},{"p":"38127.2","s":0},{"p":"38122.1","s":0}],"s":"BTC_USDT","t":1701245723824,"u":53095256410}}
{"time":1701245723,"time_ms":1701245723853,"channel":"futures.order_book_update","event":"update","result":{"U":53095256411,"a":[],"b":[{"p":"38134.1","s":12059}],"s":"BTC_USDT","t":1701245723840,"u":53095256412}}
{"time":1701245723,"time_ms":1701245723922,"channel":"futures.order_book_update","event":"update","result":{"U":53095256413,"a":[{"p":"38136.7","s":24960}],"b":[{"p":"38125.6","s":0},{"p":"38127.1","s":2830},{"p":"38134","s":23500}],"s":"BTC_USDT","t":1701245723914,"u":53095256420}}
{"time":1701245723,"time_ms":1701245723933,"channel":"futures.order_book_update","event":"update","result":{"U":53095256421,"a":[{"p":"38137.5","s":2536}],"b":[{"p":"38125.4","s":9594},{"p":"38125.3","s":9960},{"p":"38125.6","s":3633},{"p":"38129","s":0},{"p":"38130.5","s":0},{"p":"38129.7","s":0},{"p":"38127.8","s":0},{"p":"38125.5","s":182}],"s":"BTC_USDT","t":1701245723925,"u":53095256428}}
{"time":1701245723,"time_ms":1701245723953,"channel":"futures.order_book_update","event":"update","result":{"U":53095256429,"a":[{"p":"38138.4","s":3341},{"p":"38137","s":0},{"p":"38139.5","s":7042}],"b":[{"p":"38128.6","s":2},{"p":"38131.3","s":2},{"p":"38130.5","s":2},{"p":"38129.7","s":2},{"p":"38125.4","s":0},{"p":"38125.3","s":0},{"p":"38125.5","s":0},{"p":"38125.6","s":0}],"s":"BTC_USDT","t":1701245723941,"u":53095256438}}
{"time":1701245723,"time_ms":1701245723973,"channel":"futures.order_book_update","event":"update","result":{"U":53095256439,"a":[{"p":"38150.2","s":0},{"p":"38154.6","s":0}],"b":[],"s":"BTC_USDT","t":1701245723960,"u":53095256440}}
{"time":1701245723,"time_ms":1701245723993,"channel":"futures.order_book_update","event":"update","result":{"U":53095256441,"a":[{"p":"38147.5","s":0}],"b":[{"p":"38120.5","s":0}],"s":"BTC_USDT","t":1701245723981,"u":53095256447}}
{"time":1701245724,"time_ms":1701245724013,"channel":"futures.order_book_update","event":"update","result":{"U":53095256448,"a":[{"p":"38157.7","s":0}],"b":[{"p":"38125.5","s":182},{"p":"38125.6","s":3633},{"p":"38131.3","s":0},{"p":"38122","s":0},{"p":"38121.3","s":0},{"p":"38121","s":0},{"p":"38127","s":100},{"p":"38129.7","s":0},{"p":"38130.5","s":0},{"p":"38128.6","s":0},{"p":"38125.4","s":0},{"p":"38125.3","s":0},{"p":"38126","s":100}],"s":"BTC_USDT","t":1701245724003,"u":53095256459}}
{"time":1701245724,"time_ms":1701245724032,"channel":"futures.order_book_update","event":"update","result":{"U":53095256460,"a":[{"p":"38146.8","s":0},{"p":"38138.8","s":2175},{"p":"38138.1","s":40},{"p":"38137.8","s":4918},{"p":"38138","s":2318},{"p":"38138.2","s":0},{"p":"38139.5","s":0}],"b":[{"p":"38132.7","s":2},{"p":"38126.3","s":0},{"p":"38126","s":0},{"p":"38122.4","s":0},{"p":"38115.1","s":0},{"p":"38119","s":0},{"p":"38130.1","s":2},{"p":"38131.2","s":2},{"p":"38132","s":2},{"p":"38125.5","s":0},{"p":"38125.6","s":0},{"p":"38120.3","s":0}],"s":"BTC_USDT","t":1701245724017,"u":53095256479}}
{"time":1701245724,"time_ms":1701245724052,"channel":"futures.order_book_update","event":"update","result":{"U":53095256480,"a":[{"p":"38138","s":5659},{"p":"38139.5","s":7042},{"p":"38138.4","s":0},{"p":"38137.8","s":2175}],"b":[{"p":"38115.3","s":0}],"s":"BTC_USDT","t":1701245724045,"u":53095256486}}
{"time":1701245724,"time_ms":1701245724071,"channel":"futures.order_book_update","event":"update","result":{"U":53095256487,"a":[{"p":"38142","s":0}],"b":[],"s":"BTC_USDT","t":1701245724060,"u":53095256488}}
{"time":1701245724,"time_ms":1701245724091,"channel":"futures.order_book_update","event":"update","result":{"U":53095256489,"a":[{"p":"38141.9","s":0}],"b":[],"s":"BTC_USDT","t":1701245724075,"u":53095256491}}
{"time":1701245724,"time_ms":1701245724113,"channel":"futures.order_book_update","event":"update","result":{"U":53095256492,"a":[{"p":"38141.7","s":0},{"p":"38138.4","s":3341},{"p":"38138","s":2318},{"p":"38139.5","s":0}],"b":[{"p":"38125.5","s":182},{"p":"38132","s":0},{"p":"38130.1","s":0},{"p":"38132.7","s":0},{"p":"38131.2","s":0},{"p":"38120.9","s":0},{"p":"38126","s":0},{"p":"38126.3","s":4713},{"p":"38125.6","s":3633},{"p":"38125.4","s":9594},{"p":"38120.7","s":0},{"p":"38127","s":200}],"s":"BTC_USDT","t":1701245724105,"u":53095256505}}
{"time":1701245724,"time_ms":1701245724154,"channel":"futures.order_book_update","event":"update","result":{"U":53095256506,"a":[{"p":"38134.2","s":162981}],"b":[{"p":"38131.2","s":2},{"p":"38132.7","s":2},{"p":"38125.5","s":0},{"p":"38125.4","s":0},{"p":"38130.1","s":2},{"p":"38132","s":2},{"p":"38126.3","s":0},{"p":"38125.6","s":0},{"p":"38126.1","s":0}],"s":"BTC_USDT","t":1701245724143,"u":53095256515}}
{"time":1701245724,"time_ms":1701245724173,"channel":"futures.order_book_update","event":"update","result":{"U":53095256516,"a":[{"p":"38150","s":0},{"p":"38134.6","s":600},{"p":"38139.3","s":0}],"b":[{"p":"38111.5","s":0}],"s":"BTC_USDT","t":1701245724160,"u":53095256520}}
{"time":1701245724,"time_ms":1701245724193,"channel":"futures.order_book_update","event":"update","result":{"U":53095256521,"a":[{"p":"38138.3","s":2370},{"p":"38134.2","s":163244},{"p":"38138","s":0},{"p":"38139.3","s":0}],"b":[{"p":"38121.6","s":0}],"s":"BTC_USDT","t":1701245724187,"u":53095256526}}
{"time":1701245724,"time_ms":1701245724233,"channel":"futures.order_book_update","event":"update","result":{"U":53095256527,"a":[],"b":[{"p":"38112","s":0},{"p":"38134.1","s":35559},{"p":"38127","s":9115},{"p":"38125","s":0},{"p":"38121","s":0}],"s":"BTC_USDT","t":1701245724223,"u":53095256533}}
{"time":1701245724,"time_ms":1701245724252,"channel":"futures.order_book_update","event":"update","result":{"U":53095256534,"a":[{"p":"38134.2","s":173943}],"b":[{"p":"38121.5","s":0},{"p":"38120.7","s":0}],"s":"BTC_USDT","t":1701245724239,"u":53095256538}}
{"time":1701245724,"time_ms":1701245724272,"channel":"futures.order_book_update","event":"update","result":{"U":53095256539,"a":[{"p":"38138.3","s":4545},{"p":"38139.3","s":16024},{"p":"38137.8","s":0}],"b":[{"p":"38126.3","s":4713},{"p":"38134","s":0}],"s":"BTC_USDT","t":1701245724260,"u":53095256542}}
{"time":1701245724,"time_ms":1701245724294,"channel":"futures.order_book_update","event":"update","result":{"U":53095256543,"a":[{"p":"38163.6","s":0}],"b":[{"p":"38134.1","s":12059},{"p":"38121.3","s":0}],"s":"BTC_USDT","t":1701245724280,"u":53095256551}}
{"time":1701245724,"time_ms":1701245724312,"channel":"futures.order_book_update","event":"update","result":{"U":53095256552,"a":[{"p":"38143","s":0}],"b":[{"p":"38127.1","s":8653},{"p":"38127","s":200},{"p":"38123","s":0},{"p":"38121.2","s":0},{"p":"38114","s":0},{"p":"38120.3","s":0}],"s":"BTC_USDT","t":1701245724300,"u":53095256564}}
{"time":1701245724,"time_ms":1701245724337,"channel":"futures.order_book_update","event":"update","result":{"U":53095256565,"a":[],"b":[{"p":"38110.1","s":0},{"p":"38129.3","s":3642},{"p":"38126.3","s":0}],"s":"BTC_USDT","t":1701245724320,"u":53095256566}}
{"time":1701245724,"time_ms":1701245724354,"channel":"futures.order_book_update","event":"update","result":{"U":53095256567,"a":[],"b":[{"p":"38129.4","s":2193},{"p":"38126.6","s":0}],"s":"BTC_USDT","t":1701245724345,"u":53095256574}}
{"time":1701245724,"time_ms":1701245724372,"channel":"futures.order_book_update","event":"update","result":{"U":53095256575,"a":[{"p":"38139.5","s":0},{"p":"38149.6","s":0},{"p":"38137.4","s":4497},{"p":"38137.6","s":3341},{"p":"38138.2","s":2175},{"p":"38138.3","s":0},{"p":"38138.4","s":0},{"p":"38139.3","s":16024},{"p":"38142.6","s":0},{"p":"38155.5","s":0},{"p":"38138.8","s":0},{"p":"38139.9","s":0}],"b":[{"p":"38116.6","s":0},{"p":"38121.7","s":0},{"p":"38116.1","s":0},{"p":"38134.1","s":3808},{"p":"38123.3","s":0},{"p":"38120.9","s":0}],"s":"BTC_USDT","t":1701245724361,"u":53095256600}}
{"time":1701245724,"time_ms":1701245724391,"channel":"futures.order_book_update","event":"update","result":{"U":53095256601,"a":[],"b":[{"p":"38120.9","s":0},{"p":"38103.5","s":0}],"s":"BTC_USDT","t":1701245724379,"u":53095256605}}
{"time":1701245724,"time_ms":1701245724452,"channel":"futures.order_book_update","event":"update","result":{"U":53095256606,"a":[],"b":[{"p":"38131.2","s":0},{"p":"38132.7","s":0},{"p":"38130.1","s":0},{"p":"38126.1","s":655},{"p":"38126.3","s":4713},{"p":"38125.6","s":3633},{"p":"38126.6","s":131},{"p":"38132","s":0}],"s":"BTC_USDT","t":1701245724426,"u":53095256611}}
{"time":1701245724,"time_ms":1701245724472,"channel":"futures.order_book_update","event":"update","result":{"U":53095256612,"a":[{"p":"38138","s":3341},{"p":"38137.6","s":0},{"p":"38139.5","s":0}],"b":[{"p":"38126.1","s":0},{"p":"38126.3","s":0},{"p":"38125.6","s":0},{"p":"38130.1","s":2},{"p":"38132.8","s":119},{"p":"38131.2","s":2},{"p":"38132","s":2}],"s":"BTC_USDT","t":1701245724464,"u":53095256618}}
{"time":1701245724,"time_ms":1701245724494,"channel":"futures.order_book_update","event":"update","result":{"U":53095256619,"a":[{"p":"38139.5","s":7042},{"p":"38138.2","s":0},{"p":"38137.4","s":0},{"p":"38137.9","s":2835},{"p":"38138.1","s":2215},{"p":"38139.9","s":15000}],"b":[{"p":"38122.1","s":0},{"p":"38119","s":0},{"p":"38134.1","s":3808},{"p":"38120.8","s":0}],"s":"BTC_USDT","t":1701245724486,"u":53095256632}}
{"time":1701245724,"time_ms":1701245724512,"channel":"futures.order_book_update","event":"update","result":{"U":53095256633,"a":[{"p":"38138.8","s":5516},{"p":"38138","s":0},{"p":"38140","s":0},{"p":"38141.5","s":0}],"b":[{"p":"38121","s":0},{"p":"38121.7","s":0},{"p":"38115.5","s":0}],"s":"BTC_USDT","t":1701245724496,"u":53095256644}}
{"time":1701245724,"time_ms":1701245724532,"channel":"futures.order_book_update","event":"update","result":{"U":53095256645,"a":[{"p":"38142.4","s":0}],"b":[{"p":"38116.4","s":0}],"s":"BTC_USDT","t":1701245724507,"u":53095256648}}
{"time":1701245724,"time_ms":1701245724572,"channel":"futures.order_book_update","event":"update","result":{"U":53095256649,"a":[{"p":"38149.3","s":0}],"b":[],"s":"BTC_USDT","t":1701245724560,"u":53095256649}}
{"time":1701245724,"time_ms":1701245724592,"channel":"futures.order_book_update","event":"update","result":{"U":53095256650,"a":[{"p":"38145.1","s":0}],"b":[{"p":"38127","s":100},{"p":"38134","s":13000},{"p":"38126.6","s":0}],"s":"BTC_USDT","t":1701245724580,"u":53095256655}}
{"time":1701245724,"time_ms":1701245724612,"channel":"futures.order_book_update","event":"update","result":{"U":53095256656,"a":[{"p":"38151.1","s":0},{"p":"38141.8","s":0},{"p":"38166.3","s":0},{"p":"38141.7","s":0},{"p":"38162.5","s":0},{"p":"38158.7","s":0}],"b":[{"p":"38121.7","s":0},{"p":"38126.6","s":131},{"p":"38134","s":0},{"p":"38109.3","s":0},{"p":"38111.1","s":0}],"s":"BTC_USDT","t":1701245724602,"u":53095256667}}
{"time":1701245724,"time_ms":1701245724652,"channel":"futures.order_book_update","event":"update","result":{"U":53095256668,"a":[{"p":"38137.4","s":3341},{"p":"38138.8","s":2175},{"p":"38139.9","s":0}],"b":[{"p":"38115.4","s":0}],"s":"BTC_USDT","t":1701245724643,"u":53095256670}}
{"time":1701245724,"time_ms":1701245724673,"channel":"futures.order_book_update","event":"update","result":{"U":53095256671,"a":[{"p":"38138.1","s":40},{"p":"38137","s":2175},{"p":"38139.5","s":0}],"b":[{"p":"38131.2","s":0},{"p":"38130.1","s":0},{"p":"38132","s":0},{"p":"38120.9","s":0},{"p":"38122.7","s":0},{"p":"38126.3","s":4713},{"p":"38126.1","s":655},{"p":"38120","s":0},{"p":"38121.2","s":0},{"p":"38115.7","s":0},{"p":"38122.3","s":0},{"p":"38132.8","s":117},{"p":"38126","s":100}],"s":"BTC_USDT","t":1701245724665,"u":53095256689}}
{"time":1701245724,"time_ms":1701245724692,"channel":"futures.order_book_update","event":"update","result":{"U":53095256690,"a":[{"p":"38143.5","s":0},{"p":"38136.5","s":0},{"p":"38139.3","s":16024},{"p":"38137.1","s":2889},{"p":"38138","s":2175},{"p":"38137.9","s":525},{"p":"38138.8","s":0}],"b":[{"p":"38120.1","s":0},{"p":"38129.7","s":2},{"p":"38129","s":2},{"p":"38126.1","s":0},{"p":"38115.1","s":0},{"p":"38120.3","s":0},{"p":"38130.5","s":2},{"p":"38126.3","s":0},{"p":"38126","s":0},{"p":"38119.4","s":0}],"s":"BTC_USDT","t":1701245724684,"u":53095256713}}
{"time":1701245724,"time_ms":1701245724712,"channel":"futures.order_book_update","event":"update","result":{"U":53095256714,"a":[],"b":[{"p":"38126.6","s":131},{"p":"38127.8","s":2},{"p":"38126.3","s":4713},{"p":"38126.1","s":655},{"p":"38130.5","s":0},{"p":"38129","s":0},{"p":"38129.7","s":0},{"p":"38119.4","s":0}],"s":"BTC_USDT","t":1701245724701,"u":53095256719}}
{"time":1701245724,"time_ms":1701245724749,"channel":"futures.order_book_update","event":"update","result":{"U":53095256720,"a":[{"p":"38139.3","s":0},{"p":"38137.3","s":1306}],"b":[{"p":"38128.7","s":2},{"p":"38127.8","s":0},{"p":"38111.7","s":0},{"p":"38126.1","s":655},{"p":"38130.2","s":28},{"p":"38129.4","s":2195},{"p":"38134.1","s":1000}],"s":"BTC_USDT","t":1701245724742,"u":53095256728}}
{"time":1701245724,"time_ms":1701245724772,"channel":"futures.order_book_update","event":"update","result":{"U":53095256729,"a":[{"p":"38149","s":0}],"b":[{"p":"38112.5","s":0},{"p":"38120.7","s":0},{"p":"38130.2","s":26},{"p":"38129.4","s":2193},{"p":"38126","s":100},{"p":"38128.7","s":0},{"p":"38125.5","s":0},{"p":"38121","s":0}],"s":"BTC_USDT","t":1701245724761,"u":53095256741}}
{"time":1701245724,"time_ms":1701245724792,"channel":"futures.order_book_update","event":"update","result":{"U":53095256742,"a":[{"p":"38141.4","s":0}],"b":[{"p":"38125.6","s":3633},{"p":"38129.3","s":0},{"p":"38119.5","s":0},{"p":"38121.6","s":0}],"s":"BTC_USDT","t":1701245724775,"u":53095256752}}
{"time":1701245724,"time_ms":1701245724813,"channel":"futures.order_book_update","event":"update","result":{"U":53095256753,"a":[{"p":"38179.2","s":0},{"p":"38134.2","s":177613}],"b":[{"p":"38125.5","s":182},{"p":"38129.4","s":0},{"p":"38121.3","s":0}],"s":"BTC_USDT","t":1701245724794,"u":53095256758}}
{"time":1701245724,"time_ms":1701245724832,"channel":"futures.order_book_update","event":"update","result":{"U":53095256759,"a":[],"b":[{"p":"38114.5","s":0},{"p":"38116.3","s":0}],"s":"BTC_USDT","t":1701245724820,"u":53095256762}}
{"time":1701245724,"time_ms":1701245724874,"channel":"futures.order_book_update","event":"update","result":{"U":53095256763,"a":[{"p":"38150.6","s":0},{"p":"38148.8","s":0}],"b":[{"p":"38125.5","s":9097},{"p":"38020.7","s":0}],"s":"BTC_USDT","t":1701245724866,"u":53095256773}}
{"time":1701245724,"time_ms":1701245724894,"channel":"futures.order_book_update","event":"update","result":{"U":53095256774,"a":[{"p":"38134.2","s":177258}],"b":[{"p":"38116","s":0}],"s":"BTC_USDT","t":1701245724885,"u":53095256777}}
{"time":1701245724,"time_ms":1701245724914,"channel":"futures.order_book_update","event":"update","result":{"U":53095256778,"a":[],"b":[{"p":"38134.1","s":28500},{"p":"38120.9","s":0}],"s":"BTC_USDT","t":1701245724894,"u":53095256781}}
{"time":1701245724,"time_ms":1701245724934,"channel":"futures.order_book_update","event":"update","result":{"U":53095256782,"a":[{"p":"38136.5","s":14981},{"p":"38134.2","s":173588},{"p":"38139.2","s":0}],"b":[{"p":"38127.1","s":0},{"p":"38121","s":0},{"p":"38112.5","s":0},{"p":"38126.2","s":5462},{"p":"38125.5","s":182}],"s":"BTC_USDT","t":1701245724924,"u":53095256791}}
{"time":1701245724,"time_ms":1701245724952,"channel":"futures.order_book_update","event":"update","result":{"U":53095256792,"a":[{"p":"38152.9","s":0}],"b":[{"p":"38126.4","s":2185},{"p":"38126.2","s":0},{"p":"38125.4","s":0}],"s":"BTC_USDT","t":1701245724944,"u":53095256795}}
{"time":1701245724,"time_ms":1701245724980,"channel":"futures.order_book_update","event":"update","result":{"U":53095256796,"a":[{"p":"38148.6","s":0}],"b":[{"p":"38090.4","s":0},{"p":"38022.9","s":0},{"p":"38092.7","s":0},{"p":"38034","s":0},{"p":"38063.8","s":0},{"p":"38078.9","s":0},{"p":"38083.4","s":0},{"p":"38058.2","s":0},{"p":"38085.1","s":0},{"p":"38009.6","s":0},{"p":"37993.9","s":0},{"p":"38051.4","s":0},{"p":"38088.8","s":0},{"p":"38092.4","s":0},{"p":"38092","s":0},{"p":"38043.5","s":0},{"p":"38091.6","s":0},{"p":"38076","s":0},{"p":"38087.8","s":0},{"p":"38068.6","s":0},{"p":"38093.9","s":0},{"p":"38093.6","s":0},{"p":"38072.6","s":0},{"p":"38093","s":0},{"p":"38093.7","s":0},{"p":"38089.7","s":0},{"p":"38081.3","s":0},{"p":"38091.1","s":0},{"p":"38093.2","s":0},{"p":"38086.6","s":0}],"s":"BTC_USDT","t":1701245724960,"u":53095256833}}
{"time":1701245725,"time_ms":1701245725014,"channel":"futures.order_book_update","event":"update","result":{"U":53095256834,"a":[{"p":"38175.8","s":0},{"p":"38142.5","s":0},{"p":"38147","s":0}],"b":[{"p":"38121.3","s":0}],"s":"BTC_USDT","t":1701245724994,"u":53095256840}}
{"time":1701245725,"time_ms":1701245725032,"channel":"futures.order_book_update","event":"update","result":{"U":53095256841,"a":[{"p":"38137.8","s":3341},{"p":"38138.4","s":2175},{"p":"38138","s":0},{"p":"38145.6","s":0},{"p":"38137.4","s":2175},{"p":"38137","s":0},{"p":"38137.6","s":0},{"p":"38139.2","s":0},{"p":"38137.3","s":1306},{"p":"38139.3","s":0},{"p":"38142.4","s":0}],"b":[{"p":"38126.5","s":8915},{"p":"38125.5","s":0},{"p":"38125.6","s":0},{"p":"38118.7","s":0},{"p":"38114.1","s":0},{"p":"38121.7","s":0},{"p":"38129.3","s":3642},{"p":"38119.4","s":0},{"p":"38114.2","s":0},{"p":"38120.8","s":0}],"s":"BTC_USDT","t":1701245725022,"u":53095256870}}
{"time":1701245725,"time_ms":1701245725053,"channel":"futures.order_book_update","event":"update","result":{"U":53095256871,"a":[{"p":"38147.6","s":0},{"p":"38138.4","s":0},{"p":"38144.6","s":0},{"p":"38137.8","s":0},{"p":"38137.4","s":0},{"p":"38139","s":0},{"p":"38141.2","s":0},{"p":"38139.2","s":9617},{"p":"38137.9","s":2861},{"p":"38137.6","s":2175},{"p":"38139.1","s":10858},{"p":"38148.8","s":0},{"p":"38139.3","s":16024},{"p":"38137.1","s":583},{"p":"38144.9","s":0},{"p":"38138.8","s":0}],"b":[{"p":"38126","s":100},{"p":"38120.7","s":0},{"p":"38122.1","s":0},{"p":"38124","s":0},{"p":"38120.8","s":0},{"p":"38119.5","s":0},{"p":"38120.2","s":0},{"p":"38121.5","s":0},{"p":"38123.1","s":0},{"p":"38129.4","s":2193},{"p":"38126.4","s":0},{"p":"38116","s":0},{"p":"38122.4","s":0},{"p":"38121.8","s":0},{"p":"38127","s":9109},{"p":"38115.1","s":0}],"s":"BTC_USDT","t":1701245725046,"u":53095256916}}
{"time":1701245725,"time_ms":1701245725072,"channel":"futures.order_book_update","event":"update","result":{"U":53095256917,"a":[{"p":"38138.8","s":2175},{"p":"38139.3","s":0},{"p":"38142.3","s":0},{"p":"38137.9","s":2861},{"p":"38145.5","s":0}],"b":[],"s":"BTC_USDT","t":1701245725063,"u":53095256925}}
{"time":1701245725,"time_ms":1701245725090,"channel":"futures.order_book_update","event":"update","result":{"U":53095256926,"a":[{"p":"38138.4","s":3341},{"p":"38134.2","s":173326},{"p":"38139.2","s":0}],"b":[{"p":"38116.4","s":0},{"p":"38127","s":9209},{"p":"38125.6","s":3633},{"p":"38126","s":0}],"s":"BTC_USDT","t":1701245725083,"u":53095256932}}
{"time":1701245725,"time_ms":1701245725116,"channel":"futures.order_book_update","event":"update","result":{"U":53095256933,"a":[{"p":"38141.5","s":0}],"b":[{"p":"38132","s":200},{"p":"38127","s":9009},{"p":"38125.6","s":0}],"s":"BTC_USDT","t":1701245725103,"u":53095256939}}
{"time":1701245725,"time_ms":1701245725132,"channel":"futures.order_book_update","event":"update","result":{"U":53095256940,"a":[{"p":"38143.5","s":0},{"p":"38148","s":0}],"b":[{"p":"38126.1","s":655},{"p":"38134","s":0},{"p":"38122","s":0},{"p":"38126","s":8915},{"p":"38126.5","s":0}],"s":"BTC_USDT","t":1701245725118,"u":53095256950}}
{"time":1701245725,"time_ms":1701245725173,"channel":"futures.order_book_update","event":"update","result":{"U":53095256951,"a":[{"p":"38143","s":0},{"p":"38141.2","s":0},{"p":"38148.2","s":0},{"p":"38147.5","s":0}],"b":[{"p":"38125.6","s":0},{"p":"38113.5","s":0},{"p":"38121.5","s":0},{"p":"38130.3","s":2},{"p":"38131.1","s":2},{"p":"38129.5","s":2},{"p":"38126.3","s":0},{"p":"38128.4","s":732},{"p":"38126.1","s":0},{"p":"38126","s":0}],"s":"BTC_USDT","t":1701245725163,"u":53095256966}}
{"time":1701245725,"time_ms":1701245725192,"channel":"futures.order_book_update","event":"update","result":{"U":53095256967,"a":[{"p":"38138.3","s":2175},{"p":"38137.6","s":0},{"p":"38138.8","s":0},{"p":"38139.3","s":0},{"p":"38139.2","s":11792}],"b":[{"p":"38119.5","s":0}],"s":"BTC_USDT","t":1701245725178,"u":53095256974}}
{"time":1701245725,"time_ms":1701245725212,"channel":"futures.order_book_update","event":"update","result":{"U":53095256975,"a":[{"p":"38146.7","s":0},{"p":"38156","s":0}],"b":[{"p":"38126.3","s":4713},{"p":"38127","s":9209},{"p":"38132","s":0}],"s":"BTC_USDT","t":1701245725197,"u":53095256985}}
{"time":1701245725,"time_ms":1701245725253,"channel":"futures.order_book_update","event":"update","result":{"U":53095256986,"a":[],"b":[{"p":"38120.3","s":0}],"s":"BTC_USDT","t":1701245725244,"u":53095256988}}
{"time":1701245725,"time_ms":1701245725312,"channel":"futures.order_book_update","event":"update","result":{"U":53095256989,"a":[{"p":"38151","s":0}],"b":[{"p":"38110.1","s":0}],"s":"BTC_USDT","t":1701245725292,"u":53095256993}}
{"time":1701245725,"time_ms":1701245725333,"channel":"futures.order_book_update","event":"update","result":{"U":53095256994,"a":[],"b":[{"p":"38129.5","s":0},{"p":"38120.5","s":0},{"p":"38119.2","s":0},{"p":"38126.1","s":655},{"p":"38125.5","s":182},{"p":"38128.4","s":730},{"p":"38131.1","s":0},{"p":"38125.6","s":3633},{"p":"38130.3","s":0}],"s":"BTC_USDT","t":1701245725321,"u":53095257000}}
{"time":1701245725,"time_ms":1701245725353,"channel":"futures.order_book_update","event":"update","result":{"U":53095257001,"a":[{"p":"38142.6","s":0},{"p":"38146.5","s":0},{"p":"38141.7","s":0}],"b":[{"p":"38124","s":0},{"p":"38130.5","s":2},{"p":"38133.3","s":2},{"p":"38125.6","s":0},{"p":"38125.5","s":0},{"p":"38122.1","s":0},{"p":"38122","s":0}],"s":"BTC_USDT","t":1701245725338,"u":53095257014}}
{"time":1701245725,"time_ms":1701245725372,"channel":"futures.order_book_update","event":"update","result":{"U":53095257015,"a":[],"b":[{"p":"38132.6","s":2},{"p":"38134.1","s":28574},{"p":"38131.9","s":2},{"p":"38126.3","s":0},{"p":"38126.1","s":0}],"s":"BTC_USDT","t":1701245725349,"u":53095257018}}
{"time":1701245725,"time_ms":1701245725392,"channel":"futures.order_book_update","event":"update","result":{"U":53095257019,"a":[{"p":"38146","s":0},{"p":"38147.8","s":0},{"p":"38154","s":0},{"p":"38153","s":0},{"p":"38144","s":0},{"p":"38147.6","s":0},{"p":"38144.4","s":0}],"b":[{"p":"38112.2","s":0},{"p":"38120.9","s":0},{"p":"38106.8","s":0},{"p":"38120.7","s":0},{"p":"38134.1","s":1074},{"p":"38127","s":9009},{"p":"38132.5","s":2},{"p":"38130.5","s":0},{"p":"38133.3","s":0},{"p":"38121","s":0},{"p":"38125.4","s":0},{"p":"38125","s":0},{"p":"38132.6","s":0},{"p":"38125.5","s":0},{"p":"38124.5","s":0},{"p":"38111.2","s":0},{"p":"38129.8","s":2},{"p":"38128.3","s":131},{"p":"38125.6","s":0},{"p":"38131.7","s":2},{"p":"38131","s":2},{"p":"38131.9","s":0},{"p":"38126.3","s":0},{"p":"38115","s":0},{"p":"38093.7","s":0},{"p":"38126.1","s":0},{"p":"38121.8","s":0},{"p":"38122","s":0},{"p":"38124.6","s":0}],"s":"BTC_USDT","t":1701245725386,"u":53095257072}}
{"time":1701245725,"time_ms":1701245725413,"channel":"futures.order_book_update","event":"update","result":{"U":53095257073,"a":[{"p":"38137.8","s":2175},{"p":"38138.3","s":0},{"p":"38139.3","s":0},{"p":"38139.2","s":9617},{"p":"38137.2","s":6107}],"b":[{"p":"38125.6","s":3633},{"p":"38129.8","s":0},{"p":"38065.2","s":0},{"p":"38120.3","s":0},{"p":"38115.6","s":0},{"p":"38134.1","s":2308},{"p":"38126.2","s":2000},{"p":"38131","s":0},{"p":"38124","s":0},{"p":"38120.9","s":0},{"p":"38112","s":0},{"p":"38126.3","s":4189},{"p":"38132.5","s":0},{"p":"38131.7","s":0},{"p":"38114.8","s":0},{"p":"38121","s":0},{"p":"38125.5","s":182},{"p":"38122.5","s":0}],"s":"BTC_USDT","t":1701245725405,"u":53095257113}}
{"time":1701245725,"time_ms":1701245725432,"channel":"futures.order_book_update","event":"update","result":{"U":53095257114,"a":[{"p":"38138","s":3341},{"p":"38141.2","s":0},{"p":"38138.8","s":2175},{"p":"38139.2","s":0},{"p":"38137.8","s":0},{"p":"38138.4","s":0},{"p":"38137","s":0},{"p":"38136.6","s":7864},{"p":"38137.4","s":2322},{"p":"38137.9","s":525}],"b":[{"p":"38124.8","s":0},{"p":"38114.2","s":0},{"p":"38115.4","s":0},{"p":"38120.2","s":0}],"s":"BTC_USDT","t":1701245725423,"u":53095257139}}
{"time":1701245725,"time_ms":1701245725452,"channel":"futures.order_book_update","event":"update","result":{"U":53095257140,"a":[{"p":"38137.8","s":2175},{"p":"38137.2","s":3932},{"p":"38139.1","s":0}],"b":[{"p":"38119.5","s":0}],"s":"BTC_USDT","t":1701245725439,"u":53095257147}}
{"time":1701245725,"time_ms":1701245725473,"channel":"futures.order_book_update","event":"update","result":{"U":53095257148,"a":[],"b":[{"p":"38134","s":9500},{"p":"38125.5","s":0},{"p":"38054.3","s":0}],"s":"BTC_USDT","t":1701245725463,"u":53095257151}}
{"time":1701245725,"time_ms":1701245725492,"channel":"futures.order_book_update","event":"update","result":{"U":53095257152,"a":[],"b":[{"p":"38134.1","s":3808}],"s":"BTC_USDT","t":1701245725470,"u":53095257153}}
{"time":1701245725,"time_ms":1701245725512,"channel":"futures.order_book_update","event":"update","result":{"U":53095257154,"a":[{"p":"38158.3","s":0}],"b":[{"p":"38050.1","s":0},{"p":"38052.2","s":0},{"p":"38045.4","s":0}],"s":"BTC_USDT","t":1701245725497,"u":53095257166}}
{"time":1701245725,"time_ms":1701245725532,"channel":"futures.order_book_update","event":"update","result":{"U":53095257167,"a":[{"p":"38148","s":0}],"b":[{"p":"38121.3","s":0},{"p":"38099.8","s":0}],"s":"BTC_USDT","t":1701245725511,"u":53095257172}}
{"time":1701245725,"time_ms":1701245725553,"channel":"futures.order_book_update","event":"update","result":{"U":53095257173,"a":[{"p":"38169.9","s":0}],"b":[{"p":"38125.5","s":182},{"p":"38134","s":0},{"p":"38109.7","s":0}],"s":"BTC_USDT","t":1701245725546,"u":53095257178}}
{"time":1701245725,"time_ms":1701245725572,"channel":"futures.order_book_update","event":"update","result":{"U":53095257179,"a":[{"p":"38138.4","s":2175},{"p":"38137.8","s":0},{"p":"38139.1","s":0}],"b":[{"p":"38124","s":0},{"p":"38115","s":0},{"p":"38077.7","s":0},{"p":"38125.9","s":600},{"p":"38125.5","s":0}],"s":"BTC_USDT","t":1701245725561,"u":53095257189}}
{"time":1701245725,"time_ms":1701245725593,"channel":"futures.order_book_update","event":"update","result":{"U":53095257190,"a":[{"p":"38147.4","s":0},{"p":"38141.6","s":0}],"b":[{"p":"38125.9","s":1255},{"p":"38110","s":0},{"p":"38120.2","s":0}],"s":"BTC_USDT","t":1701245725582,"u":53095257197}}
{"time":1701245725,"time_ms":1701245725612,"channel":"futures.order_book_update","event":"update","result":{"U":53095257198,"a":[],"b":[{"p":"38099.6","s":0}],"s":"BTC_USDT","t":1701245725587,"u":53095257200}}
{"time":1701245725,"time_ms":1701245725655,"channel":"futures.order_book_update","event":"update","result":{"U":53095257201,"a":[{"p":"38155.8","s":0},{"p":"38157.8","s":0},{"p":"38160.2","s":0},{"p":"38163","s":0},{"p":"38186.8","s":0},{"p":"38180.3","s":0},{"p":"38154.2","s":0},{"p":"38170.2","s":0},{"p":"38174.8","s":0},{"p":"38166.3","s":0}],"b":[],"s":"BTC_USDT","t":1701245725636,"u":53095257234}}
{"time":1701245725,"time_ms":1701245725732,"channel":"futures.order_book_update","event":"update","result":{"U":53095257235,"a":[],"b":[{"p":"38134","s":15000},{"p":"38125.6","s":0}],"s":"BTC_USDT","t":1701245725719,"u":53095257239}}
{"time":1701245725,"time_ms":1701245725754,"channel":"futures.order_book_update","event":"update","result":{"U":53095257240,"a":[{"p":"38173.2","s":0},{"p":"38154.5","s":0},{"p":"38142","s":0},{"p":"38146.5","s":0}],"b":[{"p":"38134.1","s":2308},{"p":"38125","s":0},{"p":"38112.8","s":0},{"p":"38120.5","s":0},{"p":"38120.4","s":0}],"s":"BTC_USDT","t":1701245725743,"u":53095257257}}
{"time":1701245725,"time_ms":1701245725771,"channel":"futures.order_book_update","event":"update","result":{"U":53095257258,"a":[{"p":"38165.8","s":0}],"b":[{"p":"38125.9","s":0},{"p":"38121","s":0},{"p":"38112.5","s":0},{"p":"38126","s":100}],"s":"BTC_USDT","t":1701245725760,"u":53095257264}}
{"time":1701245725,"time_ms":1701245725794,"channel":"futures.order_book_update","event":"update","result":{"U":53095257265,"a":[{"p":"38165.5","s":0},{"p":"38165.8","s":0},{"p":"38144.5","s":0},{"p":"38147","s":0}],"b":[{"p":"38134.1","s":7896}],"s":"BTC_USDT","t":1701245725783,"u":53095257273}}
{"time":1701245725,"time_ms":1701245725812,"channel":"futures.order_book_update","event":"update","result":{"U":53095257274,"a":[],"b":[{"p":"38134","s":0},{"p":"38122","s":0},{"p":"38125.9","s":1255},{"p":"38125.6","s":3633},{"p":"38127","s":9209},{"p":"38126","s":0}],"s":"BTC_USDT","t":1701245725799,"u":53095257278}}
{"time":1701245725,"time_ms":1701245725836,"channel":"futures.order_book_update","event":"update","result":{"U":53095257279,"a":[{"p":"38165.5","s":0}],"b":[{"p":"38134.1","s":2308}],"s":"BTC_USDT","t":1701245725821,"u":53095257281}}
{"time":1701245725,"time_ms":1701245725893,"channel":"futures.order_book_update","event":"update","result":{"U":53095257282,"a":[{"p":"38165.5","s":0}],"b":[{"p":"38127","s":9109},{"p":"38126","s":100},{"p":"38125.6","s":0}],"s":"BTC_USDT","t":1701245725883,"u":53095257295}}
{"time":1701245725,"time_ms":1701245725913,"channel":"futures.order_book_update","event":"update","result":{"U":53095257296,"a":[{"p":"38135.9","s":394},{"p":"38138.9","s":0}],"b":[],"s":"BTC_USDT","t":1701245725887,"u":53095257296}}
{"time":1701245725,"time_ms":1701245725952,"channel":"futures.order_book_update","event":"update","result":{"U":53095257297,"a":[{"p":"38135.9","s":919},{"p":"38165.5","s":0}],"b":[{"p":"38113.8","s":0}],"s":"BTC_USDT","t":1701245725937,"u":53095257303}}
{"time":1701245725,"time_ms":1701245725973,"channel":"futures.order_book_update","event":"update","result":{"U":53095257304,"a":[{"p":"38146.6","s":0},{"p":"38141.7","s":0}],"b":[],"s":"BTC_USDT","t":1701245725962,"u":53095257305}}
{"time":1701245725,"time_ms":1701245725993,"channel":"futures.order_book_update","event":"update","result":{"U":53095257306,"a":[],"b":[{"p":"38125.6","s":3633},{"p":"38127","s":9209},{"p":"38126","s":0}],"s":"BTC_USDT","t":1701245725981,"u":53095257309}}
{"time":1701245726,"time_ms":1701245726010,"channel":"futures.order_book_update","event":"update","result":{"U":53095257310,"a":[{"p":"38165.6","s":0}],"b":[{"p":"38104.9","s":0}],"s":"BTC_USDT","t":1701245726001,"u":53095257315}}
{"time":1701245726,"time_ms":1701245726032,"channel":"futures.order_book_update","event":"update","result":{"U":53095257316,"a":[{"p":"38138","s":0},{"p":"38152.5","s":0},{"p":"38144","s":0},{"p":"38137.9","s":5066},{"p":"38138.7","s":3341},{"p":"38138.9","s":609},{"p":"38137.4","s":0},{"p":"38139.1","s":10858},{"p":"38138.4","s":0},{"p":"38165.6","s":0},{"p":"38140","s":0}],"b":[{"p":"38115.7","s":0},{"p":"38119.4","s":0},{"p":"38111","s":0},{"p":"38121.1","s":0},{"p":"38121.7","s":0},{"p":"38114.1","s":0},{"p":"38119.5","s":0}],"s":"BTC_USDT","t":1701245726025,"u":53095257348}}
{"time":1701245726,"time_ms":1701245726051,"channel":"futures.order_book_update","event":"update","result":{"U":53095257349,"a":[],"b":[{"p":"38123.5","s":0}],"s":"BTC_USDT","t":1701245726034,"u":53095257350}}
{"time":1701245726,"time_ms":1701245726091,"channel":"futures.order_book_update","event":"update","result":{"U":53095257351,"a":[{"p":"38137.9","s":2700}],"b":[{"p":"38121.3","s":0}],"s":"BTC_USDT","t":1701245726082,"u":53095257354}}
{"time":1701245726,"time_ms":1701245726112,"channel":"futures.order_book_update","event":"update","result":{"U":53095257355,"a":[{"p":"38138.4","s":2008},{"p":"38137.4","s":2301},{"p":"38137.3","s":0},{"p":"38139.1","s":0},{"p":"38165.6","s":0},{"p":"38142.6","s":0},{"p":"38138.9","s":609}],"b":[{"p":"38081.2","s":0},{"p":"38121.3","s":0},{"p":"38120.9","s":0},{"p":"38120.3","s":0},{"p":"38126","s":100},{"p":"38127","s":9109},{"p":"38125.6","s":0}],"s":"BTC_USDT","t":1701245726101,"u":53095257375}}
{"time":1701245726,"time_ms":1701245726131,"channel":"futures.order_book_update","event":"update","result":{"U":53095257376,"a":[{"p":"38137.4","s":0},{"p":"38141.7","s":0},{"p":"38140.2","s":0},{"p":"38137.9","s":525},{"p":"38138.4","s":5349},{"p":"38139.1","s":10858},{"p":"38137.8","s":4520},{"p":"38138.7","s":0}],"b":[{"p":"38128.7","s":2},{"p":"38129.5","s":2},{"p":"38126.2","s":0},{"p":"38125.9","s":0},{"p":"38126.3","s":0},{"p":"38126","s":0},{"p":"38128","s":2},{"p":"38126.8","s":2}],"s":"BTC_USDT","t":1701245726114,"u":53095257398}}
{"time":1701245726,"time_ms":1701245726151,"channel":"futures.order_book_update","event":"update","result":{"U":53095257399,"a":[{"p":"38138.6","s":0},{"p":"38139.1","s":10858},{"p":"38139.2","s":9617},{"p":"38138.4","s":0}],"b":[],"s":"BTC_USDT","t":1701245726133,"u":53095257402}}
{"time":1701245726,"time_ms":1701245726175,"channel":"futures.order_book_update","event":"update","result":{"U":53095257403,"a":[{"p":"38165.7","s":0},{"p":"38165.6","s":0},{"p":"38138.6","s":3341},{"p":"38139.2","s":0},{"p":"38146.2","s":0}],"b":[],"s":"BTC_USDT","t":1701245726163,"u":53095257408}}
{"time":1701245726,"time_ms":1701245726196,"channel":"futures.order_book_update","event":"update","result":{"U":53095257409,"a":[],"b":[{"p":"38112.1","s":0},{"p":"38121.2","s":0},{"p":"38120","s":0}],"s":"BTC_USDT","t":1701245726187,"u":53095257416}}
{"time":1701245726,"time_ms":1701245726213,"channel":"futures.order_book_update","event":"update","result":{"U":53095257417,"a":[{"p":"38165.7","s":0}],"b":[{"p":"38127","s":9209},{"p":"38126","s":0},{"p":"38121.1","s":0},{"p":"38121.2","s":0}],"s":"BTC_USDT","t":1701245726200,"u":53095257425}}
{"time":1701245726,"time_ms":1701245726232,"channel":"futures.order_book_update","event":"update","result":{"U":53095257426,"a":[{"p":"38173.7","s":0}],"b":[{"p":"38105.4","s":0}],"s":"BTC_USDT","t":1701245726221,"u":53095257429}}
{"time":1701245726,"time_ms":1701245726276,"channel":"futures.order_book_update","event":"update","result":{"U":53095257430,"a":[{"p":"38165.7","s":0}],"b":[{"p":"38126.3","s":4189},{"p":"38126.2","s":2000},{"p":"38125.9","s":1255},{"p":"38128.7","s":0},{"p":"38128","s":0},{"p":"38129.5","s":0}],"s":"BTC_USDT","t":1701245726267,"u":53095257438}}
{"time":1701245726,"time_ms":1701245726292,"channel":"futures.order_book_update","event":"update","result":{"U":53095257439,"a":[],"b":[{"p":"38127","s":9109},{"p":"38126","s":100},{"p":"38126.8","s":0},{"p":"38125.6","s":0}],"s":"BTC_USDT","t":1701245726281,"u":53095257442}}
{"time":1701245726,"time_ms":1701245726313,"channel":"futures.order_book_update","event":"update","result":{"U":53095257443,"a":[{"p":"38165.7","s":0}],"b":[{"p":"38126.2","s":0},{"p":"38125.9","s":0},{"p":"38126","s":0},{"p":"38128.7","s":2},{"p":"38128","s":2},{"p":"38126.8","s":2},{"p":"38129.5","s":2},{"p":"38126.3","s":0}],"s":"BTC_USDT","t":1701245726300,"u":53095257451}}
{"time":1701245726,"time_ms":1701245726351,"channel":"futures.order_book_update","event":"update","result":{"U":53095257452,"a":[],"b":[{"p":"38126.8","s":657},{"p":"38125.9","s":0},{"p":"38111.2","s":0}],"s":"BTC_USDT","t":1701245726339,"u":53095257455}}
{"time":1701245726,"time_ms":1701245726372,"channel":"futures.order_book_update","event":"update","result":{"U":53095257456,"a":[{"p":"38145.8","s":0},{"p":"38165.8","s":0}],"b":[],"s":"BTC_USDT","t":1701245726362,"u":53095257462}}
{"time":1701245726,"time_ms":1701245726392,"channel":"futures.order_book_update","event":"update","result":{"U":53095257463,"a":[{"p":"38137.6","s":2175},{"p":"38137.4","s":3341},{"p":"38138.6","s":0},{"p":"38138.8","s":0},{"p":"38146.5","s":0},{"p":"38136.6","s":12344},{"p":"38137.8","s":0},{"p":"38165.5","s":0},{"p":"38141.9","s":0},{"p":"38165.6","s":0},{"p":"38139.3","s":0},{"p":"38139.2","s":9617}],"b":[{"p":"38120.9","s":0},{"p":"38092.4","s":0},{"p":"38134.1","s":1808},{"p":"38115.1","s":0},{"p":"38119.4","s":0},{"p":"38124","s":0},{"p":"38122.8","s":0},{"p":"38120","s":0},{"p":"38122","s":0},{"p":"38116","s":0},{"p":"38119.1","s":0},{"p":"38120.2","s":0},{"p":"38125.9","s":0}],"s":"BTC_USDT","t":1701245726385,"u":53095257513}}
{"time":1701245726,"time_ms":1701245726411,"channel":"futures.order_book_update","event":"update","result":{"U":53095257514,"a":[{"p":"38138.4","s":2175},{"p":"38136.6","s":10039},{"p":"38137.6","s":0},{"p":"38152.5","s":0},{"p":"38139.3","s":0}],"b":[{"p":"38126","s":0},{"p":"38114.2","s":0},{"p":"38127","s":9209}],"s":"BTC_USDT","t":1701245726399,"u":53095257522}}
{"time":1701245726,"time_ms":1701245726432,"channel":"futures.order_book_update","event":"update","result":{"U":53095257523,"a":[{"p":"38136.6","s":7864},{"p":"38137.1","s":5130},{"p":"38165.6","s":0}],"b":[{"p":"38126.3","s":4189},{"p":"38129.3","s":0},{"p":"38120.2","s":0},{"p":"38118.1","s":0},{"p":"37999.6","s":0}],"s":"BTC_USDT","t":1701245726421,"u":53095257535}}
{"time":1701245726,"time_ms":1701245726453,"channel":"futures.order_book_update","event":"update","result":{"U":53095257536,"a":[],"b":[{"p":"38126.2","s":2000},{"p":"38129.4","s":0}],"s":"BTC_USDT","t":1701245726444,"u":53095257537}}
{"time":1701245726,"time_ms":1701245726472,"channel":"futures.order_book_update","event":"update","result":{"U":53095257538,"a":[{"p":"38165.7","s":0}],"b":[],"s":"BTC_USDT","t":1701245726453,"u":53095257541}}
{"time":1701245726,"time_ms":1701245726497,"channel":"futures.order_book_update","event":"update","result":{"U":53095257542,"a":[],"b":[{"p":"38134.1","s":2308},{"p":"38114.7","s":0}],"s":"BTC_USDT","t":1701245726487,"u":53095257545}}
{"time":1701245726,"time_ms":1701245726513,"channel":"futures.order_book_update","event":"update","result":{"U":53095257546,"a":[{"p":"38165.7","s":0}],"b":[{"p":"38108.5","s":0}],"s":"BTC_USDT","t":1701245726506,"u":53095257549}}
{"time":1701245726,"time_ms":1701245726537,"channel":"futures.order_book_update","event":"update","result":{"U":53095257550,"a":[],"b":[{"p":"38129.3","s":3642},{"p":"38126.2","s":0}],"s":"BTC_USDT","t":1701245726518,"u":53095257550}}
{"time":1701245726,"time_ms":1701245726554,"channel":"futures.order_book_update","event":"update","result":{"U":53095257551,"a":[],"b":[{"p":"38129.4","s":2190},{"p":"38126.3","s":0}],"s":"BTC_USDT","t":1701245726538,"u":53095257552}}
{"time":1701245726,"time_ms":1701245726572,"channel":"futures.order_book_update","event":"update","result":{"U":53095257553,"a":[{"p":"38165.7","s":0},{"p":"38145.4","s":0}],"b":[],"s":"BTC_USDT","t":1701245726563,"u":53095257557}}
{"time":1701245726,"time_ms":1701245726593,"channel":"futures.order_book_update","event":"update","result":{"U":53095257558,"a":[{"p":"38142","s":0},{"p":"38154.5","s":0},{"p":"38146","s":0},{"p":"38139.3","s":0},{"p":"38165.8","s":0},{"p":"38141","s":0},{"p":"38138","s":3341},{"p":"38137.4","s":0}],"b":[{"p":"38125","s":0},{"p":"38121","s":0},{"p":"38112.5","s":0},{"p":"38116.6","s":0},{"p":"38119.5","s":0}],"s":"BTC_USDT","t":1701245726585,"u":53095257589}}
{"time":1701245726,"time_ms":1701245726613,"channel":"futures.order_book_update","event":"update","result":{"U":53095257590,"a":[{"p":"38165.8","s":0},{"p":"38141.7","s":0}],"b":[{"p":"38119","s":0}],"s":"BTC_USDT","t":1701245726599,"u":53095257595}}
{"time":1701245726,"time_ms":1701245726633,"channel":"futures.order_book_update","event":"update","result":{"U":53095257596,"a":[{"p":"38153.1","s":0},{"p":"38156.9","s":0},{"p":"38149.3","s":0},{"p":"38139.8","s":0},{"p":"38145.5","s":0}],"b":[{"p":"38106.1","s":0},{"p":"38110","s":0}],"s":"BTC_USDT","t":1701245726622,"u":53095257602}}
{"time":1701245726,"time_ms":1701245726673,"channel":"futures.order_book_update","event":"update","result":{"U":53095257603,"a":[{"p":"38165.8","s":0}],"b":[],"s":"BTC_USDT","t":1701245726666,"u":53095257606}}
{"time":1701245726,"time_ms":1701245726713,"channel":"futures.order_book_update","event":"update","result":{"U":53095257607,"a":[{"p":"38165.8","s":0}],"b":[{"p":"38121.3","s":0}],"s":"BTC_USDT","t":1701245726696,"u":53095257612}}
{"time":1701245726,"time_ms":1701245726731,"channel":"futures.order_book_update","event":"update","result":{"U":53095257613,"a":[{"p":"38165.5","s":0}],"b":[{"p":"38126","s":0},{"p":"38121.3","s":0},{"p":"38113.5","s":0},{"p":"38126.3","s":0},{"p":"38120.6","s":0},{"p":"38123.5","s":0},{"p":"38119.5","s":0},{"p":"38122.2","s":0},{"p":"38111","s":0},{"p":"38124","s":0}],"s":"BTC_USDT","t":1701245726721,"u":53095257654}}
{"time":1701245726,"time_ms":1701245726752,"channel":"futures.order_book_update","event":"update","result":{"U":53095257655,"a":[{"p":"38156","s":0}],"b":[],"s":"BTC_USDT","t":1701245726736,"u":53095257655}}
{"time":1701245726,"time_ms":1701245726772,"channel":"futures.order_book_update","event":"update","result":{"U":53095257656,"a":[{"p":"38137.1","s":2955},{"p":"38137.8","s":2175},{"p":"38139.2","s":0},{"p":"38165.3","s":0}],"b":[{"p":"38121.6","s":0}],"s":"BTC_USDT","t":1701245726762,"u":53095257664}}
{"time":1701245726,"time_ms":1701245726792,"channel":"futures.order_book_update","event":"update","result":{"U":53095257665,"a":[{"p":"38165.5","s":0},{"p":"38145","s":0}],"b":[{"p":"38122.7","s":0}],"s":"BTC_USDT","t":1701245726776,"u":53095257670}}
{"time":1701245726,"time_ms":1701245726812,"channel":"futures.order_book_update","event":"update","result":{"U":53095257671,"a":[{"p":"38165.5","s":0}],"b":[{"p":"38076.8","s":0},{"p":"38066.4","s":0},{"p":"38081.7","s":0}],"s":"BTC_USDT","t":1701245726797,"u":53095257679}}
{"time":1701245726,"time_ms":1701245726852,"channel":"futures.order_book_update","event":"update","result":{"U":53095257680,"a":[{"p":"38165.6","s":0}],"b":[],"s":"BTC_USDT","t":1701245726832,"u":53095257696}}
{"time":1701245726,"time_ms":1701245726872,"channel":"futures.order_book_update","event":"update","result":{"U":53095257697,"a":[{"p":"38165.6","s":0}],"b":[],"s":"BTC_USDT","t":1701245726863,"u":53095257701}}
{"time":1701245726,"time_ms":1701245726913,"channel":"futures.order_book_update","event":"update","result":{"U":53095257702,"a":[{"p":"38165.6","s":0}],"b":[],"s":"BTC_USDT","t":1701245726903,"u":53095257716}}
{"time":1701245726,"time_ms":1701245726931,"channel":"futures.order_book_update","event":"update","result":{"U":53095257717,"a":[{"p":"38137.7","s":3248},{"p":"38137.1","s":583}],"b":[],"s":"BTC_USDT","t":1701245726907,"u":53095257718}}
{"time":1701245726,"time_ms":1701245726974,"channel":"futures.order_book_update","event":"update","result":{"U":53095257719,"a":[{"p":"38165.6","s":0},{"p":"38144.6","s":0},{"p":"38145.5","s":0}],"b":[{"p":"38105.7","s":0}],"s":"BTC_USDT","t":1701245726963,"u":53095257725}}
{"time":1701245726,"time_ms":1701245726994,"channel":"futures.order_book_update","event":"update","result":{"U":53095257726,"a":[{"p":"38165.7","s":0}],"b":[],"s":"BTC_USDT","t":1701245726984,"u":53095257730}}
{"time":1701245727,"time_ms":1701245727012,"channel":"futures.order_book_update","event":"update","result":{"U":53095257731,"a":[{"p":"38165.7","s":0}],"b":[],"s":"BTC_USDT","t":1701245726987,"u":53095257731}}
{"time":1701245727,"time_ms":1701245727031,"channel":"futures.order_book_update","event":"update","result":{"U":53095257732,"a":[{"p":"38138.3","s":3341},{"p":"38139.1","s":0},{"p":"38138","s":0},{"p":"38141.5","s":0},{"p":"38165.7","s":0},{"p":"38138.8","s":2175},{"p":"38137.4","s":2307},{"p":"38137.7","s":919},{"p":"38138.4","s":0},{"p":"38139.2","s":0}],"b":[{"p":"38120.6","s":0},{"p":"38115.1","s":0},{"p":"38114.1","s":0},{"p":"38122","s":0},{"p":"38119.3","s":0},{"p":"38120","s":0}],"s":"BTC_USDT","t":1701245727022,"u":53095257753}}
{"time":1701245727,"time_ms":1701245727052,"channel":"futures.order_book_update","event":"update","result":{"U":53095257754,"a":[{"p":"38165.6","s":0}],"b":[{"p":"38121.3","s":0}],"s":"BTC_USDT","t":1701245727041,"u":53095257768}}
{"time":1701245727,"time_ms":1701245727073,"channel":"futures.order_book_update","event":"update","result":{"U":53095257769,"a":[{"p":"38140.2","s":0},{"p":"38165.7","s":0},{"p":"38141.7","s":0},{"p":"38154.7","s":0}],"b":[],"s":"BTC_USDT","t":1701245727066,"u":53095257777}}
{"time":1701245727,"time_ms":1701245727112,"channel":"futures.order_book_update","event":"update","result":{"U":53095257778,"a":[{"p":"38165.7","s":0}],"b":[],"s":"BTC_USDT","t":1701245727087,"u":53095257781}}
{"time":1701245727,"time_ms":1701245727134,"channel":"futures.order_book_update","event":"update","result":{"U":53095257782,"a":[],"b":[{"p":"38078.7","s":0}],"s":"BTC_USDT","t":1701245727125,"u":53095257785}}
{"time":1701245727,"time_ms":1701245727151,"channel":"futures.order_book_update","event":"update","result":{"U":53095257786,"a":[{"p":"38165.7","s":0}],"b":[],"s":"BTC_USDT","t":1701245727142,"u":53095257789}}
{"time":1701245727,"time_ms":1701245727171,"channel":"futures.order_book_update","event":"update","result":{"U":53095257790,"a":[{"p":"38165.7","s":0}],"b":[{"p":"38134.1","s":3808}],"s":"BTC_USDT","t":1701245727146,"u":53095257792}}
{"time":1701245727,"time_ms":1701245727192,"channel":"futures.order_book_update","event":"update","result":{"U":53095257793,"a":[{"p":"38144.2","s":0},{"p":"38165.7","s":0}],"b":[{"p":"38121.2","s":0}],"s":"BTC_USDT","t":1701245727171,"u":53095257798}}
{"time":1701245727,"time_ms":1701245727212,"channel":"futures.order_book_update","event":"update","result":{"U":53095257799,"a":[{"p":"38137.6","s":2175},{"p":"38137.8","s":0},{"p":"38139.1","s":0},{"p":"38139.9","s":0},{"p":"38165.7","s":0}],"b":[{"p":"38122.8","s":0},{"p":"38120.2","s":0}],"s":"BTC_USDT","t":1701245727204,"u":53095257809}}
{"time":1701245727,"time_ms":1701245727233,"channel":"futures.order_book_update","event":"update","result":{"U":53095257810,"a":[{"p":"38138","s":3341},{"p":"38138.3","s":0},{"p":"38139.1","s":0}],"b":[{"p":"38115.8","s":0},{"p":"38121.2","s":0}],"s":"BTC_USDT","t":1701245727207,"u":53095257815}}
{"time":1701245727,"time_ms":1701245727251,"channel":"futures.order_book_update","event":"update","result":{"U":53095257816,"a":[{"p":"38165.7","s":0}],"b":[],"s":"BTC_USDT","t":1701245727233,"u":53095257818}}
{"time":1701245727,"time_ms":1701245727271,"channel":"futures.order_book_update","event":"update","result":{"U":53095257819,"a":[{"p":"38165.7","s":0}],"b":[],"s":"BTC_USDT","t":1701245727266,"u":53095257830}}
{"time":1701245727,"time_ms":1701245727312,"channel":"futures.order_book_update","event":"update","result":{"U":53095257831,"a":[{"p":"38165.7","s":0}],"b":[],"s":"BTC_USDT","t":1701245727289,"u":53095257832}}
{"time":1701245727,"time_ms":1701245727332,"channel":"futures.order_book_update","event":"update","result":{"U":53095257833,"a":[{"p":"38165.8","s":0}],"b":[],"s":"BTC_USDT","t":1701245727307,"u":53095257834}}
{"time":1701245727,"time_ms":1701245727353,"channel":"futures.order_book_update","event":"update","result":{"U":53095257835,"a":[{"p":"38165.8","s":0}],"b":[],"s":"BTC_USDT","t":1701245727344,"u":53095257836}}
{"time":1701245727,"time_ms":1701245727374,"channel":"futures.order_book_update","event":"update","result":{"U":53095257837,"a":[{"p":"38137.6","s":0},{"p":"38143.8","s":0},{"p":"38139.1","s":0},{"p":"38139.2","s":0},{"p":"38137.8","s":2175},{"p":"38138.4","s":3341},{"p":"38138","s":0}],"b":[{"p":"38126.8","s":655},{"p":"38126","s":600},{"p":"38125.6","s":3633},{"p":"38126.2","s":2000},{"p":"38128.7","s":0},{"p":"38120.5","s":0},{"p":"38128","s":0},{"p":"38129.5","s":0},{"p":"38056.1","s":0}],"s":"BTC_USDT","t":1701245727365,"u":53095257848}}
{"time":1701245727,"time_ms":1701245727394,"channel":"futures.order_book_update","event":"update","result":{"U":53095257849,"a":[{"p":"38165.8","s":0}],"b":[{"p":"38127","s":9109},{"p":"38125.6","s":0},{"p":"38126.2","s":0},{"p":"38126","s":0},{"p":"38128.4","s":732},{"p":"38126.5","s":2},{"p":"38129.2","s":2},{"p":"38127.6","s":2}],"s":"BTC_USDT","t":1701245727386,"u":53095257857}}
{"time":1701245727,"time_ms":1701245727413,"channel":"futures.order_book_update","event":"update","result":{"U":53095257858,"a":[{"p":"38139.9","s":0},{"p":"38137.3","s":5516},{"p":"38137.8","s":0},{"p":"38138.8","s":0},{"p":"38141.9","s":0},{"p":"38144.4","s":0},{"p":"38138.3","s":2175},{"p":"38139.1","s":10858},{"p":"38138.4","s":0},{"p":"38139.2","s":0}],"b":[{"p":"38056.6","s":0},{"p":"38111.5","s":0},{"p":"38115.2","s":0},{"p":"38126.2","s":2000},{"p":"38117","s":0},{"p":"38121","s":0},{"p":"38126","s":0},{"p":"38114.8","s":0},{"p":"38119.5","s":0},{"p":"38123.5","s":0},{"p":"38126.8","s":0},{"p":"38122.5","s":0},{"p":"38120.9","s":0},{"p":"38120","s":0},{"p":"38115.6","s":0}],"s":"BTC_USDT","t":1701245727404,"u":53095257900}}
{"time":1701245727,"time_ms":1701245727432,"channel":"futures.order_book_update","event":"update","result":{"U":53095257901,"a":[{"p":"38156.5","s":0}],"b":[],"s":"BTC_USDT","t":1701245727422,"u":53095257901}}
{"time":1701245727,"time_ms":1701245727453,"channel":"futures.order_book_update","event":"update","result":{"U":53095257902,"a":[{"p":"38165.8","s":0},{"p":"38154.8","s":0}],"b":[{"p":"38107.6","s":0},{"p":"38119.6","s":0}],"s":"BTC_USDT","t":1701245727445,"u":53095257910}}
{"time":1701245727,"time_ms":1701245727473,"channel":"futures.order_book_update","event":"update","result":{"U":53095257911,"a":[{"p":"38165.8","s":0}],"b":[],"s":"BTC_USDT","t":1701245727463,"u":53095257913}}
{"time":1701245727,"time_ms":1701245727495,"channel":"futures.order_book_update","event":"update","result":{"U":53095257914,"a":[{"p":"38165.8","s":0}],"b":[],"s":"BTC_USDT","t":1701245727484,"u":53095257916}}
{"time":1701245727,"time_ms":1701245727512,"channel":"futures.order_book_update","event":"update","result":{"U":53095257917,"a":[{"p":"38165.8","s":0}],"b":[{"p":"38127","s":9209},{"p":"38126","s":0}],"s":"BTC_USDT","t":1701245727492,"u":53095257922}}
{"time":1701245727,"time_ms":1701245727552,"channel":"futures.order_book_update","event":"update","result":{"U":53095257923,"a":[{"p":"38150.9","s":0},{"p":"38165.8","s":0}],"b":[],"s":"BTC_USDT","t":1701245727539,"u":53095257927}}
{"time":1701245727,"time_ms":1701245727573,"channel":"futures.order_book_update","event":"update","result":{"U":53095257928,"a":[{"p":"38143.5","s":0}],"b":[],"s":"BTC_USDT","t":1701245727565,"u":53095257930}}
{"time":1701245727,"time_ms":1701245727612,"channel":"futures.order_book_update","event":"update","result":{"U":53095257931,"a":[{"p":"38165.8","s":0},{"p":"38140.8","s":0}],"b":[],"s":"BTC_USDT","t":1701245727591,"u":53095257941}}
{"time":1701245727,"time_ms":1701245727633,"channel":"futures.order_book_update","event":"update","result":{"U":53095257942,"a":[{"p":"38165.9","s":0}],"b":[],"s":"BTC_USDT","t":1701245727616,"u":53095257945}}
{"time":1701245727,"time_ms":1701245727678,"channel":"futures.order_book_update","event":"update","result":{"U":53095257946,"a":[{"p":"38165.9","s":0}],"b":[],"s":"BTC_USDT","t":1701245727665,"u":53095257950}}
{"time":1701245727,"time_ms":1701245727714,"channel":"futures.order_book_update","event":"update","result":{"U":53095257951,"a":[],"b":[{"p":"38115","s":0}],"s":"BTC_USDT","t":1701245727687,"u":53095257953}}
{"time":1701245727,"time_ms":1701245727732,"channel":"futures.order_book_update","event":"update","result":{"U":53095257954,"a":[{"p":"38166","s":0},{"p":"38165.9","s":0}],"b":[],"s":"BTC_USDT","t":1701245727715,"u":53095257956}}
{"time":1701245727,"time_ms":1701245727752,"channel":"futures.order_book_update","event":"update","result":{"U":53095257957,"a":[],"b":[{"p":"38101.3","s":0}],"s":"BTC_USDT","t":1701245727728,"u":53095257958}}
{"time":1701245727,"time_ms":1701245727771,"channel":"futures.order_book_update","event":"update","result":{"U":53095257959,"a":[{"p":"38166","s":0},{"p":"38143.2","s":0}],"b":[],"s":"BTC_USDT","t":1701245727764,"u":53095257964}}
{"time":1701245727,"time_ms":1701245727814,"channel":"futures.order_book_update","event":"update","result":{"U":53095257965,"a":[{"p":"38166","s":0}],"b":[],"s":"BTC_USDT","t":1701245727793,"u":53095257969}}
{"time":1701245727,"time_ms":1701245727833,"channel":"futures.order_book_update","event":"update","result":{"U":53095257970,"a":[{"p":"38166","s":0}],"b":[],"s":"BTC_USDT","t":1701245727822,"u":53095257971}}
{"time":1701245727,"time_ms":1701245727851,"channel":"futures.order_book_update","event":"update","result":{"U":53095257972,"a":[{"p":"38149.8","s":0}],"b":[],"s":"BTC_USDT","t":1701245727841,"u":53095257972}}
{"time":1701245727,"time_ms":1701245727893,"channel":"futures.order_book_update","event":"update","result":{"U":53095257973,"a":[{"p":"38166","s":0}],"b":[],"s":"BTC_USDT","t":1701245727885,"u":53095257980}}
{"time":1701245727,"time_ms":1701245727954,"channel":"futures.order_book_update","event":"update","result":{"U":53095257981,"a":[{"p":"38166","s":0}],"b":[],"s":"BTC_USDT","t":1701245727929,"u":53095257985}}
{"time":1701245727,"time_ms":1701245727973,"channel":"futures.order_book_update","event":"update","result":{"U":53095257986,"a":[{"p":"38144","s":0},{"p":"38140","s":0},{"p":"38142.8","s":0},{"p":"38166","s":0}],"b":[{"p":"38119.5","s":0},{"p":"38123.5","s":0},{"p":"38104.7","s":0}],"s":"BTC_USDT","t":1701245727964,"u":53095258008}}
{"time":1701245727,"time_ms":1701245727994,"channel":"futures.order_book_update","event":"update","result":{"U":53095258009,"a":[{"p":"38166.1","s":0},{"p":"38143.5","s":0}],"b":[{"p":"38114.1","s":0}],"s":"BTC_USDT","t":1701245727982,"u":53095258016}}
{"time":1701245728,"time_ms":1701245728014,"channel":"futures.order_book_update","event":"update","result":{"U":53095258017,"a":[{"p":"38166.1","s":0}],"b":[{"p":"38120.3","s":0}],"s":"BTC_USDT","t":1701245728004,"u":53095258019}}
{"time":1701245728,"time_ms":1701245728032,"channel":"futures.order_book_update","event":"update","result":{"U":53095258020,"a":[{"p":"38145.1","s":0},{"p":"38137.1","s":2917},{"p":"38138.4","s":2175},{"p":"38137.3","s":0},{"p":"38138.3","s":0},{"p":"38137.4","s":0},{"p":"38139.1","s":10858},{"p":"38137.2","s":6107},{"p":"38137.6","s":3341},{"p":"38139.2","s":9617}],"b":[{"p":"38134.1","s":5318},{"p":"38120.3","s":0},{"p":"38122","s":0},{"p":"38119.3","s":0},{"p":"38115","s":0}],"s":"BTC_USDT","t":1701245728017,"u":53095258039}}
{"time":1701245728,"time_ms":1701245728052,"channel":"futures.order_book_update","event":"update","result":{"U":53095258040,"a":[{"p":"38166.1","s":0}],"b":[{"p":"38106.9","s":0},{"p":"38112.5","s":0}],"s":"BTC_USDT","t":1701245728041,"u":53095258050}}
{"time":1701245728,"time_ms":1701245728092,"channel":"futures.order_book_update","event":"update","result":{"U":53095258051,"a":[{"p":"38139.2","s":0},{"p":"38166","s":0},{"p":"38166.1","s":0},{"p":"38137.4","s":2175},{"p":"38137.2","s":3932}],"b":[{"p":"38134.1","s":6828}],"s":"BTC_USDT","t":1701245728084,"u":53095258059}}
{"time":1701245728,"time_ms":1701245728112,"channel":"futures.order_book_update","event":"update","result":{"U":53095258060,"a":[],"b":[{"p":"38120.6","s":0}],"s":"BTC_USDT","t":1701245728099,"u":53095258061}}
{"time":1701245728,"time_ms":1701245728132,"channel":"futures.order_book_update","event":"update","result":{"U":53095258062,"a":[],"b":[{"p":"38126.5","s":0},{"p":"38125.6","s":3633},{"p":"38125.9","s":655},{"p":"38128.4","s":730},{"p":"38125.5","s":182},{"p":"38129.2","s":0},{"p":"38127.6","s":0}],"s":"BTC_USDT","t":1701245728125,"u":53095258066}}
{"time":1701245728,"time_ms":1701245728152,"channel":"futures.order_book_update","event":"update","result":{"U":53095258067,"a":[{"p":"38166.1","s":0}],"b":[{"p":"38134.1","s":7311}],"s":"BTC_USDT","t":1701245728141,"u":53095258070}}
{"time":1701245728,"time_ms":1701245728173,"channel":"futures.order_book_update","event":"update","result":{"U":53095258071,"a":[],"b":[{"p":"38130.3","s":2},{"p":"38129.6","s":2},{"p":"38131.1","s":2},{"p":"38128.4","s":732},{"p":"38125.5","s":0},{"p":"38125.9","s":0},{"p":"38125.6","s":0}],"s":"BTC_USDT","t":1701245728152,"u":53095258075}}
{"time":1701245728,"time_ms":1701245728192,"channel":"futures.order_book_update","event":"update","result":{"U":53095258076,"a":[{"p":"38142.4","s":0},{"p":"38166.1","s":0}],"b":[{"p":"38115.5","s":0}],"s":"BTC_USDT","t":1701245728179,"u":53095258090}}
{"time":1701245728,"time_ms":1701245728211,"channel":"futures.order_book_update","event":"update","result":{"U":53095258091,"a":[{"p":"38166.2","s":0}],"b":[{"p":"38120.7","s":0},{"p":"38120.5","s":0}],"s":"BTC_USDT","t":1701245728191,"u":53095258096}}
{"time":1701245728,"time_ms":1701245728252,"channel":"futures.order_book_update","event":"update","result":{"U":53095258097,"a":[{"p":"38137.4","s":0},{"p":"38166.2","s":0},{"p":"38139.2","s":0},{"p":"38141.2","s":0},{"p":"38139.1","s":10858},{"p":"38137","s":2175},{"p":"38137.3","s":3341},{"p":"38137.6","s":0}],"b":[{"p":"38119.4","s":0},{"p":"38120.6","s":0},{"p":"38122.3","s":0},{"p":"38115.4","s":0},{"p":"38120.3","s":0}],"s":"BTC_USDT","t":1701245728238,"u":53095258116}}
{"time":1701245728,"time_ms":1701245728271,"channel":"futures.order_book_update","event":"update","result":{"U":53095258117,"a":[{"p":"38166.2","s":0}],"b":[{"p":"38124","s":0},{"p":"38111.5","s":0},{"p":"38120","s":0}],"s":"BTC_USDT","t":1701245728265,"u":53095258124}}
{"time":1701245728,"time_ms":1701245728291,"channel":"futures.order_book_update","event":"update","result":{"U":53095258125,"a":[{"p":"38137.3","s":2175},{"p":"38137.6","s":3341},{"p":"38137","s":0},{"p":"38139.2","s":0},{"p":"38143.8","s":0},{"p":"38140.8","s":0},{"p":"38166.3","s":0}],"b":[{"p":"38114.1","s":0},{"p":"38120.1","s":0},{"p":"38120.3","s":0}],"s":"BTC_USDT","t":1701245728285,"u":53095258138}}
{"time":1701245728,"time_ms":1701245728313,"channel":"futures.order_book_update","event":"update","result":{"U":53095258139,"a":[{"p":"38166.3","s":0},{"p":"38139.2","s":0},{"p":"38138.8","s":2175},{"p":"38138.4","s":0}],"b":[{"p":"38120.7","s":0},{"p":"38119","s":0},{"p":"38115.1","s":0}],"s":"BTC_USDT","t":1701245728299,"u":53095258148}}
{"time":1701245728,"time_ms":1701245728331,"channel":"futures.order_book_update","event":"update","result":{"U":53095258149,"a":[{"p":"38138.3","s":95},{"p":"38139.1","s":0},{"p":"38166.3","s":0}],"b":[],"s":"BTC_USDT","t":1701245728321,"u":53095258154}}
{"time":1701245728,"time_ms":1701245728352,"channel":"futures.order_book_update","event":"update","result":{"U":53095258155,"a":[{"p":"38143.4","s":0},{"p":"38172.5","s":0},{"p":"38166.3","s":0}],"b":[{"p":"38125.6","s":3633},{"p":"38125.5","s":182},{"p":"38130.3","s":0},{"p":"38129.6","s":0},{"p":"38125.9","s":0},{"p":"38120","s":0},{"p":"38125.4","s":9594},{"p":"38128.4","s":730},{"p":"38131.1","s":0},{"p":"38115.8","s":0}],"s":"BTC_USDT","t":1701245728344,"u":53095258168}}
{"time":1701245728,"time_ms":1701245728371,"channel":"futures.order_book_update","event":"update","result":{"U":53095258169,"a":[{"p":"38166.3","s":0}],"b":[{"p":"38131.1","s":2},{"p":"38128.4","s":732},{"p":"38130.3","s":2},{"p":"38126.6","s":786},{"p":"38125.4","s":0},{"p":"38125.5","s":0}],"s":"BTC_USDT","t":1701245728361,"u":53095258176}}
{"time":1701245728,"time_ms":1701245728391,"channel":"futures.order_book_update","event":"update","result":{"U":53095258177,"a":[{"p":"38142","s":0},{"p":"38139.1","s":10858},{"p":"38138.3","s":2270},{"p":"38137.3","s":0}],"b":[{"p":"38125.6","s":0},{"p":"38088.8","s":0},{"p":"38120.2","s":0},{"p":"38126","s":0},{"p":"38120.8","s":0},{"p":"38121.6","s":0},{"p":"38113.5","s":0},{"p":"38129.6","s":2}],"s":"BTC_USDT","t":1701245728374,"u":53095258195}}
{"time":1701245728,"time_ms":1701245728411,"channel":"futures.order_book_update","event":"update","result":{"U":53095258196,"a":[{"p":"38137.1","s":583},{"p":"38137.4","s":2342},{"p":"38139.1","s":0}],"b":[],"s":"BTC_USDT","t":1701245728393,"u":53095258197}}
{"time":1701245728,"time_ms":1701245728433,"channel":"futures.order_book_update","event":"update","result":{"U":53095258198,"a":[{"p":"38166.3","s":0}],"b":[],"s":"BTC_USDT","t":1701245728407,"u":53095258209}}
{"time":1701245728,"time_ms":1701245728455,"channel":"futures.order_book_update","event":"update","result":{"U":53095258210,"a":[{"p":"38166.3","s":0}],"b":[],"s":"BTC_USDT","t":1701245728444,"u":53095258211}}
{"time":1701245728,"time_ms":1701245728494,"channel":"futures.order_book_update","event":"update","result":{"U":53095258212,"a":[{"p":"38143.5","s":0},{"p":"38139.5","s":0}],"b":[{"p":"38120","s":0},{"p":"38124","s":0},{"p":"38112","s":0}],"s":"BTC_USDT","t":1701245728481,"u":53095258223}}
{"time":1701245728,"time_ms":1701245728514,"channel":"futures.order_book_update","event":"update","result":{"U":53095258224,"a":[{"p":"38166.3","s":0}],"b":[{"p":"38107.8","s":0}],"s":"BTC_USDT","t":1701245728504,"u":53095258229}}
{"time":1701245728,"time_ms":1701245728531,"channel":"futures.order_book_update","event":"update","result":{"U":53095258230,"a":[{"p":"38141.8","s":0}],"b":[{"p":"38120.2","s":0},{"p":"38126","s":0}],"s":"BTC_USDT","t":1701245728514,"u":53095258232}}
{"time":1701245728,"time_ms":1701245728552,"channel":"futures.order_book_update","event":"update","result":{"U":53095258233,"a":[{"p":"38166.4","s":0}],"b":[],"s":"BTC_USDT","t":1701245728543,"u":53095258235}}
{"time":1701245728,"time_ms":1701245728573,"channel":"futures.order_book_update","event":"update","result":{"U":53095258236,"a":[{"p":"38141.6","s":0}],"b":[],"s":"BTC_USDT","t":1701245728565,"u":53095258237}}
{"time":1701245728,"time_ms":1701245728612,"channel":"futures.order_book_update","event":"update","result":{"U":53095258238,"a":[{"p":"38166.4","s":0}],"b":[],"s":"BTC_USDT","t":1701245728591,"u":53095258242}}
{"time":1701245728,"time_ms":1701245728632,"channel":"futures.order_book_update","event":"update","result":{"U":53095258243,"a":[{"p":"38145.5","s":0},{"p":"38166.4","s":0},{"p":"38141.5","s":0}],"b":[{"p":"38125.5","s":182},{"p":"38128.4","s":730},{"p":"38126","s":600},{"p":"38125.6","s":3633},{"p":"38130.3","s":0},{"p":"38121.5","s":0},{"p":"38129.6","s":0},{"p":"38131.1","s":0},{"p":"38113.5","s":0}],"s":"BTC_USDT","t":1701245728609,"u":53095258258}}
{"time":1701245728,"time_ms":1701245728673,"channel":"futures.order_book_update","event":"update","result":{"U":53095258259,"a":[{"p":"38166.4","s":0}],"b":[],"s":"BTC_USDT","t":1701245728663,"u":53095258266}}
{"time":1701245728,"time_ms":1701245728693,"channel":"futures.order_book_update","event":"update","result":{"U":53095258267,"a":[{"p":"38166.4","s":0}],"b":[{"p":"38131.1","s":2},{"p":"38126","s":0},{"p":"38125.5","s":0},{"p":"38125.6","s":0},{"p":"38128.4","s":732},{"p":"38127","s":9109},{"p":"38129.6","s":2},{"p":"38130.3","s":2}],"s":"BTC_USDT","t":1701245728687,"u":53095258276}}
{"time":1701245728,"time_ms":1701245728711,"channel":"futures.order_book_update","event":"update","result":{"U":53095258277,"a":[{"p":"38137.4","s":0},{"p":"38137.6","s":0},{"p":"38144.6","s":0},{"p":"38139.1","s":0},{"p":"38141.2","s":0},{"p":"38138.9","s":609},{"p":"38138.2","s":2406},{"p":"38138.4","s":3341}],"b":[{"p":"38126","s":0},{"p":"38119.4","s":0},{"p":"38120.3","s":0},{"p":"38122","s":0},{"p":"38134.1","s":12749}],"s":"BTC_USDT","t":1701245728699,"u":53095258293}}
{"time":1701245728,"time_ms":1701245728732,"channel":"futures.order_book_update","event":"update","result":{"U":53095258294,"a":[{"p":"38166.4","s":0}],"b":[{"p":"38112.6","s":0},{"p":"38120.5","s":0},{"p":"38134.1","s":7311}],"s":"BTC_USDT","t":1701245728717,"u":53095258301}}
{"time":1701245728,"time_ms":1701245728772,"channel":"futures.order_book_update","event":"update","result":{"U":53095258302,"a":[{"p":"38139.1","s":10858},{"p":"38134.2","s":174071},{"p":"38137.1","s":2880},{"p":"38138.2","s":0},{"p":"38166.4","s":0},{"p":"38141.8","s":0}],"b":[{"p":"38120.3","s":0}],"s":"BTC_USDT","t":1701245728764,"u":53095258311}}
{"time":1701245728,"time_ms":1701245728814,"channel":"futures.order_book_update","event":"update","result":{"U":53095258312,"a":[{"p":"38166.4","s":0}],"b":[{"p":"38127","s":9209},{"p":"38126","s":0}],"s":"BTC_USDT","t":1701245728797,"u":53095258317}}
{"time":1701245728,"time_ms":1701245728832,"channel":"futures.order_book_update","event":"update","result":{"U":53095258318,"a":[{"p":"38166.4","s":0}],"b":[{"p":"38128.4","s":730},{"p":"38126","s":600},{"p":"38125.6","s":3633},{"p":"38125.5","s":182},{"p":"38130.3","s":0},{"p":"38129.6","s":0},{"p":"38131.1","s":0},{"p":"38013.4","s":0}],"s":"BTC_USDT","t":1701245728821,"u":53095258323}}
{"time":1701245728,"time_ms":1701245728893,"channel":"futures.order_book_update","event":"update","result":{"U":53095258324,"a":[{"p":"38166.7","s":0}],"b":[{"p":"38126","s":0},{"p":"38129.6","s":2},{"p":"38128.4","s":732},{"p":"38131.1","s":2},{"p":"38130.3","s":2},{"p":"38125.6","s":0},{"p":"38125.5","s":0}],"s":"BTC_USDT","t":1701245728876,"u":53095258330}}
{"time":1701245728,"time_ms":1701245728912,"channel":"futures.order_book_update","event":"update","result":{"U":53095258331,"a":[{"p":"38166.7","s":0},{"p":"38142.3","s":0}],"b":[{"p":"38131.1","s":0},{"p":"38130.3","s":0},{"p":"38122.8","s":0},{"p":"38125.6","s":3633},{"p":"38126","s":600},{"p":"38125.5","s":182},{"p":"38128.4","s":730},{"p":"38129.6","s":0}],"s":"BTC_USDT","t":1701245728897,"u":53095258343}}
{"time":1701245728,"time_ms":1701245728934,"channel":"futures.order_book_update","event":"update","result":{"U":53095258344,"a":[{"p":"38138.2","s":2413},{"p":"38137.1","s":583},{"p":"38139.1","s":0},{"p":"38141.2","s":0},{"p":"38166.7","s":0}],"b":[{"p":"38125.6","s":0},{"p":"38125.5","s":0},{"p":"38108.2","s":0},{"p":"38128.4","s":732},{"p":"38129.2","s":2},{"p":"38126.5","s":2},{"p":"38127.7","s":2518}],"s":"BTC_USDT","t":1701245728916,"u":53095258354}}
{"time":1701245728,"time_ms":1701245728952,"channel":"futures.order_book_update","event":"update","result":{"U":53095258355,"a":[{"p":"38166.7","s":0}],"b":[],"s":"BTC_USDT","t":1701245728936,"u":53095258356}}
{"time":1701245728,"time_ms":1701245728993,"channel":"futures.order_book_update","event":"update","result":{"U":53095258357,"a":[{"p":"38148.3","s":0},{"p":"38166.5","s":0},{"p":"38141.8","s":0}],"b":[{"p":"38125.6","s":3633},{"p":"38126.5","s":2},{"p":"38128.4","s":730},{"p":"38127.7","s":2516},{"p":"38129.2","s":0},{"p":"38120.3","s":0},{"p":"38125.4","s":0},{"p":"38125.5","s":0},{"p":"38126","s":600}],"s":"BTC_USDT","t":1701245728983,"u":53095258371}}
{"time":1701245729,"time_ms":1701245729013,"channel":"futures.order_book_update","event":"update","result":{"U":53095258372,"a":[],"b":[{"p":"38127","s":9109},{"p":"38129.2","s":2},{"p":"38127.6","s":2},{"p":"38128.4","s":732},{"p":"38125.6","s":0},{"p":"38126","s":0},{"p":"38120.9","s":0}],"s":"BTC_USDT","t":1701245729002,"u":53095258377}}
{"time":1701245729,"time_ms":1701245729032,"channel":"futures.order_book_update","event":"update","result":{"U":53095258378,"a":[{"p":"38138.3","s":95},{"p":"38137.8","s":3341},{"p":"38137.4","s":4519},{"p":"38138.4","s":2175},{"p":"38138.8","s":0},{"p":"38142.2","s":0},{"p":"38145.2","s":0},{"p":"38138.2","s":0},{"p":"38139.1","s":0},{"p":"38139.2","s":0}],"b":[{"p":"38122.3","s":0},{"p":"38119.5","s":0}],"s":"BTC_USDT","t":1701245729017,"u":53095258395}}
{"time":1701245729,"time_ms":1701245729052,"channel":"futures.order_book_update","event":"update","result":{"U":53095258396,"a":[{"p":"38137.1","s":2876},{"p":"38137.4","s":2175},{"p":"38166.5","s":0}],"b":[],"s":"BTC_USDT","t":1701245729037,"u":53095258399}}
{"time":1701245729,"time_ms":1701245729071,"channel":"futures.order_book_update","event":"update","result":{"U":53095258400,"a":[{"p":"38137.1","s":583},{"p":"38137.4","s":2175}],"b":[{"p":"38126.5","s":0},{"p":"38127.6","s":0},{"p":"38126","s":700},{"p":"38125.5","s":182},{"p":"38125.6","s":3633},{"p":"38128.4","s":730},{"p":"38129.2","s":0}],"s":"BTC_USDT","t":1701245729065,"u":53095258407}}
{"time":1701245729,"time_ms":1701245729091,"channel":"futures.order_book_update","event":"update","result":{"U":53095258408,"a":[{"p":"38137.1","s":2878},{"p":"38166.6","s":0}],"b":[{"p":"38126","s":100}],"s":"BTC_USDT","t":1701245729086,"u":53095258411}}
{"time":1701245729,"time_ms":1701245729156,"channel":"futures.order_book_update","event":"update","result":{"U":53095258412,"a":[{"p":"38166.5","s":0}],"b":[],"s":"BTC_USDT","t":1701245729144,"u":53095258422}}
{"time":1701245729,"time_ms":1701245729213,"channel":"futures.order_book_update","event":"update","result":{"U":53095258423,"a":[{"p":"38166.5","s":0}],"b":[],"s":"BTC_USDT","t":1701245729200,"u":53095258428}}
{"time":1701245729,"time_ms":1701245729252,"channel":"futures.order_book_update","event":"update","result":{"U":53095258429,"a":[{"p":"38166.5","s":0}],"b":[],"s":"BTC_USDT","t":1701245729243,"u":53095258431}}
{"time":1701245729,"time_ms":1701245729292,"channel":"futures.order_book_update","event":"update","result":{"U":53095258432,"a":[{"p":"38166.6","s":0}],"b":[],"s":"BTC_USDT","t":1701245729280,"u":53095258434}}
{"time":1701245729,"time_ms":1701245729313,"channel":"futures.order_book_update","event":"update","result":{"U":53095258435,"a":[{"p":"38166.6","s":0}],"b":[{"p":"38126","s":700},{"p":"38120.3","s":0}],"s":"BTC_USDT","t":1701245729298,"u":53095258445}}
{"time":1701245729,"time_ms":1701245729351,"channel":"futures.order_book_update","event":"update","result":{"U":53095258446,"a":[],"b":[{"p":"38126","s":100}],"s":"BTC_USDT","t":1701245729344,"u":53095258448}}
{"time":1701245729,"time_ms":1701245729372,"channel":"futures.order_book_update","event":"update","result":{"U":53095258449,"a":[{"p":"38166.6","s":0}],"b":[],"s":"BTC_USDT","t":1701245729352,"u":53095258451}}
{"time":1701245729,"time_ms":1701245729411,"channel":"futures.order_book_update","event":"update","result":{"U":53095258452,"a":[{"p":"38166.6","s":0}],"b":[],"s":"BTC_USDT","t":1701245729394,"u":53095258453}}
{"time":1701245729,"time_ms":1701245729431,"channel":"futures.order_book_update","event":"update","result":{"U":53095258454,"a":[],"b":[{"p":"38126","s":700},{"p":"38120.3","s":0}],"s":"BTC_USDT","t":1701245729422,"u":53095258456}}
{"time":1701245729,"time_ms":1701245729451,"channel":"futures.order_book_update","event":"update","result":{"U":53095258457,"a":[{"p":"38137.8","s":0},{"p":"38166.6","s":0},{"p":"38139.1","s":0},{"p":"38138","s":3341}],"b":[{"p":"38126","s":100}],"s":"BTC_USDT","t":1701245729428,"u":53095258461}}
{"time":1701245729,"time_ms":1701245729496,"channel":"futures.order_book_update","event":"update","result":{"U":53095258462,"a":[{"p":"38142.4","s":0}],"b":[],"s":"BTC_USDT","t":1701245729486,"u":53095258462}}
{"time":1701245729,"time_ms":1701245729513,"channel":"futures.order_book_update","event":"update","result":{"U":53095258463,"a":[],"b":[{"p":"38120.3","s":0},{"p":"38126","s":700}],"s":"BTC_USDT","t":1701245729498,"u":53095258465}}
{"time":1701245729,"time_ms":1701245729570,"channel":"futures.order_book_update","event":"update","result":{"U":53095258466,"a":[{"p":"38139.8","s":0}],"b":[],"s":"BTC_USDT","t":1701245729559,"u":53095258466}}
{"time":1701245729,"time_ms":1701245729593,"channel":"futures.order_book_update","event":"update","result":{"U":53095258467,"a":[],"b":[{"p":"38127.9","s":2},{"p":"38126.8","s":2},{"p":"38125.6","s":0},{"p":"38125.5","s":0},{"p":"38126","s":0},{"p":"38126.2","s":0},{"p":"38129.5","s":2},{"p":"38128.7","s":2}],"s":"BTC_USDT","t":1701245729579,"u":53095258471}}
{"time":1701245729,"time_ms":1701245729613,"channel":"futures.order_book_update","event":"update","result":{"U":53095258472,"a":[],"b":[{"p":"38126","s":0},{"p":"38127","s":9209}],"s":"BTC_USDT","t":1701245729593,"u":53095258474}}
{"time":1701245729,"time_ms":1701245729633,"channel":"futures.order_book_update","event":"update","result":{"U":53095258475,"a":[{"p":"38140.2","s":0}],"b":[],"s":"BTC_USDT","t":1701245729622,"u":53095258475}}
{"time":1701245729,"time_ms":1701245729653,"channel":"futures.order_book_update","event":"update","result":{"U":53095258476,"a":[{"p":"38137.4","s":0},{"p":"38139.1","s":0},{"p":"38138.8","s":2175},{"p":"38137.6","s":2175},{"p":"38138.4","s":0}],"b":[{"p":"38127.9","s":0},{"p":"38121","s":0},{"p":"38125.6","s":3633},{"p":"38126","s":600},{"p":"38126.2","s":2000},{"p":"38129.5","s":0},{"p":"38120.9","s":0},{"p":"38125.5","s":182},{"p":"38128.7","s":0},{"p":"38126.8","s":0}],"s":"BTC_USDT","t":1701245729638,"u":53095258488}}
{"time":1701245729,"time_ms":1701245729673,"channel":"futures.order_book_update","event":"update","result":{"U":53095258489,"a":[{"p":"38137.8","s":2175},{"p":"38139.1","s":0},{"p":"38141.5","s":0},{"p":"38137.9","s":2898},{"p":"38138.2","s":3341},{"p":"38137.1","s":583},{"p":"38137.6","s":0},{"p":"38138","s":0},{"p":"38142.6","s":0}],"b":[{"p":"38128.8","s":2},{"p":"38129.6","s":2},{"p":"38126.9","s":15002},{"p":"38115.4","s":0},{"p":"38117","s":0},{"p":"38114.4","s":0},{"p":"38128","s":2},{"p":"38125.5","s":0},{"p":"38125.6","s":0},{"p":"38126","s":0},{"p":"38119.4","s":0},{"p":"38124.4","s":0}],"s":"BTC_USDT","t":1701245729663,"u":53095258510}}
{"time":1701245729,"time_ms":1701245729692,"channel":"futures.order_book_update","event":"update","result":{"U":53095258511,"a":[{"p":"38138.2","s":0},{"p":"38138.8","s":0},{"p":"38134.2","s":174680},{"p":"38139.3","s":0},{"p":"38151.1","s":0},{"p":"38137.9","s":525},{"p":"38137","s":3341},{"p":"38139.2","s":0},{"p":"38140.3","s":0},{"p":"38136.6","s":7864},{"p":"38137.8","s":2175},{"p":"38136.4","s":2175},{"p":"38139.1","s":10858},{"p":"38138.9","s":0},{"p":"38147.1","s":0},{"p":"38148.7","s":0},{"p":"38141.5","s":0},{"p":"38137.1","s":2961}],"b":[{"p":"38102.8","s":0},{"p":"38112","s":0},{"p":"38121.1","s":0},{"p":"38124","s":0},{"p":"38127","s":9009},{"p":"38115.3","s":0},{"p":"38114.8","s":0},{"p":"38119","s":0},{"p":"38115","s":0},{"p":"38120.1","s":0},{"p":"38116","s":0},{"p":"38120","s":0},{"p":"38120.3","s":0},{"p":"38126","s":0},{"p":"38122.5","s":0},{"p":"38121.3","s":0},{"p":"38117.2","s":0}],"s":"BTC_USDT","t":1701245729685,"u":53095258568}}
{"time":1701245729,"time_ms":1701245729713,"channel":"futures.order_book_update","event":"update","result":{"U":53095258569,"a":[{"p":"38154.4","s":0},{"p":"38139.3","s":0},{"p":"38138.1","s":2215},{"p":"38139.2","s":10932},{"p":"38137.4","s":3341},{"p":"38137","s":2175},{"p":"38137.8","s":0},{"p":"38136.4","s":0}],"b":[{"p":"38119","s":0}],"s":"BTC_USDT","t":1701245729696,"u":53095258581}}
{"time":1701245729,"time_ms":1701245729732,"channel":"futures.order_book_update","event":"update","result":{"U":53095258582,"a":[{"p":"38140.5","s":0}],"b":[{"p":"38076.1","s":0},{"p":"38119.6","s":0}],"s":"BTC_USDT","t":1701245729724,"u":53095258584}}
