{"time":1701245691,"time_ms":1701245691473,"channel":"futures.order_book_update","event":"update","result":{"U":53095244485,"a":[{"p":"38153.3","s":0}],"b":[],"s":"BTC_USDT","t":1701245691463,"u":53095244486}}
{"time":1701245691,"time_ms":1701245691496,"channel":"futures.order_book_update","event":"update","result":{"U":53095244487,"a":[{"p":"38151.8","s":0},{"p":"38151.4","s":0},{"p":"38153.5","s":0},{"p":"38150.9","s":15702},{"p":"38147.3","s":2349},{"p":"38147.2","s":0},{"p":"38159.4","s":0},{"p":"38157.5","s":0}],"b":[{"p":"38144.3","s":2},{"p":"38139.9","s":0},{"p":"38145","s":2},{"p":"38145.6","s":71437},{"p":"38143.1","s":2},{"p":"38141.1","s":0},{"p":"38137.4","s":0},{"p":"38138","s":100},{"p":"38141.9","s":0},{"p":"38131.4","s":0},{"p":"38131","s":0},{"p":"38142.6","s":0},{"p":"38137.1","s":0},{"p":"38120.5","s":0}],"s":"BTC_USDT","t":1701245691490,"u":53095244519}}
{"time":1701245691,"time_ms":1701245691512,"channel":"futures.order_book_update","event":"update","result":{"U":53095244520,"a":[{"p":"38151.6","s":0}],"b":[{"p":"38136","s":0}],"s":"BTC_USDT","t":1701245691497,"u":53095244525}}
{"time":1701245691,"time_ms":1701245691533,"channel":"futures.order_book_update","event":"update","result":{"U":53095244526,"a":[{"p":"38152.7","s":0},{"p":"38170","s":0}],"b":[{"p":"38145.6","s":70937},{"p":"38136.5","s":0}],"s":"BTC_USDT","t":1701245691526,"u":53095244532}}
{"time":1701245691,"time_ms":1701245691553,"channel":"futures.order_book_update","event":"update","result":{"U":53095244533,"a":[{"p":"38173.1","s":0}],"b":[{"p":"38135.6","s":0},{"p":"38106.2","s":0},{"p":"38137.8","s":0},{"p":"38136.2","s":0},{"p":"38139","s":100},{"p":"38144","s":0},{"p":"38093.4","s":0}],"s":"BTC_USDT","t":1701245691541,"u":53095244545}}
{"time":1701245691,"time_ms":1701245691573,"channel":"futures.order_book_update","event":"update","result":{"U":53095244546,"a":[],"b":[{"p":"38031.3","s":0}],"s":"BTC_USDT","t":1701245691555,"u":53095244548}}
{"time":1701245691,"time_ms":1701245691612,"channel":"futures.order_book_update","event":"update","result":{"U":53095244549,"a":[],"b":[{"p":"38139","s":0},{"p":"38137.4","s":0},{"p":"38138","s":100},{"p":"38144","s":100}],"s":"BTC_USDT","t":1701245691597,"u":53095244553}}
{"time":1701245691,"time_ms":1701245691631,"channel":"futures.order_book_update","event":"update","result":{"U":53095244554,"a":[{"p":"38156.5","s":0}],"b":[{"p":"38137.4","s":1315},{"p":"38144.3","s":0},{"p":"38143.1","s":0},{"p":"38145","s":0},{"p":"38137.8","s":15208},{"p":"38137.3","s":3958},{"p":"38145.6","s":70935}],"s":"BTC_USDT","t":1701245691621,"u":53095244558}}
{"time":1701245691,"time_ms":1701245691651,"channel":"futures.order_book_update","event":"update","result":{"U":53095244559,"a":[],"b":[{"p":"38142.7","s":2},{"p":"38137.4","s":0},{"p":"38137.8","s":0},{"p":"38137.3","s":0},{"p":"38145.3","s":2},{"p":"38144.5","s":2},{"p":"38143.8","s":395}],"s":"BTC_USDT","t":1701245691643,"u":53095244562}}
{"time":1701245691,"time_ms":1701245691713,"channel":"futures.order_book_update","event":"update","result":{"U":53095244563,"a":[],"b":[{"p":"38142.7","s":0},{"p":"38138","s":100},{"p":"38137.8","s":15208},{"p":"38139","s":100},{"p":"38144","s":0}],"s":"BTC_USDT","t":1701245691701,"u":53095244565}}
{"time":1701245691,"time_ms":1701245691733,"channel":"futures.order_book_update","event":"update","result":{"U":53095244566,"a":[],"b":[{"p":"38145.2","s":3859},{"p":"38142.5","s":2},{"p":"38144.4","s":2},{"p":"38145.3","s":0},{"p":"38143.8","s":393},{"p":"38143.7","s":657},{"p":"38144.5","s":0},{"p":"38137.4","s":0},{"p":"38137.3","s":0}],"s":"BTC_USDT","t":1701245691724,"u":53095244572}}
{"time":1701245691,"time_ms":1701245691753,"channel":"futures.order_book_update","event":"update","result":{"U":53095244573,"a":[],"b":[{"p":"38137.6","s":0}],"s":"BTC_USDT","t":1701245691729,"u":53095244573}}
{"time":1701245691,"time_ms":1701245691812,"channel":"futures.order_book_update","event":"update","result":{"U":53095244574,"a":[],"b":[{"p":"38137.8","s":15208},{"p":"38144","s":100},{"p":"38139","s":0}],"s":"BTC_USDT","t":1701245691791,"u":53095244575}}
{"time":1701245691,"time_ms":1701245691852,"channel":"futures.order_book_update","event":"update","result":{"U":53095244576,"a":[],"b":[{"p":"38135.9","s":0}],"s":"BTC_USDT","t":1701245691830,"u":53095244576}}
{"time":1701245691,"time_ms":1701245691891,"channel":"futures.order_book_update","event":"update","result":{"U":53095244577,"a":[{"p":"38151.9","s":0}],"b":[{"p":"38137.6","s":1315},{"p":"38143.7","s":655},{"p":"38145.2","s":3857},{"p":"38137.4","s":1315},{"p":"38144.4","s":0},{"p":"38142.5","s":0},{"p":"38131.5","s":0}],"s":"BTC_USDT","t":1701245691872,"u":53095244585}}
{"time":1701245691,"time_ms":1701245691912,"channel":"futures.order_book_update","event":"update","result":{"U":53095244586,"a":[],"b":[{"p":"38137.6","s":0},{"p":"38138","s":0},{"p":"38137.8","s":0},{"p":"38137.4","s":0},{"p":"38142.3","s":2},{"p":"38143.5","s":2},{"p":"38145","s":2},{"p":"38144.3","s":2}],"s":"BTC_USDT","t":1701245691905,"u":53095244591}}
{"time":1701245692,"time_ms":1701245692013,"channel":"futures.order_book_update","event":"update","result":{"U":53095244592,"a":[],"b":[{"p":"38139","s":100},{"p":"38144","s":0},{"p":"38138","s":0}],"s":"BTC_USDT","t":1701245691991,"u":53095244597}}
{"time":1701245692,"time_ms":1701245692032,"channel":"futures.order_book_update","event":"update","result":{"U":53095244598,"a":[{"p":"38152.1","s":0},{"p":"38159.9","s":0}],"b":[{"p":"38137","s":0}],"s":"BTC_USDT","t":1701245692010,"u":53095244605}}
{"time":1701245692,"time_ms":1701245692052,"channel":"futures.order_book_update","event":"update","result":{"U":53095244606,"a":[{"p":"38155.7","s":0},{"p":"38153","s":0}],"b":[{"p":"38136.1","s":0},{"p":"38137.2","s":0}],"s":"BTC_USDT","t":1701245692038,"u":53095244614}}
{"time":1701245692,"time_ms":1701245692091,"channel":"futures.order_book_update","event":"update","result":{"U":53095244615,"a":[],"b":[{"p":"38136.2","s":0}],"s":"BTC_USDT","t":1701245692080,"u":53095244616}}
{"time":1701245692,"time_ms":1701245692272,"channel":"futures.order_book_update","event":"update","result":{"U":53095244617,"a":[],"b":[{"p":"38145.6","s":71935}],"s":"BTC_USDT","t":1701245692255,"u":53095244618}}
{"time":1701245692,"time_ms":1701245692296,"channel":"futures.order_book_update","event":"update","result":{"U":53095244619,"a":[],"b":[{"p":"38137.1","s":0},{"p":"38137.4","s":0}],"s":"BTC_USDT","t":1701245692283,"u":53095244622}}
{"time":1701245692,"time_ms":1701245692332,"channel":"futures.order_book_update","event":"update","result":{"U":53095244623,"a":[{"p":"38151.9","s":0}],"b":[{"p":"38129.5","s":0}],"s":"BTC_USDT","t":1701245692321,"u":53095244624}}
{"time":1701245692,"time_ms":1701245692352,"channel":"futures.order_book_update","event":"update","result":{"U":53095244625,"a":[{"p":"38151.9","s":0},{"p":"38159.5","s":0},{"p":"38156.2","s":0},{"p":"38152.3","s":0},{"p":"38152.4","s":0}],"b":[{"p":"38132.5","s":0},{"p":"38135.9","s":0},{"p":"38137","s":0}],"s":"BTC_USDT","t":1701245692342,"u":53095244642}}
{"time":1701245692,"time_ms":1701245692374,"channel":"futures.order_book_update","event":"update","result":{"U":53095244643,"a":[{"p":"38152.7","s":0}],"b":[{"p":"38137.3","s":0}],"s":"BTC_USDT","t":1701245692348,"u":53095244646}}
{"time":1701245692,"time_ms":1701245692394,"channel":"futures.order_book_update","event":"update","result":{"U":53095244647,"a":[{"p":"38152.2","s":0},{"p":"38152.6","s":0},{"p":"38152.1","s":0},{"p":"38153","s":0},{"p":"38152","s":0}],"b":[{"p":"38132.7","s":0},{"p":"38137.2","s":0},{"p":"38137.7","s":0}],"s":"BTC_USDT","t":1701245692388,"u":53095244661}}
{"time":1701245692,"time_ms":1701245692413,"channel":"futures.order_book_update","event":"update","result":{"U":53095244662,"a":[{"p":"38145.7","s":142169},{"p":"38152.4","s":0},{"p":"38153.3","s":0},{"p":"38159.9","s":0},{"p":"38153.5","s":0},{"p":"38152.5","s":0},{"p":"38156.8","s":0},{"p":"38156.4","s":0}],"b":[{"p":"38138.2","s":3046},{"p":"38143.7","s":0},{"p":"38138.1","s":0},{"p":"38133.2","s":0},{"p":"38133.3","s":0},{"p":"38137.3","s":0},{"p":"38144.4","s":655},{"p":"38129.4","s":0},{"p":"38137.5","s":0},{"p":"38136.5","s":0}],"s":"BTC_USDT","t":1701245692404,"u":53095244693}}
{"time":1701245692,"time_ms":1701245692431,"channel":"futures.order_book_update","event":"update","result":{"U":53095244694,"a":[{"p":"38152.9","s":0},{"p":"38153.9","s":0}],"b":[{"p":"38143.8","s":0},{"p":"38138.1","s":0},{"p":"38144.5","s":395}],"s":"BTC_USDT","t":1701245692423,"u":53095244699}}
{"time":1701245692,"time_ms":1701245692451,"channel":"futures.order_book_update","event":"update","result":{"U":53095244700,"a":[{"p":"38153.1","s":0}],"b":[{"p":"38136.4","s":0}],"s":"BTC_USDT","t":1701245692430,"u":53095244704}}
{"time":1701245692,"time_ms":1701245692492,"channel":"futures.order_book_update","event":"update","result":{"U":53095244705,"a":[{"p":"38155.7","s":0}],"b":[{"p":"38137.3","s":0}],"s":"BTC_USDT","t":1701245692480,"u":53095244708}}
{"time":1701245692,"time_ms":1701245692531,"channel":"futures.order_book_update","event":"update","result":{"U":53095244709,"a":[{"p":"38145.7","s":130067}],"b":[],"s":"BTC_USDT","t":1701245692524,"u":53095244712}}
{"time":1701245692,"time_ms":1701245692551,"channel":"futures.order_book_update","event":"update","result":{"U":53095244713,"a":[{"p":"38145.7","s":100398},{"p":"38146.6","s":15000}],"b":[{"p":"38138.2","s":4361}],"s":"BTC_USDT","t":1701245692543,"u":53095244716}}
{"time":1701245692,"time_ms":1701245692591,"channel":"futures.order_book_update","event":"update","result":{"U":53095244717,"a":[{"p":"38157.5","s":0},{"p":"38153.5","s":0},{"p":"38145.7","s":100398},{"p":"38155.2","s":0},{"p":"38154.5","s":0},{"p":"38153.9","s":0},{"p":"38155.4","s":0}],"b":[{"p":"38137.5","s":0},{"p":"38145.6","s":71935},{"p":"38134.1","s":0}],"s":"BTC_USDT","t":1701245692582,"u":53095244737}}
{"time":1701245692,"time_ms":1701245692612,"channel":"futures.order_book_update","event":"update","result":{"U":53095244738,"a":[{"p":"38152","s":0},{"p":"38152.7","s":0},{"p":"38156.3","s":0},{"p":"38152.9","s":0}],"b":[{"p":"38144","s":100},{"p":"38139","s":0},{"p":"38138.2","s":4361}],"s":"BTC_USDT","t":1701245692597,"u":53095244746}}
{"time":1701245692,"time_ms":1701245692652,"channel":"futures.order_book_update","event":"update","result":{"U":53095244747,"a":[{"p":"38153","s":0}],"b":[{"p":"38136.6","s":0},{"p":"38128.6","s":0}],"s":"BTC_USDT","t":1701245692644,"u":53095244751}}
{"time":1701245692,"time_ms":1701245692791,"channel":"futures.order_book_update","event":"update","result":{"U":53095244752,"a":[],"b":[{"p":"38143.5","s":0},{"p":"38144.3","s":0},{"p":"38142.3","s":0},{"p":"38138.1","s":9126},{"p":"38138","s":1415},{"p":"38137.7","s":2175},{"p":"38137.8","s":16523},{"p":"38145","s":0}],"s":"BTC_USDT","t":1701245692770,"u":53095244757}}
{"time":1701245692,"time_ms":1701245692813,"channel":"futures.order_book_update","event":"update","result":{"U":53095244758,"a":[],"b":[{"p":"38138","s":0},{"p":"38144.8","s":2},{"p":"38144","s":202},{"p":"38143.2","s":2},{"p":"38142.1","s":2},{"p":"38137.7","s":0},{"p":"38137.8","s":0}],"s":"BTC_USDT","t":1701245692792,"u":53095244763}}
{"time":1701245693,"time_ms":1701245693032,"channel":"futures.order_book_update","event":"update","result":{"U":53095244764,"a":[{"p":"38160.5","s":0},{"p":"38153.8","s":0},{"p":"38157.5","s":0},{"p":"38152.8","s":0}],"b":[{"p":"38138.2","s":0},{"p":"38138.1","s":0},{"p":"38136.8","s":0},{"p":"38137.7","s":0},{"p":"38133.3","s":0},{"p":"38139","s":733},{"p":"38138.3","s":4526}],"s":"BTC_USDT","t":1701245693022,"u":53095244796}}
{"time":1701245693,"time_ms":1701245693091,"channel":"futures.order_book_update","event":"update","result":{"U":53095244797,"a":[],"b":[{"p":"38145.6","s":72435}],"s":"BTC_USDT","t":1701245693078,"u":53095244798}}
{"time":1701245693,"time_ms":1701245693113,"channel":"futures.order_book_update","event":"update","result":{"U":53095244799,"a":[{"p":"38154.8","s":0}],"b":[{"p":"38144","s":102}],"s":"BTC_USDT","t":1701245693097,"u":53095244802}}
{"time":1701245693,"time_ms":1701245693192,"channel":"futures.order_book_update","event":"update","result":{"U":53095244803,"a":[{"p":"38154","s":0}],"b":[],"s":"BTC_USDT","t":1701245693183,"u":53095244804}}
{"time":1701245693,"time_ms":1701245693213,"channel":"futures.order_book_update","event":"update","result":{"U":53095244805,"a":[],"b":[{"p":"38142.1","s":0},{"p":"38143.2","s":0},{"p":"38138.1","s":9126},{"p":"38138.2","s":1315},{"p":"38138","s":1415},{"p":"38144","s":100},{"p":"38144.8","s":0}],"s":"BTC_USDT","t":1701245693197,"u":53095244808}}
{"time":1701245693,"time_ms":1701245693311,"channel":"futures.order_book_update","event":"update","result":{"U":53095244809,"a":[],"b":[{"p":"38138.2","s":0},{"p":"38144.6","s":2},{"p":"38143.9","s":2},{"p":"38143.1","s":2},{"p":"38138.3","s":0},{"p":"38144","s":200},{"p":"38141.9","s":2},{"p":"38138.1","s":0},{"p":"38138","s":0}],"s":"BTC_USDT","t":1701245693293,"u":53095244814}}
{"time":1701245693,"time_ms":1701245693352,"channel":"futures.order_book_update","event":"update","result":{"U":53095244815,"a":[{"p":"38146.5","s":200},{"p":"38150.9","s":0}],"b":[],"s":"BTC_USDT","t":1701245693339,"u":53095244817}}
{"time":1701245693,"time_ms":1701245693413,"channel":"futures.order_book_update","event":"update","result":{"U":53095244818,"a":[],"b":[{"p":"38144","s":100}],"s":"BTC_USDT","t":1701245693393,"u":53095244819}}
{"time":1701245693,"time_ms":1701245693432,"channel":"futures.order_book_update","event":"update","result":{"U":53095244820,"a":[{"p":"38153.9","s":0},{"p":"38165","s":0},{"p":"38154.2","s":0},{"p":"38153","s":0},{"p":"38155.2","s":0},{"p":"38160.9","s":0},{"p":"38154","s":0},{"p":"38157.6","s":0},{"p":"38145.7","s":100398},{"p":"38158","s":0}],"b":[{"p":"38125.7","s":0},{"p":"38137.6","s":0},{"p":"38137.9","s":0},{"p":"38134.2","s":0},{"p":"38134.1","s":0},{"p":"38139","s":2908},{"p":"38138.3","s":0}],"s":"BTC_USDT","t":1701245693411,"u":53095244849}}
{"time":1701245693,"time_ms":1701245693451,"channel":"futures.order_book_update","event":"update","result":{"U":53095244850,"a":[{"p":"38154.2","s":0}],"b":[{"p":"38138.4","s":0}],"s":"BTC_USDT","t":1701245693441,"u":53095244852}}
{"time":1701245693,"time_ms":1701245693493,"channel":"futures.order_book_update","event":"update","result":{"U":53095244853,"a":[{"p":"38153.9","s":0}],"b":[],"s":"BTC_USDT","t":1701245693482,"u":53095244854}}
{"time":1701245693,"time_ms":1701245693533,"channel":"futures.order_book_update","event":"update","result":{"U":53095244855,"a":[{"p":"38174.9","s":0}],"b":[],"s":"BTC_USDT","t":1701245693516,"u":53095244858}}
{"time":1701245693,"time_ms":1701245693551,"channel":"futures.order_book_update","event":"update","result":{"U":53095244859,"a":[],"b":[{"p":"38136.8","s":0}],"s":"BTC_USDT","t":1701245693532,"u":53095244860}}
{"time":1701245693,"time_ms":1701245693574,"channel":"futures.order_book_update","event":"update","result":{"U":53095244861,"a":[{"p":"38155.5","s":0}],"b":[],"s":"BTC_USDT","t":1701245693563,"u":53095244861}}
{"time":1701245693,"time_ms":1701245693652,"channel":"futures.order_book_update","event":"update","result":{"U":53095244862,"a":[{"p":"38155.2","s":0}],"b":[],"s":"BTC_USDT","t":1701245693634,"u":53095244865}}
{"time":1701245693,"time_ms":1701245693733,"channel":"futures.order_book_update","event":"update","result":{"U":53095244866,"a":[{"p":"38154.5","s":0},{"p":"38152.7","s":0},{"p":"38153.3","s":0},{"p":"38153.4","s":0},{"p":"38145.7","s":100398},{"p":"38153","s":0},{"p":"38155.3","s":0},{"p":"38153.5","s":0}],"b":[{"p":"38134.9","s":0},{"p":"38137.3","s":0},{"p":"38139","s":733},{"p":"38138.3","s":0},{"p":"38134.7","s":0}],"s":"BTC_USDT","t":1701245693724,"u":53095244892}}
{"time":1701245693,"time_ms":1701245693798,"channel":"futures.order_book_update","event":"update","result":{"U":53095244893,"a":[{"p":"38145.7","s":99806},{"p":"38182.8","s":0},{"p":"38159","s":0}],"b":[{"p":"38145.6","s":97435},{"p":"38144","s":200},{"p":"38138","s":0}],"s":"BTC_USDT","t":1701245693786,"u":53095244902}}
{"time":1701245693,"time_ms":1701245693814,"channel":"futures.order_book_update","event":"update","result":{"U":53095244903,"a":[{"p":"38145.7","s":96965},{"p":"38164","s":0}],"b":[{"p":"38138.5","s":733},{"p":"38139","s":0},{"p":"38137.9","s":0},{"p":"38138.4","s":0},{"p":"38144","s":100}],"s":"BTC_USDT","t":1701245693805,"u":53095244911}}
{"time":1701245693,"time_ms":1701245693832,"channel":"futures.order_book_update","event":"update","result":{"U":53095244912,"a":[{"p":"38145.7","s":94565}],"b":[{"p":"38145.6","s":72435}],"s":"BTC_USDT","t":1701245693816,"u":53095244913}}
{"time":1701245693,"time_ms":1701245693852,"channel":"futures.order_book_update","event":"update","result":{"U":53095244914,"a":[],"b":[{"p":"38139.1","s":733},{"p":"38138.5","s":0},{"p":"38138.4","s":0}],"s":"BTC_USDT","t":1701245693840,"u":53095244915}}
{"time":1701245693,"time_ms":1701245693872,"channel":"futures.order_book_update","event":"update","result":{"U":53095244916,"a":[],"b":[{"p":"38143.9","s":0},{"p":"38143.1","s":0},{"p":"38144.6","s":0},{"p":"38138.4","s":1315},{"p":"38138.2","s":1315},{"p":"38138.1","s":9126},{"p":"38138.3","s":4526},{"p":"38141.9","s":0}],"s":"BTC_USDT","t":1701245693864,"u":53095244919}}
{"time":1701245693,"time_ms":1701245693893,"channel":"futures.order_book_update","event":"update","result":{"U":53095244920,"a":[],"b":[{"p":"38143","s":2},{"p":"38141.8","s":9024},{"p":"38144","s":200},{"p":"38143.7","s":2},{"p":"38138.2","s":0},{"p":"38138.1","s":0},{"p":"38138","s":0},{"p":"38144.5","s":397}],"s":"BTC_USDT","t":1701245693886,"u":53095244925}}
{"time":1701245693,"time_ms":1701245693932,"channel":"futures.order_book_update","event":"update","result":{"U":53095244926,"a":[{"p":"38145.7","s":94465}],"b":[],"s":"BTC_USDT","t":1701245693919,"u":53095244926}}
{"time":1701245694,"time_ms":1701245694033,"channel":"futures.order_book_update","event":"update","result":{"U":53095244927,"a":[{"p":"38154.5","s":0},{"p":"38153.3","s":0},{"p":"38157.9","s":0},{"p":"38153.5","s":0},{"p":"38161.3","s":0}],"b":[{"p":"38138.5","s":4501},{"p":"38139","s":733},{"p":"38139.1","s":0},{"p":"38138.3","s":0},{"p":"38138.2","s":0},{"p":"38137.5","s":0}],"s":"BTC_USDT","t":1701245694017,"u":53095244946}}
{"time":1701245694,"time_ms":1701245694091,"channel":"futures.order_book_update","event":"update","result":{"U":53095244947,"a":[{"p":"38153.2","s":0}],"b":[{"p":"38138.5","s":2326},{"p":"38138.6","s":2175},{"p":"38138.4","s":0}],"s":"BTC_USDT","t":1701245694080,"u":53095244950}}
{"time":1701245694,"time_ms":1701245694131,"channel":"futures.order_book_update","event":"update","result":{"U":53095244951,"a":[{"p":"38154.1","s":0}],"b":[],"s":"BTC_USDT","t":1701245694123,"u":53095244952}}
{"time":1701245694,"time_ms":1701245694292,"channel":"futures.order_book_update","event":"update","result":{"U":53095244953,"a":[],"b":[{"p":"38122.4","s":0}],"s":"BTC_USDT","t":1701245694273,"u":53095244953}}
{"time":1701245694,"time_ms":1701245694313,"channel":"futures.order_book_update","event":"update","result":{"U":53095244954,"a":[],"b":[{"p":"38138","s":0}],"s":"BTC_USDT","t":1701245694291,"u":53095244956}}
{"time":1701245694,"time_ms":1701245694334,"channel":"futures.order_book_update","event":"update","result":{"U":53095244957,"a":[],"b":[{"p":"38143","s":0},{"p":"38143.7","s":0},{"p":"38137.9","s":0},{"p":"38138.2","s":1315},{"p":"38141.8","s":9022},{"p":"38138.4","s":1315},{"p":"38144.5","s":395}],"s":"BTC_USDT","t":1701245694324,"u":53095244962}}
{"time":1701245694,"time_ms":1701245694354,"channel":"futures.order_book_update","event":"update","result":{"U":53095244963,"a":[],"b":[{"p":"38144.5","s":397},{"p":"38143.7","s":2},{"p":"38143","s":2},{"p":"38138.2","s":0},{"p":"38138.4","s":0},{"p":"38137.7","s":0}],"s":"BTC_USDT","t":1701245694336,"u":53095244967}}
{"time":1701245694,"time_ms":1701245694372,"channel":"futures.order_book_update","event":"update","result":{"U":53095244968,"a":[],"b":[{"p":"38141.8","s":9024}],"s":"BTC_USDT","t":1701245694348,"u":53095244968}}
{"time":1701245694,"time_ms":1701245694492,"channel":"futures.order_book_update","event":"update","result":{"U":53095244969,"a":[],"b":[{"p":"38137.9","s":0}],"s":"BTC_USDT","t":1701245694470,"u":53095244970}}
{"time":1701245694,"time_ms":1701245694672,"channel":"futures.order_book_update","event":"update","result":{"U":53095244971,"a":[{"p":"38150","s":61060},{"p":"38157.6","s":0}],"b":[{"p":"38144.5","s":395},{"p":"38139","s":0},{"p":"38143","s":0},{"p":"38137.7","s":0},{"p":"38143.7","s":0},{"p":"38121.6","s":0},{"p":"38138.4","s":1315},{"p":"38138.2","s":1315},{"p":"38138.7","s":733},{"p":"38141.8","s":9022}],"s":"BTC_USDT","t":1701245694665,"u":53095244982}}
{"time":1701245694,"time_ms":1701245694693,"channel":"futures.order_book_update","event":"update","result":{"U":53095244983,"a":[],"b":[{"p":"38145.2","s":3859},{"p":"38138.2","s":0},{"p":"38143.3","s":2},{"p":"38145.6","s":72437}],"s":"BTC_USDT","t":1701245694679,"u":53095244988}}
{"time":1701245694,"time_ms":1701245694712,"channel":"futures.order_book_update","event":"update","result":{"U":53095244989,"a":[],"b":[{"p":"38138.6","s":0},{"p":"38144.4","s":657},{"p":"38138.8","s":2318},{"p":"38138.2","s":1315}],"s":"BTC_USDT","t":1701245694692,"u":53095244991}}
{"time":1701245694,"time_ms":1701245694792,"channel":"futures.order_book_update","event":"update","result":{"U":53095244992,"a":[{"p":"38157.2","s":0}],"b":[],"s":"BTC_USDT","t":1701245694775,"u":53095244993}}
{"time":1701245695,"time_ms":1701245695012,"channel":"futures.order_book_update","event":"update","result":{"U":53095244994,"a":[{"p":"38153.5","s":0}],"b":[],"s":"BTC_USDT","t":1701245695004,"u":53095244997}}
{"time":1701245695,"time_ms":1701245695033,"channel":"futures.order_book_update","event":"update","result":{"U":53095244998,"a":[{"p":"38153","s":0},{"p":"38153.1","s":0},{"p":"38153.9","s":0}],"b":[{"p":"38138.1","s":0},{"p":"38137.5","s":0},{"p":"38139","s":2908},{"p":"38138.8","s":143},{"p":"38138.7","s":0}],"s":"BTC_USDT","t":1701245695014,"u":53095245009}}
{"time":1701245695,"time_ms":1701245695051,"channel":"futures.order_book_update","event":"update","result":{"U":53095245010,"a":[{"p":"38153.4","s":0},{"p":"38153.9","s":0},{"p":"38157.5","s":0}],"b":[{"p":"38143.3","s":0},{"p":"38138.5","s":0},{"p":"38138.2","s":1315},{"p":"38144.4","s":655},{"p":"38139","s":0},{"p":"38145.6","s":72435},{"p":"38138.3","s":2323},{"p":"38138.1","s":9152},{"p":"38145.2","s":3857},{"p":"38137.7","s":0},{"p":"38138.8","s":876},{"p":"38138.6","s":2175}],"s":"BTC_USDT","t":1701245695041,"u":53095245027}}
{"time":1701245695,"time_ms":1701245695075,"channel":"futures.order_book_update","event":"update","result":{"U":53095245028,"a":[],"b":[{"p":"38143","s":0},{"p":"38141.8","s":9024},{"p":"38143.7","s":2},{"p":"38139","s":733},{"p":"38138.8","s":143},{"p":"38138.1","s":0},{"p":"38138.2","s":0},{"p":"38137.6","s":0},{"p":"38144.5","s":397}],"s":"BTC_USDT","t":1701245695067,"u":53095245036}}
{"time":1701245695,"time_ms":1701245695090,"channel":"futures.order_book_update","event":"update","result":{"U":53095245037,"a":[{"p":"38153.8","s":0}],"b":[],"s":"BTC_USDT","t":1701245695083,"u":53095245038}}
{"time":1701245695,"time_ms":1701245695112,"channel":"futures.order_book_update","event":"update","result":{"U":53095245039,"a":[],"b":[{"p":"38138.3","s":0},{"p":"38141.2","s":2}],"s":"BTC_USDT","t":1701245695093,"u":53095245039}}
{"time":1701245695,"time_ms":1701245695151,"channel":"futures.order_book_update","event":"update","result":{"U":53095245040,"a":[],"b":[{"p":"38138.3","s":2323},{"p":"38144.5","s":395},{"p":"38141.8","s":9022},{"p":"38143.7","s":0},{"p":"38141.2","s":0},{"p":"38135.8","s":0},{"p":"38138.2","s":1315}],"s":"BTC_USDT","t":1701245695126,"u":53095245046}}
{"time":1701245695,"time_ms":1701245695172,"channel":"futures.order_book_update","event":"update","result":{"U":53095245047,"a":[{"p":"38157.1","s":0}],"b":[{"p":"38138.6","s":0},{"p":"38138.4","s":0},{"p":"38138.3","s":0},{"p":"38142.7","s":2},{"p":"38141.2","s":2},{"p":"38140","s":2},{"p":"38141.9","s":2},{"p":"38138.2","s":0}],"s":"BTC_USDT","t":1701245695156,"u":53095245052}}
{"time":1701245695,"time_ms":1701245695192,"channel":"futures.order_book_update","event":"update","result":{"U":53095245053,"a":[{"p":"38155.2","s":0}],"b":[],"s":"BTC_USDT","t":1701245695177,"u":53095245054}}
{"time":1701245695,"time_ms":1701245695213,"channel":"futures.order_book_update","event":"update","result":{"U":53095245055,"a":[{"p":"38160.9","s":0},{"p":"38154.2","s":0},{"p":"38153.8","s":0},{"p":"38152.8","s":0},{"p":"38157.5","s":0},{"p":"38159.3","s":0},{"p":"38153.9","s":0},{"p":"38145.7","s":105755},{"p":"38153","s":0},{"p":"38154","s":0},{"p":"38153.3","s":0},{"p":"38165.5","s":0}],"b":[{"p":"38141.9","s":0},{"p":"38145.4","s":2},{"p":"38144.6","s":2},{"p":"38139","s":3037},{"p":"38139.1","s":2175},{"p":"38143.9","s":2},{"p":"38141.2","s":0},{"p":"38142.7","s":2},{"p":"38137.7","s":0},{"p":"38134.1","s":0},{"p":"38138.8","s":0},{"p":"38140","s":0},{"p":"38138.6","s":0},{"p":"38138.3","s":0}],"s":"BTC_USDT","t":1701245695206,"u":53095245092}}
{"time":1701245695,"time_ms":1701245695231,"channel":"futures.order_book_update","event":"update","result":{"U":53095245093,"a":[{"p":"38158","s":0}],"b":[{"p":"38139.7","s":733},{"p":"38139","s":2304},{"p":"38138.9","s":0}],"s":"BTC_USDT","t":1701245695207,"u":53095245095}}
{"time":1701245695,"time_ms":1701245695251,"channel":"futures.order_book_update","event":"update","result":{"U":53095245096,"a":[],"b":[{"p":"38129.6","s":0}],"s":"BTC_USDT","t":1701245695241,"u":53095245097}}
{"time":1701245695,"time_ms":1701245695272,"channel":"futures.order_book_update","event":"update","result":{"U":53095245098,"a":[{"p":"38145.7","s":98655}],"b":[{"p":"38139.1","s":2908},{"p":"38138.9","s":7234},{"p":"38139.7","s":0},{"p":"38032.4","s":0}],"s":"BTC_USDT","t":1701245695261,"u":53095245101}}
{"time":1701245695,"time_ms":1701245695291,"channel":"futures.order_book_update","event":"update","result":{"U":53095245102,"a":[{"p":"38153.7","s":0}],"b":[{"p":"38139","s":0},{"p":"38138.3","s":0},{"p":"38134.7","s":0},{"p":"38138.8","s":143},{"p":"38139.1","s":733}],"s":"BTC_USDT","t":1701245695278,"u":53095245112}}
{"time":1701245695,"time_ms":1701245695312,"channel":"futures.order_book_update","event":"update","result":{"U":53095245113,"a":[{"p":"38154.5","s":0}],"b":[{"p":"38144","s":100},{"p":"38137.9","s":0}],"s":"BTC_USDT","t":1701245695303,"u":53095245119}}
{"time":1701245695,"time_ms":1701245695331,"channel":"futures.order_book_update","event":"update","result":{"U":53095245120,"a":[],"b":[{"p":"38138.4","s":1315},{"p":"38138.2","s":1315},{"p":"38138.5","s":2308},{"p":"38143.9","s":0},{"p":"38145.4","s":0},{"p":"38142.7","s":0},{"p":"38144.6","s":0},{"p":"38138.7","s":2175}],"s":"BTC_USDT","t":1701245695318,"u":53095245127}}
{"time":1701245695,"time_ms":1701245695351,"channel":"futures.order_book_update","event":"update","result":{"U":53095245128,"a":[],"b":[{"p":"38138.5","s":0},{"p":"38138.4","s":0},{"p":"38138.2","s":0},{"p":"38145.3","s":2},{"p":"38144.6","s":2},{"p":"38143.4","s":2},{"p":"38145.6","s":72437}],"s":"BTC_USDT","t":1701245695340,"u":53095245131}}
{"time":1701245695,"time_ms":1701245695373,"channel":"futures.order_book_update","event":"update","result":{"U":53095245132,"a":[{"p":"38171","s":0},{"p":"38157.9","s":0}],"b":[],"s":"BTC_USDT","t":1701245695348,"u":53095245135}}
{"time":1701245695,"time_ms":1701245695393,"channel":"futures.order_book_update","event":"update","result":{"U":53095245136,"a":[{"p":"38156.1","s":0}],"b":[{"p":"38144","s":200},{"p":"38138","s":0},{"p":"38029.1","s":0},{"p":"38040.8","s":0}],"s":"BTC_USDT","t":1701245695383,"u":53095245140}}
{"time":1701245695,"time_ms":1701245695413,"channel":"futures.order_book_update","event":"update","result":{"U":53095245141,"a":[{"p":"38156.8","s":0},{"p":"38153.8","s":0},{"p":"38153.7","s":0}],"b":[{"p":"38051.2","s":0},{"p":"38046","s":0}],"s":"BTC_USDT","t":1701245695394,"u":53095245148}}
{"time":1701245695,"time_ms":1701245695432,"channel":"futures.order_book_update","event":"update","result":{"U":53095245149,"a":[{"p":"38152.9","s":0}],"b":[{"p":"38049.8","s":0},{"p":"38044.9","s":0}],"s":"BTC_USDT","t":1701245695422,"u":53095245161}}
{"time":1701245695,"time_ms":1701245695454,"channel":"futures.order_book_update","event":"update","result":{"U":53095245162,"a":[],"b":[{"p":"38054.2","s":0},{"p":"38052","s":0}],"s":"BTC_USDT","t":1701245695430,"u":53095245163}}
{"time":1701245695,"time_ms":1701245695491,"channel":"futures.order_book_update","event":"update","result":{"U":53095245164,"a":[],"b":[{"p":"38138.1","s":0}],"s":"BTC_USDT","t":1701245695474,"u":53095245165}}
{"time":1701245695,"time_ms":1701245695534,"channel":"futures.order_book_update","event":"update","result":{"U":53095245166,"a":[{"p":"38145.7","s":87365},{"p":"38156.8","s":0}],"b":[{"p":"38138.3","s":26},{"p":"38145.2","s":4512},{"p":"38138.4","s":1315},{"p":"38145.3","s":0},{"p":"38145.6","s":72435},{"p":"38138.5","s":2308},{"p":"38138.2","s":1315},{"p":"38144.6","s":0},{"p":"38143.4","s":0},{"p":"38144.4","s":0},{"p":"38134.9","s":0}],"s":"BTC_USDT","t":1701245695519,"u":53095245175}}
{"time":1701245695,"time_ms":1701245695550,"channel":"futures.order_book_update","event":"update","result":{"U":53095245176,"a":[],"b":[{"p":"38145.3","s":2},{"p":"38138.2","s":0},{"p":"38144.5","s":0},{"p":"38138.3","s":0},{"p":"38138.1","s":0},{"p":"38145.6","s":100087},{"p":"38144.6","s":2},{"p":"38138.6","s":1315}],"s":"BTC_USDT","t":1701245695542,"u":53095245183}}
{"time":1701245695,"time_ms":1701245695572,"channel":"futures.order_book_update","event":"update","result":{"U":53095245184,"a":[],"b":[{"p":"38143.4","s":2},{"p":"38138.4","s":0}],"s":"BTC_USDT","t":1701245695548,"u":53095245184}}
{"time":1701245695,"time_ms":1701245695593,"channel":"futures.order_book_update","event":"update","result":{"U":53095245185,"a":[{"p":"38153.5","s":0}],"b":[],"s":"BTC_USDT","t":1701245695575,"u":53095245186}}
{"time":1701245695,"time_ms":1701245695631,"channel":"futures.order_book_update","event":"update","result":{"U":53095245187,"a":[],"b":[{"p":"38128.2","s":0}],"s":"BTC_USDT","t":1701245695616,"u":53095245189}}
{"time":1701245695,"time_ms":1701245695653,"channel":"futures.order_book_update","event":"update","result":{"U":53095245190,"a":[],"b":[{"p":"38137","s":0}],"s":"BTC_USDT","t":1701245695639,"u":53095245191}}
{"time":1701245695,"time_ms":1701245695672,"channel":"futures.order_book_update","event":"update","result":{"U":53095245192,"a":[{"p":"38154.2","s":0},{"p":"38157.5","s":0}],"b":[],"s":"BTC_USDT","t":1701245695655,"u":53095245195}}
{"time":1701245695,"time_ms":1701245695692,"channel":"futures.order_book_update","event":"update","result":{"U":53095245196,"a":[{"p":"38156.8","s":0}],"b":[{"p":"38145.6","s":100587}],"s":"BTC_USDT","t":1701245695675,"u":53095245197}}
{"time":1701245695,"time_ms":1701245695753,"channel":"futures.order_book_update","event":"update","result":{"U":53095245198,"a":[],"b":[{"p":"38138.8","s":1458},{"p":"38145.6","s":73087}],"s":"BTC_USDT","t":1701245695740,"u":53095245201}}
{"time":1701245695,"time_ms":1701245695772,"channel":"futures.order_book_update","event":"update","result":{"U":53095245202,"a":[],"b":[{"p":"38139.7","s":2175},{"p":"38138.8","s":3633},{"p":"38138.7","s":0},{"p":"38138.5","s":2308},{"p":"38134.2","s":0},{"p":"38137.5","s":0}],"s":"BTC_USDT","t":1701245695759,"u":53095245207}}
{"time":1701245695,"time_ms":1701245695794,"channel":"futures.order_book_update","event":"update","result":{"U":53095245208,"a":[],"b":[{"p":"38145.6","s":72587}],"s":"BTC_USDT","t":1701245695772,"u":53095245208}}
{"time":1701245695,"time_ms":1701245695853,"channel":"futures.order_book_update","event":"update","result":{"U":53095245209,"a":[],"b":[{"p":"38137.2","s":0}],"s":"BTC_USDT","t":1701245695843,"u":53095245210}}
{"time":1701245695,"time_ms":1701245695871,"channel":"futures.order_book_update","event":"update","result":{"U":53095245211,"a":[{"p":"38145.7","s":87365},{"p":"38155.3","s":0},{"p":"38158.5","s":0}],"b":[{"p":"38139.2","s":2175},{"p":"38138.5","s":0},{"p":"38135.2","s":0},{"p":"38138.4","s":0},{"p":"38145.2","s":3857},{"p":"38138.8","s":1458},{"p":"38145","s":655},{"p":"38139.7","s":0},{"p":"38135.6","s":0}],"s":"BTC_USDT","t":1701245695866,"u":53095245233}}
{"time":1701245695,"time_ms":1701245695893,"channel":"futures.order_book_update","event":"update","result":{"U":53095245234,"a":[{"p":"38157","s":0}],"b":[],"s":"BTC_USDT","t":1701245695869,"u":53095245235}}
{"time":1701245695,"time_ms":1701245695933,"channel":"futures.order_book_update","event":"update","result":{"U":53095245236,"a":[],"b":[{"p":"38138.5","s":0},{"p":"38134.7","s":0},{"p":"38138.3","s":0},{"p":"38138.7","s":2175},{"p":"38139.2","s":0}],"s":"BTC_USDT","t":1701245695915,"u":53095245241}}
{"time":1701245695,"time_ms":1701245695951,"channel":"futures.order_book_update","event":"update","result":{"U":53095245242,"a":[{"p":"38158","s":0},{"p":"38154","s":0}],"b":[],"s":"BTC_USDT","t":1701245695928,"u":53095245245}}
{"time":1701245696,"time_ms":1701245696011,"channel":"futures.order_book_update","event":"update","result":{"U":53095245246,"a":[],"b":[{"p":"38138.3","s":26},{"p":"38145.3","s":0},{"p":"38144.6","s":0},{"p":"38143.4","s":0},{"p":"38138.5","s":0},{"p":"38138.2","s":1315},{"p":"38145.6","s":73085},{"p":"38138.4","s":1315}],"s":"BTC_USDT","t":1701245696004,"u":53095245251}}
{"time":1701245696,"time_ms":1701245696034,"channel":"futures.order_book_update","event":"update","result":{"U":53095245252,"a":[{"p":"38154.7","s":0}],"b":[{"p":"38138.2","s":0},{"p":"38137.5","s":0},{"p":"38139.2","s":2175},{"p":"38138.6","s":3490},{"p":"38143.4","s":2},{"p":"38139","s":2310},{"p":"38138.7","s":0},{"p":"38138.3","s":0},{"p":"38134.1","s":0},{"p":"38130.6","s":0},{"p":"38145.6","s":73087}],"s":"BTC_USDT","t":1701245696027,"u":53095245266}}
{"time":1701245696,"time_ms":1701245696052,"channel":"futures.order_book_update","event":"update","result":{"U":53095245267,"a":[{"p":"38157.7","s":0}],"b":[{"p":"38139.7","s":733},{"p":"38139.1","s":0},{"p":"38138.4","s":0},{"p":"38145.3","s":2}],"s":"BTC_USDT","t":1701245696031,"u":53095245271}}
{"time":1701245696,"time_ms":1701245696072,"channel":"futures.order_book_update","event":"update","result":{"U":53095245272,"a":[],"b":[{"p":"38144.6","s":2},{"p":"38138.6","s":0}],"s":"BTC_USDT","t":1701245696047,"u":53095245272}}
{"time":1701245696,"time_ms":1701245696091,"channel":"futures.order_book_update","event":"update","result":{"U":53095245273,"a":[{"p":"38153.5","s":0},{"p":"38154.4","s":0},{"p":"38155.3","s":0},{"p":"38153.9","s":0},{"p":"38159.6","s":0},{"p":"38154.2","s":0},{"p":"38157.9","s":0},{"p":"38161.3","s":0}],"b":[{"p":"38138.8","s":1458},{"p":"38131.4","s":0},{"p":"38138.4","s":1315},{"p":"38141.1","s":394},{"p":"38138.6","s":4223},{"p":"38139.2","s":0},{"p":"38139.7","s":0},{"p":"38139","s":0},{"p":"38134.7","s":0}],"s":"BTC_USDT","t":1701245696083,"u":53095245299}}
{"time":1701245696,"time_ms":1701245696112,"channel":"futures.order_book_update","event":"update","result":{"U":53095245300,"a":[{"p":"38153.4","s":0},{"p":"38153","s":0},{"p":"38152.7","s":0},{"p":"38145.7","s":87365},{"p":"38156.8","s":0}],"b":[{"p":"38139","s":2175},{"p":"38139.2","s":733},{"p":"38138.6","s":0},{"p":"38138.4","s":0},{"p":"38137.5","s":0},{"p":"38145","s":655}],"s":"BTC_USDT","t":1701245696098,"u":53095245321}}
{"time":1701245696,"time_ms":1701245696131,"channel":"futures.order_book_update","event":"update","result":{"U":53095245322,"a":[{"p":"38153","s":0},{"p":"38153.8","s":0},{"p":"38153.4","s":0},{"p":"38158.7","s":0}],"b":[{"p":"38134.1","s":0}],"s":"BTC_USDT","t":1701245696116,"u":53095245330}}
{"time":1701245696,"time_ms":1701245696191,"channel":"futures.order_book_update","event":"update","result":{"U":53095245331,"a":[{"p":"38154.5","s":0},{"p":"38158.5","s":0}],"b":[],"s":"BTC_USDT","t":1701245696182,"u":53095245334}}
{"time":1701245696,"time_ms":1701245696273,"channel":"futures.order_book_update","event":"update","result":{"U":53095245335,"a":[{"p":"38156.8","s":0}],"b":[{"p":"38138.4","s":1315},{"p":"38145.6","s":73085},{"p":"38138.6","s":1315},{"p":"38138.3","s":4515},{"p":"38144.6","s":0},{"p":"38143.4","s":0},{"p":"38145.3","s":0},{"p":"38134.7","s":0}],"s":"BTC_USDT","t":1701245696265,"u":53095245342}}
{"time":1701245696,"time_ms":1701245696292,"channel":"futures.order_book_update","event":"update","result":{"U":53095245343,"a":[{"p":"38154.9","s":0},{"p":"38158.7","s":0}],"b":[{"p":"38141.9","s":2},{"p":"38140","s":2},{"p":"38138.3","s":0},{"p":"38138.4","s":0}],"s":"BTC_USDT","t":1701245696284,"u":53095245348}}
{"time":1701245696,"time_ms":1701245696310,"channel":"futures.order_book_update","event":"update","result":{"U":53095245349,"a":[],"b":[{"p":"38141.2","s":2},{"p":"38142.7","s":2},{"p":"38138.6","s":0},{"p":"38138.8","s":0}],"s":"BTC_USDT","t":1701245696286,"u":53095245350}}
{"time":1701245696,"time_ms":1701245696331,"channel":"futures.order_book_update","event":"update","result":{"U":53095245351,"a":[{"p":"38162.5","s":0},{"p":"38155","s":0},{"p":"38170.2","s":0},{"p":"38166.3","s":0},{"p":"38170.1","s":0}],"b":[{"p":"38138.3","s":0},{"p":"38128.7","s":0},{"p":"38120.1","s":0},{"p":"38124.9","s":0},{"p":"38121.1","s":0}],"s":"BTC_USDT","t":1701245696319,"u":53095245360}}
{"time":1701245696,"time_ms":1701245696352,"channel":"futures.order_book_update","event":"update","result":{"U":53095245361,"a":[],"b":[{"p":"38130.5","s":0}],"s":"BTC_USDT","t":1701245696337,"u":53095245363}}
{"time":1701245696,"time_ms":1701245696433,"channel":"futures.order_book_update","event":"update","result":{"U":53095245364,"a":[{"p":"38153.4","s":0}],"b":[],"s":"BTC_USDT","t":1701245696419,"u":53095245364}}
{"time":1701245696,"time_ms":1701245696512,"channel":"futures.order_book_update","event":"update","result":{"U":53095245365,"a":[{"p":"38145.7","s":87365},{"p":"38153.4","s":0},{"p":"38153.8","s":0},{"p":"38153.1","s":0},{"p":"38157.6","s":0},{"p":"38155.3","s":0},{"p":"38156.8","s":0},{"p":"38153.9","s":0},{"p":"38152.8","s":0}],"b":[{"p":"38138.6","s":1315},{"p":"38138.8","s":1458},{"p":"38139.2","s":0},{"p":"38139","s":0},{"p":"38138.3","s":0},{"p":"38138.5","s":0}],"s":"BTC_USDT","t":1701245696501,"u":53095245389}}
{"time":1701245696,"time_ms":1701245696532,"channel":"futures.order_book_update","event":"update","result":{"U":53095245390,"a":[],"b":[{"p":"38137.5","s":0}],"s":"BTC_USDT","t":1701245696513,"u":53095245391}}
{"time":1701245696,"time_ms":1701245696673,"channel":"futures.order_book_update","event":"update","result":{"U":53095245392,"a":[],"b":[{"p":"38142.7","s":0},{"p":"38140","s":0},{"p":"38141.9","s":0},{"p":"38141.2","s":0},{"p":"38138.3","s":4489},{"p":"38138.5","s":2908},{"p":"38138.4","s":1315},{"p":"38138.2","s":1315}],"s":"BTC_USDT","t":1701245696660,"u":53095245395}}
{"time":1701245696,"time_ms":1701245696693,"channel":"futures.order_book_update","event":"update","result":{"U":53095245396,"a":[],"b":[{"p":"38138.4","s":0},{"p":"38138.2","s":0},{"p":"38142.7","s":2},{"p":"38141.1","s":396},{"p":"38140","s":2},{"p":"38141.9","s":2},{"p":"38138.3","s":0}],"s":"BTC_USDT","t":1701245696678,"u":53095245399}}
{"time":1701245696,"time_ms":1701245696757,"channel":"futures.order_book_update","event":"update","result":{"U":53095245400,"a":[{"p":"38189.3","s":0}],"b":[],"s":"BTC_USDT","t":1701245696739,"u":53095245402}}
{"time":1701245696,"time_ms":1701245696792,"channel":"futures.order_book_update","event":"update","result":{"U":53095245403,"a":[],"b":[{"p":"38138.4","s":1315},{"p":"38145","s":0},{"p":"38135.4","s":0}],"s":"BTC_USDT","t":1701245696781,"u":53095245405}}
{"time":1701245696,"time_ms":1701245696814,"channel":"futures.order_book_update","event":"update","result":{"U":53095245406,"a":[],"b":[{"p":"38145.5","s":861}],"s":"BTC_USDT","t":1701245696793,"u":53095245407}}
{"time":1701245697,"time_ms":1701245697033,"channel":"futures.order_book_update","event":"update","result":{"U":53095245408,"a":[{"p":"38154.1","s":0},{"p":"38160.9","s":0},{"p":"38152.7","s":0}],"b":[{"p":"38141.1","s":394},{"p":"38138.4","s":3490},{"p":"38138.5","s":0},{"p":"38141.9","s":0},{"p":"38138.3","s":0},{"p":"38130.7","s":0},{"p":"38138.7","s":2323},{"p":"38138.2","s":1315},{"p":"38139","s":2908},{"p":"38140","s":0},{"p":"38142.7","s":0},{"p":"38134.1","s":0},{"p":"38138.1","s":9126}],"s":"BTC_USDT","t":1701245697020,"u":53095245431}}
{"time":1701245697,"time_ms":1701245697052,"channel":"futures.order_book_update","event":"update","result":{"U":53095245432,"a":[{"p":"38154.2","s":0},{"p":"38153.9","s":0},{"p":"38161.3","s":0},{"p":"38153.5","s":0}],"b":[{"p":"38138.3","s":2298},{"p":"38139","s":733},{"p":"38138.7","s":0},{"p":"38134.7","s":0},{"p":"38138","s":0}],"s":"BTC_USDT","t":1701245697044,"u":53095245443}}
{"time":1701245697,"time_ms":1701245697073,"channel":"futures.order_book_update","event":"update","result":{"U":53095245444,"a":[{"p":"38153.4","s":0},{"p":"38157.6","s":0},{"p":"38153","s":0}],"b":[{"p":"38145.6","s":73087},{"p":"38138.2","s":0},{"p":"38138.4","s":0},{"p":"38139","s":0},{"p":"38137.4","s":0},{"p":"38144.6","s":2},{"p":"38143.4","s":2},{"p":"38138.7","s":733},{"p":"38138.1","s":0},{"p":"38138.3","s":0},{"p":"38145.3","s":2},{"p":"38138.5","s":2175}],"s":"BTC_USDT","t":1701245697056,"u":53095245461}}
{"time":1701245697,"time_ms":1701245697092,"channel":"futures.order_book_update","event":"update","result":{"U":53095245462,"a":[],"b":[{"p":"38138.5","s":733},{"p":"38138.7","s":0},{"p":"38138.3","s":0},{"p":"38138.4","s":1315}],"s":"BTC_USDT","t":1701245697078,"u":53095245465}}
{"time":1701245697,"time_ms":1701245697192,"channel":"futures.order_book_update","event":"update","result":{"U":53095245466,"a":[],"b":[{"p":"38145.6","s":72087}],"s":"BTC_USDT","t":1701245697182,"u":53095245467}}
{"time":1701245697,"time_ms":1701245697214,"channel":"futures.order_book_update","event":"update","result":{"U":53095245468,"a":[],"b":[{"p":"38138.3","s":4473},{"p":"38141.1","s":0}],"s":"BTC_USDT","t":1701245697187,"u":53095245468}}
{"time":1701245697,"time_ms":1701245697254,"channel":"futures.order_book_update","event":"update","result":{"U":53095245469,"a":[{"p":"38145.7","s":117365},{"p":"38154","s":0},{"p":"38165.5","s":0},{"p":"38156.8","s":0},{"p":"38158","s":0}],"b":[{"p":"38138","s":1315},{"p":"38145.6","s":72085},{"p":"38138.2","s":1315},{"p":"38143.4","s":0},{"p":"38145.3","s":0},{"p":"38144.6","s":0},{"p":"38138.1","s":9126}],"s":"BTC_USDT","t":1701245697243,"u":53095245482}}
{"time":1701245697,"time_ms":1701245697272,"channel":"futures.order_book_update","event":"update","result":{"U":53095245483,"a":[{"p":"38153.5","s":0},{"p":"38156.8","s":0},{"p":"38157.5","s":0}],"b":[{"p":"38137.8","s":18523},{"p":"38138.5","s":0},{"p":"38138.3","s":0},{"p":"38134.2","s":0},{"p":"38130.6","s":0},{"p":"38137.9","s":2303}],"s":"BTC_USDT","t":1701245697263,"u":53095245501}}
{"time":1701245697,"time_ms":1701245697292,"channel":"futures.order_book_update","event":"update","result":{"U":53095245502,"a":[{"p":"38156.2","s":0}],"b":[{"p":"38138.1","s":9152},{"p":"38138.2","s":3490},{"p":"38137.5","s":0},{"p":"38137","s":0}],"s":"BTC_USDT","t":1701245697284,"u":53095245512}}
{"time":1701245697,"time_ms":1701245697312,"channel":"futures.order_book_update","event":"update","result":{"U":53095245513,"a":[{"p":"38145.7","s":117965},{"p":"38153","s":0},{"p":"38155.3","s":0},{"p":"38153.9","s":0}],"b":[{"p":"38138.1","s":9126},{"p":"38136.5","s":0},{"p":"38133.7","s":0},{"p":"38137.1","s":0},{"p":"38138.2","s":1315}],"s":"BTC_USDT","t":1701245697301,"u":53095245535}}
{"time":1701245697,"time_ms":1701245697371,"channel":"futures.order_book_update","event":"update","result":{"U":53095245536,"a":[{"p":"38153","s":0}],"b":[{"p":"38137.7","s":733},{"p":"38145.6","s":57085},{"p":"38137.9","s":0},{"p":"38136.6","s":0}],"s":"BTC_USDT","t":1701245697358,"u":53095245546}}
{"time":1701245697,"time_ms":1701245697391,"channel":"futures.order_book_update","event":"update","result":{"U":53095245547,"a":[{"p":"38153.3","s":0}],"b":[{"p":"38137.6","s":0},{"p":"38134.2","s":0},{"p":"38138.1","s":9152}],"s":"BTC_USDT","t":1701245697377,"u":53095245551}}
{"time":1701245697,"time_ms":1701245697496,"channel":"futures.order_book_update","event":"update","result":{"U":53095245552,"a":[{"p":"38162.5","s":0},{"p":"38151","s":0},{"p":"38155","s":0}],"b":[{"p":"38120.1","s":0}],"s":"BTC_USDT","t":1701245697485,"u":53095245559}}
{"time":1701245697,"time_ms":1701245697533,"channel":"futures.order_book_update","event":"update","result":{"U":53095245560,"a":[{"p":"38152.3","s":0},{"p":"38153.3","s":0},{"p":"38153.1","s":0},{"p":"38154.8","s":0}],"b":[{"p":"38130.1","s":0}],"s":"BTC_USDT","t":1701245697523,"u":53095245568}}
{"time":1701245697,"time_ms":1701245697553,"channel":"futures.order_book_update","event":"update","result":{"U":53095245569,"a":[{"p":"38152.1","s":0}],"b":[],"s":"BTC_USDT","t":1701245697529,"u":53095245570}}
{"time":1701245697,"time_ms":1701245697593,"channel":"futures.order_book_update","event":"update","result":{"U":53095245571,"a":[],"b":[{"p":"38145.6","s":58085}],"s":"BTC_USDT","t":1701245697573,"u":53095245573}}
{"time":1701245697,"time_ms":1701245697752,"channel":"futures.order_book_update","event":"update","result":{"U":53095245574,"a":[{"p":"38165.5","s":0},{"p":"38154","s":0},{"p":"38159.5","s":0},{"p":"38151.3","s":0},{"p":"38158","s":0},{"p":"38155.5","s":0}],"b":[{"p":"38138.3","s":2175},{"p":"38139","s":1315},{"p":"38137.8","s":0},{"p":"38137.7","s":0},{"p":"38137","s":0},{"p":"38145.6","s":73085}],"s":"BTC_USDT","t":1701245697742,"u":53095245589}}
{"time":1701245697,"time_ms":1701245697773,"channel":"futures.order_book_update","event":"update","result":{"U":53095245590,"a":[{"p":"38160.5","s":0},{"p":"38145.7","s":102365},{"p":"38152.7","s":0},{"p":"38152.1","s":0},{"p":"38153","s":0},{"p":"38167","s":0},{"p":"38156.5","s":0},{"p":"38152","s":0}],"b":[{"p":"38128.1","s":0},{"p":"38020.1","s":0},{"p":"38138.7","s":733},{"p":"38138","s":0},{"p":"38136.2","s":0},{"p":"38137.7","s":0}],"s":"BTC_USDT","t":1701245697758,"u":53095245612}}
{"time":1701245697,"time_ms":1701245697812,"channel":"futures.order_book_update","event":"update","result":{"U":53095245613,"a":[{"p":"38161","s":0},{"p":"38157","s":0},{"p":"38187.9","s":0},{"p":"38167.9","s":0}],"b":[{"p":"38126.2","s":0},{"p":"38106","s":0}],"s":"BTC_USDT","t":1701245697797,"u":53095245623}}
{"time":1701245697,"time_ms":1701245697833,"channel":"futures.order_book_update","event":"update","result":{"U":53095245624,"a":[],"b":[{"p":"38138.7","s":0},{"p":"38138","s":1315},{"p":"38138.2","s":2048}],"s":"BTC_USDT","t":1701245697803,"u":53095245625}}
{"time":1701245697,"time_ms":1701245697851,"channel":"futures.order_book_update","event":"update","result":{"U":53095245626,"a":[],"b":[{"p":"38137.4","s":0}],"s":"BTC_USDT","t":1701245697834,"u":53095245626}}
{"time":1701245697,"time_ms":1701245697896,"channel":"futures.order_book_update","event":"update","result":{"U":53095245627,"a":[{"p":"38160.5","s":0},{"p":"38156.5","s":0},{"p":"38168.5","s":0}],"b":[],"s":"BTC_USDT","t":1701245697886,"u":53095245632}}
{"time":1701245698,"time_ms":1701245698032,"channel":"futures.order_book_update","event":"update","result":{"U":53095245633,"a":[{"p":"38153.5","s":0},{"p":"38152.6","s":0},{"p":"38156.7","s":0}],"b":[{"p":"38137.5","s":0},{"p":"38129.4","s":0},{"p":"38138.4","s":2048},{"p":"38138.2","s":1315},{"p":"38133.3","s":0},{"p":"38137.9","s":0}],"s":"BTC_USDT","t":1701245698017,"u":53095245649}}
{"time":1701245698,"time_ms":1701245698053,"channel":"futures.order_book_update","event":"update","result":{"U":53095245650,"a":[{"p":"38152.6","s":0},{"p":"38153.1","s":0}],"b":[{"p":"38137.5","s":0}],"s":"BTC_USDT","t":1701245698040,"u":53095245663}}
{"time":1701245698,"time_ms":1701245698091,"channel":"futures.order_book_update","event":"update","result":{"U":53095245664,"a":[],"b":[{"p":"38138.5","s":2175},{"p":"38138.3","s":0},{"p":"38137.9","s":0}],"s":"BTC_USDT","t":1701245698080,"u":53095245671}}
{"time":1701245698,"time_ms":1701245698113,"channel":"futures.order_book_update","event":"update","result":{"U":53095245672,"a":[{"p":"38153.3","s":0}],"b":[],"s":"BTC_USDT","t":1701245698093,"u":53095245673}}
{"time":1701245698,"time_ms":1701245698212,"channel":"futures.order_book_update","event":"update","result":{"U":53095245674,"a":[{"p":"38145.7","s":117965},{"p":"38153.9","s":0},{"p":"38153.5","s":0},{"p":"38155.3","s":0},{"p":"38156.8","s":0},{"p":"38152.3","s":0}],"b":[{"p":"38138.3","s":2908},{"p":"38138.4","s":1315},{"p":"38138.5","s":0},{"p":"38137.9","s":0}],"s":"BTC_USDT","t":1701245698192,"u":53095245688}}
{"time":1701245698,"time_ms":1701245698233,"channel":"futures.order_book_update","event":"update","result":{"U":53095245689,"a":[{"p":"38152","s":0},{"p":"38153.5","s":0},{"p":"38156.4","s":0},{"p":"38153","s":0}],"b":[],"s":"BTC_USDT","t":1701245698212,"u":53095245696}}
{"time":1701245698,"time_ms":1701245698251,"channel":"futures.order_book_update","event":"update","result":{"U":53095245697,"a":[],"b":[{"p":"38130.4","s":0}],"s":"BTC_USDT","t":1701245698235,"u":53095245698}}
{"time":1701245698,"time_ms":1701245698392,"channel":"futures.order_book_update","event":"update","result":{"U":53095245699,"a":[],"b":[{"p":"38140","s":395},{"p":"38138","s":0}],"s":"BTC_USDT","t":1701245698373,"u":53095245702}}
{"time":1701245698,"time_ms":1701245698413,"channel":"futures.order_book_update","event":"update","result":{"U":53095245703,"a":[],"b":[{"p":"38137.9","s":0}],"s":"BTC_USDT","t":1701245698393,"u":53095245704}}
{"time":1701245698,"time_ms":1701245698432,"channel":"futures.order_book_update","event":"update","result":{"U":53095245705,"a":[],"b":[{"p":"38145.6","s":72085}],"s":"BTC_USDT","t":1701245698423,"u":53095245706}}
{"time":1701245698,"time_ms":1701245698534,"channel":"futures.order_book_update","event":"update","result":{"U":53095245707,"a":[],"b":[{"p":"38138","s":1315},{"p":"38140","s":0}],"s":"BTC_USDT","t":1701245698515,"u":53095245707}}
{"time":1701245698,"time_ms":1701245698672,"channel":"futures.order_book_update","event":"update","result":{"U":53095245708,"a":[{"p":"38153.8","s":0}],"b":[{"p":"38137","s":0},{"p":"38136.5","s":0},{"p":"38130.1","s":0},{"p":"38145.6","s":56085},{"p":"38137.9","s":2175},{"p":"38138.3","s":0},{"p":"38137.7","s":0},{"p":"38134.1","s":0}],"s":"BTC_USDT","t":1701245698664,"u":53095245726}}
{"time":1701245698,"time_ms":1701245698694,"channel":"futures.order_book_update","event":"update","result":{"U":53095245727,"a":[{"p":"38156.7","s":0},{"p":"38152.2","s":0}],"b":[{"p":"38137.9","s":0},{"p":"38133.7","s":0},{"p":"38136.2","s":0},{"p":"38137.7","s":0},{"p":"38137.4","s":0},{"p":"38137.8","s":18523}],"s":"BTC_USDT","t":1701245698683,"u":53095245739}}
{"time":1701245698,"time_ms":1701245698732,"channel":"futures.order_book_update","event":"update","result":{"U":53095245740,"a":[],"b":[{"p":"38137.7","s":0}],"s":"BTC_USDT","t":1701245698710,"u":53095245742}}
{"time":1701245698,"time_ms":1701245698932,"channel":"futures.order_book_update","event":"update","result":{"U":53095245743,"a":[{"p":"38145.7","s":117365}],"b":[{"p":"38145.6","s":71085},{"p":"38133.3","s":0}],"s":"BTC_USDT","t":1701245698922,"u":53095245761}}
{"time":1701245699,"time_ms":1701245699014,"channel":"futures.order_book_update","event":"update","result":{"U":53095245762,"a":[{"p":"38153.3","s":0},{"p":"38152.7","s":0},{"p":"38160.5","s":0}],"b":[{"p":"38138.2","s":3490},{"p":"38137.4","s":0},{"p":"38129.4","s":0}],"s":"BTC_USDT","t":1701245699005,"u":53095245773}}
{"time":1701245699,"time_ms":1701245699033,"channel":"futures.order_book_update","event":"update","result":{"U":53095245774,"a":[{"p":"38151.9","s":0},{"p":"38155.9","s":0},{"p":"38151.7","s":0}],"b":[{"p":"38138.2","s":4223},{"p":"38136.5","s":0},{"p":"38137.7","s":0}],"s":"BTC_USDT","t":1701245699024,"u":53095245783}}
{"time":1701245699,"time_ms":1701245699054,"channel":"futures.order_book_update","event":"update","result":{"U":53095245784,"a":[],"b":[{"p":"38134","s":0}],"s":"BTC_USDT","t":1701245699028,"u":53095245785}}
{"time":1701245699,"time_ms":1701245699153,"channel":"futures.order_book_update","event":"update","result":{"U":53095245786,"a":[{"p":"38160","s":0},{"p":"38153.3","s":0},{"p":"38153","s":0},{"p":"38156.2","s":0},{"p":"38152.3","s":0}],"b":[{"p":"38137.8","s":0},{"p":"38133.7","s":0},{"p":"38136.1","s":0},{"p":"38131.4","s":0},{"p":"38141.8","s":9024},{"p":"38139.9","s":2},{"p":"38142.6","s":2},{"p":"38138","s":0}],"s":"BTC_USDT","t":1701245699142,"u":53095245803}}
{"time":1701245699,"time_ms":1701245699173,"channel":"futures.order_book_update","event":"update","result":{"U":53095245804,"a":[{"p":"38153.3","s":0},{"p":"38152","s":0},{"p":"38153.5","s":0},{"p":"38156.4","s":0}],"b":[{"p":"38138.1","s":0},{"p":"38138.2","s":0},{"p":"38138.5","s":2175},{"p":"38141.1","s":2}],"s":"BTC_USDT","t":1701245699160,"u":53095245815}}
{"time":1701245699,"time_ms":1701245699193,"channel":"futures.order_book_update","event":"update","result":{"U":53095245816,"a":[{"p":"38153.5","s":0},{"p":"38145.7","s":102365},{"p":"38152.3","s":0}],"b":[{"p":"38144","s":100},{"p":"38136.8","s":0}],"s":"BTC_USDT","t":1701245699184,"u":53095245824}}
{"time":1701245699,"time_ms":1701245699212,"channel":"futures.order_book_update","event":"update","result":{"U":53095245825,"a":[{"p":"38145.7","s":102965},{"p":"38152.7","s":0},{"p":"38155.1","s":0},{"p":"38153.9","s":0}],"b":[{"p":"38137.4","s":0}],"s":"BTC_USDT","t":1701245699202,"u":53095245832}}
{"time":1701245699,"time_ms":1701245699232,"channel":"futures.order_book_update","event":"update","result":{"U":53095245833,"a":[{"p":"38145.7","s":102365}],"b":[],"s":"BTC_USDT","t":1701245699217,"u":53095245834}}
{"time":1701245699,"time_ms":1701245699259,"channel":"futures.order_book_update","event":"update","result":{"U":53095245835,"a":[{"p":"38152","s":0}],"b":[],"s":"BTC_USDT","t":1701245699221,"u":53095245836}}
{"time":1701245699,"time_ms":1701245699298,"channel":"futures.order_book_update","event":"update","result":{"U":53095245837,"a":[{"p":"38145.7","s":117365},{"p":"38153.3","s":0}],"b":[{"p":"38144","s":200},{"p":"38138","s":0}],"s":"BTC_USDT","t":1701245699281,"u":53095245840}}
{"time":1701245699,"time_ms":1701245699314,"channel":"futures.order_book_update","event":"update","result":{"U":53095245841,"a":[{"p":"38153","s":0}],"b":[{"p":"38138.2","s":2048},{"p":"38138.1","s":9152},{"p":"38141.8","s":9022},{"p":"38141.1","s":0},{"p":"38142.6","s":0},{"p":"38139.9","s":2},{"p":"38138","s":0}],"s":"BTC_USDT","t":1701245699302,"u":53095245848}}
{"time":1701245699,"time_ms":1701245699331,"channel":"futures.order_book_update","event":"update","result":{"U":53095245849,"a":[{"p":"38145.7","s":117965},{"p":"38155.1","s":0}],"b":[{"p":"38141.1","s":2},{"p":"38138.2","s":0},{"p":"38138.1","s":0},{"p":"38141.8","s":9024},{"p":"38142.6","s":2}],"s":"BTC_USDT","t":1701245699316,"u":53095245853}}
{"time":1701245699,"time_ms":1701245699399,"channel":"futures.order_book_update","event":"update","result":{"U":53095245854,"a":[{"p":"38153.3","s":0}],"b":[{"p":"38144","s":100}],"s":"BTC_USDT","t":1701245699382,"u":53095245856}}
{"time":1701245699,"time_ms":1701245699452,"channel":"futures.order_book_update","event":"update","result":{"U":53095245857,"a":[{"p":"38153.3","s":0}],"b":[],"s":"BTC_USDT","t":1701245699434,"u":53095245859}}
{"time":1701245699,"time_ms":1701245699493,"channel":"futures.order_book_update","event":"update","result":{"U":53095245860,"a":[],"b":[{"p":"38145.6","s":72085}],"s":"BTC_USDT","t":1701245699469,"u":53095245861}}
{"time":1701245699,"time_ms":1701245699531,"channel":"futures.order_book_update","event":"update","result":{"U":53095245862,"a":[],"b":[{"p":"38138.1","s":9152},{"p":"38138.2","s":2048},{"p":"38138","s":1415},{"p":"38141.8","s":9022},{"p":"38142.6","s":0},{"p":"38141.1","s":0},{"p":"38139.9","s":0}],"s":"BTC_USDT","t":1701245699520,"u":53095245865}}
{"time":1701245699,"time_ms":1701245699553,"channel":"futures.order_book_update","event":"update","result":{"U":53095245866,"a":[{"p":"38153.3","s":0}],"b":[{"p":"38145.6","s":72087},{"p":"38144.4","s":2},{"p":"38145.2","s":3859},{"p":"38143.2","s":2},{"p":"38138.1","s":0},{"p":"38138","s":0}],"s":"BTC_USDT","t":1701245699544,"u":53095245871}}
{"time":1701245699,"time_ms":1701245699612,"channel":"futures.order_book_update","event":"update","result":{"U":53095245872,"a":[{"p":"38152.7","s":0}],"b":[],"s":"BTC_USDT","t":1701245699596,"u":53095245873}}
{"time":1701245699,"time_ms":1701245699633,"channel":"futures.order_book_update","event":"update","result":{"U":53095245874,"a":[],"b":[{"p":"38139","s":2048},{"p":"38138.2","s":1315},{"p":"38134.1","s":0}],"s":"BTC_USDT","t":1701245699625,"u":53095245877}}
{"time":1701245699,"time_ms":1701245699712,"channel":"futures.order_book_update","event":"update","result":{"U":53095245878,"a":[{"p":"38156.8","s":0},{"p":"38153","s":0},{"p":"38153.9","s":0},{"p":"38153.8","s":0}],"b":[{"p":"38139","s":4355},{"p":"38130.1","s":0}],"s":"BTC_USDT","t":1701245699703,"u":53095245890}}
{"time":1701245699,"time_ms":1701245699732,"channel":"futures.order_book_update","event":"update","result":{"U":53095245891,"a":[{"p":"38145.7","s":102965},{"p":"38160.5","s":0},{"p":"38157.1","s":0},{"p":"38152.4","s":0}],"b":[{"p":"38137.7","s":0},{"p":"38139","s":3622},{"p":"38139.7","s":2908},{"p":"38138.7","s":2175},{"p":"38138.5","s":0},{"p":"38138.2","s":0},{"p":"38137","s":0},{"p":"38138.1","s":0}],"s":"BTC_USDT","t":1701245699714,"u":53095245906}}
{"time":1701245699,"time_ms":1701245699752,"channel":"futures.order_book_update","event":"update","result":{"U":53095245907,"a":[],"b":[{"p":"38138.1","s":0},{"p":"38145.2","s":3857},{"p":"38145.6","s":72085},{"p":"38144.3","s":2},{"p":"38138.2","s":1315},{"p":"38143.2","s":0},{"p":"38144.4","s":0}],"s":"BTC_USDT","t":1701245699742,"u":53095245911}}
{"time":1701245699,"time_ms":1701245699833,"channel":"futures.order_book_update","event":"update","result":{"U":53095245912,"a":[],"b":[{"p":"38144","s":200},{"p":"38145.6","s":72087},{"p":"38143.1","s":2},{"p":"38138.4","s":0},{"p":"38138.2","s":0},{"p":"38138","s":0},{"p":"38145","s":2}],"s":"BTC_USDT","t":1701245699806,"u":53095245916}}
{"time":1701245699,"time_ms":1701245699952,"channel":"futures.order_book_update","event":"update","result":{"U":53095245917,"a":[],"b":[{"p":"38145.6","s":72587}],"s":"BTC_USDT","t":1701245699944,"u":53095245923}}
{"time":1701245699,"time_ms":1701245699974,"channel":"futures.order_book_update","event":"update","result":{"U":53095245924,"a":[],"b":[{"p":"38145.6","s":72087},{"p":"38131.4","s":0}],"s":"BTC_USDT","t":1701245699954,"u":53095245928}}
{"time":1701245699,"time_ms":1701245699992,"channel":"futures.order_book_update","event":"update","result":{"U":53095245929,"a":[],"b":[{"p":"38145.6","s":73087}],"s":"BTC_USDT","t":1701245699975,"u":53095245930}}
{"time":1701245700,"time_ms":1701245700012,"channel":"futures.order_book_update","event":"update","result":{"U":53095245931,"a":[{"p":"38158","s":0},{"p":"38154","s":0},{"p":"38165.5","s":0}],"b":[],"s":"BTC_USDT","t":1701245699989,"u":53095245933}}
{"time":1701245700,"time_ms":1701245700033,"channel":"futures.order_book_update","event":"update","result":{"U":53095245934,"a":[{"p":"38158","s":0},{"p":"38153.7","s":0},{"p":"38154.6","s":0}],"b":[{"p":"38138.9","s":9544},{"p":"38139","s":1315},{"p":"38138.5","s":2175},{"p":"38139.7","s":2175},{"p":"38138.7","s":0}],"s":"BTC_USDT","t":1701245700022,"u":53095245946}}
{"time":1701245700,"time_ms":1701245700053,"channel":"futures.order_book_update","event":"update","result":{"U":53095245947,"a":[{"p":"38154.7","s":0}],"b":[{"p":"38145.6","s":72087},{"p":"38139.6","s":6088},{"p":"38134.7","s":0}],"s":"BTC_USDT","t":1701245700034,"u":53095245953}}
{"time":1701245700,"time_ms":1701245700072,"channel":"futures.order_book_update","event":"update","result":{"U":53095245954,"a":[{"p":"38154.5","s":0}],"b":[{"p":"38138.3","s":0},{"p":"38139.1","s":733},{"p":"38138.4","s":1315},{"p":"38139.6","s":5355},{"p":"38138.5","s":0},{"p":"38139.7","s":0},{"p":"38135.1","s":0}],"s":"BTC_USDT","t":1701245700063,"u":53095245965}}
{"time":1701245700,"time_ms":1701245700093,"channel":"futures.order_book_update","event":"update","result":{"U":53095245966,"a":[{"p":"38154.5","s":0},{"p":"38157.9","s":0},{"p":"38161.3","s":0},{"p":"38153.5","s":0}],"b":[{"p":"38138.9","s":7234},{"p":"38139.1","s":0},{"p":"38138.4","s":1315},{"p":"38137.4","s":0},{"p":"38138.7","s":0},{"p":"38138.3","s":0},{"p":"38138.5","s":2908}],"s":"BTC_USDT","t":1701245700074,"u":53095245986}}
{"time":1701245700,"time_ms":1701245700112,"channel":"futures.order_book_update","event":"update","result":{"U":53095245987,"a":[{"p":"38145.7","s":117965}],"b":[],"s":"BTC_USDT","t":1701245700094,"u":53095245990}}
{"time":1701245700,"time_ms":1701245700132,"channel":"futures.order_book_update","event":"update","result":{"U":53095245991,"a":[{"p":"38153.5","s":0},{"p":"38152.4","s":0}],"b":[],"s":"BTC_USDT","t":1701245700120,"u":53095245998}}
{"time":1701245700,"time_ms":1701245700172,"channel":"futures.order_book_update","event":"update","result":{"U":53095245999,"a":[{"p":"38153.9","s":0},{"p":"38153.8","s":0}],"b":[{"p":"38145.6","s":72087},{"p":"38138.2","s":0},{"p":"38137.4","s":0}],"s":"BTC_USDT","t":1701245700157,"u":53095246010}}
{"time":1701245700,"time_ms":1701245700211,"channel":"futures.order_book_update","event":"update","result":{"U":53095246011,"a":[],"b":[{"p":"38144","s":100},{"p":"38130.6","s":0}],"s":"BTC_USDT","t":1701245700201,"u":53095246013}}
{"time":1701245700,"time_ms":1701245700232,"channel":"futures.order_book_update","event":"update","result":{"U":53095246014,"a":[],"b":[{"p":"38134.1","s":0},{"p":"38138.2","s":4223},{"p":"38138.5","s":0}],"s":"BTC_USDT","t":1701245700213,"u":53095246020}}
{"time":1701245700,"time_ms":1701245700293,"channel":"futures.order_book_update","event":"update","result":{"U":53095246021,"a":[{"p":"38152.7","s":0}],"b":[{"p":"38138.2","s":3490},{"p":"38145.6","s":41087},{"p":"38137","s":0}],"s":"BTC_USDT","t":1701245700284,"u":53095246030}}
{"time":1701245700,"time_ms":1701245700314,"channel":"futures.order_book_update","event":"update","result":{"U":53095246031,"a":[],"b":[{"p":"38137.9","s":0},{"p":"38137.4","s":0},{"p":"38133.7","s":0}],"s":"BTC_USDT","t":1701245700304,"u":53095246037}}
{"time":1701245700,"time_ms":1701245700331,"channel":"futures.order_book_update","event":"update","result":{"U":53095246038,"a":[],"b":[{"p":"38137.8","s":18523},{"p":"38138","s":1415},{"p":"38138.1","s":9152},{"p":"38145.6","s":41085},{"p":"38143.1","s":0},{"p":"38144.3","s":0},{"p":"38145","s":0}],"s":"BTC_USDT","t":1701245700316,"u":53095246041}}
{"time":1701245700,"time_ms":1701245700351,"channel":"futures.order_book_update","event":"update","result":{"U":53095246042,"a":[],"b":[{"p":"38144.8","s":2},{"p":"38144.1","s":2},{"p":"38137.8","s":0},{"p":"38138.1","s":0},{"p":"38138","s":0},{"p":"38145.6","s":41087},{"p":"38142.9","s":2},{"p":"38138.3","s":733},{"p":"38138.2","s":0}],"s":"BTC_USDT","t":1701245700342,"u":53095246046}}
{"time":1701245700,"time_ms":1701245700493,"channel":"futures.order_book_update","event":"update","result":{"U":53095246047,"a":[],"b":[{"p":"38145.6","s":50587}],"s":"BTC_USDT","t":1701245700475,"u":53095246047}}
{"time":1701245700,"time_ms":1701245700513,"channel":"futures.order_book_update","event":"update","result":{"U":53095246048,"a":[],"b":[{"p":"38145.6","s":41087}],"s":"BTC_USDT","t":1701245700487,"u":53095246048}}
{"time":1701245700,"time_ms":1701245700552,"channel":"futures.order_book_update","event":"update","result":{"U":53095246049,"a":[{"p":"38159.7","s":0}],"b":[],"s":"BTC_USDT","t":1701245700538,"u":53095246050}}
{"time":1701245700,"time_ms":1701245700577,"channel":"futures.order_book_update","event":"update","result":{"U":53095246051,"a":[{"p":"38156.6","s":0}],"b":[{"p":"38130.1","s":0}],"s":"BTC_USDT","t":1701245700559,"u":53095246053}}
{"time":1701245700,"time_ms":1701245700733,"channel":"futures.order_book_update","event":"update","result":{"U":53095246054,"a":[],"b":[{"p":"38138.2","s":3490},{"p":"38138","s":1415},{"p":"38142.9","s":0},{"p":"38144.8","s":0},{"p":"38144.1","s":0},{"p":"38145.6","s":41085},{"p":"38138.1","s":9152}],"s":"BTC_USDT","t":1701245700716,"u":53095246060}}
{"time":1701245700,"time_ms":1701245700752,"channel":"futures.order_book_update","event":"update","result":{"U":53095246061,"a":[{"p":"38156.2","s":0}],"b":[{"p":"38139.9","s":2},{"p":"38138","s":0},{"p":"38138.2","s":0},{"p":"38138.1","s":0},{"p":"38141.1","s":2},{"p":"38142.6","s":2},{"p":"38141.8","s":9024}],"s":"BTC_USDT","t":1701245700732,"u":53095246066}}
{"time":1701245700,"time_ms":1701245700986,"channel":"futures.order_book_update","event":"update","result":{"U":53095246067,"a":[{"p":"38156.2","s":0},{"p":"38158","s":0},{"p":"38154","s":0},{"p":"38153.3","s":0}],"b":[{"p":"38142.6","s":2},{"p":"38139.9","s":2},{"p":"38141.8","s":9024},{"p":"38141.1","s":2},{"p":"38138","s":0},{"p":"38138.1","s":0},{"p":"38138.2","s":0}],"s":"BTC_USDT","t":1701245700978,"u":53095246086}}
{"time":1701245700,"time_ms":1701245700993,"channel":"futures.order_book_update","event":"update","result":{"U":53095246087,"a":[{"p":"38153.4","s":0},{"p":"38145.7","s":117365},{"p":"38156.8","s":0},{"p":"38153.1","s":0},{"p":"38151.8","s":0}],"b":[{"p":"38139","s":3490},{"p":"38138.5","s":2175},{"p":"38138.3","s":0},{"p":"38138.4","s":0},{"p":"38138.2","s":0},{"p":"38145.6","s":56085},{"p":"38139.8","s":524},{"p":"38139.7","s":733},{"p":"38136.5","s":0}],"s":"BTC_USDT","t":1701245700984,"u":53095246104}}
{"time":1701245701,"time_ms":1701245701012,"channel":"futures.order_book_update","event":"update","result":{"U":53095246105,"a":[{"p":"38153.9","s":0},{"p":"38153.5","s":0},{"p":"38158.7","s":0},{"p":"38153","s":0},{"p":"38160.5","s":0},{"p":"38152.8","s":0},{"p":"38154.6","s":0}],"b":[{"p":"38145.6","s":71085},{"p":"38137.4","s":0},{"p":"38133.3","s":0},{"p":"38138.5","s":4499}],"s":"BTC_USDT","t":1701245700995,"u":53095246125}}
{"time":1701245701,"time_ms":1701245701031,"channel":"futures.order_book_update","event":"update","result":{"U":53095246126,"a":[{"p":"38157.5","s":0},{"p":"38153.5","s":0},{"p":"38154.2","s":0},{"p":"38153.9","s":0},{"p":"38153.3","s":0}],"b":[{"p":"38138.5","s":2175},{"p":"38139.7","s":2908},{"p":"38138.9","s":9536},{"p":"38129.4","s":0},{"p":"38135.8","s":0},{"p":"38139","s":1315}],"s":"BTC_USDT","t":1701245701020,"u":53095246144}}
{"time":1701245701,"time_ms":1701245701050,"channel":"futures.order_book_update","event":"update","result":{"U":53095246145,"a":[{"p":"38145.7","s":87215},{"p":"38161.3","s":0},{"p":"38154.5","s":0},{"p":"38154.6","s":0},{"p":"38148.3","s":732},{"p":"38154.4","s":0},{"p":"38159","s":0},{"p":"38147.3","s":1825},{"p":"38157.9","s":0},{"p":"38155.3","s":0},{"p":"38155.8","s":0},{"p":"38153.5","s":0},{"p":"38158.5","s":0},{"p":"38153.9","s":0},{"p":"38165.5","s":0},{"p":"38155.2","s":0}],"b":[{"p":"38141.8","s":9022},{"p":"38143.9","s":2},{"p":"38141.1","s":0},{"p":"38138.8","s":0},{"p":"38138.6","s":0},{"p":"38138.2","s":0},{"p":"38142.8","s":2},{"p":"38139.2","s":1315},{"p":"38145.6","s":78950},{"p":"38139.1","s":2175},{"p":"38139.9","s":733},{"p":"38145.5","s":863},{"p":"38138.7","s":0},{"p":"38138.5","s":0},{"p":"38130.6","s":0},{"p":"38144.7","s":2},{"p":"38139.7","s":2175},{"p":"38142.6","s":0},{"p":"38138.4","s":0},{"p":"38136.7","s":0}],"s":"BTC_USDT","t":1701245701040,"u":53095246191}}
{"time":1701245701,"time_ms":1701245701071,"channel":"futures.order_book_update","event":"update","result":{"U":53095246192,"a":[{"p":"38160","s":0},{"p":"38156.2","s":0},{"p":"38154.9","s":0},{"p":"38155.4","s":0},{"p":"38158.4","s":0},{"p":"38154.4","s":0},{"p":"38153.9","s":0},{"p":"38158.6","s":0},{"p":"38159","s":0},{"p":"38155.1","s":0},{"p":"38161.7","s":0},{"p":"38155.9","s":0}],"b":[{"p":"38139.1","s":2175},{"p":"38139.6","s":5355},{"p":"38135.9","s":0},{"p":"38145.6","s":79450},{"p":"38138.8","s":1458},{"p":"38140.9","s":2908},{"p":"38139.9","s":0},{"p":"38139.7","s":0},{"p":"38120.4","s":0}],"s":"BTC_USDT","t":1701245701061,"u":53095246231}}
{"time":1701245701,"time_ms":1701245701092,"channel":"futures.order_book_update","event":"update","result":{"U":53095246232,"a":[{"p":"38151","s":5345},{"p":"38146.6","s":0},{"p":"38145.7","s":87215},{"p":"38156","s":0},{"p":"38156.4","s":0},{"p":"38150.9","s":15702},{"p":"38145.9","s":0},{"p":"38155.7","s":0},{"p":"38154.8","s":0}],"b":[{"p":"38132.2","s":0},{"p":"38145.6","s":93872},{"p":"38136.6","s":0}],"s":"BTC_USDT","t":1701245701082,"u":53095246255}}
{"time":1701245701,"time_ms":1701245701113,"channel":"futures.order_book_update","event":"update","result":{"U":53095246256,"a":[{"p":"38145.7","s":38959},{"p":"38151","s":0},{"p":"38149.3","s":0},{"p":"38165","s":0},{"p":"38150.9","s":15702},{"p":"38146.6","s":654},{"p":"38149.7","s":45757}],"b":[{"p":"38139.7","s":2175},{"p":"38144","s":200},{"p":"38139.1","s":0},{"p":"38138.8","s":1458},{"p":"38138","s":0}],"s":"BTC_USDT","t":1701245701099,"u":53095246270}}
{"time":1701245701,"time_ms":1701245701152,"channel":"futures.order_book_update","event":"update","result":{"U":53095246271,"a":[{"p":"38156.4","s":0}],"b":[{"p":"38137.6","s":0}],"s":"BTC_USDT","t":1701245701137,"u":53095246276}}
{"time":1701245701,"time_ms":1701245701173,"channel":"futures.order_book_update","event":"update","result":{"U":53095246277,"a":[{"p":"38151","s":5345},{"p":"38149.2","s":0},{"p":"38154.5","s":0},{"p":"38158.5","s":0}],"b":[{"p":"38145.2","s":6538},{"p":"38138.6","s":1315},{"p":"38138.2","s":1315},{"p":"38138.4","s":1315},{"p":"38144.7","s":0},{"p":"38143.9","s":0},{"p":"38142.8","s":0},{"p":"38145.5","s":861}],"s":"BTC_USDT","t":1701245701159,"u":53095246287}}
{"time":1701245701,"time_ms":1701245701191,"channel":"futures.order_book_update","event":"update","result":{"U":53095246288,"a":[],"b":[{"p":"38143.9","s":2},{"p":"38144.6","s":2},{"p":"38142.7","s":2},{"p":"38138.2","s":0},{"p":"38138.6","s":0},{"p":"38138.4","s":0}],"s":"BTC_USDT","t":1701245701174,"u":53095246290}}
{"time":1701245701,"time_ms":1701245701212,"channel":"futures.order_book_update","event":"update","result":{"U":53095246291,"a":[{"p":"38145.7","s":37959},{"p":"38164","s":0}],"b":[{"p":"38145.4","s":2},{"p":"38138.8","s":0}],"s":"BTC_USDT","t":1701245701195,"u":53095246298}}
{"time":1701245701,"time_ms":1701245701252,"channel":"futures.order_book_update","event":"update","result":{"U":53095246299,"a":[{"p":"38169","s":0}],"b":[{"p":"38138.9","s":0},{"p":"38115.6","s":0},{"p":"38139.4","s":1315},{"p":"38140.9","s":2175}],"s":"BTC_USDT","t":1701245701246,"u":53095246303}}
{"time":1701245701,"time_ms":1701245701273,"channel":"futures.order_book_update","event":"update","result":{"U":53095246304,"a":[{"p":"38165","s":0}],"b":[{"p":"38139.9","s":733},{"p":"38139","s":0}],"s":"BTC_USDT","t":1701245701263,"u":53095246307}}
{"time":1701245701,"time_ms":1701245701292,"channel":"futures.order_book_update","event":"update","result":{"U":53095246308,"a":[{"p":"38178.2","s":0}],"b":[{"p":"38121.7","s":0}],"s":"BTC_USDT","t":1701245701271,"u":53095246312}}
{"time":1701245701,"time_ms":1701245701315,"channel":"futures.order_book_update","event":"update","result":{"U":53095246313,"a":[{"p":"38152.5","s":0}],"b":[],"s":"BTC_USDT","t":1701245701297,"u":53095246315}}
{"time":1701245701,"time_ms":1701245701331,"channel":"futures.order_book_update","event":"update","result":{"U":53095246316,"a":[{"p":"38155","s":0},{"p":"38158.8","s":0}],"b":[],"s":"BTC_USDT","t":1701245701317,"u":53095246319}}
{"time":1701245701,"time_ms":1701245701351,"channel":"futures.order_book_update","event":"update","result":{"U":53095246320,"a":[{"p":"38148.3","s":208},{"p":"38155.3","s":0},{"p":"38164","s":0},{"p":"38170.2","s":0},{"p":"38155.8","s":0},{"p":"38166.4","s":0},{"p":"38171","s":0},{"p":"38156.2","s":0},{"p":"38162.6","s":0}],"b":[{"p":"38126.6","s":0},{"p":"38122.8","s":0},{"p":"38137.8","s":0},{"p":"38138.1","s":0},{"p":"38140.9","s":2908},{"p":"38139.9","s":0},{"p":"38129.1","s":0},{"p":"38118.9","s":0},{"p":"38130.4","s":0},{"p":"38139","s":1315}],"s":"BTC_USDT","t":1701245701338,"u":53095246342}}
{"time":1701245701,"time_ms":1701245701373,"channel":"futures.order_book_update","event":"update","result":{"U":53095246343,"a":[{"p":"38145.7","s":37565},{"p":"38156.4","s":0},{"p":"38161.8","s":0},{"p":"38159","s":0},{"p":"38156.3","s":0},{"p":"38159.8","s":0}],"b":[{"p":"38140","s":2908},{"p":"38145.2","s":3857},{"p":"38140.9","s":0},{"p":"38139","s":1315},{"p":"38137.4","s":0}],"s":"BTC_USDT","t":1701245701363,"u":53095246362}}
{"time":1701245701,"time_ms":1701245701393,"channel":"futures.order_book_update","event":"update","result":{"U":53095246363,"a":[{"p":"38164","s":0},{"p":"38152.5","s":0}],"b":[{"p":"38141","s":2908},{"p":"38140","s":0},{"p":"38136.5","s":0},{"p":"38128.3","s":0},{"p":"38139","s":1315}],"s":"BTC_USDT","t":1701245701386,"u":53095246371}}
{"time":1701245701,"time_ms":1701245701412,"channel":"futures.order_book_update","event":"update","result":{"U":53095246372,"a":[{"p":"38164","s":0},{"p":"38147.3","s":2479},{"p":"38151.1","s":525},{"p":"38146.6","s":0}],"b":[{"p":"38137.4","s":0}],"s":"BTC_USDT","t":1701245701399,"u":53095246377}}
{"time":1701245701,"time_ms":1701245701433,"channel":"futures.order_book_update","event":"update","result":{"U":53095246378,"a":[{"p":"38145.7","s":37615},{"p":"38151.5","s":0}],"b":[{"p":"38098.9","s":0}],"s":"BTC_USDT","t":1701245701414,"u":53095246395}}
{"time":1701245701,"time_ms":1701245701454,"channel":"futures.order_book_update","event":"update","result":{"U":53095246396,"a":[{"p":"38156","s":0},{"p":"38167.8","s":0}],"b":[{"p":"38139.6","s":6670}],"s":"BTC_USDT","t":1701245701441,"u":53095246398}}
{"time":1701245701,"time_ms":1701245701472,"channel":"futures.order_book_update","event":"update","result":{"U":53095246399,"a":[{"p":"38151.2","s":5},{"p":"38150.9","s":12069},{"p":"38150.7","s":0},{"p":"38165","s":0}],"b":[],"s":"BTC_USDT","t":1701245701460,"u":53095246403}}
{"time":1701245701,"time_ms":1701245701492,"channel":"futures.order_book_update","event":"update","result":{"U":53095246404,"a":[{"p":"38145.7","s":37115},{"p":"38158","s":0},{"p":"38154.9","s":0},{"p":"38169.5","s":0}],"b":[{"p":"38138.9","s":0},{"p":"38145.6","s":104372},{"p":"38125.1","s":0},{"p":"38135","s":0}],"s":"BTC_USDT","t":1701245701482,"u":53095246433}}
{"time":1701245701,"time_ms":1701245701513,"channel":"futures.order_book_update","event":"update","result":{"U":53095246434,"a":[{"p":"38154","s":0},{"p":"38147.3","s":1825},{"p":"38151.3","s":0},{"p":"38159","s":0},{"p":"38153.3","s":0},{"p":"38169","s":0},{"p":"38148.1","s":654},{"p":"38149.8","s":0},{"p":"38156.6","s":0},{"p":"38164.1","s":0},{"p":"38165.8","s":0},{"p":"38152.9","s":0},{"p":"38160.9","s":0},{"p":"38151","s":4030},{"p":"38145.7","s":35615},{"p":"38180","s":0}],"b":[{"p":"38119.9","s":0},{"p":"38140.2","s":0},{"p":"38143.9","s":0},{"p":"38138.7","s":2620},{"p":"38140.9","s":2306},{"p":"38145.4","s":0},{"p":"38138.6","s":0},{"p":"38139","s":1315},{"p":"38145.3","s":1},{"p":"38138.9","s":7234},{"p":"38142.7","s":0},{"p":"38138","s":0},{"p":"38097.3","s":0},{"p":"38131.4","s":0},{"p":"38129.8","s":0},{"p":"38138.4","s":0},{"p":"38138.8","s":1458},{"p":"38145.2","s":6538},{"p":"38144.6","s":0},{"p":"38133.1","s":0}],"s":"BTC_USDT","t":1701245701502,"u":53095246477}}
{"time":1701245701,"time_ms":1701245701533,"channel":"futures.order_book_update","event":"update","result":{"U":53095246478,"a":[{"p":"38152.2","s":0},{"p":"38151","s":3505},{"p":"38155","s":0},{"p":"38157.3","s":0},{"p":"38155.6","s":0},{"p":"38156.8","s":0},{"p":"38161.9","s":0},{"p":"38160","s":0},{"p":"38151.6","s":0},{"p":"38151.3","s":0},{"p":"38156.7","s":0},{"p":"38155.2","s":0},{"p":"38150.9","s":8468},{"p":"38145.7","s":34085},{"p":"38152.8","s":0},{"p":"38158.5","s":0},{"p":"38159.3","s":0},{"p":"38166","s":0},{"p":"38152.4","s":0},{"p":"38152.5","s":0},{"p":"38159","s":0},{"p":"38154.5","s":0},{"p":"38151.9","s":0}],"b":[{"p":"38138.7","s":0},{"p":"38140.9","s":2306},{"p":"38132.4","s":0},{"p":"38143.4","s":2},{"p":"38139.9","s":2175},{"p":"38145.6","s":104374},{"p":"38139.7","s":0},{"p":"38120.2","s":0},{"p":"38145.3","s":3},{"p":"38101.7","s":0},{"p":"38132.6","s":0},{"p":"38144.6","s":2},{"p":"38138.8","s":0},{"p":"38138.6","s":0}],"s":"BTC_USDT","t":1701245701520,"u":53095246544}}
{"time":1701245701,"time_ms":1701245701553,"channel":"futures.order_book_update","event":"update","result":{"U":53095246545,"a":[{"p":"38151","s":397},{"p":"38145.7","s":33083},{"p":"38158.7","s":0},{"p":"38163.3","s":0},{"p":"38158.3","s":0},{"p":"38167.7","s":0},{"p":"38151.4","s":3622},{"p":"38157.6","s":0},{"p":"38158.5","s":0},{"p":"38152.4","s":0},{"p":"38181.8","s":0},{"p":"38148.1","s":0},{"p":"38151.5","s":0},{"p":"38155.5","s":0},{"p":"38155.3","s":0},{"p":"38152.8","s":0},{"p":"38157.5","s":0},{"p":"38159.1","s":0},{"p":"38164.8","s":0},{"p":"38156.2","s":0}],"b":[{"p":"38145.3","s":2},{"p":"38145.2","s":9648},{"p":"38126.1","s":0},{"p":"38134","s":0},{"p":"38138","s":0}],"s":"BTC_USDT","t":1701245701542,"u":53095246592}}
{"time":1701245701,"time_ms":1701245701572,"channel":"futures.order_book_update","event":"update","result":{"U":53095246593,"a":[{"p":"38150.9","s":3943},{"p":"38153","s":0},{"p":"38157.5","s":0},{"p":"38158.7","s":0},{"p":"38151","s":3},{"p":"38145.7","s":25218},{"p":"38187","s":0},{"p":"38151.1","s":0},{"p":"38155.8","s":0},{"p":"38170.8","s":0},{"p":"38163.5","s":0},{"p":"38157","s":0},{"p":"38164","s":0},{"p":"38153.1","s":0},{"p":"38151.8","s":394}],"b":[{"p":"38143.5","s":524},{"p":"38133.6","s":0},{"p":"38126.8","s":0},{"p":"38141.9","s":2174},{"p":"38139.9","s":0},{"p":"38138.9","s":0},{"p":"38098.3","s":0},{"p":"38137.5","s":0},{"p":"38127.3","s":0},{"p":"38139","s":1315},{"p":"38109.9","s":0},{"p":"38145.6","s":121374}],"s":"BTC_USDT","t":1701245701563,"u":53095246652}}
{"time":1701245701,"time_ms":1701245701595,"channel":"futures.order_book_update","event":"update","result":{"U":53095246653,"a":[{"p":"38151.9","s":788},{"p":"38187.1","s":0},{"p":"38154.1","s":0},{"p":"38157.7","s":0},{"p":"38145.7","s":30512},{"p":"38151.4","s":0},{"p":"38156.1","s":0},{"p":"38177.2","s":0},{"p":"38160.4","s":0}],"b":[{"p":"38139","s":0},{"p":"38139.2","s":1315},{"p":"38134.2","s":0},{"p":"38139.6","s":10602},{"p":"38145.6","s":130354},{"p":"38143.6","s":322},{"p":"38141.1","s":2175},{"p":"38141.9","s":0}],"s":"BTC_USDT","t":1701245701582,"u":53095246678}}
{"time":1701245701,"time_ms":1701245701614,"channel":"futures.order_book_update","event":"update","result":{"U":53095246679,"a":[{"p":"38152.1","s":0},{"p":"38186.8","s":0}],"b":[{"p":"38145.6","s":130424},{"p":"38140.4","s":92},{"p":"38139.2","s":0}],"s":"BTC_USDT","t":1701245701603,"u":53095246688}}
{"time":1701245701,"time_ms":1701245701635,"channel":"futures.order_book_update","event":"update","result":{"U":53095246689,"a":[],"b":[{"p":"38092.7","s":0}],"s":"BTC_USDT","t":1701245701620,"u":53095246699}}
{"time":1701245701,"time_ms":1701245701655,"channel":"futures.order_book_update","event":"update","result":{"U":53095246700,"a":[{"p":"38172.4","s":0},{"p":"38153.2","s":0},{"p":"38188.4","s":0},{"p":"38164.7","s":0},{"p":"38153.6","s":0},{"p":"38167.3","s":0},{"p":"38180.1","s":0},{"p":"38190.4","s":0},{"p":"38183.3","s":0},{"p":"38174.4","s":0}],"b":[{"p":"38061.5","s":0},{"p":"37993.2","s":0},{"p":"38123.1","s":0},{"p":"38136.3","s":0},{"p":"38007.9","s":0},{"p":"38125.4","s":0},{"p":"38099","s":0},{"p":"38097","s":0},{"p":"38084.3","s":0},{"p":"38136.7","s":0},{"p":"38139.8","s":1839},{"p":"38005.9","s":0},{"p":"38119.8","s":0},{"p":"38130.7","s":0},{"p":"38098.2","s":0},{"p":"38145.6","s":134094},{"p":"38121.8","s":0},{"p":"38076.1","s":0},{"p":"38107.1","s":0},{"p":"38074.1","s":0}],"s":"BTC_USDT","t":1701245701649,"u":53095246760}}
{"time":1701245701,"time_ms":1701245701672,"channel":"futures.order_book_update","event":"update","result":{"U":53095246761,"a":[{"p":"38168.5","s":0}],"b":[{"p":"38033.3","s":0},{"p":"38125.3","s":0},{"p":"38128.1","s":0}],"s":"BTC_USDT","t":1701245701663,"u":53095246768}}
{"time":1701245701,"time_ms":1701245701695,"channel":"futures.order_book_update","event":"update","result":{"U":53095246769,"a":[{"p":"38165.8","s":0}],"b":[],"s":"BTC_USDT","t":1701245701686,"u":53095246777}}
{"time":1701245701,"time_ms":1701245701712,"channel":"futures.order_book_update","event":"update","result":{"U":53095246778,"a":[{"p":"38170.5","s":0},{"p":"38170.7","s":0},{"p":"38158.4","s":0}],"b":[{"p":"38127.5","s":0}],"s":"BTC_USDT","t":1701245701704,"u":53095246790}}
{"time":1701245701,"time_ms":1701245701734,"channel":"futures.order_book_update","event":"update","result":{"U":53095246791,"a":[{"p":"38145.7","s":32012},{"p":"38146.4","s":0},{"p":"38152.2","s":0},{"p":"38157.7","s":0},{"p":"38156.5","s":0},{"p":"38156.8","s":0},{"p":"38152.9","s":0},{"p":"38152","s":1971}],"b":[{"p":"38125.3","s":0},{"p":"38145.6","s":134564},{"p":"38141.9","s":3932},{"p":"38139.4","s":0},{"p":"38136.7","s":0}],"s":"BTC_USDT","t":1701245701724,"u":53095246820}}
{"time":1701245701,"time_ms":1701245701751,"channel":"futures.order_book_update","event":"update","result":{"U":53095246821,"a":[{"p":"38145.7","s":32511},{"p":"38179.1","s":0}],"b":[{"p":"38139.4","s":1315},{"p":"38139","s":1315},{"p":"38145.6","s":135062},{"p":"38144.6","s":0},{"p":"38145.3","s":0},{"p":"38137.8","s":0},{"p":"38139.2","s":1315},{"p":"38143.4","s":0},{"p":"38138.2","s":0}],"s":"BTC_USDT","t":1701245701741,"u":53095246854}}
{"time":1701245701,"time_ms":1701245701774,"channel":"futures.order_book_update","event":"update","result":{"U":53095246855,"a":[{"p":"38152.1","s":525},{"p":"38145.7","s":32011},{"p":"38145.8","s":0},{"p":"38164.8","s":0},{"p":"38155.8","s":0}],"b":[{"p":"38137.8","s":0},{"p":"38034.8","s":0},{"p":"38145.6","s":135588},{"p":"38145","s":2},{"p":"38139","s":0},{"p":"38143.5","s":0},{"p":"38124.4","s":0},{"p":"38130.2","s":0},{"p":"38143.9","s":2},{"p":"38136.7","s":0}],"s":"BTC_USDT","t":1701245701763,"u":53095246878}}
{"time":1701245701,"time_ms":1701245701793,"channel":"futures.order_book_update","event":"update","result":{"U":53095246879,"a":[{"p":"38145.7","s":24360},{"p":"38158.6","s":0}],"b":[{"p":"38143.6","s":0},{"p":"38139","s":1315},{"p":"38145.6","s":135590},{"p":"38139.8","s":3839}],"s":"BTC_USDT","t":1701245701784,"u":53095246887}}
{"time":1701245701,"time_ms":1701245701813,"channel":"futures.order_book_update","event":"update","result":{"U":53095246888,"a":[{"p":"38148.2","s":946},{"p":"38167","s":0},{"p":"38155","s":0},{"p":"38169","s":0},{"p":"38159","s":0},{"p":"38145.7","s":29188}],"b":[{"p":"38145.6","s":138665},{"p":"38134.6","s":0}],"s":"BTC_USDT","t":1701245701797,"u":53095246900}}
{"time":1701245701,"time_ms":1701245701832,"channel":"futures.order_book_update","event":"update","result":{"U":53095246901,"a":[{"p":"38152.4","s":1},{"p":"38145.7","s":15850},{"p":"38152.2","s":935},{"p":"38161.3","s":0},{"p":"38164.9","s":0},{"p":"38156","s":0},{"p":"38149.7","s":0},{"p":"38150.6","s":0},{"p":"38166.6","s":0},{"p":"38154","s":0},{"p":"38155.9","s":0},{"p":"38167.7","s":0}],"b":[{"p":"38145","s":2},{"p":"38120","s":0},{"p":"38138.9","s":0},{"p":"38133.8","s":0},{"p":"38128.6","s":0},{"p":"38145.6","s":146506},{"p":"38143.9","s":2},{"p":"38131.5","s":0},{"p":"38138.8","s":0}],"s":"BTC_USDT","t":1701245701826,"u":53095246966}}
{"time":1701245701,"time_ms":1701245701852,"channel":"futures.order_book_update","event":"update","result":{"U":53095246967,"a":[{"p":"38152.1","s":0},{"p":"38159.3","s":0},{"p":"38157","s":0},{"p":"38153.2","s":0},{"p":"38159","s":0},{"p":"38158.8","s":0},{"p":"38155","s":0},{"p":"38153.6","s":0},{"p":"38181","s":0},{"p":"38153","s":34},{"p":"38153.1","s":13214},{"p":"38145.7","s":3558},{"p":"38152.5","s":79},{"p":"38157.4","s":0},{"p":"38152","s":1052},{"p":"38151.9","s":0},{"p":"38151.8","s":0}],"b":[{"p":"38145","s":0},{"p":"38143.9","s":0},{"p":"38134.1","s":0},{"p":"38138.9","s":0},{"p":"38138.8","s":0},{"p":"38145.6","s":150149},{"p":"38141.1","s":2177},{"p":"38143","s":2},{"p":"38144.2","s":3932},{"p":"38142.2","s":2},{"p":"38139.5","s":0},{"p":"38135.5","s":0},{"p":"38139","s":10227}],"s":"BTC_USDT","t":1701245701844,"u":53095247005}}
{"time":1701245701,"time_ms":1701245701872,"channel":"futures.order_book_update","event":"update","result":{"U":53095247006,"a":[{"p":"38156","s":0},{"p":"38155","s":0},{"p":"38158.6","s":0},{"p":"38153.2","s":0},{"p":"38150.9","s":11},{"p":"38148.9","s":654},{"p":"38150.4","s":0}],"b":[{"p":"38145.6","s":150151},{"p":"38145.3","s":2},{"p":"38141.1","s":2175},{"p":"38142.2","s":0},{"p":"38136.7","s":0},{"p":"38144.1","s":2},{"p":"38144.3","s":2364},{"p":"38139","s":0},{"p":"38143","s":0},{"p":"38138.9","s":0},{"p":"38066.5","s":0},{"p":"38135.3","s":0},{"p":"38125.3","s":0}],"s":"BTC_USDT","t":1701245701862,"u":53095247034}}
{"time":1701245701,"time_ms":1701245701891,"channel":"futures.order_book_update","event":"update","result":{"U":53095247035,"a":[{"p":"38157.5","s":0},{"p":"38150.3","s":0},{"p":"38153.2","s":0},{"p":"38154.8","s":0},{"p":"38153.1","s":9292},{"p":"38151.9","s":638},{"p":"38148.9","s":0},{"p":"38157.7","s":0},{"p":"38159.1","s":0}],"b":[{"p":"38138.7","s":0},{"p":"38145.6","s":150151},{"p":"38140.5","s":3341},{"p":"38139.2","s":0},{"p":"38134.9","s":0}],"s":"BTC_USDT","t":1701245701879,"u":53095247060}}
{"time":1701245701,"time_ms":1701245701914,"channel":"futures.order_book_update","event":"update","result":{"U":53095247061,"a":[{"p":"38164","s":0},{"p":"38159.5","s":0},{"p":"38145.7","s":3500},{"p":"38169.6","s":0},{"p":"38181.3","s":0},{"p":"38154.8","s":0},{"p":"38154.3","s":0},{"p":"38154.2","s":0},{"p":"38165","s":0},{"p":"38156.9","s":0}],"b":[{"p":"38145.6","s":150221},{"p":"38122.9","s":0},{"p":"38132.7","s":0},{"p":"38135.6","s":0},{"p":"38135.2","s":0}],"s":"BTC_USDT","t":1701245701906,"u":53095247090}}
{"time":1701245701,"time_ms":1701245701932,"channel":"futures.order_book_update","event":"update","result":{"U":53095247091,"a":[{"p":"38164.9","s":0},{"p":"38158.6","s":0},{"p":"38186.4","s":0},{"p":"38168","s":0},{"p":"38181","s":0}],"b":[],"s":"BTC_USDT","t":1701245701918,"u":53095247101}}
{"time":1701245701,"time_ms":1701245701952,"channel":"futures.order_book_update","event":"update","result":{"U":53095247102,"a":[],"b":[{"p":"38136.9","s":0},{"p":"38140","s":1315},{"p":"38139.4","s":0}],"s":"BTC_USDT","t":1701245701939,"u":53095247108}}
{"time":1701245701,"time_ms":1701245701973,"channel":"futures.order_book_update","event":"update","result":{"U":53095247109,"a":[{"p":"38164","s":0}],"b":[{"p":"38035.9","s":0}],"s":"BTC_USDT","t":1701245701965,"u":53095247120}}
{"time":1701245702,"time_ms":1701245702012,"channel":"futures.order_book_update","event":"update","result":{"U":53095247121,"a":[{"p":"38159.3","s":0},{"p":"38160.3","s":0}],"b":[],"s":"BTC_USDT","t":1701245702002,"u":53095247127}}
{"time":1701245702,"time_ms":1701245702034,"channel":"futures.order_book_update","event":"update","result":{"U":53095247128,"a":[{"p":"38172.4","s":0},{"p":"38162.1","s":0},{"p":"38156.3","s":0},{"p":"38158.5","s":0}],"b":[{"p":"38139.2","s":1315},{"p":"38142","s":7610},{"p":"38141.1","s":0},{"p":"38141","s":0},{"p":"38133.3","s":0},{"p":"38139.9","s":0},{"p":"38139.7","s":3341},{"p":"38139.4","s":1315},{"p":"38140.5","s":0},{"p":"38140.9","s":0}],"s":"BTC_USDT","t":1701245702023,"u":53095247149}}
{"time":1701245702,"time_ms":1701245702052,"channel":"futures.order_book_update","event":"update","result":{"U":53095247150,"a":[{"p":"38157.7","s":0},{"p":"38164.5","s":0},{"p":"38160.5","s":0}],"b":[{"p":"38138.4","s":0}],"s":"BTC_USDT","t":1701245702043,"u":53095247157}}
{"time":1701245702,"time_ms":1701245702073,"channel":"futures.order_book_update","event":"update","result":{"U":53095247158,"a":[{"p":"38165","s":0},{"p":"38161","s":0},{"p":"38172.5","s":0}],"b":[],"s":"BTC_USDT","t":1701245702061,"u":53095247166}}
{"time":1701245702,"time_ms":1701245702093,"channel":"futures.order_book_update","event":"update","result":{"U":53095247167,"a":[{"p":"38145.7","s":2000},{"p":"38156.2","s":0},{"p":"38158.2","s":0},{"p":"38161.3","s":0},{"p":"38157.9","s":0}],"b":[{"p":"38145.3","s":0},{"p":"38135.2","s":0},{"p":"38145.6","s":150217},{"p":"38138.9","s":7784},{"p":"38139","s":10227},{"p":"38144.1","s":0}],"s":"BTC_USDT","t":1701245702082,"u":53095247189}}
{"time":1701245702,"time_ms":1701245702112,"channel":"futures.order_book_update","event":"update","result":{"U":53095247190,"a":[{"p":"38161.6","s":0},{"p":"38158.8","s":0}],"b":[{"p":"38145.6","s":150223}],"s":"BTC_USDT","t":1701245702095,"u":53095247197}}
{"time":1701245702,"time_ms":1701245702132,"channel":"futures.order_book_update","event":"update","result":{"U":53095247198,"a":[],"b":[{"p":"38145.6","s":150225}],"s":"BTC_USDT","t":1701245702107,"u":53095247199}}
{"time":1701245702,"time_ms":1701245702191,"channel":"futures.order_book_update","event":"update","result":{"U":53095247200,"a":[{"p":"38176.1","s":0},{"p":"38159.1","s":0}],"b":[],"s":"BTC_USDT","t":1701245702178,"u":53095247207}}
{"time":1701245702,"time_ms":1701245702211,"channel":"futures.order_book_update","event":"update","result":{"U":53095247208,"a":[{"p":"38160","s":0},{"p":"38158","s":0},{"p":"38158.7","s":0},{"p":"38164.2","s":0},{"p":"38153.5","s":0},{"p":"38158.3","s":0},{"p":"38154.5","s":0},{"p":"38164","s":0},{"p":"38172","s":0},{"p":"38156.8","s":0},{"p":"38162.2","s":0},{"p":"38158.2","s":0},{"p":"38161.5","s":0},{"p":"38167.9","s":0}],"b":[],"s":"BTC_USDT","t":1701245702200,"u":53095247230}}
{"time":1701245702,"time_ms":1701245702233,"channel":"futures.order_book_update","event":"update","result":{"U":53095247231,"a":[{"p":"38170.3","s":0},{"p":"38155.1","s":0},{"p":"38161.8","s":0},{"p":"38173.1","s":0},{"p":"38159.8","s":0},{"p":"38156.1","s":0},{"p":"38161.9","s":0},{"p":"38159","s":0},{"p":"38158.6","s":0},{"p":"38156.2","s":0},{"p":"38159.1","s":0},{"p":"38162.4","s":0},{"p":"38188.8","s":0},{"p":"38158","s":0},{"p":"38154.9","s":0},{"p":"38158.7","s":0},{"p":"38166.7","s":0},{"p":"38164","s":0},{"p":"38157.7","s":0}],"b":[{"p":"38139.7","s":0},{"p":"38138.9","s":0},{"p":"38139","s":10227},{"p":"38128.5","s":0},{"p":"38144.3","s":3097},{"p":"38142","s":2174},{"p":"38140.5","s":3341},{"p":"38142.1","s":4824},{"p":"38144.4","s":0}],"s":"BTC_USDT","t":1701245702225,"u":53095247317}}
{"time":1701245702,"time_ms":1701245702252,"channel":"futures.order_book_update","event":"update","result":{"U":53095247318,"a":[{"p":"38159.6","s":0},{"p":"38189.7","s":0},{"p":"38145.7","s":2500},{"p":"38157.9","s":0}],"b":[{"p":"38144.3","s":2364},{"p":"38142.1","s":5557},{"p":"38140.5","s":4656},{"p":"38137.9","s":0}],"s":"BTC_USDT","t":1701245702242,"u":53095247332}}
{"time":1701245702,"time_ms":1701245702273,"channel":"futures.order_book_update","event":"update","result":{"U":53095247333,"a":[{"p":"38165","s":0},{"p":"38153.6","s":0},{"p":"38157","s":0},{"p":"38145.7","s":2000},{"p":"38171.5","s":0},{"p":"38170.5","s":0},{"p":"38160.4","s":0},{"p":"38156.2","s":0}],"b":[{"p":"38139.5","s":2620},{"p":"38139","s":0},{"p":"38008.2","s":0},{"p":"38084.4","s":0},{"p":"38029.2","s":0},{"p":"38136.1","s":0},{"p":"38134.7","s":0},{"p":"38139.8","s":7180},{"p":"38140.5","s":1315},{"p":"38131.3","s":0},{"p":"38069.2","s":0},{"p":"38088.4","s":0}],"s":"BTC_USDT","t":1701245702263,"u":53095247386}}
{"time":1701245702,"time_ms":1701245702292,"channel":"futures.order_book_update","event":"update","result":{"U":53095247387,"a":[{"p":"38158.2","s":0},{"p":"38184.2","s":0}],"b":[{"p":"38139.5","s":0},{"p":"38139","s":10227}],"s":"BTC_USDT","t":1701245702281,"u":53095247391}}
{"time":1701245702,"time_ms":1701245702312,"channel":"futures.order_book_update","event":"update","result":{"U":53095247392,"a":[{"p":"38145.7","s":8224},{"p":"38159","s":0},{"p":"38162.9","s":0}],"b":[{"p":"38145.6","s":237090}],"s":"BTC_USDT","t":1701245702304,"u":53095247403}}
{"time":1701245702,"time_ms":1701245702333,"channel":"futures.order_book_update","event":"update","result":{"U":53095247404,"a":[{"p":"38145.7","s":8724},{"p":"38165","s":0},{"p":"38161","s":0}],"b":[{"p":"38139.8","s":3839},{"p":"38142","s":0},{"p":"38139","s":10227},{"p":"38136.8","s":0},{"p":"38140.9","s":2175},{"p":"38145.6","s":237607}],"s":"BTC_USDT","t":1701245702322,"u":53095247421}}
{"time":1701245702,"time_ms":1701245702352,"channel":"futures.order_book_update","event":"update","result":{"U":53095247422,"a":[{"p":"38156.4","s":0},{"p":"38159","s":0},{"p":"38145.7","s":18150},{"p":"38153.2","s":15000},{"p":"38148.3","s":0},{"p":"38159.1","s":0},{"p":"38156.7","s":0},{"p":"38157.9","s":0}],"b":[{"p":"38138.7","s":0},{"p":"38145.6","s":237615},{"p":"38138.6","s":0}],"s":"BTC_USDT","t":1701245702343,"u":53095247456}}
{"time":1701245702,"time_ms":1701245702373,"channel":"futures.order_book_update","event":"update","result":{"U":53095247457,"a":[{"p":"38161.5","s":0},{"p":"38159.5","s":0},{"p":"38165.3","s":0},{"p":"38169.1","s":0},{"p":"38145.7","s":18650},{"p":"38172.9","s":0}],"b":[],"s":"BTC_USDT","t":1701245702364,"u":53095247487}}
{"time":1701245702,"time_ms":1701245702393,"channel":"futures.order_book_update","event":"update","result":{"U":53095247488,"a":[{"p":"38145.7","s":11650},{"p":"38156.6","s":0},{"p":"38169","s":0}],"b":[{"p":"38133","s":0}],"s":"BTC_USDT","t":1701245702384,"u":53095247511}}
{"time":1701245702,"time_ms":1701245702434,"channel":"futures.order_book_update","event":"update","result":{"U":53095247512,"a":[{"p":"38165","s":0},{"p":"38174.1","s":0}],"b":[{"p":"38141.9","s":4153}],"s":"BTC_USDT","t":1701245702424,"u":53095247518}}
{"time":1701245702,"time_ms":1701245702454,"channel":"futures.order_book_update","event":"update","result":{"U":53095247519,"a":[{"p":"38172.9","s":0}],"b":[],"s":"BTC_USDT","t":1701245702430,"u":53095247519}}
{"time":1701245702,"time_ms":1701245702492,"channel":"futures.order_book_update","event":"update","result":{"U":53095247520,"a":[],"b":[{"p":"38142.1","s":4824},{"p":"38141","s":733},{"p":"38139","s":0}],"s":"BTC_USDT","t":1701245702480,"u":53095247523}}
{"time":1701245702,"time_ms":1701245702552,"channel":"futures.order_book_update","event":"update","result":{"U":53095247524,"a":[{"p":"38145.7","s":12150}],"b":[],"s":"BTC_USDT","t":1701245702523,"u":53095247527}}
{"time":1701245702,"time_ms":1701245702592,"channel":"futures.order_book_update","event":"update","result":{"U":53095247528,"a":[{"p":"38159.1","s":0}],"b":[],"s":"BTC_USDT","t":1701245702578,"u":53095247528}}
{"time":1701245702,"time_ms":1701245702612,"channel":"futures.order_book_update","event":"update","result":{"U":53095247529,"a":[{"p":"38158.9","s":0}],"b":[],"s":"BTC_USDT","t":1701245702599,"u":53095247530}}
{"time":1701245702,"time_ms":1701245702633,"channel":"futures.order_book_update","event":"update","result":{"U":53095247531,"a":[],"b":[{"p":"38139","s":0},{"p":"38141.1","s":2174},{"p":"38142.1","s":2650},{"p":"38140.1","s":2175},{"p":"38139.2","s":0},{"p":"38140.9","s":0}],"s":"BTC_USDT","t":1701245702613,"u":53095247534}}
{"time":1701245702,"time_ms":1701245702653,"channel":"futures.order_book_update","event":"update","result":{"U":53095247535,"a":[{"p":"38170","s":0}],"b":[],"s":"BTC_USDT","t":1701245702643,"u":53095247537}}
{"time":1701245702,"time_ms":1701245702672,"channel":"futures.order_book_update","event":"update","result":{"U":53095247538,"a":[{"p":"38171","s":0}],"b":[],"s":"BTC_USDT","t":1701245702651,"u":53095247539}}
{"time":1701245702,"time_ms":1701245702772,"channel":"futures.order_book_update","event":"update","result":{"U":53095247540,"a":[{"p":"38153.1","s":9291}],"b":[{"p":"38129.9","s":0}],"s":"BTC_USDT","t":1701245702756,"u":53095247544}}
{"time":1701245702,"time_ms":1701245702813,"channel":"futures.order_book_update","event":"update","result":{"U":53095247545,"a":[],"b":[{"p":"38128.1","s":0}],"s":"BTC_USDT","t":1701245702791,"u":53095247547}}
{"time":1701245702,"time_ms":1701245702872,"channel":"futures.order_book_update","event":"update","result":{"U":53095247548,"a":[{"p":"38159","s":0}],"b":[],"s":"BTC_USDT","t":1701245702847,"u":53095247549}}
{"time":1701245702,"time_ms":1701245702894,"channel":"futures.order_book_update","event":"update","result":{"U":53095247550,"a":[{"p":"38145.7","s":11650}],"b":[],"s":"BTC_USDT","t":1701245702882,"u":53095247554}}
{"time":1701245702,"time_ms":1701245702914,"channel":"futures.order_book_update","event":"update","result":{"U":53095247555,"a":[],"b":[{"p":"38145.6","s":238115}],"s":"BTC_USDT","t":1701245702903,"u":53095247557}}
{"time":1701245702,"time_ms":1701245702931,"channel":"futures.order_book_update","event":"update","result":{"U":53095247558,"a":[{"p":"38166","s":0}],"b":[],"s":"BTC_USDT","t":1701245702922,"u":53095247562}}
{"time":1701245702,"time_ms":1701245702954,"channel":"futures.order_book_update","event":"update","result":{"U":53095247563,"a":[{"p":"38152.9","s":654},{"p":"38145.7","s":9724},{"p":"38153.2","s":0}],"b":[],"s":"BTC_USDT","t":1701245702941,"u":53095247564}}
{"time":1701245702,"time_ms":1701245702972,"channel":"futures.order_book_update","event":"update","result":{"U":53095247565,"a":[{"p":"38158.9","s":0}],"b":[{"p":"38135.3","s":0},{"p":"38145.6","s":238639}],"s":"BTC_USDT","t":1701245702961,"u":53095247567}}
{"time":1701245702,"time_ms":1701245702992,"channel":"futures.order_book_update","event":"update","result":{"U":53095247568,"a":[],"b":[{"p":"38145.6","s":239070}],"s":"BTC_USDT","t":1701245702982,"u":53095247575}}
{"time":1701245703,"time_ms":1701245703014,"channel":"futures.order_book_update","event":"update","result":{"U":53095247576,"a":[{"p":"38157.7","s":0},{"p":"38165","s":0}],"b":[{"p":"38139.2","s":1315},{"p":"38142.1","s":0},{"p":"38135.9","s":0}],"s":"BTC_USDT","t":1701245703004,"u":53095247581}}
{"time":1701245703,"time_ms":1701245703032,"channel":"futures.order_book_update","event":"update","result":{"U":53095247582,"a":[{"p":"38161.6","s":0},{"p":"38158","s":0},{"p":"38157.6","s":0},{"p":"38155.7","s":0}],"b":[{"p":"38142.2","s":2174},{"p":"38142","s":2451},{"p":"38141.1","s":0},{"p":"38139.2","s":0},{"p":"38141","s":0},{"p":"38137.9","s":0},{"p":"38140.6","s":2175},{"p":"38141.2","s":733},{"p":"38140.1","s":0}],"s":"BTC_USDT","t":1701245703016,"u":53095247601}}
{"time":1701245703,"time_ms":1701245703053,"channel":"futures.order_book_update","event":"update","result":{"U":53095247602,"a":[{"p":"38161.2","s":0},{"p":"38158.8","s":0},{"p":"38157.7","s":0},{"p":"38158.3","s":0},{"p":"38155.6","s":0},{"p":"38160.9","s":0},{"p":"38165","s":0},{"p":"38158","s":0},{"p":"38172.7","s":0}],"b":[{"p":"38142.2","s":0},{"p":"38139.6","s":0},{"p":"38142","s":2451},{"p":"38138","s":0},{"p":"38139.2","s":0},{"p":"38145.6","s":239062},{"p":"38142.1","s":2},{"p":"38139.4","s":0},{"p":"38138.2","s":0},{"p":"38142.8","s":2},{"p":"38140.9","s":2}],"s":"BTC_USDT","t":1701245703042,"u":53095247632}}
{"time":1701245703,"time_ms":1701245703072,"channel":"futures.order_book_update","event":"update","result":{"U":53095247633,"a":[{"p":"38165","s":0},{"p":"38172.7","s":0}],"b":[{"p":"38143.6","s":2},{"p":"38139.8","s":0},{"p":"38121.6","s":0}],"s":"BTC_USDT","t":1701245703059,"u":53095247640}}
{"time":1701245703,"time_ms":1701245703093,"channel":"futures.order_book_update","event":"update","result":{"U":53095247641,"a":[{"p":"38145.7","s":13224},{"p":"38155.4","s":0}],"b":[{"p":"38142.2","s":2174},{"p":"38140","s":0}],"s":"BTC_USDT","t":1701245703078,"u":53095247651}}
{"time":1701245703,"time_ms":1701245703112,"channel":"futures.order_book_update","event":"update","result":{"U":53095247652,"a":[],"b":[{"p":"38140.9","s":735},{"p":"38141.2","s":0},{"p":"38140","s":1315}],"s":"BTC_USDT","t":1701245703090,"u":53095247653}}
{"time":1701245703,"time_ms":1701245703133,"channel":"futures.order_book_update","event":"update","result":{"U":53095247654,"a":[{"p":"38157.7","s":0}],"b":[],"s":"BTC_USDT","t":1701245703116,"u":53095247655}}
{"time":1701245703,"time_ms":1701245703193,"channel":"futures.order_book_update","event":"update","result":{"U":53095247656,"a":[],"b":[{"p":"38140.9","s":733},{"p":"38139.8","s":3839},{"p":"38139.4","s":1315},{"p":"38143.6","s":0},{"p":"38142.1","s":0},{"p":"38142.8","s":0},{"p":"38139.6","s":10602}],"s":"BTC_USDT","t":1701245703180,"u":53095247660}}
{"time":1701245703,"time_ms":1701245703232,"channel":"futures.order_book_update","event":"update","result":{"U":53095247661,"a":[{"p":"38164.5","s":0},{"p":"38160.5","s":0}],"b":[{"p":"38141.9","s":4155},{"p":"38140.7","s":2},{"p":"38139.8","s":0},{"p":"38135","s":0},{"p":"38143.4","s":2},{"p":"38139.4","s":0},{"p":"38139.6","s":0},{"p":"38139","s":0},{"p":"38142.7","s":2}],"s":"BTC_USDT","t":1701245703210,"u":53095247672}}
{"time":1701245703,"time_ms":1701245703270,"channel":"futures.order_book_update","event":"update","result":{"U":53095247673,"a":[{"p":"38163.3","s":0}],"b":[],"s":"BTC_USDT","t":1701245703244,"u":53095247674}}
{"time":1701245703,"time_ms":1701245703291,"channel":"futures.order_book_update","event":"update","result":{"U":53095247675,"a":[],"b":[{"p":"38056.4","s":0}],"s":"BTC_USDT","t":1701245703283,"u":53095247678}}
{"time":1701245703,"time_ms":1701245703312,"channel":"futures.order_book_update","event":"update","result":{"U":53095247679,"a":[{"p":"38158.7","s":0}],"b":[{"p":"38142.7","s":0},{"p":"38140.7","s":0},{"p":"38139.8","s":3839},{"p":"38139.6","s":10602},{"p":"38141.9","s":4153},{"p":"38139.5","s":8912},{"p":"38143.4","s":0}],"s":"BTC_USDT","t":1701245703303,"u":53095247684}}
{"time":1701245703,"time_ms":1701245703333,"channel":"futures.order_book_update","event":"update","result":{"U":53095247685,"a":[],"b":[{"p":"38142.5","s":2},{"p":"38141.7","s":15028},{"p":"38140.5","s":1317},{"p":"38139.6","s":0},{"p":"38139.5","s":0},{"p":"38143.2","s":2}],"s":"BTC_USDT","t":1701245703323,"u":53095247689}}
{"time":1701245703,"time_ms":1701245703376,"channel":"futures.order_book_update","event":"update","result":{"U":53095247690,"a":[{"p":"38155.6","s":0}],"b":[],"s":"BTC_USDT","t":1701245703358,"u":53095247692}}
{"time":1701245703,"time_ms":1701245703413,"channel":"futures.order_book_update","event":"update","result":{"U":53095247693,"a":[{"p":"38154.3","s":0},{"p":"38158","s":0},{"p":"38155.8","s":0}],"b":[],"s":"BTC_USDT","t":1701245703398,"u":53095247699}}
{"time":1701245703,"time_ms":1701245703453,"channel":"futures.order_book_update","event":"update","result":{"U":53095247700,"a":[{"p":"38174.7","s":0}],"b":[],"s":"BTC_USDT","t":1701245703443,"u":53095247701}}
{"time":1701245703,"time_ms":1701245703473,"channel":"futures.order_book_update","event":"update","result":{"U":53095247702,"a":[{"p":"38161.2","s":0},{"p":"38164","s":0},{"p":"38160","s":0}],"b":[{"p":"38140.9","s":0},{"p":"38139.6","s":10602},{"p":"38142","s":3184}],"s":"BTC_USDT","t":1701245703457,"u":53095247710}}
{"time":1701245703,"time_ms":1701245703571,"channel":"futures.order_book_update","event":"update","result":{"U":53095247711,"a":[{"p":"38153.1","s":9292},{"p":"38145.7","s":13224}],"b":[],"s":"BTC_USDT","t":1701245703550,"u":53095247721}}
{"time":1701245703,"time_ms":1701245703590,"channel":"futures.order_book_update","event":"update","result":{"U":53095247722,"a":[{"p":"38145.7","s":14224}],"b":[],"s":"BTC_USDT","t":1701245703577,"u":53095247723}}
{"time":1701245703,"time_ms":1701245703612,"channel":"futures.order_book_update","event":"update","result":{"U":53095247724,"a":[],"b":[{"p":"38136.5","s":0}],"s":"BTC_USDT","t":1701245703590,"u":53095247724}}
{"time":1701245703,"time_ms":1701245703812,"channel":"futures.order_book_update","event":"update","result":{"U":53095247725,"a":[{"p":"38160.5","s":0},{"p":"38164.5","s":0}],"b":[],"s":"BTC_USDT","t":1701245703802,"u":53095247731}}
{"time":1701245703,"time_ms":1701245703832,"channel":"futures.order_book_update","event":"update","result":{"U":53095247732,"a":[{"p":"38153.8","s":0}],"b":[],"s":"BTC_USDT","t":1701245703814,"u":53095247732}}
{"time":1701245703,"time_ms":1701245703871,"channel":"futures.order_book_update","event":"update","result":{"U":53095247733,"a":[],"b":[{"p":"38139.6","s":10602},{"p":"38140.9","s":0},{"p":"38142","s":2451},{"p":"38141.9","s":4886}],"s":"BTC_USDT","t":1701245703861,"u":53095247737}}
{"time":1701245703,"time_ms":1701245703897,"channel":"futures.order_book_update","event":"update","result":{"U":53095247738,"a":[{"p":"38157.5","s":0},{"p":"38153.5","s":0},{"p":"38164","s":0},{"p":"38160","s":0},{"p":"38156.1","s":0}],"b":[{"p":"38139.5","s":8912},{"p":"38145.6","s":239068},{"p":"38145.2","s":9650},{"p":"38141.7","s":15026},{"p":"38140.5","s":1315},{"p":"38143.2","s":0},{"p":"38142.5","s":0},{"p":"38139.4","s":1315}],"s":"BTC_USDT","t":1701245703874,"u":53095247754}}
{"time":1701245703,"time_ms":1701245703952,"channel":"futures.order_book_update","event":"update","result":{"U":53095247755,"a":[],"b":[{"p":"38141.9","s":4153},{"p":"38140.9","s":733},{"p":"38139.4","s":0}],"s":"BTC_USDT","t":1701245703927,"u":53095247757}}
{"time":1701245703,"time_ms":1701245703971,"channel":"futures.order_book_update","event":"update","result":{"U":53095247758,"a":[{"p":"38165.8","s":0}],"b":[{"p":"38104.7","s":0}],"s":"BTC_USDT","t":1701245703959,"u":53095247761}}
{"time":1701245703,"time_ms":1701245703994,"channel":"futures.order_book_update","event":"update","result":{"U":53095247762,"a":[],"b":[{"p":"38145.1","s":2},{"p":"38139.5","s":0},{"p":"38145.6","s":239068},{"p":"38145.2","s":9648}],"s":"BTC_USDT","t":1701245703984,"u":53095247771}}
{"time":1701245704,"time_ms":1701245704031,"channel":"futures.order_book_update","event":"update","result":{"U":53095247772,"a":[{"p":"38159.1","s":0},{"p":"38156.8","s":0},{"p":"38158","s":0},{"p":"38161.5","s":0}],"b":[{"p":"38142.2","s":0},{"p":"38142","s":0},{"p":"38139.6","s":10602},{"p":"38139.5","s":0},{"p":"38142.1","s":2174},{"p":"38142.3","s":2405}],"s":"BTC_USDT","t":1701245704022,"u":53095247785}}
{"time":1701245704,"time_ms":1701245704072,"channel":"futures.order_book_update","event":"update","result":{"U":53095247786,"a":[{"p":"38164.5","s":0},{"p":"38160.5","s":0},{"p":"38158.5","s":0}],"b":[],"s":"BTC_USDT","t":1701245704061,"u":53095247790}}
{"time":1701245704,"time_ms":1701245704111,"channel":"futures.order_book_update","event":"update","result":{"U":53095247791,"a":[],"b":[{"p":"38142.1","s":0},{"p":"38142.3","s":0},{"p":"38139.5","s":0},{"p":"38142.2","s":2419},{"p":"38142.4","s":2174}],"s":"BTC_USDT","t":1701245704101,"u":53095247796}}
{"time":1701245704,"time_ms":1701245704132,"channel":"futures.order_book_update","event":"update","result":{"U":53095247797,"a":[],"b":[{"p":"38142.2","s":4593},{"p":"38139.5","s":8912},{"p":"38142.4","s":0}],"s":"BTC_USDT","t":1701245704114,"u":53095247799}}
{"time":1701245704,"time_ms":1701245704233,"channel":"futures.order_book_update","event":"update","result":{"U":53095247800,"a":[],"b":[{"p":"38145.6","s":239062},{"p":"38139.4","s":0},{"p":"38145.1","s":2}],"s":"BTC_USDT","t":1701245704223,"u":53095247805}}
{"time":1701245704,"time_ms":1701245704252,"channel":"futures.order_book_update","event":"update","result":{"U":53095247806,"a":[],"b":[{"p":"38145.6","s":239068},{"p":"38138.2","s":0}],"s":"BTC_USDT","t":1701245704243,"u":53095247810}}
{"time":1701245704,"time_ms":1701245704274,"channel":"futures.order_book_update","event":"update","result":{"U":53095247811,"a":[{"p":"38156.2","s":0},{"p":"38157.5","s":0},{"p":"38161.6","s":0},{"p":"38156.8","s":0},{"p":"38161.4","s":0},{"p":"38156.1","s":0},{"p":"38172.7","s":0}],"b":[{"p":"38140.9","s":0},{"p":"38138.5","s":0},{"p":"38140.7","s":0},{"p":"38141","s":0},{"p":"38142","s":0},{"p":"38139.4","s":1315},{"p":"38139.2","s":1315},{"p":"38140.6","s":0}],"s":"BTC_USDT","t":1701245704265,"u":53095247837}}
{"time":1701245704,"time_ms":1701245704293,"channel":"futures.order_book_update","event":"update","result":{"U":53095247838,"a":[{"p":"38169.6","s":0}],"b":[{"p":"38142","s":733},{"p":"38139.2","s":0}],"s":"BTC_USDT","t":1701245704277,"u":53095247841}}
{"time":1701245704,"time_ms":1701245704311,"channel":"futures.order_book_update","event":"update","result":{"U":53095247842,"a":[{"p":"38159","s":0}],"b":[{"p":"38141","s":2175},{"p":"38139.4","s":0}],"s":"BTC_USDT","t":1701245704301,"u":53095247845}}
{"time":1701245704,"time_ms":1701245704411,"channel":"futures.order_book_update","event":"update","result":{"U":53095247846,"a":[{"p":"38152.2","s":1589},{"p":"38153.2","s":15000},{"p":"38152.9","s":0}],"b":[],"s":"BTC_USDT","t":1701245704400,"u":53095247847}}
{"time":1701245704,"time_ms":1701245704532,"channel":"futures.order_book_update","event":"update","result":{"U":53095247848,"a":[{"p":"38145.7","s":13224}],"b":[],"s":"BTC_USDT","t":1701245704524,"u":53095247849}}
{"time":1701245704,"time_ms":1701245704571,"channel":"futures.order_book_update","event":"update","result":{"U":53095247850,"a":[],"b":[{"p":"38104.9","s":0}],"s":"BTC_USDT","t":1701245704550,"u":53095247852}}
{"time":1701245704,"time_ms":1701245704632,"channel":"futures.order_book_update","event":"update","result":{"U":53095247853,"a":[{"p":"38159","s":0},{"p":"38158.5","s":0}],"b":[],"s":"BTC_USDT","t":1701245704614,"u":53095247856}}
{"time":1701245704,"time_ms":1701245704652,"channel":"futures.order_book_update","event":"update","result":{"U":53095247857,"a":[{"p":"38162.4","s":0}],"b":[{"p":"38132.6","s":0}],"s":"BTC_USDT","t":1701245704641,"u":53095247860}}
{"time":1701245704,"time_ms":1701245704713,"channel":"futures.order_book_update","event":"update","result":{"U":53095247861,"a":[{"p":"38159.3","s":0}],"b":[],"s":"BTC_USDT","t":1701245704697,"u":53095247862}}
{"time":1701245704,"time_ms":1701245704732,"channel":"futures.order_book_update","event":"update","result":{"U":53095247863,"a":[{"p":"38145.7","s":7000},{"p":"38158.4","s":0}],"b":[],"s":"BTC_USDT","t":1701245704725,"u":53095247864}}
{"time":1701245704,"time_ms":1701245704753,"channel":"futures.order_book_update","event":"update","result":{"U":53095247865,"a":[{"p":"38145.7","s":1500},{"p":"38161.9","s":0},{"p":"38157.8","s":0},{"p":"38159.6","s":0},{"p":"38159.8","s":0},{"p":"38159.3","s":0}],"b":[{"p":"38138.3","s":0}],"s":"BTC_USDT","t":1701245704744,"u":53095247889}}
{"time":1701245704,"time_ms":1701245704772,"channel":"futures.order_book_update","event":"update","result":{"U":53095247890,"a":[{"p":"38158.3","s":0},{"p":"38159.9","s":0},{"p":"38156.8","s":0},{"p":"38173","s":0}],"b":[{"p":"38139.4","s":1315},{"p":"38141.9","s":6327},{"p":"38141","s":0}],"s":"BTC_USDT","t":1701245704750,"u":53095247900}}
{"time":1701245704,"time_ms":1701245704811,"channel":"futures.order_book_update","event":"update","result":{"U":53095247901,"a":[{"p":"38159.9","s":0}],"b":[],"s":"BTC_USDT","t":1701245704795,"u":53095247904}}
{"time":1701245704,"time_ms":1701245704833,"channel":"futures.order_book_update","event":"update","result":{"U":53095247905,"a":[{"p":"38145.7","s":2372}],"b":[{"p":"38145.1","s":0},{"p":"38139.2","s":1315},{"p":"38145.6","s":239062}],"s":"BTC_USDT","t":1701245704814,"u":53095247910}}
{"time":1701245704,"time_ms":1701245704852,"channel":"futures.order_book_update","event":"update","result":{"U":53095247911,"a":[{"p":"38158.4","s":0},{"p":"38153.3","s":0}],"b":[{"p":"38141.9","s":4153},{"p":"38140.9","s":2175},{"p":"38139.2","s":0}],"s":"BTC_USDT","t":1701245704826,"u":53095247914}}
{"time":1701245704,"time_ms":1701245704872,"channel":"futures.order_book_update","event":"update","result":{"U":53095247915,"a":[],"b":[{"p":"38139.5","s":0},{"p":"38139.4","s":0},{"p":"38139.6","s":0},{"p":"38141.1","s":2},{"p":"38139.9","s":2},{"p":"38141.8","s":9024},{"p":"38142.6","s":2}],"s":"BTC_USDT","t":1701245704858,"u":53095247918}}
{"time":1701245704,"time_ms":1701245704892,"channel":"futures.order_book_update","event":"update","result":{"U":53095247919,"a":[{"p":"38145.7","s":1500},{"p":"38153.3","s":0}],"b":[],"s":"BTC_USDT","t":1701245704877,"u":53095247922}}
{"time":1701245704,"time_ms":1701245704914,"channel":"futures.order_book_update","event":"update","result":{"U":53095247923,"a":[],"b":[{"p":"38142.6","s":0},{"p":"38145","s":2},{"p":"38139.6","s":10602},{"p":"38139.5","s":8912},{"p":"38145.6","s":239066},{"p":"38139.9","s":0},{"p":"38141.1","s":0}],"s":"BTC_USDT","t":1701245704894,"u":53095247928}}
{"time":1701245704,"time_ms":1701245704933,"channel":"futures.order_book_update","event":"update","result":{"U":53095247929,"a":[],"b":[{"p":"38141.8","s":9022},{"p":"38145.6","s":239068}],"s":"BTC_USDT","t":1701245704922,"u":53095247932}}
{"time":1701245704,"time_ms":1701245704953,"channel":"futures.order_book_update","event":"update","result":{"U":53095247933,"a":[{"p":"38145.7","s":2372}],"b":[],"s":"BTC_USDT","t":1701245704943,"u":53095247939}}
{"time":1701245704,"time_ms":1701245704974,"channel":"futures.order_book_update","event":"update","result":{"U":53095247940,"a":[{"p":"38145.7","s":2406},{"p":"38160.3","s":0},{"p":"38160.4","s":0}],"b":[{"p":"38137.3","s":0}],"s":"BTC_USDT","t":1701245704962,"u":53095247951}}
{"time":1701245705,"time_ms":1701245705014,"channel":"futures.order_book_update","event":"update","result":{"U":53095247952,"a":[{"p":"38173.6","s":0},{"p":"38164","s":0},{"p":"38173","s":0},{"p":"38159.4","s":0},{"p":"38158.6","s":0},{"p":"38160","s":0}],"b":[{"p":"38142.3","s":2518},{"p":"38142.2","s":0},{"p":"38139.4","s":0},{"p":"38135.2","s":0}],"s":"BTC_USDT","t":1701245705006,"u":53095247967}}
{"time":1701245705,"time_ms":1701245705031,"channel":"futures.order_book_update","event":"update","result":{"U":53095247968,"a":[{"p":"38159.3","s":0},{"p":"38162.4","s":0},{"p":"38157.7","s":0}],"b":[{"p":"38139.4","s":1315},{"p":"38142","s":0},{"p":"38142.3","s":5425}],"s":"BTC_USDT","t":1701245705016,"u":53095247978}}
{"time":1701245705,"time_ms":1701245705051,"channel":"futures.order_book_update","event":"update","result":{"U":53095247979,"a":[{"p":"38145.7","s":2716},{"p":"38159.6","s":0}],"b":[{"p":"38139.1","s":0},{"p":"38138.5","s":0},{"p":"38133.6","s":0},{"p":"38138.9","s":0}],"s":"BTC_USDT","t":1701245705041,"u":53095247991}}
{"time":1701245705,"time_ms":1701245705073,"channel":"futures.order_book_update","event":"update","result":{"U":53095247992,"a":[{"p":"38163.5","s":0},{"p":"38159.5","s":0}],"b":[],"s":"BTC_USDT","t":1701245705056,"u":53095247996}}
{"time":1701245705,"time_ms":1701245705091,"channel":"futures.order_book_update","event":"update","result":{"U":53095247997,"a":[{"p":"38145.7","s":2406},{"p":"38158.4","s":0}],"b":[{"p":"38134.2","s":0}],"s":"BTC_USDT","t":1701245705079,"u":53095248000}}
{"time":1701245705,"time_ms":1701245705112,"channel":"futures.order_book_update","event":"update","result":{"U":53095248001,"a":[],"b":[{"p":"38142.3","s":4692},{"p":"38139.4","s":0},{"p":"38142","s":733}],"s":"BTC_USDT","t":1701245705098,"u":53095248003}}
{"time":1701245705,"time_ms":1701245705133,"channel":"futures.order_book_update","event":"update","result":{"U":53095248004,"a":[],"b":[{"p":"38135.9","s":0}],"s":"BTC_USDT","t":1701245705106,"u":53095248005}}
{"time":1701245705,"time_ms":1701245705153,"channel":"futures.order_book_update","event":"update","result":{"U":53095248006,"a":[{"p":"38170.6","s":0},{"p":"38161.5","s":0},{"p":"38165.1","s":0}],"b":[],"s":"BTC_USDT","t":1701245705143,"u":53095248008}}
{"time":1701245705,"time_ms":1701245705171,"channel":"futures.order_book_update","event":"update","result":{"U":53095248009,"a":[{"p":"38145.7","s":3250},{"p":"38163","s":0},{"p":"38158.3","s":0},{"p":"38159","s":0}],"b":[{"p":"38139.4","s":1315},{"p":"38139.5","s":0},{"p":"38135.6","s":0},{"p":"38128","s":0},{"p":"38135.5","s":0}],"s":"BTC_USDT","t":1701245705161,"u":53095248023}}
{"time":1701245705,"time_ms":1701245705194,"channel":"futures.order_book_update","event":"update","result":{"U":53095248024,"a":[{"p":"38163","s":0},{"p":"38159.5","s":0},{"p":"38163.5","s":0},{"p":"38156.8","s":0},{"p":"38162.2","s":0},{"p":"38159.3","s":0},{"p":"38145.7","s":4250}],"b":[],"s":"BTC_USDT","t":1701245705188,"u":53095248037}}
{"time":1701245705,"time_ms":1701245705213,"channel":"futures.order_book_update","event":"update","result":{"U":53095248038,"a":[{"p":"38159","s":0}],"b":[{"p":"38135.7","s":0}],"s":"BTC_USDT","t":1701245705192,"u":53095248040}}
{"time":1701245705,"time_ms":1701245705252,"channel":"futures.order_book_update","event":"update","result":{"U":53095248041,"a":[{"p":"38171.5","s":0},{"p":"38145.7","s":6176},{"p":"38162.5","s":0},{"p":"38158.9","s":0},{"p":"38159.4","s":0}],"b":[{"p":"38141","s":733},{"p":"38140.9","s":0},{"p":"38142.3","s":2518},{"p":"38142.1","s":2174},{"p":"38140.6","s":2175},{"p":"38139.4","s":0},{"p":"38142","s":0},{"p":"38138.5","s":0},{"p":"38140.1","s":0}],"s":"BTC_USDT","t":1701245705245,"u":53095248062}}
{"time":1701245705,"time_ms":1701245705273,"channel":"futures.order_book_update","event":"update","result":{"U":53095248063,"a":[{"p":"38156.1","s":0},{"p":"38167.8","s":0},{"p":"38158.5","s":0}],"b":[{"p":"38145.6","s":213973},{"p":"38140.1","s":2175},{"p":"38140.6","s":0},{"p":"38139.4","s":0}],"s":"BTC_USDT","t":1701245705255,"u":53095248071}}
{"time":1701245705,"time_ms":1701245705293,"channel":"futures.order_book_update","event":"update","result":{"U":53095248072,"a":[{"p":"38158","s":0},{"p":"38157.7","s":0},{"p":"38145.7","s":6676},{"p":"38158.3","s":0},{"p":"38162","s":0},{"p":"38173.4","s":0},{"p":"38161.5","s":0},{"p":"38155.6","s":0}],"b":[{"p":"38139.6","s":10602},{"p":"38141","s":2175},{"p":"38140.6","s":733},{"p":"38142.1","s":0},{"p":"38137.9","s":0},{"p":"38139.4","s":0},{"p":"38145.6","s":196542},{"p":"38139.9","s":2175},{"p":"38140.1","s":0},{"p":"38137.5","s":0},{"p":"38135.2","s":0}],"s":"BTC_USDT","t":1701245705286,"u":53095248101}}
{"time":1701245705,"time_ms":1701245705314,"channel":"futures.order_book_update","event":"update","result":{"U":53095248102,"a":[{"p":"38162.5","s":0},{"p":"38164.2","s":0},{"p":"38170","s":0},{"p":"38149.9","s":29682},{"p":"38169.5","s":0},{"p":"38155.2","s":0},{"p":"38158.5","s":0}],"b":[{"p":"38143.1","s":524},{"p":"38141.8","s":11319},{"p":"38145.6","s":166873},{"p":"38142.3","s":0},{"p":"38139.6","s":10602},{"p":"38136.3","s":0},{"p":"38131.3","s":0}],"s":"BTC_USDT","t":1701245705303,"u":53095248126}}
{"time":1701245705,"time_ms":1701245705332,"channel":"futures.order_book_update","event":"update","result":{"U":53095248127,"a":[{"p":"38145.7","s":8676}],"b":[{"p":"38145.6","s":144628}],"s":"BTC_USDT","t":1701245705324,"u":53095248131}}
{"time":1701245705,"time_ms":1701245705360,"channel":"futures.order_book_update","event":"update","result":{"U":53095248132,"a":[{"p":"38145.7","s":12676},{"p":"38152.4","s":3634},{"p":"38167.7","s":0},{"p":"38156.8","s":0},{"p":"38160.5","s":0}],"b":[{"p":"38141.1","s":4522},{"p":"38141","s":0},{"p":"38139.4","s":0},{"p":"38134.3","s":0},{"p":"38141.8","s":9022},{"p":"38129.8","s":0},{"p":"38142","s":0},{"p":"38117.5","s":0},{"p":"38145.6","s":146848}],"s":"BTC_USDT","t":1701245705348,"u":53095248160}}
{"time":1701245705,"time_ms":1701245705374,"channel":"futures.order_book_update","event":"update","result":{"U":53095248161,"a":[{"p":"38153","s":2208},{"p":"38161","s":0},{"p":"38155","s":0},{"p":"38145.7","s":19970},{"p":"38152.2","s":935},{"p":"38165.3","s":0},{"p":"38170.8","s":0},{"p":"38159","s":0},{"p":"38167","s":0},{"p":"38154.7","s":0},{"p":"38157","s":0}],"b":[{"p":"38129.1","s":0},{"p":"38134.8","s":0},{"p":"38145.6","s":140453},{"p":"38139.4","s":1315},{"p":"38139.2","s":1315},{"p":"38143.1","s":0},{"p":"38145","s":0},{"p":"38126.3","s":0},{"p":"38139.1","s":0}],"s":"BTC_USDT","t":1701245705363,"u":53095248193}}
{"time":1701245705,"time_ms":1701245705392,"channel":"futures.order_book_update","event":"update","result":{"U":53095248194,"a":[{"p":"38150.6","s":3633},{"p":"38153.3","s":0},{"p":"38158.3","s":0},{"p":"38165.8","s":0},{"p":"38153.2","s":0},{"p":"38179.7","s":0},{"p":"38185.2","s":0},{"p":"38156.2","s":0},{"p":"38156.4","s":0},{"p":"38159.3","s":0},{"p":"38156.8","s":0}],"b":[{"p":"38145.6","s":136673},{"p":"38139.1","s":2175},{"p":"38139","s":2572},{"p":"38144","s":0},{"p":"38139.9","s":0},{"p":"38133.3","s":0},{"p":"38140.1","s":2175},{"p":"38138.9","s":7784},{"p":"38141.1","s":0},{"p":"38140.6","s":0},{"p":"38102.1","s":0},{"p":"38137","s":0},{"p":"38139.7","s":0}],"s":"BTC_USDT","t":1701245705382,"u":53095248238}}
{"time":1701245705,"time_ms":1701245705414,"channel":"futures.order_book_update","event":"update","result":{"U":53095248239,"a":[{"p":"38157.7","s":0},{"p":"38153","s":0},{"p":"38167.2","s":0},{"p":"38165","s":0},{"p":"38157.2","s":0},{"p":"38169","s":0},{"p":"38150.1","s":609},{"p":"38149.7","s":2},{"p":"38153.1","s":0},{"p":"38164.6","s":0},{"p":"38153.3","s":0},{"p":"38152.5","s":2090},{"p":"38157.5","s":0},{"p":"38164","s":0},{"p":"38155.7","s":0},{"p":"38161.5","s":0}],"b":[{"p":"38135.2","s":0},{"p":"38127","s":0},{"p":"38139","s":1315},{"p":"38138.8","s":1458},{"p":"38139.1","s":0},{"p":"38050.6","s":0},{"p":"38135","s":0},{"p":"38120.8","s":0},{"p":"38145.5","s":206},{"p":"38138.4","s":78},{"p":"38140.1","s":0},{"p":"38130.4","s":0},{"p":"38109.8","s":0}],"s":"BTC_USDT","t":1701245705402,"u":53095248284}}
{"time":1701245705,"time_ms":1701245705432,"channel":"futures.order_book_update","event":"update","result":{"U":53095248285,"a":[{"p":"38152.5","s":0},{"p":"38157.7","s":0},{"p":"38161.5","s":0},{"p":"38167.5","s":0},{"p":"38152.3","s":2174},{"p":"38150.6","s":10840},{"p":"38149.8","s":2174},{"p":"38152.4","s":0},{"p":"38171.1","s":0},{"p":"38159.7","s":0},{"p":"38153.9","s":0},{"p":"38165.4","s":0}],"b":[{"p":"38139.1","s":2317},{"p":"38138.4","s":0},{"p":"38137","s":0},{"p":"38138.2","s":0},{"p":"38090.1","s":0},{"p":"38145.6","s":135998},{"p":"38145.2","s":6967}],"s":"BTC_USDT","t":1701245705423,"u":53095248316}}
{"time":1701245705,"time_ms":1701245705454,"channel":"futures.order_book_update","event":"update","result":{"U":53095248317,"a":[{"p":"38148.8","s":206},{"p":"38151.8","s":3340},{"p":"38152.2","s":0},{"p":"38150.8","s":0},{"p":"38154","s":0},{"p":"38152.3","s":0},{"p":"38155.2","s":0},{"p":"38160.7","s":0},{"p":"38153","s":0}],"b":[{"p":"38145.2","s":9648},{"p":"38138.4","s":78},{"p":"38139.1","s":0},{"p":"38132.3","s":0},{"p":"38134.3","s":0}],"s":"BTC_USDT","t":1701245705447,"u":53095248351}}
{"time":1701245705,"time_ms":1701245705471,"channel":"futures.order_book_update","event":"update","result":{"U":53095248352,"a":[{"p":"38186.7","s":0},{"p":"38149.8","s":5514},{"p":"38152.2","s":935},{"p":"38151.7","s":2010},{"p":"38151.8","s":0},{"p":"38151.9","s":0},{"p":"38184.8","s":0},{"p":"38152","s":1052}],"b":[{"p":"38145.2","s":6967},{"p":"38145.6","s":115718},{"p":"38127.7","s":0},{"p":"38138.1","s":0},{"p":"38138","s":0}],"s":"BTC_USDT","t":1701245705464,"u":53095248369}}
{"time":1701245705,"time_ms":1701245705493,"channel":"futures.order_book_update","event":"update","result":{"U":53095248370,"a":[{"p":"38149.5","s":3340},{"p":"38152.2","s":0},{"p":"38151.8","s":0},{"p":"38176.5","s":0},{"p":"38156.2","s":0},{"p":"38151.7","s":638},{"p":"38145.7","s":34970},{"p":"38149.8","s":2174}],"b":[{"p":"38145.6","s":115118},{"p":"38137","s":0},{"p":"38133.7","s":0}],"s":"BTC_USDT","t":1701245705483,"u":53095248393}}
{"time":1701245705,"time_ms":1701245705511,"channel":"futures.order_book_update","event":"update","result":{"U":53095248394,"a":[{"p":"38159","s":0},{"p":"38162.4","s":0},{"p":"38164.7","s":0},{"p":"38151.7","s":1932},{"p":"38149.5","s":0},{"p":"38152.2","s":0},{"p":"38162.3","s":0},{"p":"38145.7","s":19970},{"p":"38151.9","s":3340}],"b":[{"p":"38145.6","s":115648},{"p":"38130.5","s":0},{"p":"38136.9","s":0}],"s":"BTC_USDT","t":1701245705502,"u":53095248420}}
{"time":1701245705,"time_ms":1701245705532,"channel":"futures.order_book_update","event":"update","result":{"U":53095248421,"a":[{"p":"38152.2","s":0},{"p":"38152","s":1052},{"p":"38154.5","s":0},{"p":"38150","s":61061},{"p":"38151.7","s":1933},{"p":"38162.3","s":0},{"p":"38149.8","s":2174},{"p":"38151.6","s":0}],"b":[{"p":"38138.4","s":0},{"p":"38141.4","s":524},{"p":"38145.6","s":116148}],"s":"BTC_USDT","t":1701245705520,"u":53095248435}}
{"time":1701245705,"time_ms":1701245705552,"channel":"futures.order_book_update","event":"update","result":{"U":53095248436,"a":[],"b":[{"p":"38135.9","s":0}],"s":"BTC_USDT","t":1701245705541,"u":53095248438}}
{"time":1701245705,"time_ms":1701245705576,"channel":"futures.order_book_update","event":"update","result":{"U":53095248439,"a":[],"b":[{"p":"38139","s":10227}],"s":"BTC_USDT","t":1701245705563,"u":53095248443}}
{"time":1701245705,"time_ms":1701245705594,"channel":"futures.order_book_update","event":"update","result":{"U":53095248444,"a":[{"p":"38155","s":0}],"b":[],"s":"BTC_USDT","t":1701245705582,"u":53095248447}}
{"time":1701245705,"time_ms":1701245705613,"channel":"futures.order_book_update","event":"update","result":{"U":53095248448,"a":[{"p":"38159","s":0}],"b":[{"p":"38145.6","s":116218}],"s":"BTC_USDT","t":1701245705594,"u":53095248454}}
{"time":1701245705,"time_ms":1701245705632,"channel":"futures.order_book_update","event":"update","result":{"U":53095248455,"a":[{"p":"38151.1","s":2},{"p":"38149.7","s":0},{"p":"38152.2","s":0}],"b":[{"p":"38145.2","s":9648}],"s":"BTC_USDT","t":1701245705620,"u":53095248457}}
{"time":1701245705,"time_ms":1701245705673,"channel":"futures.order_book_update","event":"update","result":{"U":53095248458,"a":[{"p":"38160","s":0}],"b":[],"s":"BTC_USDT","t":1701245705642,"u":53095248458}}
{"time":1701245705,"time_ms":1701245705695,"channel":"futures.order_book_update","event":"update","result":{"U":53095248459,"a":[{"p":"38151.9","s":0},{"p":"38152.5","s":0},{"p":"38152.2","s":935},{"p":"38151.6","s":2174},{"p":"38149.8","s":0},{"p":"38152","s":1052},{"p":"38151.5","s":1305},{"p":"38151.7","s":0},{"p":"38154.9","s":0}],"b":[{"p":"38115.1","s":0}],"s":"BTC_USDT","t":1701245705685,"u":53095248469}}
{"time":1701245705,"time_ms":1701245705712,"channel":"futures.order_book_update","event":"update","result":{"U":53095248470,"a":[{"p":"38164","s":0}],"b":[],"s":"BTC_USDT","t":1701245705689,"u":53095248471}}
{"time":1701245705,"time_ms":1701245705752,"channel":"futures.order_book_update","event":"update","result":{"U":53095248472,"a":[{"p":"38152.3","s":2174},{"p":"38150.1","s":0}],"b":[],"s":"BTC_USDT","t":1701245705733,"u":53095248473}}
{"time":1701245705,"time_ms":1701245705774,"channel":"futures.order_book_update","event":"update","result":{"U":53095248474,"a":[{"p":"38152.4","s":7235},{"p":"38152.5","s":79},{"p":"38152.3","s":0},{"p":"38151.1","s":0}],"b":[],"s":"BTC_USDT","t":1701245705760,"u":53095248476}}
{"time":1701245705,"time_ms":1701245705792,"channel":"futures.order_book_update","event":"update","result":{"U":53095248477,"a":[{"p":"38152","s":1054}],"b":[{"p":"38145.2","s":10303},{"p":"38132.3","s":0}],"s":"BTC_USDT","t":1701245705784,"u":53095248482}}
{"time":1701245705,"time_ms":1701245705834,"channel":"futures.order_book_update","event":"update","result":{"U":53095248483,"a":[{"p":"38162.8","s":0},{"p":"38168.3","s":0}],"b":[],"s":"BTC_USDT","t":1701245705809,"u":53095248487}}
{"time":1701245705,"time_ms":1701245705852,"channel":"futures.order_book_update","event":"update","result":{"U":53095248488,"a":[{"p":"38160","s":0},{"p":"38156","s":0},{"p":"38152.5","s":2090}],"b":[],"s":"BTC_USDT","t":1701245705842,"u":53095248493}}
{"time":1701245705,"time_ms":1701245705914,"channel":"futures.order_book_update","event":"update","result":{"U":53095248494,"a":[{"p":"38155.4","s":0}],"b":[],"s":"BTC_USDT","t":1701245705885,"u":53095248498}}
{"time":1701245705,"time_ms":1701245705952,"channel":"futures.order_book_update","event":"update","result":{"U":53095248499,"a":[{"p":"38159.6","s":0}],"b":[],"s":"BTC_USDT","t":1701245705942,"u":53095248499}}
{"time":1701245705,"time_ms":1701245705973,"channel":"futures.order_book_update","event":"update","result":{"U":53095248500,"a":[],"b":[{"p":"38140.6","s":2},{"p":"38138.8","s":0},{"p":"38138.9","s":0},{"p":"38139.8","s":3841},{"p":"38141.3","s":2}],"s":"BTC_USDT","t":1701245705957,"u":53095248504}}
{"time":1701245706,"time_ms":1701245706034,"channel":"futures.order_book_update","event":"update","result":{"U":53095248505,"a":[{"p":"38153.3","s":0},{"p":"38152.9","s":0},{"p":"38161.4","s":0},{"p":"38152","s":1052},{"p":"38151.6","s":0},{"p":"38156.2","s":0},{"p":"38156.4","s":0},{"p":"38151.9","s":2174},{"p":"38152.5","s":2090}],"b":[{"p":"38130.5","s":0},{"p":"38132.9","s":0},{"p":"38137.4","s":0},{"p":"38135.9","s":0},{"p":"38137.9","s":0},{"p":"38136.5","s":0}],"s":"BTC_USDT","t":1701245706027,"u":53095248533}}
{"time":1701245706,"time_ms":1701245706052,"channel":"futures.order_book_update","event":"update","result":{"U":53095248534,"a":[{"p":"38151.5","s":1959}],"b":[{"p":"38144","s":100},{"p":"38139","s":0},{"p":"38138","s":0}],"s":"BTC_USDT","t":1701245706043,"u":53095248537}}
{"time":1701245706,"time_ms":1701245706074,"channel":"futures.order_book_update","event":"update","result":{"U":53095248538,"a":[{"p":"38152","s":1054}],"b":[{"p":"38144","s":200},{"p":"38138","s":0}],"s":"BTC_USDT","t":1701245706058,"u":53095248544}}
{"time":1701245706,"time_ms":1701245706094,"channel":"futures.order_book_update","event":"update","result":{"U":53095248545,"a":[{"p":"38153","s":0}],"b":[],"s":"BTC_USDT","t":1701245706086,"u":53095248546}}
{"time":1701245706,"time_ms":1701245706112,"channel":"futures.order_book_update","event":"update","result":{"U":53095248547,"a":[{"p":"38156.4","s":0},{"p":"38153.6","s":0}],"b":[{"p":"38138.2","s":0},{"p":"38138.9","s":0},{"p":"38137.9","s":0}],"s":"BTC_USDT","t":1701245706105,"u":53095248558}}
{"time":1701245706,"time_ms":1701245706134,"channel":"futures.order_book_update","event":"update","result":{"U":53095248559,"a":[{"p":"38156.3","s":0},{"p":"38145.7","s":14676},{"p":"38152.9","s":0},{"p":"38156.8","s":0}],"b":[{"p":"38136.5","s":0},{"p":"38138.3","s":0},{"p":"38136.8","s":0}],"s":"BTC_USDT","t":1701245706124,"u":53095248573}}
{"time":1701245706,"time_ms":1701245706152,"channel":"futures.order_book_update","event":"update","result":{"U":53095248574,"a":[{"p":"38152.1","s":0},{"p":"38161.2","s":0},{"p":"38152.5","s":2090},{"p":"38152.8","s":788},{"p":"38152","s":1052},{"p":"38151.9","s":0},{"p":"38155.5","s":0},{"p":"38153.5","s":0},{"p":"38167","s":0},{"p":"38159.5","s":0},{"p":"38156.8","s":0},{"p":"38153.6","s":0},{"p":"38159.2","s":0}],"b":[{"p":"38139.7","s":2325},{"p":"38139","s":0},{"p":"38138.7","s":0},{"p":"38139.1","s":0},{"p":"38145.6","s":116224},{"p":"38144.9","s":2},{"p":"38139.3","s":2175},{"p":"38139.2","s":0},{"p":"38139.8","s":3839},{"p":"38140.6","s":0},{"p":"38138","s":0},{"p":"38141.3","s":0},{"p":"38133.3","s":0},{"p":"38137.4","s":0},{"p":"38138.9","s":0},{"p":"38130.6","s":0},{"p":"38137","s":0}],"s":"BTC_USDT","t":1701245706142,"u":53095248614}}
{"time":1701245706,"time_ms":1701245706172,"channel":"futures.order_book_update","event":"update","result":{"U":53095248615,"a":[{"p":"38158.6","s":0},{"p":"38151.4","s":635},{"p":"38151.5","s":654},{"p":"38152.8","s":0},{"p":"38154.2","s":0},{"p":"38154","s":0},{"p":"38153","s":0}],"b":[{"p":"38139.1","s":0},{"p":"38138.2","s":0},{"p":"38132.2","s":0},{"p":"38134.4","s":0},{"p":"38139.2","s":1315},{"p":"38139.3","s":0},{"p":"38138","s":0}],"s":"BTC_USDT","t":1701245706161,"u":53095248635}}
{"time":1701245706,"time_ms":1701245706193,"channel":"futures.order_book_update","event":"update","result":{"U":53095248636,"a":[{"p":"38152.3","s":2174},{"p":"38152.5","s":0},{"p":"38155","s":0},{"p":"38152.8","s":0}],"b":[],"s":"BTC_USDT","t":1701245706183,"u":53095248639}}
{"time":1701245706,"time_ms":1701245706254,"channel":"futures.order_book_update","event":"update","result":{"U":53095248640,"a":[{"p":"38161.5","s":0},{"p":"38157.5","s":0}],"b":[{"p":"38139","s":10227},{"p":"38145.6","s":116218},{"p":"38144.9","s":0}],"s":"BTC_USDT","t":1701245706242,"u":53095248648}}
{"time":1701245706,"time_ms":1701245706272,"channel":"futures.order_book_update","event":"update","result":{"U":53095248649,"a":[],"b":[{"p":"38145.6","s":116224},{"p":"38144.9","s":2},{"p":"38139","s":0}],"s":"BTC_USDT","t":1701245706253,"u":53095248652}}
{"time":1701245706,"time_ms":1701245706291,"channel":"futures.order_book_update","event":"update","result":{"U":53095248653,"a":[{"p":"38161","s":0},{"p":"38157","s":0}],"b":[],"s":"BTC_USDT","t":1701245706273,"u":53095248656}}
{"time":1701245706,"time_ms":1701245706354,"channel":"futures.order_book_update","event":"update","result":{"U":53095248657,"a":[{"p":"38169.5","s":0},{"p":"38157","s":0},{"p":"38156.5","s":0},{"p":"38153.5","s":0},{"p":"38160.5","s":0}],"b":[],"s":"BTC_USDT","t":1701245706334,"u":53095248666}}
{"time":1701245706,"time_ms":1701245706373,"channel":"futures.order_book_update","event":"update","result":{"U":53095248667,"a":[{"p":"38158.4","s":0}],"b":[],"s":"BTC_USDT","t":1701245706343,"u":53095248667}}
{"time":1701245706,"time_ms":1701245706392,"channel":"futures.order_book_update","event":"update","result":{"U":53095248668,"a":[{"p":"38157.7","s":0}],"b":[{"p":"38139.5","s":2175},{"p":"38139.2","s":0},{"p":"38138.3","s":0}],"s":"BTC_USDT","t":1701245706385,"u":53095248672}}
{"time":1701245706,"time_ms":1701245706412,"channel":"futures.order_book_update","event":"update","result":{"U":53095248673,"a":[{"p":"38152.5","s":2090},{"p":"38152.3","s":0},{"p":"38153.9","s":0}],"b":[{"p":"38134","s":0},{"p":"38128.1","s":0}],"s":"BTC_USDT","t":1701245706395,"u":53095248680}}
{"time":1701245706,"time_ms":1701245706553,"channel":"futures.order_book_update","event":"update","result":{"U":53095248681,"a":[{"p":"38157.6","s":0}],"b":[],"s":"BTC_USDT","t":1701245706543,"u":53095248682}}
{"time":1701245706,"time_ms":1701245706613,"channel":"futures.order_book_update","event":"update","result":{"U":53095248683,"a":[],"b":[{"p":"38139.2","s":1315},{"p":"38139.5","s":0},{"p":"38095.6","s":0},{"p":"38135.1","s":0}],"s":"BTC_USDT","t":1701245706592,"u":53095248687}}
{"time":1701245706,"time_ms":1701245706651,"channel":"futures.order_book_update","event":"update","result":{"U":53095248688,"a":[],"b":[{"p":"38126.6","s":0}],"s":"BTC_USDT","t":1701245706638,"u":53095248690}}
{"time":1701245706,"time_ms":1701245706672,"channel":"futures.order_book_update","event":"update","result":{"U":53095248691,"a":[],"b":[{"p":"38145.6","s":116218},{"p":"38139","s":10227},{"p":"38144.9","s":0}],"s":"BTC_USDT","t":1701245706660,"u":53095248695}}
{"time":1701245706,"time_ms":1701245706712,"channel":"futures.order_book_update","event":"update","result":{"U":53095248696,"a":[],"b":[{"p":"38145.6","s":116224},{"p":"38144.9","s":2},{"p":"38139","s":0}],"s":"BTC_USDT","t":1701245706689,"u":53095248700}}
{"time":1701245706,"time_ms":1701245706770,"channel":"futures.order_book_update","event":"update","result":{"U":53095248701,"a":[{"p":"38156.9","s":0}],"b":[],"s":"BTC_USDT","t":1701245706755,"u":53095248703}}
{"time":1701245706,"time_ms":1701245706854,"channel":"futures.order_book_update","event":"update","result":{"U":53095248704,"a":[{"p":"38160","s":0},{"p":"38155.5","s":0},{"p":"38159.5","s":0},{"p":"38156","s":0}],"b":[],"s":"BTC_USDT","t":1701245706841,"u":53095248711}}
{"time":1701245706,"time_ms":1701245706933,"channel":"futures.order_book_update","event":"update","result":{"U":53095248712,"a":[],"b":[{"p":"38139","s":10227},{"p":"38145.6","s":116218},{"p":"38144.9","s":0}],"s":"BTC_USDT","t":1701245706915,"u":53095248716}}
{"time":1701245706,"time_ms":1701245706952,"channel":"futures.order_book_update","event":"update","result":{"U":53095248717,"a":[],"b":[{"p":"38139","s":0},{"p":"38144.8","s":2},{"p":"38145.6","s":116224}],"s":"BTC_USDT","t":1701245706943,"u":53095248722}}
{"time":1701245707,"time_ms":1701245707032,"channel":"futures.order_book_update","event":"update","result":{"U":53095248723,"a":[{"p":"38154.5","s":0},{"p":"38152.7","s":0},{"p":"38158.9","s":0},{"p":"38154.4","s":0},{"p":"38153.6","s":0},{"p":"38162.6","s":0},{"p":"38154.7","s":0}],"b":[{"p":"38145.6","s":116220},{"p":"38144.8","s":0},{"p":"38139.7","s":0},{"p":"38133.9","s":0},{"p":"38131.4","s":0},{"p":"38134.4","s":0},{"p":"38139.5","s":2297},{"p":"38139","s":10227}],"s":"BTC_USDT","t":1701245707023,"u":53095248745}}
{"time":1701245707,"time_ms":1701245707052,"channel":"futures.order_book_update","event":"update","result":{"U":53095248746,"a":[{"p":"38153.9","s":0},{"p":"38154","s":0}],"b":[{"p":"38145.6","s":116224}],"s":"BTC_USDT","t":1701245707042,"u":53095248752}}
{"time":1701245707,"time_ms":1701245707072,"channel":"futures.order_book_update","event":"update","result":{"U":53095248753,"a":[],"b":[{"p":"38144.7","s":2},{"p":"38139","s":0}],"s":"BTC_USDT","t":1701245707061,"u":53095248754}}
{"time":1701245707,"time_ms":1701245707152,"channel":"futures.order_book_update","event":"update","result":{"U":53095248755,"a":[{"p":"38152.3","s":0},{"p":"38158.2","s":0},{"p":"38152.7","s":0},{"p":"38152.5","s":2090}],"b":[{"p":"38139.3","s":2315},{"p":"38139.5","s":0},{"p":"38139","s":0}],"s":"BTC_USDT","t":1701245707138,"u":53095248761}}
{"time":1701245707,"time_ms":1701245707311,"channel":"futures.order_book_update","event":"update","result":{"U":53095248762,"a":[{"p":"38153.9","s":0},{"p":"38158.1","s":0},{"p":"38153.6","s":0},{"p":"38157.6","s":0}],"b":[{"p":"38145.6","s":116218},{"p":"38139","s":10227},{"p":"38144.7","s":0},{"p":"38138.5","s":0},{"p":"38133.7","s":0}],"s":"BTC_USDT","t":1701245707300,"u":53095248781}}
{"time":1701245707,"time_ms":1701245707332,"channel":"futures.order_book_update","event":"update","result":{"U":53095248782,"a":[],"b":[{"p":"38142.5","s":2},{"p":"38141.8","s":9024},{"p":"38139.2","s":0},{"p":"38139","s":0},{"p":"38138.7","s":0},{"p":"38138.5","s":0},{"p":"38141","s":2},{"p":"38139.8","s":3841}],"s":"BTC_USDT","t":1701245707323,"u":53095248788}}
{"time":1701245707,"time_ms":1701245707371,"channel":"futures.order_book_update","event":"update","result":{"U":53095248789,"a":[{"p":"38156.2","s":0}],"b":[],"s":"BTC_USDT","t":1701245707345,"u":53095248790}}
{"time":1701245707,"time_ms":1701245707393,"channel":"futures.order_book_update","event":"update","result":{"U":53095248791,"a":[{"p":"38153.2","s":0},{"p":"38155.5","s":0},{"p":"38159.5","s":0}],"b":[{"p":"38139.3","s":2315},{"p":"38141.8","s":9022},{"p":"38141","s":0},{"p":"38145.6","s":116224},{"p":"38144.7","s":2},{"p":"38142.5","s":0},{"p":"38125.3","s":0},{"p":"38136.7","s":0},{"p":"38139.2","s":1315},{"p":"38139.8","s":3839}],"s":"BTC_USDT","t":1701245707368,"u":53095248806}}
{"time":1701245707,"time_ms":1701245707412,"channel":"futures.order_book_update","event":"update","result":{"U":53095248807,"a":[{"p":"38152.7","s":0},{"p":"38154.3","s":0},{"p":"38153.9","s":0},{"p":"38161.9","s":0},{"p":"38157.7","s":0},{"p":"38154.2","s":0}],"b":[{"p":"38145.6","s":119369},{"p":"38139.9","s":0},{"p":"38137.4","s":0},{"p":"38138.6","s":0},{"p":"38138.2","s":0},{"p":"38139.2","s":1315},{"p":"38138.7","s":0},{"p":"38139.3","s":2908}],"s":"BTC_USDT","t":1701245707402,"u":53095248831}}
{"time":1701245707,"time_ms":1701245707430,"channel":"futures.order_book_update","event":"update","result":{"U":53095248832,"a":[{"p":"38158.6","s":0}],"b":[{"p":"38137.9","s":0},{"p":"38139.5","s":2313},{"p":"38139.3","s":0},{"p":"38139.2","s":1315}],"s":"BTC_USDT","t":1701245707406,"u":53095248839}}
{"time":1701245707,"time_ms":1701245707451,"channel":"futures.order_book_update","event":"update","result":{"U":53095248840,"a":[{"p":"38152.6","s":0},{"p":"38153","s":0}],"b":[],"s":"BTC_USDT","t":1701245707427,"u":53095248842}}
{"time":1701245707,"time_ms":1701245707494,"channel":"futures.order_book_update","event":"update","result":{"U":53095248843,"a":[{"p":"38158","s":0}],"b":[],"s":"BTC_USDT","t":1701245707467,"u":53095248843}}
{"time":1701245707,"time_ms":1701245707513,"channel":"futures.order_book_update","event":"update","result":{"U":53095248844,"a":[{"p":"38155","s":0}],"b":[{"p":"38138.7","s":0}],"s":"BTC_USDT","t":1701245707503,"u":53095248847}}
{"time":1701245707,"time_ms":1701245707753,"channel":"futures.order_book_update","event":"update","result":{"U":53095248848,"a":[{"p":"38156","s":0}],"b":[],"s":"BTC_USDT","t":1701245707744,"u":53095248849}}
{"time":1701245707,"time_ms":1701245707774,"channel":"futures.order_book_update","event":"update","result":{"U":53095248850,"a":[{"p":"38160","s":0}],"b":[],"s":"BTC_USDT","t":1701245707759,"u":53095248851}}
{"time":1701245707,"time_ms":1701245707792,"channel":"futures.order_book_update","event":"update","result":{"U":53095248852,"a":[],"b":[{"p":"38135.2","s":0}],"s":"BTC_USDT","t":1701245707779,"u":53095248854}}
{"time":1701245707,"time_ms":1701245707812,"channel":"futures.order_book_update","event":"update","result":{"U":53095248855,"a":[{"p":"38155.5","s":0},{"p":"38159.5","s":0}],"b":[],"s":"BTC_USDT","t":1701245707798,"u":53095248858}}
{"time":1701245707,"time_ms":1701245707832,"channel":"futures.order_book_update","event":"update","result":{"U":53095248859,"a":[],"b":[{"p":"38139.5","s":11225},{"p":"38139","s":0},{"p":"38135","s":0}],"s":"BTC_USDT","t":1701245707814,"u":53095248864}}
{"time":1701245707,"time_ms":1701245707893,"channel":"futures.order_book_update","event":"update","result":{"U":53095248865,"a":[{"p":"38152.5","s":79}],"b":[],"s":"BTC_USDT","t":1701245707884,"u":53095248865}}
{"time":1701245707,"time_ms":1701245707912,"channel":"futures.order_book_update","event":"update","result":{"U":53095248866,"a":[{"p":"38155","s":0}],"b":[],"s":"BTC_USDT","t":1701245707890,"u":53095248868}}
{"time":1701245707,"time_ms":1701245707995,"channel":"futures.order_book_update","event":"update","result":{"U":53095248869,"a":[{"p":"38171.4","s":0},{"p":"38154.2","s":0}],"b":[],"s":"BTC_USDT","t":1701245707985,"u":53095248878}}
{"time":1701245708,"time_ms":1701245708032,"channel":"futures.order_book_update","event":"update","result":{"U":53095248879,"a":[{"p":"38162.6","s":0},{"p":"38154.6","s":0},{"p":"38154.8","s":0}],"b":[{"p":"38138.7","s":0},{"p":"38134.1","s":0},{"p":"38138.2","s":0}],"s":"BTC_USDT","t":1701245708013,"u":53095248900}}
{"time":1701245708,"time_ms":1701245708052,"channel":"futures.order_book_update","event":"update","result":{"U":53095248901,"a":[{"p":"38154.1","s":0},{"p":"38154.2","s":0},{"p":"38152.6","s":0},{"p":"38152.7","s":0}],"b":[{"p":"38139","s":1315},{"p":"38145.6","s":119365},{"p":"38144.7","s":0},{"p":"38137.5","s":0},{"p":"38138.8","s":0}],"s":"BTC_USDT","t":1701245708042,"u":53095248914}}
{"time":1701245708,"time_ms":1701245708073,"channel":"futures.order_book_update","event":"update","result":{"U":53095248915,"a":[{"p":"38152.5","s":2090},{"p":"38157.8","s":0},{"p":"38155","s":0}],"b":[{"p":"38144.4","s":2},{"p":"38139.3","s":2315},{"p":"38145.6","s":119369},{"p":"38139.2","s":0},{"p":"38139","s":0},{"p":"38138.3","s":0}],"s":"BTC_USDT","t":1701245708067,"u":53095248925}}
{"time":1701245708,"time_ms":1701245708092,"channel":"futures.order_book_update","event":"update","result":{"U":53095248926,"a":[{"p":"38157.5","s":0},{"p":"38152.3","s":2174},{"p":"38152.5","s":0},{"p":"38159","s":0},{"p":"38154.3","s":0},{"p":"38157.7","s":0},{"p":"38152.7","s":0}],"b":[{"p":"38139.5","s":8912},{"p":"38134.4","s":0},{"p":"38138.8","s":0}],"s":"BTC_USDT","t":1701245708073,"u":53095248940}}
{"time":1701245708,"time_ms":1701245708112,"channel":"futures.order_book_update","event":"update","result":{"U":53095248941,"a":[{"p":"38152.5","s":2090},{"p":"38152.3","s":0},{"p":"38152.7","s":0}],"b":[],"s":"BTC_USDT","t":1701245708095,"u":53095248944}}
{"time":1701245708,"time_ms":1701245708152,"channel":"futures.order_book_update","event":"update","result":{"U":53095248945,"a":[{"p":"38153.9","s":0}],"b":[],"s":"BTC_USDT","t":1701245708140,"u":53095248948}}
{"time":1701245708,"time_ms":1701245708193,"channel":"futures.order_book_update","event":"update","result":{"U":53095248949,"a":[{"p":"38158.5","s":0},{"p":"38154.5","s":0}],"b":[],"s":"BTC_USDT","t":1701245708179,"u":53095248953}}
{"time":1701245708,"time_ms":1701245708212,"channel":"futures.order_book_update","event":"update","result":{"U":53095248954,"a":[{"p":"38155","s":0},{"p":"38159","s":0}],"b":[],"s":"BTC_USDT","t":1701245708201,"u":53095248958}}
{"time":1701245708,"time_ms":1701245708231,"channel":"futures.order_book_update","event":"update","result":{"U":53095248959,"a":[{"p":"38152.5","s":79}],"b":[{"p":"38139.2","s":1315},{"p":"38139.5","s":0},{"p":"38135.5","s":0},{"p":"38127","s":0}],"s":"BTC_USDT","t":1701245708222,"u":53095248963}}
{"time":1701245708,"time_ms":1701245708273,"channel":"futures.order_book_update","event":"update","result":{"U":53095248964,"a":[{"p":"38155.7","s":0}],"b":[],"s":"BTC_USDT","t":1701245708245,"u":53095248964}}
{"time":1701245708,"time_ms":1701245708293,"channel":"futures.order_book_update","event":"update","result":{"U":53095248965,"a":[{"p":"38154.5","s":0},{"p":"38158.5","s":0}],"b":[],"s":"BTC_USDT","t":1701245708283,"u":53095248970}}
{"time":1701245708,"time_ms":1701245708332,"channel":"futures.order_book_update","event":"update","result":{"U":53095248971,"a":[],"b":[{"p":"38139.5","s":8912},{"p":"38139.2","s":0}],"s":"BTC_USDT","t":1701245708311,"u":53095248975}}
{"time":1701245708,"time_ms":1701245708374,"channel":"futures.order_book_update","event":"update","result":{"U":53095248976,"a":[{"p":"38152.5","s":2090}],"b":[{"p":"38139.2","s":1315},{"p":"38139.5","s":0},{"p":"38135.5","s":0},{"p":"38127.5","s":0}],"s":"BTC_USDT","t":1701245708346,"u":53095248982}}
{"time":1701245708,"time_ms":1701245708472,"channel":"futures.order_book_update","event":"update","result":{"U":53095248983,"a":[{"p":"38155.3","s":0}],"b":[],"s":"BTC_USDT","t":1701245708445,"u":53095248984}}
{"time":1701245708,"time_ms":1701245708512,"channel":"futures.order_book_update","event":"update","result":{"U":53095248985,"a":[{"p":"38157.7","s":0}],"b":[{"p":"38131.8","s":0}],"s":"BTC_USDT","t":1701245708496,"u":53095248988}}
{"time":1701245708,"time_ms":1701245708531,"channel":"futures.order_book_update","event":"update","result":{"U":53095248989,"a":[],"b":[{"p":"38139.5","s":8912},{"p":"38139.2","s":0}],"s":"BTC_USDT","t":1701245708505,"u":53095248991}}
{"time":1701245708,"time_ms":1701245708552,"channel":"futures.order_book_update","event":"update","result":{"U":53095248992,"a":[{"p":"38152.1","s":2174},{"p":"38152.5","s":0},{"p":"38154.3","s":0},{"p":"38152.7","s":0}],"b":[],"s":"BTC_USDT","t":1701245708543,"u":53095248995}}
{"time":1701245708,"time_ms":1701245708572,"channel":"futures.order_book_update","event":"update","result":{"U":53095248996,"a":[{"p":"38154.3","s":0},{"p":"38155","s":0},{"p":"38159","s":0}],"b":[{"p":"38145.6","s":115724},{"p":"38137.4","s":0}],"s":"BTC_USDT","t":1701245708565,"u":53095249006}}
{"time":1701245708,"time_ms":1701245708593,"channel":"futures.order_book_update","event":"update","result":{"U":53095249007,"a":[{"p":"38153.6","s":0}],"b":[{"p":"38145.6","s":115724}],"s":"BTC_USDT","t":1701245708568,"u":53095249010}}
{"time":1701245708,"time_ms":1701245708612,"channel":"futures.order_book_update","event":"update","result":{"U":53095249011,"a":[{"p":"38154.2","s":0}],"b":[{"p":"38128.1","s":0}],"s":"BTC_USDT","t":1701245708593,"u":53095249014}}
{"time":1701245708,"time_ms":1701245708672,"channel":"futures.order_book_update","event":"update","result":{"U":53095249015,"a":[{"p":"38154.9","s":0}],"b":[],"s":"BTC_USDT","t":1701245708645,"u":53095249015}}
{"time":1701245708,"time_ms":1701245708697,"channel":"futures.order_book_update","event":"update","result":{"U":53095249016,"a":[],"b":[{"p":"38145.6","s":116224},{"p":"38139.2","s":1315},{"p":"38139.5","s":0},{"p":"38127.5","s":0}],"s":"BTC_USDT","t":1701245708681,"u":53095249019}}
{"time":1701245708,"time_ms":1701245708714,"channel":"futures.order_book_update","event":"update","result":{"U":53095249020,"a":[],"b":[{"p":"38135.5","s":0}],"s":"BTC_USDT","t":1701245708692,"u":53095249020}}
{"time":1701245708,"time_ms":1701245708756,"channel":"futures.order_book_update","event":"update","result":{"U":53095249021,"a":[{"p":"38155.5","s":0},{"p":"38159.5","s":0}],"b":[{"p":"38134.2","s":0}],"s":"BTC_USDT","t":1701245708741,"u":53095249026}}
{"time":1701245708,"time_ms":1701245708813,"channel":"futures.order_book_update","event":"update","result":{"U":53095249027,"a":[{"p":"38155","s":0}],"b":[{"p":"38139.5","s":8912},{"p":"38139.2","s":0}],"s":"BTC_USDT","t":1701245708792,"u":53095249034}}
{"time":1701245708,"time_ms":1701245708833,"channel":"futures.order_book_update","event":"update","result":{"U":53095249035,"a":[],"b":[{"p":"38145.6","s":116220},{"p":"38143.9","s":2},{"p":"38145","s":2},{"p":"38144.4","s":0},{"p":"38139.3","s":0},{"p":"38139.2","s":0}],"s":"BTC_USDT","t":1701245708823,"u":53095249041}}
{"time":1701245708,"time_ms":1701245708873,"channel":"futures.order_book_update","event":"update","result":{"U":53095249042,"a":[],"b":[{"p":"38145.6","s":116222}],"s":"BTC_USDT","t":1701245708846,"u":53095249042}}
{"time":1701245708,"time_ms":1701245708894,"channel":"futures.order_book_update","event":"update","result":{"U":53095249043,"a":[{"p":"38159","s":0}],"b":[],"s":"BTC_USDT","t":1701245708880,"u":53095249044}}
{"time":1701245708,"time_ms":1701245708912,"channel":"futures.order_book_update","event":"update","result":{"U":53095249045,"a":[{"p":"38155","s":0}],"b":[],"s":"BTC_USDT","t":1701245708891,"u":53095249046}}
{"time":1701245708,"time_ms":1701245708931,"channel":"futures.order_book_update","event":"update","result":{"U":53095249047,"a":[],"b":[{"p":"38139.3","s":2315},{"p":"38143.9","s":0},{"p":"38145","s":0},{"p":"38139.2","s":1315},{"p":"38145.6","s":116218}],"s":"BTC_USDT","t":1701245708915,"u":53095249051}}
{"time":1701245708,"time_ms":1701245708972,"channel":"futures.order_book_update","event":"update","result":{"U":53095249052,"a":[],"b":[{"p":"38143.8","s":2},{"p":"38145","s":2},{"p":"38145.6","s":116222},{"p":"38139.2","s":0},{"p":"38139.3","s":0}],"s":"BTC_USDT","t":1701245708955,"u":53095249057}}
{"time":1701245708,"time_ms":1701245708993,"channel":"futures.order_book_update","event":"update","result":{"U":53095249058,"a":[{"p":"38154.3","s":0}],"b":[],"s":"BTC_USDT","t":1701245708978,"u":53095249060}}
{"time":1701245709,"time_ms":1701245709033,"channel":"futures.order_book_update","event":"update","result":{"U":53095249061,"a":[{"p":"38161.9","s":0},{"p":"38157.2","s":0},{"p":"38154.1","s":0},{"p":"38152.3","s":2174},{"p":"38152.1","s":0},{"p":"38152.5","s":0}],"b":[{"p":"38138.3","s":0},{"p":"38137","s":0},{"p":"38138.2","s":0},{"p":"38133.7","s":0}],"s":"BTC_USDT","t":1701245709017,"u":53095249076}}
{"time":1701245709,"time_ms":1701245709112,"channel":"futures.order_book_update","event":"update","result":{"U":53095249077,"a":[{"p":"38157","s":0}],"b":[{"p":"38138.4","s":0}],"s":"BTC_USDT","t":1701245709096,"u":53095249080}}
{"time":1701245709,"time_ms":1701245709153,"channel":"futures.order_book_update","event":"update","result":{"U":53095249081,"a":[],"b":[{"p":"38145.6","s":116218},{"p":"38139.2","s":1315},{"p":"38139.3","s":2315},{"p":"38143.8","s":0},{"p":"38145","s":0}],"s":"BTC_USDT","t":1701245709127,"u":53095249084}}
{"time":1701245709,"time_ms":1701245709176,"channel":"futures.order_book_update","event":"update","result":{"U":53095249085,"a":[{"p":"38157.3","s":0},{"p":"38152.1","s":2174},{"p":"38152.3","s":0},{"p":"38153.9","s":0},{"p":"38157.2","s":0},{"p":"38152.5","s":0},{"p":"38153.6","s":0}],"b":[{"p":"38142.6","s":2},{"p":"38138.2","s":0},{"p":"38138.5","s":0},{"p":"38137.4","s":0},{"p":"38139.9","s":2},{"p":"38141.8","s":9024},{"p":"38141.1","s":2},{"p":"38139.4","s":0},{"p":"38139.2","s":0},{"p":"38139.3","s":0},{"p":"38134.1","s":0}],"s":"BTC_USDT","t":1701245709167,"u":53095249112}}
{"time":1701245709,"time_ms":1701245709295,"channel":"futures.order_book_update","event":"update","result":{"U":53095249113,"a":[{"p":"38153","s":0}],"b":[],"s":"BTC_USDT","t":1701245709274,"u":53095249115}}
{"time":1701245709,"time_ms":1701245709333,"channel":"futures.order_book_update","event":"update","result":{"U":53095249116,"a":[{"p":"38153.5","s":0}],"b":[],"s":"BTC_USDT","t":1701245709326,"u":53095249117}}
{"time":1701245709,"time_ms":1701245709372,"channel":"futures.order_book_update","event":"update","result":{"U":53095249118,"a":[{"p":"38154.5","s":0}],"b":[],"s":"BTC_USDT","t":1701245709345,"u":53095249118}}
{"time":1701245709,"time_ms":1701245709393,"channel":"futures.order_book_update","event":"update","result":{"U":53095249119,"a":[{"p":"38145.7","s":21176}],"b":[{"p":"38141.8","s":9022},{"p":"38139.2","s":1315},{"p":"38142.6","s":0},{"p":"38139.9","s":0},{"p":"38141.1","s":0},{"p":"38139.1","s":2310},{"p":"38139.4","s":1315}],"s":"BTC_USDT","t":1701245709375,"u":53095249123}}
{"time":1701245709,"time_ms":1701245709412,"channel":"futures.order_book_update","event":"update","result":{"U":53095249124,"a":[{"p":"38152.3","s":2174},{"p":"38152.1","s":0},{"p":"38152.4","s":7235}],"b":[{"p":"38139.9","s":2},{"p":"38141.8","s":9024},{"p":"38142.6","s":2},{"p":"38139.2","s":0},{"p":"38139.1","s":0}],"s":"BTC_USDT","t":1701245709398,"u":53095249128}}
{"time":1701245709,"time_ms":1701245709432,"channel":"futures.order_book_update","event":"update","result":{"U":53095249129,"a":[],"b":[{"p":"38141.1","s":2},{"p":"38139.4","s":0}],"s":"BTC_USDT","t":1701245709405,"u":53095249129}}
{"time":1701245709,"time_ms":1701245709557,"channel":"futures.order_book_update","event":"update","result":{"U":53095249130,"a":[{"p":"38154.1","s":0}],"b":[],"s":"BTC_USDT","t":1701245709547,"u":53095249131}}
{"time":1701245709,"time_ms":1701245709573,"channel":"futures.order_book_update","event":"update","result":{"U":53095249132,"a":[],"b":[{"p":"38141.1","s":0},{"p":"38139.9","s":0},{"p":"38142.6","s":0},{"p":"38139.4","s":1315},{"p":"38139.2","s":1315},{"p":"38139.1","s":2310},{"p":"38141.8","s":9022}],"s":"BTC_USDT","t":1701245709549,"u":53095249135}}
{"time":1701245709,"time_ms":1701245709694,"channel":"futures.order_book_update","event":"update","result":{"U":53095249136,"a":[],"b":[{"p":"38134.3","s":0}],"s":"BTC_USDT","t":1701245709680,"u":53095249137}}
{"time":1701245709,"time_ms":1701245709753,"channel":"futures.order_book_update","event":"update","result":{"U":53095249138,"a":[{"p":"38153.3","s":0},{"p":"38145.7","s":14676}],"b":[],"s":"BTC_USDT","t":1701245709741,"u":53095249139}}
{"time":1701245710,"time_ms":1701245710032,"channel":"futures.order_book_update","event":"update","result":{"U":53095249140,"a":[{"p":"38152.5","s":0},{"p":"38153.8","s":0},{"p":"38153.9","s":0},{"p":"38152.1","s":2174},{"p":"38152.3","s":0},{"p":"38153.4","s":0}],"b":[{"p":"38133.7","s":0},{"p":"38137.9","s":0},{"p":"38138.2","s":0},{"p":"38137","s":0}],"s":"BTC_USDT","t":1701245710014,"u":53095249158}}
{"time":1701245710,"time_ms":1701245710054,"channel":"futures.order_book_update","event":"update","result":{"U":53095249159,"a":[{"p":"38162","s":0}],"b":[{"p":"38141.1","s":2},{"p":"38139.1","s":0},{"p":"38139.4","s":0},{"p":"38139.2","s":0},{"p":"38141.8","s":9024},{"p":"38142.6","s":2},{"p":"38139.9","s":2}],"s":"BTC_USDT","t":1701245710034,"u":53095249163}}
{"time":1701245710,"time_ms":1701245710092,"channel":"futures.order_book_update","event":"update","result":{"U":53095249164,"a":[{"p":"38152.1","s":0},{"p":"38152.4","s":7235},{"p":"38153","s":0},{"p":"38151.9","s":2174}],"b":[{"p":"38141.8","s":9022},{"p":"38139.4","s":1315},{"p":"38137.4","s":0},{"p":"38136.7","s":0},{"p":"38139.9","s":0},{"p":"38138.5","s":0},{"p":"38139.1","s":0},{"p":"38134","s":0},{"p":"38141.1","s":2},{"p":"38139.2","s":0},{"p":"38142.6","s":2},{"p":"38138.2","s":0}],"s":"BTC_USDT","t":1701245710085,"u":53095249182}}
{"time":1701245710,"time_ms":1701245710112,"channel":"futures.order_book_update","event":"update","result":{"U":53095249183,"a":[{"p":"38151.4","s":1230},{"p":"38161.5","s":0}],"b":[{"p":"38139.9","s":2},{"p":"38141.8","s":9024},{"p":"38139.4","s":0}],"s":"BTC_USDT","t":1701245710093,"u":53095249187}}
{"time":1701245710,"time_ms":1701245710172,"channel":"futures.order_book_update","event":"update","result":{"U":53095249188,"a":[{"p":"38152.3","s":1315},{"p":"38152.4","s":0}],"b":[],"s":"BTC_USDT","t":1701245710157,"u":53095249191}}
{"time":1701245710,"time_ms":1701245710193,"channel":"futures.order_book_update","event":"update","result":{"U":53095249192,"a":[],"b":[{"p":"38136.8","s":0}],"s":"BTC_USDT","t":1701245710183,"u":53095249193}}
{"time":1701245710,"time_ms":1701245710212,"channel":"futures.order_book_update","event":"update","result":{"U":53095249194,"a":[{"p":"38161.3","s":0},{"p":"38145.7","s":29676},{"p":"38152.1","s":2174},{"p":"38151.9","s":0},{"p":"38152.4","s":0}],"b":[{"p":"38138.3","s":0}],"s":"BTC_USDT","t":1701245710192,"u":53095249200}}
{"time":1701245710,"time_ms":1701245710233,"channel":"futures.order_book_update","event":"update","result":{"U":53095249201,"a":[{"p":"38153.6","s":0},{"p":"38145.7","s":44676},{"p":"38151.4","s":635},{"p":"38156.8","s":0},{"p":"38152.8","s":0}],"b":[{"p":"38145.2","s":7193},{"p":"38132.9","s":0},{"p":"38114.4","s":0}],"s":"BTC_USDT","t":1701245710229,"u":53095249210}}
{"time":1701245710,"time_ms":1701245710252,"channel":"futures.order_book_update","event":"update","result":{"U":53095249211,"a":[{"p":"38157","s":0},{"p":"38153.9","s":0},{"p":"38152.4","s":7235},{"p":"38152.1","s":0},{"p":"38153.3","s":0}],"b":[{"p":"38141.8","s":9022},{"p":"38145.6","s":116220},{"p":"38144.3","s":2366},{"p":"38141.1","s":0},{"p":"38139.9","s":0},{"p":"38145.1","s":2},{"p":"38143.2","s":2},{"p":"38139.4","s":1315},{"p":"38142.6","s":0}],"s":"BTC_USDT","t":1701245710243,"u":53095249228}}
{"time":1701245710,"time_ms":1701245710271,"channel":"futures.order_book_update","event":"update","result":{"U":53095249229,"a":[{"p":"38153.9","s":0},{"p":"38154.2","s":0}],"b":[],"s":"BTC_USDT","t":1701245710257,"u":53095249232}}
{"time":1701245710,"time_ms":1701245710312,"channel":"futures.order_book_update","event":"update","result":{"U":53095249233,"a":[],"b":[{"p":"38139.1","s":2310},{"p":"38145.6","s":116148},{"p":"38139.2","s":1315},{"p":"38144.3","s":2364},{"p":"38145.1","s":0},{"p":"38143.2","s":0}],"s":"BTC_USDT","t":1701245710306,"u":53095249237}}
{"time":1701245710,"time_ms":1701245710331,"channel":"futures.order_book_update","event":"update","result":{"U":53095249238,"a":[{"p":"38145.7","s":29676}],"b":[],"s":"BTC_USDT","t":1701245710311,"u":53095249238}}
{"time":1701245710,"time_ms":1701245710351,"channel":"futures.order_book_update","event":"update","result":{"U":53095249239,"a":[{"p":"38157.6","s":0}],"b":[{"p":"38143.7","s":2},{"p":"38139.2","s":0},{"p":"38139.1","s":0},{"p":"38139.4","s":0},{"p":"38145.2","s":7195},{"p":"38142.6","s":2},{"p":"38144.5","s":2}],"s":"BTC_USDT","t":1701245710345,"u":53095249244}}
{"time":1701245710,"time_ms":1701245710432,"channel":"futures.order_book_update","event":"update","result":{"U":53095249245,"a":[{"p":"38153.9","s":0},{"p":"38156.3","s":0}],"b":[{"p":"38072.6","s":0},{"p":"38050.1","s":0}],"s":"BTC_USDT","t":1701245710423,"u":53095249249}}
{"time":1701245710,"time_ms":1701245710453,"channel":"futures.order_book_update","event":"update","result":{"U":53095249250,"a":[{"p":"38153","s":0}],"b":[{"p":"38049.8","s":0},{"p":"38044.9","s":0}],"s":"BTC_USDT","t":1701245710441,"u":53095249253}}
{"time":1701245710,"time_ms":1701245710471,"channel":"futures.order_book_update","event":"update","result":{"U":53095249254,"a":[{"p":"38145.7","s":14676}],"b":[{"p":"38054.2","s":0},{"p":"38052","s":0}],"s":"BTC_USDT","t":1701245710459,"u":53095249260}}
{"time":1701245710,"time_ms":1701245710494,"channel":"futures.order_book_update","event":"update","result":{"U":53095249261,"a":[{"p":"38155","s":0},{"p":"38155.5","s":0},{"p":"38159.5","s":0}],"b":[{"p":"38143.7","s":0},{"p":"38139.2","s":1315},{"p":"38145.2","s":7193},{"p":"38139.4","s":1315},{"p":"38139.1","s":2310},{"p":"38142.6","s":0},{"p":"38144.5","s":0}],"s":"BTC_USDT","t":1701245710485,"u":53095249270}}
{"time":1701245710,"time_ms":1701245710514,"channel":"futures.order_book_update","event":"update","result":{"U":53095249271,"a":[],"b":[{"p":"38139.4","s":0},{"p":"38139.1","s":0},{"p":"38143.6","s":2},{"p":"38145.6","s":116218},{"p":"38145.1","s":2},{"p":"38142.4","s":2},{"p":"38144.3","s":2366},{"p":"38139.2","s":0}],"s":"BTC_USDT","t":1701245710503,"u":53095249275}}
{"time":1701245710,"time_ms":1701245710590,"channel":"futures.order_book_update","event":"update","result":{"U":53095249276,"a":[{"p":"38156","s":0},{"p":"38160","s":0}],"b":[{"p":"38129.3","s":0}],"s":"BTC_USDT","t":1701245710579,"u":53095249281}}
{"time":1701245710,"time_ms":1701245710712,"channel":"futures.order_book_update","event":"update","result":{"U":53095249282,"a":[{"p":"38153.9","s":0}],"b":[],"s":"BTC_USDT","t":1701245710686,"u":53095249284}}
{"time":1701245710,"time_ms":1701245710813,"channel":"futures.order_book_update","event":"update","result":{"U":53095249285,"a":[{"p":"38151.9","s":2174},{"p":"38152.4","s":0},{"p":"38153","s":0},{"p":"38152.6","s":0},{"p":"38154","s":0}],"b":[],"s":"BTC_USDT","t":1701245710794,"u":53095249294}}
{"time":1701245710,"time_ms":1701245710832,"channel":"futures.order_book_update","event":"update","result":{"U":53095249295,"a":[{"p":"38151.4","s":1234},{"p":"38159.5","s":0},{"p":"38155.5","s":0}],"b":[],"s":"BTC_USDT","t":1701245710816,"u":53095249299}}
{"time":1701245710,"time_ms":1701245710852,"channel":"futures.order_book_update","event":"update","result":{"U":53095249300,"a":[],"b":[{"p":"38139.2","s":1315},{"p":"38139.1","s":2310},{"p":"38139.4","s":1315},{"p":"38145.1","s":0},{"p":"38142.4","s":0},{"p":"38143.6","s":0},{"p":"38144.3","s":2364}],"s":"BTC_USDT","t":1701245710842,"u":53095249303}}
{"time":1701245710,"time_ms":1701245710892,"channel":"futures.order_book_update","event":"update","result":{"U":53095249304,"a":[{"p":"38155","s":0}],"b":[],"s":"BTC_USDT","t":1701245710882,"u":53095249305}}
{"time":1701245710,"time_ms":1701245710912,"channel":"futures.order_book_update","event":"update","result":{"U":53095249306,"a":[{"p":"38160","s":0},{"p":"38156","s":0}],"b":[{"p":"38139.5","s":0},{"p":"38142.2","s":2},{"p":"38144.1","s":2},{"p":"38143.3","s":2},{"p":"38144.9","s":2},{"p":"38139.4","s":0},{"p":"38139.2","s":0},{"p":"38139.1","s":0}],"s":"BTC_USDT","t":1701245710896,"u":53095249313}}
{"time":1701245710,"time_ms":1701245710932,"channel":"futures.order_book_update","event":"update","result":{"U":53095249314,"a":[],"b":[{"p":"38129.2","s":0}],"s":"BTC_USDT","t":1701245710910,"u":53095249315}}
{"time":1701245710,"time_ms":1701245710992,"channel":"futures.order_book_update","event":"update","result":{"U":53095249316,"a":[{"p":"38162","s":0}],"b":[],"s":"BTC_USDT","t":1701245710971,"u":53095249318}}
{"time":1701245711,"time_ms":1701245711013,"channel":"futures.order_book_update","event":"update","result":{"U":53095249319,"a":[{"p":"38154.3","s":0}],"b":[{"p":"38145.5","s":3316}],"s":"BTC_USDT","t":1701245710995,"u":53095249323}}
{"time":1701245711,"time_ms":1701245711033,"channel":"futures.order_book_update","event":"update","result":{"U":53095249324,"a":[{"p":"38161.5","s":0},{"p":"38153.8","s":0},{"p":"38153.4","s":0}],"b":[{"p":"38133.7","s":0}],"s":"BTC_USDT","t":1701245711020,"u":53095249331}}
{"time":1701245711,"time_ms":1701245711072,"channel":"futures.order_book_update","event":"update","result":{"U":53095249332,"a":[{"p":"38152.1","s":1315},{"p":"38152.3","s":0}],"b":[],"s":"BTC_USDT","t":1701245711047,"u":53095249332}}
{"time":1701245711,"time_ms":1701245711095,"channel":"futures.order_book_update","event":"update","result":{"U":53095249333,"a":[],"b":[{"p":"38139.2","s":0},{"p":"38139.1","s":0},{"p":"38139.4","s":1315},{"p":"38139.5","s":8912},{"p":"38144.9","s":0},{"p":"38142.2","s":0},{"p":"38144.1","s":2},{"p":"38143.3","s":2}],"s":"BTC_USDT","t":1701245711083,"u":53095249339}}
{"time":1701245711,"time_ms":1701245711110,"channel":"futures.order_book_update","event":"update","result":{"U":53095249340,"a":[{"p":"38153.9","s":0}],"b":[{"p":"38139.5","s":0},{"p":"38139.4","s":0},{"p":"38142.2","s":2},{"p":"38144.9","s":2}],"s":"BTC_USDT","t":1701245711097,"u":53095249343}}
{"time":1701245711,"time_ms":1701245711134,"channel":"futures.order_book_update","event":"update","result":{"U":53095249344,"a":[{"p":"38159.5","s":0},{"p":"38155.5","s":0}],"b":[],"s":"BTC_USDT","t":1701245711103,"u":53095249347}}
{"time":1701245711,"time_ms":1701245711172,"channel":"futures.order_book_update","event":"update","result":{"U":53095249348,"a":[{"p":"38153.7","s":0}],"b":[{"p":"38125.3","s":0},{"p":"38145.6","s":119363},{"p":"38121.2","s":0},{"p":"38137.9","s":0},{"p":"38136.7","s":0}],"s":"BTC_USDT","t":1701245711162,"u":53095249355}}
{"time":1701245711,"time_ms":1701245711192,"channel":"futures.order_book_update","event":"update","result":{"U":53095249356,"a":[],"b":[{"p":"38138.2","s":0}],"s":"BTC_USDT","t":1701245711179,"u":53095249357}}
{"time":1701245711,"time_ms":1701245711211,"channel":"futures.order_book_update","event":"update","result":{"U":53095249358,"a":[{"p":"38155","s":0},{"p":"38153.7","s":0}],"b":[],"s":"BTC_USDT","t":1701245711195,"u":53095249362}}
{"time":1701245711,"time_ms":1701245711272,"channel":"futures.order_book_update","event":"update","result":{"U":53095249363,"a":[{"p":"38151.9","s":3489}],"b":[{"p":"38083.2","s":0}],"s":"BTC_USDT","t":1701245711249,"u":53095249367}}
{"time":1701245711,"time_ms":1701245711292,"channel":"futures.order_book_update","event":"update","result":{"U":53095249368,"a":[{"p":"38151.4","s":1943}],"b":[],"s":"BTC_USDT","t":1701245711274,"u":53095249368}}
{"time":1701245711,"time_ms":1701245711350,"channel":"futures.order_book_update","event":"update","result":{"U":53095249369,"a":[{"p":"38164.8","s":0}],"b":[],"s":"BTC_USDT","t":1701245711337,"u":53095249370}}
{"time":1701245711,"time_ms":1701245711372,"channel":"futures.order_book_update","event":"update","result":{"U":53095249371,"a":[{"p":"38145.7","s":21676},{"p":"38153.5","s":0}],"b":[],"s":"BTC_USDT","t":1701245711352,"u":53095249372}}
{"time":1701245711,"time_ms":1701245711393,"channel":"futures.order_book_update","event":"update","result":{"U":53095249373,"a":[{"p":"38151.9","s":1315},{"p":"38145.7","s":14676},{"p":"38152","s":1052},{"p":"38153.4","s":0}],"b":[],"s":"BTC_USDT","t":1701245711385,"u":53095249378}}
{"time":1701245711,"time_ms":1701245711413,"channel":"futures.order_book_update","event":"update","result":{"U":53095249379,"a":[{"p":"38151.9","s":3489},{"p":"38151.4","s":635}],"b":[],"s":"BTC_USDT","t":1701245711394,"u":53095249381}}
{"time":1701245711,"time_ms":1701245711433,"channel":"futures.order_book_update","event":"update","result":{"U":53095249382,"a":[{"p":"38151.4","s":2018}],"b":[],"s":"BTC_USDT","t":1701245711414,"u":53095249382}}
{"time":1701245711,"time_ms":1701245711518,"channel":"futures.order_book_update","event":"update","result":{"U":53095249383,"a":[{"p":"38151.9","s":1315},{"p":"38151.8","s":2174},{"p":"38152.2","s":0},{"p":"38153.6","s":0}],"b":[{"p":"38139.5","s":8912},{"p":"38143.7","s":2},{"p":"38141.8","s":9024},{"p":"38144.1","s":0},{"p":"38143.3","s":0},{"p":"38139.1","s":0},{"p":"38144.5","s":2},{"p":"38143","s":2},{"p":"38144.9","s":0},{"p":"38142.2","s":0},{"p":"38139.2","s":0},{"p":"38139.4","s":0}],"s":"BTC_USDT","t":1701245711509,"u":53095249395}}
{"time":1701245711,"time_ms":1701245711532,"channel":"futures.order_book_update","event":"update","result":{"U":53095249396,"a":[{"p":"38153","s":0},{"p":"38151.4","s":1230}],"b":[],"s":"BTC_USDT","t":1701245711523,"u":53095249399}}
{"time":1701245711,"time_ms":1701245711593,"channel":"futures.order_book_update","event":"update","result":{"U":53095249400,"a":[],"b":[{"p":"38139.2","s":1315},{"p":"38139.1","s":2310},{"p":"38139.4","s":1315},{"p":"38143.7","s":0},{"p":"38143","s":0},{"p":"38144.5","s":0},{"p":"38141.8","s":9022}],"s":"BTC_USDT","t":1701245711581,"u":53095249403}}
{"time":1701245711,"time_ms":1701245711612,"channel":"futures.order_book_update","event":"update","result":{"U":53095249404,"a":[],"b":[{"p":"38142.8","s":2},{"p":"38139.1","s":0},{"p":"38139.4","s":0},{"p":"38139.2","s":0},{"p":"38125.9","s":0},{"p":"38143.6","s":2},{"p":"38144.4","s":2},{"p":"38141.7","s":15028}],"s":"BTC_USDT","t":1701245711604,"u":53095249409}}
{"time":1701245711,"time_ms":1701245711633,"channel":"futures.order_book_update","event":"update","result":{"U":53095249410,"a":[{"p":"38155.5","s":0},{"p":"38153.5","s":0},{"p":"38159","s":0},{"p":"38155","s":0}],"b":[{"p":"38139.1","s":0}],"s":"BTC_USDT","t":1701245711625,"u":53095249417}}
{"time":1701245711,"time_ms":1701245711653,"channel":"futures.order_book_update","event":"update","result":{"U":53095249418,"a":[{"p":"38152.2","s":935},{"p":"38151.8","s":0},{"p":"38156.8","s":0},{"p":"38152.9","s":0},{"p":"38161.3","s":0},{"p":"38153.9","s":0}],"b":[{"p":"38139.1","s":0},{"p":"38138.9","s":0},{"p":"38131.4","s":0},{"p":"38137","s":0},{"p":"38138.2","s":0},{"p":"38139.7","s":2310},{"p":"38139.5","s":0}],"s":"BTC_USDT","t":1701245711642,"u":53095249438}}
{"time":1701245711,"time_ms":1701245711672,"channel":"futures.order_book_update","event":"update","result":{"U":53095249439,"a":[{"p":"38152.7","s":0},{"p":"38154.2","s":0},{"p":"38152.1","s":3489},{"p":"38151.4","s":635},{"p":"38154.3","s":0},{"p":"38157.8","s":0}],"b":[{"p":"38138.1","s":0},{"p":"38139.5","s":8912},{"p":"38139.7","s":0}],"s":"BTC_USDT","t":1701245711654,"u":53095249451}}
{"time":1701245711,"time_ms":1701245711711,"channel":"futures.order_book_update","event":"update","result":{"U":53095249452,"a":[{"p":"38154.9","s":0},{"p":"38152.5","s":0}],"b":[],"s":"BTC_USDT","t":1701245711696,"u":53095249455}}
{"time":1701245711,"time_ms":1701245711733,"channel":"futures.order_book_update","event":"update","result":{"U":53095249456,"a":[],"b":[{"p":"38132.1","s":0}],"s":"BTC_USDT","t":1701245711706,"u":53095249457}}
{"time":1701245711,"time_ms":1701245711752,"channel":"futures.order_book_update","event":"update","result":{"U":53095249458,"a":[{"p":"38146.9","s":1462},{"p":"38154.3","s":0},{"p":"38152","s":1054},{"p":"38156","s":0},{"p":"38154.8","s":0},{"p":"38153.6","s":0},{"p":"38162.6","s":0},{"p":"38157","s":0},{"p":"38167.5","s":0},{"p":"38152.1","s":0},{"p":"38152.2","s":0},{"p":"38153.8","s":0},{"p":"38160","s":0},{"p":"38149.8","s":2174}],"b":[{"p":"38143.6","s":0},{"p":"38131.4","s":0},{"p":"38134","s":0},{"p":"38137.4","s":0},{"p":"38141.7","s":15026},{"p":"38139.2","s":1315},{"p":"38139.3","s":0},{"p":"38138","s":0},{"p":"38138.5","s":0},{"p":"38139","s":1315},{"p":"38139.4","s":1315},{"p":"38144.4","s":0},{"p":"38145.6","s":95455},{"p":"38142.8","s":0}],"s":"BTC_USDT","t":1701245711743,"u":53095249498}}
{"time":1701245711,"time_ms":1701245711772,"channel":"futures.order_book_update","event":"update","result":{"U":53095249499,"a":[{"p":"38155.9","s":0},{"p":"38151.7","s":1315},{"p":"38145.7","s":44676},{"p":"38149.8","s":0},{"p":"38152","s":0},{"p":"38152.3","s":0},{"p":"38155","s":0},{"p":"38159","s":0},{"p":"38151.8","s":2174}],"b":[{"p":"38140.4","s":94},{"p":"38139.6","s":10604},{"p":"38141.2","s":2},{"p":"38139","s":0},{"p":"38137","s":0},{"p":"38137.5","s":0},{"p":"38136.5","s":0}],"s":"BTC_USDT","t":1701245711764,"u":53095249521}}
{"time":1701245711,"time_ms":1701245711792,"channel":"futures.order_book_update","event":"update","result":{"U":53095249522,"a":[{"p":"38151.4","s":1234},{"p":"38152.7","s":0}],"b":[{"p":"38145.5","s":206},{"p":"38135.9","s":0},{"p":"38115.2","s":0},{"p":"38133.7","s":0},{"p":"38038.9","s":0},{"p":"38145.6","s":110533}],"s":"BTC_USDT","t":1701245711783,"u":53095249533}}
{"time":1701245711,"time_ms":1701245711812,"channel":"futures.order_book_update","event":"update","result":{"U":53095249534,"a":[{"p":"38154.2","s":0},{"p":"38152.8","s":0}],"b":[{"p":"38145.6","s":110463},{"p":"38142.2","s":3110},{"p":"38139.2","s":0}],"s":"BTC_USDT","t":1701245711796,"u":53095249541}}
{"time":1701245711,"time_ms":1701245711852,"channel":"futures.order_book_update","event":"update","result":{"U":53095249542,"a":[],"b":[{"p":"38145.6","s":110963}],"s":"BTC_USDT","t":1701245711826,"u":53095249542}}
{"time":1701245711,"time_ms":1701245711874,"channel":"futures.order_book_update","event":"update","result":{"U":53095249543,"a":[{"p":"38153.3","s":0}],"b":[{"p":"38138.2","s":0}],"s":"BTC_USDT","t":1701245711855,"u":53095249547}}
{"time":1701245711,"time_ms":1701245711893,"channel":"futures.order_book_update","event":"update","result":{"U":53095249548,"a":[],"b":[{"p":"38139.5","s":0},{"p":"38135.5","s":0},{"p":"38127.5","s":0},{"p":"38139.2","s":1315},{"p":"38145.6","s":108963}],"s":"BTC_USDT","t":1701245711881,"u":53095249554}}
{"time":1701245711,"time_ms":1701245711912,"channel":"futures.order_book_update","event":"update","result":{"U":53095249555,"a":[],"b":[{"p":"38139.6","s":10602},{"p":"38139","s":1315},{"p":"38140.4","s":92},{"p":"38141.2","s":0},{"p":"38138.5","s":0}],"s":"BTC_USDT","t":1701245711905,"u":53095249558}}
{"time":1701245711,"time_ms":1701245711954,"channel":"futures.order_book_update","event":"update","result":{"U":53095249559,"a":[],"b":[{"p":"38139","s":0},{"p":"38139.2","s":0},{"p":"38090","s":0},{"p":"38139.9","s":2},{"p":"38140.7","s":2}],"s":"BTC_USDT","t":1701245711939,"u":53095249563}}
{"time":1701245711,"time_ms":1701245711972,"channel":"futures.order_book_update","event":"update","result":{"U":53095249564,"a":[{"p":"38154","s":0},{"p":"38158","s":0}],"b":[{"p":"38139.2","s":1315},{"p":"38139","s":1315},{"p":"38140.7","s":0},{"p":"38139.9","s":0},{"p":"38138","s":0}],"s":"BTC_USDT","t":1701245711961,"u":53095249572}}
{"time":1701245711,"time_ms":1701245711994,"channel":"futures.order_book_update","event":"update","result":{"U":53095249573,"a":[],"b":[{"p":"38139.5","s":8912},{"p":"38139","s":0}],"s":"BTC_USDT","t":1701245711971,"u":53095249575}}
{"time":1701245712,"time_ms":1701245712013,"channel":"futures.order_book_update","event":"update","result":{"U":53095249576,"a":[{"p":"38156.8","s":0}],"b":[{"p":"38137.5","s":0}],"s":"BTC_USDT","t":1701245712006,"u":53095249579}}
{"time":1701245712,"time_ms":1701245712033,"channel":"futures.order_book_update","event":"update","result":{"U":53095249580,"a":[{"p":"38153.2","s":0},{"p":"38153.5","s":0}],"b":[{"p":"38133.3","s":0},{"p":"38137.4","s":0},{"p":"38133.7","s":0},{"p":"38104.3","s":0}],"s":"BTC_USDT","t":1701245712023,"u":53095249592}}
{"time":1701245712,"time_ms":1701245712053,"channel":"futures.order_book_update","event":"update","result":{"U":53095249593,"a":[{"p":"38152","s":1054},{"p":"38151.9","s":3489},{"p":"38151.8","s":0},{"p":"38153","s":0}],"b":[{"p":"38136.9","s":0}],"s":"BTC_USDT","t":1701245712035,"u":53095249598}}
{"time":1701245712,"time_ms":1701245712071,"channel":"futures.order_book_update","event":"update","result":{"U":53095249599,"a":[{"p":"38151.4","s":1941}],"b":[{"p":"38136.8","s":0},{"p":"38125.6","s":0}],"s":"BTC_USDT","t":1701245712055,"u":53095249601}}
{"time":1701245712,"time_ms":1701245712091,"channel":"futures.order_book_update","event":"update","result":{"U":53095249602,"a":[{"p":"38153.9","s":0}],"b":[{"p":"38145.6","s":110963}],"s":"BTC_USDT","t":1701245712082,"u":53095249608}}
{"time":1701245712,"time_ms":1701245712114,"channel":"futures.order_book_update","event":"update","result":{"U":53095249609,"a":[{"p":"38153.4","s":0},{"p":"38153.6","s":0}],"b":[{"p":"38137.6","s":0}],"s":"BTC_USDT","t":1701245712098,"u":53095249615}}
{"time":1701245712,"time_ms":1701245712132,"channel":"futures.order_book_update","event":"update","result":{"U":53095249616,"a":[],"b":[{"p":"38137.4","s":0},{"p":"38137.7","s":0}],"s":"BTC_USDT","t":1701245712115,"u":53095249621}}
{"time":1701245712,"time_ms":1701245712174,"channel":"futures.order_book_update","event":"update","result":{"U":53095249622,"a":[{"p":"38153.3","s":0},{"p":"38160.9","s":0},{"p":"38145.7","s":29676},{"p":"38151.3","s":1315},{"p":"38152","s":0},{"p":"38153.6","s":0}],"b":[{"p":"38137.4","s":0}],"s":"BTC_USDT","t":1701245712166,"u":53095249632}}
{"time":1701245712,"time_ms":1701245712196,"channel":"futures.order_book_update","event":"update","result":{"U":53095249633,"a":[{"p":"38153.3","s":0}],"b":[{"p":"38134","s":0}],"s":"BTC_USDT","t":1701245712184,"u":53095249637}}
{"time":1701245712,"time_ms":1701245712215,"channel":"futures.order_book_update","event":"update","result":{"U":53095249638,"a":[{"p":"38152","s":0}],"b":[{"p":"38055.1","s":0},{"p":"38077.2","s":0},{"p":"38137.9","s":0}],"s":"BTC_USDT","t":1701245712206,"u":53095249643}}
{"time":1701245712,"time_ms":1701245712232,"channel":"futures.order_book_update","event":"update","result":{"U":53095249644,"a":[],"b":[{"p":"38137.9","s":0}],"s":"BTC_USDT","t":1701245712213,"u":53095249645}}
{"time":1701245712,"time_ms":1701245712275,"channel":"futures.order_book_update","event":"update","result":{"U":53095249646,"a":[{"p":"38151.1","s":2},{"p":"38151.9","s":0},{"p":"38153.1","s":0}],"b":[],"s":"BTC_USDT","t":1701245712248,"u":53095249647}}
{"time":1701245712,"time_ms":1701245712312,"channel":"futures.order_book_update","event":"update","result":{"U":53095249648,"a":[{"p":"38158.5","s":0},{"p":"38165.5","s":0},{"p":"38151.9","s":3489},{"p":"38151.1","s":0},{"p":"38154.5","s":0},{"p":"38152.9","s":0},{"p":"38156.4","s":0}],"b":[{"p":"38138.2","s":0},{"p":"38137.4","s":0},{"p":"38140.4","s":94},{"p":"38139.6","s":10604}],"s":"BTC_USDT","t":1701245712304,"u":53095249668}}
{"time":1701245712,"time_ms":1701245712332,"channel":"futures.order_book_update","event":"update","result":{"U":53095249669,"a":[{"p":"38151","s":5},{"p":"38151.9","s":1315}],"b":[{"p":"38145.6","s":114108},{"p":"38136.7","s":0},{"p":"38125.3","s":0}],"s":"BTC_USDT","t":1701245712317,"u":53095249682}}
{"time":1701245712,"time_ms":1701245712353,"channel":"futures.order_book_update","event":"update","result":{"U":53095249683,"a":[{"p":"38151.4","s":635}],"b":[],"s":"BTC_USDT","t":1701245712337,"u":53095249686}}
{"time":1701245712,"time_ms":1701245712502,"channel":"futures.order_book_update","event":"update","result":{"U":53095249687,"a":[{"p":"38161.4","s":0},{"p":"38176.7","s":0},{"p":"38157.5","s":0}],"b":[{"p":"38140.4","s":92},{"p":"38139.6","s":10602},{"p":"38138.9","s":0},{"p":"38137.7","s":0},{"p":"38115","s":0}],"s":"BTC_USDT","t":1701245712489,"u":53095249708}}
{"time":1701245712,"time_ms":1701245712531,"channel":"futures.order_book_update","event":"update","result":{"U":53095249709,"a":[{"p":"38169.7","s":0}],"b":[{"p":"38139.6","s":10604},{"p":"38140.3","s":2},{"p":"38139.2","s":0},{"p":"38135.4","s":0}],"s":"BTC_USDT","t":1701245712513,"u":53095249716}}
{"time":1701245712,"time_ms":1701245712573,"channel":"futures.order_book_update","event":"update","result":{"U":53095249717,"a":[{"p":"38155.5","s":0}],"b":[],"s":"BTC_USDT","t":1701245712558,"u":53095249720}}
{"time":1701245712,"time_ms":1701245712600,"channel":"futures.order_book_update","event":"update","result":{"U":53095249721,"a":[{"p":"38159.5","s":0},{"p":"38151","s":3}],"b":[{"p":"38138.8","s":0},{"p":"38137.7","s":0},{"p":"38145.6","s":109463},{"p":"38139.2","s":1315},{"p":"38139.6","s":10602},{"p":"38140.3","s":0}],"s":"BTC_USDT","t":1701245712584,"u":53095249731}}
{"time":1701245712,"time_ms":1701245712614,"channel":"futures.order_book_update","event":"update","result":{"U":53095249732,"a":[{"p":"38155","s":0},{"p":"38156.8","s":0}],"b":[{"p":"38142.6","s":2},{"p":"38140","s":1317},{"p":"38139.2","s":0},{"p":"38139.4","s":0},{"p":"38141.9","s":4155},{"p":"38141.1","s":2}],"s":"BTC_USDT","t":1701245712604,"u":53095249740}}
{"time":1701245712,"time_ms":1701245712631,"channel":"futures.order_book_update","event":"update","result":{"U":53095249741,"a":[{"p":"38164.4","s":0}],"b":[],"s":"BTC_USDT","t":1701245712609,"u":53095249743}}
{"time":1701245712,"time_ms":1701245712653,"channel":"futures.order_book_update","event":"update","result":{"U":53095249744,"a":[{"p":"38155","s":0},{"p":"38159","s":0},{"p":"38145.7","s":30202},{"p":"38167","s":0}],"b":[],"s":"BTC_USDT","t":1701245712642,"u":53095249750}}
{"time":1701245712,"time_ms":1701245712672,"channel":"futures.order_book_update","event":"update","result":{"U":53095249751,"a":[{"p":"38156.8","s":0},{"p":"38168.2","s":0},{"p":"38151.1","s":1315},{"p":"38151.9","s":0},{"p":"38172","s":0}],"b":[{"p":"38138.8","s":0}],"s":"BTC_USDT","t":1701245712650,"u":53095249755}}
{"time":1701245712,"time_ms":1701245712692,"channel":"futures.order_book_update","event":"update","result":{"U":53095249756,"a":[{"p":"38154.9","s":0}],"b":[],"s":"BTC_USDT","t":1701245712680,"u":53095249757}}
{"time":1701245712,"time_ms":1701245712732,"channel":"futures.order_book_update","event":"update","result":{"U":53095249758,"a":[],"b":[{"p":"38140","s":1315},{"p":"38145.6","s":106318},{"p":"38141.9","s":4153}],"s":"BTC_USDT","t":1701245712723,"u":53095249761}}
{"time":1701245712,"time_ms":1701245712752,"channel":"futures.order_book_update","event":"update","result":{"U":53095249762,"a":[],"b":[{"p":"38139.4","s":1315},{"p":"38139.2","s":1315},{"p":"38142.6","s":0},{"p":"38141.1","s":0}],"s":"BTC_USDT","t":1701245712740,"u":53095249763}}
{"time":1701245712,"time_ms":1701245712772,"channel":"futures.order_book_update","event":"update","result":{"U":53095249764,"a":[{"p":"38152.9","s":0}],"b":[{"p":"38140","s":1317},{"p":"38142.6","s":2},{"p":"38139.2","s":0}],"s":"BTC_USDT","t":1701245712760,"u":53095249767}}
{"time":1701245712,"time_ms":1701245712792,"channel":"futures.order_book_update","event":"update","result":{"U":53095249768,"a":[{"p":"38154","s":0},{"p":"38158","s":0}],"b":[{"p":"38141.9","s":4155},{"p":"38141.1","s":2},{"p":"38145.6","s":107318},{"p":"38139.4","s":0}],"s":"BTC_USDT","t":1701245712783,"u":53095249775}}
{"time":1701245712,"time_ms":1701245712812,"channel":"futures.order_book_update","event":"update","result":{"U":53095249776,"a":[],"b":[{"p":"38145.6","s":107318}],"s":"BTC_USDT","t":1701245712797,"u":53095249779}}
{"time":1701245712,"time_ms":1701245712852,"channel":"futures.order_book_update","event":"update","result":{"U":53095249780,"a":[],"b":[{"p":"38138.9","s":0}],"s":"BTC_USDT","t":1701245712845,"u":53095249781}}
{"time":1701245712,"time_ms":1701245712933,"channel":"futures.order_book_update","event":"update","result":{"U":53095249782,"a":[],"b":[{"p":"38141.1","s":0},{"p":"38140","s":1315},{"p":"38139.4","s":1315},{"p":"38141.9","s":4153}],"s":"BTC_USDT","t":1701245712920,"u":53095249784}}
{"time":1701245712,"time_ms":1701245712952,"channel":"futures.order_book_update","event":"update","result":{"U":53095249785,"a":[],"b":[{"p":"38139.2","s":0},{"p":"38140","s":1317},{"p":"38141.9","s":4155},{"p":"38141.1","s":2},{"p":"38142.6","s":0}],"s":"BTC_USDT","t":1701245712943,"u":53095249788}}
{"time":1701245712,"time_ms":1701245712973,"channel":"futures.order_book_update","event":"update","result":{"U":53095249789,"a":[{"p":"38150.9","s":1326}],"b":[],"s":"BTC_USDT","t":1701245712949,"u":53095249789}}
{"time":1701245712,"time_ms":1701245712993,"channel":"futures.order_book_update","event":"update","result":{"U":53095249790,"a":[],"b":[{"p":"38145.6","s":106318}],"s":"BTC_USDT","t":1701245712976,"u":53095249791}}
{"time":1701245713,"time_ms":1701245713013,"channel":"futures.order_book_update","event":"update","result":{"U":53095249792,"a":[{"p":"38145.7","s":57702},{"p":"38172.6","s":0}],"b":[{"p":"38144","s":100},{"p":"38145.6","s":97338},{"p":"38139.4","s":0},{"p":"38104","s":0},{"p":"38114.2","s":0},{"p":"38142.6","s":2}],"s":"BTC_USDT","t":1701245713001,"u":53095249807}}
{"time":1701245713,"time_ms":1701245713032,"channel":"futures.order_book_update","event":"update","result":{"U":53095249808,"a":[{"p":"38153.3","s":0},{"p":"38152.1","s":0},{"p":"38153.6","s":0}],"b":[{"p":"38133.3","s":0},{"p":"38138","s":0},{"p":"38138.2","s":0},{"p":"38144","s":200},{"p":"38136.9","s":0},{"p":"38133.4","s":0}],"s":"BTC_USDT","t":1701245713015,"u":53095249823}}
{"time":1701245713,"time_ms":1701245713052,"channel":"futures.order_book_update","event":"update","result":{"U":53095249824,"a":[],"b":[{"p":"38138.2","s":0}],"s":"BTC_USDT","t":1701245713032,"u":53095249825}}
{"time":1701245713,"time_ms":1701245713072,"channel":"futures.order_book_update","event":"update","result":{"U":53095249826,"a":[{"p":"38152.7","s":0}],"b":[],"s":"BTC_USDT","t":1701245713051,"u":53095249826}}
{"time":1701245713,"time_ms":1701245713112,"channel":"futures.order_book_update","event":"update","result":{"U":53095249827,"a":[{"p":"38153.5","s":0}],"b":[{"p":"38138.3","s":0},{"p":"38133.5","s":0}],"s":"BTC_USDT","t":1701245713092,"u":53095249834}}
{"time":1701245713,"time_ms":1701245713131,"channel":"futures.order_book_update","event":"update","result":{"U":53095249835,"a":[{"p":"38145.7","s":42702},{"p":"38153.3","s":0},{"p":"38153.4","s":0}],"b":[{"p":"38140.1","s":2},{"p":"38141.1","s":0},{"p":"38138.9","s":0},{"p":"38138.3","s":0},{"p":"38139.4","s":1317},{"p":"38141.9","s":4153},{"p":"38133.3","s":0},{"p":"38138.4","s":0},{"p":"38140","s":1315},{"p":"38142.6","s":0}],"s":"BTC_USDT","t":1701245713125,"u":53095249853}}
{"time":1701245713,"time_ms":1701245713153,"channel":"futures.order_book_update","event":"update","result":{"U":53095249854,"a":[{"p":"38153.6","s":0},{"p":"38153.5","s":0},{"p":"38152.2","s":0},{"p":"38156.8","s":0},{"p":"38157.2","s":0}],"b":[{"p":"38137","s":0},{"p":"38130.6","s":0}],"s":"BTC_USDT","t":1701245713143,"u":53095249869}}
{"time":1701245713,"time_ms":1701245713171,"channel":"futures.order_book_update","event":"update","result":{"U":53095249870,"a":[{"p":"38150.8","s":2},{"p":"38150.7","s":1315},{"p":"38151.7","s":0},{"p":"38151.5","s":0}],"b":[],"s":"BTC_USDT","t":1701245713151,"u":53095249872}}
{"time":1701245713,"time_ms":1701245713193,"channel":"futures.order_book_update","event":"update","result":{"U":53095249873,"a":[],"b":[{"p":"38145.6","s":97838}],"s":"BTC_USDT","t":1701245713182,"u":53095249873}}
{"time":1701245713,"time_ms":1701245713214,"channel":"futures.order_book_update","event":"update","result":{"U":53095249874,"a":[],"b":[{"p":"38139.2","s":1315},{"p":"38140.1","s":0},{"p":"38138.6","s":0},{"p":"38137.5","s":0},{"p":"38139.4","s":1315}],"s":"BTC_USDT","t":1701245713190,"u":53095249877}}
{"time":1701245713,"time_ms":1701245713233,"channel":"futures.order_book_update","event":"update","result":{"U":53095249878,"a":[],"b":[{"p":"38139.3","s":0},{"p":"38140.1","s":2},{"p":"38139.2","s":0}],"s":"BTC_USDT","t":1701245713217,"u":53095249881}}
{"time":1701245713,"time_ms":1701245713253,"channel":"futures.order_book_update","event":"update","result":{"U":53095249882,"a":[{"p":"38156.8","s":0}],"b":[{"p":"38137.4","s":0}],"s":"BTC_USDT","t":1701245713245,"u":53095249885}}
{"time":1701245713,"time_ms":1701245713273,"channel":"futures.order_book_update","event":"update","result":{"U":53095249886,"a":[{"p":"38185.8","s":0},{"p":"38152.5","s":0},{"p":"38157.2","s":0}],"b":[],"s":"BTC_USDT","t":1701245713265,"u":53095249890}}
{"time":1701245713,"time_ms":1701245713294,"channel":"futures.order_book_update","event":"update","result":{"U":53095249891,"a":[{"p":"38161.2","s":0}],"b":[],"s":"BTC_USDT","t":1701245713273,"u":53095249892}}
{"time":1701245713,"time_ms":1701245713334,"channel":"futures.order_book_update","event":"update","result":{"U":53095249893,"a":[],"b":[{"p":"38117.8","s":0}],"s":"BTC_USDT","t":1701245713314,"u":53095249894}}
{"time":1701245713,"time_ms":1701245713352,"channel":"futures.order_book_update","event":"update","result":{"U":53095249895,"a":[{"p":"38163.8","s":0},{"p":"38186.8","s":0}],"b":[{"p":"38130.5","s":0}],"s":"BTC_USDT","t":1701245713344,"u":53095249900}}
{"time":1701245713,"time_ms":1701245713413,"channel":"futures.order_book_update","event":"update","result":{"U":53095249901,"a":[{"p":"38155","s":0},{"p":"38165.5","s":0},{"p":"38151.5","s":0},{"p":"38145.7","s":14676},{"p":"38150.7","s":1969},{"p":"38159","s":0},{"p":"38153.9","s":0}],"b":[{"p":"38145.6","s":82760}],"s":"BTC_USDT","t":1701245713393,"u":53095249915}}
{"time":1701245713,"time_ms":1701245713432,"channel":"futures.order_book_update","event":"update","result":{"U":53095249916,"a":[{"p":"38154.3","s":0}],"b":[{"p":"38138.5","s":0},{"p":"38138.2","s":0}],"s":"BTC_USDT","t":1701245713422,"u":53095249926}}
{"time":1701245713,"time_ms":1701245713472,"channel":"futures.order_book_update","event":"update","result":{"U":53095249927,"a":[{"p":"38153.6","s":0},{"p":"38153.9","s":0}],"b":[{"p":"38133.7","s":0},{"p":"38137.9","s":0}],"s":"BTC_USDT","t":1701245713462,"u":53095249934}}
{"time":1701245713,"time_ms":1701245713501,"channel":"futures.order_book_update","event":"update","result":{"U":53095249935,"a":[{"p":"38152.5","s":0}],"b":[{"p":"38138.6","s":0}],"s":"BTC_USDT","t":1701245713489,"u":53095249938}}
{"time":1701245713,"time_ms":1701245713513,"channel":"futures.order_book_update","event":"update","result":{"U":53095249939,"a":[],"b":[{"p":"38145.6","s":82830}],"s":"BTC_USDT","t":1701245713494,"u":53095249940}}
{"time":1701245713,"time_ms":1701245713532,"channel":"futures.order_book_update","event":"update","result":{"U":53095249941,"a":[{"p":"38151.7","s":1315},{"p":"38150.8","s":0},{"p":"38155.5","s":0},{"p":"38159.5","s":0}],"b":[{"p":"38142.6","s":2},{"p":"38054.9","s":0},{"p":"38115","s":0},{"p":"38141.1","s":2},{"p":"38139.9","s":2},{"p":"38139.4","s":0},{"p":"38137.4","s":0},{"p":"38139.3","s":0},{"p":"38140.1","s":0},{"p":"38077","s":0},{"p":"38141.9","s":4155},{"p":"38139.5","s":0},{"p":"38138.6","s":0},{"p":"38134.9","s":0}],"s":"BTC_USDT","t":1701245713522,"u":53095249959}}
{"time":1701245713,"time_ms":1701245713552,"channel":"futures.order_book_update","event":"update","result":{"U":53095249960,"a":[],"b":[{"p":"38145.6","s":91810},{"p":"38125.3","s":0},{"p":"38136.7","s":0}],"s":"BTC_USDT","t":1701245713541,"u":53095249964}}
{"time":1701245713,"time_ms":1701245713571,"channel":"futures.order_book_update","event":"update","result":{"U":53095249965,"a":[],"b":[{"p":"38145.6","s":94955}],"s":"BTC_USDT","t":1701245713553,"u":53095249966}}
{"time":1701245713,"time_ms":1701245713594,"channel":"futures.order_book_update","event":"update","result":{"U":53095249967,"a":[{"p":"38155","s":0}],"b":[{"p":"38145.6","s":99311}],"s":"BTC_USDT","t":1701245713580,"u":53095249970}}
{"time":1701245713,"time_ms":1701245713611,"channel":"futures.order_book_update","event":"update","result":{"U":53095249971,"a":[{"p":"38145.7","s":14176}],"b":[{"p":"38129","s":0}],"s":"BTC_USDT","t":1701245713595,"u":53095249973}}
{"time":1701245713,"time_ms":1701245713673,"channel":"futures.order_book_update","event":"update","result":{"U":53095249974,"a":[{"p":"38154.3","s":0}],"b":[],"s":"BTC_USDT","t":1701245713655,"u":53095249976}}
{"time":1701245713,"time_ms":1701245713692,"channel":"futures.order_book_update","event":"update","result":{"U":53095249977,"a":[{"p":"38145.7","s":14676},{"p":"38154.9","s":0}],"b":[],"s":"BTC_USDT","t":1701245713682,"u":53095249980}}
{"time":1701245713,"time_ms":1701245713732,"channel":"futures.order_book_update","event":"update","result":{"U":53095249981,"a":[{"p":"38157.5","s":0}],"b":[{"p":"38142.6","s":0},{"p":"38141.1","s":0},{"p":"38139.3","s":733},{"p":"38139.4","s":1315},{"p":"38141.9","s":4153},{"p":"38139.5","s":8912},{"p":"38139.9","s":0}],"s":"BTC_USDT","t":1701245713711,"u":53095249986}}
{"time":1701245713,"time_ms":1701245713752,"channel":"futures.order_book_update","event":"update","result":{"U":53095249987,"a":[],"b":[{"p":"38141.1","s":2},{"p":"38139.9","s":2},{"p":"38142.6","s":2},{"p":"38141.9","s":4155},{"p":"38139.3","s":0},{"p":"38139.4","s":0},{"p":"38139.5","s":0}],"s":"BTC_USDT","t":1701245713740,"u":53095249990}}
{"time":1701245713,"time_ms":1701245713832,"channel":"futures.order_book_update","event":"update","result":{"U":53095249991,"a":[{"p":"38153.3","s":0}],"b":[],"s":"BTC_USDT","t":1701245713821,"u":53095249991}}
{"time":1701245713,"time_ms":1701245713993,"channel":"futures.order_book_update","event":"update","result":{"U":53095249992,"a":[{"p":"38153.3","s":0},{"p":"38152.5","s":0}],"b":[{"p":"38139.3","s":733},{"p":"38141.1","s":0},{"p":"38139.9","s":0},{"p":"38142.6","s":0},{"p":"38139.5","s":8912},{"p":"38139.4","s":1315},{"p":"38141.9","s":4153}],"s":"BTC_USDT","t":1701245713983,"u":53095250002}}
{"time":1701245714,"time_ms":1701245714012,"channel":"futures.order_book_update","event":"update","result":{"U":53095250003,"a":[],"b":[{"p":"38141.8","s":9024},{"p":"38142.6","s":2},{"p":"38139.4","s":0},{"p":"38139.3","s":0},{"p":"38139.9","s":2}],"s":"BTC_USDT","t":1701245714000,"u":53095250006}}
{"time":1701245714,"time_ms":1701245714033,"channel":"futures.order_book_update","event":"update","result":{"U":53095250007,"a":[{"p":"38154.2","s":0},{"p":"38158","s":0},{"p":"38168.3","s":0},{"p":"38154.9","s":0},{"p":"38154.1","s":0},{"p":"38152.7","s":0},{"p":"38161.9","s":0},{"p":"38154","s":0}],"b":[{"p":"38139.6","s":0},{"p":"38134.3","s":0},{"p":"38136.4","s":0},{"p":"38131.4","s":0},{"p":"38138.3","s":0},{"p":"38139.1","s":0},{"p":"38141.1","s":2},{"p":"38139.7","s":2312},{"p":"38139.5","s":0},{"p":"38039.2","s":0}],"s":"BTC_USDT","t":1701245714024,"u":53095250035}}
{"time":1701245714,"time_ms":1701245714052,"channel":"futures.order_book_update","event":"update","result":{"U":53095250036,"a":[{"p":"38154.3","s":0}],"b":[],"s":"BTC_USDT","t":1701245714034,"u":53095250039}}
{"time":1701245714,"time_ms":1701245714071,"channel":"futures.order_book_update","event":"update","result":{"U":53095250040,"a":[{"p":"38157.7","s":0}],"b":[{"p":"38139.3","s":0},{"p":"38139.5","s":0}],"s":"BTC_USDT","t":1701245714048,"u":53095250045}}
{"time":1701245714,"time_ms":1701245714153,"channel":"futures.order_book_update","event":"update","result":{"U":53095250046,"a":[],"b":[{"p":"38139.6","s":10602},{"p":"38139.4","s":1315},{"p":"38142.6","s":0},{"p":"38141.1","s":0},{"p":"38139.9","s":0},{"p":"38141.8","s":9022},{"p":"38139.5","s":8912}],"s":"BTC_USDT","t":1701245714128,"u":53095250050}}
{"time":1701245714,"time_ms":1701245714174,"channel":"futures.order_book_update","event":"update","result":{"U":53095250051,"a":[],"b":[{"p":"38141.8","s":9024},{"p":"38139.9","s":2},{"p":"38141.1","s":2},{"p":"38139.6","s":0},{"p":"38139.4","s":0},{"p":"38139.5","s":0},{"p":"38142.6","s":2}],"s":"BTC_USDT","t":1701245714169,"u":53095250054}}
{"time":1701245714,"time_ms":1701245714233,"channel":"futures.order_book_update","event":"update","result":{"U":53095250055,"a":[{"p":"38154.5","s":0},{"p":"38155","s":0},{"p":"38159","s":0},{"p":"38145.7","s":15202},{"p":"38167","s":0}],"b":[],"s":"BTC_USDT","t":1701245714222,"u":53095250067}}
{"time":1701245714,"time_ms":1701245714252,"channel":"futures.order_book_update","event":"update","result":{"U":53095250068,"a":[{"p":"38158.5","s":0}],"b":[],"s":"BTC_USDT","t":1701245714231,"u":53095250071}}
{"time":1701245714,"time_ms":1701245714272,"channel":"futures.order_book_update","event":"update","result":{"U":53095250072,"a":[{"p":"38145.7","s":14676},{"p":"38162.5","s":0}],"b":[],"s":"BTC_USDT","t":1701245714263,"u":53095250075}}
{"time":1701245714,"time_ms":1701245714292,"channel":"futures.order_book_update","event":"update","result":{"U":53095250076,"a":[{"p":"38154.8","s":0}],"b":[],"s":"BTC_USDT","t":1701245714281,"u":53095250077}}
{"time":1701245714,"time_ms":1701245714413,"channel":"futures.order_book_update","event":"update","result":{"U":53095250078,"a":[{"p":"38154","s":0},{"p":"38158","s":0}],"b":[],"s":"BTC_USDT","t":1701245714388,"u":53095250081}}
{"time":1701245714,"time_ms":1701245714433,"channel":"futures.order_book_update","event":"update","result":{"U":53095250082,"a":[],"b":[{"p":"38145.6","s":99386}],"s":"BTC_USDT","t":1701245714420,"u":53095250084}}
{"time":1701245714,"time_ms":1701245714451,"channel":"futures.order_book_update","event":"update","result":{"U":53095250085,"a":[],"b":[{"p":"38139.5","s":8912},{"p":"38139.4","s":1315},{"p":"38141.8","s":9022},{"p":"38139.6","s":10602},{"p":"38141.1","s":0},{"p":"38142.6","s":0},{"p":"38139.9","s":0}],"s":"BTC_USDT","t":1701245714442,"u":53095250089}}
{"time":1701245714,"time_ms":1701245714493,"channel":"futures.order_book_update","event":"update","result":{"U":53095250090,"a":[],"b":[{"p":"38139.5","s":0},{"p":"38141.1","s":2},{"p":"38139.9","s":2},{"p":"38142.6","s":2},{"p":"38141.8","s":9024},{"p":"38139.4","s":0},{"p":"38139.6","s":0}],"s":"BTC_USDT","t":1701245714479,"u":53095250093}}
{"time":1701245714,"time_ms":1701245714571,"channel":"futures.order_book_update","event":"update","result":{"U":53095250094,"a":[],"b":[{"p":"38141.8","s":9022},{"p":"38139.5","s":8912},{"p":"38139.9","s":0},{"p":"38141.1","s":0},{"p":"38142.6","s":0},{"p":"38139.4","s":1315},{"p":"38139.6","s":10602}],"s":"BTC_USDT","t":1701245714555,"u":53095250098}}
{"time":1701245714,"time_ms":1701245714593,"channel":"futures.order_book_update","event":"update","result":{"U":53095250099,"a":[{"p":"38155","s":0}],"b":[{"p":"38139.4","s":0},{"p":"38139.6","s":0},{"p":"38139.5","s":0},{"p":"38139.9","s":2},{"p":"38141.8","s":9024},{"p":"38141.1","s":2},{"p":"38142.6","s":2}],"s":"BTC_USDT","t":1701245714582,"u":53095250104}}
{"time":1701245714,"time_ms":1701245714632,"channel":"futures.order_book_update","event":"update","result":{"U":53095250105,"a":[],"b":[{"p":"38132.1","s":0},{"p":"38139.3","s":0}],"s":"BTC_USDT","t":1701245714603,"u":53095250108}}
{"time":1701245714,"time_ms":1701245714692,"channel":"futures.order_book_update","event":"update","result":{"U":53095250109,"a":[],"b":[{"p":"38141.1","s":0},{"p":"38139.1","s":0},{"p":"38139.6","s":10602},{"p":"38141.8","s":9022},{"p":"38139.5","s":8912},{"p":"38139.4","s":1341},{"p":"38142.6","s":0},{"p":"38139.9","s":0}],"s":"BTC_USDT","t":1701245714669,"u":53095250114}}
{"time":1701245714,"time_ms":1701245714732,"channel":"futures.order_book_update","event":"update","result":{"U":53095250115,"a":[],"b":[{"p":"38141.8","s":9024},{"p":"38139.9","s":2},{"p":"38139.6","s":0},{"p":"38139.5","s":0},{"p":"38139.4","s":0},{"p":"38141.1","s":2},{"p":"38142.6","s":2}],"s":"BTC_USDT","t":1701245714718,"u":53095250118}}
{"time":1701245714,"time_ms":1701245714813,"channel":"futures.order_book_update","event":"update","result":{"U":53095250119,"a":[],"b":[{"p":"38128.1","s":0}],"s":"BTC_USDT","t":1701245714801,"u":53095250120}}
{"time":1701245714,"time_ms":1701245714953,"channel":"futures.order_book_update","event":"update","result":{"U":53095250121,"a":[{"p":"38150.7","s":1971},{"p":"38153.3","s":0}],"b":[{"p":"38140","s":1317},{"p":"38139.6","s":10602},{"p":"38139.5","s":8912},{"p":"38139.4","s":1341},{"p":"38141.8","s":9022},{"p":"38142.6","s":0},{"p":"38141.1","s":0},{"p":"38139.9","s":0}],"s":"BTC_USDT","t":1701245714935,"u":53095250132}}
{"time":1701245714,"time_ms":1701245714998,"channel":"futures.order_book_update","event":"update","result":{"U":53095250133,"a":[{"p":"38150.7","s":1969},{"p":"38152.8","s":0},{"p":"38157.8","s":0}],"b":[{"p":"38139.3","s":0},{"p":"38135.2","s":0}],"s":"BTC_USDT","t":1701245714988,"u":53095250141}}
{"time":1701245715,"time_ms":1701245715013,"channel":"futures.order_book_update","event":"update","result":{"U":53095250142,"a":[{"p":"38156.8","s":0},{"p":"38152.3","s":0}],"b":[{"p":"38134.9","s":0}],"s":"BTC_USDT","t":1701245715003,"u":53095250147}}
