{"time":1701245665,"time_ms":1701245665777,"channel":"futures.order_book_update","event":"update","result":{"U":53095239569,"a":[{"p":"38146.6","s":42359},{"p":"38150.4","s":0},{"p":"38151","s":0},{"p":"38157.4","s":0},{"p":"38162.3","s":0},{"p":"38167.5","s":0},{"p":"38146.1","s":3108},{"p":"38145.7","s":176639},{"p":"38157","s":0},{"p":"38153","s":0},{"p":"38167","s":0},{"p":"38182.8","s":0},{"p":"38176.1","s":0},{"p":"38148.5","s":2},{"p":"38148","s":4720},{"p":"38147.2","s":0},{"p":"38161","s":0},{"p":"38150.9","s":14783},{"p":"38151.1","s":0},{"p":"38153.6","s":0},{"p":"38167.6","s":0},{"p":"38154.7","s":0},{"p":"38151.4","s":0}],"b":[{"p":"38104.6","s":0},{"p":"38132.3","s":0},{"p":"38135.4","s":0},{"p":"38135.3","s":7207},{"p":"38139.6","s":0},{"p":"38129","s":0},{"p":"38134.3","s":0},{"p":"38130.1","s":0},{"p":"38126.6","s":0},{"p":"38120.9","s":0},{"p":"38130.4","s":0},{"p":"38138","s":216},{"p":"38136.7","s":6815}],"s":"BTC_USDT","t":1701245665767,"u":53095239638}}
{"time":1701245665,"time_ms":1701245665797,"channel":"futures.order_book_update","event":"update","result":{"U":53095239639,"a":[{"p":"38151.2","s":0},{"p":"38146.6","s":42967},{"p":"38171.7","s":0},{"p":"38152.8","s":0},{"p":"38156.1","s":0},{"p":"38152.9","s":0},{"p":"38191.7","s":0},{"p":"38167.4","s":0},{"p":"38145.7","s":177687},{"p":"38151.1","s":0},{"p":"38167.3","s":0},{"p":"38153.4","s":0}],"b":[{"p":"38135.1","s":0},{"p":"38134.6","s":0},{"p":"38130","s":0},{"p":"38133.5","s":0},{"p":"38038.5","s":0},{"p":"38135.8","s":0},{"p":"38051.2","s":0},{"p":"38130.4","s":0},{"p":"38137.8","s":15210},{"p":"38140","s":317},{"p":"38137","s":2},{"p":"38136.8","s":4093},{"p":"38136.3","s":17},{"p":"38109.9","s":0},{"p":"38132.7","s":0},{"p":"38136.7","s":3145},{"p":"38134.4","s":0},{"p":"38129.5","s":0},{"p":"38119.7","s":0},{"p":"38135.3","s":0},{"p":"38134","s":0},{"p":"38125.3","s":0},{"p":"38127.5","s":0},{"p":"38134.8","s":0}],"s":"BTC_USDT","t":1701245665785,"u":53095239688}}
{"time":1701245665,"time_ms":1701245665812,"channel":"futures.order_book_update","event":"update","result":{"U":53095239689,"a":[{"p":"38167.3","s":0},{"p":"38158.8","s":0},{"p":"38145.7","s":176287},{"p":"38150.9","s":0},{"p":"38175.7","s":0},{"p":"38161.9","s":0},{"p":"38160.4","s":0},{"p":"38163","s":0},{"p":"38150.6","s":30997},{"p":"38160","s":0},{"p":"38184.7","s":0}],"b":[{"p":"38140.1","s":582},{"p":"38136.7","s":0},{"p":"38129.8","s":0},{"p":"38145.6","s":2593},{"p":"38110.1","s":0},{"p":"38125.6","s":0},{"p":"38133.9","s":0},{"p":"38133","s":0},{"p":"38127","s":0},{"p":"38136.3","s":17},{"p":"38134.1","s":0},{"p":"38126.7","s":0},{"p":"38135.3","s":0},{"p":"38131.3","s":0},{"p":"38114.6","s":0}],"s":"BTC_USDT","t":1701245665797,"u":53095239744}}
{"time":1701245665,"time_ms":1701245665834,"channel":"futures.order_book_update","event":"update","result":{"U":53095239745,"a":[{"p":"38146.5","s":3575},{"p":"38150.6","s":0},{"p":"38160","s":0},{"p":"38159.1","s":0},{"p":"38145.7","s":176787},{"p":"38147.2","s":2174}],"b":[{"p":"38133","s":0},{"p":"38135.1","s":3364},{"p":"38141.7","s":26},{"p":"38140","s":0},{"p":"38111.1","s":0},{"p":"38125.3","s":0},{"p":"38125.8","s":0},{"p":"38117.9","s":0},{"p":"38135.8","s":0},{"p":"38135.9","s":2025},{"p":"38139.9","s":0},{"p":"38134.1","s":0}],"s":"BTC_USDT","t":1701245665819,"u":53095239781}}
{"time":1701245665,"time_ms":1701245665854,"channel":"futures.order_book_update","event":"update","result":{"U":53095239782,"a":[{"p":"38151.2","s":0},{"p":"38145.7","s":177050},{"p":"38185.7","s":0},{"p":"38168.8","s":0}],"b":[{"p":"38131.5","s":0},{"p":"38134.4","s":0},{"p":"38136.3","s":15},{"p":"38135.1","s":3362},{"p":"38102.7","s":0},{"p":"38112.1","s":0},{"p":"38140.2","s":0},{"p":"38131.6","s":0},{"p":"38135.3","s":550},{"p":"38135.8","s":2681},{"p":"38136.8","s":0},{"p":"38137","s":0},{"p":"38134.7","s":0}],"s":"BTC_USDT","t":1701245665843,"u":53095239811}}
{"time":1701245665,"time_ms":1701245665882,"channel":"futures.order_book_update","event":"update","result":{"U":53095239812,"a":[{"p":"38158.3","s":0},{"p":"38150.1","s":2116},{"p":"38150.2","s":0}],"b":[{"p":"38140.2","s":428},{"p":"38137.8","s":15208},{"p":"38135.1","s":0}],"s":"BTC_USDT","t":1701245665857,"u":53095239821}}
{"time":1701245665,"time_ms":1701245665911,"channel":"futures.order_book_update","event":"update","result":{"U":53095239822,"a":[{"p":"38150.2","s":2},{"p":"38146.6","s":42359},{"p":"38148","s":4721},{"p":"38146.5","s":0},{"p":"38157.6","s":0},{"p":"38150.5","s":18601},{"p":"38148.5","s":0},{"p":"38150.6","s":0},{"p":"38151.2","s":0},{"p":"38168.5","s":0}],"b":[{"p":"38135.1","s":0},{"p":"38130.5","s":0},{"p":"38072.1","s":0},{"p":"38140.7","s":2},{"p":"38138","s":0}],"s":"BTC_USDT","t":1701245665883,"u":53095239847}}
{"time":1701245665,"time_ms":1701245665945,"channel":"futures.order_book_update","event":"update","result":{"U":53095239848,"a":[{"p":"38162","s":0},{"p":"38150.8","s":0},{"p":"38181.7","s":0},{"p":"38148","s":4720},{"p":"38145.7","s":177080}],"b":[{"p":"38036.4","s":0},{"p":"38141.7","s":26},{"p":"38106.5","s":0},{"p":"38119.8","s":0},{"p":"38122.2","s":0},{"p":"38104.3","s":0},{"p":"38131","s":0}],"s":"BTC_USDT","t":1701245665900,"u":53095239861}}
{"time":1701245665,"time_ms":1701245665946,"channel":"futures.order_book_update","event":"update","result":{"U":53095239862,"a":[{"p":"38169.5","s":0},{"p":"38155.5","s":0},{"p":"38153.9","s":0},{"p":"38154","s":0},{"p":"38146.4","s":3942},{"p":"38162.4","s":0},{"p":"38162.7","s":0}],"b":[{"p":"38140.2","s":432},{"p":"38141.8","s":0},{"p":"38122.2","s":0},{"p":"38134.6","s":0},{"p":"38103.7","s":0},{"p":"38134.5","s":0},{"p":"38138.4","s":2},{"p":"38135.3","s":0},{"p":"38135.8","s":2681},{"p":"38133.2","s":0}],"s":"BTC_USDT","t":1701245665923,"u":53095239885}}
{"time":1701245665,"time_ms":1701245665970,"channel":"futures.order_book_update","event":"update","result":{"U":53095239886,"a":[{"p":"38145.7","s":189182}],"b":[{"p":"38140.4","s":2},{"p":"38139.6","s":2},{"p":"38135.9","s":0},{"p":"38135.8","s":0},{"p":"38132.2","s":0},{"p":"38135.1","s":0},{"p":"38134.3","s":0}],"s":"BTC_USDT","t":1701245665939,"u":53095239898}}
{"time":1701245665,"time_ms":1701245665981,"channel":"futures.order_book_update","event":"update","result":{"U":53095239899,"a":[{"p":"38150.5","s":0},{"p":"38149.2","s":92},{"p":"38148.7","s":20374}],"b":[{"p":"38145.6","s":2592}],"s":"BTC_USDT","t":1701245665961,"u":53095239906}}
{"time":1701245666,"time_ms":1701245666010,"channel":"futures.order_book_update","event":"update","result":{"U":53095239907,"a":[{"p":"38147.1","s":394},{"p":"38150.2","s":0},{"p":"38156","s":0},{"p":"38151.5","s":0},{"p":"38163.5","s":0}],"b":[{"p":"38145.6","s":10243}],"s":"BTC_USDT","t":1701245665982,"u":53095239922}}
{"time":1701245666,"time_ms":1701245666013,"channel":"futures.order_book_update","event":"update","result":{"U":53095239923,"a":[{"p":"38154.8","s":0},{"p":"38159","s":0},{"p":"38147.1","s":919}],"b":[{"p":"38102.4","s":0}],"s":"BTC_USDT","t":1701245666002,"u":53095239933}}
{"time":1701245666,"time_ms":1701245666032,"channel":"futures.order_book_update","event":"update","result":{"U":53095239934,"a":[{"p":"38146.5","s":2174},{"p":"38149.9","s":0},{"p":"38147.2","s":0},{"p":"38154.5","s":0},{"p":"38151.8","s":0},{"p":"38150.1","s":0},{"p":"38146","s":2174},{"p":"38147.9","s":4493},{"p":"38145.7","s":183668},{"p":"38146.3","s":3340},{"p":"38150","s":0}],"b":[{"p":"38132.2","s":0},{"p":"38131.4","s":0},{"p":"38141.7","s":15026},{"p":"38136.3","s":0},{"p":"38120","s":0},{"p":"38134.6","s":0},{"p":"38133.3","s":0},{"p":"38123.7","s":0},{"p":"38137.5","s":8913},{"p":"38104.6","s":0},{"p":"38126.7","s":0}],"s":"BTC_USDT","t":1701245666022,"u":53095239966}}
{"time":1701245666,"time_ms":1701245666055,"channel":"futures.order_book_update","event":"update","result":{"U":53095239967,"a":[{"p":"38146.5","s":0},{"p":"38146.3","s":0},{"p":"38150","s":0},{"p":"38150.1","s":0},{"p":"38146","s":0},{"p":"38148.6","s":2379},{"p":"38149.9","s":109},{"p":"38147.9","s":2174},{"p":"38147.1","s":4259},{"p":"38151.3","s":0},{"p":"38155.4","s":0},{"p":"38146.9","s":2174}],"b":[{"p":"38129","s":0},{"p":"38132.7","s":0},{"p":"38141.8","s":9038},{"p":"38140.2","s":0},{"p":"38134.1","s":0},{"p":"38136.4","s":2621}],"s":"BTC_USDT","t":1701245666039,"u":53095239990}}
{"time":1701245666,"time_ms":1701245666074,"channel":"futures.order_book_update","event":"update","result":{"U":53095239991,"a":[{"p":"38147.1","s":4259},{"p":"38146.9","s":2174},{"p":"38145.7","s":190768},{"p":"38150","s":0}],"b":[{"p":"38133.4","s":0},{"p":"38134","s":0}],"s":"BTC_USDT","t":1701245666063,"u":53095239999}}
{"time":1701245666,"time_ms":1701245666094,"channel":"futures.order_book_update","event":"update","result":{"U":53095240000,"a":[{"p":"38154.4","s":0},{"p":"38147.1","s":919},{"p":"38148.1","s":10038},{"p":"38147.9","s":3340},{"p":"38150","s":0}],"b":[{"p":"38113.4","s":0},{"p":"38133.4","s":0}],"s":"BTC_USDT","t":1701245666084,"u":53095240010}}
{"time":1701245666,"time_ms":1701245666113,"channel":"futures.order_book_update","event":"update","result":{"U":53095240011,"a":[{"p":"38148.1","s":7864},{"p":"38158.5","s":0},{"p":"38167.8","s":0},{"p":"38154.5","s":0}],"b":[{"p":"38136.5","s":8913},{"p":"38137.5","s":0},{"p":"38134.1","s":0},{"p":"38136.3","s":0},{"p":"38133.5","s":0},{"p":"38134.8","s":0}],"s":"BTC_USDT","t":1701245666096,"u":53095240025}}
{"time":1701245666,"time_ms":1701245666134,"channel":"futures.order_book_update","event":"update","result":{"U":53095240026,"a":[{"p":"38148.6","s":4553},{"p":"38160.1","s":0},{"p":"38153.7","s":0}],"b":[{"p":"38135.9","s":0},{"p":"38136.6","s":5539},{"p":"38144.5","s":655},{"p":"38141.7","s":26},{"p":"38136.4","s":0},{"p":"38134.8","s":0},{"p":"38126.4","s":0},{"p":"38132.4","s":0}],"s":"BTC_USDT","t":1701245666122,"u":53095240040}}
{"time":1701245666,"time_ms":1701245666151,"channel":"futures.order_book_update","event":"update","result":{"U":53095240041,"a":[{"p":"38145.7","s":190918}],"b":[],"s":"BTC_USDT","t":1701245666126,"u":53095240042}}
{"time":1701245666,"time_ms":1701245666173,"channel":"futures.order_book_update","event":"update","result":{"U":53095240043,"a":[{"p":"38147.9","s":3340},{"p":"38175.9","s":0},{"p":"38165.3","s":0}],"b":[{"p":"38136.4","s":2621},{"p":"38140.2","s":429},{"p":"38136.3","s":15},{"p":"38144.5","s":0},{"p":"38141.8","s":0},{"p":"38141.3","s":0},{"p":"38136.5","s":8913},{"p":"38141.7","s":15026}],"s":"BTC_USDT","t":1701245666157,"u":53095240057}}
{"time":1701245666,"time_ms":1701245666194,"channel":"futures.order_book_update","event":"update","result":{"U":53095240058,"a":[],"b":[{"p":"38141.8","s":9016},{"p":"38140.2","s":0},{"p":"38136.3","s":15},{"p":"38134.7","s":0}],"s":"BTC_USDT","t":1701245666177,"u":53095240061}}
{"time":1701245666,"time_ms":1701245666213,"channel":"futures.order_book_update","event":"update","result":{"U":53095240062,"a":[],"b":[{"p":"38134.9","s":0},{"p":"38136.5","s":9513}],"s":"BTC_USDT","t":1701245666193,"u":53095240067}}
{"time":1701245666,"time_ms":1701245666231,"channel":"futures.order_book_update","event":"update","result":{"U":53095240068,"a":[],"b":[{"p":"38135.3","s":550},{"p":"38135.8","s":2733},{"p":"38139.6","s":0},{"p":"38126.2","s":0},{"p":"38126.1","s":0},{"p":"38126.4","s":0},{"p":"38135.1","s":3362},{"p":"38138.4","s":0},{"p":"38140.7","s":0},{"p":"38140.4","s":0},{"p":"38134","s":0},{"p":"38134.2","s":2908}],"s":"BTC_USDT","t":1701245666219,"u":53095240081}}
{"time":1701245666,"time_ms":1701245666253,"channel":"futures.order_book_update","event":"update","result":{"U":53095240082,"a":[{"p":"38147.1","s":3020},{"p":"38147.3","s":2875},{"p":"38147.2","s":394},{"p":"38149.9","s":0},{"p":"38151.8","s":0}],"b":[{"p":"38140.9","s":2},{"p":"38134.2","s":0}],"s":"BTC_USDT","t":1701245666242,"u":53095240092}}
{"time":1701245666,"time_ms":1701245666276,"channel":"futures.order_book_update","event":"update","result":{"U":53095240093,"a":[{"p":"38157.5","s":0},{"p":"38153.5","s":0},{"p":"38167","s":0}],"b":[{"p":"38136.5","s":600},{"p":"38132.5","s":0},{"p":"38139","s":2},{"p":"38141.6","s":2},{"p":"38140.1","s":584},{"p":"38141.7","s":26},{"p":"38135.1","s":0},{"p":"38135.3","s":0},{"p":"38125","s":0}],"s":"BTC_USDT","t":1701245666259,"u":53095240110}}
{"time":1701245666,"time_ms":1701245666297,"channel":"futures.order_book_update","event":"update","result":{"U":53095240111,"a":[{"p":"38147.3","s":3400}],"b":[{"p":"38136.6","s":183},{"p":"38135.9","s":2021},{"p":"38140.2","s":430},{"p":"38141.8","s":0},{"p":"38135.8","s":0}],"s":"BTC_USDT","t":1701245666280,"u":53095240115}}
{"time":1701245666,"time_ms":1701245666313,"channel":"futures.order_book_update","event":"update","result":{"U":53095240116,"a":[{"p":"38149.9","s":109},{"p":"38146.9","s":0},{"p":"38154.4","s":0},{"p":"38157.8","s":0}],"b":[{"p":"38135.8","s":2733},{"p":"38135.9","s":0}],"s":"BTC_USDT","t":1701245666302,"u":53095240122}}
{"time":1701245666,"time_ms":1701245666331,"channel":"futures.order_book_update","event":"update","result":{"U":53095240123,"a":[{"p":"38147.8","s":2174},{"p":"38149.9","s":0},{"p":"38153.4","s":0}],"b":[],"s":"BTC_USDT","t":1701245666309,"u":53095240126}}
{"time":1701245666,"time_ms":1701245666352,"channel":"futures.order_book_update","event":"update","result":{"U":53095240127,"a":[{"p":"38147.9","s":5514},{"p":"38146.5","s":2174},{"p":"38147.8","s":0},{"p":"38149.9","s":0},{"p":"38148.6","s":2379},{"p":"38147.2","s":919}],"b":[{"p":"38135.4","s":5352},{"p":"38136.5","s":0},{"p":"38135.1","s":3362},{"p":"38141.6","s":0},{"p":"38139","s":0},{"p":"38140.9","s":0},{"p":"38133.3","s":0},{"p":"38140.1","s":582},{"p":"38135","s":8913},{"p":"38135.3","s":550}],"s":"BTC_USDT","t":1701245666335,"u":53095240140}}
{"time":1701245666,"time_ms":1701245666373,"channel":"futures.order_book_update","event":"update","result":{"U":53095240141,"a":[],"b":[{"p":"38140.8","s":2},{"p":"38140.1","s":584},{"p":"38141.6","s":2},{"p":"38138.9","s":3},{"p":"38135.1","s":0},{"p":"38135","s":0}],"s":"BTC_USDT","t":1701245666350,"u":53095240144}}
{"time":1701245666,"time_ms":1701245666412,"channel":"futures.order_book_update","event":"update","result":{"U":53095240145,"a":[{"p":"38146.6","s":42361},{"p":"38151.8","s":0}],"b":[{"p":"38135.1","s":3362},{"p":"38141.6","s":0},{"p":"38140.8","s":0},{"p":"38140.1","s":582},{"p":"38138.9","s":1},{"p":"38135","s":8913}],"s":"BTC_USDT","t":1701245666401,"u":53095240152}}
{"time":1701245666,"time_ms":1701245666452,"channel":"futures.order_book_update","event":"update","result":{"U":53095240153,"a":[],"b":[{"p":"38133","s":0},{"p":"38138","s":100},{"p":"38136.7","s":525},{"p":"38135.9","s":2},{"p":"38135.1","s":0},{"p":"38135.3","s":0},{"p":"38135","s":0}],"s":"BTC_USDT","t":1701245666443,"u":53095240162}}
{"time":1701245666,"time_ms":1701245666472,"channel":"futures.order_book_update","event":"update","result":{"U":53095240163,"a":[],"b":[{"p":"38138","s":200},{"p":"38132","s":0}],"s":"BTC_USDT","t":1701245666452,"u":53095240164}}
{"time":1701245666,"time_ms":1701245666514,"channel":"futures.order_book_update","event":"update","result":{"U":53095240165,"a":[{"p":"38147.2","s":3093},{"p":"38148.5","s":2174},{"p":"38147.9","s":3340},{"p":"38146.5","s":0},{"p":"38149.6","s":40}],"b":[],"s":"BTC_USDT","t":1701245666494,"u":53095240170}}
{"time":1701245666,"time_ms":1701245666533,"channel":"futures.order_book_update","event":"update","result":{"U":53095240171,"a":[{"p":"38146.3","s":2174},{"p":"38149.9","s":109},{"p":"38148.5","s":0},{"p":"38152.1","s":0},{"p":"38147.8","s":0},{"p":"38153.1","s":0},{"p":"38147.2","s":3224},{"p":"38147","s":2774},{"p":"38148.6","s":0},{"p":"38157.5","s":0},{"p":"38149.6","s":40}],"b":[{"p":"38135.3","s":550},{"p":"38133.2","s":0},{"p":"38129.4","s":0},{"p":"38134.3","s":0},{"p":"38133.4","s":0},{"p":"38125.6","s":0},{"p":"38135.9","s":0},{"p":"38132.7","s":0},{"p":"38125","s":0},{"p":"38134.2","s":0},{"p":"38135.1","s":0}],"s":"BTC_USDT","t":1701245666524,"u":53095240202}}
{"time":1701245666,"time_ms":1701245666554,"channel":"futures.order_book_update","event":"update","result":{"U":53095240203,"a":[{"p":"38150.1","s":0},{"p":"38145.7","s":190918},{"p":"38147","s":600},{"p":"38147.2","s":919},{"p":"38146.6","s":42359},{"p":"38147.9","s":0},{"p":"38150","s":0},{"p":"38151.2","s":0},{"p":"38149.9","s":109},{"p":"38147.8","s":7857},{"p":"38146.3","s":2174}],"b":[{"p":"38132.8","s":0},{"p":"38127.9","s":0},{"p":"38128.5","s":0},{"p":"38133.3","s":0},{"p":"38132","s":0}],"s":"BTC_USDT","t":1701245666546,"u":53095240229}}
{"time":1701245666,"time_ms":1701245666571,"channel":"futures.order_book_update","event":"update","result":{"U":53095240230,"a":[{"p":"38148.5","s":2174},{"p":"38145.7","s":190920},{"p":"38147.8","s":5683},{"p":"38149.9","s":0}],"b":[{"p":"38032.5","s":0}],"s":"BTC_USDT","t":1701245666564,"u":53095240241}}
{"time":1701245666,"time_ms":1701245666594,"channel":"futures.order_book_update","event":"update","result":{"U":53095240242,"a":[],"b":[{"p":"38133","s":0}],"s":"BTC_USDT","t":1701245666578,"u":53095240244}}
{"time":1701245666,"time_ms":1701245666679,"channel":"futures.order_book_update","event":"update","result":{"U":53095240245,"a":[{"p":"38164","s":0},{"p":"38151.5","s":0},{"p":"38155.5","s":0}],"b":[{"p":"38135.3","s":0},{"p":"38135","s":0},{"p":"38122.5","s":0},{"p":"38131","s":0},{"p":"38136.5","s":8913}],"s":"BTC_USDT","t":1701245666668,"u":53095240265}}
{"time":1701245666,"time_ms":1701245666692,"channel":"futures.order_book_update","event":"update","result":{"U":53095240266,"a":[{"p":"38149.6","s":0},{"p":"38146","s":655}],"b":[],"s":"BTC_USDT","t":1701245666677,"u":53095240266}}
{"time":1701245666,"time_ms":1701245666714,"channel":"futures.order_book_update","event":"update","result":{"U":53095240267,"a":[{"p":"38154.9","s":0}],"b":[{"p":"38135.3","s":550},{"p":"38136.6","s":5538},{"p":"38135.4","s":0}],"s":"BTC_USDT","t":1701245666697,"u":53095240272}}
{"time":1701245666,"time_ms":1701245666733,"channel":"futures.order_book_update","event":"update","result":{"U":53095240273,"a":[{"p":"38147.3","s":3925}],"b":[{"p":"38135.8","s":2733},{"p":"38129.1","s":0},{"p":"38141.2","s":393},{"p":"38141.1","s":655},{"p":"38140.2","s":0},{"p":"38135.3","s":0}],"s":"BTC_USDT","t":1701245666726,"u":53095240279}}
{"time":1701245666,"time_ms":1701245666752,"channel":"futures.order_book_update","event":"update","result":{"U":53095240280,"a":[],"b":[{"p":"38133.1","s":0},{"p":"38141.2","s":395},{"p":"38131.2","s":0},{"p":"38140.2","s":0},{"p":"38132.4","s":0},{"p":"38135.8","s":2733},{"p":"38133.9","s":0},{"p":"38135.3","s":0}],"s":"BTC_USDT","t":1701245666738,"u":53095240288}}
{"time":1701245666,"time_ms":1701245666792,"channel":"futures.order_book_update","event":"update","result":{"U":53095240289,"a":[],"b":[{"p":"38139","s":100},{"p":"38138","s":100},{"p":"38135.8","s":0}],"s":"BTC_USDT","t":1701245666783,"u":53095240298}}
{"time":1701245666,"time_ms":1701245666812,"channel":"futures.order_book_update","event":"update","result":{"U":53095240299,"a":[],"b":[{"p":"38106.5","s":0}],"s":"BTC_USDT","t":1701245666800,"u":53095240300}}
{"time":1701245666,"time_ms":1701245666873,"channel":"futures.order_book_update","event":"update","result":{"U":53095240301,"a":[{"p":"38145.7","s":163420}],"b":[],"s":"BTC_USDT","t":1701245666854,"u":53095240302}}
{"time":1701245666,"time_ms":1701245666973,"channel":"futures.order_book_update","event":"update","result":{"U":53095240303,"a":[{"p":"38145.7","s":163418},{"p":"38153.5","s":0},{"p":"38157.5","s":0},{"p":"38166","s":0}],"b":[{"p":"38136.9","s":3633},{"p":"38145.6","s":2592},{"p":"38136.5","s":0},{"p":"38136.3","s":15},{"p":"38124","s":0},{"p":"38132.5","s":0}],"s":"BTC_USDT","t":1701245666957,"u":53095240318}}
{"time":1701245666,"time_ms":1701245666991,"channel":"futures.order_book_update","event":"update","result":{"U":53095240319,"a":[{"p":"38145.7","s":163420},{"p":"38162.9","s":0}],"b":[{"p":"38121.7","s":0},{"p":"38136.6","s":183},{"p":"38135.9","s":0}],"s":"BTC_USDT","t":1701245666980,"u":53095240328}}
{"time":1701245667,"time_ms":1701245667013,"channel":"futures.order_book_update","event":"update","result":{"U":53095240329,"a":[{"p":"38158.3","s":0},{"p":"38186.9","s":0}],"b":[{"p":"38123.4","s":0}],"s":"BTC_USDT","t":1701245666983,"u":53095240331}}
{"time":1701245667,"time_ms":1701245667037,"channel":"futures.order_book_update","event":"update","result":{"U":53095240332,"a":[{"p":"38149.4","s":560},{"p":"38155.7","s":0},{"p":"38145.7","s":163479},{"p":"38147.9","s":5514},{"p":"38147.7","s":2300},{"p":"38148.5","s":0},{"p":"38147.8","s":0}],"b":[{"p":"38132.2","s":0},{"p":"38132.4","s":0},{"p":"38131.2","s":0},{"p":"38134.3","s":0},{"p":"38133.1","s":0},{"p":"38124.1","s":0},{"p":"38133.9","s":0},{"p":"38129","s":0}],"s":"BTC_USDT","t":1701245667027,"u":53095240354}}
{"time":1701245667,"time_ms":1701245667114,"channel":"futures.order_book_update","event":"update","result":{"U":53095240355,"a":[],"b":[{"p":"38135.8","s":2733},{"p":"38141.1","s":0},{"p":"38132.8","s":0}],"s":"BTC_USDT","t":1701245667099,"u":53095240361}}
{"time":1701245667,"time_ms":1701245667133,"channel":"futures.order_book_update","event":"update","result":{"U":53095240362,"a":[],"b":[{"p":"38141.2","s":0},{"p":"38135.4","s":0},{"p":"38145.6","s":10243},{"p":"38140.2","s":434}],"s":"BTC_USDT","t":1701245667122,"u":53095240364}}
{"time":1701245667,"time_ms":1701245667152,"channel":"futures.order_book_update","event":"update","result":{"U":53095240365,"a":[{"p":"38146.3","s":0},{"p":"38147.7","s":0},{"p":"38149.6","s":0},{"p":"38151.7","s":0},{"p":"38172.1","s":0},{"p":"38147.9","s":2306},{"p":"38148.6","s":5514},{"p":"38146.9","s":2174}],"b":[{"p":"38132.7","s":0}],"s":"BTC_USDT","t":1701245667135,"u":53095240379}}
{"time":1701245667,"time_ms":1701245667193,"channel":"futures.order_book_update","event":"update","result":{"U":53095240380,"a":[{"p":"38160.7","s":0},{"p":"38155","s":0},{"p":"38164.5","s":0},{"p":"38151.1","s":0},{"p":"38168.3","s":0}],"b":[{"p":"38120.5","s":0},{"p":"38100.3","s":0},{"p":"38124.3","s":0},{"p":"38116.6","s":0},{"p":"38125.6","s":0},{"p":"38135.8","s":2681}],"s":"BTC_USDT","t":1701245667184,"u":53095240392}}
{"time":1701245667,"time_ms":1701245667214,"channel":"futures.order_book_update","event":"update","result":{"U":53095240393,"a":[{"p":"38159.8","s":0},{"p":"38146.6","s":42285}],"b":[{"p":"38135.4","s":5352},{"p":"38136.7","s":0}],"s":"BTC_USDT","t":1701245667195,"u":53095240396}}
{"time":1701245667,"time_ms":1701245667291,"channel":"futures.order_book_update","event":"update","result":{"U":53095240397,"a":[{"p":"38145.7","s":163477}],"b":[],"s":"BTC_USDT","t":1701245667279,"u":53095240399}}
{"time":1701245667,"time_ms":1701245667313,"channel":"futures.order_book_update","event":"update","result":{"U":53095240400,"a":[],"b":[{"p":"38141.7","s":15026}],"s":"BTC_USDT","t":1701245667303,"u":53095240401}}
{"time":1701245667,"time_ms":1701245667333,"channel":"futures.order_book_update","event":"update","result":{"U":53095240402,"a":[{"p":"38151.9","s":0}],"b":[{"p":"38135.8","s":0},{"p":"38140.8","s":2},{"p":"38140.2","s":0},{"p":"38136.3","s":0},{"p":"38133.9","s":0},{"p":"38133.1","s":0},{"p":"38141.8","s":9023},{"p":"38139.7","s":2},{"p":"38125.8","s":0},{"p":"38141.6","s":2},{"p":"38135.4","s":0},{"p":"38132.4","s":0},{"p":"38131.2","s":0},{"p":"38142.4","s":2},{"p":"38136.4","s":0}],"s":"BTC_USDT","t":1701245667324,"u":53095240416}}
{"time":1701245667,"time_ms":1701245667374,"channel":"futures.order_book_update","event":"update","result":{"U":53095240417,"a":[],"b":[{"p":"38138.9","s":3634}],"s":"BTC_USDT","t":1701245667348,"u":53095240417}}
{"time":1701245667,"time_ms":1701245667393,"channel":"futures.order_book_update","event":"update","result":{"U":53095240418,"a":[],"b":[{"p":"38139","s":2289},{"p":"38132.9","s":0}],"s":"BTC_USDT","t":1701245667385,"u":53095240420}}
{"time":1701245667,"time_ms":1701245667412,"channel":"futures.order_book_update","event":"update","result":{"U":53095240421,"a":[],"b":[{"p":"38123.6","s":0},{"p":"38134.1","s":0},{"p":"38133.7","s":0}],"s":"BTC_USDT","t":1701245667398,"u":53095240427}}
{"time":1701245667,"time_ms":1701245667476,"channel":"futures.order_book_update","event":"update","result":{"U":53095240428,"a":[],"b":[{"p":"38141.7","s":26},{"p":"38105.8","s":0}],"s":"BTC_USDT","t":1701245667462,"u":53095240430}}
{"time":1701245667,"time_ms":1701245667493,"channel":"futures.order_book_update","event":"update","result":{"U":53095240431,"a":[],"b":[{"p":"38136.4","s":2621},{"p":"38141.8","s":0}],"s":"BTC_USDT","t":1701245667478,"u":53095240431}}
{"time":1701245667,"time_ms":1701245667532,"channel":"futures.order_book_update","event":"update","result":{"U":53095240432,"a":[{"p":"38153.1","s":0}],"b":[],"s":"BTC_USDT","t":1701245667510,"u":53095240432}}
{"time":1701245667,"time_ms":1701245667573,"channel":"futures.order_book_update","event":"update","result":{"U":53095240433,"a":[{"p":"38155.5","s":0},{"p":"38164","s":0},{"p":"38151.5","s":0}],"b":[{"p":"38136.5","s":8913},{"p":"38136.4","s":0},{"p":"38131","s":0},{"p":"38135","s":0},{"p":"38122.5","s":0}],"s":"BTC_USDT","t":1701245667560,"u":53095240445}}
{"time":1701245667,"time_ms":1701245667594,"channel":"futures.order_book_update","event":"update","result":{"U":53095240446,"a":[{"p":"38154.9","s":0}],"b":[{"p":"38136.6","s":5530},{"p":"38135.4","s":0},{"p":"38132.2","s":0},{"p":"38133.3","s":0}],"s":"BTC_USDT","t":1701245667584,"u":53095240452}}
{"time":1701245667,"time_ms":1701245667613,"channel":"futures.order_book_update","event":"update","result":{"U":53095240453,"a":[],"b":[{"p":"38133.3","s":0}],"s":"BTC_USDT","t":1701245667588,"u":53095240454}}
{"time":1701245667,"time_ms":1701245667653,"channel":"futures.order_book_update","event":"update","result":{"U":53095240455,"a":[],"b":[{"p":"38121.9","s":0}],"s":"BTC_USDT","t":1701245667630,"u":53095240455}}
{"time":1701245667,"time_ms":1701245667672,"channel":"futures.order_book_update","event":"update","result":{"U":53095240456,"a":[{"p":"38154.6","s":0},{"p":"38153.1","s":0}],"b":[{"p":"38133.7","s":0}],"s":"BTC_USDT","t":1701245667653,"u":53095240459}}
{"time":1701245667,"time_ms":1701245667732,"channel":"futures.order_book_update","event":"update","result":{"U":53095240460,"a":[{"p":"38178.3","s":0}],"b":[],"s":"BTC_USDT","t":1701245667714,"u":53095240463}}
{"time":1701245667,"time_ms":1701245667752,"channel":"futures.order_book_update","event":"update","result":{"U":53095240464,"a":[],"b":[{"p":"38071.2","s":0}],"s":"BTC_USDT","t":1701245667736,"u":53095240465}}
{"time":1701245667,"time_ms":1701245667791,"channel":"futures.order_book_update","event":"update","result":{"U":53095240466,"a":[],"b":[{"p":"38140.2","s":655},{"p":"38136.5","s":0}],"s":"BTC_USDT","t":1701245667778,"u":53095240469}}
{"time":1701245667,"time_ms":1701245667812,"channel":"futures.order_book_update","event":"update","result":{"U":53095240470,"a":[],"b":[{"p":"38122.2","s":0}],"s":"BTC_USDT","t":1701245667798,"u":53095240475}}
{"time":1701245667,"time_ms":1701245667833,"channel":"futures.order_book_update","event":"update","result":{"U":53095240476,"a":[{"p":"38153.2","s":0}],"b":[],"s":"BTC_USDT","t":1701245667819,"u":53095240476}}
{"time":1701245667,"time_ms":1701245667853,"channel":"futures.order_book_update","event":"update","result":{"U":53095240477,"a":[{"p":"38148.6","s":2174},{"p":"38149.1","s":3340},{"p":"38149.4","s":0},{"p":"38149.6","s":0},{"p":"38145.7","s":168977},{"p":"38148.5","s":2366},{"p":"38147.8","s":2174},{"p":"38147.9","s":0},{"p":"38146.9","s":0},{"p":"38152","s":0}],"b":[{"p":"38129.2","s":0},{"p":"38141.7","s":15028},{"p":"38142.5","s":2},{"p":"38142.4","s":0},{"p":"38135.8","s":0},{"p":"38140.8","s":0},{"p":"38139.7","s":0},{"p":"38136.3","s":0},{"p":"38136.5","s":8913},{"p":"38141.8","s":9016},{"p":"38136.4","s":2621},{"p":"38141.6","s":0}],"s":"BTC_USDT","t":1701245667844,"u":53095240495}}
{"time":1701245667,"time_ms":1701245667875,"channel":"futures.order_book_update","event":"update","result":{"U":53095240496,"a":[{"p":"38149.4","s":560},{"p":"38147.2","s":3093},{"p":"38145.7","s":163477},{"p":"38147.8","s":0},{"p":"38147.1","s":3020}],"b":[{"p":"38139.8","s":133},{"p":"38141","s":2},{"p":"38136.4","s":0},{"p":"38129.7","s":0}],"s":"BTC_USDT","t":1701245667866,"u":53095240505}}
{"time":1701245667,"time_ms":1701245667893,"channel":"futures.order_book_update","event":"update","result":{"U":53095240506,"a":[],"b":[{"p":"38132.7","s":0}],"s":"BTC_USDT","t":1701245667884,"u":53095240509}}
{"time":1701245667,"time_ms":1701245667913,"channel":"futures.order_book_update","event":"update","result":{"U":53095240510,"a":[{"p":"38147.2","s":919},{"p":"38147.9","s":2174},{"p":"38149.4","s":0},{"p":"38155.4","s":0}],"b":[{"p":"38134","s":0},{"p":"38103.5","s":0}],"s":"BTC_USDT","t":1701245667901,"u":53095240518}}
{"time":1701245667,"time_ms":1701245667932,"channel":"futures.order_book_update","event":"update","result":{"U":53095240519,"a":[{"p":"38149.4","s":560},{"p":"38149","s":2174},{"p":"38149.1","s":0},{"p":"38148.6","s":0},{"p":"38152.3","s":0}],"b":[{"p":"38133.5","s":0},{"p":"38132.9","s":0}],"s":"BTC_USDT","t":1701245667924,"u":53095240528}}
{"time":1701245667,"time_ms":1701245667951,"channel":"futures.order_book_update","event":"update","result":{"U":53095240529,"a":[{"p":"38155.9","s":0},{"p":"38149.8","s":0},{"p":"38149","s":2352},{"p":"38149.6","s":40},{"p":"38148.5","s":0}],"b":[{"p":"38132.2","s":0}],"s":"BTC_USDT","t":1701245667936,"u":53095240536}}
{"time":1701245667,"time_ms":1701245667971,"channel":"futures.order_book_update","event":"update","result":{"U":53095240537,"a":[{"p":"38152.7","s":0}],"b":[{"p":"38136.5","s":0},{"p":"38133.4","s":0},{"p":"38140.8","s":3633}],"s":"BTC_USDT","t":1701245667951,"u":53095240541}}
{"time":1701245667,"time_ms":1701245667993,"channel":"futures.order_book_update","event":"update","result":{"U":53095240542,"a":[{"p":"38154.1","s":0}],"b":[{"p":"38138","s":200},{"p":"38141","s":0},{"p":"38142.5","s":0},{"p":"38136.5","s":8913},{"p":"38141.7","s":15026},{"p":"38139.8","s":131},{"p":"38139","s":2189},{"p":"38138.9","s":3633},{"p":"38136.4","s":2621}],"s":"BTC_USDT","t":1701245667984,"u":53095240551}}
{"time":1701245668,"time_ms":1701245668011,"channel":"futures.order_book_update","event":"update","result":{"U":53095240552,"a":[],"b":[{"p":"38141","s":2},{"p":"38139.9","s":2},{"p":"38136.6","s":0},{"p":"38136.5","s":0},{"p":"38136.4","s":0},{"p":"38125.5","s":0},{"p":"38141.8","s":9018},{"p":"38142.5","s":2}],"s":"BTC_USDT","t":1701245667999,"u":53095240557}}
{"time":1701245668,"time_ms":1701245668032,"channel":"futures.order_book_update","event":"update","result":{"U":53095240558,"a":[{"p":"38149.9","s":0},{"p":"38149.2","s":2266}],"b":[{"p":"38141","s":0},{"p":"38139.9","s":0},{"p":"38129.4","s":0},{"p":"38136.6","s":5530},{"p":"38141.8","s":9016},{"p":"38142.5","s":0},{"p":"38133.3","s":0},{"p":"38136.4","s":2621},{"p":"38136.5","s":8913}],"s":"BTC_USDT","t":1701245668017,"u":53095240567}}
{"time":1701245668,"time_ms":1701245668053,"channel":"futures.order_book_update","event":"update","result":{"U":53095240568,"a":[{"p":"38153.3","s":0},{"p":"38149.6","s":40},{"p":"38156.7","s":0},{"p":"38148.6","s":2305},{"p":"38149","s":0}],"b":[{"p":"38125.6","s":0},{"p":"38141","s":2},{"p":"38136.4","s":0},{"p":"38134.4","s":0},{"p":"38136.5","s":0},{"p":"38136.6","s":0},{"p":"38125.5","s":0},{"p":"38142.5","s":2},{"p":"38141.8","s":9018},{"p":"38139.9","s":2}],"s":"BTC_USDT","t":1701245668036,"u":53095240584}}
{"time":1701245668,"time_ms":1701245668113,"channel":"futures.order_book_update","event":"update","result":{"U":53095240585,"a":[],"b":[{"p":"38139","s":2289},{"p":"38126.4","s":0},{"p":"38138","s":100}],"s":"BTC_USDT","t":1701245668090,"u":53095240589}}
{"time":1701245668,"time_ms":1701245668197,"channel":"futures.order_book_update","event":"update","result":{"U":53095240590,"a":[],"b":[{"p":"38095.4","s":0}],"s":"BTC_USDT","t":1701245668182,"u":53095240601}}
{"time":1701245668,"time_ms":1701245668212,"channel":"futures.order_book_update","event":"update","result":{"U":53095240602,"a":[{"p":"38153.5","s":0},{"p":"38165.5","s":0},{"p":"38157.5","s":0}],"b":[{"p":"38134","s":0},{"p":"38132.5","s":0},{"p":"38124.5","s":0},{"p":"38136.5","s":0},{"p":"38133","s":0}],"s":"BTC_USDT","t":1701245668205,"u":53095240619}}
{"time":1701245668,"time_ms":1701245668274,"channel":"futures.order_book_update","event":"update","result":{"U":53095240620,"a":[{"p":"38149.5","s":3340},{"p":"38148.6","s":4479},{"p":"38149.2","s":92},{"p":"38149.6","s":0},{"p":"38149.8","s":0}],"b":[{"p":"38133.7","s":0},{"p":"38134.1","s":0},{"p":"38129.9","s":0}],"s":"BTC_USDT","t":1701245668264,"u":53095240630}}
{"time":1701245668,"time_ms":1701245668293,"channel":"futures.order_book_update","event":"update","result":{"U":53095240631,"a":[],"b":[{"p":"38130.5","s":0},{"p":"38141.7","s":26},{"p":"38134","s":0},{"p":"38136.6","s":0},{"p":"38132.8","s":0},{"p":"38129.7","s":0}],"s":"BTC_USDT","t":1701245668286,"u":53095240639}}
{"time":1701245668,"time_ms":1701245668312,"channel":"futures.order_book_update","event":"update","result":{"U":53095240640,"a":[],"b":[{"p":"38141.8","s":2},{"p":"38140.9","s":2184},{"p":"38136.9","s":0},{"p":"38132.7","s":0}],"s":"BTC_USDT","t":1701245668295,"u":53095240644}}
{"time":1701245668,"time_ms":1701245668371,"channel":"futures.order_book_update","event":"update","result":{"U":53095240645,"a":[],"b":[{"p":"38139.9","s":0},{"p":"38141.8","s":0},{"p":"38141","s":0},{"p":"38136.4","s":2647},{"p":"38136.3","s":15},{"p":"38136.9","s":3633},{"p":"38136.6","s":183},{"p":"38142.5","s":0}],"s":"BTC_USDT","t":1701245668362,"u":53095240648}}
{"time":1701245668,"time_ms":1701245668391,"channel":"futures.order_book_update","event":"update","result":{"U":53095240649,"a":[{"p":"38145.7","s":163479},{"p":"38153.2","s":0}],"b":[],"s":"BTC_USDT","t":1701245668369,"u":53095240650}}
{"time":1701245668,"time_ms":1701245668413,"channel":"futures.order_book_update","event":"update","result":{"U":53095240651,"a":[],"b":[{"p":"38138","s":200},{"p":"38132.2","s":0},{"p":"38129.4","s":0},{"p":"38133.3","s":0},{"p":"38139","s":2189}],"s":"BTC_USDT","t":1701245668395,"u":53095240662}}
{"time":1701245668,"time_ms":1701245668472,"channel":"futures.order_book_update","event":"update","result":{"U":53095240663,"a":[],"b":[{"p":"38135","s":0},{"p":"38131","s":0},{"p":"38123","s":0}],"s":"BTC_USDT","t":1701245668449,"u":53095240665}}
{"time":1701245668,"time_ms":1701245668494,"channel":"futures.order_book_update","event":"update","result":{"U":53095240666,"a":[{"p":"38164.1","s":0}],"b":[{"p":"38080.6","s":0}],"s":"BTC_USDT","t":1701245668484,"u":53095240669}}
{"time":1701245668,"time_ms":1701245668634,"channel":"futures.order_book_update","event":"update","result":{"U":53095240670,"a":[],"b":[{"p":"38113","s":0}],"s":"BTC_USDT","t":1701245668623,"u":53095240678}}
{"time":1701245668,"time_ms":1701245668674,"channel":"futures.order_book_update","event":"update","result":{"U":53095240679,"a":[{"p":"38155.5","s":0}],"b":[{"p":"38120","s":0},{"p":"38136.5","s":8913},{"p":"38136.3","s":0},{"p":"38135","s":0}],"s":"BTC_USDT","t":1701245668666,"u":53095240689}}
{"time":1701245668,"time_ms":1701245668691,"channel":"futures.order_book_update","event":"update","result":{"U":53095240690,"a":[{"p":"38163.5","s":0},{"p":"38151.5","s":0}],"b":[{"p":"38123","s":0},{"p":"38131","s":0}],"s":"BTC_USDT","t":1701245668678,"u":53095240704}}
{"time":1701245668,"time_ms":1701245668712,"channel":"futures.order_book_update","event":"update","result":{"U":53095240705,"a":[{"p":"38154.9","s":0}],"b":[],"s":"BTC_USDT","t":1701245668686,"u":53095240705}}
{"time":1701245668,"time_ms":1701245668750,"channel":"futures.order_book_update","event":"update","result":{"U":53095240706,"a":[],"b":[{"p":"38133.1","s":0},{"p":"38131.2","s":0},{"p":"38132.4","s":0},{"p":"38133.9","s":0}],"s":"BTC_USDT","t":1701245668734,"u":53095240710}}
{"time":1701245668,"time_ms":1701245668773,"channel":"futures.order_book_update","event":"update","result":{"U":53095240711,"a":[],"b":[{"p":"38134","s":0}],"s":"BTC_USDT","t":1701245668761,"u":53095240717}}
{"time":1701245668,"time_ms":1701245668833,"channel":"futures.order_book_update","event":"update","result":{"U":53095240718,"a":[],"b":[{"p":"38126.6","s":0}],"s":"BTC_USDT","t":1701245668810,"u":53095240718}}
{"time":1701245668,"time_ms":1701245668852,"channel":"futures.order_book_update","event":"update","result":{"U":53095240719,"a":[{"p":"38145.7","s":180477}],"b":[{"p":"38131.2","s":0},{"p":"38133.9","s":0},{"p":"38133.1","s":0},{"p":"38132.4","s":0}],"s":"BTC_USDT","t":1701245668840,"u":53095240724}}
{"time":1701245668,"time_ms":1701245668872,"channel":"futures.order_book_update","event":"update","result":{"U":53095240725,"a":[{"p":"38149.2","s":2266},{"p":"38148.6","s":2305}],"b":[{"p":"38136.6","s":783},{"p":"38134.9","s":0}],"s":"BTC_USDT","t":1701245668862,"u":53095240728}}
{"time":1701245668,"time_ms":1701245668893,"channel":"futures.order_book_update","event":"update","result":{"U":53095240729,"a":[{"p":"38145.7","s":180479},{"p":"38149.6","s":40},{"p":"38149.5","s":0},{"p":"38149.8","s":0}],"b":[{"p":"38145.6","s":10251}],"s":"BTC_USDT","t":1701245668882,"u":53095240736}}
{"time":1701245668,"time_ms":1701245668913,"channel":"futures.order_book_update","event":"update","result":{"U":53095240737,"a":[],"b":[{"p":"38134.3","s":0}],"s":"BTC_USDT","t":1701245668890,"u":53095240737}}
{"time":1701245668,"time_ms":1701245668973,"channel":"futures.order_book_update","event":"update","result":{"U":53095240738,"a":[{"p":"38145.7","s":163479}],"b":[{"p":"38136.9","s":7234}],"s":"BTC_USDT","t":1701245668958,"u":53095240741}}
{"time":1701245668,"time_ms":1701245668992,"channel":"futures.order_book_update","event":"update","result":{"U":53095240742,"a":[{"p":"38149.2","s":92},{"p":"38148.6","s":4479}],"b":[{"p":"38122","s":0}],"s":"BTC_USDT","t":1701245668982,"u":53095240745}}
{"time":1701245669,"time_ms":1701245669011,"channel":"futures.order_book_update","event":"update","result":{"U":53095240746,"a":[{"p":"38179.3","s":0}],"b":[],"s":"BTC_USDT","t":1701245668988,"u":53095240749}}
{"time":1701245669,"time_ms":1701245669032,"channel":"futures.order_book_update","event":"update","result":{"U":53095240750,"a":[{"p":"38148.6","s":2174},{"p":"38149.6","s":0},{"p":"38152.8","s":0},{"p":"38149.8","s":0},{"p":"38148.5","s":2325},{"p":"38149.2","s":3432}],"b":[{"p":"38125.6","s":0},{"p":"38133.7","s":0},{"p":"38132.8","s":0},{"p":"38133.3","s":0}],"s":"BTC_USDT","t":1701245669018,"u":53095240765}}
{"time":1701245669,"time_ms":1701245669052,"channel":"futures.order_book_update","event":"update","result":{"U":53095240766,"a":[],"b":[{"p":"38133.1","s":0},{"p":"38133.9","s":0},{"p":"38132.4","s":0},{"p":"38131.2","s":0}],"s":"BTC_USDT","t":1701245669041,"u":53095240769}}
{"time":1701245669,"time_ms":1701245669072,"channel":"futures.order_book_update","event":"update","result":{"U":53095240770,"a":[],"b":[{"p":"38136.6","s":183},{"p":"38133.8","s":0}],"s":"BTC_USDT","t":1701245669051,"u":53095240773}}
{"time":1701245669,"time_ms":1701245669093,"channel":"futures.order_book_update","event":"update","result":{"U":53095240774,"a":[],"b":[{"p":"38129.9","s":0},{"p":"38134.1","s":0}],"s":"BTC_USDT","t":1701245669088,"u":53095240782}}
{"time":1701245669,"time_ms":1701245669112,"channel":"futures.order_book_update","event":"update","result":{"U":53095240783,"a":[{"p":"38149.6","s":0},{"p":"38149.1","s":0},{"p":"38148.6","s":2174},{"p":"38149.4","s":560}],"b":[{"p":"38133","s":0}],"s":"BTC_USDT","t":1701245669099,"u":53095240787}}
{"time":1701245669,"time_ms":1701245669132,"channel":"futures.order_book_update","event":"update","result":{"U":53095240788,"a":[{"p":"38148.6","s":0},{"p":"38149.5","s":0},{"p":"38149.6","s":0},{"p":"38149.2","s":92},{"p":"38145.7","s":163554},{"p":"38149.1","s":5514}],"b":[{"p":"38133.1","s":0},{"p":"38131.2","s":0},{"p":"38132.8","s":0},{"p":"38133.9","s":0},{"p":"38132.4","s":0}],"s":"BTC_USDT","t":1701245669118,"u":53095240800}}
{"time":1701245669,"time_ms":1701245669153,"channel":"futures.order_book_update","event":"update","result":{"U":53095240801,"a":[],"b":[{"p":"38133","s":0}],"s":"BTC_USDT","t":1701245669133,"u":53095240802}}
{"time":1701245669,"time_ms":1701245669233,"channel":"futures.order_book_update","event":"update","result":{"U":53095240803,"a":[],"b":[{"p":"38114.7","s":0}],"s":"BTC_USDT","t":1701245669211,"u":53095240809}}
{"time":1701245669,"time_ms":1701245669271,"channel":"futures.order_book_update","event":"update","result":{"U":53095240810,"a":[],"b":[{"p":"38136.4","s":2621}],"s":"BTC_USDT","t":1701245669262,"u":53095240815}}
{"time":1701245669,"time_ms":1701245669294,"channel":"futures.order_book_update","event":"update","result":{"U":53095240816,"a":[{"p":"38145.7","s":163552}],"b":[{"p":"38136.9","s":0},{"p":"38136.5","s":0},{"p":"38132.4","s":0},{"p":"38132.5","s":0},{"p":"38141.8","s":2},{"p":"38142.6","s":2},{"p":"38136.4","s":0},{"p":"38136.6","s":0},{"p":"38131.2","s":0},{"p":"38133.9","s":0},{"p":"38133.1","s":0},{"p":"38139.9","s":2},{"p":"38141.1","s":2}],"s":"BTC_USDT","t":1701245669283,"u":53095240827}}
{"time":1701245669,"time_ms":1701245669312,"channel":"futures.order_book_update","event":"update","result":{"U":53095240828,"a":[],"b":[{"p":"38138","s":100},{"p":"38139","s":2289}],"s":"BTC_USDT","t":1701245669297,"u":53095240829}}
{"time":1701245669,"time_ms":1701245669334,"channel":"futures.order_book_update","event":"update","result":{"U":53095240830,"a":[],"b":[{"p":"38127.5","s":0}],"s":"BTC_USDT","t":1701245669323,"u":53095240831}}
{"time":1701245669,"time_ms":1701245669375,"channel":"futures.order_book_update","event":"update","result":{"U":53095240832,"a":[],"b":[{"p":"38134","s":0}],"s":"BTC_USDT","t":1701245669352,"u":53095240834}}
{"time":1701245669,"time_ms":1701245669453,"channel":"futures.order_book_update","event":"update","result":{"U":53095240835,"a":[{"p":"38149.4","s":0},{"p":"38148.4","s":2174},{"p":"38149.1","s":3340}],"b":[],"s":"BTC_USDT","t":1701245669441,"u":53095240838}}
{"time":1701245669,"time_ms":1701245669513,"channel":"futures.order_book_update","event":"update","result":{"U":53095240839,"a":[],"b":[{"p":"38133.7","s":0},{"p":"38132.8","s":0},{"p":"38134.1","s":0}],"s":"BTC_USDT","t":1701245669492,"u":53095240846}}
{"time":1701245669,"time_ms":1701245669534,"channel":"futures.order_book_update","event":"update","result":{"U":53095240847,"a":[],"b":[{"p":"38128.4","s":0}],"s":"BTC_USDT","t":1701245669511,"u":53095240847}}
{"time":1701245669,"time_ms":1701245669552,"channel":"futures.order_book_update","event":"update","result":{"U":53095240848,"a":[{"p":"38145.7","s":163542}],"b":[],"s":"BTC_USDT","t":1701245669532,"u":53095240848}}
{"time":1701245669,"time_ms":1701245669571,"channel":"futures.order_book_update","event":"update","result":{"U":53095240849,"a":[],"b":[{"p":"38141.8","s":0},{"p":"38136.9","s":7234},{"p":"38136.6","s":183},{"p":"38144","s":100},{"p":"38142.6","s":0},{"p":"38138","s":0}],"s":"BTC_USDT","t":1701245669562,"u":53095240852}}
{"time":1701245669,"time_ms":1701245669592,"channel":"futures.order_book_update","event":"update","result":{"U":53095240853,"a":[{"p":"38149.4","s":560},{"p":"38147.9","s":0},{"p":"38147.2","s":3093}],"b":[{"p":"38136.5","s":8913},{"p":"38141.1","s":0},{"p":"38139.9","s":0},{"p":"38129.7","s":0},{"p":"38132.6","s":0},{"p":"38136.4","s":2621}],"s":"BTC_USDT","t":1701245669575,"u":53095240860}}
{"time":1701245669,"time_ms":1701245669613,"channel":"futures.order_book_update","event":"update","result":{"U":53095240861,"a":[],"b":[{"p":"38136.5","s":0},{"p":"38136.3","s":0},{"p":"38141.1","s":2},{"p":"38141.8","s":2},{"p":"38142.6","s":2},{"p":"38144","s":0},{"p":"38136.4","s":0}],"s":"BTC_USDT","t":1701245669603,"u":53095240864}}
{"time":1701245669,"time_ms":1701245669632,"channel":"futures.order_book_update","event":"update","result":{"U":53095240865,"a":[],"b":[{"p":"38138","s":100},{"p":"38139.9","s":2},{"p":"38136.9","s":0},{"p":"38136.6","s":0}],"s":"BTC_USDT","t":1701245669608,"u":53095240866}}
{"time":1701245669,"time_ms":1701245669697,"channel":"futures.order_book_update","event":"update","result":{"U":53095240867,"a":[{"p":"38147.2","s":919},{"p":"38147.9","s":2174},{"p":"38149.4","s":0}],"b":[{"p":"38125.4","s":0}],"s":"BTC_USDT","t":1701245669666,"u":53095240869}}
{"time":1701245669,"time_ms":1701245669733,"channel":"futures.order_book_update","event":"update","result":{"U":53095240870,"a":[],"b":[{"p":"38139.9","s":0},{"p":"38142.6","s":0},{"p":"38136.9","s":7234},{"p":"38136.5","s":8913},{"p":"38136.4","s":2621},{"p":"38136.6","s":183},{"p":"38141.8","s":0},{"p":"38141.1","s":0}],"s":"BTC_USDT","t":1701245669711,"u":53095240873}}
{"time":1701245669,"time_ms":1701245669774,"channel":"futures.order_book_update","event":"update","result":{"U":53095240874,"a":[{"p":"38145.7","s":163544},{"p":"38153.3","s":0}],"b":[{"p":"38136.6","s":783},{"p":"38134.9","s":0}],"s":"BTC_USDT","t":1701245669764,"u":53095240881}}
{"time":1701245669,"time_ms":1701245669812,"channel":"futures.order_book_update","event":"update","result":{"U":53095240882,"a":[],"b":[{"p":"38139","s":2189},{"p":"38138","s":200}],"s":"BTC_USDT","t":1701245669796,"u":53095240883}}
{"time":1701245669,"time_ms":1701245669874,"channel":"futures.order_book_update","event":"update","result":{"U":53095240884,"a":[{"p":"38157.5","s":0},{"p":"38153.5","s":0}],"b":[{"p":"38136.6","s":183},{"p":"38137","s":8913},{"p":"38136.5","s":0},{"p":"38136.3","s":0},{"p":"38132.5","s":0}],"s":"BTC_USDT","t":1701245669864,"u":53095240895}}
{"time":1701245669,"time_ms":1701245669892,"channel":"futures.order_book_update","event":"update","result":{"U":53095240896,"a":[{"p":"38149.4","s":560},{"p":"38148","s":7013},{"p":"38148.5","s":0}],"b":[{"p":"38109.5","s":0}],"s":"BTC_USDT","t":1701245669883,"u":53095240898}}
{"time":1701245670,"time_ms":1701245670033,"channel":"futures.order_book_update","event":"update","result":{"U":53095240899,"a":[{"p":"38149.9","s":0},{"p":"38152.7","s":0},{"p":"38149.6","s":40},{"p":"38147.1","s":5194},{"p":"38148.6","s":2174},{"p":"38148.4","s":0},{"p":"38147.9","s":0},{"p":"38156.2","s":0}],"b":[{"p":"38133.4","s":0},{"p":"38129.4","s":0},{"p":"38133.7","s":0}],"s":"BTC_USDT","t":1701245670022,"u":53095240913}}
{"time":1701245670,"time_ms":1701245670053,"channel":"futures.order_book_update","event":"update","result":{"U":53095240914,"a":[{"p":"38148.3","s":2382},{"p":"38149.9","s":109},{"p":"38148.6","s":0}],"b":[{"p":"38129.7","s":0},{"p":"38133.6","s":0}],"s":"BTC_USDT","t":1701245670042,"u":53095240919}}
{"time":1701245670,"time_ms":1701245670174,"channel":"futures.order_book_update","event":"update","result":{"U":53095240920,"a":[],"b":[{"p":"38133.5","s":0}],"s":"BTC_USDT","t":1701245670145,"u":53095240921}}
{"time":1701245670,"time_ms":1701245670232,"channel":"futures.order_book_update","event":"update","result":{"U":53095240922,"a":[],"b":[{"p":"38132.4","s":0},{"p":"38133.1","s":0},{"p":"38131.2","s":0},{"p":"38133.9","s":0}],"s":"BTC_USDT","t":1701245670221,"u":53095240927}}
{"time":1701245670,"time_ms":1701245670352,"channel":"futures.order_book_update","event":"update","result":{"U":53095240928,"a":[],"b":[{"p":"38136.3","s":0},{"p":"38131.2","s":0},{"p":"38132.4","s":0},{"p":"38122","s":0},{"p":"38140.2","s":0},{"p":"38133.1","s":0},{"p":"38133.9","s":0},{"p":"38133.5","s":0},{"p":"38133.4","s":0},{"p":"38132.2","s":0},{"p":"38141","s":655}],"s":"BTC_USDT","t":1701245670346,"u":53095240944}}
{"time":1701245670,"time_ms":1701245670393,"channel":"futures.order_book_update","event":"update","result":{"U":53095240945,"a":[{"p":"38163.6","s":0}],"b":[{"p":"38111.3","s":0},{"p":"38133.3","s":0},{"p":"38132.1","s":0}],"s":"BTC_USDT","t":1701245670384,"u":53095240952}}
{"time":1701245670,"time_ms":1701245670732,"channel":"futures.order_book_update","event":"update","result":{"U":53095240953,"a":[{"p":"38147.1","s":3020},{"p":"38146.5","s":2174},{"p":"38149.9","s":0}],"b":[],"s":"BTC_USDT","t":1701245670709,"u":53095240958}}
{"time":1701245670,"time_ms":1701245670792,"channel":"futures.order_book_update","event":"update","result":{"U":53095240959,"a":[],"b":[{"p":"38133.3","s":0}],"s":"BTC_USDT","t":1701245670775,"u":53095240960}}
{"time":1701245670,"time_ms":1701245670813,"channel":"futures.order_book_update","event":"update","result":{"U":53095240961,"a":[],"b":[{"p":"38139","s":2289},{"p":"38138","s":100}],"s":"BTC_USDT","t":1701245670790,"u":53095240962}}
{"time":1701245670,"time_ms":1701245670833,"channel":"futures.order_book_update","event":"update","result":{"U":53095240963,"a":[],"b":[{"p":"38132","s":0}],"s":"BTC_USDT","t":1701245670818,"u":53095240964}}
{"time":1701245670,"time_ms":1701245670853,"channel":"futures.order_book_update","event":"update","result":{"U":53095240965,"a":[],"b":[{"p":"38133.1","s":0}],"s":"BTC_USDT","t":1701245670837,"u":53095240966}}
{"time":1701245670,"time_ms":1701245670875,"channel":"futures.order_book_update","event":"update","result":{"U":53095240967,"a":[],"b":[{"p":"38080.3","s":0}],"s":"BTC_USDT","t":1701245670850,"u":53095240968}}
{"time":1701245670,"time_ms":1701245670893,"channel":"futures.order_book_update","event":"update","result":{"U":53095240969,"a":[{"p":"38147","s":2774},{"p":"38148.3","s":208},{"p":"38148.6","s":2174},{"p":"38146.5","s":0},{"p":"38149.9","s":0}],"b":[{"p":"38136.6","s":783},{"p":"38134.9","s":0}],"s":"BTC_USDT","t":1701245670882,"u":53095240974}}
{"time":1701245670,"time_ms":1701245670912,"channel":"futures.order_book_update","event":"update","result":{"U":53095240975,"a":[],"b":[{"p":"38132.8","s":0}],"s":"BTC_USDT","t":1701245670885,"u":53095240977}}
{"time":1701245670,"time_ms":1701245670973,"channel":"futures.order_book_update","event":"update","result":{"U":53095240978,"a":[{"p":"38155.9","s":0}],"b":[{"p":"38145.6","s":10751}],"s":"BTC_USDT","t":1701245670960,"u":53095240980}}
{"time":1701245671,"time_ms":1701245671011,"channel":"futures.order_book_update","event":"update","result":{"U":53095240981,"a":[],"b":[{"p":"38139","s":2189},{"p":"38138","s":200}],"s":"BTC_USDT","t":1701245670992,"u":53095240983}}
{"time":1701245671,"time_ms":1701245671032,"channel":"futures.order_book_update","event":"update","result":{"U":53095240984,"a":[{"p":"38147.9","s":2310},{"p":"38148","s":4720},{"p":"38149.6","s":0},{"p":"38155.7","s":0},{"p":"38152.1","s":0}],"b":[{"p":"38133.4","s":0},{"p":"38133.2","s":0},{"p":"38129.5","s":0},{"p":"38133.3","s":0}],"s":"BTC_USDT","t":1701245671020,"u":53095240998}}
{"time":1701245671,"time_ms":1701245671051,"channel":"futures.order_book_update","event":"update","result":{"U":53095240999,"a":[{"p":"38167.1","s":0},{"p":"38149.4","s":560},{"p":"38146.9","s":2174},{"p":"38147","s":600},{"p":"38145.7","s":163542},{"p":"38148.1","s":10038},{"p":"38148.6","s":0}],"b":[{"p":"38121.2","s":0},{"p":"38131.8","s":0}],"s":"BTC_USDT","t":1701245671042,"u":53095241007}}
{"time":1701245671,"time_ms":1701245671072,"channel":"futures.order_book_update","event":"update","result":{"U":53095241008,"a":[{"p":"38149.2","s":3432},{"p":"38149.6","s":40},{"p":"38149.1","s":0},{"p":"38146.9","s":0},{"p":"38145.7","s":163544},{"p":"38148.5","s":2174},{"p":"38148.1","s":7864},{"p":"38149.4","s":560},{"p":"38147.1","s":5194}],"b":[{"p":"38129.7","s":0},{"p":"38109.6","s":0},{"p":"38128","s":0},{"p":"38141.7","s":15026}],"s":"BTC_USDT","t":1701245671064,"u":53095241025}}
{"time":1701245671,"time_ms":1701245671090,"channel":"futures.order_book_update","event":"update","result":{"U":53095241026,"a":[{"p":"38145.7","s":159874},{"p":"38149.2","s":92},{"p":"38147.9","s":0},{"p":"38152","s":0},{"p":"38149.8","s":3340},{"p":"38148.5","s":4550}],"b":[{"p":"38141.8","s":9417},{"p":"38140.9","s":0},{"p":"38136.3","s":0}],"s":"BTC_USDT","t":1701245671074,"u":53095241034}}
{"time":1701245671,"time_ms":1701245671131,"channel":"futures.order_book_update","event":"update","result":{"U":53095241035,"a":[{"p":"38148.5","s":2174},{"p":"38148.4","s":2359},{"p":"38149.8","s":0},{"p":"38148","s":4720}],"b":[{"p":"38132.4","s":0},{"p":"38133.9","s":0},{"p":"38131.2","s":0},{"p":"38133.1","s":0}],"s":"BTC_USDT","t":1701245671122,"u":53095241042}}
{"time":1701245671,"time_ms":1701245671152,"channel":"futures.order_book_update","event":"update","result":{"U":53095241043,"a":[{"p":"38147.9","s":0},{"p":"38147.2","s":3093},{"p":"38147.1","s":3020},{"p":"38149.6","s":40}],"b":[],"s":"BTC_USDT","t":1701245671140,"u":53095241049}}
{"time":1701245671,"time_ms":1701245671173,"channel":"futures.order_book_update","event":"update","result":{"U":53095241050,"a":[{"p":"38147.2","s":919}],"b":[],"s":"BTC_USDT","t":1701245671145,"u":53095241051}}
{"time":1701245671,"time_ms":1701245671192,"channel":"futures.order_book_update","event":"update","result":{"U":53095241052,"a":[{"p":"38147.9","s":2174},{"p":"38149.6","s":0}],"b":[],"s":"BTC_USDT","t":1701245671177,"u":53095241052}}
{"time":1701245671,"time_ms":1701245671217,"channel":"futures.order_book_update","event":"update","result":{"U":53095241053,"a":[{"p":"38147.9","s":0},{"p":"38149.6","s":40},{"p":"38147.2","s":3093}],"b":[],"s":"BTC_USDT","t":1701245671196,"u":53095241054}}
{"time":1701245671,"time_ms":1701245671311,"channel":"futures.order_book_update","event":"update","result":{"U":53095241055,"a":[{"p":"38147.2","s":3483}],"b":[{"p":"38131.2","s":0},{"p":"38132.4","s":0},{"p":"38133.9","s":0},{"p":"38133.1","s":0}],"s":"BTC_USDT","t":1701245671303,"u":53095241061}}
{"time":1701245671,"time_ms":1701245671332,"channel":"futures.order_book_update","event":"update","result":{"U":53095241062,"a":[{"p":"38165.5","s":0},{"p":"38157","s":0},{"p":"38153","s":0}],"b":[{"p":"38123.2","s":0},{"p":"38136.3","s":15},{"p":"38137","s":0},{"p":"38133","s":0}],"s":"BTC_USDT","t":1701245671318,"u":53095241079}}
{"time":1701245671,"time_ms":1701245671413,"channel":"futures.order_book_update","event":"update","result":{"U":53095241080,"a":[],"b":[{"p":"38135.9","s":0},{"p":"38133.8","s":0},{"p":"38135.4","s":0}],"s":"BTC_USDT","t":1701245671393,"u":53095241086}}
{"time":1701245671,"time_ms":1701245671512,"channel":"futures.order_book_update","event":"update","result":{"U":53095241087,"a":[{"p":"38145.7","s":159872}],"b":[],"s":"BTC_USDT","t":1701245671490,"u":53095241087}}
{"time":1701245671,"time_ms":1701245671532,"channel":"futures.order_book_update","event":"update","result":{"U":53095241088,"a":[{"p":"38145.7","s":159874}],"b":[],"s":"BTC_USDT","t":1701245671506,"u":53095241088}}
{"time":1701245671,"time_ms":1701245671557,"channel":"futures.order_book_update","event":"update","result":{"U":53095241089,"a":[{"p":"38149.2","s":92},{"p":"38149.8","s":0},{"p":"38149.7","s":0}],"b":[],"s":"BTC_USDT","t":1701245671523,"u":53095241092}}
{"time":1701245671,"time_ms":1701245671592,"channel":"futures.order_book_update","event":"update","result":{"U":53095241093,"a":[{"p":"38149.6","s":0},{"p":"38152.3","s":0},{"p":"38147.2","s":1309},{"p":"38147.9","s":2174}],"b":[],"s":"BTC_USDT","t":1701245671577,"u":53095241096}}
{"time":1701245671,"time_ms":1701245671673,"channel":"futures.order_book_update","event":"update","result":{"U":53095241097,"a":[],"b":[{"p":"38122.8","s":0}],"s":"BTC_USDT","t":1701245671664,"u":53095241098}}
{"time":1701245671,"time_ms":1701245671692,"channel":"futures.order_book_update","event":"update","result":{"U":53095241099,"a":[{"p":"38166.4","s":0}],"b":[{"p":"38132.4","s":0},{"p":"38133.1","s":0},{"p":"38131.2","s":0},{"p":"38135.9","s":5347},{"p":"38145.6","s":10251},{"p":"38141.7","s":15681},{"p":"38141","s":0},{"p":"38133.9","s":0}],"s":"BTC_USDT","t":1701245671678,"u":53095241107}}
{"time":1701245671,"time_ms":1701245671713,"channel":"futures.order_book_update","event":"update","result":{"U":53095241108,"a":[{"p":"38149.6","s":40},{"p":"38148.3","s":2382},{"p":"38146.9","s":2174},{"p":"38147.9","s":0},{"p":"38148.5","s":0},{"p":"38148","s":4720},{"p":"38152.7","s":0}],"b":[{"p":"38133.3","s":0},{"p":"38133.5","s":0}],"s":"BTC_USDT","t":1701245671702,"u":53095241123}}
{"time":1701245671,"time_ms":1701245671770,"channel":"futures.order_book_update","event":"update","result":{"U":53095241124,"a":[],"b":[{"p":"38133.9","s":0},{"p":"38133.1","s":0},{"p":"38132.4","s":0},{"p":"38131.2","s":0}],"s":"BTC_USDT","t":1701245671748,"u":53095241127}}
{"time":1701245671,"time_ms":1701245671792,"channel":"futures.order_book_update","event":"update","result":{"U":53095241128,"a":[],"b":[{"p":"38129.9","s":0},{"p":"38138","s":100},{"p":"38139","s":2289}],"s":"BTC_USDT","t":1701245671782,"u":53095241131}}
{"time":1701245671,"time_ms":1701245671972,"channel":"futures.order_book_update","event":"update","result":{"U":53095241132,"a":[{"p":"38145.7","s":159872}],"b":[{"p":"38071.8","s":0},{"p":"38049.1","s":0}],"s":"BTC_USDT","t":1701245671963,"u":53095241136}}
{"time":1701245671,"time_ms":1701245671992,"channel":"futures.order_book_update","event":"update","result":{"U":53095241137,"a":[{"p":"38145.7","s":159874}],"b":[{"p":"38114.5","s":0}],"s":"BTC_USDT","t":1701245671980,"u":53095241138}}
{"time":1701245672,"time_ms":1701245672032,"channel":"futures.order_book_update","event":"update","result":{"U":53095241139,"a":[{"p":"38149.1","s":3340},{"p":"38147.9","s":2174},{"p":"38146.9","s":0},{"p":"38148.4","s":0},{"p":"38149.6","s":40},{"p":"38148","s":7019},{"p":"38148.3","s":208},{"p":"38147","s":2774},{"p":"38155.5","s":0},{"p":"38149.7","s":0},{"p":"38148.2","s":2542}],"b":[{"p":"38133.3","s":0},{"p":"38129.4","s":0},{"p":"38132.1","s":0}],"s":"BTC_USDT","t":1701245672024,"u":53095241159}}
{"time":1701245672,"time_ms":1701245672050,"channel":"futures.order_book_update","event":"update","result":{"U":53095241160,"a":[{"p":"38147","s":600},{"p":"38147.9","s":0},{"p":"38152","s":0},{"p":"38149.9","s":109},{"p":"38147.1","s":5194}],"b":[{"p":"38133","s":0}],"s":"BTC_USDT","t":1701245672033,"u":53095241167}}
{"time":1701245672,"time_ms":1701245672071,"channel":"futures.order_book_update","event":"update","result":{"U":53095241168,"a":[{"p":"38145.7","s":159872},{"p":"38148","s":4720}],"b":[{"p":"38129.7","s":0},{"p":"38133.4","s":0}],"s":"BTC_USDT","t":1701245672062,"u":53095241176}}
{"time":1701245672,"time_ms":1701245672091,"channel":"futures.order_book_update","event":"update","result":{"U":53095241177,"a":[{"p":"38148","s":7024},{"p":"38145.7","s":159874}],"b":[{"p":"38138","s":200}],"s":"BTC_USDT","t":1701245672084,"u":53095241180}}
{"time":1701245672,"time_ms":1701245672113,"channel":"futures.order_book_update","event":"update","result":{"U":53095241181,"a":[{"p":"38148.2","s":368},{"p":"38148.6","s":2174},{"p":"38149.9","s":0}],"b":[{"p":"38139","s":2189},{"p":"38133.5","s":0}],"s":"BTC_USDT","t":1701245672091,"u":53095241185}}
{"time":1701245672,"time_ms":1701245672173,"channel":"futures.order_book_update","event":"update","result":{"U":53095241186,"a":[],"b":[{"p":"38133.9","s":0},{"p":"38133.1","s":0},{"p":"38131.2","s":0},{"p":"38132.4","s":0}],"s":"BTC_USDT","t":1701245672155,"u":53095241189}}
{"time":1701245672,"time_ms":1701245672214,"channel":"futures.order_book_update","event":"update","result":{"U":53095241190,"a":[],"b":[{"p":"38133.2","s":0}],"s":"BTC_USDT","t":1701245672189,"u":53095241195}}
{"time":1701245672,"time_ms":1701245672253,"channel":"futures.order_book_update","event":"update","result":{"U":53095241196,"a":[{"p":"38156.8","s":0},{"p":"38162.2","s":0}],"b":[{"p":"38124.5","s":0},{"p":"38131.5","s":0},{"p":"38135.5","s":0},{"p":"38119.9","s":0},{"p":"38129.1","s":0}],"s":"BTC_USDT","t":1701245672243,"u":53095241206}}
{"time":1701245672,"time_ms":1701245672272,"channel":"futures.order_book_update","event":"update","result":{"U":53095241207,"a":[{"p":"38145.7","s":159872}],"b":[{"p":"38133.1","s":0},{"p":"38133.9","s":0},{"p":"38131.2","s":0},{"p":"38132.4","s":0}],"s":"BTC_USDT","t":1701245672256,"u":53095241212}}
{"time":1701245672,"time_ms":1701245672298,"channel":"futures.order_book_update","event":"update","result":{"U":53095241213,"a":[{"p":"38148","s":9198},{"p":"38149.9","s":109},{"p":"38148.6","s":0}],"b":[{"p":"38141.8","s":9419},{"p":"38139","s":2289},{"p":"38138","s":100},{"p":"38141.1","s":2},{"p":"38142.6","s":2},{"p":"38135.9","s":0},{"p":"38136.3","s":0}],"s":"BTC_USDT","t":1701245672286,"u":53095241221}}
{"time":1701245672,"time_ms":1701245672314,"channel":"futures.order_book_update","event":"update","result":{"U":53095241222,"a":[],"b":[{"p":"38139.9","s":2},{"p":"38136.4","s":0}],"s":"BTC_USDT","t":1701245672289,"u":53095241222}}
{"time":1701245672,"time_ms":1701245672411,"channel":"futures.order_book_update","event":"update","result":{"U":53095241223,"a":[{"p":"38146.5","s":2174},{"p":"38147.1","s":3020},{"p":"38149.9","s":0}],"b":[],"s":"BTC_USDT","t":1701245672395,"u":53095241227}}
{"time":1701245672,"time_ms":1701245672453,"channel":"futures.order_book_update","event":"update","result":{"U":53095241228,"a":[],"b":[{"p":"38132.2","s":0}],"s":"BTC_USDT","t":1701245672444,"u":53095241229}}
{"time":1701245672,"time_ms":1701245672473,"channel":"futures.order_book_update","event":"update","result":{"U":53095241230,"a":[],"b":[{"p":"38141.8","s":9417},{"p":"38136.4","s":2621},{"p":"38136.3","s":15},{"p":"38145.6","s":10751},{"p":"38135.9","s":5347},{"p":"38142.6","s":0},{"p":"38141.1","s":0},{"p":"38139.9","s":0}],"s":"BTC_USDT","t":1701245672458,"u":53095241235}}
{"time":1701245672,"time_ms":1701245672496,"channel":"futures.order_book_update","event":"update","result":{"U":53095241236,"a":[{"p":"38146.5","s":0},{"p":"38149.9","s":0},{"p":"38146.9","s":2174}],"b":[{"p":"38136.3","s":0},{"p":"38142.6","s":2},{"p":"38141.8","s":9419},{"p":"38141.1","s":2},{"p":"38139.9","s":2},{"p":"38135.9","s":0},{"p":"38136.4","s":0}],"s":"BTC_USDT","t":1701245672481,"u":53095241241}}
{"time":1701245672,"time_ms":1701245672512,"channel":"futures.order_book_update","event":"update","result":{"U":53095241242,"a":[],"b":[{"p":"38133","s":0},{"p":"38135.5","s":0},{"p":"38123.5","s":0},{"p":"38131.5","s":0}],"s":"BTC_USDT","t":1701245672504,"u":53095241246}}
{"time":1701245672,"time_ms":1701245672534,"channel":"futures.order_book_update","event":"update","result":{"U":53095241247,"a":[],"b":[{"p":"38133.3","s":0}],"s":"BTC_USDT","t":1701245672508,"u":53095241248}}
{"time":1701245672,"time_ms":1701245672672,"channel":"futures.order_book_update","event":"update","result":{"U":53095241249,"a":[{"p":"38146.3","s":2174},{"p":"38146.9","s":0},{"p":"38153.3","s":0},{"p":"38149.9","s":0}],"b":[{"p":"38145.6","s":10251}],"s":"BTC_USDT","t":1701245672650,"u":53095241257}}
{"time":1701245672,"time_ms":1701245672734,"channel":"futures.order_book_update","event":"update","result":{"U":53095241258,"a":[{"p":"38164.1","s":0}],"b":[{"p":"38133.4","s":0}],"s":"BTC_USDT","t":1701245672725,"u":53095241265}}
{"time":1701245672,"time_ms":1701245672773,"channel":"futures.order_book_update","event":"update","result":{"U":53095241266,"a":[{"p":"38153.3","s":0}],"b":[],"s":"BTC_USDT","t":1701245672756,"u":53095241268}}
{"time":1701245672,"time_ms":1701245672813,"channel":"futures.order_book_update","event":"update","result":{"U":53095241269,"a":[],"b":[{"p":"38136.3","s":15},{"p":"38142.6","s":0},{"p":"38141.1","s":0},{"p":"38139.9","s":0},{"p":"38136.4","s":2621},{"p":"38135.9","s":5347},{"p":"38141.8","s":9417}],"s":"BTC_USDT","t":1701245672798,"u":53095241275}}
{"time":1701245672,"time_ms":1701245672853,"channel":"futures.order_book_update","event":"update","result":{"U":53095241276,"a":[],"b":[{"p":"38142.6","s":2},{"p":"38136.3","s":0},{"p":"38136.4","s":0},{"p":"38135.9","s":0},{"p":"38139.9","s":2},{"p":"38141.8","s":9419},{"p":"38141.1","s":2}],"s":"BTC_USDT","t":1701245672829,"u":53095241279}}
{"time":1701245672,"time_ms":1701245672873,"channel":"futures.order_book_update","event":"update","result":{"U":53095241280,"a":[],"b":[{"p":"38141.1","s":0},{"p":"38135.9","s":5347},{"p":"38141.8","s":9417},{"p":"38136.4","s":2621},{"p":"38136.3","s":15},{"p":"38142.6","s":0},{"p":"38139.9","s":0}],"s":"BTC_USDT","t":1701245672859,"u":53095241283}}
{"time":1701245672,"time_ms":1701245672933,"channel":"futures.order_book_update","event":"update","result":{"U":53095241284,"a":[{"p":"38146.9","s":2174},{"p":"38146.3","s":0},{"p":"38149.9","s":0}],"b":[{"p":"38141.8","s":9419},{"p":"38139.9","s":2},{"p":"38142.6","s":2},{"p":"38141.1","s":2},{"p":"38135.9","s":0},{"p":"38136.4","s":0},{"p":"38136.3","s":0}],"s":"BTC_USDT","t":1701245672919,"u":53095241291}}
{"time":1701245673,"time_ms":1701245673012,"channel":"futures.order_book_update","event":"update","result":{"U":53095241292,"a":[{"p":"38152.1","s":0}],"b":[{"p":"38132.8","s":0}],"s":"BTC_USDT","t":1701245673004,"u":53095241294}}
{"time":1701245673,"time_ms":1701245673034,"channel":"futures.order_book_update","event":"update","result":{"U":53095241295,"a":[{"p":"38147.9","s":2300},{"p":"38148","s":6894},{"p":"38149.6","s":0},{"p":"38153.3","s":0},{"p":"38155.7","s":0}],"b":[{"p":"38133","s":0},{"p":"38132","s":0},{"p":"38133.1","s":0},{"p":"38129.5","s":0}],"s":"BTC_USDT","t":1701245673019,"u":53095241308}}
{"time":1701245673,"time_ms":1701245673073,"channel":"futures.order_book_update","event":"update","result":{"U":53095241309,"a":[],"b":[{"p":"38129.7","s":0}],"s":"BTC_USDT","t":1701245673056,"u":53095241311}}
{"time":1701245673,"time_ms":1701245673113,"channel":"futures.order_book_update","event":"update","result":{"U":53095241312,"a":[],"b":[{"p":"38133.1","s":0},{"p":"38129.6","s":0},{"p":"38133.3","s":0}],"s":"BTC_USDT","t":1701245673096,"u":53095241317}}
{"time":1701245673,"time_ms":1701245673172,"channel":"futures.order_book_update","event":"update","result":{"U":53095241318,"a":[],"b":[{"p":"38145.6","s":10751}],"s":"BTC_USDT","t":1701245673161,"u":53095241318}}
{"time":1701245673,"time_ms":1701245673192,"channel":"futures.order_book_update","event":"update","result":{"U":53095241319,"a":[{"p":"38148","s":4720}],"b":[{"p":"38136.4","s":2621},{"p":"38142.6","s":0},{"p":"38141.1","s":0},{"p":"38139.9","s":0},{"p":"38116.5","s":0},{"p":"38136.3","s":15},{"p":"38135.9","s":5347},{"p":"38141.8","s":9417}],"s":"BTC_USDT","t":1701245673183,"u":53095241324}}
{"time":1701245673,"time_ms":1701245673212,"channel":"futures.order_book_update","event":"update","result":{"U":53095241325,"a":[{"p":"38148.1","s":10038}],"b":[{"p":"38142.6","s":2},{"p":"38135.9","s":0}],"s":"BTC_USDT","t":1701245673189,"u":53095241326}}
{"time":1701245673,"time_ms":1701245673233,"channel":"futures.order_book_update","event":"update","result":{"U":53095241327,"a":[{"p":"38149.4","s":560},{"p":"38146.9","s":2174},{"p":"38146.5","s":0},{"p":"38149.6","s":0}],"b":[{"p":"38141.8","s":9419},{"p":"38139.9","s":2},{"p":"38141.1","s":2},{"p":"38136.4","s":0},{"p":"38136.3","s":0},{"p":"38132.2","s":0}],"s":"BTC_USDT","t":1701245673222,"u":53095241335}}
{"time":1701245673,"time_ms":1701245673273,"channel":"futures.order_book_update","event":"update","result":{"U":53095241336,"a":[],"b":[{"p":"38138.9","s":7234}],"s":"BTC_USDT","t":1701245673255,"u":53095241336}}
{"time":1701245673,"time_ms":1701245673293,"channel":"futures.order_book_update","event":"update","result":{"U":53095241337,"a":[],"b":[{"p":"38139","s":4170}],"s":"BTC_USDT","t":1701245673275,"u":53095241337}}
{"time":1701245673,"time_ms":1701245673353,"channel":"futures.order_book_update","event":"update","result":{"U":53095241338,"a":[{"p":"38148.1","s":7864},{"p":"38148.6","s":2174},{"p":"38149.4","s":0}],"b":[],"s":"BTC_USDT","t":1701245673344,"u":53095241339}}
{"time":1701245673,"time_ms":1701245673476,"channel":"futures.order_book_update","event":"update","result":{"U":53095241340,"a":[{"p":"38148.5","s":2372},{"p":"38149.4","s":560},{"p":"38147.9","s":0},{"p":"38146.9","s":0},{"p":"38152","s":0},{"p":"38147.1","s":5194}],"b":[],"s":"BTC_USDT","t":1701245673467,"u":53095241347}}
{"time":1701245673,"time_ms":1701245673551,"channel":"futures.order_book_update","event":"update","result":{"U":53095241348,"a":[],"b":[{"p":"38124.3","s":0}],"s":"BTC_USDT","t":1701245673532,"u":53095241349}}
{"time":1701245673,"time_ms":1701245673592,"channel":"futures.order_book_update","event":"update","result":{"U":53095241350,"a":[],"b":[{"p":"38135.9","s":5347},{"p":"38136.4","s":2621},{"p":"38136.3","s":15},{"p":"38141.8","s":9417},{"p":"38142.6","s":0},{"p":"38139.9","s":0},{"p":"38141.1","s":0}],"s":"BTC_USDT","t":1701245673583,"u":53095241353}}
{"time":1701245673,"time_ms":1701245673613,"channel":"futures.order_book_update","event":"update","result":{"U":53095241354,"a":[{"p":"38145.7","s":159874},{"p":"38153.3","s":0}],"b":[],"s":"BTC_USDT","t":1701245673598,"u":53095241359}}
{"time":1701245673,"time_ms":1701245673632,"channel":"futures.order_book_update","event":"update","result":{"U":53095241360,"a":[],"b":[{"p":"38135.9","s":5373},{"p":"38135.4","s":0}],"s":"BTC_USDT","t":1701245673614,"u":53095241361}}
{"time":1701245673,"time_ms":1701245673693,"channel":"futures.order_book_update","event":"update","result":{"U":53095241362,"a":[{"p":"38149.6","s":0},{"p":"38149.5","s":3340},{"p":"38149.1","s":0},{"p":"38155.5","s":0}],"b":[{"p":"38133","s":0},{"p":"38129.4","s":0}],"s":"BTC_USDT","t":1701245673674,"u":53095241369}}
{"time":1701245673,"time_ms":1701245673713,"channel":"futures.order_book_update","event":"update","result":{"U":53095241370,"a":[{"p":"38147.9","s":2174},{"p":"38149.5","s":0},{"p":"38149.8","s":0},{"p":"38149.6","s":0},{"p":"38147.1","s":3020}],"b":[{"p":"38139","s":4070},{"p":"38138","s":200}],"s":"BTC_USDT","t":1701245673700,"u":53095241376}}
{"time":1701245673,"time_ms":1701245673733,"channel":"futures.order_book_update","event":"update","result":{"U":53095241377,"a":[{"p":"38149.6","s":0},{"p":"38152.3","s":0},{"p":"38145.7","s":159872},{"p":"38147.2","s":1309},{"p":"38147.9","s":2174}],"b":[{"p":"38048.1","s":0},{"p":"38133.4","s":0},{"p":"38070.7","s":0}],"s":"BTC_USDT","t":1701245673724,"u":53095241386}}
{"time":1701245673,"time_ms":1701245673753,"channel":"futures.order_book_update","event":"update","result":{"U":53095241387,"a":[{"p":"38145.7","s":159874},{"p":"38149.6","s":40},{"p":"38149.2","s":2266},{"p":"38148.6","s":0}],"b":[],"s":"BTC_USDT","t":1701245673729,"u":53095241390}}
{"time":1701245673,"time_ms":1701245673771,"channel":"futures.order_book_update","event":"update","result":{"U":53095241391,"a":[{"p":"38145.7","s":156729},{"p":"38149.8","s":0}],"b":[{"p":"38145.6","s":11251}],"s":"BTC_USDT","t":1701245673761,"u":53095241393}}
{"time":1701245673,"time_ms":1701245673791,"channel":"futures.order_book_update","event":"update","result":{"U":53095241394,"a":[{"p":"38155.9","s":0},{"p":"38152.7","s":0},{"p":"38149.8","s":0},{"p":"38149.2","s":2462},{"p":"38149.9","s":2283},{"p":"38148.5","s":0}],"b":[{"p":"38125.5","s":0},{"p":"38132.1","s":0},{"p":"38133.3","s":0},{"p":"38133.5","s":0}],"s":"BTC_USDT","t":1701245673778,"u":53095241411}}
{"time":1701245673,"time_ms":1701245673811,"channel":"futures.order_book_update","event":"update","result":{"U":53095241412,"a":[{"p":"38149.1","s":2174},{"p":"38149.9","s":0},{"p":"38147.9","s":0},{"p":"38150","s":0},{"p":"38148.4","s":2174}],"b":[],"s":"BTC_USDT","t":1701245673795,"u":53095241415}}
{"time":1701245673,"time_ms":1701245673832,"channel":"futures.order_book_update","event":"update","result":{"U":53095241416,"a":[{"p":"38149.8","s":2174},{"p":"38145.7","s":156727},{"p":"38149.1","s":0},{"p":"38149.9","s":0}],"b":[],"s":"BTC_USDT","t":1701245673824,"u":53095241418}}
{"time":1701245673,"time_ms":1701245673851,"channel":"futures.order_book_update","event":"update","result":{"U":53095241419,"a":[{"p":"38145.7","s":156729},{"p":"38153.3","s":0}],"b":[],"s":"BTC_USDT","t":1701245673841,"u":53095241423}}
{"time":1701245673,"time_ms":1701245673912,"channel":"futures.order_book_update","event":"update","result":{"U":53095241424,"a":[{"p":"38156","s":0}],"b":[],"s":"BTC_USDT","t":1701245673886,"u":53095241426}}
{"time":1701245673,"time_ms":1701245673933,"channel":"futures.order_book_update","event":"update","result":{"U":53095241427,"a":[{"p":"38145.7","s":156729}],"b":[{"p":"38136.7","s":600},{"p":"38135.9","s":0},{"p":"38136.6","s":183}],"s":"BTC_USDT","t":1701245673922,"u":53095241430}}
{"time":1701245673,"time_ms":1701245673954,"channel":"futures.order_book_update","event":"update","result":{"U":53095241431,"a":[{"p":"38149.7","s":2375},{"p":"38149.2","s":92},{"p":"38149.8","s":0}],"b":[{"p":"38127","s":0}],"s":"BTC_USDT","t":1701245673940,"u":53095241433}}
{"time":1701245674,"time_ms":1701245674012,"channel":"futures.order_book_update","event":"update","result":{"U":53095241434,"a":[],"b":[{"p":"38132.5","s":0},{"p":"38134.1","s":0},{"p":"38133.3","s":0},{"p":"38131.4","s":0}],"s":"BTC_USDT","t":1701245673988,"u":53095241438}}
{"time":1701245674,"time_ms":1701245674033,"channel":"futures.order_book_update","event":"update","result":{"U":53095241439,"a":[{"p":"38145.7","s":156727},{"p":"38146.1","s":3110},{"p":"38148.4","s":0},{"p":"38148.3","s":2382},{"p":"38149.6","s":2388},{"p":"38149.9","s":109},{"p":"38153.3","s":0},{"p":"38156.8","s":0},{"p":"38150","s":61060},{"p":"38148.6","s":0},{"p":"38149.2","s":92},{"p":"38149.7","s":0},{"p":"38149.8","s":0},{"p":"38151.2","s":0}],"b":[{"p":"38142.6","s":2},{"p":"38136.3","s":0},{"p":"38133","s":0},{"p":"38133.7","s":0},{"p":"38134.1","s":0},{"p":"38127","s":0},{"p":"38134.2","s":0},{"p":"38131","s":0},{"p":"38130.6","s":0},{"p":"38130","s":0},{"p":"38126.5","s":0}],"s":"BTC_USDT","t":1701245674023,"u":53095241481}}
{"time":1701245674,"time_ms":1701245674053,"channel":"futures.order_book_update","event":"update","result":{"U":53095241482,"a":[{"p":"38151.4","s":0},{"p":"38153.9","s":0},{"p":"38146.3","s":2},{"p":"38149.2","s":2266},{"p":"38146.1","s":3108},{"p":"38149.9","s":3449},{"p":"38150","s":0}],"b":[{"p":"38136.3","s":15},{"p":"38142.6","s":0},{"p":"38133.5","s":0}],"s":"BTC_USDT","t":1701245674030,"u":53095241493}}
{"time":1701245674,"time_ms":1701245674071,"channel":"futures.order_book_update","event":"update","result":{"U":53095241494,"a":[{"p":"38147.9","s":2174},{"p":"38148.3","s":208},{"p":"38149.9","s":0}],"b":[],"s":"BTC_USDT","t":1701245674060,"u":53095241495}}
{"time":1701245674,"time_ms":1701245674093,"channel":"futures.order_book_update","event":"update","result":{"U":53095241496,"a":[],"b":[{"p":"38138","s":100},{"p":"38139","s":4170}],"s":"BTC_USDT","t":1701245674080,"u":53095241497}}
{"time":1701245674,"time_ms":1701245674132,"channel":"futures.order_book_update","event":"update","result":{"U":53095241498,"a":[],"b":[{"p":"38133.7","s":0},{"p":"38132.5","s":0},{"p":"38134.4","s":0},{"p":"38135.6","s":0}],"s":"BTC_USDT","t":1701245674108,"u":53095241501}}
{"time":1701245674,"time_ms":1701245674154,"channel":"futures.order_book_update","event":"update","result":{"U":53095241502,"a":[],"b":[{"p":"38145.6","s":10751},{"p":"38133.3","s":0},{"p":"38134.3","s":0},{"p":"38130.6","s":0}],"s":"BTC_USDT","t":1701245674137,"u":53095241512}}
{"time":1701245674,"time_ms":1701245674174,"channel":"futures.order_book_update","event":"update","result":{"U":53095241513,"a":[{"p":"38153.1","s":0},{"p":"38148.6","s":2300},{"p":"38149.6","s":0}],"b":[{"p":"38145.6","s":10826},{"p":"38134.2","s":0},{"p":"38126.6","s":0},{"p":"38134.1","s":0},{"p":"38129.9","s":0}],"s":"BTC_USDT","t":1701245674162,"u":53095241524}}
{"time":1701245674,"time_ms":1701245674192,"channel":"futures.order_book_update","event":"update","result":{"U":53095241525,"a":[{"p":"38161.1","s":0}],"b":[{"p":"38124.6","s":0}],"s":"BTC_USDT","t":1701245674181,"u":53095241531}}
{"time":1701245674,"time_ms":1701245674353,"channel":"futures.order_book_update","event":"update","result":{"U":53095241532,"a":[{"p":"38163","s":0},{"p":"38151","s":0}],"b":[{"p":"38137","s":8913},{"p":"38136.3","s":0},{"p":"38131.5","s":0},{"p":"38135.5","s":0}],"s":"BTC_USDT","t":1701245674339,"u":53095241539}}
{"time":1701245674,"time_ms":1701245674375,"channel":"futures.order_book_update","event":"update","result":{"U":53095241540,"a":[{"p":"38149.1","s":2370},{"p":"38148.6","s":0},{"p":"38152.7","s":0},{"p":"38155","s":0},{"p":"38149.6","s":0}],"b":[{"p":"38140.8","s":7234},{"p":"38135","s":0},{"p":"38133.1","s":0},{"p":"38135.7","s":0},{"p":"38134.2","s":0},{"p":"38123.5","s":0}],"s":"BTC_USDT","t":1701245674364,"u":53095241552}}
{"time":1701245674,"time_ms":1701245674393,"channel":"futures.order_book_update","event":"update","result":{"U":53095241553,"a":[{"p":"38154.9","s":0}],"b":[{"p":"38134","s":0}],"s":"BTC_USDT","t":1701245674379,"u":53095241555}}
{"time":1701245674,"time_ms":1701245674413,"channel":"futures.order_book_update","event":"update","result":{"U":53095241556,"a":[{"p":"38149.6","s":40},{"p":"38146.3","s":0}],"b":[],"s":"BTC_USDT","t":1701245674390,"u":53095241560}}
{"time":1701245674,"time_ms":1701245674432,"channel":"futures.order_book_update","event":"update","result":{"U":53095241561,"a":[{"p":"38153","s":0},{"p":"38149.9","s":0},{"p":"38146.8","s":2},{"p":"38149.2","s":92},{"p":"38149.6","s":0},{"p":"38157","s":0}],"b":[{"p":"38136.3","s":0},{"p":"38133","s":0},{"p":"38137.5","s":8913},{"p":"38137","s":0}],"s":"BTC_USDT","t":1701245674422,"u":53095241572}}
{"time":1701245674,"time_ms":1701245674451,"channel":"futures.order_book_update","event":"update","result":{"U":53095241573,"a":[],"b":[{"p":"38133.7","s":0}],"s":"BTC_USDT","t":1701245674426,"u":53095241575}}
{"time":1701245674,"time_ms":1701245674472,"channel":"futures.order_book_update","event":"update","result":{"U":53095241576,"a":[{"p":"38150.4","s":0}],"b":[],"s":"BTC_USDT","t":1701245674454,"u":53095241577}}
{"time":1701245674,"time_ms":1701245674492,"channel":"futures.order_book_update","event":"update","result":{"U":53095241578,"a":[{"p":"38147.9","s":0},{"p":"38150.8","s":0},{"p":"38153.5","s":0},{"p":"38153.4","s":0},{"p":"38157.5","s":0},{"p":"38149.6","s":0},{"p":"38153","s":0},{"p":"38148.6","s":2174}],"b":[{"p":"38136.3","s":0},{"p":"38135.2","s":0},{"p":"38133.5","s":0},{"p":"38136","s":0},{"p":"38134.4","s":0},{"p":"38137","s":8913},{"p":"38137.5","s":0},{"p":"38133.3","s":0}],"s":"BTC_USDT","t":1701245674484,"u":53095241597}}
{"time":1701245674,"time_ms":1701245674513,"channel":"futures.order_book_update","event":"update","result":{"U":53095241598,"a":[{"p":"38149.6","s":40},{"p":"38149.1","s":0},{"p":"38153.9","s":0},{"p":"38149.7","s":0}],"b":[{"p":"38134.3","s":0}],"s":"BTC_USDT","t":1701245674502,"u":53095241607}}
{"time":1701245674,"time_ms":1701245674532,"channel":"futures.order_book_update","event":"update","result":{"U":53095241608,"a":[{"p":"38149.8","s":0},{"p":"38164.5","s":0},{"p":"38151.2","s":0},{"p":"38151.3","s":0},{"p":"38157","s":0},{"p":"38153","s":0}],"b":[{"p":"38140.8","s":10835},{"p":"38134.7","s":0},{"p":"38133.5","s":0},{"p":"38125.5","s":0},{"p":"38135.4","s":0},{"p":"38136.2","s":0},{"p":"38133","s":0},{"p":"38130","s":0},{"p":"38136.3","s":15},{"p":"38137","s":0}],"s":"BTC_USDT","t":1701245674523,"u":53095241637}}
{"time":1701245674,"time_ms":1701245674551,"channel":"futures.order_book_update","event":"update","result":{"U":53095241638,"a":[{"p":"38149.7","s":4552},{"p":"38148.6","s":0},{"p":"38156.9","s":0},{"p":"38153.9","s":0}],"b":[{"p":"38136.3","s":17},{"p":"38125.7","s":0},{"p":"38133.5","s":0}],"s":"BTC_USDT","t":1701245674538,"u":53095241650}}
{"time":1701245674,"time_ms":1701245674612,"channel":"futures.order_book_update","event":"update","result":{"U":53095241651,"a":[{"p":"38154.9","s":0}],"b":[{"p":"38133.8","s":0}],"s":"BTC_USDT","t":1701245674590,"u":53095241656}}
{"time":1701245674,"time_ms":1701245674632,"channel":"futures.order_book_update","event":"update","result":{"U":53095241657,"a":[],"b":[{"p":"38129","s":0}],"s":"BTC_USDT","t":1701245674615,"u":53095241657}}
{"time":1701245674,"time_ms":1701245674672,"channel":"futures.order_book_update","event":"update","result":{"U":53095241658,"a":[{"p":"38149.9","s":109},{"p":"38146.8","s":0}],"b":[],"s":"BTC_USDT","t":1701245674654,"u":53095241658}}
{"time":1701245674,"time_ms":1701245674692,"channel":"futures.order_book_update","event":"update","result":{"U":53095241659,"a":[{"p":"38147.2","s":1311}],"b":[{"p":"38136.3","s":15},{"p":"38133.7","s":0},{"p":"38134.8","s":0},{"p":"38135.6","s":0}],"s":"BTC_USDT","t":1701245674677,"u":53095241665}}
{"time":1701245674,"time_ms":1701245674714,"channel":"futures.order_book_update","event":"update","result":{"U":53095241666,"a":[],"b":[{"p":"38139","s":4070},{"p":"38136.3","s":0},{"p":"38136","s":0},{"p":"38136.8","s":2},{"p":"38138","s":200}],"s":"BTC_USDT","t":1701245674700,"u":53095241671}}
{"time":1701245674,"time_ms":1701245674732,"channel":"futures.order_book_update","event":"update","result":{"U":53095241672,"a":[],"b":[{"p":"38135.2","s":0},{"p":"38131.8","s":0}],"s":"BTC_USDT","t":1701245674715,"u":53095241677}}
{"time":1701245674,"time_ms":1701245674792,"channel":"futures.order_book_update","event":"update","result":{"U":53095241678,"a":[],"b":[{"p":"38140.8","s":11188}],"s":"BTC_USDT","t":1701245674778,"u":53095241678}}
{"time":1701245674,"time_ms":1701245674831,"channel":"futures.order_book_update","event":"update","result":{"U":53095241679,"a":[],"b":[{"p":"38136.3","s":15},{"p":"38136.8","s":0},{"p":"38135.2","s":0},{"p":"38136","s":0},{"p":"38134","s":0}],"s":"BTC_USDT","t":1701245674810,"u":53095241682}}
{"time":1701245674,"time_ms":1701245674893,"channel":"futures.order_book_update","event":"update","result":{"U":53095241683,"a":[{"p":"38149.7","s":2174}],"b":[{"p":"38136","s":0},{"p":"38135.1","s":0}],"s":"BTC_USDT","t":1701245674884,"u":53095241690}}
{"time":1701245675,"time_ms":1701245675014,"channel":"futures.order_book_update","event":"update","result":{"U":53095241691,"a":[{"p":"38151.7","s":0},{"p":"38150","s":61060},{"p":"38149.9","s":2283},{"p":"38147.2","s":1309},{"p":"38149.7","s":0},{"p":"38152","s":0}],"b":[{"p":"38136.5","s":2},{"p":"38137.3","s":2},{"p":"38136.3","s":0},{"p":"38136.4","s":0},{"p":"38131","s":0},{"p":"38134","s":0}],"s":"BTC_USDT","t":1701245675006,"u":53095241704}}
{"time":1701245675,"time_ms":1701245675034,"channel":"futures.order_book_update","event":"update","result":{"U":53095241705,"a":[{"p":"38154.5","s":0}],"b":[{"p":"38134.4","s":0},{"p":"38134.5","s":0},{"p":"38127.7","s":0}],"s":"BTC_USDT","t":1701245675016,"u":53095241714}}
{"time":1701245675,"time_ms":1701245675053,"channel":"futures.order_book_update","event":"update","result":{"U":53095241715,"a":[{"p":"38148","s":4722}],"b":[],"s":"BTC_USDT","t":1701245675033,"u":53095241715}}
{"time":1701245675,"time_ms":1701245675072,"channel":"futures.order_book_update","event":"update","result":{"U":53095241716,"a":[],"b":[{"p":"38131.8","s":0},{"p":"38118.8","s":0}],"s":"BTC_USDT","t":1701245675060,"u":53095241718}}
{"time":1701245675,"time_ms":1701245675112,"channel":"futures.order_book_update","event":"update","result":{"U":53095241719,"a":[],"b":[{"p":"38134.6","s":0},{"p":"38128.2","s":0},{"p":"38135.2","s":0}],"s":"BTC_USDT","t":1701245675097,"u":53095241725}}
{"time":1701245675,"time_ms":1701245675133,"channel":"futures.order_book_update","event":"update","result":{"U":53095241726,"a":[],"b":[{"p":"38129.6","s":0}],"s":"BTC_USDT","t":1701245675116,"u":53095241726}}
{"time":1701245675,"time_ms":1701245675211,"channel":"futures.order_book_update","event":"update","result":{"U":53095241727,"a":[{"p":"38150","s":0},{"p":"38150.4","s":0},{"p":"38149.2","s":92},{"p":"38164.4","s":0},{"p":"38149.8","s":2174},{"p":"38149.9","s":109}],"b":[{"p":"38134.5","s":0},{"p":"38136","s":0},{"p":"38135.6","s":0},{"p":"38131.4","s":0}],"s":"BTC_USDT","t":1701245675201,"u":53095241744}}
{"time":1701245675,"time_ms":1701245675233,"channel":"futures.order_book_update","event":"update","result":{"U":53095241745,"a":[],"b":[{"p":"38135.7","s":0}],"s":"BTC_USDT","t":1701245675219,"u":53095241746}}
{"time":1701245675,"time_ms":1701245675272,"channel":"futures.order_book_update","event":"update","result":{"U":53095241747,"a":[],"b":[{"p":"38145.6","s":11326}],"s":"BTC_USDT","t":1701245675261,"u":53095241747}}
{"time":1701245675,"time_ms":1701245675311,"channel":"futures.order_book_update","event":"update","result":{"U":53095241748,"a":[{"p":"38151.9","s":0}],"b":[{"p":"38135.6","s":0},{"p":"38136","s":0}],"s":"BTC_USDT","t":1701245675297,"u":53095241755}}
{"time":1701245675,"time_ms":1701245675352,"channel":"futures.order_book_update","event":"update","result":{"U":53095241756,"a":[{"p":"38155.2","s":0}],"b":[{"p":"38135.9","s":0}],"s":"BTC_USDT","t":1701245675339,"u":53095241759}}
{"time":1701245675,"time_ms":1701245675376,"channel":"futures.order_book_update","event":"update","result":{"U":53095241760,"a":[{"p":"38151.3","s":0},{"p":"38150.3","s":0},{"p":"38150","s":0},{"p":"38154.6","s":0},{"p":"38149.2","s":2386},{"p":"38149.7","s":3340},{"p":"38149.8","s":0},{"p":"38149.9","s":0},{"p":"38148.6","s":2174},{"p":"38151.8","s":0}],"b":[{"p":"38131","s":0},{"p":"38135.2","s":0},{"p":"38135.8","s":0},{"p":"38137.3","s":2},{"p":"38136.4","s":0},{"p":"38134.6","s":0},{"p":"38136.5","s":2},{"p":"38135.4","s":0},{"p":"38127.9","s":0},{"p":"38134.2","s":0},{"p":"38136.3","s":0}],"s":"BTC_USDT","t":1701245675366,"u":53095241789}}
{"time":1701245675,"time_ms":1701245675391,"channel":"futures.order_book_update","event":"update","result":{"U":53095241790,"a":[{"p":"38149.7","s":5717},{"p":"38149.2","s":92}],"b":[],"s":"BTC_USDT","t":1701245675383,"u":53095241792}}
{"time":1701245675,"time_ms":1701245675412,"channel":"futures.order_book_update","event":"update","result":{"U":53095241793,"a":[],"b":[{"p":"38145.6","s":11436}],"s":"BTC_USDT","t":1701245675389,"u":53095241794}}
{"time":1701245675,"time_ms":1701245675472,"channel":"futures.order_book_update","event":"update","result":{"U":53095241795,"a":[],"b":[{"p":"38145.6","s":10936}],"s":"BTC_USDT","t":1701245675455,"u":53095241795}}
{"time":1701245675,"time_ms":1701245675552,"channel":"futures.order_book_update","event":"update","result":{"U":53095241796,"a":[{"p":"38149.9","s":0}],"b":[],"s":"BTC_USDT","t":1701245675542,"u":53095241796}}
{"time":1701245675,"time_ms":1701245675572,"channel":"futures.order_book_update","event":"update","result":{"U":53095241797,"a":[{"p":"38150.4","s":0}],"b":[],"s":"BTC_USDT","t":1701245675548,"u":53095241799}}
{"time":1701245675,"time_ms":1701245675713,"channel":"futures.order_book_update","event":"update","result":{"U":53095241800,"a":[{"p":"38145.7","s":172727}],"b":[{"p":"38136.4","s":2621},{"p":"38136.5","s":0},{"p":"38137.3","s":0},{"p":"38134.6","s":0},{"p":"38135.8","s":0},{"p":"38136.3","s":15},{"p":"38145.6","s":10635}],"s":"BTC_USDT","t":1701245675705,"u":53095241805}}
{"time":1701245675,"time_ms":1701245675731,"channel":"futures.order_book_update","event":"update","result":{"U":53095241806,"a":[{"p":"38145.7","s":156727},{"p":"38148","s":4720},{"p":"38177.4","s":0}],"b":[{"p":"38136.3","s":0},{"p":"38136.4","s":0},{"p":"38114.6","s":0},{"p":"38104.2","s":0},{"p":"38137.6","s":2},{"p":"38136.9","s":7236},{"p":"38138.4","s":2}],"s":"BTC_USDT","t":1701245675719,"u":53095241819}}
{"time":1701245675,"time_ms":1701245675751,"channel":"futures.order_book_update","event":"update","result":{"U":53095241820,"a":[{"p":"38149.9","s":3449},{"p":"38149.4","s":562},{"p":"38149.2","s":2266},{"p":"38149.7","s":2377},{"p":"38148.6","s":0},{"p":"38151.2","s":0}],"b":[],"s":"BTC_USDT","t":1701245675736,"u":53095241826}}
{"time":1701245675,"time_ms":1701245675932,"channel":"futures.order_book_update","event":"update","result":{"U":53095241827,"a":[],"b":[{"p":"38130.4","s":0},{"p":"38145.6","s":11135}],"s":"BTC_USDT","t":1701245675918,"u":53095241833}}
{"time":1701245676,"time_ms":1701245676037,"channel":"futures.order_book_update","event":"update","result":{"U":53095241834,"a":[{"p":"38150","s":61060},{"p":"38149.7","s":0},{"p":"38157.7","s":0}],"b":[{"p":"38136.4","s":2621},{"p":"38137.9","s":0},{"p":"38134.5","s":0},{"p":"38133.5","s":0}],"s":"BTC_USDT","t":1701245676022,"u":53095241848}}
{"time":1701245676,"time_ms":1701245676052,"channel":"futures.order_book_update","event":"update","result":{"U":53095241849,"a":[{"p":"38149.8","s":2358},{"p":"38150","s":0}],"b":[{"p":"38138.1","s":9126},{"p":"38127","s":0},{"p":"38130","s":0}],"s":"BTC_USDT","t":1701245676042,"u":53095241854}}
{"time":1701245676,"time_ms":1701245676095,"channel":"futures.order_book_update","event":"update","result":{"U":53095241855,"a":[],"b":[{"p":"38134.8","s":0},{"p":"38131.9","s":0},{"p":"38133.7","s":0}],"s":"BTC_USDT","t":1701245676086,"u":53095241861}}
{"time":1701245676,"time_ms":1701245676112,"channel":"futures.order_book_update","event":"update","result":{"U":53095241862,"a":[],"b":[{"p":"38134.8","s":0}],"s":"BTC_USDT","t":1701245676087,"u":53095241862}}
{"time":1701245676,"time_ms":1701245676133,"channel":"futures.order_book_update","event":"update","result":{"U":53095241863,"a":[{"p":"38149.9","s":0},{"p":"38149.2","s":92},{"p":"38148.6","s":2174}],"b":[],"s":"BTC_USDT","t":1701245676123,"u":53095241864}}
{"time":1701245676,"time_ms":1701245676152,"channel":"futures.order_book_update","event":"update","result":{"U":53095241865,"a":[],"b":[{"p":"38135.4","s":0}],"s":"BTC_USDT","t":1701245676140,"u":53095241866}}
{"time":1701245676,"time_ms":1701245676175,"channel":"futures.order_book_update","event":"update","result":{"U":53095241867,"a":[],"b":[{"p":"38121.9","s":0}],"s":"BTC_USDT","t":1701245676162,"u":53095241868}}
{"time":1701245676,"time_ms":1701245676194,"channel":"futures.order_book_update","event":"update","result":{"U":53095241869,"a":[{"p":"38164.8","s":0},{"p":"38148.6","s":2174},{"p":"38149.1","s":0},{"p":"38149.9","s":0}],"b":[{"p":"38124","s":0},{"p":"38130.7","s":0},{"p":"38135.5","s":0},{"p":"38125.6","s":0},{"p":"38131.5","s":0}],"s":"BTC_USDT","t":1701245676186,"u":53095241881}}
{"time":1701245676,"time_ms":1701245676213,"channel":"futures.order_book_update","event":"update","result":{"U":53095241882,"a":[{"p":"38149.9","s":3449},{"p":"38148.6","s":0},{"p":"38149.2","s":92}],"b":[],"s":"BTC_USDT","t":1701245676199,"u":53095241884}}
{"time":1701245676,"time_ms":1701245676252,"channel":"futures.order_book_update","event":"update","result":{"U":53095241885,"a":[{"p":"38148.6","s":2174},{"p":"38149.9","s":0},{"p":"38150.8","s":0}],"b":[{"p":"38135.6","s":0},{"p":"38134.8","s":0}],"s":"BTC_USDT","t":1701245676235,"u":53095241891}}
{"time":1701245676,"time_ms":1701245676273,"channel":"futures.order_book_update","event":"update","result":{"U":53095241892,"a":[],"b":[{"p":"38135.2","s":0}],"s":"BTC_USDT","t":1701245676246,"u":53095241893}}
{"time":1701245676,"time_ms":1701245676292,"channel":"futures.order_book_update","event":"update","result":{"U":53095241894,"a":[{"p":"38149.9","s":0}],"b":[],"s":"BTC_USDT","t":1701245676284,"u":53095241898}}
{"time":1701245676,"time_ms":1701245676312,"channel":"futures.order_book_update","event":"update","result":{"U":53095241899,"a":[{"p":"38149.9","s":0},{"p":"38150.4","s":0}],"b":[{"p":"38134.9","s":0},{"p":"38093.7","s":0}],"s":"BTC_USDT","t":1701245676299,"u":53095241907}}
{"time":1701245676,"time_ms":1701245676331,"channel":"futures.order_book_update","event":"update","result":{"U":53095241908,"a":[{"p":"38149.2","s":2266},{"p":"38149.9","s":109},{"p":"38148.6","s":0},{"p":"38150.8","s":0}],"b":[{"p":"38141.7","s":15026},{"p":"38142.4","s":655},{"p":"38136.4","s":0}],"s":"BTC_USDT","t":1701245676317,"u":53095241916}}
{"time":1701245676,"time_ms":1701245676391,"channel":"futures.order_book_update","event":"update","result":{"U":53095241917,"a":[{"p":"38150.8","s":0},{"p":"38151.2","s":0},{"p":"38149.9","s":5623}],"b":[{"p":"38135.5","s":0}],"s":"BTC_USDT","t":1701245676379,"u":53095241923}}
{"time":1701245676,"time_ms":1701245676437,"channel":"futures.order_book_update","event":"update","result":{"U":53095241924,"a":[{"p":"38149.4","s":560},{"p":"38149.9","s":109},{"p":"38150.4","s":0}],"b":[{"p":"38139.9","s":2},{"p":"38137.6","s":0},{"p":"38135.7","s":0},{"p":"38142.6","s":2},{"p":"38141.8","s":9419},{"p":"38138.4","s":0},{"p":"38136.6","s":0},{"p":"38136.7","s":600},{"p":"38141.1","s":2},{"p":"38136.9","s":7234}],"s":"BTC_USDT","t":1701245676421,"u":53095241937}}
{"time":1701245676,"time_ms":1701245676512,"channel":"futures.order_book_update","event":"update","result":{"U":53095241938,"a":[],"b":[{"p":"38138","s":100}],"s":"BTC_USDT","t":1701245676497,"u":53095241940}}
{"time":1701245676,"time_ms":1701245676533,"channel":"futures.order_book_update","event":"update","result":{"U":53095241941,"a":[],"b":[{"p":"38139","s":4170}],"s":"BTC_USDT","t":1701245676517,"u":53095241942}}
{"time":1701245676,"time_ms":1701245676551,"channel":"futures.order_book_update","event":"update","result":{"U":53095241943,"a":[{"p":"38157.1","s":0}],"b":[{"p":"38134.5","s":0}],"s":"BTC_USDT","t":1701245676541,"u":53095241946}}
{"time":1701245676,"time_ms":1701245676612,"channel":"futures.order_book_update","event":"update","result":{"U":53095241947,"a":[{"p":"38149.7","s":2174},{"p":"38149.2","s":92},{"p":"38149.8","s":0},{"p":"38150","s":0},{"p":"38151.1","s":0},{"p":"38153.9","s":0}],"b":[{"p":"38134.2","s":0},{"p":"38141.8","s":9417},{"p":"38141.1","s":0},{"p":"38136.3","s":15},{"p":"38142.6","s":0},{"p":"38139.9","s":0},{"p":"38135.2","s":0},{"p":"38130.5","s":0},{"p":"38136.6","s":183},{"p":"38136.4","s":2621}],"s":"BTC_USDT","t":1701245676598,"u":53095241970}}
{"time":1701245676,"time_ms":1701245676634,"channel":"futures.order_book_update","event":"update","result":{"U":53095241971,"a":[{"p":"38148.3","s":210},{"p":"38153.3","s":0}],"b":[{"p":"38137.6","s":2},{"p":"38136.8","s":2},{"p":"38136.4","s":0},{"p":"38136.3","s":0},{"p":"38136.1","s":0},{"p":"38135.1","s":0},{"p":"38131.2","s":0},{"p":"38132.1","s":0},{"p":"38136","s":0}],"s":"BTC_USDT","t":1701245676626,"u":53095241982}}
{"time":1701245676,"time_ms":1701245676714,"channel":"futures.order_book_update","event":"update","result":{"U":53095241983,"a":[],"b":[{"p":"38139","s":4070}],"s":"BTC_USDT","t":1701245676699,"u":53095241984}}
{"time":1701245676,"time_ms":1701245676733,"channel":"futures.order_book_update","event":"update","result":{"U":53095241985,"a":[],"b":[{"p":"38138","s":200}],"s":"BTC_USDT","t":1701245676720,"u":53095241987}}
{"time":1701245676,"time_ms":1701245676791,"channel":"futures.order_book_update","event":"update","result":{"U":53095241988,"a":[{"p":"38148.3","s":208}],"b":[],"s":"BTC_USDT","t":1701245676765,"u":53095241988}}
{"time":1701245676,"time_ms":1701245676812,"channel":"futures.order_book_update","event":"update","result":{"U":53095241989,"a":[{"p":"38148.3","s":210}],"b":[{"p":"38131","s":0},{"p":"38134.5","s":0},{"p":"38136.5","s":0},{"p":"38135.4","s":0}],"s":"BTC_USDT","t":1701245676795,"u":53095241995}}
{"time":1701245676,"time_ms":1701245676872,"channel":"futures.order_book_update","event":"update","result":{"U":53095241996,"a":[],"b":[{"p":"38123.6","s":0}],"s":"BTC_USDT","t":1701245676860,"u":53095241997}}
{"time":1701245676,"time_ms":1701245676931,"channel":"futures.order_book_update","event":"update","result":{"U":53095241998,"a":[],"b":[{"p":"38132","s":0}],"s":"BTC_USDT","t":1701245676917,"u":53095241998}}
{"time":1701245676,"time_ms":1701245676953,"channel":"futures.order_book_update","event":"update","result":{"U":53095241999,"a":[],"b":[{"p":"38135.7","s":0},{"p":"38136.5","s":0},{"p":"38132.2","s":0}],"s":"BTC_USDT","t":1701245676937,"u":53095242004}}
{"time":1701245676,"time_ms":1701245676973,"channel":"futures.order_book_update","event":"update","result":{"U":53095242005,"a":[],"b":[{"p":"38145.6","s":12635}],"s":"BTC_USDT","t":1701245676956,"u":53095242006}}
{"time":1701245676,"time_ms":1701245676992,"channel":"futures.order_book_update","event":"update","result":{"U":53095242007,"a":[{"p":"38148.3","s":208}],"b":[],"s":"BTC_USDT","t":1701245676965,"u":53095242007}}
{"time":1701245677,"time_ms":1701245677033,"channel":"futures.order_book_update","event":"update","result":{"U":53095242008,"a":[{"p":"38149.9","s":109},{"p":"38148.3","s":210},{"p":"38150","s":63360},{"p":"38149.6","s":2214},{"p":"38149.7","s":0},{"p":"38150.4","s":0},{"p":"38151.7","s":0},{"p":"38157.5","s":0},{"p":"38145.7","s":156368}],"b":[{"p":"38136.7","s":600},{"p":"38138","s":0},{"p":"38136.6","s":0},{"p":"38127.2","s":0},{"p":"38135.2","s":0},{"p":"38135.6","s":0},{"p":"38145.6","s":32135},{"p":"38144","s":200},{"p":"38145.3","s":23000}],"s":"BTC_USDT","t":1701245677024,"u":53095242033}}
{"time":1701245677,"time_ms":1701245677051,"channel":"futures.order_book_update","event":"update","result":{"U":53095242034,"a":[],"b":[{"p":"38131.5","s":0},{"p":"38135.5","s":0},{"p":"38145.3","s":0},{"p":"38136.1","s":0},{"p":"38136","s":0},{"p":"38124","s":0},{"p":"38134.8","s":0},{"p":"38139.5","s":8913},{"p":"38136.7","s":600}],"s":"BTC_USDT","t":1701245677040,"u":53095242045}}
{"time":1701245677,"time_ms":1701245677071,"channel":"futures.order_book_update","event":"update","result":{"U":53095242046,"a":[],"b":[{"p":"38131","s":0},{"p":"38135.9","s":0},{"p":"38145.6","s":12635}],"s":"BTC_USDT","t":1701245677053,"u":53095242052}}
{"time":1701245677,"time_ms":1701245677093,"channel":"futures.order_book_update","event":"update","result":{"U":53095242053,"a":[{"p":"38149.6","s":40},{"p":"38149.9","s":2283}],"b":[{"p":"38139.5","s":0},{"p":"38135.7","s":0},{"p":"38135.5","s":0},{"p":"38130.6","s":0},{"p":"38128","s":0},{"p":"38136.6","s":183},{"p":"38138","s":100},{"p":"38139","s":4170},{"p":"38144","s":0}],"s":"BTC_USDT","t":1701245677081,"u":53095242071}}
{"time":1701245677,"time_ms":1701245677132,"channel":"futures.order_book_update","event":"update","result":{"U":53095242072,"a":[{"p":"38148.3","s":208}],"b":[],"s":"BTC_USDT","t":1701245677104,"u":53095242072}}
{"time":1701245677,"time_ms":1701245677151,"channel":"futures.order_book_update","event":"update","result":{"U":53095242073,"a":[{"p":"38148.4","s":2},{"p":"38150","s":0}],"b":[],"s":"BTC_USDT","t":1701245677123,"u":53095242073}}
{"time":1701245677,"time_ms":1701245677214,"channel":"futures.order_book_update","event":"update","result":{"U":53095242074,"a":[],"b":[{"p":"38138","s":200},{"p":"38139","s":4070}],"s":"BTC_USDT","t":1701245677189,"u":53095242075}}
{"time":1701245677,"time_ms":1701245677312,"channel":"futures.order_book_update","event":"update","result":{"U":53095242076,"a":[],"b":[{"p":"38145.3","s":4500},{"p":"38136.6","s":0}],"s":"BTC_USDT","t":1701245677301,"u":53095242076}}
{"time":1701245677,"time_ms":1701245677332,"channel":"futures.order_book_update","event":"update","result":{"U":53095242077,"a":[],"b":[{"p":"38136.6","s":183},{"p":"38145.3","s":0},{"p":"38131.1","s":0}],"s":"BTC_USDT","t":1701245677320,"u":53095242080}}
{"time":1701245677,"time_ms":1701245677352,"channel":"futures.order_book_update","event":"update","result":{"U":53095242081,"a":[{"p":"38160","s":0}],"b":[{"p":"38126.6","s":0},{"p":"38131.5","s":0}],"s":"BTC_USDT","t":1701245677342,"u":53095242086}}
{"time":1701245677,"time_ms":1701245677372,"channel":"futures.order_book_update","event":"update","result":{"U":53095242087,"a":[{"p":"38150","s":63360},{"p":"38148.4","s":0},{"p":"38149.8","s":0},{"p":"38149.9","s":2283},{"p":"38154.4","s":0},{"p":"38177.2","s":0},{"p":"38151.5","s":0},{"p":"38149.2","s":92}],"b":[{"p":"38136.4","s":2621},{"p":"38137.6","s":0},{"p":"38136.1","s":0},{"p":"38135.4","s":0},{"p":"38142.6","s":0},{"p":"38073.9","s":0},{"p":"38141.8","s":9417},{"p":"38136","s":0},{"p":"38136.3","s":15},{"p":"38134.9","s":0},{"p":"38051.1","s":0},{"p":"38136.8","s":0},{"p":"38135.7","s":0},{"p":"38141.1","s":0},{"p":"38136.6","s":183},{"p":"38139.9","s":0}],"s":"BTC_USDT","t":1701245677364,"u":53095242121}}
{"time":1701245677,"time_ms":1701245677392,"channel":"futures.order_book_update","event":"update","result":{"U":53095242122,"a":[{"p":"38151.3","s":0}],"b":[{"p":"38141.1","s":2},{"p":"38136.3","s":0},{"p":"38136.2","s":0}],"s":"BTC_USDT","t":1701245677382,"u":53095242124}}
{"time":1701245677,"time_ms":1701245677413,"channel":"futures.order_book_update","event":"update","result":{"U":53095242125,"a":[{"p":"38151.5","s":0},{"p":"38149.2","s":2266},{"p":"38149.9","s":5623},{"p":"38154.5","s":0}],"b":[{"p":"38136.6","s":0},{"p":"38136.1","s":0},{"p":"38135.2","s":0},{"p":"38127.7","s":0},{"p":"38142.6","s":2},{"p":"38141.8","s":9419},{"p":"38139.9","s":2},{"p":"38136.4","s":0}],"s":"BTC_USDT","t":1701245677404,"u":53095242143}}
{"time":1701245677,"time_ms":1701245677431,"channel":"futures.order_book_update","event":"update","result":{"U":53095242144,"a":[],"b":[{"p":"38134.5","s":0},{"p":"38132.7","s":0}],"s":"BTC_USDT","t":1701245677418,"u":53095242147}}
{"time":1701245677,"time_ms":1701245677452,"channel":"futures.order_book_update","event":"update","result":{"U":53095242148,"a":[],"b":[{"p":"38141.8","s":9417},{"p":"38136.6","s":183},{"p":"38136.4","s":2621},{"p":"38142.6","s":0},{"p":"38139.9","s":0}],"s":"BTC_USDT","t":1701245677441,"u":53095242150}}
{"time":1701245677,"time_ms":1701245677474,"channel":"futures.order_book_update","event":"update","result":{"U":53095242151,"a":[{"p":"38153.3","s":0},{"p":"38148.6","s":2},{"p":"38150","s":0}],"b":[{"p":"38135.6","s":0},{"p":"38136.3","s":0},{"p":"38142.6","s":2},{"p":"38141.8","s":9419},{"p":"38141.1","s":0}],"s":"BTC_USDT","t":1701245677464,"u":53095242161}}
{"time":1701245677,"time_ms":1701245677493,"channel":"futures.order_book_update","event":"update","result":{"U":53095242162,"a":[],"b":[{"p":"38139","s":4170},{"p":"38138","s":100}],"s":"BTC_USDT","t":1701245677481,"u":53095242163}}
{"time":1701245677,"time_ms":1701245677533,"channel":"futures.order_book_update","event":"update","result":{"U":53095242164,"a":[],"b":[{"p":"38137.9","s":2},{"p":"38141.8","s":9417},{"p":"38136.4","s":0},{"p":"38142.6","s":0},{"p":"38136.3","s":0},{"p":"38137.1","s":2}],"s":"BTC_USDT","t":1701245677507,"u":53095242167}}
{"time":1701245677,"time_ms":1701245677611,"channel":"futures.order_book_update","event":"update","result":{"U":53095242168,"a":[{"p":"38150","s":63360},{"p":"38148.6","s":0}],"b":[{"p":"38139","s":4070},{"p":"38138","s":200}],"s":"BTC_USDT","t":1701245677602,"u":53095242171}}
{"time":1701245677,"time_ms":1701245677632,"channel":"futures.order_book_update","event":"update","result":{"U":53095242172,"a":[{"p":"38149.9","s":3449}],"b":[],"s":"BTC_USDT","t":1701245677621,"u":53095242172}}
{"time":1701245677,"time_ms":1701245677654,"channel":"futures.order_book_update","event":"update","result":{"U":53095242173,"a":[{"p":"38149.9","s":109},{"p":"38153.3","s":0}],"b":[{"p":"38137.1","s":0},{"p":"38130","s":0},{"p":"38136.4","s":0},{"p":"38136.3","s":0},{"p":"38135.2","s":0},{"p":"38141.1","s":2},{"p":"38137.9","s":0},{"p":"38141.8","s":9419},{"p":"38136.6","s":0},{"p":"38139.9","s":2},{"p":"38142.6","s":2}],"s":"BTC_USDT","t":1701245677633,"u":53095242185}}
{"time":1701245677,"time_ms":1701245677690,"channel":"futures.order_book_update","event":"update","result":{"U":53095242186,"a":[{"p":"38150.8","s":0},{"p":"38154","s":0}],"b":[{"p":"38135.2","s":0}],"s":"BTC_USDT","t":1701245677682,"u":53095242195}}
{"time":1701245677,"time_ms":1701245677712,"channel":"futures.order_book_update","event":"update","result":{"U":53095242196,"a":[],"b":[{"p":"38138","s":100},{"p":"38139","s":4170}],"s":"BTC_USDT","t":1701245677703,"u":53095242200}}
{"time":1701245677,"time_ms":1701245677753,"channel":"futures.order_book_update","event":"update","result":{"U":53095242201,"a":[{"p":"38149.2","s":92},{"p":"38149.9","s":2283},{"p":"38153.3","s":0}],"b":[],"s":"BTC_USDT","t":1701245677739,"u":53095242206}}
{"time":1701245677,"time_ms":1701245677773,"channel":"futures.order_book_update","event":"update","result":{"U":53095242207,"a":[{"p":"38150","s":61060}],"b":[{"p":"38134.2","s":0}],"s":"BTC_USDT","t":1701245677760,"u":53095242211}}
{"time":1701245677,"time_ms":1701245677874,"channel":"futures.order_book_update","event":"update","result":{"U":53095242212,"a":[],"b":[{"p":"38108.9","s":0}],"s":"BTC_USDT","t":1701245677851,"u":53095242213}}
{"time":1701245677,"time_ms":1701245677899,"channel":"futures.order_book_update","event":"update","result":{"U":53095242214,"a":[{"p":"38162.5","s":0}],"b":[],"s":"BTC_USDT","t":1701245677888,"u":53095242216}}
{"time":1701245677,"time_ms":1701245677912,"channel":"futures.order_book_update","event":"update","result":{"U":53095242217,"a":[],"b":[{"p":"38135.1","s":0}],"s":"BTC_USDT","t":1701245677892,"u":53095242225}}
{"time":1701245678,"time_ms":1701245678013,"channel":"futures.order_book_update","event":"update","result":{"U":53095242226,"a":[{"p":"38150.4","s":0}],"b":[{"p":"38134.8","s":0}],"s":"BTC_USDT","t":1701245678004,"u":53095242230}}
{"time":1701245678,"time_ms":1701245678032,"channel":"futures.order_book_update","event":"update","result":{"U":53095242231,"a":[{"p":"38150","s":63353},{"p":"38151.2","s":0},{"p":"38151.4","s":0}],"b":[{"p":"38127.2","s":0},{"p":"38135.2","s":0}],"s":"BTC_USDT","t":1701245678014,"u":53095242239}}
{"time":1701245678,"time_ms":1701245678052,"channel":"futures.order_book_update","event":"update","result":{"U":53095242240,"a":[],"b":[{"p":"38134.5","s":0},{"p":"38136.6","s":183},{"p":"38141.8","s":9417},{"p":"38136.4","s":2621},{"p":"38136.3","s":15},{"p":"38142.6","s":0},{"p":"38141.1","s":0},{"p":"38139.9","s":0}],"s":"BTC_USDT","t":1701245678040,"u":53095242245}}
{"time":1701245678,"time_ms":1701245678093,"channel":"futures.order_book_update","event":"update","result":{"U":53095242246,"a":[],"b":[{"p":"38134.9","s":0},{"p":"38141.8","s":9419},{"p":"38141.1","s":2},{"p":"38139.9","s":2},{"p":"38138","s":200},{"p":"38136.4","s":0},{"p":"38136.3","s":0},{"p":"38136.6","s":0},{"p":"38142.6","s":2},{"p":"38139","s":4070}],"s":"BTC_USDT","t":1701245678083,"u":53095242254}}
{"time":1701245678,"time_ms":1701245678112,"channel":"futures.order_book_update","event":"update","result":{"U":53095242255,"a":[{"p":"38145.7","s":157154}],"b":[{"p":"38136","s":0}],"s":"BTC_USDT","t":1701245678089,"u":53095242257}}
{"time":1701245678,"time_ms":1701245678212,"channel":"futures.order_book_update","event":"update","result":{"U":53095242258,"a":[],"b":[{"p":"38139","s":4170},{"p":"38138","s":100},{"p":"38136.1","s":0}],"s":"BTC_USDT","t":1701245678193,"u":53095242261}}
{"time":1701245678,"time_ms":1701245678332,"channel":"futures.order_book_update","event":"update","result":{"U":53095242262,"a":[],"b":[{"p":"38136.2","s":0}],"s":"BTC_USDT","t":1701245678298,"u":53095242265}}
{"time":1701245678,"time_ms":1701245678352,"channel":"futures.order_book_update","event":"update","result":{"U":53095242266,"a":[{"p":"38150","s":61060}],"b":[{"p":"38143.1","s":403},{"p":"38143","s":655},{"p":"38142.4","s":0},{"p":"38136.7","s":0},{"p":"38136.6","s":0}],"s":"BTC_USDT","t":1701245678333,"u":53095242271}}
{"time":1701245678,"time_ms":1701245678612,"channel":"futures.order_book_update","event":"update","result":{"U":53095242272,"a":[],"b":[{"p":"38123.7","s":0}],"s":"BTC_USDT","t":1701245678592,"u":53095242275}}
{"time":1701245678,"time_ms":1701245678672,"channel":"futures.order_book_update","event":"update","result":{"U":53095242276,"a":[{"p":"38149.2","s":2266},{"p":"38149.9","s":109}],"b":[],"s":"BTC_USDT","t":1701245678649,"u":53095242277}}
{"time":1701245678,"time_ms":1701245678693,"channel":"futures.order_book_update","event":"update","result":{"U":53095242278,"a":[],"b":[{"p":"38143.1","s":0},{"p":"38136.9","s":7234},{"p":"38145.3","s":2314}],"s":"BTC_USDT","t":1701245678673,"u":53095242279}}
{"time":1701245678,"time_ms":1701245678712,"channel":"futures.order_book_update","event":"update","result":{"U":53095242280,"a":[],"b":[{"p":"38136.1","s":0}],"s":"BTC_USDT","t":1701245678694,"u":53095242281}}
{"time":1701245678,"time_ms":1701245678774,"channel":"futures.order_book_update","event":"update","result":{"U":53095242282,"a":[],"b":[{"p":"38136.7","s":8464},{"p":"38145.3","s":0}],"s":"BTC_USDT","t":1701245678764,"u":53095242284}}
{"time":1701245678,"time_ms":1701245678793,"channel":"futures.order_book_update","event":"update","result":{"U":53095242285,"a":[],"b":[{"p":"38136.7","s":0},{"p":"38143.1","s":395}],"s":"BTC_USDT","t":1701245678775,"u":53095242285}}
{"time":1701245678,"time_ms":1701245678995,"channel":"futures.order_book_update","event":"update","result":{"U":53095242286,"a":[{"p":"38149.8","s":3340},{"p":"38149.9","s":2425},{"p":"38150","s":0},{"p":"38151.3","s":0},{"p":"38150.4","s":0}],"b":[{"p":"38130.6","s":0},{"p":"38134.8","s":0},{"p":"38135.4","s":0},{"p":"38136","s":0},{"p":"38127.8","s":0}],"s":"BTC_USDT","t":1701245678985,"u":53095242304}}
{"time":1701245679,"time_ms":1701245679014,"channel":"futures.order_book_update","event":"update","result":{"U":53095242305,"a":[{"p":"38149.9","s":4599},{"p":"38157.7","s":0},{"p":"38154.5","s":0},{"p":"38151.5","s":0}],"b":[{"p":"38134.5","s":0},{"p":"38135.2","s":0},{"p":"38130.5","s":0},{"p":"38135.7","s":0},{"p":"38127.5","s":0}],"s":"BTC_USDT","t":1701245679005,"u":53095242322}}
{"time":1701245679,"time_ms":1701245679092,"channel":"futures.order_book_update","event":"update","result":{"U":53095242323,"a":[],"b":[{"p":"38145.3","s":2006},{"p":"38143.1","s":0},{"p":"38136.7","s":0}],"s":"BTC_USDT","t":1701245679083,"u":53095242326}}
{"time":1701245679,"time_ms":1701245679111,"channel":"futures.order_book_update","event":"update","result":{"U":53095242327,"a":[],"b":[{"p":"38135.2","s":0},{"p":"38135.4","s":0}],"s":"BTC_USDT","t":1701245679099,"u":53095242330}}
{"time":1701245679,"time_ms":1701245679130,"channel":"futures.order_book_update","event":"update","result":{"U":53095242331,"a":[],"b":[{"p":"38143.1","s":397},{"p":"38145.3","s":0},{"p":"38126","s":0},{"p":"38136.7","s":0}],"s":"BTC_USDT","t":1701245679117,"u":53095242333}}
{"time":1701245679,"time_ms":1701245679153,"channel":"futures.order_book_update","event":"update","result":{"U":53095242334,"a":[{"p":"38150","s":0},{"p":"38157.2","s":0},{"p":"38149.7","s":2174},{"p":"38149.8","s":0},{"p":"38153.9","s":0},{"p":"38154.2","s":0},{"p":"38149.2","s":92},{"p":"38149.9","s":2425},{"p":"38151.2","s":0}],"b":[{"p":"38135.6","s":0},{"p":"38134.9","s":0},{"p":"38135.7","s":0},{"p":"38134.2","s":0},{"p":"38135.4","s":0},{"p":"38130.1","s":0},{"p":"38134.7","s":0}],"s":"BTC_USDT","t":1701245679143,"u":53095242364}}
{"time":1701245679,"time_ms":1701245679172,"channel":"futures.order_book_update","event":"update","result":{"U":53095242365,"a":[{"p":"38149.2","s":2266},{"p":"38150","s":61060},{"p":"38149.7","s":0}],"b":[],"s":"BTC_USDT","t":1701245679162,"u":53095242366}}
{"time":1701245679,"time_ms":1701245679673,"channel":"futures.order_book_update","event":"update","result":{"U":53095242367,"a":[{"p":"38145.7","s":157299},{"p":"38151.2","s":0}],"b":[],"s":"BTC_USDT","t":1701245679659,"u":53095242373}}
{"time":1701245679,"time_ms":1701245679692,"channel":"futures.order_book_update","event":"update","result":{"U":53095242374,"a":[{"p":"38150.8","s":0},{"p":"38149.8","s":3340},{"p":"38150","s":0},{"p":"38151.4","s":0}],"b":[{"p":"38136","s":0},{"p":"38135.9","s":0},{"p":"38134.8","s":0}],"s":"BTC_USDT","t":1701245679685,"u":53095242383}}
{"time":1701245679,"time_ms":1701245679712,"channel":"futures.order_book_update","event":"update","result":{"U":53095242384,"a":[],"b":[{"p":"38135.7","s":0},{"p":"38130.6","s":0}],"s":"BTC_USDT","t":1701245679704,"u":53095242388}}
{"time":1701245679,"time_ms":1701245679733,"channel":"futures.order_book_update","event":"update","result":{"U":53095242389,"a":[{"p":"38149.9","s":0},{"p":"38148.6","s":2174},{"p":"38149.2","s":92}],"b":[{"p":"38135.3","s":0},{"p":"38134.5","s":0}],"s":"BTC_USDT","t":1701245679707,"u":53095242395}}
{"time":1701245679,"time_ms":1701245679752,"channel":"futures.order_book_update","event":"update","result":{"U":53095242396,"a":[],"b":[{"p":"38136.7","s":8464},{"p":"38142.6","s":0},{"p":"38141.1","s":0},{"p":"38139.9","s":0},{"p":"38136.1","s":0},{"p":"38141.8","s":9417},{"p":"38136.6","s":183},{"p":"38136.4","s":2647}],"s":"BTC_USDT","t":1701245679736,"u":53095242401}}
{"time":1701245679,"time_ms":1701245679792,"channel":"futures.order_book_update","event":"update","result":{"U":53095242402,"a":[],"b":[{"p":"38124.1","s":0}],"s":"BTC_USDT","t":1701245679768,"u":53095242402}}
{"time":1701245679,"time_ms":1701245679812,"channel":"futures.order_book_update","event":"update","result":{"U":53095242403,"a":[],"b":[{"p":"38141.1","s":2},{"p":"38139.9","s":2},{"p":"38136.4","s":0},{"p":"38136.6","s":0},{"p":"38136.7","s":0},{"p":"38141.8","s":9419},{"p":"38142.6","s":2}],"s":"BTC_USDT","t":1701245679789,"u":53095242406}}
{"time":1701245679,"time_ms":1701245679840,"channel":"futures.order_book_update","event":"update","result":{"U":53095242407,"a":[{"p":"38150.4","s":0},{"p":"38149.9","s":0},{"p":"38149.2","s":2266}],"b":[{"p":"38127.2","s":0},{"p":"38134.2","s":0},{"p":"38130","s":0},{"p":"38134.9","s":0},{"p":"38130.1","s":0},{"p":"38135.2","s":0}],"s":"BTC_USDT","t":1701245679826,"u":53095242420}}
{"time":1701245679,"time_ms":1701245679852,"channel":"futures.order_book_update","event":"update","result":{"U":53095242421,"a":[{"p":"38149.2","s":4581},{"p":"38154.5","s":0}],"b":[{"p":"38135.2","s":0}],"s":"BTC_USDT","t":1701245679829,"u":53095242425}}
{"time":1701245679,"time_ms":1701245679892,"channel":"futures.order_book_update","event":"update","result":{"U":53095242426,"a":[{"p":"38153.3","s":0}],"b":[{"p":"38145.6","s":10635}],"s":"BTC_USDT","t":1701245679879,"u":53095242429}}
{"time":1701245679,"time_ms":1701245679973,"channel":"futures.order_book_update","event":"update","result":{"U":53095242430,"a":[{"p":"38148.6","s":5514},{"p":"38149.9","s":109},{"p":"38149.8","s":0}],"b":[{"p":"38134.7","s":0}],"s":"BTC_USDT","t":1701245679963,"u":53095242438}}
{"time":1701245679,"time_ms":1701245679993,"channel":"futures.order_book_update","event":"update","result":{"U":53095242439,"a":[{"p":"38148.6","s":2174},{"p":"38149.9","s":0},{"p":"38149.1","s":3340}],"b":[],"s":"BTC_USDT","t":1701245679970,"u":53095242440}}
{"time":1701245680,"time_ms":1701245680033,"channel":"futures.order_book_update","event":"update","result":{"U":53095242441,"a":[{"p":"38149.9","s":109},{"p":"38148.1","s":10038},{"p":"38148.6","s":0},{"p":"38157.5","s":0},{"p":"38148","s":4720},{"p":"38149.2","s":2266},{"p":"38149.1","s":5642}],"b":[],"s":"BTC_USDT","t":1701245680016,"u":53095242448}}
{"time":1701245680,"time_ms":1701245680053,"channel":"futures.order_book_update","event":"update","result":{"U":53095242449,"a":[{"p":"38149.1","s":7816},{"p":"38149.2","s":92}],"b":[{"p":"38129.6","s":0},{"p":"38134.2","s":0},{"p":"38134.7","s":0}],"s":"BTC_USDT","t":1701245680030,"u":53095242456}}
{"time":1701245680,"time_ms":1701245680071,"channel":"futures.order_book_update","event":"update","result":{"U":53095242457,"a":[],"b":[{"p":"38130","s":0}],"s":"BTC_USDT","t":1701245680043,"u":53095242457}}
{"time":1701245680,"time_ms":1701245680112,"channel":"futures.order_book_update","event":"update","result":{"U":53095242458,"a":[{"p":"38149.1","s":3340},{"p":"38149.2","s":4585}],"b":[{"p":"38136.7","s":0},{"p":"38136.8","s":0}],"s":"BTC_USDT","t":1701245680094,"u":53095242463}}
{"time":1701245680,"time_ms":1701245680134,"channel":"futures.order_book_update","event":"update","result":{"U":53095242464,"a":[{"p":"38149.1","s":0},{"p":"38150","s":61560},{"p":"38149.2","s":7925}],"b":[],"s":"BTC_USDT","t":1701245680117,"u":53095242465}}
{"time":1701245680,"time_ms":1701245680153,"channel":"futures.order_book_update","event":"update","result":{"U":53095242466,"a":[],"b":[{"p":"38134.8","s":0}],"s":"BTC_USDT","t":1701245680138,"u":53095242467}}
{"time":1701245680,"time_ms":1701245680193,"channel":"futures.order_book_update","event":"update","result":{"U":53095242468,"a":[{"p":"38153.3","s":0}],"b":[{"p":"38133.7","s":0},{"p":"38134.7","s":0},{"p":"38134.5","s":0}],"s":"BTC_USDT","t":1701245680178,"u":53095242475}}
{"time":1701245680,"time_ms":1701245680216,"channel":"futures.order_book_update","event":"update","result":{"U":53095242476,"a":[],"b":[{"p":"38136.6","s":183},{"p":"38141.8","s":9417},{"p":"38141.1","s":0},{"p":"38142.6","s":0},{"p":"38139.9","s":0},{"p":"38136.8","s":600},{"p":"38136.7","s":7864}],"s":"BTC_USDT","t":1701245680202,"u":53095242479}}
{"time":1701245680,"time_ms":1701245680253,"channel":"futures.order_book_update","event":"update","result":{"U":53095242480,"a":[],"b":[{"p":"38141.1","s":2},{"p":"38142.6","s":2},{"p":"38141.8","s":9419},{"p":"38139.9","s":2},{"p":"38136.8","s":0},{"p":"38136.7","s":0},{"p":"38136.6","s":0}],"s":"BTC_USDT","t":1701245680234,"u":53095242486}}
{"time":1701245680,"time_ms":1701245680294,"channel":"futures.order_book_update","event":"update","result":{"U":53095242487,"a":[],"b":[{"p":"38145.6","s":11135}],"s":"BTC_USDT","t":1701245680266,"u":53095242489}}
{"time":1701245680,"time_ms":1701245680353,"channel":"futures.order_book_update","event":"update","result":{"U":53095242490,"a":[{"p":"38153","s":0}],"b":[],"s":"BTC_USDT","t":1701245680343,"u":53095242491}}
{"time":1701245680,"time_ms":1701245680372,"channel":"futures.order_book_update","event":"update","result":{"U":53095242492,"a":[],"b":[{"p":"38054.8","s":0},{"p":"38048","s":0},{"p":"38053.2","s":0},{"p":"38051.6","s":0}],"s":"BTC_USDT","t":1701245680364,"u":53095242496}}
{"time":1701245680,"time_ms":1701245680433,"channel":"futures.order_book_update","event":"update","result":{"U":53095242497,"a":[{"p":"38149.2","s":92},{"p":"38148.6","s":2174},{"p":"38148.1","s":7864},{"p":"38149.8","s":3340},{"p":"38150","s":0},{"p":"38149.9","s":0},{"p":"38153.3","s":0}],"b":[{"p":"38134.5","s":0},{"p":"38134.2","s":0},{"p":"38127.7","s":0},{"p":"38134.8","s":0},{"p":"38129.9","s":0},{"p":"38133.5","s":0},{"p":"38132.4","s":0}],"s":"BTC_USDT","t":1701245680419,"u":53095242524}}
{"time":1701245680,"time_ms":1701245680514,"channel":"futures.order_book_update","event":"update","result":{"U":53095242525,"a":[{"p":"38149.9","s":2510},{"p":"38149.8","s":0},{"p":"38156.8","s":0},{"p":"38150.8","s":0}],"b":[{"p":"38135.2","s":0}],"s":"BTC_USDT","t":1701245680504,"u":53095242534}}
{"time":1701245680,"time_ms":1701245680532,"channel":"futures.order_book_update","event":"update","result":{"U":53095242535,"a":[{"p":"38148.6","s":0},{"p":"38149.2","s":2266},{"p":"38150","s":61560}],"b":[],"s":"BTC_USDT","t":1701245680507,"u":53095242536}}
{"time":1701245680,"time_ms":1701245680552,"channel":"futures.order_book_update","event":"update","result":{"U":53095242537,"a":[{"p":"38145.7","s":158085}],"b":[],"s":"BTC_USDT","t":1701245680534,"u":53095242537}}
{"time":1701245680,"time_ms":1701245680578,"channel":"futures.order_book_update","event":"update","result":{"U":53095242538,"a":[],"b":[{"p":"38134.1","s":0}],"s":"BTC_USDT","t":1701245680553,"u":53095242539}}
{"time":1701245680,"time_ms":1701245680592,"channel":"futures.order_book_update","event":"update","result":{"U":53095242540,"a":[],"b":[{"p":"38145.6","s":12635}],"s":"BTC_USDT","t":1701245680574,"u":53095242541}}
{"time":1701245680,"time_ms":1701245680653,"channel":"futures.order_book_update","event":"update","result":{"U":53095242542,"a":[],"b":[{"p":"38141.1","s":0},{"p":"38139.9","s":0},{"p":"38136.4","s":0},{"p":"38136.7","s":7864},{"p":"38136.6","s":209},{"p":"38141.8","s":9417},{"p":"38136.8","s":600},{"p":"38142.6","s":0}],"s":"BTC_USDT","t":1701245680643,"u":53095242550}}
{"time":1701245680,"time_ms":1701245680713,"channel":"futures.order_book_update","event":"update","result":{"U":53095242551,"a":[],"b":[{"p":"38136.6","s":0},{"p":"38141.8","s":9419},{"p":"38142.6","s":2},{"p":"38141.1","s":2},{"p":"38139.9","s":2},{"p":"38136.8","s":0},{"p":"38136.7","s":0}],"s":"BTC_USDT","t":1701245680689,"u":53095242554}}
{"time":1701245680,"time_ms":1701245680752,"channel":"futures.order_book_update","event":"update","result":{"U":53095242555,"a":[{"p":"38151.2","s":0},{"p":"38153.9","s":0}],"b":[{"p":"38135.2","s":0},{"p":"38126.5","s":0}],"s":"BTC_USDT","t":1701245680745,"u":53095242563}}
{"time":1701245680,"time_ms":1701245680772,"channel":"futures.order_book_update","event":"update","result":{"U":53095242564,"a":[{"p":"38149.2","s":92},{"p":"38149.8","s":2174},{"p":"38149.9","s":109},{"p":"38150","s":0}],"b":[{"p":"38134.7","s":0}],"s":"BTC_USDT","t":1701245680759,"u":53095242570}}
{"time":1701245680,"time_ms":1701245680812,"channel":"futures.order_book_update","event":"update","result":{"U":53095242571,"a":[{"p":"38153.3","s":0}],"b":[],"s":"BTC_USDT","t":1701245680791,"u":53095242571}}
{"time":1701245680,"time_ms":1701245680833,"channel":"futures.order_book_update","event":"update","result":{"U":53095242572,"a":[{"p":"38151.2","s":0}],"b":[{"p":"38145.6","s":11135},{"p":"38124","s":0},{"p":"38135.5","s":0},{"p":"38131.5","s":0}],"s":"BTC_USDT","t":1701245680820,"u":53095242579}}
{"time":1701245680,"time_ms":1701245680853,"channel":"futures.order_book_update","event":"update","result":{"U":53095242580,"a":[],"b":[{"p":"38130","s":0}],"s":"BTC_USDT","t":1701245680825,"u":53095242580}}
{"time":1701245680,"time_ms":1701245680872,"channel":"futures.order_book_update","event":"update","result":{"U":53095242581,"a":[{"p":"38153.3","s":0},{"p":"38158.8","s":0}],"b":[{"p":"38135.6","s":0}],"s":"BTC_USDT","t":1701245680864,"u":53095242586}}
{"time":1701245680,"time_ms":1701245680893,"channel":"futures.order_book_update","event":"update","result":{"U":53095242587,"a":[{"p":"38157.9","s":0}],"b":[{"p":"38136","s":0}],"s":"BTC_USDT","t":1701245680872,"u":53095242590}}
{"time":1701245680,"time_ms":1701245680994,"channel":"futures.order_book_update","event":"update","result":{"U":53095242591,"a":[],"b":[{"p":"38145.6","s":12635}],"s":"BTC_USDT","t":1701245680968,"u":53095242596}}
{"time":1701245681,"time_ms":1701245681033,"channel":"futures.order_book_update","event":"update","result":{"U":53095242597,"a":[{"p":"38154.5","s":0},{"p":"38151.7","s":0},{"p":"38150.4","s":0},{"p":"38151.6","s":0},{"p":"38149.2","s":2266},{"p":"38149.7","s":2311},{"p":"38149.9","s":5623},{"p":"38149.8","s":0}],"b":[{"p":"38136.8","s":600},{"p":"38127.9","s":0},{"p":"38134.8","s":0},{"p":"38136.7","s":7864},{"p":"38141.1","s":0},{"p":"38135.1","s":0},{"p":"38134.7","s":0},{"p":"38130.5","s":0},{"p":"38141.8","s":9417},{"p":"38142.6","s":0},{"p":"38139.9","s":0},{"p":"38135.6","s":0},{"p":"38135.7","s":0},{"p":"38136.6","s":209}],"s":"BTC_USDT","t":1701245681021,"u":53095242624}}
{"time":1701245681,"time_ms":1701245681051,"channel":"futures.order_book_update","event":"update","result":{"U":53095242625,"a":[],"b":[{"p":"38135.1","s":0}],"s":"BTC_USDT","t":1701245681035,"u":53095242626}}
{"time":1701245681,"time_ms":1701245681092,"channel":"futures.order_book_update","event":"update","result":{"U":53095242627,"a":[],"b":[{"p":"38136.6","s":0},{"p":"38139.4","s":2},{"p":"38141","s":2},{"p":"38140.2","s":2},{"p":"38138.3","s":2},{"p":"38136.8","s":0},{"p":"38136.7","s":0},{"p":"38136.9","s":0}],"s":"BTC_USDT","t":1701245681065,"u":53095242630}}
{"time":1701245681,"time_ms":1701245681251,"channel":"futures.order_book_update","event":"update","result":{"U":53095242631,"a":[],"b":[{"p":"38136.6","s":0}],"s":"BTC_USDT","t":1701245681228,"u":53095242632}}
{"time":1701245681,"time_ms":1701245681311,"channel":"futures.order_book_update","event":"update","result":{"U":53095242633,"a":[{"p":"38153.3","s":0}],"b":[],"s":"BTC_USDT","t":1701245681283,"u":53095242633}}
{"time":1701245681,"time_ms":1701245681333,"channel":"futures.order_book_update","event":"update","result":{"U":53095242634,"a":[{"p":"38153.9","s":0},{"p":"38148.6","s":0},{"p":"38149.1","s":2174},{"p":"38149.2","s":92},{"p":"38149.9","s":0},{"p":"38153.5","s":0},{"p":"38149.7","s":2311},{"p":"38149.5","s":0},{"p":"38149.6","s":40}],"b":[{"p":"38135.4","s":0},{"p":"38130.1","s":0},{"p":"38134.2","s":0},{"p":"38135.2","s":0},{"p":"38135.6","s":0},{"p":"38130.6","s":0}],"s":"BTC_USDT","t":1701245681317,"u":53095242662}}
{"time":1701245681,"time_ms":1701245681354,"channel":"futures.order_book_update","event":"update","result":{"U":53095242663,"a":[{"p":"38148.6","s":2174},{"p":"38149.1","s":0},{"p":"38149.9","s":0},{"p":"38150.4","s":0}],"b":[{"p":"38134.1","s":0},{"p":"38135.7","s":0}],"s":"BTC_USDT","t":1701245681336,"u":53095242668}}
{"time":1701245681,"time_ms":1701245681372,"channel":"futures.order_book_update","event":"update","result":{"U":53095242669,"a":[{"p":"38149.8","s":0}],"b":[],"s":"BTC_USDT","t":1701245681348,"u":53095242670}}
{"time":1701245681,"time_ms":1701245681432,"channel":"futures.order_book_update","event":"update","result":{"U":53095242671,"a":[],"b":[{"p":"38127.8","s":0}],"s":"BTC_USDT","t":1701245681419,"u":53095242671}}
{"time":1701245681,"time_ms":1701245681493,"channel":"futures.order_book_update","event":"update","result":{"U":53095242672,"a":[],"b":[{"p":"38136.7","s":7890},{"p":"38138.3","s":0},{"p":"38139.4","s":0},{"p":"38141","s":0},{"p":"38140.2","s":0},{"p":"38130","s":0},{"p":"38136.6","s":183},{"p":"38136.9","s":7234},{"p":"38136.8","s":600}],"s":"BTC_USDT","t":1701245681481,"u":53095242679}}
{"time":1701245681,"time_ms":1701245681534,"channel":"futures.order_book_update","event":"update","result":{"U":53095242680,"a":[],"b":[{"p":"38124","s":0}],"s":"BTC_USDT","t":1701245681518,"u":53095242680}}
{"time":1701245681,"time_ms":1701245681552,"channel":"futures.order_book_update","event":"update","result":{"U":53095242681,"a":[],"b":[{"p":"38140.4","s":2},{"p":"38136.9","s":0},{"p":"38136.7","s":0},{"p":"38136.8","s":0},{"p":"38136.6","s":0},{"p":"38138.5","s":2},{"p":"38141.2","s":2},{"p":"38139.7","s":2}],"s":"BTC_USDT","t":1701245681545,"u":53095242684}}
{"time":1701245681,"time_ms":1701245681572,"channel":"futures.order_book_update","event":"update","result":{"U":53095242685,"a":[{"p":"38153.9","s":0}],"b":[{"p":"38135.1","s":0},{"p":"38128.3","s":0},{"p":"38130.6","s":0},{"p":"38134.8","s":0},{"p":"38134.3","s":0},{"p":"38135.4","s":0},{"p":"38127.2","s":0}],"s":"BTC_USDT","t":1701245681563,"u":53095242700}}
{"time":1701245681,"time_ms":1701245681592,"channel":"futures.order_book_update","event":"update","result":{"U":53095242701,"a":[],"b":[{"p":"38130","s":0}],"s":"BTC_USDT","t":1701245681566,"u":53095242702}}
{"time":1701245681,"time_ms":1701245681616,"channel":"futures.order_book_update","event":"update","result":{"U":53095242703,"a":[{"p":"38148.6","s":5514},{"p":"38147.2","s":919},{"p":"38149.9","s":0}],"b":[{"p":"38129.6","s":0},{"p":"38128.4","s":0}],"s":"BTC_USDT","t":1701245681606,"u":53095242710}}
{"time":1701245681,"time_ms":1701245681634,"channel":"futures.order_book_update","event":"update","result":{"U":53095242711,"a":[],"b":[{"p":"38145.6","s":11135},{"p":"38134.8","s":0}],"s":"BTC_USDT","t":1701245681617,"u":53095242714}}
{"time":1701245681,"time_ms":1701245681653,"channel":"futures.order_book_update","event":"update","result":{"U":53095242715,"a":[{"p":"38151.6","s":0}],"b":[],"s":"BTC_USDT","t":1701245681627,"u":53095242715}}
{"time":1701245681,"time_ms":1701245681699,"channel":"futures.order_book_update","event":"update","result":{"U":53095242716,"a":[],"b":[{"p":"38145.6","s":10635},{"p":"38118.3","s":0}],"s":"BTC_USDT","t":1701245681681,"u":53095242718}}
{"time":1701245681,"time_ms":1701245681753,"channel":"futures.order_book_update","event":"update","result":{"U":53095242719,"a":[],"b":[{"p":"38140.4","s":0},{"p":"38141.2","s":0},{"p":"38136.8","s":600},{"p":"38136.6","s":183},{"p":"38136.9","s":7234},{"p":"38136.7","s":7890},{"p":"38138.5","s":0},{"p":"38139.7","s":0}],"s":"BTC_USDT","t":1701245681742,"u":53095242725}}
{"time":1701245681,"time_ms":1701245681792,"channel":"futures.order_book_update","event":"update","result":{"U":53095242726,"a":[{"p":"38153.1","s":0}],"b":[],"s":"BTC_USDT","t":1701245681767,"u":53095242726}}
{"time":1701245681,"time_ms":1701245681872,"channel":"futures.order_book_update","event":"update","result":{"U":53095242727,"a":[],"b":[{"p":"38134.9","s":0}],"s":"BTC_USDT","t":1701245681854,"u":53095242729}}
{"time":1701245681,"time_ms":1701245681892,"channel":"futures.order_book_update","event":"update","result":{"U":53095242730,"a":[],"b":[{"p":"38133.7","s":0}],"s":"BTC_USDT","t":1701245681866,"u":53095242731}}
{"time":1701245681,"time_ms":1701245681913,"channel":"futures.order_book_update","event":"update","result":{"U":53095242732,"a":[{"p":"38148.5","s":4469},{"p":"38149.7","s":0},{"p":"38149.8","s":0},{"p":"38157.5","s":0}],"b":[{"p":"38134.5","s":0}],"s":"BTC_USDT","t":1701245681897,"u":53095242739}}
{"time":1701245681,"time_ms":1701245681933,"channel":"futures.order_book_update","event":"update","result":{"U":53095242740,"a":[{"p":"38148.5","s":2174},{"p":"38149.2","s":2478}],"b":[],"s":"BTC_USDT","t":1701245681908,"u":53095242745}}
{"time":1701245681,"time_ms":1701245681997,"channel":"futures.order_book_update","event":"update","result":{"U":53095242746,"a":[],"b":[{"p":"38131.7","s":0}],"s":"BTC_USDT","t":1701245681979,"u":53095242746}}
{"time":1701245682,"time_ms":1701245682013,"channel":"futures.order_book_update","event":"update","result":{"U":53095242747,"a":[{"p":"38148.5","s":5514},{"p":"38149.2","s":92},{"p":"38148.6","s":4476}],"b":[{"p":"38126.5","s":0},{"p":"38133.8","s":0},{"p":"38129.7","s":0}],"s":"BTC_USDT","t":1701245682006,"u":53095242756}}
{"time":1701245682,"time_ms":1701245682032,"channel":"futures.order_book_update","event":"update","result":{"U":53095242757,"a":[{"p":"38153.1","s":0}],"b":[{"p":"38134.5","s":0}],"s":"BTC_USDT","t":1701245682014,"u":53095242760}}
{"time":1701245682,"time_ms":1701245682052,"channel":"futures.order_book_update","event":"update","result":{"U":53095242761,"a":[{"p":"38149.6","s":0},{"p":"38147.9","s":2174},{"p":"38148.6","s":2302}],"b":[{"p":"38133.3","s":0}],"s":"BTC_USDT","t":1701245682025,"u":53095242764}}
{"time":1701245682,"time_ms":1701245682072,"channel":"futures.order_book_update","event":"update","result":{"U":53095242765,"a":[],"b":[{"p":"38126.4","s":0},{"p":"38133.2","s":0}],"s":"BTC_USDT","t":1701245682062,"u":53095242769}}
{"time":1701245682,"time_ms":1701245682093,"channel":"futures.order_book_update","event":"update","result":{"U":53095242770,"a":[{"p":"38149.1","s":3340},{"p":"38148.5","s":2174},{"p":"38149.4","s":0},{"p":"38156.2","s":0}],"b":[{"p":"38133","s":0}],"s":"BTC_USDT","t":1701245682070,"u":53095242775}}
{"time":1701245682,"time_ms":1701245682113,"channel":"futures.order_book_update","event":"update","result":{"U":53095242776,"a":[{"p":"38149","s":2352},{"p":"38148.6","s":2174},{"p":"38148.5","s":0},{"p":"38149.4","s":0}],"b":[{"p":"38134.5","s":0},{"p":"38134.3","s":0},{"p":"38145.6","s":11135}],"s":"BTC_USDT","t":1701245682108,"u":53095242784}}
{"time":1701245682,"time_ms":1701245682153,"channel":"futures.order_book_update","event":"update","result":{"U":53095242785,"a":[{"p":"38149.1","s":0},{"p":"38152.2","s":0},{"p":"38149.3","s":27117},{"p":"38152.7","s":0},{"p":"38148.5","s":3340}],"b":[{"p":"38134.2","s":0},{"p":"38133.3","s":0}],"s":"BTC_USDT","t":1701245682140,"u":53095242793}}
{"time":1701245682,"time_ms":1701245682174,"channel":"futures.order_book_update","event":"update","result":{"U":53095242794,"a":[{"p":"38152.4","s":0},{"p":"38152.7","s":0}],"b":[{"p":"38134","s":0},{"p":"38134.3","s":0},{"p":"38126.1","s":0},{"p":"38133","s":0}],"s":"BTC_USDT","t":1701245682166,"u":53095242805}}
{"time":1701245682,"time_ms":1701245682193,"channel":"futures.order_book_update","event":"update","result":{"U":53095242806,"a":[{"p":"38149.4","s":560},{"p":"38147.9","s":0},{"p":"38147","s":600}],"b":[{"p":"38134.1","s":0}],"s":"BTC_USDT","t":1701245682187,"u":53095242811}}
{"time":1701245682,"time_ms":1701245682211,"channel":"futures.order_book_update","event":"update","result":{"U":53095242812,"a":[{"p":"38147.9","s":2174},{"p":"38149.4","s":0}],"b":[],"s":"BTC_USDT","t":1701245682190,"u":53095242812}}
{"time":1701245682,"time_ms":1701245682392,"channel":"futures.order_book_update","event":"update","result":{"U":53095242813,"a":[{"p":"38149.4","s":560},{"p":"38147","s":2774},{"p":"38147.9","s":0}],"b":[],"s":"BTC_USDT","t":1701245682364,"u":53095242816}}
{"time":1701245682,"time_ms":1701245682473,"channel":"futures.order_book_update","event":"update","result":{"U":53095242817,"a":[],"b":[{"p":"38125.1","s":0}],"s":"BTC_USDT","t":1701245682463,"u":53095242817}}
{"time":1701245682,"time_ms":1701245682672,"channel":"futures.order_book_update","event":"update","result":{"U":53095242818,"a":[{"p":"38147","s":600},{"p":"38147.9","s":2174},{"p":"38148.9","s":3340},{"p":"38149.4","s":0},{"p":"38148.5","s":0},{"p":"38149.6","s":0}],"b":[],"s":"BTC_USDT","t":1701245682656,"u":53095242824}}
{"time":1701245682,"time_ms":1701245682693,"channel":"futures.order_book_update","event":"update","result":{"U":53095242825,"a":[],"b":[{"p":"38118.8","s":0}],"s":"BTC_USDT","t":1701245682679,"u":53095242825}}
{"time":1701245682,"time_ms":1701245682973,"channel":"futures.order_book_update","event":"update","result":{"U":53095242826,"a":[],"b":[{"p":"38111.3","s":0}],"s":"BTC_USDT","t":1701245682953,"u":53095242832}}
{"time":1701245683,"time_ms":1701245683031,"channel":"futures.order_book_update","event":"update","result":{"U":53095242833,"a":[{"p":"38149.6","s":0},{"p":"38156.8","s":0},{"p":"38152.3","s":0},{"p":"38149.4","s":560},{"p":"38147","s":2774},{"p":"38148.5","s":2346},{"p":"38149","s":0},{"p":"38147.9","s":0}],"b":[{"p":"38133.8","s":0},{"p":"38133.5","s":0}],"s":"BTC_USDT","t":1701245683014,"u":53095242844}}
{"time":1701245683,"time_ms":1701245683053,"channel":"futures.order_book_update","event":"update","result":{"U":53095242845,"a":[{"p":"38149.6","s":40},{"p":"38148.9","s":0},{"p":"38148.6","s":5514}],"b":[{"p":"38134.1","s":0}],"s":"BTC_USDT","t":1701245683034,"u":53095242848}}
{"time":1701245683,"time_ms":1701245683113,"channel":"futures.order_book_update","event":"update","result":{"U":53095242849,"a":[{"p":"38147","s":600},{"p":"38147.1","s":5194}],"b":[{"p":"38132.2","s":0}],"s":"BTC_USDT","t":1701245683093,"u":53095242852}}
{"time":1701245683,"time_ms":1701245683132,"channel":"futures.order_book_update","event":"update","result":{"U":53095242853,"a":[],"b":[{"p":"38129.2","s":0}],"s":"BTC_USDT","t":1701245683115,"u":53095242854}}
{"time":1701245683,"time_ms":1701245683151,"channel":"futures.order_book_update","event":"update","result":{"U":53095242855,"a":[],"b":[{"p":"38125.5","s":0}],"s":"BTC_USDT","t":1701245683134,"u":53095242856}}
{"time":1701245683,"time_ms":1701245683171,"channel":"futures.order_book_update","event":"update","result":{"U":53095242857,"a":[{"p":"38152.1","s":0},{"p":"38152.3","s":0},{"p":"38155.9","s":0}],"b":[],"s":"BTC_USDT","t":1701245683162,"u":53095242861}}
{"time":1701245683,"time_ms":1701245683191,"channel":"futures.order_book_update","event":"update","result":{"U":53095242862,"a":[{"p":"38148.6","s":2174},{"p":"38149.1","s":3340},{"p":"38147.9","s":2174},{"p":"38147.1","s":3020},{"p":"38149.6","s":0},{"p":"38149.4","s":0}],"b":[{"p":"38134.1","s":0},{"p":"38129.6","s":0},{"p":"38133.7","s":0},{"p":"38134","s":0}],"s":"BTC_USDT","t":1701245683174,"u":53095242874}}
{"time":1701245683,"time_ms":1701245683213,"channel":"futures.order_book_update","event":"update","result":{"U":53095242875,"a":[{"p":"38147.2","s":3093},{"p":"38149.4","s":560},{"p":"38147.9","s":0}],"b":[{"p":"38129.9","s":0}],"s":"BTC_USDT","t":1701245683185,"u":53095242878}}
{"time":1701245683,"time_ms":1701245683233,"channel":"futures.order_book_update","event":"update","result":{"U":53095242879,"a":[{"p":"38149.6","s":40},{"p":"38148.6","s":5514},{"p":"38149.1","s":0}],"b":[],"s":"BTC_USDT","t":1701245683221,"u":53095242880}}
{"time":1701245683,"time_ms":1701245683272,"channel":"futures.order_book_update","event":"update","result":{"U":53095242881,"a":[],"b":[{"p":"38126.1","s":0}],"s":"BTC_USDT","t":1701245683265,"u":53095242882}}
{"time":1701245683,"time_ms":1701245683296,"channel":"futures.order_book_update","event":"update","result":{"U":53095242883,"a":[],"b":[{"p":"38132.7","s":0}],"s":"BTC_USDT","t":1701245683278,"u":53095242884}}
{"time":1701245683,"time_ms":1701245683332,"channel":"futures.order_book_update","event":"update","result":{"U":53095242885,"a":[{"p":"38152.6","s":0}],"b":[{"p":"38139.9","s":2},{"p":"38142.6","s":2},{"p":"38141.8","s":9419},{"p":"38141","s":2},{"p":"38136.7","s":0},{"p":"38136.6","s":0},{"p":"38136.8","s":0}],"s":"BTC_USDT","t":1701245683320,"u":53095242889}}
{"time":1701245683,"time_ms":1701245683352,"channel":"futures.order_book_update","event":"update","result":{"U":53095242890,"a":[{"p":"38152.3","s":0},{"p":"38147.2","s":919},{"p":"38149.2","s":2266},{"p":"38149.1","s":3340},{"p":"38147.9","s":2174},{"p":"38149.6","s":0},{"p":"38148.6","s":0},{"p":"38156.2","s":0}],"b":[{"p":"38132.2","s":0},{"p":"38125.5","s":0},{"p":"38134.2","s":0}],"s":"BTC_USDT","t":1701245683337,"u":53095242905}}
{"time":1701245683,"time_ms":1701245683512,"channel":"futures.order_book_update","event":"update","result":{"U":53095242906,"a":[{"p":"38149.2","s":92},{"p":"38149.4","s":0},{"p":"38148.4","s":2174}],"b":[{"p":"38134.5","s":0},{"p":"38133.2","s":0}],"s":"BTC_USDT","t":1701245683496,"u":53095242914}}
{"time":1701245683,"time_ms":1701245683574,"channel":"futures.order_book_update","event":"update","result":{"U":53095242915,"a":[],"b":[{"p":"38136.8","s":600},{"p":"38136.7","s":7890},{"p":"38142.6","s":0},{"p":"38141","s":0},{"p":"38141.8","s":9419},{"p":"38126.4","s":0},{"p":"38139.9","s":2},{"p":"38136.6","s":0}],"s":"BTC_USDT","t":1701245683565,"u":53095242923}}
{"time":1701245683,"time_ms":1701245683591,"channel":"futures.order_book_update","event":"update","result":{"U":53095242924,"a":[],"b":[{"p":"38142.6","s":2},{"p":"38141.1","s":2},{"p":"38136.8","s":0},{"p":"38136.7","s":0},{"p":"38132.8","s":0}],"s":"BTC_USDT","t":1701245683578,"u":53095242928}}
{"time":1701245683,"time_ms":1701245683613,"channel":"futures.order_book_update","event":"update","result":{"U":53095242929,"a":[{"p":"38146.5","s":2174},{"p":"38147.9","s":0},{"p":"38149.3","s":27117},{"p":"38152.7","s":0},{"p":"38153.3","s":0}],"b":[{"p":"38133.8","s":0},{"p":"38134.2","s":0}],"s":"BTC_USDT","t":1701245683598,"u":53095242936}}
{"time":1701245683,"time_ms":1701245683633,"channel":"futures.order_book_update","event":"update","result":{"U":53095242937,"a":[{"p":"38149.4","s":560},{"p":"38148.4","s":5514},{"p":"38149.1","s":0}],"b":[],"s":"BTC_USDT","t":1701245683609,"u":53095242939}}
{"time":1701245683,"time_ms":1701245683731,"channel":"futures.order_book_update","event":"update","result":{"U":53095242940,"a":[],"b":[{"p":"38141.1","s":0},{"p":"38136.7","s":7890},{"p":"38136.6","s":183},{"p":"38136.8","s":600},{"p":"38142.6","s":0},{"p":"38139.9","s":0}],"s":"BTC_USDT","t":1701245683711,"u":53095242943}}
{"time":1701245683,"time_ms":1701245683753,"channel":"futures.order_book_update","event":"update","result":{"U":53095242944,"a":[{"p":"38149.1","s":3340},{"p":"38149.4","s":0},{"p":"38148.4","s":2174}],"b":[{"p":"38141.1","s":2},{"p":"38141.8","s":9417},{"p":"38142.6","s":2},{"p":"38136.7","s":0},{"p":"38136.6","s":0},{"p":"38136.8","s":0},{"p":"38139.9","s":2}],"s":"BTC_USDT","t":1701245683744,"u":53095242953}}
{"time":1701245683,"time_ms":1701245683772,"channel":"futures.order_book_update","event":"update","result":{"U":53095242954,"a":[],"b":[{"p":"38141.1","s":0},{"p":"38142.6","s":0},{"p":"38136.8","s":600},{"p":"38136.7","s":7890},{"p":"38141.8","s":9419},{"p":"38136.6","s":183},{"p":"38139.9","s":0}],"s":"BTC_USDT","t":1701245683762,"u":53095242959}}
{"time":1701245683,"time_ms":1701245683791,"channel":"futures.order_book_update","event":"update","result":{"U":53095242960,"a":[],"b":[{"p":"38145.6","s":3484}],"s":"BTC_USDT","t":1701245683775,"u":53095242960}}
{"time":1701245683,"time_ms":1701245683812,"channel":"futures.order_book_update","event":"update","result":{"U":53095242961,"a":[],"b":[{"p":"38136.7","s":0},{"p":"38136.8","s":0},{"p":"38139.9","s":2},{"p":"38141.1","s":2},{"p":"38142.6","s":2},{"p":"38136.6","s":0}],"s":"BTC_USDT","t":1701245683783,"u":53095242963}}
{"time":1701245683,"time_ms":1701245683992,"channel":"futures.order_book_update","event":"update","result":{"U":53095242964,"a":[],"b":[{"p":"38145.6","s":11135}],"s":"BTC_USDT","t":1701245683976,"u":53095242972}}
{"time":1701245684,"time_ms":1701245684037,"channel":"futures.order_book_update","event":"update","result":{"U":53095242973,"a":[{"p":"38148.5","s":0},{"p":"38156.8","s":0},{"p":"38151.9","s":0},{"p":"38149.6","s":0},{"p":"38148.3","s":2542},{"p":"38146.9","s":2174},{"p":"38149.4","s":560},{"p":"38146.5","s":0}],"b":[{"p":"38129.7","s":0},{"p":"38129.6","s":0},{"p":"38133.5","s":0}],"s":"BTC_USDT","t":1701245684028,"u":53095242990}}
{"time":1701245684,"time_ms":1701245684054,"channel":"futures.order_book_update","event":"update","result":{"U":53095242991,"a":[{"p":"38147.9","s":2174},{"p":"38148.4","s":0},{"p":"38146.5","s":0},{"p":"38146.9","s":2174},{"p":"38149.6","s":0}],"b":[],"s":"BTC_USDT","t":1701245684046,"u":53095242996}}
{"time":1701245684,"time_ms":1701245684072,"channel":"futures.order_book_update","event":"update","result":{"U":53095242997,"a":[{"p":"38149.6","s":40},{"p":"38146.9","s":0}],"b":[],"s":"BTC_USDT","t":1701245684053,"u":53095242997}}
{"time":1701245684,"time_ms":1701245684093,"channel":"futures.order_book_update","event":"update","result":{"U":53095242998,"a":[{"p":"38146.9","s":2174},{"p":"38149.6","s":0},{"p":"38146.5","s":0}],"b":[],"s":"BTC_USDT","t":1701245684082,"u":53095243002}}
{"time":1701245684,"time_ms":1701245684112,"channel":"futures.order_book_update","event":"update","result":{"U":53095243003,"a":[{"p":"38148.6","s":3340},{"p":"38146.5","s":2174},{"p":"38148.3","s":208},{"p":"38148.2","s":2693},{"p":"38146.9","s":0},{"p":"38149.1","s":0},{"p":"38149.6","s":0},{"p":"38149.4","s":560}],"b":[{"p":"38141.8","s":9417},{"p":"38139.9","s":0},{"p":"38142.6","s":0},{"p":"38129.8","s":0},{"p":"38133.8","s":0},{"p":"38136.8","s":600},{"p":"38136.7","s":7890},{"p":"38136.6","s":183},{"p":"38141.1","s":0},{"p":"38133.6","s":0}],"s":"BTC_USDT","t":1701245684102,"u":53095243020}}
{"time":1701245684,"time_ms":1701245684213,"channel":"futures.order_book_update","event":"update","result":{"U":53095243021,"a":[{"p":"38148.5","s":2375},{"p":"38148.2","s":368},{"p":"38149.4","s":0}],"b":[],"s":"BTC_USDT","t":1701245684185,"u":53095243022}}
{"time":1701245684,"time_ms":1701245684352,"channel":"futures.order_book_update","event":"update","result":{"U":53095243023,"a":[],"b":[{"p":"38133.5","s":0},{"p":"38133.7","s":0}],"s":"BTC_USDT","t":1701245684344,"u":53095243026}}
{"time":1701245684,"time_ms":1701245684375,"channel":"futures.order_book_update","event":"update","result":{"U":53095243027,"a":[{"p":"38149.4","s":560},{"p":"38147.9","s":4479},{"p":"38148.5","s":0}],"b":[{"p":"38145.6","s":3484},{"p":"38133.6","s":0}],"s":"BTC_USDT","t":1701245684359,"u":53095243031}}
{"time":1701245684,"time_ms":1701245684512,"channel":"futures.order_book_update","event":"update","result":{"U":53095243032,"a":[],"b":[{"p":"38133.5","s":0}],"s":"BTC_USDT","t":1701245684488,"u":53095243033}}
{"time":1701245684,"time_ms":1701245684571,"channel":"futures.order_book_update","event":"update","result":{"U":53095243034,"a":[{"p":"38147.3","s":4322}],"b":[],"s":"BTC_USDT","t":1701245684549,"u":53095243034}}
{"time":1701245684,"time_ms":1701245684692,"channel":"futures.order_book_update","event":"update","result":{"U":53095243035,"a":[],"b":[{"p":"38132.2","s":0}],"s":"BTC_USDT","t":1701245684674,"u":53095243038}}
{"time":1701245684,"time_ms":1701245684813,"channel":"futures.order_book_update","event":"update","result":{"U":53095243039,"a":[{"p":"38152","s":0}],"b":[{"p":"38133.2","s":0},{"p":"38131.8","s":0},{"p":"38133.3","s":0}],"s":"BTC_USDT","t":1701245684796,"u":53095243048}}
{"time":1701245684,"time_ms":1701245684833,"channel":"futures.order_book_update","event":"update","result":{"U":53095243049,"a":[{"p":"38148","s":8060},{"p":"38149.6","s":40},{"p":"38148.6","s":0}],"b":[{"p":"38133.3","s":0}],"s":"BTC_USDT","t":1701245684814,"u":53095243052}}
{"time":1701245684,"time_ms":1701245684892,"channel":"futures.order_book_update","event":"update","result":{"U":53095243053,"a":[],"b":[{"p":"38136.4","s":0},{"p":"38140.9","s":6718},{"p":"38141.7","s":26},{"p":"38141.8","s":0}],"s":"BTC_USDT","t":1701245684881,"u":53095243055}}
{"time":1701245684,"time_ms":1701245684954,"channel":"futures.order_book_update","event":"update","result":{"U":53095243056,"a":[{"p":"38188.2","s":0}],"b":[{"p":"38092.6","s":0}],"s":"BTC_USDT","t":1701245684942,"u":53095243058}}
{"time":1701245685,"time_ms":1701245685031,"channel":"futures.order_book_update","event":"update","result":{"U":53095243059,"a":[{"p":"38147.9","s":0},{"p":"38155.7","s":0},{"p":"38149.9","s":0},{"p":"38149.6","s":40},{"p":"38151.5","s":0},{"p":"38148.2","s":3708},{"p":"38145.9","s":2174},{"p":"38146.5","s":0},{"p":"38147.8","s":4512},{"p":"38148","s":4720}],"b":[{"p":"38133","s":0},{"p":"38125.5","s":0},{"p":"38130.6","s":0}],"s":"BTC_USDT","t":1701245685018,"u":53095243079}}
{"time":1701245685,"time_ms":1701245685113,"channel":"futures.order_book_update","event":"update","result":{"U":53095243080,"a":[{"p":"38153.3","s":0}],"b":[],"s":"BTC_USDT","t":1701245685096,"u":53095243081}}
{"time":1701245685,"time_ms":1701245685132,"channel":"futures.order_book_update","event":"update","result":{"U":53095243082,"a":[],"b":[{"p":"38133.3","s":0}],"s":"BTC_USDT","t":1701245685123,"u":53095243084}}
{"time":1701245685,"time_ms":1701245685153,"channel":"futures.order_book_update","event":"update","result":{"U":53095243085,"a":[],"b":[{"p":"38141.7","s":15026},{"p":"38131.8","s":0}],"s":"BTC_USDT","t":1701245685144,"u":53095243087}}
{"time":1701245685,"time_ms":1701245685173,"channel":"futures.order_book_update","event":"update","result":{"U":53095243088,"a":[],"b":[{"p":"38123.6","s":0},{"p":"38141.8","s":9022},{"p":"38140.9","s":0},{"p":"38136.4","s":0},{"p":"38132.2","s":0}],"s":"BTC_USDT","t":1701245685155,"u":53095243092}}
{"time":1701245685,"time_ms":1701245685191,"channel":"futures.order_book_update","event":"update","result":{"U":53095243093,"a":[{"p":"38155","s":0},{"p":"38151","s":0},{"p":"38162.5","s":0}],"b":[{"p":"38136.8","s":0},{"p":"38136.7","s":0},{"p":"38136.6","s":0},{"p":"38135.5","s":0},{"p":"38141.8","s":9024},{"p":"38142.9","s":2},{"p":"38139.5","s":8912},{"p":"38123.5","s":0},{"p":"38131.5","s":0},{"p":"38145.6","s":11135},{"p":"38144.4","s":2}],"s":"BTC_USDT","t":1701245685183,"u":53095243108}}
{"time":1701245685,"time_ms":1701245685212,"channel":"futures.order_book_update","event":"update","result":{"U":53095243109,"a":[],"b":[{"p":"38139","s":100},{"p":"38139.6","s":5355},{"p":"38143.7","s":2},{"p":"38137.8","s":0},{"p":"38136.9","s":0},{"p":"38131.8","s":0}],"s":"BTC_USDT","t":1701245685193,"u":53095243114}}
{"time":1701245685,"time_ms":1701245685234,"channel":"futures.order_book_update","event":"update","result":{"U":53095243115,"a":[{"p":"38151.4","s":0},{"p":"38148.6","s":0},{"p":"38154.8","s":0},{"p":"38147.8","s":2174},{"p":"38148.2","s":368},{"p":"38145.9","s":0},{"p":"38149.6","s":0},{"p":"38149.4","s":560},{"p":"38155.2","s":0},{"p":"38149.1","s":3340},{"p":"38146.3","s":2174},{"p":"38148.1","s":10173}],"b":[{"p":"38132.2","s":0},{"p":"38138","s":100},{"p":"38133.3","s":0},{"p":"38132.8","s":0},{"p":"38133.5","s":0},{"p":"38143.1","s":395},{"p":"38137.8","s":0},{"p":"38145.3","s":0},{"p":"38128.4","s":0},{"p":"38131.4","s":0}],"s":"BTC_USDT","t":1701245685227,"u":53095243144}}
{"time":1701245685,"time_ms":1701245685251,"channel":"futures.order_book_update","event":"update","result":{"U":53095243145,"a":[{"p":"38146.9","s":2174},{"p":"38146.3","s":0},{"p":"38146.5","s":0},{"p":"38149.4","s":560}],"b":[],"s":"BTC_USDT","t":1701245685235,"u":53095243148}}
{"time":1701245685,"time_ms":1701245685272,"channel":"futures.order_book_update","event":"update","result":{"U":53095243149,"a":[{"p":"38149.6","s":0},{"p":"38146.5","s":2174},{"p":"38146.9","s":0}],"b":[],"s":"BTC_USDT","t":1701245685250,"u":53095243150}}
{"time":1701245685,"time_ms":1701245685292,"channel":"futures.order_book_update","event":"update","result":{"U":53095243151,"a":[{"p":"38153","s":0}],"b":[],"s":"BTC_USDT","t":1701245685282,"u":53095243151}}
{"time":1701245685,"time_ms":1701245685313,"channel":"futures.order_book_update","event":"update","result":{"U":53095243152,"a":[{"p":"38167","s":0},{"p":"38165","s":0},{"p":"38153.5","s":0},{"p":"38146.4","s":10},{"p":"38148.7","s":16442},{"p":"38145.7","s":154940},{"p":"38148.1","s":0},{"p":"38155.5","s":0},{"p":"38148.6","s":2394},{"p":"38149.6","s":0},{"p":"38157.5","s":0},{"p":"38159.5","s":0}],"b":[{"p":"38135.5","s":0},{"p":"38137.8","s":15208},{"p":"38139","s":9012},{"p":"38139.5","s":0},{"p":"38133.5","s":0},{"p":"38137.5","s":0},{"p":"38128","s":0}],"s":"BTC_USDT","t":1701245685303,"u":53095243180}}
{"time":1701245685,"time_ms":1701245685333,"channel":"futures.order_book_update","event":"update","result":{"U":53095243181,"a":[{"p":"38149.6","s":40},{"p":"38148","s":0}],"b":[{"p":"38133","s":0},{"p":"38126","s":0}],"s":"BTC_USDT","t":1701245685323,"u":53095243186}}
{"time":1701245685,"time_ms":1701245685372,"channel":"futures.order_book_update","event":"update","result":{"U":53095243187,"a":[{"p":"38159","s":0},{"p":"38155","s":0}],"b":[{"p":"38137.8","s":0},{"p":"38135","s":0},{"p":"38138.5","s":8913},{"p":"38139","s":100}],"s":"BTC_USDT","t":1701245685348,"u":53095243194}}
{"time":1701245685,"time_ms":1701245685413,"channel":"futures.order_book_update","event":"update","result":{"U":53095243195,"a":[{"p":"38154.8","s":0},{"p":"38148.1","s":2174},{"p":"38148.5","s":3340},{"p":"38149.1","s":0},{"p":"38147.8","s":0},{"p":"38149.9","s":0}],"b":[{"p":"38128.7","s":0}],"s":"BTC_USDT","t":1701245685396,"u":53095243201}}
{"time":1701245685,"time_ms":1701245685433,"channel":"futures.order_book_update","event":"update","result":{"U":53095243202,"a":[],"b":[{"p":"38137.8","s":15208},{"p":"38138.5","s":0},{"p":"38137","s":0}],"s":"BTC_USDT","t":1701245685407,"u":53095243203}}
{"time":1701245685,"time_ms":1701245685452,"channel":"futures.order_book_update","event":"update","result":{"U":53095243204,"a":[],"b":[{"p":"38134.5","s":0}],"s":"BTC_USDT","t":1701245685431,"u":53095243205}}
{"time":1701245685,"time_ms":1701245685472,"channel":"futures.order_book_update","event":"update","result":{"U":53095243206,"a":[{"p":"38154.5","s":0}],"b":[{"p":"38127.5","s":0}],"s":"BTC_USDT","t":1701245685460,"u":53095243209}}
{"time":1701245685,"time_ms":1701245685493,"channel":"futures.order_book_update","event":"update","result":{"U":53095243210,"a":[{"p":"38166.5","s":0}],"b":[],"s":"BTC_USDT","t":1701245685480,"u":53095243211}}
{"time":1701245685,"time_ms":1701245685511,"channel":"futures.order_book_update","event":"update","result":{"U":53095243212,"a":[{"p":"38158.5","s":0}],"b":[{"p":"38133.3","s":0}],"s":"BTC_USDT","t":1701245685498,"u":53095243218}}
{"time":1701245685,"time_ms":1701245685591,"channel":"futures.order_book_update","event":"update","result":{"U":53095243219,"a":[{"p":"38149.9","s":109},{"p":"38147","s":2774},{"p":"38146.5","s":0}],"b":[],"s":"BTC_USDT","t":1701245685575,"u":53095243221}}
{"time":1701245685,"time_ms":1701245685611,"channel":"futures.order_book_update","event":"update","result":{"U":53095243222,"a":[],"b":[{"p":"38136.8","s":0}],"s":"BTC_USDT","t":1701245685599,"u":53095243223}}
{"time":1701245685,"time_ms":1701245685633,"channel":"futures.order_book_update","event":"update","result":{"U":53095243224,"a":[{"p":"38155.5","s":0},{"p":"38150","s":0},{"p":"38151.7","s":0},{"p":"38149.1","s":3340},{"p":"38148.5","s":0}],"b":[],"s":"BTC_USDT","t":1701245685624,"u":53095243229}}
{"time":1701245685,"time_ms":1701245685792,"channel":"futures.order_book_update","event":"update","result":{"U":53095243230,"a":[],"b":[{"p":"38133.5","s":0}],"s":"BTC_USDT","t":1701245685777,"u":53095243231}}
{"time":1701245685,"time_ms":1701245685832,"channel":"futures.order_book_update","event":"update","result":{"U":53095243232,"a":[{"p":"38148.1","s":0},{"p":"38150","s":0},{"p":"38148.5","s":2174},{"p":"38145.7","s":158085}],"b":[],"s":"BTC_USDT","t":1701245685821,"u":53095243234}}
{"time":1701245685,"time_ms":1701245685852,"channel":"futures.order_book_update","event":"update","result":{"U":53095243235,"a":[{"p":"38145.7","s":158609}],"b":[],"s":"BTC_USDT","t":1701245685838,"u":53095243235}}
{"time":1701245685,"time_ms":1701245685892,"channel":"futures.order_book_update","event":"update","result":{"U":53095243236,"a":[{"p":"38148","s":2174},{"p":"38147","s":600},{"p":"38149.9","s":0}],"b":[{"p":"38130.4","s":0},{"p":"38141.8","s":9022},{"p":"38144.4","s":0},{"p":"38142.9","s":0},{"p":"38143.7","s":0},{"p":"38129.6","s":0},{"p":"38137","s":8913},{"p":"38136.7","s":7890},{"p":"38136.9","s":7834}],"s":"BTC_USDT","t":1701245685882,"u":53095243245}}
{"time":1701245685,"time_ms":1701245685933,"channel":"futures.order_book_update","event":"update","result":{"U":53095243246,"a":[],"b":[{"p":"38136.7","s":0},{"p":"38142.9","s":2},{"p":"38143.6","s":2},{"p":"38141","s":2},{"p":"38142.1","s":2},{"p":"38137.8","s":0},{"p":"38136.9","s":0},{"p":"38137","s":0}],"s":"BTC_USDT","t":1701245685907,"u":53095243249}}
{"time":1701245686,"time_ms":1701245686013,"channel":"futures.order_book_update","event":"update","result":{"U":53095243250,"a":[],"b":[{"p":"38125.4","s":0},{"p":"38133.3","s":0}],"s":"BTC_USDT","t":1701245686005,"u":53095243254}}
{"time":1701245686,"time_ms":1701245686033,"channel":"futures.order_book_update","event":"update","result":{"U":53095243255,"a":[{"p":"38148.1","s":2174},{"p":"38148","s":0},{"p":"38149.9","s":0},{"p":"38152","s":0}],"b":[{"p":"38133.8","s":0},{"p":"38132.2","s":0}],"s":"BTC_USDT","t":1701245686018,"u":53095243263}}
{"time":1701245686,"time_ms":1701245686072,"channel":"futures.order_book_update","event":"update","result":{"U":53095243264,"a":[],"b":[{"p":"38137.8","s":15208},{"p":"38136.9","s":7834},{"p":"38137","s":8913},{"p":"38143.6","s":0},{"p":"38142.9","s":0},{"p":"38142.1","s":0}],"s":"BTC_USDT","t":1701245686058,"u":53095243266}}
{"time":1701245686,"time_ms":1701245686092,"channel":"futures.order_book_update","event":"update","result":{"U":53095243267,"a":[],"b":[{"p":"38136.7","s":7890},{"p":"38141","s":0},{"p":"38133.9","s":0}],"s":"BTC_USDT","t":1701245686085,"u":53095243269}}
{"time":1701245686,"time_ms":1701245686112,"channel":"futures.order_book_update","event":"update","result":{"U":53095243270,"a":[],"b":[{"p":"38143.6","s":2},{"p":"38142.9","s":2},{"p":"38141","s":2},{"p":"38137.8","s":0},{"p":"38136.9","s":0},{"p":"38136.7","s":0},{"p":"38142.1","s":2},{"p":"38137","s":0},{"p":"38132.8","s":0},{"p":"38130","s":0}],"s":"BTC_USDT","t":1701245686102,"u":53095243276}}
{"time":1701245686,"time_ms":1701245686190,"channel":"futures.order_book_update","event":"update","result":{"U":53095243277,"a":[{"p":"38145.7","s":158709}],"b":[],"s":"BTC_USDT","t":1701245686175,"u":53095243278}}
{"time":1701245686,"time_ms":1701245686213,"channel":"futures.order_book_update","event":"update","result":{"U":53095243279,"a":[],"b":[{"p":"38130.4","s":0}],"s":"BTC_USDT","t":1701245686191,"u":53095243280}}
{"time":1701245686,"time_ms":1701245686252,"channel":"futures.order_book_update","event":"update","result":{"U":53095243281,"a":[{"p":"38163.4","s":0}],"b":[{"p":"38119.9","s":0}],"s":"BTC_USDT","t":1701245686240,"u":53095243282}}
{"time":1701245686,"time_ms":1701245686271,"channel":"futures.order_book_update","event":"update","result":{"U":53095243283,"a":[],"b":[{"p":"38136.9","s":7834},{"p":"38137","s":8913},{"p":"38136.7","s":7890},{"p":"38137.8","s":15208},{"p":"38143.6","s":0},{"p":"38142.1","s":0},{"p":"38141","s":0},{"p":"38142.9","s":0}],"s":"BTC_USDT","t":1701245686257,"u":53095243286}}
{"time":1701245686,"time_ms":1701245686293,"channel":"futures.order_book_update","event":"update","result":{"U":53095243287,"a":[],"b":[{"p":"38137","s":0},{"p":"38141","s":2},{"p":"38142.9","s":2},{"p":"38142.1","s":2},{"p":"38136.7","s":0},{"p":"38136.9","s":0}],"s":"BTC_USDT","t":1701245686283,"u":53095243289}}
{"time":1701245686,"time_ms":1701245686316,"channel":"futures.order_book_update","event":"update","result":{"U":53095243290,"a":[],"b":[{"p":"38130","s":0},{"p":"38143.6","s":2},{"p":"38137.8","s":0}],"s":"BTC_USDT","t":1701245686289,"u":53095243292}}
{"time":1701245686,"time_ms":1701245686432,"channel":"futures.order_book_update","event":"update","result":{"U":53095243293,"a":[],"b":[{"p":"38133.2","s":0},{"p":"38130.4","s":0}],"s":"BTC_USDT","t":1701245686424,"u":53095243299}}
{"time":1701245686,"time_ms":1701245686471,"channel":"futures.order_book_update","event":"update","result":{"U":53095243300,"a":[],"b":[{"p":"38143.7","s":655},{"p":"38143","s":0},{"p":"38128.6","s":0},{"p":"38137.8","s":0}],"s":"BTC_USDT","t":1701245686459,"u":53095243306}}
{"time":1701245686,"time_ms":1701245686492,"channel":"futures.order_book_update","event":"update","result":{"U":53095243307,"a":[{"p":"38156.2","s":0}],"b":[{"p":"38143.8","s":398},{"p":"38143.1","s":0},{"p":"38138","s":100},{"p":"38134.3","s":0},{"p":"38134.2","s":0}],"s":"BTC_USDT","t":1701245686473,"u":53095243314}}
{"time":1701245686,"time_ms":1701245686513,"channel":"futures.order_book_update","event":"update","result":{"U":53095243315,"a":[],"b":[{"p":"38134.4","s":0}],"s":"BTC_USDT","t":1701245686501,"u":53095243316}}
{"time":1701245686,"time_ms":1701245686652,"channel":"futures.order_book_update","event":"update","result":{"U":53095243317,"a":[],"b":[{"p":"38134.5","s":0}],"s":"BTC_USDT","t":1701245686632,"u":53095243320}}
{"time":1701245686,"time_ms":1701245686671,"channel":"futures.order_book_update","event":"update","result":{"U":53095243321,"a":[{"p":"38152.3","s":0},{"p":"38157","s":0},{"p":"38149","s":2350},{"p":"38148.6","s":0},{"p":"38149.9","s":0},{"p":"38164.5","s":0},{"p":"38153","s":0}],"b":[{"p":"38145.6","s":18963},{"p":"38138","s":0},{"p":"38134.3","s":0},{"p":"38133","s":0},{"p":"38125.5","s":0},{"p":"38130","s":0},{"p":"38137","s":0},{"p":"38139.5","s":8912}],"s":"BTC_USDT","t":1701245686662,"u":53095243340}}
{"time":1701245686,"time_ms":1701245686695,"channel":"futures.order_book_update","event":"update","result":{"U":53095243341,"a":[{"p":"38149.8","s":0},{"p":"38149.6","s":40},{"p":"38148","s":524},{"p":"38145.7","s":158185},{"p":"38149.1","s":0}],"b":[{"p":"38133.1","s":0}],"s":"BTC_USDT","t":1701245686685,"u":53095243347}}
{"time":1701245686,"time_ms":1701245686712,"channel":"futures.order_book_update","event":"update","result":{"U":53095243348,"a":[],"b":[{"p":"38145.6","s":11135},{"p":"38133.5","s":0}],"s":"BTC_USDT","t":1701245686698,"u":53095243350}}
{"time":1701245686,"time_ms":1701245686732,"channel":"futures.order_book_update","event":"update","result":{"U":53095243351,"a":[],"b":[{"p":"38134.6","s":0}],"s":"BTC_USDT","t":1701245686714,"u":53095243352}}
{"time":1701245686,"time_ms":1701245686752,"channel":"futures.order_book_update","event":"update","result":{"U":53095243353,"a":[{"p":"38159.5","s":0},{"p":"38155.5","s":0}],"b":[{"p":"38135.5","s":0},{"p":"38138","s":100},{"p":"38139","s":9012},{"p":"38139.5","s":0}],"s":"BTC_USDT","t":1701245686742,"u":53095243360}}
{"time":1701245686,"time_ms":1701245686793,"channel":"futures.order_book_update","event":"update","result":{"U":53095243361,"a":[],"b":[{"p":"38137.8","s":15208},{"p":"38136.6","s":183},{"p":"38141","s":0},{"p":"38135.9","s":0},{"p":"38136.9","s":7860},{"p":"38136.7","s":7864},{"p":"38143.6","s":0},{"p":"38142.9","s":0},{"p":"38142.1","s":0}],"s":"BTC_USDT","t":1701245686783,"u":53095243370}}
{"time":1701245686,"time_ms":1701245686812,"channel":"futures.order_book_update","event":"update","result":{"U":53095243371,"a":[{"p":"38159","s":0},{"p":"38155","s":0},{"p":"38167","s":0}],"b":[{"p":"38143.7","s":657},{"p":"38142.1","s":2},{"p":"38136.9","s":0},{"p":"38136.7","s":0},{"p":"38128","s":0},{"p":"38135","s":0},{"p":"38142.9","s":2},{"p":"38141","s":2},{"p":"38139","s":100},{"p":"38138","s":9013},{"p":"38136.6","s":0}],"s":"BTC_USDT","t":1701245686800,"u":53095243388}}
{"time":1701245686,"time_ms":1701245686852,"channel":"futures.order_book_update","event":"update","result":{"U":53095243389,"a":[{"p":"38149.1","s":3340},{"p":"38149.6","s":0},{"p":"38149.8","s":0}],"b":[],"s":"BTC_USDT","t":1701245686828,"u":53095243390}}
{"time":1701245686,"time_ms":1701245686873,"channel":"futures.order_book_update","event":"update","result":{"U":53095243391,"a":[{"p":"38158","s":0},{"p":"38154","s":0}],"b":[{"p":"38138","s":100},{"p":"38134","s":0},{"p":"38137","s":0}],"s":"BTC_USDT","t":1701245686862,"u":53095243398}}
{"time":1701245686,"time_ms":1701245686894,"channel":"futures.order_book_update","event":"update","result":{"U":53095243399,"a":[{"p":"38154.8","s":0}],"b":[{"p":"38130","s":0},{"p":"38135.7","s":0}],"s":"BTC_USDT","t":1701245686883,"u":53095243402}}
{"time":1701245687,"time_ms":1701245687035,"channel":"futures.order_book_update","event":"update","result":{"U":53095243403,"a":[{"p":"38148.1","s":0},{"p":"38149.6","s":0},{"p":"38148.6","s":0},{"p":"38152.7","s":0},{"p":"38149.4","s":560},{"p":"38147.9","s":2174},{"p":"38148.4","s":2174},{"p":"38148.5","s":0}],"b":[{"p":"38141","s":0},{"p":"38133.8","s":0},{"p":"38134.2","s":0},{"p":"38130.6","s":0},{"p":"38136.9","s":7860},{"p":"38137","s":8913},{"p":"38142.9","s":0},{"p":"38142.1","s":0},{"p":"38134.3","s":0},{"p":"38126.1","s":0},{"p":"38136.8","s":4726},{"p":"38143.7","s":655}],"s":"BTC_USDT","t":1701245687023,"u":53095243425}}
{"time":1701245687,"time_ms":1701245687057,"channel":"futures.order_book_update","event":"update","result":{"U":53095243426,"a":[],"b":[{"p":"38136.8","s":0},{"p":"38142.9","s":2},{"p":"38142.1","s":2},{"p":"38143.7","s":657},{"p":"38141","s":2},{"p":"38137","s":0},{"p":"38136.9","s":0}],"s":"BTC_USDT","t":1701245687039,"u":53095243429}}
{"time":1701245687,"time_ms":1701245687111,"channel":"futures.order_book_update","event":"update","result":{"U":53095243430,"a":[{"p":"38148.6","s":2174},{"p":"38148.4","s":0},{"p":"38149.6","s":0}],"b":[{"p":"38145.6","s":12635},{"p":"38134.4","s":0}],"s":"BTC_USDT","t":1701245687099,"u":53095243435}}
{"time":1701245687,"time_ms":1701245687132,"channel":"futures.order_book_update","event":"update","result":{"U":53095243436,"a":[{"p":"38152.4","s":0}],"b":[],"s":"BTC_USDT","t":1701245687115,"u":53095243437}}
{"time":1701245687,"time_ms":1701245687392,"channel":"futures.order_book_update","event":"update","result":{"U":53095243438,"a":[{"p":"38149.6","s":40},{"p":"38149.1","s":0},{"p":"38145.7","s":158510},{"p":"38149.2","s":3432}],"b":[],"s":"BTC_USDT","t":1701245687376,"u":53095243441}}
{"time":1701245687,"time_ms":1701245687420,"channel":"futures.order_book_update","event":"update","result":{"U":53095243442,"a":[{"p":"38149.2","s":92},{"p":"38149.5","s":3340},{"p":"38149.6","s":0},{"p":"38154.3","s":0}],"b":[{"p":"38134.2","s":0}],"s":"BTC_USDT","t":1701245687413,"u":53095243446}}
{"time":1701245687,"time_ms":1701245687433,"channel":"futures.order_book_update","event":"update","result":{"U":53095243447,"a":[],"b":[{"p":"38133.3","s":0}],"s":"BTC_USDT","t":1701245687416,"u":53095243448}}
{"time":1701245687,"time_ms":1701245687454,"channel":"futures.order_book_update","event":"update","result":{"U":53095243449,"a":[{"p":"38149.9","s":109},{"p":"38147.9","s":0},{"p":"38149.5","s":0},{"p":"38149.8","s":3340},{"p":"38148.1","s":2174},{"p":"38149","s":0},{"p":"38148.6","s":0},{"p":"38148.9","s":0},{"p":"38150","s":0},{"p":"38152.7","s":0},{"p":"38149.2","s":4566},{"p":"38149.6","s":40}],"b":[{"p":"38133.7","s":0},{"p":"38134.5","s":0},{"p":"38134.1","s":0},{"p":"38133.5","s":0},{"p":"38126.5","s":0},{"p":"38130.5","s":0}],"s":"BTC_USDT","t":1701245687443,"u":53095243473}}
{"time":1701245687,"time_ms":1701245687532,"channel":"futures.order_book_update","event":"update","result":{"U":53095243474,"a":[{"p":"38149.8","s":0},{"p":"38149.9","s":109},{"p":"38149.2","s":92},{"p":"38149.7","s":4534},{"p":"38148.6","s":2174},{"p":"38148.1","s":0}],"b":[{"p":"38134.7","s":0}],"s":"BTC_USDT","t":1701245687521,"u":53095243485}}
{"time":1701245687,"time_ms":1701245687552,"channel":"futures.order_book_update","event":"update","result":{"U":53095243486,"a":[{"p":"38153.3","s":0},{"p":"38153.1","s":0}],"b":[],"s":"BTC_USDT","t":1701245687536,"u":53095243488}}
{"time":1701245687,"time_ms":1701245687614,"channel":"futures.order_book_update","event":"update","result":{"U":53095243489,"a":[{"p":"38156.8","s":0}],"b":[],"s":"BTC_USDT","t":1701245687603,"u":53095243490}}
{"time":1701245687,"time_ms":1701245687632,"channel":"futures.order_book_update","event":"update","result":{"U":53095243491,"a":[{"p":"38155","s":0}],"b":[{"p":"38145.3","s":4500},{"p":"38137.8","s":0}],"s":"BTC_USDT","t":1701245687620,"u":53095243493}}
{"time":1701245687,"time_ms":1701245687651,"channel":"futures.order_book_update","event":"update","result":{"U":53095243494,"a":[],"b":[{"p":"38134.1","s":0}],"s":"BTC_USDT","t":1701245687626,"u":53095243496}}
{"time":1701245687,"time_ms":1701245687697,"channel":"futures.order_book_update","event":"update","result":{"U":53095243497,"a":[{"p":"38150","s":61560},{"p":"38148.6","s":0},{"p":"38153.3","s":0},{"p":"38147.3","s":3925},{"p":"38149.7","s":0},{"p":"38159","s":0},{"p":"38165.5","s":0},{"p":"38157","s":0},{"p":"38151.2","s":0},{"p":"38149.2","s":2266},{"p":"38153.9","s":0},{"p":"38157.5","s":0},{"p":"38145.7","s":152405},{"p":"38157.8","s":0},{"p":"38153","s":0},{"p":"38153.6","s":0},{"p":"38150.1","s":2116}],"b":[{"p":"38115.4","s":0},{"p":"38134.6","s":0},{"p":"38127","s":0},{"p":"38126","s":0},{"p":"38133","s":0},{"p":"38138.1","s":9726},{"p":"38143.8","s":0},{"p":"38125.4","s":0},{"p":"38129.5","s":0},{"p":"38138","s":100},{"p":"38143.7","s":2},{"p":"38145.4","s":2472},{"p":"38133.8","s":0},{"p":"38135.2","s":0},{"p":"38132.2","s":0},{"p":"38137","s":0},{"p":"38136.9","s":0},{"p":"38118.1","s":0},{"p":"38145.6","s":30781},{"p":"38131","s":0},{"p":"38137.6","s":0},{"p":"38133.7","s":0},{"p":"38120.3","s":0},{"p":"38040.3","s":0},{"p":"38135.4","s":0}],"s":"BTC_USDT","t":1701245687684,"u":53095243563}}
{"time":1701245687,"time_ms":1701245687714,"channel":"futures.order_book_update","event":"update","result":{"U":53095243564,"a":[{"p":"38149.2","s":92},{"p":"38145.7","s":152330},{"p":"38159","s":0},{"p":"38163.9","s":0},{"p":"38160.8","s":0}],"b":[{"p":"38138.5","s":8913},{"p":"38138.1","s":9126},{"p":"38138","s":0},{"p":"38134.7","s":0},{"p":"38145.1","s":655},{"p":"38145.6","s":30881},{"p":"38145.4","s":0},{"p":"38129.8","s":0},{"p":"38133.5","s":0},{"p":"38137.5","s":0},{"p":"38126.5","s":0}],"s":"BTC_USDT","t":1701245687702,"u":53095243598}}
{"time":1701245687,"time_ms":1701245687733,"channel":"futures.order_book_update","event":"update","result":{"U":53095243599,"a":[{"p":"38147.1","s":1838},{"p":"38146","s":0},{"p":"38155.4","s":0},{"p":"38153.5","s":0},{"p":"38152.9","s":0},{"p":"38145.7","s":152025},{"p":"38150.2","s":2},{"p":"38159.6","s":0},{"p":"38151.1","s":0},{"p":"38153.2","s":0},{"p":"38158.6","s":0},{"p":"38146.6","s":30000},{"p":"38147.3","s":3400}],"b":[{"p":"38145.6","s":50866},{"p":"38117.3","s":0},{"p":"38136","s":0},{"p":"38137.1","s":0},{"p":"38120.1","s":0},{"p":"38134.5","s":0},{"p":"38138.2","s":2908},{"p":"38138.5","s":0},{"p":"38138.1","s":0},{"p":"38139.5","s":8912}],"s":"BTC_USDT","t":1701245687724,"u":53095243649}}
{"time":1701245687,"time_ms":1701245687753,"channel":"futures.order_book_update","event":"update","result":{"U":53095243650,"a":[{"p":"38145.7","s":142432},{"p":"38158.5","s":0},{"p":"38153.5","s":0},{"p":"38154.5","s":0},{"p":"38166.2","s":0},{"p":"38147.1","s":919},{"p":"38148","s":0},{"p":"38159.4","s":0},{"p":"38151.8","s":0},{"p":"38150.5","s":18601},{"p":"38147.3","s":2875},{"p":"38150.4","s":550},{"p":"38154.2","s":0},{"p":"38154","s":0},{"p":"38148.7","s":0},{"p":"38155.6","s":0},{"p":"38153.8","s":0},{"p":"38156.2","s":0}],"b":[{"p":"38134.5","s":0},{"p":"38138.1","s":9126},{"p":"38138","s":100},{"p":"38143.7","s":4},{"p":"38142.9","s":0},{"p":"38136","s":0},{"p":"38145.6","s":61894},{"p":"38138.2","s":733},{"p":"38142.1","s":0},{"p":"38137.9","s":0},{"p":"38135.5","s":0},{"p":"38144.9","s":2},{"p":"38141","s":0},{"p":"38122.9","s":0},{"p":"38109.2","s":0}],"s":"BTC_USDT","t":1701245687743,"u":53095243706}}
{"time":1701245687,"time_ms":1701245687775,"channel":"futures.order_book_update","event":"update","result":{"U":53095243707,"a":[{"p":"38150.6","s":30997},{"p":"38147.2","s":525},{"p":"38147.3","s":2350},{"p":"38146.1","s":0},{"p":"38146.7","s":0},{"p":"38155.2","s":0},{"p":"38150.7","s":1315},{"p":"38145.7","s":143632},{"p":"38147.1","s":0},{"p":"38151.7","s":0},{"p":"38162.8","s":0},{"p":"38177","s":0},{"p":"38168","s":0}],"b":[{"p":"38118.1","s":0},{"p":"38139","s":100},{"p":"38123.4","s":0},{"p":"38139.7","s":0},{"p":"38136.5","s":0},{"p":"38145.6","s":62394},{"p":"38137.9","s":0},{"p":"38138","s":100},{"p":"38131","s":0}],"s":"BTC_USDT","t":1701245687764,"u":53095243754}}
{"time":1701245687,"time_ms":1701245687793,"channel":"futures.order_book_update","event":"update","result":{"U":53095243755,"a":[{"p":"38145.7","s":143032},{"p":"38174.5","s":0},{"p":"38185","s":0},{"p":"38156","s":0}],"b":[{"p":"38123.5","s":0},{"p":"38136","s":0},{"p":"38145.6","s":62394},{"p":"38119.9","s":0}],"s":"BTC_USDT","t":1701245687780,"u":53095243779}}
{"time":1701245687,"time_ms":1701245687815,"channel":"futures.order_book_update","event":"update","result":{"U":53095243780,"a":[{"p":"38145.7","s":142769},{"p":"38160","s":0},{"p":"38168","s":0},{"p":"38164","s":0}],"b":[{"p":"38145.6","s":62894},{"p":"38145.2","s":6538},{"p":"38138.2","s":2908},{"p":"38137.8","s":15208},{"p":"38145","s":584},{"p":"38145.1","s":0},{"p":"38140.1","s":0},{"p":"38127.5","s":0}],"s":"BTC_USDT","t":1701245687804,"u":53095243802}}
{"time":1701245687,"time_ms":1701245687832,"channel":"futures.order_book_update","event":"update","result":{"U":53095243803,"a":[],"b":[{"p":"38145.6","s":61894}],"s":"BTC_USDT","t":1701245687819,"u":53095243806}}
{"time":1701245687,"time_ms":1701245687854,"channel":"futures.order_book_update","event":"update","result":{"U":53095243807,"a":[],"b":[{"p":"38145.6","s":62394},{"p":"38123.5","s":0},{"p":"38133.4","s":0}],"s":"BTC_USDT","t":1701245687842,"u":53095243816}}
{"time":1701245687,"time_ms":1701245687873,"channel":"futures.order_book_update","event":"update","result":{"U":53095243817,"a":[{"p":"38150.9","s":14783},{"p":"38150.1","s":0},{"p":"38154.5","s":0},{"p":"38158.5","s":0}],"b":[{"p":"38145.6","s":72490},{"p":"38127.6","s":0}],"s":"BTC_USDT","t":1701245687861,"u":53095243827}}
{"time":1701245687,"time_ms":1701245687894,"channel":"futures.order_book_update","event":"update","result":{"U":53095243828,"a":[{"p":"38151","s":4951},{"p":"38150.5","s":0},{"p":"38154","s":0},{"p":"38169.7","s":0},{"p":"38158","s":0}],"b":[{"p":"38145.6","s":72990},{"p":"38123.5","s":0}],"s":"BTC_USDT","t":1701245687885,"u":53095243844}}
{"time":1701245687,"time_ms":1701245687913,"channel":"futures.order_book_update","event":"update","result":{"U":53095243845,"a":[],"b":[{"p":"38145.6","s":72990},{"p":"38123.5","s":0},{"p":"38137.3","s":0},{"p":"38144","s":100},{"p":"38139","s":0}],"s":"BTC_USDT","t":1701245687904,"u":53095243851}}
{"time":1701245687,"time_ms":1701245687932,"channel":"futures.order_book_update","event":"update","result":{"U":53095243852,"a":[{"p":"38149.8","s":15081},{"p":"38151","s":0}],"b":[{"p":"38135.2","s":0},{"p":"38123.5","s":0}],"s":"BTC_USDT","t":1701245687919,"u":53095243856}}
{"time":1701245687,"time_ms":1701245687954,"channel":"futures.order_book_update","event":"update","result":{"U":53095243857,"a":[],"b":[{"p":"38030.5","s":0},{"p":"38123.5","s":0},{"p":"38145.6","s":72490}],"s":"BTC_USDT","t":1701245687940,"u":53095243860}}
{"time":1701245687,"time_ms":1701245687975,"channel":"futures.order_book_update","event":"update","result":{"U":53095243861,"a":[],"b":[{"p":"38137.3","s":3932},{"p":"38145.3","s":0},{"p":"38145.6","s":72490}],"s":"BTC_USDT","t":1701245687962,"u":53095243873}}
{"time":1701245687,"time_ms":1701245687994,"channel":"futures.order_book_update","event":"update","result":{"U":53095243874,"a":[],"b":[{"p":"38145","s":0},{"p":"38123.5","s":0},{"p":"38116.8","s":0},{"p":"38137.3","s":3932},{"p":"38140.2","s":1},{"p":"38145.6","s":73574}],"s":"BTC_USDT","t":1701245687985,"u":53095243885}}
{"time":1701245688,"time_ms":1701245688012,"channel":"futures.order_book_update","event":"update","result":{"U":53095243886,"a":[],"b":[{"p":"38143.7","s":0},{"p":"38123.5","s":0},{"p":"38137.1","s":4590},{"p":"38145.6","s":73572},{"p":"38136.9","s":7260},{"p":"38144.9","s":0}],"s":"BTC_USDT","t":1701245687994,"u":53095243891}}
{"time":1701245688,"time_ms":1701245688034,"channel":"futures.order_book_update","event":"update","result":{"U":53095243892,"a":[{"p":"38157.1","s":0},{"p":"38160.5","s":0},{"p":"38152.7","s":0},{"p":"38155.2","s":0},{"p":"38147.3","s":2874},{"p":"38153.5","s":0},{"p":"38154.5","s":0}],"b":[{"p":"38137.3","s":0},{"p":"38136.9","s":0},{"p":"38134.5","s":0},{"p":"38137.4","s":0},{"p":"38144.6","s":2},{"p":"38145.4","s":2},{"p":"38138","s":100},{"p":"38128.2","s":0},{"p":"38143.9","s":2},{"p":"38137.1","s":0},{"p":"38123.5","s":0},{"p":"38142.7","s":2},{"p":"38137.8","s":0},{"p":"38138.2","s":0},{"p":"38137.9","s":0},{"p":"38138.3","s":2175}],"s":"BTC_USDT","t":1701245688025,"u":53095243925}}
{"time":1701245688,"time_ms":1701245688072,"channel":"futures.order_book_update","event":"update","result":{"U":53095243926,"a":[],"b":[{"p":"38123.5","s":0}],"s":"BTC_USDT","t":1701245688043,"u":53095243927}}
{"time":1701245688,"time_ms":1701245688092,"channel":"futures.order_book_update","event":"update","result":{"U":53095243928,"a":[],"b":[{"p":"38123.5","s":0},{"p":"38139","s":100},{"p":"38138.2","s":2175},{"p":"38144","s":0},{"p":"38138.3","s":0},{"p":"38137","s":0},{"p":"38137.9","s":0}],"s":"BTC_USDT","t":1701245688079,"u":53095243936}}
{"time":1701245688,"time_ms":1701245688113,"channel":"futures.order_book_update","event":"update","result":{"U":53095243937,"a":[],"b":[{"p":"38123.5","s":0}],"s":"BTC_USDT","t":1701245688083,"u":53095243937}}
{"time":1701245688,"time_ms":1701245688133,"channel":"futures.order_book_update","event":"update","result":{"U":53095243938,"a":[],"b":[{"p":"38123.5","s":0}],"s":"BTC_USDT","t":1701245688121,"u":53095243941}}
{"time":1701245688,"time_ms":1701245688152,"channel":"futures.order_book_update","event":"update","result":{"U":53095243942,"a":[],"b":[{"p":"38138","s":2275},{"p":"38138.2","s":0},{"p":"38123.5","s":0},{"p":"38134.2","s":0},{"p":"38137.9","s":733}],"s":"BTC_USDT","t":1701245688136,"u":53095243947}}
{"time":1701245688,"time_ms":1701245688172,"channel":"futures.order_book_update","event":"update","result":{"U":53095243948,"a":[],"b":[{"p":"38145.2","s":3857},{"p":"38137.9","s":733},{"p":"38137.8","s":0},{"p":"38136.9","s":0},{"p":"38137.5","s":0}],"s":"BTC_USDT","t":1701245688157,"u":53095243954}}
{"time":1701245688,"time_ms":1701245688191,"channel":"futures.order_book_update","event":"update","result":{"U":53095243955,"a":[],"b":[{"p":"38137.8","s":15208},{"p":"38137.9","s":0},{"p":"38137.5","s":0},{"p":"38123.5","s":0}],"s":"BTC_USDT","t":1701245688182,"u":53095243962}}
{"time":1701245688,"time_ms":1701245688214,"channel":"futures.order_book_update","event":"update","result":{"U":53095243963,"a":[],"b":[{"p":"38137.5","s":0},{"p":"38144","s":100},{"p":"38139","s":0},{"p":"38134.1","s":0},{"p":"38123.5","s":0}],"s":"BTC_USDT","t":1701245688201,"u":53095243969}}
{"time":1701245688,"time_ms":1701245688232,"channel":"futures.order_book_update","event":"update","result":{"U":53095243970,"a":[],"b":[{"p":"38137.8","s":0},{"p":"38143.6","s":655}],"s":"BTC_USDT","t":1701245688218,"u":53095243971}}
{"time":1701245688,"time_ms":1701245688253,"channel":"futures.order_book_update","event":"update","result":{"U":53095243972,"a":[],"b":[{"p":"38138","s":0},{"p":"38143.7","s":400}],"s":"BTC_USDT","t":1701245688238,"u":53095243975}}
{"time":1701245688,"time_ms":1701245688274,"channel":"futures.order_book_update","event":"update","result":{"U":53095243976,"a":[{"p":"38145.9","s":655},{"p":"38150.9","s":0},{"p":"38151.1","s":0}],"b":[{"p":"38123.5","s":0}],"s":"BTC_USDT","t":1701245688259,"u":53095243993}}
{"time":1701245688,"time_ms":1701245688313,"channel":"futures.order_book_update","event":"update","result":{"U":53095243994,"a":[{"p":"38165","s":0},{"p":"38164","s":0}],"b":[{"p":"38144","s":0},{"p":"38096.5","s":0},{"p":"38123.5","s":0},{"p":"38138","s":0},{"p":"38139","s":100}],"s":"BTC_USDT","t":1701245688303,"u":53095244005}}
{"time":1701245688,"time_ms":1701245688333,"channel":"futures.order_book_update","event":"update","result":{"U":53095244006,"a":[],"b":[{"p":"38137.5","s":733},{"p":"38138","s":2275},{"p":"38137.8","s":15208},{"p":"38142.7","s":0},{"p":"38145.4","s":0},{"p":"38143.9","s":0},{"p":"38123.5","s":0}],"s":"BTC_USDT","t":1701245688324,"u":53095244013}}
{"time":1701245688,"time_ms":1701245688352,"channel":"futures.order_book_update","event":"update","result":{"U":53095244014,"a":[],"b":[{"p":"38137.4","s":2370},{"p":"38144.6","s":0},{"p":"38136.5","s":0},{"p":"38136.9","s":0}],"s":"BTC_USDT","t":1701245688340,"u":53095244020}}
{"time":1701245688,"time_ms":1701245688373,"channel":"futures.order_book_update","event":"update","result":{"U":53095244021,"a":[],"b":[{"p":"38144.9","s":2},{"p":"38144.1","s":2},{"p":"38137.4","s":0},{"p":"38138","s":0},{"p":"38143.4","s":2},{"p":"38142.2","s":2},{"p":"38137.5","s":0},{"p":"38137.8","s":0},{"p":"38123.5","s":0}],"s":"BTC_USDT","t":1701245688359,"u":53095244028}}
{"time":1701245688,"time_ms":1701245688394,"channel":"futures.order_book_update","event":"update","result":{"U":53095244029,"a":[],"b":[{"p":"38123.5","s":0},{"p":"38136.8","s":0}],"s":"BTC_USDT","t":1701245688385,"u":53095244033}}
{"time":1701245688,"time_ms":1701245688413,"channel":"futures.order_book_update","event":"update","result":{"U":53095244034,"a":[{"p":"38145.8","s":563},{"p":"38149.4","s":0},{"p":"38150.7","s":1315}],"b":[{"p":"38123.5","s":0}],"s":"BTC_USDT","t":1701245688391,"u":53095244036}}
{"time":1701245688,"time_ms":1701245688432,"channel":"futures.order_book_update","event":"update","result":{"U":53095244037,"a":[{"p":"38153.9","s":0},{"p":"38160","s":0},{"p":"38156.8","s":0},{"p":"38145.7","s":142169},{"p":"38152.6","s":0},{"p":"38154","s":0},{"p":"38152.4","s":0}],"b":[{"p":"38138.1","s":9126},{"p":"38138.2","s":2312},{"p":"38138","s":2275},{"p":"38137.5","s":2908},{"p":"38143.4","s":0},{"p":"38142.2","s":0},{"p":"38137.4","s":0},{"p":"38136.9","s":0},{"p":"38137.8","s":15208},{"p":"38144.9","s":0},{"p":"38144.1","s":0},{"p":"38133.7","s":0},{"p":"38123.5","s":0}],"s":"BTC_USDT","t":1701245688418,"u":53095244062}}
{"time":1701245688,"time_ms":1701245688452,"channel":"futures.order_book_update","event":"update","result":{"U":53095244063,"a":[],"b":[{"p":"38134.1","s":0},{"p":"38123.5","s":0},{"p":"38144","s":2},{"p":"38142.1","s":2},{"p":"38143.3","s":2},{"p":"38138","s":0},{"p":"38137.8","s":0},{"p":"38144.8","s":2},{"p":"38138.1","s":0},{"p":"38137.5","s":0}],"s":"BTC_USDT","t":1701245688442,"u":53095244070}}
{"time":1701245688,"time_ms":1701245688473,"channel":"futures.order_book_update","event":"update","result":{"U":53095244071,"a":[],"b":[{"p":"38123.5","s":0}],"s":"BTC_USDT","t":1701245688461,"u":53095244072}}
{"time":1701245688,"time_ms":1701245688508,"channel":"futures.order_book_update","event":"update","result":{"U":53095244073,"a":[],"b":[{"p":"38138.3","s":733},{"p":"38138.2","s":0},{"p":"38123.5","s":0},{"p":"38137.5","s":0}],"s":"BTC_USDT","t":1701245688496,"u":53095244078}}
{"time":1701245688,"time_ms":1701245688533,"channel":"futures.order_book_update","event":"update","result":{"U":53095244079,"a":[{"p":"38155.6","s":0}],"b":[{"p":"38123.5","s":0},{"p":"38134.8","s":0}],"s":"BTC_USDT","t":1701245688523,"u":53095244082}}
{"time":1701245688,"time_ms":1701245688553,"channel":"futures.order_book_update","event":"update","result":{"U":53095244083,"a":[],"b":[{"p":"38137.5","s":0}],"s":"BTC_USDT","t":1701245688543,"u":53095244087}}
{"time":1701245688,"time_ms":1701245688573,"channel":"futures.order_book_update","event":"update","result":{"U":53095244088,"a":[],"b":[{"p":"38134.5","s":0},{"p":"38123.5","s":0}],"s":"BTC_USDT","t":1701245688550,"u":53095244092}}
{"time":1701245688,"time_ms":1701245688591,"channel":"futures.order_book_update","event":"update","result":{"U":53095244093,"a":[],"b":[{"p":"38123.5","s":0}],"s":"BTC_USDT","t":1701245688583,"u":53095244095}}
{"time":1701245688,"time_ms":1701245688614,"channel":"futures.order_book_update","event":"update","result":{"U":53095244096,"a":[],"b":[{"p":"38123.5","s":0}],"s":"BTC_USDT","t":1701245688605,"u":53095244097}}
{"time":1701245688,"time_ms":1701245688633,"channel":"futures.order_book_update","event":"update","result":{"U":53095244098,"a":[],"b":[{"p":"38123.5","s":0}],"s":"BTC_USDT","t":1701245688621,"u":53095244100}}
{"time":1701245688,"time_ms":1701245688653,"channel":"futures.order_book_update","event":"update","result":{"U":53095244101,"a":[],"b":[{"p":"38134.4","s":0}],"s":"BTC_USDT","t":1701245688640,"u":53095244103}}
{"time":1701245688,"time_ms":1701245688672,"channel":"futures.order_book_update","event":"update","result":{"U":53095244104,"a":[{"p":"38145.7","s":142769},{"p":"38160.6","s":0}],"b":[{"p":"38123.5","s":0},{"p":"38133.3","s":0},{"p":"38128.8","s":0}],"s":"BTC_USDT","t":1701245688665,"u":53095244111}}
{"time":1701245688,"time_ms":1701245688693,"channel":"futures.order_book_update","event":"update","result":{"U":53095244112,"a":[{"p":"38152.1","s":0},{"p":"38155.2","s":0},{"p":"38154.5","s":0},{"p":"38152.3","s":0},{"p":"38153.3","s":0},{"p":"38145.7","s":142169},{"p":"38153","s":0}],"b":[{"p":"38138","s":0},{"p":"38137","s":0},{"p":"38123.5","s":0},{"p":"38145.6","s":74072},{"p":"38142.9","s":655},{"p":"38143.6","s":0},{"p":"38138.1","s":0},{"p":"38138.2","s":0}],"s":"BTC_USDT","t":1701245688682,"u":53095244139}}
{"time":1701245688,"time_ms":1701245688713,"channel":"futures.order_book_update","event":"update","result":{"U":53095244140,"a":[],"b":[{"p":"38138.3","s":0},{"p":"38137.4","s":0},{"p":"38123.5","s":0},{"p":"38138.4","s":2175}],"s":"BTC_USDT","t":1701245688697,"u":53095244144}}
{"time":1701245688,"time_ms":1701245688772,"channel":"futures.order_book_update","event":"update","result":{"U":53095244145,"a":[],"b":[{"p":"38123.5","s":0},{"p":"38132.4","s":0},{"p":"38138.3","s":733},{"p":"38142.9","s":0}],"s":"BTC_USDT","t":1701245688756,"u":53095244150}}
{"time":1701245688,"time_ms":1701245688792,"channel":"futures.order_book_update","event":"update","result":{"U":53095244151,"a":[],"b":[{"p":"38138.1","s":9126},{"p":"38138","s":100},{"p":"38143.7","s":0},{"p":"38139","s":0},{"p":"38123.5","s":0},{"p":"38144","s":102}],"s":"BTC_USDT","t":1701245688776,"u":53095244157}}
{"time":1701245688,"time_ms":1701245688833,"channel":"futures.order_book_update","event":"update","result":{"U":53095244158,"a":[],"b":[{"p":"38137.9","s":733},{"p":"38145.6","s":74572},{"p":"38138.3","s":0},{"p":"38137.8","s":0}],"s":"BTC_USDT","t":1701245688827,"u":53095244165}}
{"time":1701245688,"time_ms":1701245688853,"channel":"futures.order_book_update","event":"update","result":{"U":53095244166,"a":[],"b":[{"p":"38145.6","s":74072}],"s":"BTC_USDT","t":1701245688845,"u":53095244168}}
{"time":1701245688,"time_ms":1701245688952,"channel":"futures.order_book_update","event":"update","result":{"U":53095244169,"a":[],"b":[{"p":"38144.8","s":0},{"p":"38143.3","s":0},{"p":"38142.1","s":0},{"p":"38144","s":100},{"p":"38137.3","s":3958},{"p":"38137.8","s":15208},{"p":"38137.4","s":2320}],"s":"BTC_USDT","t":1701245688936,"u":53095244172}}
{"time":1701245688,"time_ms":1701245688974,"channel":"futures.order_book_update","event":"update","result":{"U":53095244173,"a":[],"b":[{"p":"38137.8","s":0},{"p":"38137.4","s":0},{"p":"38137.9","s":0},{"p":"38137.3","s":0},{"p":"38144.6","s":2},{"p":"38143.8","s":2},{"p":"38143.1","s":2},{"p":"38141.9","s":2}],"s":"BTC_USDT","t":1701245688960,"u":53095244176}}
{"time":1701245689,"time_ms":1701245689013,"channel":"futures.order_book_update","event":"update","result":{"U":53095244177,"a":[{"p":"38152.8","s":0}],"b":[{"p":"38136.5","s":0}],"s":"BTC_USDT","t":1701245689004,"u":53095244180}}
{"time":1701245689,"time_ms":1701245689034,"channel":"futures.order_book_update","event":"update","result":{"U":53095244181,"a":[{"p":"38154.6","s":0},{"p":"38157.5","s":0},{"p":"38153.9","s":0}],"b":[{"p":"38138.2","s":2908},{"p":"38138.4","s":0},{"p":"38134.1","s":0},{"p":"38137.9","s":0},{"p":"38137.4","s":0}],"s":"BTC_USDT","t":1701245689017,"u":53095244194}}
{"time":1701245689,"time_ms":1701245689053,"channel":"futures.order_book_update","event":"update","result":{"U":53095244195,"a":[],"b":[{"p":"38138.2","s":2175}],"s":"BTC_USDT","t":1701245689021,"u":53095244196}}
{"time":1701245689,"time_ms":1701245689071,"channel":"futures.order_book_update","event":"update","result":{"U":53095244197,"a":[],"b":[{"p":"38134","s":0}],"s":"BTC_USDT","t":1701245689053,"u":53095244198}}
{"time":1701245689,"time_ms":1701245689113,"channel":"futures.order_book_update","event":"update","result":{"U":53095244199,"a":[{"p":"38145.7","s":142769},{"p":"38152.7","s":0},{"p":"38154","s":0},{"p":"38155.2","s":0},{"p":"38156.8","s":0}],"b":[{"p":"38137.8","s":15208},{"p":"38138.2","s":0},{"p":"38137","s":0},{"p":"38137.9","s":0},{"p":"38130.1","s":0},{"p":"38133.7","s":0}],"s":"BTC_USDT","t":1701245689098,"u":53095244220}}
{"time":1701245689,"time_ms":1701245689133,"channel":"futures.order_book_update","event":"update","result":{"U":53095244221,"a":[{"p":"38160.5","s":0},{"p":"38152.6","s":0}],"b":[{"p":"38133.3","s":0},{"p":"38145.6","s":59072},{"p":"38137.4","s":0}],"s":"BTC_USDT","t":1701245689113,"u":53095244235}}
{"time":1701245689,"time_ms":1701245689212,"channel":"futures.order_book_update","event":"update","result":{"U":53095244236,"a":[],"b":[{"p":"38142.4","s":2},{"p":"38139","s":100},{"p":"38137.3","s":3958},{"p":"38141.2","s":2},{"p":"38144.6","s":0},{"p":"38143.8","s":0},{"p":"38137.1","s":0},{"p":"38136.6","s":0},{"p":"38136.9","s":0},{"p":"38141.9","s":0},{"p":"38144","s":0},{"p":"38136.7","s":0},{"p":"38143.1","s":2}],"s":"BTC_USDT","t":1701245689202,"u":53095244244}}
{"time":1701245689,"time_ms":1701245689234,"channel":"futures.order_book_update","event":"update","result":{"U":53095244245,"a":[],"b":[{"p":"38143.9","s":2},{"p":"38137.3","s":0}],"s":"BTC_USDT","t":1701245689206,"u":53095244245}}
{"time":1701245689,"time_ms":1701245689253,"channel":"futures.order_book_update","event":"update","result":{"U":53095244246,"a":[{"p":"38166.5","s":0},{"p":"38157.5","s":0},{"p":"38153.5","s":0}],"b":[],"s":"BTC_USDT","t":1701245689236,"u":53095244251}}
{"time":1701245689,"time_ms":1701245689292,"channel":"futures.order_book_update","event":"update","result":{"U":53095244252,"a":[{"p":"38153.4","s":0}],"b":[{"p":"38136.2","s":0}],"s":"BTC_USDT","t":1701245689276,"u":53095244255}}
{"time":1701245689,"time_ms":1701245689313,"channel":"futures.order_book_update","event":"update","result":{"U":53095244256,"a":[],"b":[{"p":"38144","s":100},{"p":"38139","s":0},{"p":"38137.3","s":0}],"s":"BTC_USDT","t":1701245689294,"u":53095244257}}
{"time":1701245689,"time_ms":1701245689353,"channel":"futures.order_book_update","event":"update","result":{"U":53095244258,"a":[],"b":[{"p":"38125.3","s":0}],"s":"BTC_USDT","t":1701245689342,"u":53095244259}}
{"time":1701245689,"time_ms":1701245689371,"channel":"futures.order_book_update","event":"update","result":{"U":53095244260,"a":[{"p":"38153.1","s":0},{"p":"38152.1","s":0}],"b":[{"p":"38133","s":0}],"s":"BTC_USDT","t":1701245689360,"u":53095244265}}
{"time":1701245689,"time_ms":1701245689412,"channel":"futures.order_book_update","event":"update","result":{"U":53095244266,"a":[],"b":[{"p":"38139","s":100},{"p":"38144","s":0},{"p":"38137.3","s":0}],"s":"BTC_USDT","t":1701245689387,"u":53095244268}}
{"time":1701245689,"time_ms":1701245689474,"channel":"futures.order_book_update","event":"update","result":{"U":53095244269,"a":[{"p":"38157","s":0},{"p":"38153","s":0}],"b":[],"s":"BTC_USDT","t":1701245689446,"u":53095244273}}
{"time":1701245689,"time_ms":1701245689511,"channel":"futures.order_book_update","event":"update","result":{"U":53095244274,"a":[],"b":[{"p":"38137.3","s":0},{"p":"38144","s":100},{"p":"38139","s":0}],"s":"BTC_USDT","t":1701245689491,"u":53095244275}}
{"time":1701245689,"time_ms":1701245689533,"channel":"futures.order_book_update","event":"update","result":{"U":53095244276,"a":[{"p":"38152.1","s":0}],"b":[{"p":"38137.1","s":0},{"p":"38136","s":0}],"s":"BTC_USDT","t":1701245689517,"u":53095244285}}
{"time":1701245689,"time_ms":1701245689552,"channel":"futures.order_book_update","event":"update","result":{"U":53095244286,"a":[],"b":[{"p":"38145.6","s":74072}],"s":"BTC_USDT","t":1701245689542,"u":53095244288}}
{"time":1701245689,"time_ms":1701245689572,"channel":"futures.order_book_update","event":"update","result":{"U":53095244289,"a":[],"b":[{"p":"38135.6","s":0}],"s":"BTC_USDT","t":1701245689565,"u":53095244290}}
{"time":1701245689,"time_ms":1701245689593,"channel":"futures.order_book_update","event":"update","result":{"U":53095244291,"a":[],"b":[{"p":"38132.5","s":0}],"s":"BTC_USDT","t":1701245689569,"u":53095244292}}
{"time":1701245689,"time_ms":1701245689613,"channel":"futures.order_book_update","event":"update","result":{"U":53095244293,"a":[{"p":"38155.5","s":0}],"b":[{"p":"38136.8","s":0}],"s":"BTC_USDT","t":1701245689598,"u":53095244295}}
{"time":1701245689,"time_ms":1701245689631,"channel":"futures.order_book_update","event":"update","result":{"U":53095244296,"a":[{"p":"38156.4","s":0}],"b":[],"s":"BTC_USDT","t":1701245689613,"u":53095244298}}
{"time":1701245689,"time_ms":1701245689672,"channel":"futures.order_book_update","event":"update","result":{"U":53095244299,"a":[{"p":"38155.1","s":0}],"b":[{"p":"38145.6","s":73572}],"s":"BTC_USDT","t":1701245689663,"u":53095244302}}
{"time":1701245689,"time_ms":1701245689732,"channel":"futures.order_book_update","event":"update","result":{"U":53095244303,"a":[],"b":[{"p":"38141.2","s":0},{"p":"38143.9","s":0},{"p":"38137.3","s":3958},{"p":"38136.8","s":1315},{"p":"38136.7","s":10165},{"p":"38136.9","s":7234},{"p":"38143.1","s":0},{"p":"38142.4","s":0}],"s":"BTC_USDT","t":1701245689715,"u":53095244306}}
{"time":1701245689,"time_ms":1701245689752,"channel":"futures.order_book_update","event":"update","result":{"U":53095244307,"a":[],"b":[{"p":"38134.7","s":0}],"s":"BTC_USDT","t":1701245689728,"u":53095244307}}
{"time":1701245689,"time_ms":1701245689773,"channel":"futures.order_book_update","event":"update","result":{"U":53095244308,"a":[],"b":[{"p":"38141.9","s":2},{"p":"38142.7","s":2},{"p":"38141.2","s":2},{"p":"38140","s":2},{"p":"38137.3","s":0},{"p":"38136.8","s":0},{"p":"38136.9","s":0},{"p":"38136.7","s":0}],"s":"BTC_USDT","t":1701245689755,"u":53095244311}}
{"time":1701245689,"time_ms":1701245689952,"channel":"futures.order_book_update","event":"update","result":{"U":53095244312,"a":[],"b":[{"p":"38136.8","s":1315},{"p":"38136.9","s":7234},{"p":"38136.7","s":10165},{"p":"38142.7","s":0},{"p":"38141.2","s":0},{"p":"38140","s":0},{"p":"38141.9","s":0},{"p":"38137.3","s":3958}],"s":"BTC_USDT","t":1701245689944,"u":53095244325}}
{"time":1701245689,"time_ms":1701245689974,"channel":"futures.order_book_update","event":"update","result":{"U":53095244326,"a":[],"b":[{"p":"38141.9","s":2},{"p":"38142.6","s":2},{"p":"38140.7","s":2},{"p":"38143.4","s":2},{"p":"38136.9","s":0},{"p":"38136.7","s":0},{"p":"38137.3","s":0},{"p":"38136.8","s":0}],"s":"BTC_USDT","t":1701245689967,"u":53095244330}}
{"time":1701245689,"time_ms":1701245689995,"channel":"futures.order_book_update","event":"update","result":{"U":53095244331,"a":[],"b":[{"p":"38145.6","s":58572}],"s":"BTC_USDT","t":1701245689983,"u":53095244332}}
{"time":1701245690,"time_ms":1701245690013,"channel":"futures.order_book_update","event":"update","result":{"U":53095244333,"a":[{"p":"38152.3","s":0}],"b":[],"s":"BTC_USDT","t":1701245690002,"u":53095244336}}
{"time":1701245690,"time_ms":1701245690033,"channel":"futures.order_book_update","event":"update","result":{"U":53095244337,"a":[{"p":"38152.8","s":0},{"p":"38155.4","s":0},{"p":"38159.6","s":0},{"p":"38151.3","s":0}],"b":[{"p":"38136.2","s":0},{"p":"38136.7","s":0},{"p":"38143.7","s":655},{"p":"38137.8","s":0},{"p":"38129.4","s":0},{"p":"38136.5","s":0}],"s":"BTC_USDT","t":1701245690012,"u":53095244354}}
{"time":1701245690,"time_ms":1701245690053,"channel":"futures.order_book_update","event":"update","result":{"U":53095244355,"a":[],"b":[{"p":"38143.8","s":393},{"p":"38138","s":0},{"p":"38135.2","s":0}],"s":"BTC_USDT","t":1701245690035,"u":53095244357}}
{"time":1701245690,"time_ms":1701245690072,"channel":"futures.order_book_update","event":"update","result":{"U":53095244358,"a":[],"b":[{"p":"38137","s":0}],"s":"BTC_USDT","t":1701245690050,"u":53095244359}}
{"time":1701245690,"time_ms":1701245690112,"channel":"futures.order_book_update","event":"update","result":{"U":53095244360,"a":[],"b":[{"p":"38136.9","s":0},{"p":"38135.9","s":0},{"p":"38131.8","s":0},{"p":"38137","s":0},{"p":"38138","s":0},{"p":"38139","s":100},{"p":"38144","s":0},{"p":"38135.8","s":0}],"s":"BTC_USDT","t":1701245690102,"u":53095244371}}
{"time":1701245690,"time_ms":1701245690132,"channel":"futures.order_book_update","event":"update","result":{"U":53095244372,"a":[{"p":"38151.5","s":0}],"b":[{"p":"38136.9","s":0}],"s":"BTC_USDT","t":1701245690120,"u":53095244375}}
{"time":1701245690,"time_ms":1701245690193,"channel":"futures.order_book_update","event":"update","result":{"U":53095244376,"a":[],"b":[{"p":"38145.6","s":59072}],"s":"BTC_USDT","t":1701245690169,"u":53095244376}}
{"time":1701245690,"time_ms":1701245690271,"channel":"futures.order_book_update","event":"update","result":{"U":53095244377,"a":[{"p":"38151.3","s":0},{"p":"38152.4","s":0}],"b":[{"p":"38140.7","s":0},{"p":"38141.9","s":0},{"p":"38143.4","s":0},{"p":"38136.9","s":0},{"p":"38131.4","s":0},{"p":"38136.5","s":0},{"p":"38137.8","s":15208},{"p":"38138","s":100},{"p":"38137.3","s":3958},{"p":"38137","s":2175},{"p":"38142.6","s":0}],"s":"BTC_USDT","t":1701245690260,"u":53095244388}}
{"time":1701245690,"time_ms":1701245690292,"channel":"futures.order_book_update","event":"update","result":{"U":53095244389,"a":[],"b":[{"p":"38142.6","s":2},{"p":"38141.1","s":2},{"p":"38140","s":2},{"p":"38141.9","s":2},{"p":"38137.8","s":0},{"p":"38138","s":0},{"p":"38137.3","s":0},{"p":"38137","s":0},{"p":"38131.8","s":0}],"s":"BTC_USDT","t":1701245690283,"u":53095244394}}
{"time":1701245690,"time_ms":1701245690311,"channel":"futures.order_book_update","event":"update","result":{"U":53095244395,"a":[],"b":[{"p":"38144","s":100},{"p":"38139","s":0},{"p":"38138","s":0}],"s":"BTC_USDT","t":1701245690294,"u":53095244396}}
{"time":1701245690,"time_ms":1701245690413,"channel":"futures.order_book_update","event":"update","result":{"U":53095244397,"a":[],"b":[{"p":"38129.2","s":0}],"s":"BTC_USDT","t":1701245690401,"u":53095244398}}
{"time":1701245690,"time_ms":1701245690432,"channel":"futures.order_book_update","event":"update","result":{"U":53095244399,"a":[{"p":"38155.1","s":0}],"b":[{"p":"38139","s":100},{"p":"38144","s":0},{"p":"38138","s":0}],"s":"BTC_USDT","t":1701245690418,"u":53095244401}}
{"time":1701245690,"time_ms":1701245690593,"channel":"futures.order_book_update","event":"update","result":{"U":53095244402,"a":[],"b":[{"p":"38131.5","s":0}],"s":"BTC_USDT","t":1701245690570,"u":53095244412}}
{"time":1701245690,"time_ms":1701245690652,"channel":"futures.order_book_update","event":"update","result":{"U":53095244413,"a":[],"b":[{"p":"38137.8","s":15208},{"p":"38137.3","s":3958},{"p":"38137","s":2175},{"p":"38138","s":100},{"p":"38141.9","s":0},{"p":"38140","s":0},{"p":"38142.6","s":0},{"p":"38141.1","s":0}],"s":"BTC_USDT","t":1701245690632,"u":53095244416}}
{"time":1701245690,"time_ms":1701245690670,"channel":"futures.order_book_update","event":"update","result":{"U":53095244417,"a":[],"b":[{"p":"38137.8","s":0},{"p":"38137.3","s":0},{"p":"38137","s":0},{"p":"38138","s":0},{"p":"38139.9","s":2},{"p":"38141.9","s":2},{"p":"38141.1","s":2},{"p":"38142.6","s":2}],"s":"BTC_USDT","t":1701245690655,"u":53095244422}}
{"time":1701245690,"time_ms":1701245690692,"channel":"futures.order_book_update","event":"update","result":{"U":53095244423,"a":[],"b":[{"p":"38139.9","s":0},{"p":"38138","s":100},{"p":"38137","s":2175},{"p":"38137.8","s":15208},{"p":"38137.3","s":3958},{"p":"38141.9","s":0},{"p":"38141.1","s":0},{"p":"38142.6","s":0}],"s":"BTC_USDT","t":1701245690670,"u":53095244426}}
{"time":1701245690,"time_ms":1701245690712,"channel":"futures.order_book_update","event":"update","result":{"U":53095244427,"a":[],"b":[{"p":"38141.9","s":2},{"p":"38145.6","s":56435},{"p":"38137.8","s":0},{"p":"38137","s":0},{"p":"38141.1","s":2},{"p":"38142.6","s":2},{"p":"38138","s":0},{"p":"38139.9","s":2},{"p":"38137.3","s":0}],"s":"BTC_USDT","t":1701245690697,"u":53095244431}}
{"time":1701245690,"time_ms":1701245690813,"channel":"futures.order_book_update","event":"update","result":{"U":53095244432,"a":[{"p":"38153.3","s":0}],"b":[],"s":"BTC_USDT","t":1701245690796,"u":53095244432}}
{"time":1701245690,"time_ms":1701245690971,"channel":"futures.order_book_update","event":"update","result":{"U":53095244433,"a":[{"p":"38153.3","s":0}],"b":[],"s":"BTC_USDT","t":1701245690951,"u":53095244436}}
{"time":1701245691,"time_ms":1701245691033,"channel":"futures.order_book_update","event":"update","result":{"U":53095244437,"a":[{"p":"38151.5","s":0},{"p":"38152.7","s":0},{"p":"38151.8","s":0},{"p":"38155.7","s":0}],"b":[{"p":"38131","s":0},{"p":"38135.7","s":0},{"p":"38129.2","s":0},{"p":"38136.7","s":0},{"p":"38136.9","s":0}],"s":"BTC_USDT","t":1701245691020,"u":53095244455}}
{"time":1701245691,"time_ms":1701245691113,"channel":"futures.order_book_update","event":"update","result":{"U":53095244456,"a":[],"b":[{"p":"38137","s":0}],"s":"BTC_USDT","t":1701245691103,"u":53095244458}}
{"time":1701245691,"time_ms":1701245691154,"channel":"futures.order_book_update","event":"update","result":{"U":53095244459,"a":[],"b":[{"p":"38135","s":0}],"s":"BTC_USDT","t":1701245691136,"u":53095244459}}
{"time":1701245691,"time_ms":1701245691212,"channel":"futures.order_book_update","event":"update","result":{"U":53095244460,"a":[],"b":[{"p":"38136","s":0}],"s":"BTC_USDT","t":1701245691200,"u":53095244461}}
{"time":1701245691,"time_ms":1701245691233,"channel":"futures.order_book_update","event":"update","result":{"U":53095244462,"a":[{"p":"38153.3","s":0},{"p":"38151.6","s":0},{"p":"38152.4","s":0}],"b":[{"p":"38137.1","s":0}],"s":"BTC_USDT","t":1701245691224,"u":53095244468}}
{"time":1701245691,"time_ms":1701245691275,"channel":"futures.order_book_update","event":"update","result":{"U":53095244469,"a":[],"b":[{"p":"38127.6","s":0}],"s":"BTC_USDT","t":1701245691266,"u":53095244472}}
{"time":1701245691,"time_ms":1701245691313,"channel":"futures.order_book_update","event":"update","result":{"U":53095244473,"a":[{"p":"38151.4","s":0},{"p":"38155.8","s":0},{"p":"38151.7","s":0}],"b":[{"p":"38145.6","s":71435},{"p":"38136.2","s":0}],"s":"BTC_USDT","t":1701245691305,"u":53095244481}}
{"time":1701245691,"time_ms":1701245691352,"channel":"futures.order_book_update","event":"update","result":{"U":53095244482,"a":[],"b":[{"p":"38135.3","s":0}],"s":"BTC_USDT","t":1701245691329,"u":53095244482}}
{"time":1701245691,"time_ms":1701245691392,"channel":"futures.order_book_update","event":"update","result":{"U":53095244483,"a":[],"b":[{"p":"38144","s":100},{"p":"38139","s":0},{"p":"38138.1","s":9126}],"s":"BTC_USDT","t":1701245691382,"u":53095244484}}
